
#######################################################################
# +-----------------------------------------------------------------+ #
# |                            BO3 object                           | #
# +-----------------------------------------------------------------+ #
#######################################################################

Author: Unknown

Description: No description given

Version: 3

SettingsMode: WriteWithoutComments


#######################################################################
# +-----------------------------------------------------------------+ #
# |                          Main settings                          | #
# +-----------------------------------------------------------------+ #
#######################################################################

Tree: true

Frequency: 40

Rarity: 100.0

MaxSpawn: 0

RotateRandomly: true

SpawnHeight: highestSolidBlock

SpawnHeightOffset: 1

SpawnHeightVariance: 0

##############################
# Height Limits for the BO3. #
##############################

MinHeight: 87

MaxHeight: 94

######################
# Extrusion settings #
######################

ExtrudeMode: BottomDown

ExtrudeThroughBlocks: minecraft:grass_block,minecraft:air,minecraft:water

MaxBranchDepth: 10


#######################################################################
# +-----------------------------------------------------------------+ #
# |                      Source block settings                      | #
# +-----------------------------------------------------------------+ #
#######################################################################

SourceBlocks: minecraft:grass_block,minecraft:air,minecraft:water

MaxPercentageOutsideSourceBlock: 100

OutsideSourceBlock: dontPlace

DoReplaceBlocks: true

IsOTGPlus: false


#######################################################################
# +-----------------------------------------------------------------+ #
# |                              Blocks                             | #
# +-----------------------------------------------------------------+ #
#######################################################################

B(-13,-27,0,minecraft:terracotta)
B(-13,-26,0,minecraft:terracotta)
B(-13,-25,0,minecraft:terracotta)
B(-13,-27,1,minecraft:terracotta)
B(-13,-26,1,minecraft:terracotta)
B(-13,-25,1,minecraft:terracotta)
B(-13,-24,1,minecraft:terracotta)
B(-13,-23,1,minecraft:terracotta)
B(-13,-22,1,minecraft:terracotta)
B(-13,-27,2,minecraft:terracotta)
B(-13,-26,2,minecraft:terracotta)
B(-13,-25,2,minecraft:terracotta)
B(-12,-27,-1,minecraft:terracotta)
B(-12,-26,-1,minecraft:terracotta)
B(-12,-25,-1,minecraft:terracotta)
B(-12,-27,0,minecraft:terracotta)
B(-12,-26,0,minecraft:terracotta)
B(-12,-25,0,minecraft:terracotta)
B(-12,-24,0,minecraft:terracotta)
B(-12,-23,0,minecraft:terracotta)
B(-12,-22,0,minecraft:terracotta)
B(-12,-21,0,minecraft:terracotta)
B(-12,-27,1,minecraft:terracotta)
B(-12,-26,1,minecraft:terracotta)
B(-12,-25,1,minecraft:terracotta)
B(-12,-24,1,minecraft:terracotta)
B(-12,-23,1,minecraft:terracotta)
B(-12,-22,1,minecraft:terracotta)
B(-12,-21,1,minecraft:terracotta)
B(-12,-20,1,minecraft:terracotta)
B(-12,-19,1,minecraft:terracotta)
B(-12,-18,1,minecraft:terracotta)
B(-12,-17,1,minecraft:terracotta)
B(-12,-16,1,minecraft:terracotta)
B(-12,-27,2,minecraft:terracotta)
B(-12,-26,2,minecraft:terracotta)
B(-12,-25,2,minecraft:terracotta)
B(-12,-24,2,minecraft:terracotta)
B(-12,-23,2,minecraft:terracotta)
B(-12,-22,2,minecraft:terracotta)
B(-12,-27,3,minecraft:terracotta)
B(-12,-26,3,minecraft:terracotta)
B(-12,-27,4,minecraft:terracotta)
B(-12,-27,5,minecraft:terracotta)
B(-12,-27,6,minecraft:terracotta)
B(-11,-27,-2,minecraft:terracotta)
B(-11,-26,-2,minecraft:terracotta)
B(-11,-27,-1,minecraft:terracotta)
B(-11,-26,-1,minecraft:terracotta)
B(-11,-25,-1,minecraft:terracotta)
B(-11,-24,-1,minecraft:terracotta)
B(-11,-27,0,minecraft:terracotta)
B(-11,-26,0,minecraft:terracotta)
B(-11,-25,0,minecraft:terracotta)
B(-11,-24,0,minecraft:terracotta)
B(-11,-23,0,minecraft:terracotta)
B(-11,-22,0,minecraft:terracotta)
B(-11,-21,0,minecraft:terracotta)
B(-11,-20,0,minecraft:terracotta)
B(-11,-19,0,minecraft:terracotta)
B(-11,-18,0,minecraft:terracotta)
B(-11,-17,0,minecraft:terracotta)
B(-11,-16,0,minecraft:terracotta)
B(-11,-27,1,minecraft:terracotta)
B(-11,-26,1,minecraft:terracotta)
B(-11,-25,1,minecraft:terracotta)
B(-11,-24,1,minecraft:terracotta)
B(-11,-23,1,minecraft:terracotta)
B(-11,-22,1,minecraft:terracotta)
B(-11,-21,1,minecraft:terracotta)
B(-11,-20,1,minecraft:terracotta)
B(-11,-19,1,minecraft:terracotta)
B(-11,-18,1,minecraft:terracotta)
B(-11,-17,1,minecraft:terracotta)
B(-11,-16,1,minecraft:terracotta)
B(-11,-15,1,minecraft:terracotta)
B(-11,-27,2,minecraft:terracotta)
B(-11,-26,2,minecraft:terracotta)
B(-11,-25,2,minecraft:terracotta)
B(-11,-24,2,minecraft:terracotta)
B(-11,-23,2,minecraft:terracotta)
B(-11,-22,2,minecraft:terracotta)
B(-11,-21,2,minecraft:terracotta)
B(-11,-20,2,minecraft:terracotta)
B(-11,-27,3,minecraft:terracotta)
B(-11,-26,3,minecraft:terracotta)
B(-11,-25,3,minecraft:terracotta)
B(-11,-24,3,minecraft:terracotta)
B(-11,-23,3,minecraft:terracotta)
B(-11,-22,3,minecraft:terracotta)
B(-11,-27,4,minecraft:terracotta)
B(-11,-26,4,minecraft:terracotta)
B(-11,-25,4,minecraft:terracotta)
B(-11,-27,5,minecraft:terracotta)
B(-11,-26,5,minecraft:terracotta)
B(-11,-25,5,minecraft:terracotta)
B(-11,-27,6,minecraft:terracotta)
B(-11,-26,6,minecraft:terracotta)
B(-10,-27,-3,minecraft:terracotta)
B(-10,-26,-3,minecraft:terracotta)
B(-10,-27,-2,minecraft:terracotta)
B(-10,-26,-2,minecraft:terracotta)
B(-10,-25,-2,minecraft:terracotta)
B(-10,-24,-2,minecraft:terracotta)
B(-10,-27,-1,minecraft:terracotta)
B(-10,-26,-1,minecraft:terracotta)
B(-10,-25,-1,minecraft:terracotta)
B(-10,-24,-1,minecraft:terracotta)
B(-10,-23,-1,minecraft:terracotta)
B(-10,-22,-1,minecraft:terracotta)
B(-10,-27,0,minecraft:terracotta)
B(-10,-26,0,minecraft:terracotta)
B(-10,-25,0,minecraft:terracotta)
B(-10,-24,0,minecraft:terracotta)
B(-10,-23,0,minecraft:terracotta)
B(-10,-22,0,minecraft:terracotta)
B(-10,-21,0,minecraft:terracotta)
B(-10,-20,0,minecraft:terracotta)
B(-10,-19,0,minecraft:terracotta)
B(-10,-27,1,minecraft:terracotta)
B(-10,-26,1,minecraft:terracotta)
B(-10,-25,1,minecraft:terracotta)
B(-10,-24,1,minecraft:terracotta)
B(-10,-23,1,minecraft:terracotta)
B(-10,-22,1,minecraft:terracotta)
B(-10,-21,1,minecraft:terracotta)
B(-10,-20,1,minecraft:terracotta)
B(-10,-19,1,minecraft:terracotta)
B(-10,-18,1,minecraft:terracotta)
B(-10,-17,1,minecraft:terracotta)
B(-10,-16,1,minecraft:terracotta)
B(-10,-15,1,minecraft:terracotta)
B(-10,-27,2,minecraft:terracotta)
B(-10,-26,2,minecraft:terracotta)
B(-10,-25,2,minecraft:terracotta)
B(-10,-24,2,minecraft:terracotta)
B(-10,-23,2,minecraft:terracotta)
B(-10,-22,2,minecraft:terracotta)
B(-10,-21,2,minecraft:terracotta)
B(-10,-20,2,minecraft:terracotta)
B(-10,-19,2,minecraft:terracotta)
B(-10,-18,2,minecraft:terracotta)
B(-10,-17,2,minecraft:terracotta)
B(-10,-16,2,minecraft:terracotta)
B(-10,-15,2,minecraft:terracotta)
B(-10,-14,2,minecraft:terracotta)
B(-10,-27,3,minecraft:terracotta)
B(-10,-26,3,minecraft:terracotta)
B(-10,-25,3,minecraft:terracotta)
B(-10,-24,3,minecraft:terracotta)
B(-10,-23,3,minecraft:terracotta)
B(-10,-22,3,minecraft:terracotta)
B(-10,-21,3,minecraft:terracotta)
B(-10,-20,3,minecraft:terracotta)
B(-10,-19,3,minecraft:terracotta)
B(-10,-18,3,minecraft:terracotta)
B(-10,-17,3,minecraft:terracotta)
B(-10,-16,3,minecraft:terracotta)
B(-10,-15,3,minecraft:terracotta)
B(-10,-14,3,minecraft:terracotta)
B(-10,-13,3,minecraft:terracotta)
B(-10,-27,4,minecraft:terracotta)
B(-10,-26,4,minecraft:terracotta)
B(-10,-25,4,minecraft:terracotta)
B(-10,-24,4,minecraft:terracotta)
B(-10,-23,4,minecraft:terracotta)
B(-10,-22,4,minecraft:terracotta)
B(-10,-21,4,minecraft:terracotta)
B(-10,-20,4,minecraft:terracotta)
B(-10,-19,4,minecraft:terracotta)
B(-10,-18,4,minecraft:terracotta)
B(-10,-17,4,minecraft:terracotta)
B(-10,-27,5,minecraft:terracotta)
B(-10,-26,5,minecraft:terracotta)
B(-10,-25,5,minecraft:terracotta)
B(-10,-24,5,minecraft:terracotta)
B(-10,-23,5,minecraft:terracotta)
B(-10,-22,5,minecraft:terracotta)
B(-10,-27,6,minecraft:terracotta)
B(-10,-26,6,minecraft:terracotta)
B(-10,-25,6,minecraft:terracotta)
B(-10,-27,7,minecraft:terracotta)
B(-10,-26,7,minecraft:terracotta)
B(-9,-27,-11,minecraft:terracotta)
B(-9,-26,-11,minecraft:terracotta)
B(-9,-27,-10,minecraft:terracotta)
B(-9,-26,-10,minecraft:terracotta)
B(-9,-27,-6,minecraft:terracotta)
B(-9,-27,-5,minecraft:terracotta)
B(-9,-27,-4,minecraft:terracotta)
B(-9,-26,-4,minecraft:terracotta)
B(-9,-25,-4,minecraft:terracotta)
B(-9,-27,-3,minecraft:terracotta)
B(-9,-26,-3,minecraft:terracotta)
B(-9,-25,-3,minecraft:terracotta)
B(-9,-24,-3,minecraft:terracotta)
B(-9,-23,-3,minecraft:terracotta)
B(-9,-27,-2,minecraft:terracotta)
B(-9,-26,-2,minecraft:terracotta)
B(-9,-25,-2,minecraft:terracotta)
B(-9,-24,-2,minecraft:terracotta)
B(-9,-23,-2,minecraft:terracotta)
B(-9,-22,-2,minecraft:terracotta)
B(-9,-21,-2,minecraft:terracotta)
B(-9,-27,-1,minecraft:terracotta)
B(-9,-26,-1,minecraft:terracotta)
B(-9,-25,-1,minecraft:terracotta)
B(-9,-24,-1,minecraft:terracotta)
B(-9,-23,-1,minecraft:terracotta)
B(-9,-22,-1,minecraft:terracotta)
B(-9,-21,-1,minecraft:terracotta)
B(-9,-20,-1,minecraft:terracotta)
B(-9,-27,0,minecraft:terracotta)
B(-9,-26,0,minecraft:terracotta)
B(-9,-25,0,minecraft:terracotta)
B(-9,-24,0,minecraft:terracotta)
B(-9,-23,0,minecraft:terracotta)
B(-9,-22,0,minecraft:terracotta)
B(-9,-21,0,minecraft:terracotta)
B(-9,-20,0,minecraft:terracotta)
B(-9,-19,0,minecraft:terracotta)
B(-9,-27,1,minecraft:terracotta)
B(-9,-26,1,minecraft:terracotta)
B(-9,-25,1,minecraft:terracotta)
B(-9,-24,1,minecraft:terracotta)
B(-9,-23,1,minecraft:terracotta)
B(-9,-22,1,minecraft:terracotta)
B(-9,-21,1,minecraft:terracotta)
B(-9,-20,1,minecraft:terracotta)
B(-9,-19,1,minecraft:terracotta)
B(-9,-18,1,minecraft:terracotta)
B(-9,-17,1,minecraft:terracotta)
B(-9,-16,1,minecraft:terracotta)
B(-9,-15,1,minecraft:terracotta)
B(-9,-27,2,minecraft:terracotta)
B(-9,-26,2,minecraft:terracotta)
B(-9,-25,2,minecraft:terracotta)
B(-9,-24,2,minecraft:terracotta)
B(-9,-23,2,minecraft:terracotta)
B(-9,-22,2,minecraft:terracotta)
B(-9,-21,2,minecraft:terracotta)
B(-9,-20,2,minecraft:terracotta)
B(-9,-19,2,minecraft:terracotta)
B(-9,-18,2,minecraft:terracotta)
B(-9,-17,2,minecraft:terracotta)
B(-9,-16,2,minecraft:terracotta)
B(-9,-15,2,minecraft:terracotta)
B(-9,-14,2,minecraft:terracotta)
B(-9,-13,2,minecraft:terracotta)
B(-9,-12,2,minecraft:terracotta)
B(-9,-27,3,minecraft:terracotta)
B(-9,-26,3,minecraft:terracotta)
B(-9,-25,3,minecraft:terracotta)
B(-9,-24,3,minecraft:terracotta)
B(-9,-23,3,minecraft:terracotta)
B(-9,-22,3,minecraft:terracotta)
B(-9,-21,3,minecraft:terracotta)
B(-9,-20,3,minecraft:terracotta)
B(-9,-19,3,minecraft:terracotta)
B(-9,-18,3,minecraft:terracotta)
B(-9,-17,3,minecraft:terracotta)
B(-9,-16,3,minecraft:terracotta)
B(-9,-15,3,minecraft:terracotta)
B(-9,-14,3,minecraft:terracotta)
B(-9,-13,3,minecraft:terracotta)
B(-9,-12,3,minecraft:terracotta)
B(-9,-11,3,minecraft:terracotta)
B(-9,-10,3,minecraft:terracotta)
B(-9,-9,3,minecraft:terracotta)
B(-9,-8,3,minecraft:terracotta)
B(-9,-7,3,minecraft:terracotta)
B(-9,-27,4,minecraft:terracotta)
B(-9,-26,4,minecraft:terracotta)
B(-9,-25,4,minecraft:terracotta)
B(-9,-24,4,minecraft:terracotta)
B(-9,-23,4,minecraft:terracotta)
B(-9,-22,4,minecraft:terracotta)
B(-9,-21,4,minecraft:terracotta)
B(-9,-20,4,minecraft:terracotta)
B(-9,-19,4,minecraft:terracotta)
B(-9,-18,4,minecraft:terracotta)
B(-9,-17,4,minecraft:terracotta)
B(-9,-16,4,minecraft:terracotta)
B(-9,-15,4,minecraft:terracotta)
B(-9,-14,4,minecraft:terracotta)
B(-9,-13,4,minecraft:terracotta)
B(-9,-12,4,minecraft:terracotta)
B(-9,-11,4,minecraft:terracotta)
B(-9,-27,5,minecraft:terracotta)
B(-9,-26,5,minecraft:terracotta)
B(-9,-25,5,minecraft:terracotta)
B(-9,-24,5,minecraft:terracotta)
B(-9,-23,5,minecraft:terracotta)
B(-9,-27,6,minecraft:terracotta)
B(-9,-26,6,minecraft:terracotta)
B(-9,-25,6,minecraft:terracotta)
B(-9,-24,6,minecraft:terracotta)
B(-9,-27,7,minecraft:terracotta)
B(-9,-26,7,minecraft:terracotta)
B(-9,-27,8,minecraft:terracotta)
B(-8,-27,-13,minecraft:terracotta)
B(-8,-26,-13,minecraft:terracotta)
B(-8,-27,-12,minecraft:terracotta)
B(-8,-26,-12,minecraft:terracotta)
B(-8,-25,-12,minecraft:terracotta)
B(-8,-27,-11,minecraft:terracotta)
B(-8,-26,-11,minecraft:terracotta)
B(-8,-25,-11,minecraft:terracotta)
B(-8,-24,-11,minecraft:terracotta)
B(-8,-27,-10,minecraft:terracotta)
B(-8,-26,-10,minecraft:terracotta)
B(-8,-25,-10,minecraft:terracotta)
B(-8,-24,-10,minecraft:terracotta)
B(-8,-23,-10,minecraft:terracotta)
B(-8,-22,-10,minecraft:terracotta)
B(-8,-21,-10,minecraft:terracotta)
B(-8,-20,-10,minecraft:terracotta)
B(-8,-19,-10,minecraft:terracotta)
B(-8,-18,-10,minecraft:terracotta)
B(-8,-27,-9,minecraft:terracotta)
B(-8,-26,-9,minecraft:terracotta)
B(-8,-25,-9,minecraft:terracotta)
B(-8,-24,-9,minecraft:terracotta)
B(-8,-23,-9,minecraft:terracotta)
B(-8,-22,-9,minecraft:terracotta)
B(-8,-27,-8,minecraft:terracotta)
B(-8,-26,-8,minecraft:terracotta)
B(-8,-25,-8,minecraft:terracotta)
B(-8,-27,-7,minecraft:terracotta)
B(-8,-26,-7,minecraft:terracotta)
B(-8,-25,-7,minecraft:terracotta)
B(-8,-24,-7,minecraft:terracotta)
B(-8,-23,-7,minecraft:terracotta)
B(-8,-22,-7,minecraft:terracotta)
B(-8,-27,-6,minecraft:terracotta)
B(-8,-26,-6,minecraft:terracotta)
B(-8,-25,-6,minecraft:terracotta)
B(-8,-24,-6,minecraft:terracotta)
B(-8,-23,-6,minecraft:terracotta)
B(-8,-22,-6,minecraft:terracotta)
B(-8,-27,-5,minecraft:terracotta)
B(-8,-26,-5,minecraft:terracotta)
B(-8,-25,-5,minecraft:terracotta)
B(-8,-24,-5,minecraft:terracotta)
B(-8,-23,-5,minecraft:terracotta)
B(-8,-27,-4,minecraft:terracotta)
B(-8,-26,-4,minecraft:terracotta)
B(-8,-25,-4,minecraft:terracotta)
B(-8,-24,-4,minecraft:terracotta)
B(-8,-23,-4,minecraft:terracotta)
B(-8,-22,-4,minecraft:terracotta)
B(-8,-27,-3,minecraft:terracotta)
B(-8,-26,-3,minecraft:terracotta)
B(-8,-25,-3,minecraft:terracotta)
B(-8,-24,-3,minecraft:terracotta)
B(-8,-23,-3,minecraft:terracotta)
B(-8,-22,-3,minecraft:terracotta)
B(-8,-21,-3,minecraft:terracotta)
B(-8,-20,-3,minecraft:terracotta)
B(-8,-19,-3,minecraft:terracotta)
B(-8,-18,-3,minecraft:terracotta)
B(-8,-27,-2,minecraft:terracotta)
B(-8,-26,-2,minecraft:terracotta)
B(-8,-25,-2,minecraft:terracotta)
B(-8,-24,-2,minecraft:terracotta)
B(-8,-23,-2,minecraft:terracotta)
B(-8,-22,-2,minecraft:terracotta)
B(-8,-21,-2,minecraft:terracotta)
B(-8,-20,-2,minecraft:terracotta)
B(-8,-19,-2,minecraft:terracotta)
B(-8,-18,-2,minecraft:terracotta)
B(-8,-17,-2,minecraft:terracotta)
B(-8,-16,-2,minecraft:terracotta)
B(-8,-15,-2,minecraft:terracotta)
B(-8,-14,-2,minecraft:terracotta)
B(-8,-13,-2,minecraft:terracotta)
B(-8,-12,-2,minecraft:terracotta)
B(-8,-11,-2,minecraft:terracotta)
B(-8,-10,-2,minecraft:terracotta)
B(-8,-27,-1,minecraft:terracotta)
B(-8,-26,-1,minecraft:terracotta)
B(-8,-25,-1,minecraft:terracotta)
B(-8,-24,-1,minecraft:terracotta)
B(-8,-23,-1,minecraft:terracotta)
B(-8,-22,-1,minecraft:terracotta)
B(-8,-21,-1,minecraft:terracotta)
B(-8,-20,-1,minecraft:terracotta)
B(-8,-19,-1,minecraft:terracotta)
B(-8,-18,-1,minecraft:terracotta)
B(-8,-17,-1,minecraft:terracotta)
B(-8,-16,-1,minecraft:terracotta)
B(-8,-15,-1,minecraft:terracotta)
B(-8,-14,-1,minecraft:terracotta)
B(-8,-13,-1,minecraft:terracotta)
B(-8,-12,-1,minecraft:terracotta)
B(-8,-11,-1,minecraft:terracotta)
B(-8,-10,-1,minecraft:terracotta)
B(-8,-27,0,minecraft:terracotta)
B(-8,-26,0,minecraft:terracotta)
B(-8,-25,0,minecraft:terracotta)
B(-8,-24,0,minecraft:terracotta)
B(-8,-23,0,minecraft:terracotta)
B(-8,-22,0,minecraft:terracotta)
B(-8,-21,0,minecraft:terracotta)
B(-8,-20,0,minecraft:terracotta)
B(-8,-19,0,minecraft:terracotta)
B(-8,-18,0,minecraft:terracotta)
B(-8,-17,0,minecraft:terracotta)
B(-8,-16,0,minecraft:terracotta)
B(-8,-15,0,minecraft:terracotta)
B(-8,-14,0,minecraft:terracotta)
B(-8,-13,0,minecraft:terracotta)
B(-8,-12,0,minecraft:terracotta)
B(-8,-11,0,minecraft:terracotta)
B(-8,-10,0,minecraft:terracotta)
B(-8,-9,0,minecraft:terracotta)
B(-8,-27,1,minecraft:terracotta)
B(-8,-26,1,minecraft:terracotta)
B(-8,-25,1,minecraft:terracotta)
B(-8,-24,1,minecraft:terracotta)
B(-8,-23,1,minecraft:terracotta)
B(-8,-22,1,minecraft:terracotta)
B(-8,-21,1,minecraft:terracotta)
B(-8,-20,1,minecraft:terracotta)
B(-8,-19,1,minecraft:terracotta)
B(-8,-18,1,minecraft:terracotta)
B(-8,-17,1,minecraft:terracotta)
B(-8,-16,1,minecraft:terracotta)
B(-8,-15,1,minecraft:terracotta)
B(-8,-14,1,minecraft:terracotta)
B(-8,-13,1,minecraft:terracotta)
B(-8,-12,1,minecraft:terracotta)
B(-8,-11,1,minecraft:terracotta)
B(-8,-10,1,minecraft:terracotta)
B(-8,-9,1,minecraft:terracotta)
B(-8,-27,2,minecraft:terracotta)
B(-8,-26,2,minecraft:terracotta)
B(-8,-25,2,minecraft:terracotta)
B(-8,-24,2,minecraft:terracotta)
B(-8,-23,2,minecraft:terracotta)
B(-8,-22,2,minecraft:terracotta)
B(-8,-21,2,minecraft:terracotta)
B(-8,-20,2,minecraft:terracotta)
B(-8,-19,2,minecraft:terracotta)
B(-8,-18,2,minecraft:terracotta)
B(-8,-17,2,minecraft:terracotta)
B(-8,-16,2,minecraft:terracotta)
B(-8,-15,2,minecraft:terracotta)
B(-8,-14,2,minecraft:terracotta)
B(-8,-13,2,minecraft:terracotta)
B(-8,-12,2,minecraft:terracotta)
B(-8,-11,2,minecraft:terracotta)
B(-8,-10,2,minecraft:terracotta)
B(-8,-9,2,minecraft:terracotta)
B(-8,-8,2,minecraft:terracotta)
B(-8,-7,2,minecraft:terracotta)
B(-8,-6,2,minecraft:terracotta)
B(-8,-5,2,minecraft:terracotta)
B(-8,-27,3,minecraft:terracotta)
B(-8,-26,3,minecraft:terracotta)
B(-8,-25,3,minecraft:terracotta)
B(-8,-24,3,minecraft:terracotta)
B(-8,-23,3,minecraft:terracotta)
B(-8,-22,3,minecraft:terracotta)
B(-8,-21,3,minecraft:terracotta)
B(-8,-20,3,minecraft:terracotta)
B(-8,-19,3,minecraft:terracotta)
B(-8,-18,3,minecraft:terracotta)
B(-8,-17,3,minecraft:terracotta)
B(-8,-16,3,minecraft:terracotta)
B(-8,-15,3,minecraft:terracotta)
B(-8,-14,3,minecraft:terracotta)
B(-8,-13,3,minecraft:terracotta)
B(-8,-12,3,minecraft:terracotta)
B(-8,-11,3,minecraft:terracotta)
B(-8,-10,3,minecraft:terracotta)
B(-8,-9,3,minecraft:terracotta)
B(-8,-8,3,minecraft:terracotta)
B(-8,-7,3,minecraft:terracotta)
B(-8,-6,3,minecraft:terracotta)
B(-8,-27,4,minecraft:terracotta)
B(-8,-26,4,minecraft:terracotta)
B(-8,-25,4,minecraft:terracotta)
B(-8,-24,4,minecraft:terracotta)
B(-8,-23,4,minecraft:terracotta)
B(-8,-22,4,minecraft:terracotta)
B(-8,-21,4,minecraft:terracotta)
B(-8,-20,4,minecraft:terracotta)
B(-8,-19,4,minecraft:terracotta)
B(-8,-18,4,minecraft:terracotta)
B(-8,-17,4,minecraft:terracotta)
B(-8,-16,4,minecraft:terracotta)
B(-8,-15,4,minecraft:terracotta)
B(-8,-14,4,minecraft:terracotta)
B(-8,-13,4,minecraft:terracotta)
B(-8,-12,4,minecraft:terracotta)
B(-8,-11,4,minecraft:terracotta)
B(-8,-10,4,minecraft:terracotta)
B(-8,-9,4,minecraft:terracotta)
B(-8,-8,4,minecraft:terracotta)
B(-8,-27,5,minecraft:terracotta)
B(-8,-26,5,minecraft:terracotta)
B(-8,-25,5,minecraft:terracotta)
B(-8,-24,5,minecraft:terracotta)
B(-8,-23,5,minecraft:terracotta)
B(-8,-22,5,minecraft:terracotta)
B(-8,-21,5,minecraft:terracotta)
B(-8,-20,5,minecraft:terracotta)
B(-8,-27,6,minecraft:terracotta)
B(-8,-26,6,minecraft:terracotta)
B(-8,-25,6,minecraft:terracotta)
B(-8,-24,6,minecraft:terracotta)
B(-8,-27,7,minecraft:terracotta)
B(-8,-26,7,minecraft:terracotta)
B(-8,-27,8,minecraft:terracotta)
B(-8,-26,8,minecraft:terracotta)
B(-8,-27,9,minecraft:terracotta)
B(-8,-27,10,minecraft:terracotta)
B(-7,-27,-15,minecraft:terracotta)
B(-7,-27,-14,minecraft:terracotta)
B(-7,-26,-14,minecraft:terracotta)
B(-7,-25,-14,minecraft:terracotta)
B(-7,-27,-13,minecraft:terracotta)
B(-7,-26,-13,minecraft:terracotta)
B(-7,-25,-13,minecraft:terracotta)
B(-7,-24,-13,minecraft:terracotta)
B(-7,-27,-12,minecraft:terracotta)
B(-7,-26,-12,minecraft:terracotta)
B(-7,-25,-12,minecraft:terracotta)
B(-7,-24,-12,minecraft:terracotta)
B(-7,-23,-12,minecraft:terracotta)
B(-7,-27,-11,minecraft:terracotta)
B(-7,-26,-11,minecraft:terracotta)
B(-7,-25,-11,minecraft:terracotta)
B(-7,-24,-11,minecraft:terracotta)
B(-7,-23,-11,minecraft:terracotta)
B(-7,-22,-11,minecraft:terracotta)
B(-7,-21,-11,minecraft:terracotta)
B(-7,-20,-11,minecraft:terracotta)
B(-7,-19,-11,minecraft:terracotta)
B(-7,-27,-10,minecraft:terracotta)
B(-7,-26,-10,minecraft:terracotta)
B(-7,-25,-10,minecraft:terracotta)
B(-7,-24,-10,minecraft:terracotta)
B(-7,-23,-10,minecraft:terracotta)
B(-7,-22,-10,minecraft:terracotta)
B(-7,-21,-10,minecraft:terracotta)
B(-7,-20,-10,minecraft:terracotta)
B(-7,-19,-10,minecraft:terracotta)
B(-7,-18,-10,minecraft:terracotta)
B(-7,-17,-10,minecraft:terracotta)
B(-7,-16,-10,minecraft:terracotta)
B(-7,-15,-10,minecraft:terracotta)
B(-7,-27,-9,minecraft:terracotta)
B(-7,-26,-9,minecraft:terracotta)
B(-7,-25,-9,minecraft:terracotta)
B(-7,-24,-9,minecraft:terracotta)
B(-7,-23,-9,minecraft:terracotta)
B(-7,-22,-9,minecraft:terracotta)
B(-7,-21,-9,minecraft:terracotta)
B(-7,-20,-9,minecraft:terracotta)
B(-7,-19,-9,minecraft:terracotta)
B(-7,-18,-9,minecraft:terracotta)
B(-7,-17,-9,minecraft:terracotta)
B(-7,-16,-9,minecraft:terracotta)
B(-7,-15,-9,minecraft:terracotta)
B(-7,-27,-8,minecraft:terracotta)
B(-7,-26,-8,minecraft:terracotta)
B(-7,-25,-8,minecraft:terracotta)
B(-7,-24,-8,minecraft:terracotta)
B(-7,-23,-8,minecraft:terracotta)
B(-7,-22,-8,minecraft:terracotta)
B(-7,-21,-8,minecraft:terracotta)
B(-7,-20,-8,minecraft:terracotta)
B(-7,-19,-8,minecraft:terracotta)
B(-7,-18,-8,minecraft:terracotta)
B(-7,-17,-8,minecraft:terracotta)
B(-7,-16,-8,minecraft:terracotta)
B(-7,-15,-8,minecraft:terracotta)
B(-7,-27,-7,minecraft:terracotta)
B(-7,-26,-7,minecraft:terracotta)
B(-7,-25,-7,minecraft:terracotta)
B(-7,-24,-7,minecraft:terracotta)
B(-7,-23,-7,minecraft:terracotta)
B(-7,-22,-7,minecraft:terracotta)
B(-7,-21,-7,minecraft:terracotta)
B(-7,-20,-7,minecraft:terracotta)
B(-7,-19,-7,minecraft:terracotta)
B(-7,-18,-7,minecraft:terracotta)
B(-7,-17,-7,minecraft:terracotta)
B(-7,-16,-7,minecraft:terracotta)
B(-7,-15,-7,minecraft:terracotta)
B(-7,-14,-7,minecraft:terracotta)
B(-7,-27,-6,minecraft:terracotta)
B(-7,-26,-6,minecraft:terracotta)
B(-7,-25,-6,minecraft:terracotta)
B(-7,-24,-6,minecraft:terracotta)
B(-7,-23,-6,minecraft:terracotta)
B(-7,-22,-6,minecraft:terracotta)
B(-7,-21,-6,minecraft:terracotta)
B(-7,-20,-6,minecraft:terracotta)
B(-7,-19,-6,minecraft:terracotta)
B(-7,-18,-6,minecraft:terracotta)
B(-7,-17,-6,minecraft:terracotta)
B(-7,-16,-6,minecraft:terracotta)
B(-7,-15,-6,minecraft:terracotta)
B(-7,-14,-6,minecraft:terracotta)
B(-7,-27,-5,minecraft:terracotta)
B(-7,-26,-5,minecraft:terracotta)
B(-7,-25,-5,minecraft:terracotta)
B(-7,-24,-5,minecraft:terracotta)
B(-7,-23,-5,minecraft:terracotta)
B(-7,-22,-5,minecraft:terracotta)
B(-7,-21,-5,minecraft:terracotta)
B(-7,-20,-5,minecraft:terracotta)
B(-7,-19,-5,minecraft:terracotta)
B(-7,-18,-5,minecraft:terracotta)
B(-7,-17,-5,minecraft:terracotta)
B(-7,-16,-5,minecraft:terracotta)
B(-7,-27,-4,minecraft:terracotta)
B(-7,-26,-4,minecraft:terracotta)
B(-7,-25,-4,minecraft:terracotta)
B(-7,-24,-4,minecraft:terracotta)
B(-7,-23,-4,minecraft:terracotta)
B(-7,-22,-4,minecraft:terracotta)
B(-7,-21,-4,minecraft:terracotta)
B(-7,-20,-4,minecraft:terracotta)
B(-7,-27,-3,minecraft:terracotta)
B(-7,-26,-3,minecraft:terracotta)
B(-7,-25,-3,minecraft:terracotta)
B(-7,-24,-3,minecraft:terracotta)
B(-7,-23,-3,minecraft:terracotta)
B(-7,-22,-3,minecraft:terracotta)
B(-7,-21,-3,minecraft:terracotta)
B(-7,-20,-3,minecraft:terracotta)
B(-7,-19,-3,minecraft:terracotta)
B(-7,-18,-3,minecraft:terracotta)
B(-7,-17,-3,minecraft:terracotta)
B(-7,-16,-3,minecraft:terracotta)
B(-7,-15,-3,minecraft:terracotta)
B(-7,-14,-3,minecraft:terracotta)
B(-7,-13,-3,minecraft:terracotta)
B(-7,-27,-2,minecraft:terracotta)
B(-7,-26,-2,minecraft:terracotta)
B(-7,-25,-2,minecraft:terracotta)
B(-7,-24,-2,minecraft:terracotta)
B(-7,-23,-2,minecraft:terracotta)
B(-7,-22,-2,minecraft:terracotta)
B(-7,-21,-2,minecraft:terracotta)
B(-7,-20,-2,minecraft:terracotta)
B(-7,-19,-2,minecraft:terracotta)
B(-7,-18,-2,minecraft:terracotta)
B(-7,-17,-2,minecraft:terracotta)
B(-7,-16,-2,minecraft:terracotta)
B(-7,-15,-2,minecraft:terracotta)
B(-7,-14,-2,minecraft:terracotta)
B(-7,-13,-2,minecraft:terracotta)
B(-7,-12,-2,minecraft:terracotta)
B(-7,-11,-2,minecraft:terracotta)
B(-7,-10,-2,minecraft:terracotta)
B(-7,-9,-2,minecraft:terracotta)
B(-7,-8,-2,minecraft:terracotta)
B(-7,-7,-2,minecraft:terracotta)
B(-7,-6,-2,minecraft:terracotta)
B(-7,-27,-1,minecraft:terracotta)
B(-7,-26,-1,minecraft:terracotta)
B(-7,-25,-1,minecraft:terracotta)
B(-7,-24,-1,minecraft:terracotta)
B(-7,-23,-1,minecraft:terracotta)
B(-7,-22,-1,minecraft:terracotta)
B(-7,-21,-1,minecraft:terracotta)
B(-7,-20,-1,minecraft:terracotta)
B(-7,-19,-1,minecraft:terracotta)
B(-7,-18,-1,minecraft:terracotta)
B(-7,-17,-1,minecraft:terracotta)
B(-7,-16,-1,minecraft:terracotta)
B(-7,-15,-1,minecraft:terracotta)
B(-7,-14,-1,minecraft:terracotta)
B(-7,-13,-1,minecraft:terracotta)
B(-7,-12,-1,minecraft:terracotta)
B(-7,-11,-1,minecraft:terracotta)
B(-7,-10,-1,minecraft:terracotta)
B(-7,-9,-1,minecraft:terracotta)
B(-7,-8,-1,minecraft:terracotta)
B(-7,-7,-1,minecraft:terracotta)
B(-7,-6,-1,minecraft:terracotta)
B(-7,-5,-1,minecraft:terracotta)
B(-7,-4,-1,minecraft:terracotta)
B(-7,-3,-1,minecraft:terracotta)
B(-7,-2,-1,minecraft:terracotta)
B(-7,-1,-1,minecraft:terracotta)
B(-7,-27,0,minecraft:terracotta)
B(-7,-26,0,minecraft:terracotta)
B(-7,-25,0,minecraft:terracotta)
B(-7,-24,0,minecraft:terracotta)
B(-7,-23,0,minecraft:terracotta)
B(-7,-22,0,minecraft:terracotta)
B(-7,-21,0,minecraft:terracotta)
B(-7,-20,0,minecraft:terracotta)
B(-7,-19,0,minecraft:terracotta)
B(-7,-18,0,minecraft:terracotta)
B(-7,-17,0,minecraft:terracotta)
B(-7,-16,0,minecraft:terracotta)
B(-7,-15,0,minecraft:terracotta)
B(-7,-14,0,minecraft:terracotta)
B(-7,-13,0,minecraft:terracotta)
B(-7,-12,0,minecraft:terracotta)
B(-7,-11,0,minecraft:terracotta)
B(-7,-10,0,minecraft:terracotta)
B(-7,-9,0,minecraft:terracotta)
B(-7,-8,0,minecraft:terracotta)
B(-7,-7,0,minecraft:terracotta)
B(-7,-6,0,minecraft:terracotta)
B(-7,-5,0,minecraft:terracotta)
B(-7,-4,0,minecraft:terracotta)
B(-7,-3,0,minecraft:terracotta)
B(-7,-2,0,minecraft:coarse_dirt)
B(-7,-27,1,minecraft:terracotta)
B(-7,-26,1,minecraft:terracotta)
B(-7,-25,1,minecraft:terracotta)
B(-7,-24,1,minecraft:terracotta)
B(-7,-23,1,minecraft:terracotta)
B(-7,-22,1,minecraft:terracotta)
B(-7,-21,1,minecraft:terracotta)
B(-7,-20,1,minecraft:terracotta)
B(-7,-19,1,minecraft:terracotta)
B(-7,-18,1,minecraft:terracotta)
B(-7,-17,1,minecraft:terracotta)
B(-7,-16,1,minecraft:terracotta)
B(-7,-15,1,minecraft:terracotta)
B(-7,-14,1,minecraft:terracotta)
B(-7,-13,1,minecraft:terracotta)
B(-7,-12,1,minecraft:terracotta)
B(-7,-11,1,minecraft:terracotta)
B(-7,-10,1,minecraft:terracotta)
B(-7,-9,1,minecraft:terracotta)
B(-7,-8,1,minecraft:terracotta)
B(-7,-7,1,minecraft:terracotta)
B(-7,-6,1,minecraft:terracotta)
B(-7,-5,1,minecraft:terracotta)
B(-7,-4,1,minecraft:terracotta)
B(-7,-3,1,minecraft:terracotta)
B(-7,-27,2,minecraft:terracotta)
B(-7,-26,2,minecraft:terracotta)
B(-7,-25,2,minecraft:terracotta)
B(-7,-24,2,minecraft:terracotta)
B(-7,-23,2,minecraft:terracotta)
B(-7,-22,2,minecraft:terracotta)
B(-7,-21,2,minecraft:terracotta)
B(-7,-20,2,minecraft:terracotta)
B(-7,-19,2,minecraft:terracotta)
B(-7,-18,2,minecraft:terracotta)
B(-7,-17,2,minecraft:terracotta)
B(-7,-16,2,minecraft:terracotta)
B(-7,-15,2,minecraft:terracotta)
B(-7,-14,2,minecraft:terracotta)
B(-7,-13,2,minecraft:terracotta)
B(-7,-12,2,minecraft:terracotta)
B(-7,-11,2,minecraft:terracotta)
B(-7,-10,2,minecraft:terracotta)
B(-7,-9,2,minecraft:terracotta)
B(-7,-8,2,minecraft:terracotta)
B(-7,-7,2,minecraft:terracotta)
B(-7,-6,2,minecraft:terracotta)
B(-7,-5,2,minecraft:terracotta)
B(-7,-4,2,minecraft:terracotta)
B(-7,-27,3,minecraft:terracotta)
B(-7,-26,3,minecraft:terracotta)
B(-7,-25,3,minecraft:terracotta)
B(-7,-24,3,minecraft:terracotta)
B(-7,-23,3,minecraft:terracotta)
B(-7,-22,3,minecraft:terracotta)
B(-7,-21,3,minecraft:terracotta)
B(-7,-20,3,minecraft:terracotta)
B(-7,-19,3,minecraft:terracotta)
B(-7,-18,3,minecraft:terracotta)
B(-7,-17,3,minecraft:terracotta)
B(-7,-16,3,minecraft:terracotta)
B(-7,-15,3,minecraft:terracotta)
B(-7,-14,3,minecraft:terracotta)
B(-7,-13,3,minecraft:terracotta)
B(-7,-12,3,minecraft:terracotta)
B(-7,-11,3,minecraft:terracotta)
B(-7,-10,3,minecraft:terracotta)
B(-7,-9,3,minecraft:terracotta)
B(-7,-8,3,minecraft:terracotta)
B(-7,-7,3,minecraft:terracotta)
B(-7,-6,3,minecraft:terracotta)
B(-7,-5,3,minecraft:terracotta)
B(-7,-27,4,minecraft:terracotta)
B(-7,-26,4,minecraft:terracotta)
B(-7,-25,4,minecraft:terracotta)
B(-7,-24,4,minecraft:terracotta)
B(-7,-23,4,minecraft:terracotta)
B(-7,-22,4,minecraft:terracotta)
B(-7,-21,4,minecraft:terracotta)
B(-7,-20,4,minecraft:terracotta)
B(-7,-19,4,minecraft:terracotta)
B(-7,-18,4,minecraft:terracotta)
B(-7,-17,4,minecraft:terracotta)
B(-7,-16,4,minecraft:terracotta)
B(-7,-15,4,minecraft:terracotta)
B(-7,-14,4,minecraft:terracotta)
B(-7,-27,5,minecraft:terracotta)
B(-7,-26,5,minecraft:terracotta)
B(-7,-25,5,minecraft:terracotta)
B(-7,-24,5,minecraft:terracotta)
B(-7,-23,5,minecraft:terracotta)
B(-7,-27,6,minecraft:terracotta)
B(-7,-26,6,minecraft:terracotta)
B(-7,-25,6,minecraft:terracotta)
B(-7,-24,6,minecraft:terracotta)
B(-7,-23,6,minecraft:terracotta)
B(-7,-27,7,minecraft:terracotta)
B(-7,-26,7,minecraft:terracotta)
B(-7,-25,7,minecraft:terracotta)
B(-7,-24,7,minecraft:terracotta)
B(-7,-27,8,minecraft:terracotta)
B(-7,-26,8,minecraft:terracotta)
B(-7,-25,8,minecraft:terracotta)
B(-7,-27,9,minecraft:terracotta)
B(-7,-26,9,minecraft:terracotta)
B(-7,-27,10,minecraft:terracotta)
B(-7,-26,10,minecraft:terracotta)
B(-7,-27,11,minecraft:terracotta)
B(-6,-27,-15,minecraft:terracotta)
B(-6,-26,-15,minecraft:terracotta)
B(-6,-27,-14,minecraft:terracotta)
B(-6,-26,-14,minecraft:terracotta)
B(-6,-25,-14,minecraft:terracotta)
B(-6,-24,-14,minecraft:terracotta)
B(-6,-27,-13,minecraft:terracotta)
B(-6,-26,-13,minecraft:terracotta)
B(-6,-25,-13,minecraft:terracotta)
B(-6,-24,-13,minecraft:terracotta)
B(-6,-23,-13,minecraft:terracotta)
B(-6,-22,-13,minecraft:terracotta)
B(-6,-27,-12,minecraft:terracotta)
B(-6,-26,-12,minecraft:terracotta)
B(-6,-25,-12,minecraft:terracotta)
B(-6,-24,-12,minecraft:terracotta)
B(-6,-23,-12,minecraft:terracotta)
B(-6,-22,-12,minecraft:terracotta)
B(-6,-21,-12,minecraft:terracotta)
B(-6,-20,-12,minecraft:terracotta)
B(-6,-19,-12,minecraft:terracotta)
B(-6,-18,-12,minecraft:terracotta)
B(-6,-27,-11,minecraft:terracotta)
B(-6,-26,-11,minecraft:terracotta)
B(-6,-25,-11,minecraft:terracotta)
B(-6,-24,-11,minecraft:terracotta)
B(-6,-23,-11,minecraft:terracotta)
B(-6,-22,-11,minecraft:terracotta)
B(-6,-21,-11,minecraft:terracotta)
B(-6,-20,-11,minecraft:terracotta)
B(-6,-19,-11,minecraft:terracotta)
B(-6,-18,-11,minecraft:terracotta)
B(-6,-17,-11,minecraft:terracotta)
B(-6,-16,-11,minecraft:terracotta)
B(-6,-15,-11,minecraft:terracotta)
B(-6,-27,-10,minecraft:terracotta)
B(-6,-26,-10,minecraft:terracotta)
B(-6,-25,-10,minecraft:terracotta)
B(-6,-24,-10,minecraft:terracotta)
B(-6,-23,-10,minecraft:terracotta)
B(-6,-22,-10,minecraft:terracotta)
B(-6,-21,-10,minecraft:terracotta)
B(-6,-20,-10,minecraft:terracotta)
B(-6,-19,-10,minecraft:terracotta)
B(-6,-18,-10,minecraft:terracotta)
B(-6,-17,-10,minecraft:terracotta)
B(-6,-16,-10,minecraft:terracotta)
B(-6,-15,-10,minecraft:terracotta)
B(-6,-14,-10,minecraft:terracotta)
B(-6,-27,-9,minecraft:terracotta)
B(-6,-26,-9,minecraft:terracotta)
B(-6,-25,-9,minecraft:terracotta)
B(-6,-24,-9,minecraft:terracotta)
B(-6,-23,-9,minecraft:terracotta)
B(-6,-22,-9,minecraft:terracotta)
B(-6,-21,-9,minecraft:terracotta)
B(-6,-20,-9,minecraft:terracotta)
B(-6,-19,-9,minecraft:terracotta)
B(-6,-18,-9,minecraft:terracotta)
B(-6,-17,-9,minecraft:terracotta)
B(-6,-16,-9,minecraft:terracotta)
B(-6,-15,-9,minecraft:terracotta)
B(-6,-14,-9,minecraft:terracotta)
B(-6,-27,-8,minecraft:terracotta)
B(-6,-26,-8,minecraft:terracotta)
B(-6,-25,-8,minecraft:terracotta)
B(-6,-24,-8,minecraft:terracotta)
B(-6,-23,-8,minecraft:terracotta)
B(-6,-22,-8,minecraft:terracotta)
B(-6,-21,-8,minecraft:terracotta)
B(-6,-20,-8,minecraft:terracotta)
B(-6,-19,-8,minecraft:terracotta)
B(-6,-18,-8,minecraft:terracotta)
B(-6,-17,-8,minecraft:terracotta)
B(-6,-16,-8,minecraft:terracotta)
B(-6,-15,-8,minecraft:terracotta)
B(-6,-14,-8,minecraft:terracotta)
B(-6,-27,-7,minecraft:terracotta)
B(-6,-26,-7,minecraft:terracotta)
B(-6,-25,-7,minecraft:terracotta)
B(-6,-24,-7,minecraft:terracotta)
B(-6,-23,-7,minecraft:terracotta)
B(-6,-22,-7,minecraft:terracotta)
B(-6,-21,-7,minecraft:terracotta)
B(-6,-20,-7,minecraft:terracotta)
B(-6,-19,-7,minecraft:terracotta)
B(-6,-18,-7,minecraft:terracotta)
B(-6,-17,-7,minecraft:terracotta)
B(-6,-16,-7,minecraft:terracotta)
B(-6,-15,-7,minecraft:terracotta)
B(-6,-14,-7,minecraft:terracotta)
B(-6,-13,-7,minecraft:terracotta)
B(-6,-27,-6,minecraft:terracotta)
B(-6,-26,-6,minecraft:terracotta)
B(-6,-25,-6,minecraft:terracotta)
B(-6,-24,-6,minecraft:terracotta)
B(-6,-23,-6,minecraft:terracotta)
B(-6,-22,-6,minecraft:terracotta)
B(-6,-21,-6,minecraft:terracotta)
B(-6,-20,-6,minecraft:terracotta)
B(-6,-19,-6,minecraft:terracotta)
B(-6,-18,-6,minecraft:terracotta)
B(-6,-17,-6,minecraft:terracotta)
B(-6,-16,-6,minecraft:terracotta)
B(-6,-15,-6,minecraft:terracotta)
B(-6,-14,-6,minecraft:terracotta)
B(-6,-13,-6,minecraft:terracotta)
B(-6,-12,-6,minecraft:terracotta)
B(-6,-11,-6,minecraft:terracotta)
B(-6,-10,-6,minecraft:terracotta)
B(-6,-9,-6,minecraft:terracotta)
B(-6,-8,-6,minecraft:terracotta)
B(-6,-7,-6,minecraft:terracotta)
B(-6,-6,-6,minecraft:terracotta)
B(-6,-27,-5,minecraft:terracotta)
B(-6,-26,-5,minecraft:terracotta)
B(-6,-25,-5,minecraft:terracotta)
B(-6,-24,-5,minecraft:terracotta)
B(-6,-23,-5,minecraft:terracotta)
B(-6,-22,-5,minecraft:terracotta)
B(-6,-21,-5,minecraft:terracotta)
B(-6,-20,-5,minecraft:terracotta)
B(-6,-19,-5,minecraft:terracotta)
B(-6,-18,-5,minecraft:terracotta)
B(-6,-17,-5,minecraft:terracotta)
B(-6,-16,-5,minecraft:terracotta)
B(-6,-15,-5,minecraft:terracotta)
B(-6,-14,-5,minecraft:terracotta)
B(-6,-13,-5,minecraft:terracotta)
B(-6,-27,-4,minecraft:terracotta)
B(-6,-26,-4,minecraft:terracotta)
B(-6,-25,-4,minecraft:terracotta)
B(-6,-24,-4,minecraft:terracotta)
B(-6,-23,-4,minecraft:terracotta)
B(-6,-22,-4,minecraft:terracotta)
B(-6,-21,-4,minecraft:terracotta)
B(-6,-20,-4,minecraft:terracotta)
B(-6,-19,-4,minecraft:terracotta)
B(-6,-18,-4,minecraft:terracotta)
B(-6,-17,-4,minecraft:terracotta)
B(-6,-16,-4,minecraft:terracotta)
B(-6,-15,-4,minecraft:terracotta)
B(-6,-27,-3,minecraft:terracotta)
B(-6,-26,-3,minecraft:terracotta)
B(-6,-25,-3,minecraft:terracotta)
B(-6,-24,-3,minecraft:terracotta)
B(-6,-23,-3,minecraft:terracotta)
B(-6,-22,-3,minecraft:terracotta)
B(-6,-21,-3,minecraft:terracotta)
B(-6,-20,-3,minecraft:terracotta)
B(-6,-19,-3,minecraft:terracotta)
B(-6,-18,-3,minecraft:terracotta)
B(-6,-17,-3,minecraft:terracotta)
B(-6,-16,-3,minecraft:terracotta)
B(-6,-15,-3,minecraft:terracotta)
B(-6,-14,-3,minecraft:terracotta)
B(-6,-13,-3,minecraft:terracotta)
B(-6,-12,-3,minecraft:terracotta)
B(-6,-11,-3,minecraft:terracotta)
B(-6,-10,-3,minecraft:terracotta)
B(-6,-27,-2,minecraft:terracotta)
B(-6,-26,-2,minecraft:terracotta)
B(-6,-25,-2,minecraft:terracotta)
B(-6,-24,-2,minecraft:terracotta)
B(-6,-23,-2,minecraft:terracotta)
B(-6,-22,-2,minecraft:terracotta)
B(-6,-21,-2,minecraft:terracotta)
B(-6,-20,-2,minecraft:terracotta)
B(-6,-19,-2,minecraft:terracotta)
B(-6,-18,-2,minecraft:terracotta)
B(-6,-17,-2,minecraft:terracotta)
B(-6,-16,-2,minecraft:terracotta)
B(-6,-15,-2,minecraft:terracotta)
B(-6,-14,-2,minecraft:terracotta)
B(-6,-13,-2,minecraft:terracotta)
B(-6,-12,-2,minecraft:terracotta)
B(-6,-11,-2,minecraft:terracotta)
B(-6,-10,-2,minecraft:terracotta)
B(-6,-9,-2,minecraft:terracotta)
B(-6,-8,-2,minecraft:terracotta)
B(-6,-7,-2,minecraft:terracotta)
B(-6,-6,-2,minecraft:terracotta)
B(-6,-5,-2,minecraft:terracotta)
B(-6,-4,-2,minecraft:terracotta)
B(-6,-3,-2,minecraft:terracotta)
B(-6,-2,-2,minecraft:terracotta)
B(-6,-1,-2,minecraft:terracotta)
B(-6,0,-2,minecraft:coarse_dirt)
B(-6,-27,-1,minecraft:terracotta)
B(-6,-26,-1,minecraft:terracotta)
B(-6,-25,-1,minecraft:terracotta)
B(-6,-24,-1,minecraft:terracotta)
B(-6,-23,-1,minecraft:terracotta)
B(-6,-22,-1,minecraft:terracotta)
B(-6,-21,-1,minecraft:terracotta)
B(-6,-20,-1,minecraft:terracotta)
B(-6,-19,-1,minecraft:terracotta)
B(-6,-18,-1,minecraft:terracotta)
B(-6,-17,-1,minecraft:terracotta)
B(-6,-16,-1,minecraft:terracotta)
B(-6,-15,-1,minecraft:terracotta)
B(-6,-14,-1,minecraft:terracotta)
B(-6,-13,-1,minecraft:terracotta)
B(-6,-12,-1,minecraft:terracotta)
B(-6,-11,-1,minecraft:terracotta)
B(-6,-10,-1,minecraft:terracotta)
B(-6,-9,-1,minecraft:terracotta)
B(-6,-8,-1,minecraft:terracotta)
B(-6,-7,-1,minecraft:terracotta)
B(-6,-6,-1,minecraft:terracotta)
B(-6,-5,-1,minecraft:terracotta)
B(-6,-4,-1,minecraft:terracotta)
B(-6,-3,-1,minecraft:terracotta)
B(-6,-2,-1,minecraft:terracotta)
B(-6,-1,-1,minecraft:coarse_dirt)
B(-6,0,-1,minecraft:coarse_dirt)
B(-6,-27,0,minecraft:terracotta)
B(-6,-26,0,minecraft:terracotta)
B(-6,-25,0,minecraft:terracotta)
B(-6,-24,0,minecraft:terracotta)
B(-6,-23,0,minecraft:terracotta)
B(-6,-22,0,minecraft:terracotta)
B(-6,-21,0,minecraft:terracotta)
B(-6,-20,0,minecraft:terracotta)
B(-6,-19,0,minecraft:terracotta)
B(-6,-18,0,minecraft:terracotta)
B(-6,-17,0,minecraft:terracotta)
B(-6,-16,0,minecraft:terracotta)
B(-6,-15,0,minecraft:terracotta)
B(-6,-14,0,minecraft:terracotta)
B(-6,-13,0,minecraft:terracotta)
B(-6,-12,0,minecraft:terracotta)
B(-6,-11,0,minecraft:terracotta)
B(-6,-10,0,minecraft:terracotta)
B(-6,-9,0,minecraft:terracotta)
B(-6,-8,0,minecraft:terracotta)
B(-6,-7,0,minecraft:terracotta)
B(-6,-6,0,minecraft:terracotta)
B(-6,-5,0,minecraft:terracotta)
B(-6,-4,0,minecraft:terracotta)
B(-6,-3,0,minecraft:terracotta)
B(-6,-2,0,minecraft:coarse_dirt)
B(-6,-1,0,minecraft:coarse_dirt)
B(-6,0,0,minecraft:coarse_dirt)
B(-6,-27,1,minecraft:terracotta)
B(-6,-26,1,minecraft:terracotta)
B(-6,-25,1,minecraft:terracotta)
B(-6,-24,1,minecraft:terracotta)
B(-6,-23,1,minecraft:terracotta)
B(-6,-22,1,minecraft:terracotta)
B(-6,-21,1,minecraft:terracotta)
B(-6,-20,1,minecraft:terracotta)
B(-6,-19,1,minecraft:terracotta)
B(-6,-18,1,minecraft:terracotta)
B(-6,-17,1,minecraft:terracotta)
B(-6,-16,1,minecraft:terracotta)
B(-6,-15,1,minecraft:terracotta)
B(-6,-14,1,minecraft:terracotta)
B(-6,-13,1,minecraft:terracotta)
B(-6,-12,1,minecraft:terracotta)
B(-6,-11,1,minecraft:terracotta)
B(-6,-10,1,minecraft:terracotta)
B(-6,-9,1,minecraft:terracotta)
B(-6,-8,1,minecraft:terracotta)
B(-6,-7,1,minecraft:terracotta)
B(-6,-6,1,minecraft:terracotta)
B(-6,-5,1,minecraft:terracotta)
B(-6,-4,1,minecraft:terracotta)
B(-6,-3,1,minecraft:terracotta)
B(-6,-2,1,minecraft:terracotta)
B(-6,-1,1,minecraft:coarse_dirt)
B(-6,0,1,minecraft:coarse_dirt)
B(-6,-27,2,minecraft:terracotta)
B(-6,-26,2,minecraft:terracotta)
B(-6,-25,2,minecraft:terracotta)
B(-6,-24,2,minecraft:terracotta)
B(-6,-23,2,minecraft:terracotta)
B(-6,-22,2,minecraft:terracotta)
B(-6,-21,2,minecraft:terracotta)
B(-6,-20,2,minecraft:terracotta)
B(-6,-19,2,minecraft:terracotta)
B(-6,-18,2,minecraft:terracotta)
B(-6,-17,2,minecraft:terracotta)
B(-6,-16,2,minecraft:terracotta)
B(-6,-15,2,minecraft:terracotta)
B(-6,-14,2,minecraft:terracotta)
B(-6,-13,2,minecraft:terracotta)
B(-6,-12,2,minecraft:terracotta)
B(-6,-11,2,minecraft:terracotta)
B(-6,-10,2,minecraft:terracotta)
B(-6,-9,2,minecraft:terracotta)
B(-6,-8,2,minecraft:terracotta)
B(-6,-7,2,minecraft:terracotta)
B(-6,-6,2,minecraft:terracotta)
B(-6,-5,2,minecraft:terracotta)
B(-6,-4,2,minecraft:terracotta)
B(-6,-3,2,minecraft:terracotta)
B(-6,-27,3,minecraft:terracotta)
B(-6,-26,3,minecraft:terracotta)
B(-6,-25,3,minecraft:terracotta)
B(-6,-24,3,minecraft:terracotta)
B(-6,-23,3,minecraft:terracotta)
B(-6,-22,3,minecraft:terracotta)
B(-6,-21,3,minecraft:terracotta)
B(-6,-20,3,minecraft:terracotta)
B(-6,-19,3,minecraft:terracotta)
B(-6,-18,3,minecraft:terracotta)
B(-6,-17,3,minecraft:terracotta)
B(-6,-16,3,minecraft:terracotta)
B(-6,-15,3,minecraft:terracotta)
B(-6,-14,3,minecraft:terracotta)
B(-6,-13,3,minecraft:terracotta)
B(-6,-12,3,minecraft:terracotta)
B(-6,-11,3,minecraft:terracotta)
B(-6,-10,3,minecraft:terracotta)
B(-6,-9,3,minecraft:terracotta)
B(-6,-8,3,minecraft:terracotta)
B(-6,-7,3,minecraft:terracotta)
B(-6,-6,3,minecraft:terracotta)
B(-6,-5,3,minecraft:terracotta)
B(-6,-4,3,minecraft:terracotta)
B(-6,-27,4,minecraft:terracotta)
B(-6,-26,4,minecraft:terracotta)
B(-6,-25,4,minecraft:terracotta)
B(-6,-24,4,minecraft:terracotta)
B(-6,-23,4,minecraft:terracotta)
B(-6,-22,4,minecraft:terracotta)
B(-6,-21,4,minecraft:terracotta)
B(-6,-20,4,minecraft:terracotta)
B(-6,-19,4,minecraft:terracotta)
B(-6,-18,4,minecraft:terracotta)
B(-6,-17,4,minecraft:terracotta)
B(-6,-16,4,minecraft:terracotta)
B(-6,-15,4,minecraft:terracotta)
B(-6,-14,4,minecraft:terracotta)
B(-6,-13,4,minecraft:terracotta)
B(-6,-12,4,minecraft:terracotta)
B(-6,-11,4,minecraft:terracotta)
B(-6,-27,5,minecraft:terracotta)
B(-6,-26,5,minecraft:terracotta)
B(-6,-25,5,minecraft:terracotta)
B(-6,-24,5,minecraft:terracotta)
B(-6,-23,5,minecraft:terracotta)
B(-6,-22,5,minecraft:terracotta)
B(-6,-21,5,minecraft:terracotta)
B(-6,-20,5,minecraft:terracotta)
B(-6,-27,6,minecraft:terracotta)
B(-6,-26,6,minecraft:terracotta)
B(-6,-25,6,minecraft:terracotta)
B(-6,-24,6,minecraft:terracotta)
B(-6,-23,6,minecraft:terracotta)
B(-6,-22,6,minecraft:terracotta)
B(-6,-21,6,minecraft:terracotta)
B(-6,-27,7,minecraft:terracotta)
B(-6,-26,7,minecraft:terracotta)
B(-6,-25,7,minecraft:terracotta)
B(-6,-24,7,minecraft:terracotta)
B(-6,-23,7,minecraft:terracotta)
B(-6,-22,7,minecraft:terracotta)
B(-6,-21,7,minecraft:terracotta)
B(-6,-27,8,minecraft:terracotta)
B(-6,-26,8,minecraft:terracotta)
B(-6,-25,8,minecraft:terracotta)
B(-6,-24,8,minecraft:terracotta)
B(-6,-27,9,minecraft:terracotta)
B(-6,-26,9,minecraft:terracotta)
B(-6,-25,9,minecraft:terracotta)
B(-6,-27,10,minecraft:terracotta)
B(-6,-26,10,minecraft:terracotta)
B(-6,-25,10,minecraft:terracotta)
B(-6,-27,11,minecraft:terracotta)
B(-6,-26,11,minecraft:terracotta)
B(-6,-27,12,minecraft:terracotta)
B(-5,-27,-15,minecraft:terracotta)
B(-5,-26,-15,minecraft:terracotta)
B(-5,-27,-14,minecraft:terracotta)
B(-5,-26,-14,minecraft:terracotta)
B(-5,-25,-14,minecraft:terracotta)
B(-5,-24,-14,minecraft:terracotta)
B(-5,-23,-14,minecraft:terracotta)
B(-5,-27,-13,minecraft:terracotta)
B(-5,-26,-13,minecraft:terracotta)
B(-5,-25,-13,minecraft:terracotta)
B(-5,-24,-13,minecraft:terracotta)
B(-5,-23,-13,minecraft:terracotta)
B(-5,-22,-13,minecraft:terracotta)
B(-5,-21,-13,minecraft:terracotta)
B(-5,-27,-12,minecraft:terracotta)
B(-5,-26,-12,minecraft:terracotta)
B(-5,-25,-12,minecraft:terracotta)
B(-5,-24,-12,minecraft:terracotta)
B(-5,-23,-12,minecraft:terracotta)
B(-5,-22,-12,minecraft:terracotta)
B(-5,-21,-12,minecraft:terracotta)
B(-5,-20,-12,minecraft:terracotta)
B(-5,-19,-12,minecraft:terracotta)
B(-5,-18,-12,minecraft:terracotta)
B(-5,-17,-12,minecraft:terracotta)
B(-5,-16,-12,minecraft:terracotta)
B(-5,-15,-12,minecraft:terracotta)
B(-5,-27,-11,minecraft:terracotta)
B(-5,-26,-11,minecraft:terracotta)
B(-5,-25,-11,minecraft:terracotta)
B(-5,-24,-11,minecraft:terracotta)
B(-5,-23,-11,minecraft:terracotta)
B(-5,-22,-11,minecraft:terracotta)
B(-5,-21,-11,minecraft:terracotta)
B(-5,-20,-11,minecraft:terracotta)
B(-5,-19,-11,minecraft:terracotta)
B(-5,-18,-11,minecraft:terracotta)
B(-5,-17,-11,minecraft:terracotta)
B(-5,-16,-11,minecraft:terracotta)
B(-5,-15,-11,minecraft:terracotta)
B(-5,-14,-11,minecraft:terracotta)
B(-5,-27,-10,minecraft:terracotta)
B(-5,-26,-10,minecraft:terracotta)
B(-5,-25,-10,minecraft:terracotta)
B(-5,-24,-10,minecraft:terracotta)
B(-5,-23,-10,minecraft:terracotta)
B(-5,-22,-10,minecraft:terracotta)
B(-5,-21,-10,minecraft:terracotta)
B(-5,-20,-10,minecraft:terracotta)
B(-5,-19,-10,minecraft:terracotta)
B(-5,-18,-10,minecraft:terracotta)
B(-5,-17,-10,minecraft:terracotta)
B(-5,-16,-10,minecraft:terracotta)
B(-5,-15,-10,minecraft:terracotta)
B(-5,-14,-10,minecraft:terracotta)
B(-5,-13,-10,minecraft:terracotta)
B(-5,-27,-9,minecraft:terracotta)
B(-5,-26,-9,minecraft:terracotta)
B(-5,-25,-9,minecraft:terracotta)
B(-5,-24,-9,minecraft:terracotta)
B(-5,-23,-9,minecraft:terracotta)
B(-5,-22,-9,minecraft:terracotta)
B(-5,-21,-9,minecraft:terracotta)
B(-5,-20,-9,minecraft:terracotta)
B(-5,-19,-9,minecraft:terracotta)
B(-5,-18,-9,minecraft:terracotta)
B(-5,-17,-9,minecraft:terracotta)
B(-5,-16,-9,minecraft:terracotta)
B(-5,-15,-9,minecraft:terracotta)
B(-5,-14,-9,minecraft:terracotta)
B(-5,-13,-9,minecraft:terracotta)
B(-5,-27,-8,minecraft:terracotta)
B(-5,-26,-8,minecraft:terracotta)
B(-5,-25,-8,minecraft:terracotta)
B(-5,-24,-8,minecraft:terracotta)
B(-5,-23,-8,minecraft:terracotta)
B(-5,-22,-8,minecraft:terracotta)
B(-5,-21,-8,minecraft:terracotta)
B(-5,-20,-8,minecraft:terracotta)
B(-5,-19,-8,minecraft:terracotta)
B(-5,-18,-8,minecraft:terracotta)
B(-5,-17,-8,minecraft:terracotta)
B(-5,-16,-8,minecraft:terracotta)
B(-5,-15,-8,minecraft:terracotta)
B(-5,-14,-8,minecraft:terracotta)
B(-5,-13,-8,minecraft:terracotta)
B(-5,-27,-7,minecraft:terracotta)
B(-5,-26,-7,minecraft:terracotta)
B(-5,-25,-7,minecraft:terracotta)
B(-5,-24,-7,minecraft:terracotta)
B(-5,-23,-7,minecraft:terracotta)
B(-5,-22,-7,minecraft:terracotta)
B(-5,-21,-7,minecraft:terracotta)
B(-5,-20,-7,minecraft:terracotta)
B(-5,-19,-7,minecraft:terracotta)
B(-5,-18,-7,minecraft:terracotta)
B(-5,-17,-7,minecraft:terracotta)
B(-5,-16,-7,minecraft:terracotta)
B(-5,-15,-7,minecraft:terracotta)
B(-5,-14,-7,minecraft:terracotta)
B(-5,-13,-7,minecraft:terracotta)
B(-5,-12,-7,minecraft:terracotta)
B(-5,-11,-7,minecraft:terracotta)
B(-5,-10,-7,minecraft:terracotta)
B(-5,-9,-7,minecraft:terracotta)
B(-5,-8,-7,minecraft:terracotta)
B(-5,-27,-6,minecraft:terracotta)
B(-5,-26,-6,minecraft:terracotta)
B(-5,-25,-6,minecraft:terracotta)
B(-5,-24,-6,minecraft:terracotta)
B(-5,-23,-6,minecraft:terracotta)
B(-5,-22,-6,minecraft:terracotta)
B(-5,-21,-6,minecraft:terracotta)
B(-5,-20,-6,minecraft:terracotta)
B(-5,-19,-6,minecraft:terracotta)
B(-5,-18,-6,minecraft:terracotta)
B(-5,-17,-6,minecraft:terracotta)
B(-5,-16,-6,minecraft:terracotta)
B(-5,-15,-6,minecraft:terracotta)
B(-5,-14,-6,minecraft:terracotta)
B(-5,-13,-6,minecraft:terracotta)
B(-5,-12,-6,minecraft:terracotta)
B(-5,-11,-6,minecraft:terracotta)
B(-5,-10,-6,minecraft:terracotta)
B(-5,-9,-6,minecraft:terracotta)
B(-5,-8,-6,minecraft:terracotta)
B(-5,-7,-6,minecraft:terracotta)
B(-5,-6,-6,minecraft:terracotta)
B(-5,-5,-6,minecraft:terracotta)
B(-5,-4,-6,minecraft:terracotta)
B(-5,-27,-5,minecraft:terracotta)
B(-5,-26,-5,minecraft:terracotta)
B(-5,-25,-5,minecraft:terracotta)
B(-5,-24,-5,minecraft:terracotta)
B(-5,-23,-5,minecraft:terracotta)
B(-5,-22,-5,minecraft:terracotta)
B(-5,-21,-5,minecraft:terracotta)
B(-5,-20,-5,minecraft:terracotta)
B(-5,-19,-5,minecraft:terracotta)
B(-5,-18,-5,minecraft:terracotta)
B(-5,-17,-5,minecraft:terracotta)
B(-5,-16,-5,minecraft:terracotta)
B(-5,-15,-5,minecraft:terracotta)
B(-5,-14,-5,minecraft:terracotta)
B(-5,-13,-5,minecraft:terracotta)
B(-5,-12,-5,minecraft:terracotta)
B(-5,-11,-5,minecraft:terracotta)
B(-5,-10,-5,minecraft:terracotta)
B(-5,-9,-5,minecraft:terracotta)
B(-5,-8,-5,minecraft:terracotta)
B(-5,-7,-5,minecraft:terracotta)
B(-5,-6,-5,minecraft:terracotta)
B(-5,-5,-5,minecraft:terracotta)
B(-5,-4,-5,minecraft:terracotta)
B(-5,-3,-5,minecraft:coarse_dirt)
B(-5,-27,-4,minecraft:terracotta)
B(-5,-26,-4,minecraft:terracotta)
B(-5,-25,-4,minecraft:terracotta)
B(-5,-24,-4,minecraft:terracotta)
B(-5,-23,-4,minecraft:terracotta)
B(-5,-22,-4,minecraft:terracotta)
B(-5,-21,-4,minecraft:terracotta)
B(-5,-20,-4,minecraft:terracotta)
B(-5,-19,-4,minecraft:terracotta)
B(-5,-18,-4,minecraft:terracotta)
B(-5,-17,-4,minecraft:terracotta)
B(-5,-16,-4,minecraft:terracotta)
B(-5,-15,-4,minecraft:terracotta)
B(-5,-14,-4,minecraft:terracotta)
B(-5,-13,-4,minecraft:terracotta)
B(-5,-12,-4,minecraft:terracotta)
B(-5,-11,-4,minecraft:terracotta)
B(-5,-10,-4,minecraft:terracotta)
B(-5,-9,-4,minecraft:terracotta)
B(-5,-8,-4,minecraft:terracotta)
B(-5,-7,-4,minecraft:terracotta)
B(-5,-6,-4,minecraft:terracotta)
B(-5,-5,-4,minecraft:terracotta)
B(-5,-4,-4,minecraft:terracotta)
B(-5,-3,-4,minecraft:terracotta)
B(-5,-2,-4,minecraft:terracotta)
B(-5,-27,-3,minecraft:terracotta)
B(-5,-26,-3,minecraft:terracotta)
B(-5,-25,-3,minecraft:terracotta)
B(-5,-24,-3,minecraft:terracotta)
B(-5,-23,-3,minecraft:terracotta)
B(-5,-22,-3,minecraft:terracotta)
B(-5,-21,-3,minecraft:terracotta)
B(-5,-20,-3,minecraft:terracotta)
B(-5,-19,-3,minecraft:terracotta)
B(-5,-18,-3,minecraft:terracotta)
B(-5,-17,-3,minecraft:terracotta)
B(-5,-16,-3,minecraft:terracotta)
B(-5,-15,-3,minecraft:terracotta)
B(-5,-14,-3,minecraft:terracotta)
B(-5,-13,-3,minecraft:terracotta)
B(-5,-12,-3,minecraft:terracotta)
B(-5,-11,-3,minecraft:terracotta)
B(-5,-10,-3,minecraft:terracotta)
B(-5,-9,-3,minecraft:terracotta)
B(-5,-8,-3,minecraft:terracotta)
B(-5,-7,-3,minecraft:terracotta)
B(-5,-6,-3,minecraft:terracotta)
B(-5,-5,-3,minecraft:terracotta)
B(-5,-4,-3,minecraft:terracotta)
B(-5,-3,-3,minecraft:terracotta)
B(-5,-2,-3,minecraft:terracotta)
B(-5,-1,-3,minecraft:coarse_dirt)
B(-5,0,-3,minecraft:coarse_dirt)
B(-5,-27,-2,minecraft:terracotta)
B(-5,-26,-2,minecraft:terracotta)
B(-5,-25,-2,minecraft:terracotta)
B(-5,-24,-2,minecraft:terracotta)
B(-5,-23,-2,minecraft:terracotta)
B(-5,-22,-2,minecraft:terracotta)
B(-5,-21,-2,minecraft:terracotta)
B(-5,-20,-2,minecraft:terracotta)
B(-5,-19,-2,minecraft:terracotta)
B(-5,-18,-2,minecraft:terracotta)
B(-5,-17,-2,minecraft:terracotta)
B(-5,-16,-2,minecraft:terracotta)
B(-5,-15,-2,minecraft:terracotta)
B(-5,-14,-2,minecraft:terracotta)
B(-5,-13,-2,minecraft:terracotta)
B(-5,-12,-2,minecraft:terracotta)
B(-5,-11,-2,minecraft:terracotta)
B(-5,-10,-2,minecraft:terracotta)
B(-5,-9,-2,minecraft:terracotta)
B(-5,-8,-2,minecraft:terracotta)
B(-5,-7,-2,minecraft:terracotta)
B(-5,-6,-2,minecraft:terracotta)
B(-5,-5,-2,minecraft:terracotta)
B(-5,-4,-2,minecraft:terracotta)
B(-5,-3,-2,minecraft:terracotta)
B(-5,-2,-2,minecraft:coarse_dirt)
B(-5,-1,-2,minecraft:coarse_dirt)
B(-5,0,-2,minecraft:coarse_dirt)
B(-5,-27,-1,minecraft:terracotta)
B(-5,-26,-1,minecraft:terracotta)
B(-5,-25,-1,minecraft:terracotta)
B(-5,-24,-1,minecraft:terracotta)
B(-5,-23,-1,minecraft:terracotta)
B(-5,-22,-1,minecraft:terracotta)
B(-5,-21,-1,minecraft:terracotta)
B(-5,-20,-1,minecraft:terracotta)
B(-5,-19,-1,minecraft:terracotta)
B(-5,-18,-1,minecraft:terracotta)
B(-5,-17,-1,minecraft:terracotta)
B(-5,-16,-1,minecraft:terracotta)
B(-5,-15,-1,minecraft:terracotta)
B(-5,-14,-1,minecraft:terracotta)
B(-5,-13,-1,minecraft:terracotta)
B(-5,-12,-1,minecraft:terracotta)
B(-5,-11,-1,minecraft:terracotta)
B(-5,-10,-1,minecraft:terracotta)
B(-5,-9,-1,minecraft:terracotta)
B(-5,-8,-1,minecraft:terracotta)
B(-5,-7,-1,minecraft:terracotta)
B(-5,-6,-1,minecraft:terracotta)
B(-5,-5,-1,minecraft:terracotta)
B(-5,-4,-1,minecraft:terracotta)
B(-5,-3,-1,minecraft:terracotta)
B(-5,-2,-1,minecraft:coarse_dirt)
B(-5,-1,-1,minecraft:coarse_dirt)
B(-5,0,-1,minecraft:coarse_dirt)
B(-5,-27,0,minecraft:terracotta)
B(-5,-26,0,minecraft:terracotta)
B(-5,-25,0,minecraft:terracotta)
B(-5,-24,0,minecraft:terracotta)
B(-5,-23,0,minecraft:terracotta)
B(-5,-22,0,minecraft:terracotta)
B(-5,-21,0,minecraft:terracotta)
B(-5,-20,0,minecraft:terracotta)
B(-5,-19,0,minecraft:terracotta)
B(-5,-18,0,minecraft:terracotta)
B(-5,-17,0,minecraft:terracotta)
B(-5,-16,0,minecraft:terracotta)
B(-5,-15,0,minecraft:terracotta)
B(-5,-14,0,minecraft:terracotta)
B(-5,-13,0,minecraft:terracotta)
B(-5,-12,0,minecraft:terracotta)
B(-5,-11,0,minecraft:terracotta)
B(-5,-10,0,minecraft:terracotta)
B(-5,-9,0,minecraft:terracotta)
B(-5,-8,0,minecraft:terracotta)
B(-5,-7,0,minecraft:terracotta)
B(-5,-6,0,minecraft:terracotta)
B(-5,-5,0,minecraft:terracotta)
B(-5,-4,0,minecraft:terracotta)
B(-5,-3,0,minecraft:terracotta)
B(-5,-2,0,minecraft:coarse_dirt)
B(-5,-1,0,minecraft:coarse_dirt)
B(-5,0,0,minecraft:coarse_dirt)
B(-5,-27,1,minecraft:terracotta)
B(-5,-26,1,minecraft:terracotta)
B(-5,-25,1,minecraft:terracotta)
B(-5,-24,1,minecraft:terracotta)
B(-5,-23,1,minecraft:terracotta)
B(-5,-22,1,minecraft:terracotta)
B(-5,-21,1,minecraft:terracotta)
B(-5,-20,1,minecraft:terracotta)
B(-5,-19,1,minecraft:terracotta)
B(-5,-18,1,minecraft:terracotta)
B(-5,-17,1,minecraft:terracotta)
B(-5,-16,1,minecraft:terracotta)
B(-5,-15,1,minecraft:terracotta)
B(-5,-14,1,minecraft:terracotta)
B(-5,-13,1,minecraft:terracotta)
B(-5,-12,1,minecraft:terracotta)
B(-5,-11,1,minecraft:terracotta)
B(-5,-10,1,minecraft:terracotta)
B(-5,-9,1,minecraft:terracotta)
B(-5,-8,1,minecraft:terracotta)
B(-5,-7,1,minecraft:terracotta)
B(-5,-6,1,minecraft:terracotta)
B(-5,-5,1,minecraft:terracotta)
B(-5,-4,1,minecraft:terracotta)
B(-5,-3,1,minecraft:terracotta)
B(-5,-2,1,minecraft:coarse_dirt)
B(-5,-1,1,minecraft:coarse_dirt)
B(-5,0,1,minecraft:coarse_dirt)
B(-5,-27,2,minecraft:terracotta)
B(-5,-26,2,minecraft:terracotta)
B(-5,-25,2,minecraft:terracotta)
B(-5,-24,2,minecraft:terracotta)
B(-5,-23,2,minecraft:terracotta)
B(-5,-22,2,minecraft:terracotta)
B(-5,-21,2,minecraft:terracotta)
B(-5,-20,2,minecraft:terracotta)
B(-5,-19,2,minecraft:terracotta)
B(-5,-18,2,minecraft:terracotta)
B(-5,-17,2,minecraft:terracotta)
B(-5,-16,2,minecraft:terracotta)
B(-5,-15,2,minecraft:terracotta)
B(-5,-14,2,minecraft:terracotta)
B(-5,-13,2,minecraft:terracotta)
B(-5,-12,2,minecraft:terracotta)
B(-5,-11,2,minecraft:terracotta)
B(-5,-10,2,minecraft:terracotta)
B(-5,-9,2,minecraft:terracotta)
B(-5,-8,2,minecraft:terracotta)
B(-5,-7,2,minecraft:terracotta)
B(-5,-6,2,minecraft:terracotta)
B(-5,-5,2,minecraft:terracotta)
B(-5,-4,2,minecraft:terracotta)
B(-5,-3,2,minecraft:terracotta)
B(-5,-2,2,minecraft:terracotta)
B(-5,-1,2,minecraft:terracotta)
B(-5,0,2,minecraft:coarse_dirt)
B(-5,-27,3,minecraft:terracotta)
B(-5,-26,3,minecraft:terracotta)
B(-5,-25,3,minecraft:terracotta)
B(-5,-24,3,minecraft:terracotta)
B(-5,-23,3,minecraft:terracotta)
B(-5,-22,3,minecraft:terracotta)
B(-5,-21,3,minecraft:terracotta)
B(-5,-20,3,minecraft:terracotta)
B(-5,-19,3,minecraft:terracotta)
B(-5,-18,3,minecraft:terracotta)
B(-5,-17,3,minecraft:terracotta)
B(-5,-16,3,minecraft:terracotta)
B(-5,-15,3,minecraft:terracotta)
B(-5,-14,3,minecraft:terracotta)
B(-5,-13,3,minecraft:terracotta)
B(-5,-12,3,minecraft:terracotta)
B(-5,-11,3,minecraft:terracotta)
B(-5,-10,3,minecraft:terracotta)
B(-5,-9,3,minecraft:terracotta)
B(-5,-8,3,minecraft:terracotta)
B(-5,-7,3,minecraft:terracotta)
B(-5,-6,3,minecraft:terracotta)
B(-5,-5,3,minecraft:terracotta)
B(-5,-4,3,minecraft:terracotta)
B(-5,-3,3,minecraft:coarse_dirt)
B(-5,-27,4,minecraft:terracotta)
B(-5,-26,4,minecraft:terracotta)
B(-5,-25,4,minecraft:terracotta)
B(-5,-24,4,minecraft:terracotta)
B(-5,-23,4,minecraft:terracotta)
B(-5,-22,4,minecraft:terracotta)
B(-5,-21,4,minecraft:terracotta)
B(-5,-20,4,minecraft:terracotta)
B(-5,-19,4,minecraft:terracotta)
B(-5,-18,4,minecraft:terracotta)
B(-5,-17,4,minecraft:terracotta)
B(-5,-16,4,minecraft:terracotta)
B(-5,-15,4,minecraft:terracotta)
B(-5,-14,4,minecraft:terracotta)
B(-5,-13,4,minecraft:terracotta)
B(-5,-12,4,minecraft:terracotta)
B(-5,-27,5,minecraft:terracotta)
B(-5,-26,5,minecraft:terracotta)
B(-5,-25,5,minecraft:terracotta)
B(-5,-24,5,minecraft:terracotta)
B(-5,-23,5,minecraft:terracotta)
B(-5,-22,5,minecraft:terracotta)
B(-5,-21,5,minecraft:terracotta)
B(-5,-20,5,minecraft:terracotta)
B(-5,-19,5,minecraft:terracotta)
B(-5,-18,5,minecraft:terracotta)
B(-5,-17,5,minecraft:terracotta)
B(-5,-16,5,minecraft:terracotta)
B(-5,-15,5,minecraft:terracotta)
B(-5,-14,5,minecraft:terracotta)
B(-5,-27,6,minecraft:terracotta)
B(-5,-26,6,minecraft:terracotta)
B(-5,-25,6,minecraft:terracotta)
B(-5,-24,6,minecraft:terracotta)
B(-5,-23,6,minecraft:terracotta)
B(-5,-22,6,minecraft:terracotta)
B(-5,-21,6,minecraft:terracotta)
B(-5,-20,6,minecraft:terracotta)
B(-5,-19,6,minecraft:terracotta)
B(-5,-18,6,minecraft:terracotta)
B(-5,-17,6,minecraft:terracotta)
B(-5,-16,6,minecraft:terracotta)
B(-5,-27,7,minecraft:terracotta)
B(-5,-26,7,minecraft:terracotta)
B(-5,-25,7,minecraft:terracotta)
B(-5,-24,7,minecraft:terracotta)
B(-5,-23,7,minecraft:terracotta)
B(-5,-22,7,minecraft:terracotta)
B(-5,-21,7,minecraft:terracotta)
B(-5,-20,7,minecraft:terracotta)
B(-5,-19,7,minecraft:terracotta)
B(-5,-18,7,minecraft:terracotta)
B(-5,-27,8,minecraft:terracotta)
B(-5,-26,8,minecraft:terracotta)
B(-5,-25,8,minecraft:terracotta)
B(-5,-24,8,minecraft:terracotta)
B(-5,-23,8,minecraft:terracotta)
B(-5,-22,8,minecraft:terracotta)
B(-5,-21,8,minecraft:terracotta)
B(-5,-20,8,minecraft:terracotta)
B(-5,-27,9,minecraft:terracotta)
B(-5,-26,9,minecraft:terracotta)
B(-5,-25,9,minecraft:terracotta)
B(-5,-24,9,minecraft:terracotta)
B(-5,-23,9,minecraft:terracotta)
B(-5,-22,9,minecraft:terracotta)
B(-5,-27,10,minecraft:terracotta)
B(-5,-26,10,minecraft:terracotta)
B(-5,-25,10,minecraft:terracotta)
B(-5,-24,10,minecraft:terracotta)
B(-5,-27,11,minecraft:terracotta)
B(-5,-26,11,minecraft:terracotta)
B(-5,-25,11,minecraft:terracotta)
B(-5,-27,12,minecraft:terracotta)
B(-5,-26,12,minecraft:terracotta)
B(-4,-27,-15,minecraft:terracotta)
B(-4,-26,-15,minecraft:terracotta)
B(-4,-27,-14,minecraft:terracotta)
B(-4,-26,-14,minecraft:terracotta)
B(-4,-25,-14,minecraft:terracotta)
B(-4,-24,-14,minecraft:terracotta)
B(-4,-23,-14,minecraft:terracotta)
B(-4,-27,-13,minecraft:terracotta)
B(-4,-26,-13,minecraft:terracotta)
B(-4,-25,-13,minecraft:terracotta)
B(-4,-24,-13,minecraft:terracotta)
B(-4,-23,-13,minecraft:terracotta)
B(-4,-22,-13,minecraft:terracotta)
B(-4,-21,-13,minecraft:terracotta)
B(-4,-20,-13,minecraft:terracotta)
B(-4,-27,-12,minecraft:terracotta)
B(-4,-26,-12,minecraft:terracotta)
B(-4,-25,-12,minecraft:terracotta)
B(-4,-24,-12,minecraft:terracotta)
B(-4,-23,-12,minecraft:terracotta)
B(-4,-22,-12,minecraft:terracotta)
B(-4,-21,-12,minecraft:terracotta)
B(-4,-20,-12,minecraft:terracotta)
B(-4,-19,-12,minecraft:terracotta)
B(-4,-18,-12,minecraft:terracotta)
B(-4,-17,-12,minecraft:terracotta)
B(-4,-16,-12,minecraft:terracotta)
B(-4,-15,-12,minecraft:terracotta)
B(-4,-14,-12,minecraft:terracotta)
B(-4,-27,-11,minecraft:terracotta)
B(-4,-26,-11,minecraft:terracotta)
B(-4,-25,-11,minecraft:terracotta)
B(-4,-24,-11,minecraft:terracotta)
B(-4,-23,-11,minecraft:terracotta)
B(-4,-22,-11,minecraft:terracotta)
B(-4,-21,-11,minecraft:terracotta)
B(-4,-20,-11,minecraft:terracotta)
B(-4,-19,-11,minecraft:terracotta)
B(-4,-18,-11,minecraft:terracotta)
B(-4,-17,-11,minecraft:terracotta)
B(-4,-16,-11,minecraft:terracotta)
B(-4,-15,-11,minecraft:terracotta)
B(-4,-14,-11,minecraft:terracotta)
B(-4,-13,-11,minecraft:terracotta)
B(-4,-27,-10,minecraft:terracotta)
B(-4,-26,-10,minecraft:terracotta)
B(-4,-25,-10,minecraft:terracotta)
B(-4,-24,-10,minecraft:terracotta)
B(-4,-23,-10,minecraft:terracotta)
B(-4,-22,-10,minecraft:terracotta)
B(-4,-21,-10,minecraft:terracotta)
B(-4,-20,-10,minecraft:terracotta)
B(-4,-19,-10,minecraft:terracotta)
B(-4,-18,-10,minecraft:terracotta)
B(-4,-17,-10,minecraft:terracotta)
B(-4,-16,-10,minecraft:terracotta)
B(-4,-15,-10,minecraft:terracotta)
B(-4,-14,-10,minecraft:terracotta)
B(-4,-13,-10,minecraft:terracotta)
B(-4,-27,-9,minecraft:terracotta)
B(-4,-26,-9,minecraft:terracotta)
B(-4,-25,-9,minecraft:terracotta)
B(-4,-24,-9,minecraft:terracotta)
B(-4,-23,-9,minecraft:terracotta)
B(-4,-22,-9,minecraft:terracotta)
B(-4,-21,-9,minecraft:terracotta)
B(-4,-20,-9,minecraft:terracotta)
B(-4,-19,-9,minecraft:terracotta)
B(-4,-18,-9,minecraft:terracotta)
B(-4,-17,-9,minecraft:terracotta)
B(-4,-16,-9,minecraft:terracotta)
B(-4,-15,-9,minecraft:terracotta)
B(-4,-14,-9,minecraft:terracotta)
B(-4,-13,-9,minecraft:terracotta)
B(-4,-27,-8,minecraft:terracotta)
B(-4,-26,-8,minecraft:terracotta)
B(-4,-25,-8,minecraft:terracotta)
B(-4,-24,-8,minecraft:terracotta)
B(-4,-23,-8,minecraft:terracotta)
B(-4,-22,-8,minecraft:terracotta)
B(-4,-21,-8,minecraft:terracotta)
B(-4,-20,-8,minecraft:terracotta)
B(-4,-19,-8,minecraft:terracotta)
B(-4,-18,-8,minecraft:terracotta)
B(-4,-17,-8,minecraft:terracotta)
B(-4,-16,-8,minecraft:terracotta)
B(-4,-15,-8,minecraft:terracotta)
B(-4,-14,-8,minecraft:terracotta)
B(-4,-13,-8,minecraft:terracotta)
B(-4,-12,-8,minecraft:terracotta)
B(-4,-27,-7,minecraft:terracotta)
B(-4,-26,-7,minecraft:terracotta)
B(-4,-25,-7,minecraft:terracotta)
B(-4,-24,-7,minecraft:terracotta)
B(-4,-23,-7,minecraft:terracotta)
B(-4,-22,-7,minecraft:terracotta)
B(-4,-21,-7,minecraft:terracotta)
B(-4,-20,-7,minecraft:terracotta)
B(-4,-19,-7,minecraft:terracotta)
B(-4,-18,-7,minecraft:terracotta)
B(-4,-17,-7,minecraft:terracotta)
B(-4,-16,-7,minecraft:terracotta)
B(-4,-15,-7,minecraft:terracotta)
B(-4,-14,-7,minecraft:terracotta)
B(-4,-13,-7,minecraft:terracotta)
B(-4,-12,-7,minecraft:terracotta)
B(-4,-11,-7,minecraft:terracotta)
B(-4,-10,-7,minecraft:terracotta)
B(-4,-9,-7,minecraft:terracotta)
B(-4,-8,-7,minecraft:terracotta)
B(-4,-7,-7,minecraft:terracotta)
B(-4,-6,-7,minecraft:terracotta)
B(-4,-27,-6,minecraft:terracotta)
B(-4,-26,-6,minecraft:terracotta)
B(-4,-25,-6,minecraft:terracotta)
B(-4,-24,-6,minecraft:terracotta)
B(-4,-23,-6,minecraft:terracotta)
B(-4,-22,-6,minecraft:terracotta)
B(-4,-21,-6,minecraft:terracotta)
B(-4,-20,-6,minecraft:terracotta)
B(-4,-19,-6,minecraft:terracotta)
B(-4,-18,-6,minecraft:terracotta)
B(-4,-17,-6,minecraft:terracotta)
B(-4,-16,-6,minecraft:terracotta)
B(-4,-15,-6,minecraft:terracotta)
B(-4,-14,-6,minecraft:terracotta)
B(-4,-13,-6,minecraft:terracotta)
B(-4,-12,-6,minecraft:terracotta)
B(-4,-11,-6,minecraft:terracotta)
B(-4,-10,-6,minecraft:terracotta)
B(-4,-9,-6,minecraft:terracotta)
B(-4,-8,-6,minecraft:terracotta)
B(-4,-7,-6,minecraft:terracotta)
B(-4,-6,-6,minecraft:terracotta)
B(-4,-5,-6,minecraft:terracotta)
B(-4,-4,-6,minecraft:terracotta)
B(-4,-3,-6,minecraft:terracotta)
B(-4,-2,-6,minecraft:coarse_dirt)
B(-4,-27,-5,minecraft:terracotta)
B(-4,-26,-5,minecraft:terracotta)
B(-4,-25,-5,minecraft:terracotta)
B(-4,-24,-5,minecraft:terracotta)
B(-4,-23,-5,minecraft:terracotta)
B(-4,-22,-5,minecraft:terracotta)
B(-4,-21,-5,minecraft:terracotta)
B(-4,-20,-5,minecraft:terracotta)
B(-4,-19,-5,minecraft:terracotta)
B(-4,-18,-5,minecraft:terracotta)
B(-4,-17,-5,minecraft:terracotta)
B(-4,-16,-5,minecraft:terracotta)
B(-4,-15,-5,minecraft:terracotta)
B(-4,-14,-5,minecraft:terracotta)
B(-4,-13,-5,minecraft:terracotta)
B(-4,-12,-5,minecraft:terracotta)
B(-4,-11,-5,minecraft:terracotta)
B(-4,-10,-5,minecraft:terracotta)
B(-4,-9,-5,minecraft:terracotta)
B(-4,-8,-5,minecraft:terracotta)
B(-4,-7,-5,minecraft:terracotta)
B(-4,-6,-5,minecraft:terracotta)
B(-4,-5,-5,minecraft:terracotta)
B(-4,-4,-5,minecraft:terracotta)
B(-4,-3,-5,minecraft:terracotta)
B(-4,-2,-5,minecraft:coarse_dirt)
B(-4,-1,-5,minecraft:coarse_dirt)
B(-4,0,-5,minecraft:coarse_dirt)
B(-4,-27,-4,minecraft:terracotta)
B(-4,-26,-4,minecraft:terracotta)
B(-4,-25,-4,minecraft:terracotta)
B(-4,-24,-4,minecraft:terracotta)
B(-4,-23,-4,minecraft:terracotta)
B(-4,-22,-4,minecraft:terracotta)
B(-4,-21,-4,minecraft:terracotta)
B(-4,-20,-4,minecraft:terracotta)
B(-4,-19,-4,minecraft:terracotta)
B(-4,-18,-4,minecraft:terracotta)
B(-4,-17,-4,minecraft:terracotta)
B(-4,-16,-4,minecraft:terracotta)
B(-4,-15,-4,minecraft:terracotta)
B(-4,-14,-4,minecraft:terracotta)
B(-4,-13,-4,minecraft:terracotta)
B(-4,-12,-4,minecraft:terracotta)
B(-4,-11,-4,minecraft:terracotta)
B(-4,-10,-4,minecraft:terracotta)
B(-4,-9,-4,minecraft:terracotta)
B(-4,-8,-4,minecraft:terracotta)
B(-4,-7,-4,minecraft:terracotta)
B(-4,-6,-4,minecraft:terracotta)
B(-4,-5,-4,minecraft:terracotta)
B(-4,-4,-4,minecraft:terracotta)
B(-4,-3,-4,minecraft:terracotta)
B(-4,-2,-4,minecraft:terracotta)
B(-4,-1,-4,minecraft:coarse_dirt)
B(-4,0,-4,minecraft:coarse_dirt)
B(-4,-27,-3,minecraft:terracotta)
B(-4,-26,-3,minecraft:terracotta)
B(-4,-25,-3,minecraft:terracotta)
B(-4,-24,-3,minecraft:terracotta)
B(-4,-23,-3,minecraft:terracotta)
B(-4,-22,-3,minecraft:terracotta)
B(-4,-21,-3,minecraft:terracotta)
B(-4,-20,-3,minecraft:terracotta)
B(-4,-19,-3,minecraft:terracotta)
B(-4,-18,-3,minecraft:terracotta)
B(-4,-17,-3,minecraft:terracotta)
B(-4,-16,-3,minecraft:terracotta)
B(-4,-15,-3,minecraft:terracotta)
B(-4,-14,-3,minecraft:terracotta)
B(-4,-13,-3,minecraft:terracotta)
B(-4,-12,-3,minecraft:terracotta)
B(-4,-11,-3,minecraft:terracotta)
B(-4,-10,-3,minecraft:terracotta)
B(-4,-9,-3,minecraft:terracotta)
B(-4,-8,-3,minecraft:terracotta)
B(-4,-7,-3,minecraft:terracotta)
B(-4,-6,-3,minecraft:terracotta)
B(-4,-5,-3,minecraft:terracotta)
B(-4,-4,-3,minecraft:terracotta)
B(-4,-3,-3,minecraft:terracotta)
B(-4,-2,-3,minecraft:coarse_dirt)
B(-4,-1,-3,minecraft:coarse_dirt)
B(-4,0,-3,minecraft:coarse_dirt)
B(-4,-27,-2,minecraft:terracotta)
B(-4,-26,-2,minecraft:terracotta)
B(-4,-25,-2,minecraft:terracotta)
B(-4,-24,-2,minecraft:terracotta)
B(-4,-23,-2,minecraft:terracotta)
B(-4,-22,-2,minecraft:terracotta)
B(-4,-21,-2,minecraft:terracotta)
B(-4,-20,-2,minecraft:terracotta)
B(-4,-19,-2,minecraft:terracotta)
B(-4,-18,-2,minecraft:terracotta)
B(-4,-17,-2,minecraft:terracotta)
B(-4,-16,-2,minecraft:terracotta)
B(-4,-15,-2,minecraft:terracotta)
B(-4,-14,-2,minecraft:terracotta)
B(-4,-13,-2,minecraft:terracotta)
B(-4,-12,-2,minecraft:terracotta)
B(-4,-11,-2,minecraft:terracotta)
B(-4,-10,-2,minecraft:terracotta)
B(-4,-9,-2,minecraft:terracotta)
B(-4,-8,-2,minecraft:terracotta)
B(-4,-7,-2,minecraft:terracotta)
B(-4,-6,-2,minecraft:terracotta)
B(-4,-5,-2,minecraft:terracotta)
B(-4,-4,-2,minecraft:terracotta)
B(-4,-3,-2,minecraft:terracotta)
B(-4,-2,-2,minecraft:coarse_dirt)
B(-4,-1,-2,minecraft:coarse_dirt)
B(-4,0,-2,minecraft:coarse_dirt)
B(-4,-27,-1,minecraft:terracotta)
B(-4,-26,-1,minecraft:terracotta)
B(-4,-25,-1,minecraft:terracotta)
B(-4,-24,-1,minecraft:terracotta)
B(-4,-23,-1,minecraft:terracotta)
B(-4,-22,-1,minecraft:terracotta)
B(-4,-21,-1,minecraft:terracotta)
B(-4,-20,-1,minecraft:terracotta)
B(-4,-19,-1,minecraft:terracotta)
B(-4,-18,-1,minecraft:terracotta)
B(-4,-17,-1,minecraft:terracotta)
B(-4,-16,-1,minecraft:terracotta)
B(-4,-15,-1,minecraft:terracotta)
B(-4,-14,-1,minecraft:terracotta)
B(-4,-13,-1,minecraft:terracotta)
B(-4,-12,-1,minecraft:terracotta)
B(-4,-11,-1,minecraft:terracotta)
B(-4,-10,-1,minecraft:terracotta)
B(-4,-9,-1,minecraft:terracotta)
B(-4,-8,-1,minecraft:terracotta)
B(-4,-7,-1,minecraft:terracotta)
B(-4,-6,-1,minecraft:terracotta)
B(-4,-5,-1,minecraft:terracotta)
B(-4,-4,-1,minecraft:terracotta)
B(-4,-3,-1,minecraft:terracotta)
B(-4,-2,-1,minecraft:coarse_dirt)
B(-4,-1,-1,minecraft:coarse_dirt)
B(-4,0,-1,minecraft:coarse_dirt)
B(-4,-27,0,minecraft:terracotta)
B(-4,-26,0,minecraft:terracotta)
B(-4,-25,0,minecraft:terracotta)
B(-4,-24,0,minecraft:terracotta)
B(-4,-23,0,minecraft:terracotta)
B(-4,-22,0,minecraft:terracotta)
B(-4,-21,0,minecraft:terracotta)
B(-4,-20,0,minecraft:terracotta)
B(-4,-19,0,minecraft:terracotta)
B(-4,-18,0,minecraft:terracotta)
B(-4,-17,0,minecraft:terracotta)
B(-4,-16,0,minecraft:terracotta)
B(-4,-15,0,minecraft:terracotta)
B(-4,-14,0,minecraft:terracotta)
B(-4,-13,0,minecraft:terracotta)
B(-4,-12,0,minecraft:terracotta)
B(-4,-11,0,minecraft:terracotta)
B(-4,-10,0,minecraft:terracotta)
B(-4,-9,0,minecraft:terracotta)
B(-4,-8,0,minecraft:terracotta)
B(-4,-7,0,minecraft:terracotta)
B(-4,-6,0,minecraft:terracotta)
B(-4,-5,0,minecraft:terracotta)
B(-4,-4,0,minecraft:terracotta)
B(-4,-3,0,minecraft:terracotta)
B(-4,-2,0,minecraft:coarse_dirt)
B(-4,-1,0,minecraft:coarse_dirt)
B(-4,0,0,minecraft:coarse_dirt)
B(-4,-27,1,minecraft:terracotta)
B(-4,-26,1,minecraft:terracotta)
B(-4,-25,1,minecraft:terracotta)
B(-4,-24,1,minecraft:terracotta)
B(-4,-23,1,minecraft:terracotta)
B(-4,-22,1,minecraft:terracotta)
B(-4,-21,1,minecraft:terracotta)
B(-4,-20,1,minecraft:terracotta)
B(-4,-19,1,minecraft:terracotta)
B(-4,-18,1,minecraft:terracotta)
B(-4,-17,1,minecraft:terracotta)
B(-4,-16,1,minecraft:terracotta)
B(-4,-15,1,minecraft:terracotta)
B(-4,-14,1,minecraft:terracotta)
B(-4,-13,1,minecraft:terracotta)
B(-4,-12,1,minecraft:terracotta)
B(-4,-11,1,minecraft:terracotta)
B(-4,-10,1,minecraft:terracotta)
B(-4,-9,1,minecraft:terracotta)
B(-4,-8,1,minecraft:terracotta)
B(-4,-7,1,minecraft:terracotta)
B(-4,-6,1,minecraft:terracotta)
B(-4,-5,1,minecraft:terracotta)
B(-4,-4,1,minecraft:terracotta)
B(-4,-3,1,minecraft:terracotta)
B(-4,-2,1,minecraft:terracotta)
B(-4,-1,1,minecraft:coarse_dirt)
B(-4,0,1,minecraft:coarse_dirt)
B(-4,-27,2,minecraft:terracotta)
B(-4,-26,2,minecraft:terracotta)
B(-4,-25,2,minecraft:terracotta)
B(-4,-24,2,minecraft:terracotta)
B(-4,-23,2,minecraft:terracotta)
B(-4,-22,2,minecraft:terracotta)
B(-4,-21,2,minecraft:terracotta)
B(-4,-20,2,minecraft:terracotta)
B(-4,-19,2,minecraft:terracotta)
B(-4,-18,2,minecraft:terracotta)
B(-4,-17,2,minecraft:terracotta)
B(-4,-16,2,minecraft:terracotta)
B(-4,-15,2,minecraft:terracotta)
B(-4,-14,2,minecraft:terracotta)
B(-4,-13,2,minecraft:terracotta)
B(-4,-12,2,minecraft:terracotta)
B(-4,-11,2,minecraft:terracotta)
B(-4,-10,2,minecraft:terracotta)
B(-4,-9,2,minecraft:terracotta)
B(-4,-8,2,minecraft:terracotta)
B(-4,-7,2,minecraft:terracotta)
B(-4,-6,2,minecraft:terracotta)
B(-4,-5,2,minecraft:terracotta)
B(-4,-4,2,minecraft:terracotta)
B(-4,-3,2,minecraft:terracotta)
B(-4,-2,2,minecraft:terracotta)
B(-4,-1,2,minecraft:coarse_dirt)
B(-4,0,2,minecraft:coarse_dirt)
B(-4,-27,3,minecraft:terracotta)
B(-4,-26,3,minecraft:terracotta)
B(-4,-25,3,minecraft:terracotta)
B(-4,-24,3,minecraft:terracotta)
B(-4,-23,3,minecraft:terracotta)
B(-4,-22,3,minecraft:terracotta)
B(-4,-21,3,minecraft:terracotta)
B(-4,-20,3,minecraft:terracotta)
B(-4,-19,3,minecraft:terracotta)
B(-4,-18,3,minecraft:terracotta)
B(-4,-17,3,minecraft:terracotta)
B(-4,-16,3,minecraft:terracotta)
B(-4,-15,3,minecraft:terracotta)
B(-4,-14,3,minecraft:terracotta)
B(-4,-13,3,minecraft:terracotta)
B(-4,-12,3,minecraft:terracotta)
B(-4,-11,3,minecraft:terracotta)
B(-4,-10,3,minecraft:terracotta)
B(-4,-9,3,minecraft:terracotta)
B(-4,-8,3,minecraft:terracotta)
B(-4,-7,3,minecraft:terracotta)
B(-4,-6,3,minecraft:terracotta)
B(-4,-5,3,minecraft:terracotta)
B(-4,-4,3,minecraft:terracotta)
B(-4,-3,3,minecraft:terracotta)
B(-4,-2,3,minecraft:coarse_dirt)
B(-4,-1,3,minecraft:coarse_dirt)
B(-4,0,3,minecraft:coarse_dirt)
B(-4,-27,4,minecraft:terracotta)
B(-4,-26,4,minecraft:terracotta)
B(-4,-25,4,minecraft:terracotta)
B(-4,-24,4,minecraft:terracotta)
B(-4,-23,4,minecraft:terracotta)
B(-4,-22,4,minecraft:terracotta)
B(-4,-21,4,minecraft:terracotta)
B(-4,-20,4,minecraft:terracotta)
B(-4,-19,4,minecraft:terracotta)
B(-4,-18,4,minecraft:terracotta)
B(-4,-17,4,minecraft:terracotta)
B(-4,-16,4,minecraft:terracotta)
B(-4,-15,4,minecraft:terracotta)
B(-4,-14,4,minecraft:terracotta)
B(-4,-13,4,minecraft:terracotta)
B(-4,-12,4,minecraft:terracotta)
B(-4,-11,4,minecraft:terracotta)
B(-4,-10,4,minecraft:terracotta)
B(-4,-9,4,minecraft:terracotta)
B(-4,-8,4,minecraft:terracotta)
B(-4,-7,4,minecraft:terracotta)
B(-4,-6,4,minecraft:terracotta)
B(-4,-5,4,minecraft:terracotta)
B(-4,-4,4,minecraft:terracotta)
B(-4,-27,5,minecraft:terracotta)
B(-4,-26,5,minecraft:terracotta)
B(-4,-25,5,minecraft:terracotta)
B(-4,-24,5,minecraft:terracotta)
B(-4,-23,5,minecraft:terracotta)
B(-4,-22,5,minecraft:terracotta)
B(-4,-21,5,minecraft:terracotta)
B(-4,-20,5,minecraft:terracotta)
B(-4,-19,5,minecraft:terracotta)
B(-4,-18,5,minecraft:terracotta)
B(-4,-17,5,minecraft:terracotta)
B(-4,-16,5,minecraft:terracotta)
B(-4,-15,5,minecraft:terracotta)
B(-4,-14,5,minecraft:terracotta)
B(-4,-13,5,minecraft:terracotta)
B(-4,-12,5,minecraft:terracotta)
B(-4,-27,6,minecraft:terracotta)
B(-4,-26,6,minecraft:terracotta)
B(-4,-25,6,minecraft:terracotta)
B(-4,-24,6,minecraft:terracotta)
B(-4,-23,6,minecraft:terracotta)
B(-4,-22,6,minecraft:terracotta)
B(-4,-21,6,minecraft:terracotta)
B(-4,-20,6,minecraft:terracotta)
B(-4,-19,6,minecraft:terracotta)
B(-4,-18,6,minecraft:terracotta)
B(-4,-17,6,minecraft:terracotta)
B(-4,-16,6,minecraft:terracotta)
B(-4,-15,6,minecraft:terracotta)
B(-4,-14,6,minecraft:terracotta)
B(-4,-13,6,minecraft:terracotta)
B(-4,-27,7,minecraft:terracotta)
B(-4,-26,7,minecraft:terracotta)
B(-4,-25,7,minecraft:terracotta)
B(-4,-24,7,minecraft:terracotta)
B(-4,-23,7,minecraft:terracotta)
B(-4,-22,7,minecraft:terracotta)
B(-4,-21,7,minecraft:terracotta)
B(-4,-20,7,minecraft:terracotta)
B(-4,-19,7,minecraft:terracotta)
B(-4,-18,7,minecraft:terracotta)
B(-4,-17,7,minecraft:terracotta)
B(-4,-16,7,minecraft:terracotta)
B(-4,-15,7,minecraft:terracotta)
B(-4,-14,7,minecraft:terracotta)
B(-4,-27,8,minecraft:terracotta)
B(-4,-26,8,minecraft:terracotta)
B(-4,-25,8,minecraft:terracotta)
B(-4,-24,8,minecraft:terracotta)
B(-4,-23,8,minecraft:terracotta)
B(-4,-22,8,minecraft:terracotta)
B(-4,-21,8,minecraft:terracotta)
B(-4,-20,8,minecraft:terracotta)
B(-4,-19,8,minecraft:terracotta)
B(-4,-18,8,minecraft:terracotta)
B(-4,-17,8,minecraft:terracotta)
B(-4,-16,8,minecraft:terracotta)
B(-4,-15,8,minecraft:terracotta)
B(-4,-14,8,minecraft:terracotta)
B(-4,-27,9,minecraft:terracotta)
B(-4,-26,9,minecraft:terracotta)
B(-4,-25,9,minecraft:terracotta)
B(-4,-24,9,minecraft:terracotta)
B(-4,-23,9,minecraft:terracotta)
B(-4,-22,9,minecraft:terracotta)
B(-4,-21,9,minecraft:terracotta)
B(-4,-20,9,minecraft:terracotta)
B(-4,-19,9,minecraft:terracotta)
B(-4,-18,9,minecraft:terracotta)
B(-4,-17,9,minecraft:terracotta)
B(-4,-16,9,minecraft:terracotta)
B(-4,-27,10,minecraft:terracotta)
B(-4,-26,10,minecraft:terracotta)
B(-4,-25,10,minecraft:terracotta)
B(-4,-24,10,minecraft:terracotta)
B(-4,-23,10,minecraft:terracotta)
B(-4,-22,10,minecraft:terracotta)
B(-4,-27,11,minecraft:terracotta)
B(-4,-26,11,minecraft:terracotta)
B(-4,-25,11,minecraft:terracotta)
B(-4,-27,12,minecraft:terracotta)
B(-3,-27,-15,minecraft:terracotta)
B(-3,-26,-15,minecraft:terracotta)
B(-3,-27,-14,minecraft:terracotta)
B(-3,-26,-14,minecraft:terracotta)
B(-3,-25,-14,minecraft:terracotta)
B(-3,-24,-14,minecraft:terracotta)
B(-3,-23,-14,minecraft:terracotta)
B(-3,-22,-14,minecraft:terracotta)
B(-3,-27,-13,minecraft:terracotta)
B(-3,-26,-13,minecraft:terracotta)
B(-3,-25,-13,minecraft:terracotta)
B(-3,-24,-13,minecraft:terracotta)
B(-3,-23,-13,minecraft:terracotta)
B(-3,-22,-13,minecraft:terracotta)
B(-3,-21,-13,minecraft:terracotta)
B(-3,-20,-13,minecraft:terracotta)
B(-3,-19,-13,minecraft:terracotta)
B(-3,-18,-13,minecraft:terracotta)
B(-3,-17,-13,minecraft:terracotta)
B(-3,-16,-13,minecraft:terracotta)
B(-3,-27,-12,minecraft:terracotta)
B(-3,-26,-12,minecraft:terracotta)
B(-3,-25,-12,minecraft:terracotta)
B(-3,-24,-12,minecraft:terracotta)
B(-3,-23,-12,minecraft:terracotta)
B(-3,-22,-12,minecraft:terracotta)
B(-3,-21,-12,minecraft:terracotta)
B(-3,-20,-12,minecraft:terracotta)
B(-3,-19,-12,minecraft:terracotta)
B(-3,-18,-12,minecraft:terracotta)
B(-3,-17,-12,minecraft:terracotta)
B(-3,-16,-12,minecraft:terracotta)
B(-3,-15,-12,minecraft:terracotta)
B(-3,-14,-12,minecraft:terracotta)
B(-3,-27,-11,minecraft:terracotta)
B(-3,-26,-11,minecraft:terracotta)
B(-3,-25,-11,minecraft:terracotta)
B(-3,-24,-11,minecraft:terracotta)
B(-3,-23,-11,minecraft:terracotta)
B(-3,-22,-11,minecraft:terracotta)
B(-3,-21,-11,minecraft:terracotta)
B(-3,-20,-11,minecraft:terracotta)
B(-3,-19,-11,minecraft:terracotta)
B(-3,-18,-11,minecraft:terracotta)
B(-3,-17,-11,minecraft:terracotta)
B(-3,-16,-11,minecraft:terracotta)
B(-3,-15,-11,minecraft:terracotta)
B(-3,-14,-11,minecraft:terracotta)
B(-3,-13,-11,minecraft:terracotta)
B(-3,-27,-10,minecraft:terracotta)
B(-3,-26,-10,minecraft:terracotta)
B(-3,-25,-10,minecraft:terracotta)
B(-3,-24,-10,minecraft:terracotta)
B(-3,-23,-10,minecraft:terracotta)
B(-3,-22,-10,minecraft:terracotta)
B(-3,-21,-10,minecraft:terracotta)
B(-3,-20,-10,minecraft:terracotta)
B(-3,-19,-10,minecraft:terracotta)
B(-3,-18,-10,minecraft:terracotta)
B(-3,-17,-10,minecraft:terracotta)
B(-3,-16,-10,minecraft:terracotta)
B(-3,-15,-10,minecraft:terracotta)
B(-3,-14,-10,minecraft:terracotta)
B(-3,-13,-10,minecraft:terracotta)
B(-3,-27,-9,minecraft:terracotta)
B(-3,-26,-9,minecraft:terracotta)
B(-3,-25,-9,minecraft:terracotta)
B(-3,-24,-9,minecraft:terracotta)
B(-3,-23,-9,minecraft:terracotta)
B(-3,-22,-9,minecraft:terracotta)
B(-3,-21,-9,minecraft:terracotta)
B(-3,-20,-9,minecraft:terracotta)
B(-3,-19,-9,minecraft:terracotta)
B(-3,-18,-9,minecraft:terracotta)
B(-3,-17,-9,minecraft:terracotta)
B(-3,-16,-9,minecraft:terracotta)
B(-3,-15,-9,minecraft:terracotta)
B(-3,-14,-9,minecraft:terracotta)
B(-3,-13,-9,minecraft:terracotta)
B(-3,-27,-8,minecraft:terracotta)
B(-3,-26,-8,minecraft:terracotta)
B(-3,-25,-8,minecraft:terracotta)
B(-3,-24,-8,minecraft:terracotta)
B(-3,-23,-8,minecraft:terracotta)
B(-3,-22,-8,minecraft:terracotta)
B(-3,-21,-8,minecraft:terracotta)
B(-3,-20,-8,minecraft:terracotta)
B(-3,-19,-8,minecraft:terracotta)
B(-3,-18,-8,minecraft:terracotta)
B(-3,-17,-8,minecraft:terracotta)
B(-3,-16,-8,minecraft:terracotta)
B(-3,-15,-8,minecraft:terracotta)
B(-3,-14,-8,minecraft:terracotta)
B(-3,-13,-8,minecraft:terracotta)
B(-3,-12,-8,minecraft:terracotta)
B(-3,-11,-8,minecraft:terracotta)
B(-3,-27,-7,minecraft:terracotta)
B(-3,-26,-7,minecraft:terracotta)
B(-3,-25,-7,minecraft:terracotta)
B(-3,-24,-7,minecraft:terracotta)
B(-3,-23,-7,minecraft:terracotta)
B(-3,-22,-7,minecraft:terracotta)
B(-3,-21,-7,minecraft:terracotta)
B(-3,-20,-7,minecraft:terracotta)
B(-3,-19,-7,minecraft:terracotta)
B(-3,-18,-7,minecraft:terracotta)
B(-3,-17,-7,minecraft:terracotta)
B(-3,-16,-7,minecraft:terracotta)
B(-3,-15,-7,minecraft:terracotta)
B(-3,-14,-7,minecraft:terracotta)
B(-3,-13,-7,minecraft:terracotta)
B(-3,-12,-7,minecraft:terracotta)
B(-3,-11,-7,minecraft:terracotta)
B(-3,-10,-7,minecraft:terracotta)
B(-3,-9,-7,minecraft:terracotta)
B(-3,-8,-7,minecraft:terracotta)
B(-3,-7,-7,minecraft:terracotta)
B(-3,-6,-7,minecraft:terracotta)
B(-3,-5,-7,minecraft:terracotta)
B(-3,-4,-7,minecraft:terracotta)
B(-3,-27,-6,minecraft:terracotta)
B(-3,-26,-6,minecraft:terracotta)
B(-3,-25,-6,minecraft:terracotta)
B(-3,-24,-6,minecraft:terracotta)
B(-3,-23,-6,minecraft:terracotta)
B(-3,-22,-6,minecraft:terracotta)
B(-3,-21,-6,minecraft:terracotta)
B(-3,-20,-6,minecraft:terracotta)
B(-3,-19,-6,minecraft:terracotta)
B(-3,-18,-6,minecraft:terracotta)
B(-3,-17,-6,minecraft:terracotta)
B(-3,-16,-6,minecraft:terracotta)
B(-3,-15,-6,minecraft:terracotta)
B(-3,-14,-6,minecraft:terracotta)
B(-3,-13,-6,minecraft:terracotta)
B(-3,-12,-6,minecraft:terracotta)
B(-3,-11,-6,minecraft:terracotta)
B(-3,-10,-6,minecraft:terracotta)
B(-3,-9,-6,minecraft:terracotta)
B(-3,-8,-6,minecraft:terracotta)
B(-3,-7,-6,minecraft:terracotta)
B(-3,-6,-6,minecraft:terracotta)
B(-3,-5,-6,minecraft:terracotta)
B(-3,-4,-6,minecraft:terracotta)
B(-3,-3,-6,minecraft:terracotta)
B(-3,-2,-6,minecraft:coarse_dirt)
B(-3,-1,-6,minecraft:coarse_dirt)
B(-3,0,-6,minecraft:coarse_dirt)
B(-3,-27,-5,minecraft:terracotta)
B(-3,-26,-5,minecraft:terracotta)
B(-3,-25,-5,minecraft:terracotta)
B(-3,-24,-5,minecraft:terracotta)
B(-3,-23,-5,minecraft:terracotta)
B(-3,-22,-5,minecraft:terracotta)
B(-3,-21,-5,minecraft:terracotta)
B(-3,-20,-5,minecraft:terracotta)
B(-3,-19,-5,minecraft:terracotta)
B(-3,-18,-5,minecraft:terracotta)
B(-3,-17,-5,minecraft:terracotta)
B(-3,-16,-5,minecraft:terracotta)
B(-3,-15,-5,minecraft:terracotta)
B(-3,-14,-5,minecraft:terracotta)
B(-3,-13,-5,minecraft:terracotta)
B(-3,-12,-5,minecraft:terracotta)
B(-3,-11,-5,minecraft:terracotta)
B(-3,-10,-5,minecraft:terracotta)
B(-3,-9,-5,minecraft:terracotta)
B(-3,-8,-5,minecraft:terracotta)
B(-3,-7,-5,minecraft:terracotta)
B(-3,-6,-5,minecraft:terracotta)
B(-3,-5,-5,minecraft:terracotta)
B(-3,-4,-5,minecraft:terracotta)
B(-3,-3,-5,minecraft:terracotta)
B(-3,-2,-5,minecraft:coarse_dirt)
B(-3,-1,-5,minecraft:coarse_dirt)
B(-3,0,-5,minecraft:coarse_dirt)
B(-3,-27,-4,minecraft:terracotta)
B(-3,-26,-4,minecraft:terracotta)
B(-3,-25,-4,minecraft:terracotta)
B(-3,-24,-4,minecraft:terracotta)
B(-3,-23,-4,minecraft:terracotta)
B(-3,-22,-4,minecraft:terracotta)
B(-3,-21,-4,minecraft:terracotta)
B(-3,-20,-4,minecraft:terracotta)
B(-3,-19,-4,minecraft:terracotta)
B(-3,-18,-4,minecraft:terracotta)
B(-3,-17,-4,minecraft:terracotta)
B(-3,-16,-4,minecraft:terracotta)
B(-3,-15,-4,minecraft:terracotta)
B(-3,-14,-4,minecraft:terracotta)
B(-3,-13,-4,minecraft:terracotta)
B(-3,-12,-4,minecraft:terracotta)
B(-3,-11,-4,minecraft:terracotta)
B(-3,-10,-4,minecraft:terracotta)
B(-3,-9,-4,minecraft:terracotta)
B(-3,-8,-4,minecraft:terracotta)
B(-3,-7,-4,minecraft:terracotta)
B(-3,-6,-4,minecraft:terracotta)
B(-3,-5,-4,minecraft:terracotta)
B(-3,-4,-4,minecraft:terracotta)
B(-3,-3,-4,minecraft:terracotta)
B(-3,-2,-4,minecraft:coarse_dirt)
B(-3,-1,-4,minecraft:coarse_dirt)
B(-3,0,-4,minecraft:coarse_dirt)
B(-3,-27,-3,minecraft:terracotta)
B(-3,-26,-3,minecraft:terracotta)
B(-3,-25,-3,minecraft:terracotta)
B(-3,-24,-3,minecraft:terracotta)
B(-3,-23,-3,minecraft:terracotta)
B(-3,-22,-3,minecraft:terracotta)
B(-3,-21,-3,minecraft:terracotta)
B(-3,-20,-3,minecraft:terracotta)
B(-3,-19,-3,minecraft:terracotta)
B(-3,-18,-3,minecraft:terracotta)
B(-3,-17,-3,minecraft:terracotta)
B(-3,-16,-3,minecraft:terracotta)
B(-3,-15,-3,minecraft:terracotta)
B(-3,-14,-3,minecraft:terracotta)
B(-3,-13,-3,minecraft:terracotta)
B(-3,-12,-3,minecraft:terracotta)
B(-3,-11,-3,minecraft:terracotta)
B(-3,-10,-3,minecraft:terracotta)
B(-3,-9,-3,minecraft:terracotta)
B(-3,-8,-3,minecraft:terracotta)
B(-3,-7,-3,minecraft:terracotta)
B(-3,-6,-3,minecraft:terracotta)
B(-3,-5,-3,minecraft:terracotta)
B(-3,-4,-3,minecraft:terracotta)
B(-3,-3,-3,minecraft:terracotta)
B(-3,-2,-3,minecraft:terracotta)
B(-3,-1,-3,minecraft:coarse_dirt)
B(-3,0,-3,minecraft:coarse_dirt)
B(-3,-27,-2,minecraft:terracotta)
B(-3,-26,-2,minecraft:terracotta)
B(-3,-25,-2,minecraft:terracotta)
B(-3,-24,-2,minecraft:terracotta)
B(-3,-23,-2,minecraft:terracotta)
B(-3,-22,-2,minecraft:terracotta)
B(-3,-21,-2,minecraft:terracotta)
B(-3,-20,-2,minecraft:terracotta)
B(-3,-19,-2,minecraft:terracotta)
B(-3,-18,-2,minecraft:terracotta)
B(-3,-17,-2,minecraft:terracotta)
B(-3,-16,-2,minecraft:terracotta)
B(-3,-15,-2,minecraft:terracotta)
B(-3,-14,-2,minecraft:terracotta)
B(-3,-13,-2,minecraft:terracotta)
B(-3,-12,-2,minecraft:terracotta)
B(-3,-11,-2,minecraft:terracotta)
B(-3,-10,-2,minecraft:terracotta)
B(-3,-9,-2,minecraft:terracotta)
B(-3,-8,-2,minecraft:terracotta)
B(-3,-7,-2,minecraft:terracotta)
B(-3,-6,-2,minecraft:terracotta)
B(-3,-5,-2,minecraft:terracotta)
B(-3,-4,-2,minecraft:terracotta)
B(-3,-3,-2,minecraft:terracotta)
B(-3,-2,-2,minecraft:coarse_dirt)
B(-3,-1,-2,minecraft:coarse_dirt)
B(-3,0,-2,minecraft:coarse_dirt)
B(-3,-27,-1,minecraft:terracotta)
B(-3,-26,-1,minecraft:terracotta)
B(-3,-25,-1,minecraft:terracotta)
B(-3,-24,-1,minecraft:terracotta)
B(-3,-23,-1,minecraft:terracotta)
B(-3,-22,-1,minecraft:terracotta)
B(-3,-21,-1,minecraft:terracotta)
B(-3,-20,-1,minecraft:terracotta)
B(-3,-19,-1,minecraft:terracotta)
B(-3,-18,-1,minecraft:terracotta)
B(-3,-17,-1,minecraft:terracotta)
B(-3,-16,-1,minecraft:terracotta)
B(-3,-15,-1,minecraft:terracotta)
B(-3,-14,-1,minecraft:terracotta)
B(-3,-13,-1,minecraft:terracotta)
B(-3,-12,-1,minecraft:terracotta)
B(-3,-11,-1,minecraft:terracotta)
B(-3,-10,-1,minecraft:terracotta)
B(-3,-9,-1,minecraft:terracotta)
B(-3,-8,-1,minecraft:terracotta)
B(-3,-7,-1,minecraft:terracotta)
B(-3,-6,-1,minecraft:terracotta)
B(-3,-5,-1,minecraft:terracotta)
B(-3,-4,-1,minecraft:terracotta)
B(-3,-3,-1,minecraft:terracotta)
B(-3,-2,-1,minecraft:terracotta)
B(-3,-1,-1,minecraft:coarse_dirt)
B(-3,0,-1,minecraft:coarse_dirt)
B(-3,-27,0,minecraft:terracotta)
B(-3,-26,0,minecraft:terracotta)
B(-3,-25,0,minecraft:terracotta)
B(-3,-24,0,minecraft:terracotta)
B(-3,-23,0,minecraft:terracotta)
B(-3,-22,0,minecraft:terracotta)
B(-3,-21,0,minecraft:terracotta)
B(-3,-20,0,minecraft:terracotta)
B(-3,-19,0,minecraft:terracotta)
B(-3,-18,0,minecraft:terracotta)
B(-3,-17,0,minecraft:terracotta)
B(-3,-16,0,minecraft:terracotta)
B(-3,-15,0,minecraft:terracotta)
B(-3,-14,0,minecraft:terracotta)
B(-3,-13,0,minecraft:terracotta)
B(-3,-12,0,minecraft:terracotta)
B(-3,-11,0,minecraft:terracotta)
B(-3,-10,0,minecraft:terracotta)
B(-3,-9,0,minecraft:terracotta)
B(-3,-8,0,minecraft:terracotta)
B(-3,-7,0,minecraft:terracotta)
B(-3,-6,0,minecraft:terracotta)
B(-3,-5,0,minecraft:terracotta)
B(-3,-4,0,minecraft:terracotta)
B(-3,-3,0,minecraft:terracotta)
B(-3,-2,0,minecraft:terracotta)
B(-3,-1,0,minecraft:terracotta)
B(-3,0,0,minecraft:coarse_dirt)
B(-3,-27,1,minecraft:terracotta)
B(-3,-26,1,minecraft:terracotta)
B(-3,-25,1,minecraft:terracotta)
B(-3,-24,1,minecraft:terracotta)
B(-3,-23,1,minecraft:terracotta)
B(-3,-22,1,minecraft:terracotta)
B(-3,-21,1,minecraft:terracotta)
B(-3,-20,1,minecraft:terracotta)
B(-3,-19,1,minecraft:terracotta)
B(-3,-18,1,minecraft:terracotta)
B(-3,-17,1,minecraft:terracotta)
B(-3,-16,1,minecraft:terracotta)
B(-3,-15,1,minecraft:terracotta)
B(-3,-14,1,minecraft:terracotta)
B(-3,-13,1,minecraft:terracotta)
B(-3,-12,1,minecraft:terracotta)
B(-3,-11,1,minecraft:terracotta)
B(-3,-10,1,minecraft:terracotta)
B(-3,-9,1,minecraft:terracotta)
B(-3,-8,1,minecraft:terracotta)
B(-3,-7,1,minecraft:terracotta)
B(-3,-6,1,minecraft:terracotta)
B(-3,-5,1,minecraft:terracotta)
B(-3,-4,1,minecraft:terracotta)
B(-3,-3,1,minecraft:terracotta)
B(-3,-2,1,minecraft:terracotta)
B(-3,-1,1,minecraft:coarse_dirt)
B(-3,0,1,minecraft:coarse_dirt)
B(-3,-27,2,minecraft:terracotta)
B(-3,-26,2,minecraft:terracotta)
B(-3,-25,2,minecraft:terracotta)
B(-3,-24,2,minecraft:terracotta)
B(-3,-23,2,minecraft:terracotta)
B(-3,-22,2,minecraft:terracotta)
B(-3,-21,2,minecraft:terracotta)
B(-3,-20,2,minecraft:terracotta)
B(-3,-19,2,minecraft:terracotta)
B(-3,-18,2,minecraft:terracotta)
B(-3,-17,2,minecraft:terracotta)
B(-3,-16,2,minecraft:terracotta)
B(-3,-15,2,minecraft:terracotta)
B(-3,-14,2,minecraft:terracotta)
B(-3,-13,2,minecraft:terracotta)
B(-3,-12,2,minecraft:terracotta)
B(-3,-11,2,minecraft:terracotta)
B(-3,-10,2,minecraft:terracotta)
B(-3,-9,2,minecraft:terracotta)
B(-3,-8,2,minecraft:terracotta)
B(-3,-7,2,minecraft:terracotta)
B(-3,-6,2,minecraft:terracotta)
B(-3,-5,2,minecraft:terracotta)
B(-3,-4,2,minecraft:terracotta)
B(-3,-3,2,minecraft:terracotta)
B(-3,-2,2,minecraft:coarse_dirt)
B(-3,-1,2,minecraft:coarse_dirt)
B(-3,0,2,minecraft:coarse_dirt)
B(-3,-27,3,minecraft:terracotta)
B(-3,-26,3,minecraft:terracotta)
B(-3,-25,3,minecraft:terracotta)
B(-3,-24,3,minecraft:terracotta)
B(-3,-23,3,minecraft:terracotta)
B(-3,-22,3,minecraft:terracotta)
B(-3,-21,3,minecraft:terracotta)
B(-3,-20,3,minecraft:terracotta)
B(-3,-19,3,minecraft:terracotta)
B(-3,-18,3,minecraft:terracotta)
B(-3,-17,3,minecraft:terracotta)
B(-3,-16,3,minecraft:terracotta)
B(-3,-15,3,minecraft:terracotta)
B(-3,-14,3,minecraft:terracotta)
B(-3,-13,3,minecraft:terracotta)
B(-3,-12,3,minecraft:terracotta)
B(-3,-11,3,minecraft:terracotta)
B(-3,-10,3,minecraft:terracotta)
B(-3,-9,3,minecraft:terracotta)
B(-3,-8,3,minecraft:terracotta)
B(-3,-7,3,minecraft:terracotta)
B(-3,-6,3,minecraft:terracotta)
B(-3,-5,3,minecraft:terracotta)
B(-3,-4,3,minecraft:terracotta)
B(-3,-3,3,minecraft:terracotta)
B(-3,-2,3,minecraft:coarse_dirt)
B(-3,-1,3,minecraft:coarse_dirt)
B(-3,0,3,minecraft:coarse_dirt)
B(-3,-27,4,minecraft:terracotta)
B(-3,-26,4,minecraft:terracotta)
B(-3,-25,4,minecraft:terracotta)
B(-3,-24,4,minecraft:terracotta)
B(-3,-23,4,minecraft:terracotta)
B(-3,-22,4,minecraft:terracotta)
B(-3,-21,4,minecraft:terracotta)
B(-3,-20,4,minecraft:terracotta)
B(-3,-19,4,minecraft:terracotta)
B(-3,-18,4,minecraft:terracotta)
B(-3,-17,4,minecraft:terracotta)
B(-3,-16,4,minecraft:terracotta)
B(-3,-15,4,minecraft:terracotta)
B(-3,-14,4,minecraft:terracotta)
B(-3,-13,4,minecraft:terracotta)
B(-3,-12,4,minecraft:terracotta)
B(-3,-11,4,minecraft:terracotta)
B(-3,-10,4,minecraft:terracotta)
B(-3,-9,4,minecraft:terracotta)
B(-3,-8,4,minecraft:terracotta)
B(-3,-7,4,minecraft:terracotta)
B(-3,-6,4,minecraft:terracotta)
B(-3,-5,4,minecraft:terracotta)
B(-3,-4,4,minecraft:terracotta)
B(-3,-3,4,minecraft:terracotta)
B(-3,-2,4,minecraft:coarse_dirt)
B(-3,-1,4,minecraft:coarse_dirt)
B(-3,-27,5,minecraft:terracotta)
B(-3,-26,5,minecraft:terracotta)
B(-3,-25,5,minecraft:terracotta)
B(-3,-24,5,minecraft:terracotta)
B(-3,-23,5,minecraft:terracotta)
B(-3,-22,5,minecraft:terracotta)
B(-3,-21,5,minecraft:terracotta)
B(-3,-20,5,minecraft:terracotta)
B(-3,-19,5,minecraft:terracotta)
B(-3,-18,5,minecraft:terracotta)
B(-3,-17,5,minecraft:terracotta)
B(-3,-16,5,minecraft:terracotta)
B(-3,-15,5,minecraft:terracotta)
B(-3,-14,5,minecraft:terracotta)
B(-3,-13,5,minecraft:terracotta)
B(-3,-12,5,minecraft:terracotta)
B(-3,-11,5,minecraft:terracotta)
B(-3,-10,5,minecraft:terracotta)
B(-3,-9,5,minecraft:terracotta)
B(-3,-8,5,minecraft:terracotta)
B(-3,-7,5,minecraft:terracotta)
B(-3,-6,5,minecraft:terracotta)
B(-3,-5,5,minecraft:terracotta)
B(-3,-4,5,minecraft:terracotta)
B(-3,-3,5,minecraft:coarse_dirt)
B(-3,-27,6,minecraft:terracotta)
B(-3,-26,6,minecraft:terracotta)
B(-3,-25,6,minecraft:terracotta)
B(-3,-24,6,minecraft:terracotta)
B(-3,-23,6,minecraft:terracotta)
B(-3,-22,6,minecraft:terracotta)
B(-3,-21,6,minecraft:terracotta)
B(-3,-20,6,minecraft:terracotta)
B(-3,-19,6,minecraft:terracotta)
B(-3,-18,6,minecraft:terracotta)
B(-3,-17,6,minecraft:terracotta)
B(-3,-16,6,minecraft:terracotta)
B(-3,-15,6,minecraft:terracotta)
B(-3,-14,6,minecraft:terracotta)
B(-3,-13,6,minecraft:terracotta)
B(-3,-12,6,minecraft:terracotta)
B(-3,-11,6,minecraft:terracotta)
B(-3,-10,6,minecraft:terracotta)
B(-3,-9,6,minecraft:terracotta)
B(-3,-8,6,minecraft:terracotta)
B(-3,-7,6,minecraft:terracotta)
B(-3,-6,6,minecraft:terracotta)
B(-3,-27,7,minecraft:terracotta)
B(-3,-26,7,minecraft:terracotta)
B(-3,-25,7,minecraft:terracotta)
B(-3,-24,7,minecraft:terracotta)
B(-3,-23,7,minecraft:terracotta)
B(-3,-22,7,minecraft:terracotta)
B(-3,-21,7,minecraft:terracotta)
B(-3,-20,7,minecraft:terracotta)
B(-3,-19,7,minecraft:terracotta)
B(-3,-18,7,minecraft:terracotta)
B(-3,-17,7,minecraft:terracotta)
B(-3,-16,7,minecraft:terracotta)
B(-3,-15,7,minecraft:terracotta)
B(-3,-14,7,minecraft:terracotta)
B(-3,-13,7,minecraft:terracotta)
B(-3,-27,8,minecraft:terracotta)
B(-3,-26,8,minecraft:terracotta)
B(-3,-25,8,minecraft:terracotta)
B(-3,-24,8,minecraft:terracotta)
B(-3,-23,8,minecraft:terracotta)
B(-3,-22,8,minecraft:terracotta)
B(-3,-21,8,minecraft:terracotta)
B(-3,-20,8,minecraft:terracotta)
B(-3,-19,8,minecraft:terracotta)
B(-3,-18,8,minecraft:terracotta)
B(-3,-17,8,minecraft:terracotta)
B(-3,-16,8,minecraft:terracotta)
B(-3,-15,8,minecraft:terracotta)
B(-3,-14,8,minecraft:terracotta)
B(-3,-27,9,minecraft:terracotta)
B(-3,-26,9,minecraft:terracotta)
B(-3,-25,9,minecraft:terracotta)
B(-3,-24,9,minecraft:terracotta)
B(-3,-23,9,minecraft:terracotta)
B(-3,-22,9,minecraft:terracotta)
B(-3,-21,9,minecraft:terracotta)
B(-3,-20,9,minecraft:terracotta)
B(-3,-19,9,minecraft:terracotta)
B(-3,-18,9,minecraft:terracotta)
B(-3,-17,9,minecraft:terracotta)
B(-3,-16,9,minecraft:terracotta)
B(-3,-27,10,minecraft:terracotta)
B(-3,-26,10,minecraft:terracotta)
B(-3,-25,10,minecraft:terracotta)
B(-3,-24,10,minecraft:terracotta)
B(-3,-23,10,minecraft:terracotta)
B(-3,-22,10,minecraft:terracotta)
B(-3,-21,10,minecraft:terracotta)
B(-3,-20,10,minecraft:terracotta)
B(-3,-19,10,minecraft:terracotta)
B(-3,-27,11,minecraft:terracotta)
B(-3,-26,11,minecraft:terracotta)
B(-3,-25,11,minecraft:terracotta)
B(-2,-27,-15,minecraft:terracotta)
B(-2,-26,-15,minecraft:terracotta)
B(-2,-27,-14,minecraft:terracotta)
B(-2,-26,-14,minecraft:terracotta)
B(-2,-25,-14,minecraft:terracotta)
B(-2,-24,-14,minecraft:terracotta)
B(-2,-23,-14,minecraft:terracotta)
B(-2,-22,-14,minecraft:terracotta)
B(-2,-21,-14,minecraft:terracotta)
B(-2,-27,-13,minecraft:terracotta)
B(-2,-26,-13,minecraft:terracotta)
B(-2,-25,-13,minecraft:terracotta)
B(-2,-24,-13,minecraft:terracotta)
B(-2,-23,-13,minecraft:terracotta)
B(-2,-22,-13,minecraft:terracotta)
B(-2,-21,-13,minecraft:terracotta)
B(-2,-20,-13,minecraft:terracotta)
B(-2,-19,-13,minecraft:terracotta)
B(-2,-18,-13,minecraft:terracotta)
B(-2,-17,-13,minecraft:terracotta)
B(-2,-16,-13,minecraft:terracotta)
B(-2,-15,-13,minecraft:terracotta)
B(-2,-27,-12,minecraft:terracotta)
B(-2,-26,-12,minecraft:terracotta)
B(-2,-25,-12,minecraft:terracotta)
B(-2,-24,-12,minecraft:terracotta)
B(-2,-23,-12,minecraft:terracotta)
B(-2,-22,-12,minecraft:terracotta)
B(-2,-21,-12,minecraft:terracotta)
B(-2,-20,-12,minecraft:terracotta)
B(-2,-19,-12,minecraft:terracotta)
B(-2,-18,-12,minecraft:terracotta)
B(-2,-17,-12,minecraft:terracotta)
B(-2,-16,-12,minecraft:terracotta)
B(-2,-15,-12,minecraft:terracotta)
B(-2,-14,-12,minecraft:terracotta)
B(-2,-27,-11,minecraft:terracotta)
B(-2,-26,-11,minecraft:terracotta)
B(-2,-25,-11,minecraft:terracotta)
B(-2,-24,-11,minecraft:terracotta)
B(-2,-23,-11,minecraft:terracotta)
B(-2,-22,-11,minecraft:terracotta)
B(-2,-21,-11,minecraft:terracotta)
B(-2,-20,-11,minecraft:terracotta)
B(-2,-19,-11,minecraft:terracotta)
B(-2,-18,-11,minecraft:terracotta)
B(-2,-17,-11,minecraft:terracotta)
B(-2,-16,-11,minecraft:terracotta)
B(-2,-15,-11,minecraft:terracotta)
B(-2,-14,-11,minecraft:terracotta)
B(-2,-13,-11,minecraft:terracotta)
B(-2,-27,-10,minecraft:terracotta)
B(-2,-26,-10,minecraft:terracotta)
B(-2,-25,-10,minecraft:terracotta)
B(-2,-24,-10,minecraft:terracotta)
B(-2,-23,-10,minecraft:terracotta)
B(-2,-22,-10,minecraft:terracotta)
B(-2,-21,-10,minecraft:terracotta)
B(-2,-20,-10,minecraft:terracotta)
B(-2,-19,-10,minecraft:terracotta)
B(-2,-18,-10,minecraft:terracotta)
B(-2,-17,-10,minecraft:terracotta)
B(-2,-16,-10,minecraft:terracotta)
B(-2,-15,-10,minecraft:terracotta)
B(-2,-14,-10,minecraft:terracotta)
B(-2,-13,-10,minecraft:terracotta)
B(-2,-12,-10,minecraft:terracotta)
B(-2,-27,-9,minecraft:terracotta)
B(-2,-26,-9,minecraft:terracotta)
B(-2,-25,-9,minecraft:terracotta)
B(-2,-24,-9,minecraft:terracotta)
B(-2,-23,-9,minecraft:terracotta)
B(-2,-22,-9,minecraft:terracotta)
B(-2,-21,-9,minecraft:terracotta)
B(-2,-20,-9,minecraft:terracotta)
B(-2,-19,-9,minecraft:terracotta)
B(-2,-18,-9,minecraft:terracotta)
B(-2,-17,-9,minecraft:terracotta)
B(-2,-16,-9,minecraft:terracotta)
B(-2,-15,-9,minecraft:terracotta)
B(-2,-14,-9,minecraft:terracotta)
B(-2,-13,-9,minecraft:terracotta)
B(-2,-12,-9,minecraft:terracotta)
B(-2,-11,-9,minecraft:terracotta)
B(-2,-27,-8,minecraft:terracotta)
B(-2,-26,-8,minecraft:terracotta)
B(-2,-25,-8,minecraft:terracotta)
B(-2,-24,-8,minecraft:terracotta)
B(-2,-23,-8,minecraft:terracotta)
B(-2,-22,-8,minecraft:terracotta)
B(-2,-21,-8,minecraft:terracotta)
B(-2,-20,-8,minecraft:terracotta)
B(-2,-19,-8,minecraft:terracotta)
B(-2,-18,-8,minecraft:terracotta)
B(-2,-17,-8,minecraft:terracotta)
B(-2,-16,-8,minecraft:terracotta)
B(-2,-15,-8,minecraft:terracotta)
B(-2,-14,-8,minecraft:terracotta)
B(-2,-13,-8,minecraft:terracotta)
B(-2,-12,-8,minecraft:terracotta)
B(-2,-11,-8,minecraft:terracotta)
B(-2,-10,-8,minecraft:terracotta)
B(-2,-9,-8,minecraft:terracotta)
B(-2,-8,-8,minecraft:terracotta)
B(-2,-7,-8,minecraft:terracotta)
B(-2,-6,-8,minecraft:terracotta)
B(-2,-5,-8,minecraft:terracotta)
B(-2,-4,-8,minecraft:terracotta)
B(-2,-27,-7,minecraft:terracotta)
B(-2,-26,-7,minecraft:terracotta)
B(-2,-25,-7,minecraft:terracotta)
B(-2,-24,-7,minecraft:terracotta)
B(-2,-23,-7,minecraft:terracotta)
B(-2,-22,-7,minecraft:terracotta)
B(-2,-21,-7,minecraft:terracotta)
B(-2,-20,-7,minecraft:terracotta)
B(-2,-19,-7,minecraft:terracotta)
B(-2,-18,-7,minecraft:terracotta)
B(-2,-17,-7,minecraft:terracotta)
B(-2,-16,-7,minecraft:terracotta)
B(-2,-15,-7,minecraft:terracotta)
B(-2,-14,-7,minecraft:terracotta)
B(-2,-13,-7,minecraft:terracotta)
B(-2,-12,-7,minecraft:terracotta)
B(-2,-11,-7,minecraft:terracotta)
B(-2,-10,-7,minecraft:terracotta)
B(-2,-9,-7,minecraft:terracotta)
B(-2,-8,-7,minecraft:terracotta)
B(-2,-7,-7,minecraft:terracotta)
B(-2,-6,-7,minecraft:terracotta)
B(-2,-5,-7,minecraft:terracotta)
B(-2,-4,-7,minecraft:terracotta)
B(-2,-3,-7,minecraft:terracotta)
B(-2,-2,-7,minecraft:coarse_dirt)
B(-2,-1,-7,minecraft:coarse_dirt)
B(-2,0,-7,minecraft:coarse_dirt)
B(-2,-27,-6,minecraft:terracotta)
B(-2,-26,-6,minecraft:terracotta)
B(-2,-25,-6,minecraft:terracotta)
B(-2,-24,-6,minecraft:terracotta)
B(-2,-23,-6,minecraft:terracotta)
B(-2,-22,-6,minecraft:terracotta)
B(-2,-21,-6,minecraft:terracotta)
B(-2,-20,-6,minecraft:terracotta)
B(-2,-19,-6,minecraft:terracotta)
B(-2,-18,-6,minecraft:terracotta)
B(-2,-17,-6,minecraft:terracotta)
B(-2,-16,-6,minecraft:terracotta)
B(-2,-15,-6,minecraft:terracotta)
B(-2,-14,-6,minecraft:terracotta)
B(-2,-13,-6,minecraft:terracotta)
B(-2,-12,-6,minecraft:terracotta)
B(-2,-11,-6,minecraft:terracotta)
B(-2,-10,-6,minecraft:terracotta)
B(-2,-9,-6,minecraft:terracotta)
B(-2,-8,-6,minecraft:terracotta)
B(-2,-7,-6,minecraft:terracotta)
B(-2,-6,-6,minecraft:terracotta)
B(-2,-5,-6,minecraft:terracotta)
B(-2,-4,-6,minecraft:terracotta)
B(-2,-3,-6,minecraft:terracotta)
B(-2,-2,-6,minecraft:terracotta)
B(-2,-1,-6,minecraft:coarse_dirt)
B(-2,0,-6,minecraft:coarse_dirt)
B(-2,-27,-5,minecraft:terracotta)
B(-2,-26,-5,minecraft:terracotta)
B(-2,-25,-5,minecraft:terracotta)
B(-2,-24,-5,minecraft:terracotta)
B(-2,-23,-5,minecraft:terracotta)
B(-2,-22,-5,minecraft:terracotta)
B(-2,-21,-5,minecraft:terracotta)
B(-2,-20,-5,minecraft:terracotta)
B(-2,-19,-5,minecraft:terracotta)
B(-2,-18,-5,minecraft:terracotta)
B(-2,-17,-5,minecraft:terracotta)
B(-2,-16,-5,minecraft:terracotta)
B(-2,-15,-5,minecraft:terracotta)
B(-2,-14,-5,minecraft:terracotta)
B(-2,-13,-5,minecraft:terracotta)
B(-2,-12,-5,minecraft:terracotta)
B(-2,-11,-5,minecraft:terracotta)
B(-2,-10,-5,minecraft:terracotta)
B(-2,-9,-5,minecraft:terracotta)
B(-2,-8,-5,minecraft:terracotta)
B(-2,-7,-5,minecraft:terracotta)
B(-2,-6,-5,minecraft:terracotta)
B(-2,-5,-5,minecraft:terracotta)
B(-2,-4,-5,minecraft:terracotta)
B(-2,-3,-5,minecraft:terracotta)
B(-2,-2,-5,minecraft:coarse_dirt)
B(-2,-1,-5,minecraft:coarse_dirt)
B(-2,0,-5,minecraft:coarse_dirt)
B(-2,-27,-4,minecraft:terracotta)
B(-2,-26,-4,minecraft:terracotta)
B(-2,-25,-4,minecraft:terracotta)
B(-2,-24,-4,minecraft:terracotta)
B(-2,-23,-4,minecraft:terracotta)
B(-2,-22,-4,minecraft:terracotta)
B(-2,-21,-4,minecraft:terracotta)
B(-2,-20,-4,minecraft:terracotta)
B(-2,-19,-4,minecraft:terracotta)
B(-2,-18,-4,minecraft:terracotta)
B(-2,-17,-4,minecraft:terracotta)
B(-2,-16,-4,minecraft:terracotta)
B(-2,-15,-4,minecraft:terracotta)
B(-2,-14,-4,minecraft:terracotta)
B(-2,-13,-4,minecraft:terracotta)
B(-2,-12,-4,minecraft:terracotta)
B(-2,-11,-4,minecraft:terracotta)
B(-2,-10,-4,minecraft:terracotta)
B(-2,-9,-4,minecraft:terracotta)
B(-2,-8,-4,minecraft:terracotta)
B(-2,-7,-4,minecraft:terracotta)
B(-2,-6,-4,minecraft:terracotta)
B(-2,-5,-4,minecraft:terracotta)
B(-2,-4,-4,minecraft:terracotta)
B(-2,-3,-4,minecraft:terracotta)
B(-2,-2,-4,minecraft:coarse_dirt)
B(-2,-1,-4,minecraft:coarse_dirt)
B(-2,0,-4,minecraft:coarse_dirt)
B(-2,-27,-3,minecraft:terracotta)
B(-2,-26,-3,minecraft:terracotta)
B(-2,-25,-3,minecraft:terracotta)
B(-2,-24,-3,minecraft:terracotta)
B(-2,-23,-3,minecraft:terracotta)
B(-2,-22,-3,minecraft:terracotta)
B(-2,-21,-3,minecraft:terracotta)
B(-2,-20,-3,minecraft:terracotta)
B(-2,-19,-3,minecraft:terracotta)
B(-2,-18,-3,minecraft:terracotta)
B(-2,-17,-3,minecraft:terracotta)
B(-2,-16,-3,minecraft:terracotta)
B(-2,-15,-3,minecraft:terracotta)
B(-2,-14,-3,minecraft:terracotta)
B(-2,-13,-3,minecraft:terracotta)
B(-2,-12,-3,minecraft:terracotta)
B(-2,-11,-3,minecraft:terracotta)
B(-2,-10,-3,minecraft:terracotta)
B(-2,-9,-3,minecraft:terracotta)
B(-2,-8,-3,minecraft:terracotta)
B(-2,-7,-3,minecraft:terracotta)
