
#######################################################################
# +-----------------------------------------------------------------+ #
# |                            BO3 object                           | #
# +-----------------------------------------------------------------+ #
#######################################################################

Author: Unknown

Description: Converted version of the BO2 OakForestLarge3

Version: 3

SettingsMode: WriteWithoutComments


#######################################################################
# +-----------------------------------------------------------------+ #
# |                          Main settings                          | #
# +-----------------------------------------------------------------+ #
#######################################################################

Tree: true

Frequency: 1

Rarity: 10.0

MaxSpawn: 0

RotateRandomly: true

SpawnHeight: highestSolidBlock

SpawnHeightOffset: 0

SpawnHeightVariance: 0

##############################
# Height Limits for the BO3. #
##############################

MinHeight: 63

MaxHeight: 210

######################
# Extrusion settings #
######################

ExtrudeMode: None

ExtrudeThroughBlocks: otg:air

MaxBranchDepth: 10


#######################################################################
# +-----------------------------------------------------------------+ #
# |                      Source block settings                      | #
# +-----------------------------------------------------------------+ #
#######################################################################

SourceBlocks: otg:dirt,minecraft:sand,otg:stained_clay,otg:sandstone,otg:air,otg:stone,otg:long_grass,minecraft:granite,minecraft:diorite,minecraft:andesite,minecraft:coarse_dirt,minecraft:grass_block,minecraft:podzol,minecraft:water,minecraft:terracotta,minecraft:clay,minecraft:red_sand,minecraft:gravel,minecraft:grass,minecraft:fern,minecraft:dead_bush,minecraft:dandelion,minecraft:poppy,minecraft:brown_mushroom,minecraft:red_mushroom

MaxPercentageOutsideSourceBlock: 0

OutsideSourceBlock: placeAnyway

DoReplaceBlocks: true

IsOTGPlus: false


#######################################################################
# +-----------------------------------------------------------------+ #
# |                              Blocks                             | #
# +-----------------------------------------------------------------+ #
#######################################################################

B(-4,7,2,minecraft:oak_leaves)
B(-4,6,2,minecraft:oak_leaves)
B(-4,5,2,minecraft:oak_log)
B(-4,4,2,minecraft:oak_leaves)
B(1,8,-4,minecraft:oak_log)
B(1,9,-4,minecraft:oak_leaves)
B(1,6,-4,minecraft:oak_leaves)
B(-2,13,-3,minecraft:oak_leaves)
B(1,7,-4,minecraft:oak_log)
B(-2,12,-3,minecraft:oak_leaves)
B(-3,7,4,minecraft:oak_log)
B(-3,6,4,minecraft:oak_log)
B(-3,9,4,minecraft:oak_leaves)
B(-3,8,4,minecraft:oak_leaves)
B(-3,5,4,minecraft:oak_leaves)
B(-4,13,-1,minecraft:oak_leaves)
B(-4,12,-1,minecraft:oak_leaves)
B(-3,10,2,minecraft:oak_leaves)
B(-4,11,-1,minecraft:oak_leaves)
B(-4,10,-1,minecraft:oak_log)
B(-6,11,0,minecraft:oak_leaves)
B(-3,12,2,minecraft:oak_leaves)
B(-2,9,6,minecraft:oak_leaves)
B(-3,11,2,minecraft:oak_leaves)
B(-2,8,6,minecraft:oak_leaves)
B(-2,11,-3,minecraft:oak_leaves)
B(-2,10,-3,minecraft:oak_leaves)
B(-3,4,-2,minecraft:oak_leaves)
B(-3,5,-2,minecraft:oak_leaves)
B(-3,6,-2,minecraft:oak_leaves)
B(1,10,1,minecraft:oak_leaves)
B(-3,7,-2,minecraft:oak_leaves)
B(1,11,1,minecraft:oak_leaves)
B(-3,8,-2,minecraft:oak_leaves)
B(-3,9,-2,minecraft:oak_leaves)
B(1,14,-1,minecraft:oak_leaves)
B(-2,10,-4,minecraft:oak_leaves)
B(-2,11,-4,minecraft:oak_leaves)
B(-2,12,-4,minecraft:oak_leaves)
B(-7,10,2,minecraft:oak_leaves)
B(-4,5,1,minecraft:oak_leaves)
B(1,9,-3,minecraft:oak_leaves)
B(1,7,-3,minecraft:oak_leaves)
B(1,8,-3,minecraft:oak_leaves)
B(1,5,-3,minecraft:oak_leaves)
B(-3,8,3,minecraft:oak_leaves)
B(1,10,2,minecraft:oak_leaves)
B(1,6,-3,minecraft:oak_log)
B(-3,7,3,minecraft:oak_leaves)
B(1,11,2,minecraft:oak_leaves)
B(1,12,2,minecraft:oak_leaves)
B(1,13,2,minecraft:oak_leaves)
B(-3,4,3,minecraft:oak_leaves)
B(1,13,-1,minecraft:oak_log[axis=x])
B(1,12,-1,minecraft:oak_leaves)
B(-3,6,3,minecraft:oak_leaves)
B(1,11,-1,minecraft:oak_leaves)
B(-3,5,3,minecraft:oak_log)
B(1,10,-1,minecraft:oak_log)
B(-6,12,0,minecraft:oak_leaves)
B(-6,13,0,minecraft:oak_leaves)
B(-4,10,5,minecraft:oak_leaves)
B(-2,9,5,minecraft:oak_log)
B(-2,8,5,minecraft:oak_log)
B(-4,11,5,minecraft:oak_leaves)
B(-2,7,5,minecraft:oak_leaves)
B(-3,7,-1,minecraft:oak_leaves)
B(-3,8,-1,minecraft:oak_log)
B(-3,9,-1,minecraft:oak_leaves)
B(-3,11,3,minecraft:oak_leaves)
B(-3,10,3,minecraft:oak_leaves)
B(-4,8,4,minecraft:oak_leaves)
B(-4,7,4,minecraft:oak_leaves)
B(-4,6,4,minecraft:oak_leaves)
B(0,5,0,minecraft:oak_leaves)
B(0,4,0,minecraft:oak_leaves)
B(0,6,0,minecraft:oak_leaves)
B(-4,9,4,minecraft:oak_leaves)
B(-2,13,0,minecraft:oak_leaves)
B(-2,12,0,minecraft:oak_leaves)
B(-2,14,0,minecraft:oak_leaves)
B(-2,11,0,minecraft:oak_leaves)
B(-2,10,0,minecraft:oak_leaves)
B(-2,9,-5,minecraft:oak_leaves)
B(-3,9,6,minecraft:oak_leaves)
B(-3,8,6,minecraft:oak_leaves)
B(1,8,-2,minecraft:oak_leaves)
B(1,9,-2,minecraft:oak_leaves)
B(1,6,-2,minecraft:oak_leaves)
B(1,7,-2,minecraft:oak_leaves)
B(-3,7,6,minecraft:oak_leaves)
B(1,5,-2,minecraft:oak_leaves)
B(-4,8,-1,minecraft:oak_leaves)
B(-4,11,-3,minecraft:oak_leaves)
B(-4,12,-3,minecraft:oak_leaves)
B(-4,9,-1,minecraft:oak_log)
B(-4,13,-3,minecraft:oak_leaves)
B(-4,10,3,minecraft:oak_leaves)
B(-5,7,1,minecraft:oak_leaves)
B(-2,13,-4,minecraft:oak_leaves)
B(-2,14,-4,minecraft:oak_leaves)
B(-2,15,-4,minecraft:oak_leaves)
B(2,9,-1,minecraft:oak_leaves)
B(2,8,-1,minecraft:oak_leaves)
B(2,7,-1,minecraft:oak_leaves)
B(0,9,1,minecraft:oak_leaves)
B(-6,10,1,minecraft:oak_leaves)
B(-5,6,1,minecraft:oak_leaves)
B(-4,9,3,minecraft:oak_leaves)
B(-4,8,3,minecraft:oak_leaves)
B(-4,7,3,minecraft:oak_leaves)
B(-4,6,3,minecraft:oak_leaves)
B(-4,10,4,minecraft:oak_leaves)
B(-1,10,6,minecraft:oak_leaves)
B(-4,5,3,minecraft:oak_leaves)
B(-3,9,5,minecraft:oak_leaves)
B(1,9,-1,minecraft:oak_leaves)
B(-3,6,5,minecraft:oak_leaves)
B(1,7,-1,minecraft:oak_leaves)
B(1,8,-1,minecraft:oak_leaves)
B(-3,8,5,minecraft:oak_leaves)
B(1,6,-1,minecraft:oak_leaves)
B(-3,7,5,minecraft:oak_leaves)
B(-6,11,2,minecraft:oak_leaves)
B(-6,10,2,minecraft:oak_leaves)
B(-3,10,4,minecraft:oak_leaves)
B(-2,9,7,minecraft:oak_leaves)
B(-2,10,-5,minecraft:oak_leaves)
B(-2,11,-5,minecraft:oak_leaves)
B(-5,7,2,minecraft:oak_log)
B(-5,6,2,minecraft:oak_log)
B(-5,9,2,minecraft:oak_leaves)
B(1,10,3,minecraft:oak_leaves)
B(-5,8,2,minecraft:oak_leaves)
B(1,11,3,minecraft:oak_leaves)
B(2,8,-2,minecraft:oak_log)
B(0,9,0,minecraft:oak_leaves)
B(2,7,-2,minecraft:oak_log)
B(2,6,-2,minecraft:oak_leaves)
B(-5,5,2,minecraft:oak_leaves)
B(2,9,-2,minecraft:oak_leaves)
B(-4,9,6,minecraft:oak_leaves)
B(0,8,-4,minecraft:oak_leaves)
B(-4,8,6,minecraft:oak_leaves)
B(0,7,-4,minecraft:oak_leaves)
B(-4,11,2,minecraft:oak_leaves)
B(-4,10,2,minecraft:oak_leaves)
B(-2,9,-3,minecraft:oak_log[axis=z])
B(-2,8,-3,minecraft:oak_leaves)
B(0,13,1,minecraft:oak_leaves)
B(0,12,1,minecraft:oak_leaves)
B(-5,10,5,minecraft:oak_leaves)
B(0,9,-4,minecraft:oak_leaves)
B(0,11,1,minecraft:oak_leaves)
B(-2,5,-3,minecraft:oak_leaves)
B(0,10,1,minecraft:oak_leaves)
B(-2,4,-3,minecraft:oak_leaves)
B(-4,6,-3,minecraft:oak_leaves)
B(-4,5,-3,minecraft:oak_leaves)
B(-6,9,1,minecraft:oak_leaves)
B(-6,8,1,minecraft:oak_leaves)
B(-5,6,3,minecraft:oak_leaves)
B(-5,8,3,minecraft:oak_leaves)
B(-1,10,-2,minecraft:oak_leaves)
B(-5,7,3,minecraft:oak_leaves)
B(-1,11,-2,minecraft:oak_log[axis=z])
B(4,7,2,minecraft:oak_leaves)
B(4,6,2,minecraft:oak_leaves)
B(-5,9,3,minecraft:oak_leaves)
B(2,7,-3,minecraft:oak_leaves)
B(-3,10,5,minecraft:oak_leaves)
B(2,6,-3,minecraft:oak_leaves)
B(2,9,-3,minecraft:oak_leaves)
B(2,8,-3,minecraft:oak_leaves)
B(-4,7,5,minecraft:oak_leaves)
B(-4,9,5,minecraft:oak_log)
B(-4,8,5,minecraft:oak_log)
B(-2,12,-1,minecraft:oak_leaves)
B(-2,13,-1,minecraft:oak_leaves)
B(-2,10,-1,minecraft:oak_leaves)
B(-3,9,7,minecraft:oak_leaves)
B(-1,10,-1,minecraft:oak_log)
B(-2,11,-1,minecraft:oak_leaves)
B(-2,16,-1,minecraft:oak_leaves)
B(-2,17,-1,minecraft:oak_leaves)
B(-2,8,-4,minecraft:oak_leaves)
B(-2,14,-1,minecraft:oak_leaves)
B(-2,9,-4,minecraft:oak_log[axis=z])
B(-2,15,-1,minecraft:oak_leaves)
B(-5,13,-2,minecraft:oak_leaves)
B(2,10,1,minecraft:oak_leaves)
B(-5,12,-2,minecraft:oak_leaves)
B(-4,9,-2,minecraft:oak_leaves)
B(-5,11,-2,minecraft:oak_leaves)
B(-1,15,-1,minecraft:oak_log)
B(-2,13,1,minecraft:oak_leaves)
B(-1,16,-1,minecraft:oak_log)
B(-1,17,-1,minecraft:oak_leaves)
B(-6,9,2,minecraft:oak_log)
B(-1,18,-1,minecraft:oak_leaves)
B(-6,8,2,minecraft:oak_log)
B(-2,10,1,minecraft:oak_leaves)
B(-1,11,-1,minecraft:oak_log)
B(-6,7,2,minecraft:oak_leaves)
B(-1,12,-1,minecraft:oak_log)
B(-6,6,2,minecraft:oak_leaves)
B(-2,12,1,minecraft:oak_leaves)
B(-1,13,-1,minecraft:oak_log)
B(-2,11,1,minecraft:oak_leaves)
B(-1,14,-1,minecraft:oak_log)
B(0,13,0,minecraft:oak_leaves)
B(0,12,0,minecraft:oak_leaves)
B(-5,9,4,minecraft:oak_leaves)
B(-5,8,4,minecraft:oak_leaves)
B(-5,10,4,minecraft:oak_leaves)
B(0,10,0,minecraft:oak_leaves)
B(2,9,-4,minecraft:oak_leaves)
B(2,8,-4,minecraft:oak_leaves)
B(2,7,-4,minecraft:oak_leaves)
B(0,4,-2,minecraft:oak_leaves)
B(0,6,-2,minecraft:oak_leaves)
B(0,5,-2,minecraft:oak_log[axis=z])
B(0,8,-2,minecraft:oak_leaves)
B(0,7,-2,minecraft:oak_leaves)
B(0,9,-2,minecraft:oak_leaves)
B(-2,10,-2,minecraft:oak_leaves)
B(2,13,0,minecraft:oak_leaves)
B(2,14,0,minecraft:oak_leaves)
B(2,15,0,minecraft:oak_leaves)
B(-1,10,-3,minecraft:oak_leaves)
B(-2,10,3,minecraft:oak_leaves)
B(-1,12,-3,minecraft:oak_log)
B(-2,9,-1,minecraft:oak_leaves)
B(-1,11,-3,minecraft:oak_leaves)
B(-2,4,-1,minecraft:oak_leaves)
B(-2,3,-1,minecraft:oak_leaves)
B(-2,8,-1,minecraft:oak_leaves)
B(-2,7,-1,minecraft:oak_log[axis=x])
B(-2,6,-1,minecraft:oak_leaves)
B(-2,5,-1,minecraft:oak_leaves)
B(-3,10,6,minecraft:oak_leaves)
B(-6,9,3,minecraft:oak_leaves)
B(-6,8,3,minecraft:oak_leaves)
B(-1,14,-3,minecraft:oak_leaves)
B(-1,13,-3,minecraft:oak_leaves)
B(-2,11,3,minecraft:oak_leaves)
B(1,10,5,minecraft:oak_leaves)
B(-5,8,5,minecraft:oak_leaves)
B(-4,12,0,minecraft:oak_leaves)
B(0,13,2,minecraft:oak_leaves)
B(-4,13,0,minecraft:oak_leaves)
B(0,14,2,minecraft:oak_leaves)
B(-4,10,0,minecraft:oak_leaves)
B(-5,9,5,minecraft:oak_leaves)
B(-4,11,0,minecraft:oak_leaves)
B(-3,10,-1,minecraft:oak_leaves)
B(0,10,2,minecraft:oak_leaves)
B(-3,11,-1,minecraft:oak_leaves)
B(0,11,2,minecraft:oak_log)
B(-4,14,-2,minecraft:oak_leaves)
B(-3,12,-1,minecraft:oak_leaves)
B(0,12,2,minecraft:oak_log)
B(-4,13,-2,minecraft:oak_leaves)
B(-4,12,-2,minecraft:oak_log)
B(-3,13,-1,minecraft:oak_leaves)
B(-4,11,-2,minecraft:oak_log)
B(-4,10,-2,minecraft:oak_leaves)
B(-5,12,-1,minecraft:oak_leaves)
B(-5,11,-1,minecraft:oak_leaves)
B(0,5,-3,minecraft:oak_leaves)
B(-5,13,-1,minecraft:oak_leaves)
B(0,7,-3,minecraft:oak_leaves)
B(0,6,-3,minecraft:oak_leaves)
B(0,9,-3,minecraft:oak_leaves)
B(-5,10,-1,minecraft:oak_leaves)
B(0,8,-3,minecraft:oak_leaves)
B(-1,16,-2,minecraft:oak_leaves)
B(-1,17,-2,minecraft:oak_leaves)
B(-1,12,-2,minecraft:oak_leaves)
B(-2,12,2,minecraft:oak_leaves)
B(-1,13,-2,minecraft:oak_leaves)
B(-2,10,2,minecraft:oak_log[axis=x])
B(-1,14,-2,minecraft:oak_leaves)
B(-2,11,2,minecraft:oak_leaves)
B(-1,15,-2,minecraft:oak_leaves)
B(-2,9,-2,minecraft:oak_leaves)
B(-2,8,-2,minecraft:oak_leaves)
B(-4,12,1,minecraft:oak_leaves)
B(-4,11,1,minecraft:oak_leaves)
B(-2,3,-2,minecraft:oak_leaves)
B(-7,9,2,minecraft:oak_leaves)
B(-7,8,2,minecraft:oak_leaves)
B(-2,7,-2,minecraft:oak_leaves)
B(-2,6,-2,minecraft:oak_leaves)
B(-2,5,-2,minecraft:oak_leaves)
B(-2,4,-2,minecraft:oak_log[axis=z])
B(-4,10,1,minecraft:oak_leaves)
B(-2,13,-2,minecraft:oak_leaves)
B(-2,12,-2,minecraft:oak_leaves)
B(-2,11,-2,minecraft:oak_leaves)
B(1,9,4,minecraft:oak_leaves)
B(1,8,4,minecraft:oak_leaves)
B(1,7,4,minecraft:oak_leaves)
B(1,6,4,minecraft:oak_log)
B(1,5,4,minecraft:oak_log)
B(1,4,4,minecraft:oak_leaves)
B(-1,15,-4,minecraft:oak_leaves)
B(-1,14,-4,minecraft:oak_log)
B(-1,16,-4,minecraft:oak_leaves)
B(2,9,2,minecraft:oak_leaves)
B(2,8,2,minecraft:oak_leaves)
B(2,5,2,minecraft:oak_log)
B(2,4,2,minecraft:oak_leaves)
B(2,7,2,minecraft:oak_leaves)
B(2,6,2,minecraft:oak_log)
B(-3,11,-2,minecraft:oak_leaves)
B(-1,10,1,minecraft:oak_log)
B(-3,13,-2,minecraft:oak_leaves)
B(-1,11,1,minecraft:oak_leaves)
B(-3,12,-2,minecraft:oak_leaves)
B(-1,12,1,minecraft:oak_leaves)
B(-1,5,0,minecraft:oak_leaves)
B(-1,4,0,minecraft:oak_log[axis=z])
B(-1,7,0,minecraft:oak_leaves)
B(-1,6,0,minecraft:oak_leaves)
B(-1,9,0,minecraft:oak_log[axis=z])
B(-1,8,0,minecraft:oak_leaves)
B(-1,9,-3,minecraft:oak_leaves)
B(-1,8,-3,minecraft:oak_leaves)
B(-1,7,-3,minecraft:oak_leaves)
B(-5,10,2,minecraft:oak_leaves)
B(1,3,3,minecraft:oak_leaves)
B(0,5,-1,minecraft:oak_leaves)
B(1,9,5,minecraft:oak_leaves)
B(3,7,-2,minecraft:oak_leaves)
B(1,8,5,minecraft:oak_log)
B(0,7,-1,minecraft:oak_leaves)
B(1,7,5,minecraft:oak_log)
B(3,8,-2,minecraft:oak_leaves)
B(0,6,-1,minecraft:oak_leaves)
B(1,6,5,minecraft:oak_leaves)
B(3,9,-2,minecraft:oak_leaves)
B(1,5,5,minecraft:oak_leaves)
B(0,9,-1,minecraft:oak_log[axis=x])
B(0,8,-1,minecraft:oak_leaves)
B(-3,10,-3,minecraft:oak_leaves)
B(2,8,3,minecraft:oak_leaves)
B(2,7,3,minecraft:oak_leaves)
B(2,4,3,minecraft:oak_leaves)
B(2,6,3,minecraft:oak_leaves)
B(2,5,3,minecraft:oak_leaves)
B(0,10,3,minecraft:oak_leaves)
B(0,11,3,minecraft:oak_leaves)
B(0,12,3,minecraft:oak_leaves)
B(0,13,3,minecraft:oak_leaves)
B(-1,6,-2,minecraft:oak_leaves)
B(3,7,1,minecraft:oak_leaves)
B(0,16,-1,minecraft:oak_leaves)
B(-1,5,-2,minecraft:oak_leaves)
B(3,6,1,minecraft:oak_leaves)
B(0,15,-1,minecraft:oak_leaves)
B(-1,4,-2,minecraft:oak_leaves)
B(0,17,-1,minecraft:oak_leaves)
B(3,9,1,minecraft:oak_leaves)
B(3,8,1,minecraft:oak_leaves)
B(-5,12,1,minecraft:oak_leaves)
B(-1,9,-2,minecraft:oak_leaves)
B(-5,13,1,minecraft:oak_leaves)
B(-1,8,-2,minecraft:oak_log[axis=z])
B(-1,7,-2,minecraft:oak_leaves)
B(-1,10,-4,minecraft:oak_leaves)
B(-2,10,4,minecraft:oak_leaves)
B(-1,13,-4,minecraft:oak_log)
B(-1,12,-4,minecraft:oak_leaves)
B(-1,10,2,minecraft:oak_leaves)
B(-3,12,-3,minecraft:oak_leaves)
B(-3,11,-3,minecraft:oak_leaves)
B(0,10,-1,minecraft:oak_leaves)
B(-1,12,2,minecraft:oak_leaves)
B(-1,11,2,minecraft:oak_leaves)
B(0,12,-1,minecraft:oak_leaves)
B(0,11,-1,minecraft:oak_leaves)
B(-1,13,2,minecraft:oak_leaves)
B(0,9,6,minecraft:oak_leaves)
B(0,14,-1,minecraft:oak_leaves)
B(0,13,-1,minecraft:oak_log[axis=x])
B(1,8,6,minecraft:oak_leaves)
B(1,7,6,minecraft:oak_leaves)
B(2,7,4,minecraft:oak_leaves)
B(2,6,4,minecraft:oak_leaves)
B(2,5,4,minecraft:oak_leaves)
B(-1,3,2,minecraft:oak_leaves)
B(3,6,2,minecraft:oak_leaves)
B(3,5,2,minecraft:oak_leaves)
B(-1,5,2,minecraft:oak_leaves)
B(-1,4,2,minecraft:oak_leaves)
B(-3,10,-4,minecraft:oak_leaves)
B(-1,6,2,minecraft:oak_leaves)
B(-3,11,-4,minecraft:oak_leaves)
B(3,8,2,minecraft:oak_leaves)
B(-1,9,2,minecraft:oak_leaves)
B(3,7,2,minecraft:oak_leaves)
B(-2,9,0,minecraft:oak_leaves)
B(-2,8,0,minecraft:oak_leaves)
B(-2,7,0,minecraft:oak_leaves)
B(-2,4,0,minecraft:oak_leaves)
B(1,10,-4,minecraft:oak_leaves)
B(-1,15,0,minecraft:oak_leaves)
B(-1,16,0,minecraft:oak_leaves)
B(-1,17,0,minecraft:oak_leaves)
B(-1,10,0,minecraft:oak_leaves)
B(-1,11,0,minecraft:oak_leaves)
B(-1,12,0,minecraft:oak_leaves)
B(-1,13,0,minecraft:oak_leaves)
B(-1,14,0,minecraft:oak_leaves)
B(-1,13,-5,minecraft:oak_leaves)
B(-5,10,3,minecraft:oak_leaves)
B(-2,11,5,minecraft:oak_leaves)
B(-1,14,-5,minecraft:oak_leaves)
B(2,8,5,minecraft:oak_leaves)
B(-2,10,5,minecraft:oak_leaves)
B(2,7,5,minecraft:oak_leaves)
B(2,9,5,minecraft:oak_leaves)
B(-5,9,-1,minecraft:oak_leaves)
B(-1,4,1,minecraft:oak_log[axis=z])
B(3,5,3,minecraft:oak_leaves)
B(-1,3,1,minecraft:oak_leaves)
B(-1,6,1,minecraft:oak_leaves)
B(-1,5,1,minecraft:oak_leaves)
B(3,7,3,minecraft:oak_leaves)
B(3,6,3,minecraft:oak_leaves)
B(-1,9,1,minecraft:oak_leaves)
B(-1,9,-4,minecraft:oak_leaves)
B(-1,8,-4,minecraft:oak_leaves)
B(-1,15,-5,minecraft:oak_leaves)
B(0,11,4,minecraft:oak_leaves)
B(0,12,4,minecraft:oak_leaves)
B(0,10,4,minecraft:oak_leaves)
B(0,3,2,minecraft:oak_leaves)
B(-3,11,-5,minecraft:oak_leaves)
B(-1,10,4,minecraft:oak_leaves)
B(-3,12,-5,minecraft:oak_leaves)
B(0,5,2,minecraft:oak_leaves)
B(1,8,0,minecraft:oak_leaves)
B(0,4,2,minecraft:oak_log[axis=z])
B(-3,10,-5,minecraft:oak_log)
B(2,14,-2,minecraft:oak_leaves)
B(2,15,-2,minecraft:oak_leaves)
B(2,13,-2,minecraft:oak_leaves)
B(2,10,-2,minecraft:oak_leaves)
B(1,12,-3,minecraft:oak_leaves)
B(1,13,-3,minecraft:oak_leaves)
B(1,14,-3,minecraft:oak_leaves)
B(0,13,-4,minecraft:oak_leaves)
B(-3,9,0,minecraft:oak_leaves)
B(-3,8,0,minecraft:oak_leaves)
B(0,14,-4,minecraft:oak_leaves)
B(0,15,-4,minecraft:oak_leaves)
B(-1,5,4,minecraft:oak_leaves)
B(-1,7,4,minecraft:oak_leaves)
B(-1,6,4,minecraft:oak_leaves)
B(-2,9,2,minecraft:oak_leaves)
B(-1,9,4,minecraft:oak_leaves)
B(-1,8,4,minecraft:oak_leaves)
B(-2,6,2,minecraft:oak_leaves)
B(-2,5,2,minecraft:oak_leaves)
B(-2,4,2,minecraft:oak_leaves)
B(-2,3,2,minecraft:oak_leaves)
B(0,6,3,minecraft:oak_leaves)
B(0,5,3,minecraft:oak_leaves)
B(0,9,3,minecraft:oak_leaves)
B(0,4,1,minecraft:oak_leaves)
B(1,9,1,minecraft:oak_leaves)
B(1,8,1,minecraft:oak_leaves)
B(0,6,1,minecraft:oak_leaves)
B(1,7,1,minecraft:oak_leaves)
B(0,5,1,minecraft:oak_leaves)
B(1,6,1,minecraft:oak_leaves)
B(-4,11,-5,minecraft:oak_leaves)
B(-4,10,-5,minecraft:oak_leaves)
B(-3,11,0,minecraft:oak_leaves)
B(-3,12,0,minecraft:oak_leaves)
B(-1,4,3,minecraft:oak_leaves)
B(-3,10,0,minecraft:oak_leaves)
B(-1,6,3,minecraft:oak_leaves)
B(-1,10,5,minecraft:oak_leaves)
B(-1,5,3,minecraft:oak_leaves)
B(-3,11,-6,minecraft:oak_leaves)
B(-3,13,0,minecraft:oak_leaves)
B(-3,10,-6,minecraft:oak_leaves)
B(-2,5,1,minecraft:oak_leaves)
B(-2,4,1,minecraft:oak_log[axis=x])
B(-2,3,1,minecraft:oak_leaves)
B(1,6,0,minecraft:oak_leaves)
B(0,6,2,minecraft:oak_leaves)
B(-6,10,3,minecraft:oak_leaves)
B(0,9,2,minecraft:oak_leaves)
B(-3,9,-5,minecraft:oak_leaves)
B(-4,9,0,minecraft:oak_leaves)
B(1,9,2,minecraft:oak_leaves)
B(1,6,2,minecraft:oak_leaves)
B(1,5,2,minecraft:oak_leaves)
B(-5,11,1,minecraft:oak_leaves)
B(2,7,0,minecraft:oak_leaves)
B(2,6,0,minecraft:oak_leaves)
B(2,9,0,minecraft:oak_leaves)
B(2,8,0,minecraft:oak_leaves)
B(-3,5,2,minecraft:oak_leaves)
B(-3,4,2,minecraft:oak_log[axis=x])
B(-3,6,2,minecraft:oak_leaves)
B(-3,3,2,minecraft:oak_leaves)
B(-1,7,-1,minecraft:oak_log)
B(-1,6,-1,minecraft:oak_log)
B(-1,5,-1,minecraft:oak_log)
B(-1,4,-1,minecraft:oak_log)
B(-1,3,-1,minecraft:oak_log)
B(-1,2,-1,minecraft:oak_log)
B(-2,9,4,minecraft:oak_leaves)
B(-1,1,-1,minecraft:oak_log)
B(-2,8,4,minecraft:oak_leaves)
B(1,13,0,minecraft:oak_leaves)
B(-1,0,-1,minecraft:oak_log)
B(-2,7,4,minecraft:oak_leaves)
B(1,12,0,minecraft:oak_leaves)
B(-2,6,4,minecraft:oak_leaves)
B(-1,7,6,minecraft:oak_leaves)
B(1,11,0,minecraft:oak_leaves)
B(-2,5,4,minecraft:oak_leaves)
B(1,10,0,minecraft:oak_leaves)
B(-1,9,6,minecraft:oak_leaves)
B(-1,8,6,minecraft:oak_leaves)
B(2,14,-1,minecraft:oak_log)
B(2,13,-1,minecraft:oak_leaves)
B(-1,9,-1,minecraft:oak_log)
B(2,16,-1,minecraft:oak_leaves)
B(-1,8,-1,minecraft:oak_log)
B(2,15,-1,minecraft:oak_leaves)
B(2,10,-1,minecraft:oak_leaves)
B(2,12,-1,minecraft:oak_leaves)
B(2,11,-1,minecraft:oak_leaves)
B(-3,5,-4,minecraft:oak_leaves)
B(-3,6,-4,minecraft:oak_leaves)
B(1,5,1,minecraft:oak_leaves)
B(0,11,-3,minecraft:oak_leaves)
B(0,12,-3,minecraft:oak_leaves)
B(0,6,5,minecraft:oak_leaves)
B(-3,9,-4,minecraft:oak_leaves)
B(0,10,-3,minecraft:oak_leaves)
B(0,8,5,minecraft:oak_leaves)
B(0,7,5,minecraft:oak_leaves)
B(0,13,-3,minecraft:oak_leaves)
B(0,9,5,minecraft:oak_leaves)
B(0,14,-3,minecraft:oak_leaves)
B(-3,12,1,minecraft:oak_leaves)
B(1,9,3,minecraft:oak_leaves)
B(-3,10,1,minecraft:oak_leaves)
B(1,8,3,minecraft:oak_leaves)
B(-3,11,1,minecraft:oak_leaves)
B(1,7,3,minecraft:oak_leaves)
B(1,6,3,minecraft:oak_leaves)
B(0,4,3,minecraft:oak_leaves)
B(1,5,3,minecraft:oak_leaves)
B(1,4,3,minecraft:oak_log[axis=z])
B(-5,14,0,minecraft:oak_leaves)
B(-5,13,0,minecraft:oak_leaves)
B(-5,12,0,minecraft:oak_log)
B(-5,11,0,minecraft:oak_log)
B(1,9,-5,minecraft:oak_leaves)
B(1,7,-5,minecraft:oak_leaves)
B(1,8,-5,minecraft:oak_leaves)
B(2,9,1,minecraft:oak_leaves)
B(2,6,1,minecraft:oak_leaves)
B(2,5,1,minecraft:oak_leaves)
B(-3,9,1,minecraft:oak_leaves)
B(2,8,1,minecraft:oak_log)
B(2,7,1,minecraft:oak_log)
B(-1,11,3,minecraft:oak_leaves)
B(-1,10,3,minecraft:oak_leaves)
B(0,11,-2,minecraft:oak_leaves)
B(0,10,-2,minecraft:oak_leaves)
B(-1,12,3,minecraft:oak_leaves)
B(0,13,-2,minecraft:oak_leaves)
B(0,12,-2,minecraft:oak_leaves)
B(-3,4,1,minecraft:oak_leaves)
B(0,14,-2,minecraft:oak_leaves)
B(-1,8,5,minecraft:oak_leaves)
B(-2,6,3,minecraft:oak_leaves)
B(-1,7,5,minecraft:oak_leaves)
B(-2,5,3,minecraft:oak_leaves)
B(-2,4,3,minecraft:oak_leaves)
B(-1,9,5,minecraft:oak_leaves)
B(1,10,-2,minecraft:oak_leaves)
B(-3,4,-3,minecraft:oak_leaves)
B(-5,10,0,minecraft:oak_leaves)
B(1,11,-2,minecraft:oak_leaves)
B(3,12,-1,minecraft:oak_leaves)
B(-3,5,-3,minecraft:oak_log)
B(1,12,-2,minecraft:oak_leaves)
B(3,13,-1,minecraft:oak_leaves)
B(-3,6,-3,minecraft:oak_leaves)
B(1,13,-2,minecraft:oak_leaves)
B(3,14,-1,minecraft:oak_leaves)
B(-3,7,-3,minecraft:oak_leaves)
B(1,14,-2,minecraft:oak_leaves)
B(3,15,-1,minecraft:oak_leaves)
B(1,4,2,minecraft:oak_leaves)
B(0,5,4,minecraft:oak_leaves)
B(-3,9,-3,minecraft:oak_leaves)
B(0,7,4,minecraft:oak_leaves)
B(0,6,4,minecraft:oak_leaves)
B(0,9,4,minecraft:oak_leaves)
B(0,8,4,minecraft:oak_leaves)

#######################################################################
# +-----------------------------------------------------------------+ #
# |                            BO3 checks                           | #
# +-----------------------------------------------------------------+ #
#######################################################################

BlockCheck(-1,-1,-1,otg:dirt,minecraft:grass_block,minecraft:podzol)

#######################################################################
# +-----------------------------------------------------------------+ #
# |                             Branches                            | #
# +-----------------------------------------------------------------+ #
#######################################################################


#######################################################################
# +-----------------------------------------------------------------+ #
# |                             Entities                            | #
# +-----------------------------------------------------------------+ #
#######################################################################

