
#######################################################################
# +-----------------------------------------------------------------+ #
# |                            BO3 object                           | #
# +-----------------------------------------------------------------+ #
#######################################################################

Author: Unknown

Description: Converted version of the BO2 OakMangroveTree2

Version: 3

SettingsMode: WriteWithoutComments


#######################################################################
# +-----------------------------------------------------------------+ #
# |                          Main settings                          | #
# +-----------------------------------------------------------------+ #
#######################################################################

Tree: true

Frequency: 1

Rarity: 50.0

MaxSpawn: 0

RotateRandomly: true

SpawnHeight: highestSolidBlock

SpawnHeightOffset: 0

SpawnHeightVariance: 0

##############################
# Height Limits for the BO3. #
##############################

MinHeight: 59

MaxHeight: 62

######################
# Extrusion settings #
######################

ExtrudeMode: None

ExtrudeThroughBlocks: otg:air

MaxBranchDepth: 10


#######################################################################
# +-----------------------------------------------------------------+ #
# |                      Source block settings                      | #
# +-----------------------------------------------------------------+ #
#######################################################################

SourceBlocks: otg:dirt,minecraft:sand,otg:stained_clay,otg:sandstone,otg:air,otg:stone,otg:long_grass,minecraft:granite,minecraft:diorite,minecraft:andesite,minecraft:coarse_dirt,minecraft:grass_block,minecraft:podzol,minecraft:water,minecraft:terracotta,minecraft:clay,minecraft:red_sand,minecraft:gravel,minecraft:grass,minecraft:fern,minecraft:dead_bush,minecraft:dandelion,minecraft:poppy,minecraft:brown_mushroom,minecraft:red_mushroom,minecraft:lily_pad

MaxPercentageOutsideSourceBlock: 0

OutsideSourceBlock: placeAnyway

DoReplaceBlocks: true

IsOTGPlus: false


#######################################################################
# +-----------------------------------------------------------------+ #
# |                              Blocks                             | #
# +-----------------------------------------------------------------+ #
#######################################################################

B(2,11,4,minecraft:oak_leaves)
B(-2,12,4,minecraft:oak_leaves)
B(-2,12,-3,minecraft:oak_leaves)
B(-3,11,-2,minecraft:oak_leaves)
B(-1,10,1,minecraft:oak_log)
B(-1,11,1,minecraft:oak_log)
B(-3,12,-2,minecraft:oak_leaves)
B(-4,12,-1,minecraft:oak_leaves)
B(-3,10,2,minecraft:oak_leaves)
B(-4,11,-1,minecraft:oak_leaves)
B(-1,12,1,minecraft:oak_leaves)
B(-1,13,1,minecraft:oak_leaves)
B(-6,11,0,minecraft:oak_leaves)
B(-1,4,0,minecraft:oak_log)
B(-3,12,2,minecraft:oak_leaves)
B(-3,11,2,minecraft:oak_leaves)
B(2,-4,-1,minecraft:oak_log)
B(2,-3,-1,minecraft:oak_log)
B(2,-5,-1,minecraft:oak_log)
B(-2,11,-3,minecraft:oak_log)
B(-2,10,-3,minecraft:oak_leaves)
B(2,-2,-1,minecraft:oak_log)
B(2,-1,-1,minecraft:oak_log)
B(1,10,1,minecraft:oak_leaves)
B(1,11,1,minecraft:oak_log)
B(1,12,1,minecraft:oak_leaves)
B(3,10,2,minecraft:oak_leaves)
B(-6,11,5,minecraft:oak_leaves)
B(3,11,2,minecraft:oak_leaves)
B(1,1,3,minecraft:oak_log)
B(1,0,3,minecraft:oak_log)
B(-1,3,0,minecraft:oak_log)
B(3,12,2,minecraft:oak_leaves)
B(-3,10,-3,minecraft:oak_leaves)
B(-4,1,1,minecraft:oak_log)
B(-2,11,-4,minecraft:oak_leaves)
B(-4,0,1,minecraft:oak_log)
B(0,1,-1,minecraft:oak_log)
B(0,2,-1,minecraft:oak_log)
B(-1,-5,3,minecraft:oak_log)
B(-4,-4,1,minecraft:oak_log)
B(-1,-4,3,minecraft:oak_log)
B(-4,-3,1,minecraft:oak_log)
B(-4,-2,1,minecraft:oak_log)
B(-4,-1,1,minecraft:oak_log)
B(1,10,2,minecraft:oak_leaves)
B(1,11,2,minecraft:oak_leaves)
B(1,12,2,minecraft:oak_leaves)
B(1,13,2,minecraft:oak_leaves)
B(0,10,3,minecraft:oak_leaves)
B(0,11,3,minecraft:oak_log)
B(1,12,-1,minecraft:oak_leaves)
B(1,11,-1,minecraft:oak_leaves)
B(0,12,3,minecraft:oak_leaves)
B(-1,-1,3,minecraft:oak_log)
B(-1,-3,3,minecraft:oak_log)
B(-4,-5,1,minecraft:oak_log)
B(-1,-2,3,minecraft:oak_log)
B(4,11,-2,minecraft:oak_leaves)
B(-4,11,5,minecraft:oak_leaves)
B(3,-2,-1,minecraft:oak_log)
B(-1,11,-4,minecraft:oak_leaves)
B(-2,11,4,minecraft:oak_leaves)
B(3,-3,-1,minecraft:oak_log)
B(3,-4,-1,minecraft:oak_log)
B(3,-5,-1,minecraft:oak_log)
B(1,-2,3,minecraft:oak_log)
B(-1,10,2,minecraft:oak_leaves)
B(1,-1,3,minecraft:oak_log)
B(-3,11,-3,minecraft:oak_leaves)
B(1,-4,3,minecraft:oak_log)
B(0,10,-1,minecraft:oak_leaves)
B(-1,12,2,minecraft:oak_leaves)
B(1,-3,3,minecraft:oak_log)
B(-1,11,2,minecraft:oak_log)
B(-3,11,3,minecraft:oak_log)
B(0,12,-1,minecraft:oak_leaves)
B(1,-5,3,minecraft:oak_log)
B(-3,10,3,minecraft:oak_leaves)
B(0,11,-1,minecraft:oak_leaves)
B(-1,13,2,minecraft:oak_leaves)
B(0,3,0,minecraft:oak_log)
B(0,2,0,minecraft:oak_log)
B(-3,12,3,minecraft:oak_leaves)
B(-2,13,0,minecraft:oak_leaves)
B(-2,12,0,minecraft:oak_leaves)
B(-2,11,0,minecraft:oak_leaves)
B(-2,10,0,minecraft:oak_leaves)
B(-1,-2,1,minecraft:oak_log)
B(-1,-3,1,minecraft:oak_log)
B(-1,-4,1,minecraft:oak_log)
B(-1,-5,1,minecraft:oak_log)
B(1,-3,4,minecraft:oak_log)
B(1,-2,4,minecraft:oak_log)
B(1,-5,4,minecraft:oak_log)
B(1,-4,4,minecraft:oak_log)
B(0,11,5,minecraft:oak_leaves)
B(-1,-1,1,minecraft:oak_log)
B(0,10,5,minecraft:oak_leaves)
B(-1,3,2,minecraft:oak_log)
B(-1,2,2,minecraft:oak_log)
B(-4,11,-3,minecraft:oak_leaves)
B(2,12,3,minecraft:oak_leaves)
B(-1,4,2,minecraft:oak_log)
B(-3,11,-4,minecraft:oak_leaves)
B(2,11,3,minecraft:oak_leaves)
B(-4,11,3,minecraft:oak_leaves)
B(-4,12,3,minecraft:oak_leaves)
B(3,11,-3,minecraft:oak_leaves)
B(-2,3,0,minecraft:oak_log)
B(-2,2,0,minecraft:oak_log)
B(2,0,-1,minecraft:oak_log)
B(-2,1,0,minecraft:oak_log)
B(-1,10,0,minecraft:oak_leaves)
B(-1,11,0,minecraft:oak_log)
B(-1,12,0,minecraft:oak_leaves)
B(-1,1,2,minecraft:oak_log)
B(-6,11,1,minecraft:oak_leaves)
B(2,12,2,minecraft:oak_leaves)
B(2,11,2,minecraft:oak_leaves)
B(-4,10,4,minecraft:oak_leaves)
B(-4,11,4,minecraft:oak_leaves)
B(2,10,2,minecraft:oak_leaves)
B(4,11,1,minecraft:oak_leaves)
B(-5,11,3,minecraft:oak_leaves)
B(-2,11,5,minecraft:oak_leaves)
B(-2,-2,-1,minecraft:oak_log)
B(-2,-3,-1,minecraft:oak_log)
B(-2,-1,-1,minecraft:oak_log)
B(-2,-4,-1,minecraft:oak_log)
B(1,1,-1,minecraft:oak_log)
B(-2,-5,-1,minecraft:oak_log)
B(-3,12,4,minecraft:oak_leaves)
B(1,0,-1,minecraft:oak_log)
B(-3,11,4,minecraft:oak_log)
B(-3,10,4,minecraft:oak_leaves)
B(3,11,1,minecraft:oak_leaves)
B(-1,4,1,minecraft:oak_log)
B(-1,3,1,minecraft:oak_log)
B(-1,6,1,minecraft:oak_log)
B(-1,5,1,minecraft:oak_log)
B(-1,8,1,minecraft:oak_log)
B(-1,7,1,minecraft:oak_log)
B(-1,9,1,minecraft:oak_log)
B(-2,11,-5,minecraft:oak_leaves)
B(1,10,3,minecraft:oak_leaves)
B(1,12,3,minecraft:oak_leaves)
B(1,11,3,minecraft:oak_leaves)
B(1,13,3,minecraft:oak_leaves)
B(0,11,4,minecraft:oak_log)
B(-1,0,1,minecraft:oak_log)
B(-1,2,1,minecraft:oak_log)
B(-1,1,1,minecraft:oak_log)
B(0,10,4,minecraft:oak_leaves)
B(-4,11,-4,minecraft:oak_leaves)
B(0,3,2,minecraft:oak_log)
B(-3,11,-5,minecraft:oak_leaves)
B(0,2,2,minecraft:oak_log)
B(-1,10,4,minecraft:oak_leaves)
B(-6,11,-2,minecraft:oak_leaves)
B(-4,11,2,minecraft:oak_leaves)
B(1,11,4,minecraft:oak_log)
B(0,13,1,minecraft:oak_leaves)
B(1,10,4,minecraft:oak_leaves)
B(2,11,-2,minecraft:oak_leaves)
B(0,12,1,minecraft:oak_leaves)
B(-5,11,5,minecraft:oak_leaves)
B(1,12,4,minecraft:oak_leaves)
B(0,11,1,minecraft:oak_log)
B(0,10,1,minecraft:oak_leaves)
B(-2,-5,3,minecraft:oak_log)
B(-2,-3,3,minecraft:oak_log)
B(-2,-4,3,minecraft:oak_log)
B(-2,-2,3,minecraft:oak_log)
B(2,-4,3,minecraft:oak_log)
B(2,-5,3,minecraft:oak_log)
B(2,-2,3,minecraft:oak_log)
B(2,-3,3,minecraft:oak_log)
B(-3,-3,-1,minecraft:oak_log)
B(-3,-4,-1,minecraft:oak_log)
B(-3,-5,-1,minecraft:oak_log)
B(-1,10,-2,minecraft:oak_leaves)
B(-1,11,-2,minecraft:oak_log)
B(-3,11,5,minecraft:oak_leaves)
B(-1,11,4,minecraft:oak_leaves)
B(-1,12,4,minecraft:oak_leaves)
B(-3,-2,-1,minecraft:oak_log)
B(0,11,6,minecraft:oak_leaves)
B(3,11,-2,minecraft:oak_leaves)
B(-2,12,-1,minecraft:oak_leaves)
B(-2,10,-1,minecraft:oak_leaves)
B(-1,10,-1,minecraft:oak_leaves)
B(-2,11,-1,minecraft:oak_leaves)
B(-3,11,0,minecraft:oak_log)
B(2,11,1,minecraft:oak_leaves)
B(-1,1,3,minecraft:oak_log)
B(2,10,1,minecraft:oak_leaves)
B(-3,12,0,minecraft:oak_leaves)
B(-3,10,0,minecraft:oak_leaves)
B(2,12,1,minecraft:oak_leaves)
B(-1,11,5,minecraft:oak_leaves)
B(-5,11,-2,minecraft:oak_leaves)
B(-3,13,0,minecraft:oak_leaves)
B(-2,13,1,minecraft:oak_leaves)
B(-2,10,1,minecraft:oak_leaves)
B(-1,11,-1,minecraft:oak_log)
B(-2,4,1,minecraft:oak_log)
B(4,11,2,minecraft:oak_leaves)
B(-1,12,-1,minecraft:oak_leaves)
B(-2,3,1,minecraft:oak_log)
B(-2,12,1,minecraft:oak_leaves)
B(-2,2,1,minecraft:oak_log)
B(-2,11,1,minecraft:oak_log)
B(-5,11,4,minecraft:oak_leaves)
B(0,13,0,minecraft:oak_leaves)
B(0,12,0,minecraft:oak_leaves)
B(0,11,0,minecraft:oak_leaves)
B(-2,-4,-2,minecraft:oak_log)
B(-2,-3,-2,minecraft:oak_log)
B(-2,-2,-2,minecraft:oak_log)
B(-2,-5,-2,minecraft:oak_log)
B(0,10,0,minecraft:oak_leaves)
B(3,11,0,minecraft:oak_leaves)
B(-1,0,3,minecraft:oak_log)
B(2,11,0,minecraft:oak_log)
B(2,12,0,minecraft:oak_leaves)
B(-2,0,-1,minecraft:oak_log)
B(2,-4,-2,minecraft:oak_log)
B(2,-5,-2,minecraft:oak_log)
B(2,-2,-2,minecraft:oak_log)
B(-2,10,-2,minecraft:oak_leaves)
B(2,-3,-2,minecraft:oak_log)
B(4,11,3,minecraft:oak_leaves)
B(-2,10,3,minecraft:oak_leaves)
B(-1,11,-3,minecraft:oak_leaves)
B(-5,11,1,minecraft:oak_leaves)
B(-3,11,6,minecraft:oak_leaves)
B(3,11,3,minecraft:oak_leaves)
B(-2,1,-1,minecraft:oak_log)
B(1,13,0,minecraft:oak_leaves)
B(1,12,0,minecraft:oak_leaves)
B(1,11,0,minecraft:oak_log)
B(1,10,0,minecraft:oak_leaves)
B(-2,13,3,minecraft:oak_leaves)
B(-2,11,3,minecraft:oak_log)
B(-2,12,3,minecraft:oak_leaves)
B(1,11,5,minecraft:oak_leaves)
B(-1,-5,4,minecraft:oak_log)
B(2,12,-1,minecraft:oak_leaves)
B(2,11,-1,minecraft:oak_leaves)
B(-4,12,0,minecraft:oak_leaves)
B(0,13,2,minecraft:oak_leaves)
B(-4,10,0,minecraft:oak_leaves)
B(-4,11,0,minecraft:oak_log)
B(0,11,-3,minecraft:oak_leaves)
B(0,10,2,minecraft:oak_leaves)
B(-3,11,-1,minecraft:oak_leaves)
B(0,11,2,minecraft:oak_leaves)
B(-3,12,-1,minecraft:oak_leaves)
B(0,12,2,minecraft:oak_leaves)
B(-1,-3,4,minecraft:oak_log)
B(-4,12,-2,minecraft:oak_leaves)
B(-3,13,-1,minecraft:oak_leaves)
B(-1,-4,4,minecraft:oak_log)
B(-4,11,-2,minecraft:oak_leaves)
B(-1,-2,4,minecraft:oak_log)
B(-3,12,1,minecraft:oak_leaves)
B(-5,11,-1,minecraft:oak_leaves)
B(-3,10,1,minecraft:oak_leaves)
B(-3,11,1,minecraft:oak_log)
B(-5,11,0,minecraft:oak_leaves)
B(-1,12,-2,minecraft:oak_leaves)
B(-2,12,2,minecraft:oak_leaves)
B(-2,13,2,minecraft:oak_leaves)
B(-2,10,2,minecraft:oak_leaves)
B(-2,11,2,minecraft:oak_leaves)
B(1,11,6,minecraft:oak_leaves)
B(-4,11,1,minecraft:oak_leaves)
B(-1,11,3,minecraft:oak_log)
B(-1,10,3,minecraft:oak_leaves)
B(0,11,-2,minecraft:oak_leaves)
B(4,11,-1,minecraft:oak_leaves)
B(-1,13,3,minecraft:oak_leaves)
B(-1,12,3,minecraft:oak_leaves)
B(-3,2,1,minecraft:oak_log)
B(-3,1,1,minecraft:oak_log)
B(0,12,-2,minecraft:oak_leaves)
B(2,11,5,minecraft:oak_leaves)
B(-5,-2,1,minecraft:oak_log)
B(-4,10,1,minecraft:oak_leaves)
B(-5,-3,1,minecraft:oak_log)
B(-5,-4,1,minecraft:oak_log)
B(-5,-5,1,minecraft:oak_log)
B(3,11,-1,minecraft:oak_leaves)
B(-4,-5,2,minecraft:oak_log)
B(-4,-4,2,minecraft:oak_log)
B(-4,-3,2,minecraft:oak_log)
B(-2,12,-2,minecraft:oak_leaves)
B(-4,-2,2,minecraft:oak_log)
B(-2,11,-2,minecraft:oak_log)
B(-5,10,0,minecraft:oak_leaves)
B(1,11,-2,minecraft:oak_leaves)
B(3,12,-1,minecraft:oak_leaves)
B(1,2,2,minecraft:oak_log)
B(3,11,4,minecraft:oak_leaves)
B(1,1,2,minecraft:oak_log)

#######################################################################
# +-----------------------------------------------------------------+ #
# |                            BO3 checks                           | #
# +-----------------------------------------------------------------+ #
#######################################################################


#######################################################################
# +-----------------------------------------------------------------+ #
# |                             Branches                            | #
# +-----------------------------------------------------------------+ #
#######################################################################


#######################################################################
# +-----------------------------------------------------------------+ #
# |                             Entities                            | #
# +-----------------------------------------------------------------+ #
#######################################################################

