
#######################################################################
# +-----------------------------------------------------------------+ #
# |                            BO3 object                           | #
# +-----------------------------------------------------------------+ #
#######################################################################

Author: Unknown

Description: Converted version of the BO2 OakMangroveTree8

Version: 3

SettingsMode: WriteWithoutComments


#######################################################################
# +-----------------------------------------------------------------+ #
# |                          Main settings                          | #
# +-----------------------------------------------------------------+ #
#######################################################################

Tree: true

Frequency: 1

Rarity: 50.0

MaxSpawn: 0

RotateRandomly: true

SpawnHeight: highestSolidBlock

SpawnHeightOffset: 0

SpawnHeightVariance: 0

##############################
# Height Limits for the BO3. #
##############################

MinHeight: 59

MaxHeight: 62

######################
# Extrusion settings #
######################

ExtrudeMode: None

ExtrudeThroughBlocks: otg:air

MaxBranchDepth: 10


#######################################################################
# +-----------------------------------------------------------------+ #
# |                      Source block settings                      | #
# +-----------------------------------------------------------------+ #
#######################################################################

SourceBlocks: otg:dirt,minecraft:sand,otg:stained_clay,otg:sandstone,otg:air,otg:stone,otg:long_grass,minecraft:granite,minecraft:diorite,minecraft:andesite,minecraft:coarse_dirt,minecraft:grass_block,minecraft:podzol,minecraft:water,minecraft:terracotta,minecraft:clay,minecraft:red_sand,minecraft:gravel,minecraft:grass,minecraft:fern,minecraft:dead_bush,minecraft:dandelion,minecraft:poppy,minecraft:brown_mushroom,minecraft:red_mushroom,minecraft:lily_pad

MaxPercentageOutsideSourceBlock: 0

OutsideSourceBlock: placeAnyway

DoReplaceBlocks: true

IsOTGPlus: false


#######################################################################
# +-----------------------------------------------------------------+ #
# |                              Blocks                             | #
# +-----------------------------------------------------------------+ #
#######################################################################

B(-3,1,0,minecraft:oak_log)
B(5,10,2,minecraft:oak_leaves)
B(1,9,0,minecraft:oak_leaves)
B(-4,10,2,minecraft:oak_leaves)
B(1,10,-3,minecraft:oak_leaves)
B(2,10,-2,minecraft:oak_leaves)
B(0,9,-4,minecraft:oak_leaves)
B(-3,10,-2,minecraft:oak_leaves)
B(0,10,-4,minecraft:oak_leaves)
B(-1,10,1,minecraft:oak_leaves)
B(-3,10,2,minecraft:oak_log)
B(-4,10,-1,minecraft:oak_leaves)
B(0,10,1,minecraft:oak_leaves)
B(-1,5,0,minecraft:oak_log)
B(-1,4,0,minecraft:oak_log)
B(-1,7,0,minecraft:oak_log)
B(-1,6,0,minecraft:oak_log)
B(-3,11,2,minecraft:oak_leaves)
B(-1,9,0,minecraft:oak_log)
B(-1,8,0,minecraft:oak_log)
B(3,9,0,minecraft:oak_leaves)
B(-2,9,2,minecraft:oak_leaves)
B(-1,9,-3,minecraft:oak_leaves)
B(-2,10,-3,minecraft:oak_leaves)
B(-2,0,2,minecraft:oak_log)
B(-5,10,2,minecraft:oak_leaves)
B(-1,10,-2,minecraft:oak_log)
B(-1,11,-2,minecraft:oak_leaves)
B(1,10,1,minecraft:oak_leaves)
B(3,10,2,minecraft:oak_leaves)
B(-3,10,5,minecraft:oak_leaves)
B(0,2,1,minecraft:oak_log)
B(0,1,1,minecraft:oak_log)
B(0,9,-1,minecraft:oak_leaves)
B(1,9,1,minecraft:oak_leaves)
B(-3,10,-3,minecraft:oak_leaves)
B(-2,10,-4,minecraft:oak_leaves)
B(3,10,-2,minecraft:oak_leaves)
B(0,1,-1,minecraft:oak_log)
B(0,2,-1,minecraft:oak_log)
B(-2,10,-1,minecraft:oak_leaves)
B(-1,10,-1,minecraft:oak_log)
B(-2,11,-1,minecraft:oak_leaves)
B(1,10,2,minecraft:oak_leaves)
B(0,10,-6,minecraft:oak_leaves)
B(1,11,-1,minecraft:oak_leaves)
B(1,10,-1,minecraft:oak_leaves)
B(-3,11,0,minecraft:oak_leaves)
B(2,11,1,minecraft:oak_leaves)
B(2,10,1,minecraft:oak_leaves)
B(5,10,1,minecraft:oak_leaves)
B(-3,10,0,minecraft:oak_leaves)
B(3,9,1,minecraft:oak_leaves)
B(-2,9,1,minecraft:oak_leaves)
B(-2,10,1,minecraft:oak_log)
B(-1,11,-1,minecraft:oak_leaves)
B(-1,9,-2,minecraft:oak_leaves)
B(-3,0,-1,minecraft:oak_log)
B(4,10,2,minecraft:oak_leaves)
B(-2,11,1,minecraft:oak_leaves)
B(-1,10,-4,minecraft:oak_leaves)
B(0,11,0,minecraft:oak_leaves)
B(2,10,-3,minecraft:oak_leaves)
B(-1,10,2,minecraft:oak_leaves)
B(6,10,0,minecraft:oak_leaves)
B(0,10,-1,minecraft:oak_leaves)
B(0,10,0,minecraft:oak_log)
B(3,11,0,minecraft:oak_leaves)
B(3,10,0,minecraft:oak_log)
B(-3,10,3,minecraft:oak_leaves)
B(0,11,-1,minecraft:oak_leaves)
B(-1,0,3,minecraft:oak_log)
B(2,10,0,minecraft:oak_log)
B(2,11,0,minecraft:oak_leaves)
B(0,9,-2,minecraft:oak_leaves)
B(0,0,-2,minecraft:oak_log)
B(-2,10,-2,minecraft:oak_leaves)
B(-2,11,0,minecraft:oak_leaves)
B(-2,10,0,minecraft:oak_log)
B(4,10,3,minecraft:oak_leaves)
B(-1,10,-3,minecraft:oak_log)
B(-2,10,3,minecraft:oak_leaves)
B(-5,10,1,minecraft:oak_leaves)
B(7,10,1,minecraft:oak_leaves)
B(1,9,-2,minecraft:oak_leaves)
B(-2,9,-1,minecraft:oak_leaves)
B(-1,11,-3,minecraft:oak_leaves)
B(-4,0,0,minecraft:oak_log)
B(-3,9,2,minecraft:oak_leaves)
B(2,9,0,minecraft:oak_leaves)
B(6,10,1,minecraft:oak_leaves)
B(3,10,3,minecraft:oak_leaves)
B(-4,10,-3,minecraft:oak_leaves)
B(-1,2,2,minecraft:oak_log)
B(-1,4,-1,minecraft:oak_log)
B(-1,3,-1,minecraft:oak_log)
B(-3,10,-4,minecraft:oak_leaves)
B(2,10,3,minecraft:oak_leaves)
B(-4,10,3,minecraft:oak_leaves)
B(1,11,0,minecraft:oak_leaves)
B(-2,9,0,minecraft:oak_leaves)
B(3,10,-3,minecraft:oak_leaves)
B(1,10,0,minecraft:oak_log)
B(4,10,0,minecraft:oak_leaves)
B(-2,4,0,minecraft:oak_log)
B(-1,9,-1,minecraft:oak_leaves)
B(-2,3,0,minecraft:oak_log)
B(-2,2,0,minecraft:oak_log)
B(1,10,-4,minecraft:oak_leaves)
B(2,10,-1,minecraft:oak_leaves)
B(2,11,-1,minecraft:oak_leaves)
B(-1,10,-6,minecraft:oak_leaves)
B(-4,10,0,minecraft:oak_leaves)
B(2,9,-1,minecraft:oak_leaves)
B(0,11,-3,minecraft:oak_leaves)
B(-3,10,-1,minecraft:oak_leaves)
B(0,10,2,minecraft:oak_leaves)
B(0,9,1,minecraft:oak_leaves)
B(0,10,-3,minecraft:oak_log)
B(-1,10,0,minecraft:oak_log)
B(-6,10,1,minecraft:oak_leaves)
B(-1,11,0,minecraft:oak_leaves)
B(1,0,1,minecraft:oak_log)
B(-1,1,2,minecraft:oak_log)
B(-4,10,-2,minecraft:oak_leaves)
B(5,10,0,minecraft:oak_leaves)
B(-3,10,1,minecraft:oak_log)
B(-3,11,1,minecraft:oak_leaves)
B(4,10,-1,minecraft:oak_leaves)
B(0,9,-3,minecraft:oak_leaves)
B(2,10,2,minecraft:oak_leaves)
B(4,10,1,minecraft:oak_log)
B(4,11,1,minecraft:oak_leaves)
B(-2,10,2,minecraft:oak_leaves)
B(2,9,1,minecraft:oak_leaves)
B(1,10,-5,minecraft:oak_leaves)
B(-5,10,3,minecraft:oak_leaves)
B(1,9,-1,minecraft:oak_leaves)
B(-3,9,1,minecraft:oak_leaves)
B(-1,10,-5,minecraft:oak_leaves)
B(2,10,-4,minecraft:oak_leaves)
B(3,10,1,minecraft:oak_log)
B(0,11,-2,minecraft:oak_leaves)
B(0,10,-2,minecraft:oak_leaves)
B(1,0,-1,minecraft:oak_log)
B(-6,10,2,minecraft:oak_leaves)
B(-3,10,4,minecraft:oak_leaves)
B(3,11,1,minecraft:oak_leaves)
B(-1,4,1,minecraft:oak_log)
B(-1,3,1,minecraft:oak_log)
B(-1,9,1,minecraft:oak_leaves)
B(-2,10,-5,minecraft:oak_leaves)
B(-4,10,1,minecraft:oak_leaves)
B(3,10,-1,minecraft:oak_leaves)
B(1,10,-2,minecraft:oak_leaves)
B(-2,11,-2,minecraft:oak_leaves)
B(0,10,-5,minecraft:oak_leaves)
B(-5,10,0,minecraft:oak_leaves)
B(1,11,-2,minecraft:oak_leaves)
B(4,9,1,minecraft:oak_leaves)
B(0,9,0,minecraft:oak_leaves)
B(3,10,4,minecraft:oak_leaves)

#######################################################################
# +-----------------------------------------------------------------+ #
# |                            BO3 checks                           | #
# +-----------------------------------------------------------------+ #
#######################################################################


#######################################################################
# +-----------------------------------------------------------------+ #
# |                             Branches                            | #
# +-----------------------------------------------------------------+ #
#######################################################################


#######################################################################
# +-----------------------------------------------------------------+ #
# |                             Entities                            | #
# +-----------------------------------------------------------------+ #
#######################################################################

