
#######################################################################
# +-----------------------------------------------------------------+ #
# |                            BO3 object                           | #
# +-----------------------------------------------------------------+ #
#######################################################################

Author: MC_Pitman

Description: No description given

Version: 3

SettingsMode: WriteWithoutComments


#######################################################################
# +-----------------------------------------------------------------+ #
# |                          Main settings                          | #
# +-----------------------------------------------------------------+ #
#######################################################################

Tree: false

Frequency: 1

Rarity: 1.0

MaxSpawn: 0

RotateRandomly: true

SpawnHeight: highestSolidBlock

SpawnHeightOffset: 0

SpawnHeightVariance: 0

##############################
# Height Limits for the BO3. #
##############################

MinHeight: 52

MaxHeight: 100

######################
# Extrusion settings #
######################

ExtrudeMode: None

ExtrudeThroughBlocks: otg:air

MaxBranchDepth: 10


#######################################################################
# +-----------------------------------------------------------------+ #
# |                      Source block settings                      | #
# +-----------------------------------------------------------------+ #
#######################################################################

SourceBlocks: otg:dirt,minecraft:sand,otg:stained_clay,otg:sandstone,otg:air,otg:stone,otg:long_grass,minecraft:granite,minecraft:diorite,minecraft:andesite,minecraft:coarse_dirt,minecraft:grass_block,minecraft:podzol,minecraft:water,minecraft:terracotta,minecraft:clay,minecraft:red_sand,minecraft:gravel,minecraft:grass,minecraft:fern,minecraft:dead_bush,minecraft:dandelion,minecraft:poppy,minecraft:brown_mushroom,minecraft:red_mushroom

MaxPercentageOutsideSourceBlock: 100

OutsideSourceBlock: placeAnyway

DoReplaceBlocks: true

IsOTGPlus: false


#######################################################################
# +-----------------------------------------------------------------+ #
# |                              Blocks                             | #
# +-----------------------------------------------------------------+ #
#######################################################################

B(-17,-7,0,minecraft:stone)
B(-16,-9,-2,minecraft:stone)
B(-16,-9,-1,minecraft:stone)
B(-16,-9,0,minecraft:stone)
B(-16,-9,1,minecraft:stone)
B(-16,-8,-2,minecraft:stone)
B(-16,-8,-1,minecraft:stone)
B(-16,-8,0,minecraft:stone)
B(-16,-8,1,minecraft:stone)
B(-16,-7,-2,minecraft:stone)
B(-16,-7,-1,minecraft:stone)
B(-16,-7,0,minecraft:stone)
B(-16,-7,1,minecraft:stone)
B(-16,-6,-2,minecraft:stone)
B(-16,-6,-1,minecraft:stone)
B(-16,-6,0,minecraft:stone)
B(-16,-6,1,minecraft:stone)
B(-16,-5,-2,minecraft:stone)
B(-16,-5,-1,minecraft:stone)
B(-16,-4,-2,minecraft:stone)
B(-15,-10,-1,minecraft:stone)
B(-15,-10,0,minecraft:stone)
B(-15,-10,1,minecraft:stone)
B(-15,-10,2,minecraft:stone)
B(-15,-10,3,minecraft:stone)
B(-15,-9,-3,minecraft:stone)
B(-15,-9,-2,minecraft:stone)
B(-15,-9,-1,minecraft:stone)
B(-15,-9,0,minecraft:stone)
B(-15,-9,1,minecraft:stone)
B(-15,-9,2,minecraft:stone)
B(-15,-9,3,minecraft:stone)
B(-15,-8,-3,minecraft:stone)
B(-15,-8,-2,minecraft:stone)
B(-15,-8,-1,minecraft:stone)
B(-15,-8,0,minecraft:stone)
B(-15,-8,1,minecraft:stone)
B(-15,-8,2,minecraft:stone)
B(-15,-8,3,minecraft:stone)
B(-15,-7,-3,minecraft:stone)
B(-15,-7,-2,minecraft:stone)
B(-15,-7,-1,minecraft:stone)
B(-15,-7,0,minecraft:stone)
B(-15,-7,1,minecraft:stone)
B(-15,-7,2,minecraft:stone)
B(-15,-7,3,minecraft:stone)
B(-15,-6,-3,minecraft:stone)
B(-15,-6,-2,minecraft:stone)
B(-15,-6,-1,minecraft:stone)
B(-15,-6,0,minecraft:stone)
B(-15,-6,1,minecraft:stone)
B(-15,-6,2,minecraft:stone)
B(-15,-6,3,minecraft:stone)
B(-15,-5,-3,minecraft:stone)
B(-15,-5,-2,minecraft:stone)
B(-15,-5,-1,minecraft:stone)
B(-15,-5,0,minecraft:stone)
B(-15,-5,1,minecraft:stone)
B(-15,-5,2,minecraft:stone)
B(-15,-4,-3,minecraft:stone)
B(-15,-4,-2,minecraft:stone)
B(-15,-4,-1,minecraft:stone)
B(-15,-4,0,minecraft:stone)
B(-15,-3,-3,minecraft:stone)
B(-15,-3,-2,minecraft:stone)
B(-15,-3,-1,minecraft:stone)
B(-15,-2,-3,minecraft:stone)
B(-15,-2,-2,minecraft:stone)
B(-15,-1,-3,minecraft:stone)
B(-14,-10,-4,minecraft:stone)
B(-14,-10,-3,minecraft:stone)
B(-14,-10,-2,minecraft:stone)
B(-14,-10,-1,minecraft:stone)
B(-14,-10,0,minecraft:stone)
B(-14,-10,1,minecraft:stone)
B(-14,-10,2,minecraft:stone)
B(-14,-10,3,minecraft:stone)
B(-14,-10,4,minecraft:stone)
B(-14,-10,5,minecraft:stone)
B(-14,-10,6,minecraft:stone)
B(-14,-9,-4,minecraft:stone)
B(-14,-9,-3,minecraft:stone)
B(-14,-9,-2,minecraft:stone)
B(-14,-9,-1,minecraft:stone)
B(-14,-9,0,minecraft:stone)
B(-14,-9,1,minecraft:stone)
B(-14,-9,2,minecraft:stone)
B(-14,-9,3,minecraft:stone)
B(-14,-9,4,minecraft:stone)
B(-14,-9,5,minecraft:stone)
B(-14,-8,-5,minecraft:stone)
B(-14,-8,-4,minecraft:stone)
B(-14,-8,-3,minecraft:stone)
B(-14,-8,-2,minecraft:stone)
B(-14,-8,-1,minecraft:stone)
B(-14,-8,0,minecraft:stone)
B(-14,-8,1,minecraft:stone)
B(-14,-8,2,minecraft:stone)
B(-14,-8,3,minecraft:stone)
B(-14,-8,4,minecraft:stone)
B(-14,-8,5,minecraft:stone)
B(-14,-7,-4,minecraft:stone)
B(-14,-7,-3,minecraft:stone)
B(-14,-7,-2,minecraft:stone)
B(-14,-7,-1,minecraft:stone)
B(-14,-7,0,minecraft:stone)
B(-14,-7,1,minecraft:stone)
B(-14,-7,2,minecraft:stone)
B(-14,-7,3,minecraft:stone)
B(-14,-7,4,minecraft:stone)
B(-14,-7,5,minecraft:stone)
B(-14,-6,-4,minecraft:stone)
B(-14,-6,-3,minecraft:stone)
B(-14,-6,-2,minecraft:stone)
B(-14,-6,-1,minecraft:stone)
B(-14,-6,0,minecraft:stone)
B(-14,-6,1,minecraft:stone)
B(-14,-6,2,minecraft:stone)
B(-14,-6,3,minecraft:stone)
B(-14,-6,4,minecraft:stone)
B(-14,-5,-4,minecraft:stone)
B(-14,-5,-3,minecraft:stone)
B(-14,-5,-2,minecraft:stone)
B(-14,-5,-1,minecraft:stone)
B(-14,-5,0,minecraft:stone)
B(-14,-5,1,minecraft:stone)
B(-14,-5,2,minecraft:stone)
B(-14,-5,3,minecraft:stone)
B(-14,-5,4,minecraft:stone)
B(-14,-4,-4,minecraft:stone)
B(-14,-4,-3,minecraft:stone)
B(-14,-4,-2,minecraft:stone)
B(-14,-4,-1,minecraft:stone)
B(-14,-4,0,minecraft:stone)
B(-14,-4,1,minecraft:stone)
B(-14,-4,2,minecraft:stone)
B(-14,-4,3,minecraft:stone)
B(-14,-3,-4,minecraft:stone)
B(-14,-3,-3,minecraft:stone)
B(-14,-3,-2,minecraft:stone)
B(-14,-3,-1,minecraft:stone)
B(-14,-3,0,minecraft:stone)
B(-14,-3,1,minecraft:stone)
B(-14,-2,-4,minecraft:stone)
B(-14,-2,-3,minecraft:stone)
B(-14,-2,-2,minecraft:stone)
B(-14,-2,-1,minecraft:stone)
B(-14,-2,0,minecraft:stone)
B(-14,-1,-4,minecraft:stone)
B(-14,-1,-3,minecraft:stone)
B(-14,-1,-2,minecraft:stone)
B(-14,-1,-1,minecraft:stone)
B(-14,0,-4,minecraft:stone)
B(-14,0,-3,minecraft:stone)
B(-14,0,-2,minecraft:stone)
B(-14,0,-1,minecraft:stone)
B(-14,1,-3,minecraft:stone)
B(-14,1,-2,minecraft:stone)
B(-14,2,-3,minecraft:stone)
B(-13,-11,-1,minecraft:stone)
B(-13,-11,0,minecraft:stone)
B(-13,-11,1,minecraft:stone)
B(-13,-11,2,minecraft:stone)
B(-13,-11,3,minecraft:stone)
B(-13,-11,4,minecraft:stone)
B(-13,-11,5,minecraft:stone)
B(-13,-11,6,minecraft:stone)
B(-13,-10,-4,minecraft:stone)
B(-13,-10,-3,minecraft:stone)
B(-13,-10,-2,minecraft:stone)
B(-13,-10,-1,minecraft:stone)
B(-13,-10,0,minecraft:stone)
B(-13,-10,1,minecraft:stone)
B(-13,-10,2,minecraft:stone)
B(-13,-10,3,minecraft:stone)
B(-13,-10,4,minecraft:stone)
B(-13,-10,5,minecraft:stone)
B(-13,-10,6,minecraft:stone)
B(-13,-10,7,minecraft:stone)
B(-13,-9,-5,minecraft:stone)
B(-13,-9,-4,minecraft:stone)
B(-13,-9,-3,minecraft:stone)
B(-13,-9,-2,minecraft:stone)
B(-13,-9,-1,minecraft:stone)
B(-13,-9,0,minecraft:stone)
B(-13,-9,1,minecraft:stone)
B(-13,-9,2,minecraft:stone)
B(-13,-9,3,minecraft:stone)
B(-13,-9,4,minecraft:stone)
B(-13,-9,5,minecraft:stone)
B(-13,-9,6,minecraft:stone)
B(-13,-9,7,minecraft:stone)
B(-13,-8,-5,minecraft:stone)
B(-13,-8,-4,minecraft:stone)
B(-13,-8,-3,minecraft:stone)
B(-13,-8,-2,minecraft:stone)
B(-13,-8,-1,minecraft:stone)
B(-13,-8,0,minecraft:stone)
B(-13,-8,1,minecraft:stone)
B(-13,-8,2,minecraft:stone)
B(-13,-8,3,minecraft:stone)
B(-13,-8,4,minecraft:stone)
B(-13,-8,5,minecraft:stone)
B(-13,-8,6,minecraft:stone)
B(-13,-8,7,minecraft:stone)
B(-13,-7,-5,minecraft:stone)
B(-13,-7,-4,minecraft:stone)
B(-13,-7,-3,minecraft:stone)
B(-13,-7,-2,minecraft:stone)
B(-13,-7,-1,minecraft:stone)
B(-13,-7,0,minecraft:stone)
B(-13,-7,1,minecraft:stone)
B(-13,-7,2,minecraft:stone)
B(-13,-7,3,minecraft:stone)
B(-13,-7,4,minecraft:stone)
B(-13,-7,5,minecraft:stone)
B(-13,-7,6,minecraft:stone)
B(-13,-7,7,minecraft:stone)
B(-13,-6,-5,minecraft:stone)
B(-13,-6,-4,minecraft:stone)
B(-13,-6,-3,minecraft:stone)
B(-13,-6,-2,minecraft:stone)
B(-13,-6,-1,minecraft:stone)
B(-13,-6,0,minecraft:stone)
B(-13,-6,1,minecraft:stone)
B(-13,-6,2,minecraft:stone)
B(-13,-6,3,minecraft:stone)
B(-13,-6,4,minecraft:stone)
B(-13,-6,5,minecraft:stone)
B(-13,-6,6,minecraft:stone)
B(-13,-5,-5,minecraft:stone)
B(-13,-5,-4,minecraft:stone)
B(-13,-5,-3,minecraft:stone)
B(-13,-5,-2,minecraft:stone)
B(-13,-5,-1,minecraft:stone)
B(-13,-5,0,minecraft:stone)
B(-13,-5,1,minecraft:stone)
B(-13,-5,2,minecraft:stone)
B(-13,-5,3,minecraft:stone)
B(-13,-5,4,minecraft:stone)
B(-13,-5,5,minecraft:stone)
B(-13,-5,6,minecraft:stone)
B(-13,-4,-5,minecraft:stone)
B(-13,-4,-4,minecraft:stone)
B(-13,-4,-3,minecraft:stone)
B(-13,-4,-2,minecraft:stone)
B(-13,-4,-1,minecraft:stone)
B(-13,-4,0,minecraft:stone)
B(-13,-4,1,minecraft:stone)
B(-13,-4,2,minecraft:stone)
B(-13,-4,3,minecraft:stone)
B(-13,-4,4,minecraft:stone)
B(-13,-4,5,minecraft:stone)
B(-13,-3,-5,minecraft:stone)
B(-13,-3,-4,minecraft:stone)
B(-13,-3,-3,minecraft:stone)
B(-13,-3,-2,minecraft:stone)
B(-13,-3,-1,minecraft:stone)
B(-13,-3,0,minecraft:stone)
B(-13,-3,1,minecraft:stone)
B(-13,-3,2,minecraft:stone)
B(-13,-3,3,minecraft:stone)
B(-13,-3,4,minecraft:stone)
B(-13,-2,-5,minecraft:stone)
B(-13,-2,-4,minecraft:stone)
B(-13,-2,-3,minecraft:stone)
B(-13,-2,-2,minecraft:stone)
B(-13,-2,-1,minecraft:stone)
B(-13,-2,0,minecraft:stone)
B(-13,-2,1,minecraft:stone)
B(-13,-2,2,minecraft:stone)
B(-13,-2,3,minecraft:stone)
B(-13,-1,-5,minecraft:stone)
B(-13,-1,-4,minecraft:stone)
B(-13,-1,-3,minecraft:stone)
B(-13,-1,-2,minecraft:stone)
B(-13,-1,-1,minecraft:stone)
B(-13,-1,0,minecraft:stone)
B(-13,-1,1,minecraft:stone)
B(-13,-1,2,minecraft:stone)
B(-13,0,-5,minecraft:stone)
B(-13,0,-4,minecraft:stone)
B(-13,0,-3,minecraft:stone)
B(-13,0,-2,minecraft:stone)
B(-13,0,-1,minecraft:stone)
B(-13,0,0,minecraft:stone)
B(-13,0,1,minecraft:stone)
B(-13,1,-5,minecraft:stone)
B(-13,1,-4,minecraft:stone)
B(-13,1,-3,minecraft:stone)
B(-13,1,-2,minecraft:stone)
B(-13,1,-1,minecraft:stone)
B(-13,1,0,minecraft:stone)
B(-13,2,-4,minecraft:stone)
B(-13,2,-3,minecraft:stone)
B(-13,2,-2,minecraft:stone)
B(-13,2,-1,minecraft:stone)
B(-13,3,-4,minecraft:stone)
B(-13,3,-3,minecraft:stone)
B(-13,3,-2,minecraft:stone)
B(-13,4,-4,minecraft:stone)
B(-12,-11,-3,minecraft:stone)
B(-12,-11,-2,minecraft:stone)
B(-12,-11,-1,minecraft:stone)
B(-12,-11,0,minecraft:stone)
B(-12,-11,1,minecraft:stone)
B(-12,-11,2,minecraft:stone)
B(-12,-11,3,minecraft:stone)
B(-12,-11,4,minecraft:stone)
B(-12,-11,5,minecraft:stone)
B(-12,-11,6,minecraft:stone)
B(-12,-11,7,minecraft:stone)
B(-12,-11,8,minecraft:stone)
B(-12,-10,-5,minecraft:stone)
B(-12,-10,-4,minecraft:stone)
B(-12,-10,-3,minecraft:stone)
B(-12,-10,-2,minecraft:stone)
B(-12,-10,-1,minecraft:stone)
B(-12,-10,0,minecraft:stone)
B(-12,-10,1,minecraft:stone)
B(-12,-10,2,minecraft:stone)
B(-12,-10,3,minecraft:stone)
B(-12,-10,4,minecraft:stone)
B(-12,-10,5,minecraft:stone)
B(-12,-10,6,minecraft:stone)
B(-12,-10,7,minecraft:stone)
B(-12,-10,8,minecraft:stone)
B(-12,-10,9,minecraft:stone)
B(-12,-9,-5,minecraft:stone)
B(-12,-9,-4,minecraft:stone)
B(-12,-9,-3,minecraft:stone)
B(-12,-9,-2,minecraft:stone)
B(-12,-9,-1,minecraft:stone)
B(-12,-9,0,minecraft:stone)
B(-12,-9,1,minecraft:stone)
B(-12,-9,2,minecraft:stone)
B(-12,-9,3,minecraft:stone)
B(-12,-9,4,minecraft:stone)
B(-12,-9,5,minecraft:stone)
B(-12,-9,6,minecraft:stone)
B(-12,-9,7,minecraft:stone)
B(-12,-9,8,minecraft:stone)
B(-12,-8,-6,minecraft:stone)
B(-12,-8,-5,minecraft:stone)
B(-12,-8,-4,minecraft:stone)
B(-12,-8,-3,minecraft:stone)
B(-12,-8,-2,minecraft:stone)
B(-12,-8,-1,minecraft:stone)
B(-12,-8,0,minecraft:stone)
B(-12,-8,1,minecraft:stone)
B(-12,-8,2,minecraft:stone)
B(-12,-8,3,minecraft:stone)
B(-12,-8,4,minecraft:stone)
B(-12,-8,5,minecraft:stone)
B(-12,-8,6,minecraft:stone)
B(-12,-8,7,minecraft:stone)
B(-12,-8,8,minecraft:stone)
B(-12,-7,-6,minecraft:stone)
B(-12,-7,-5,minecraft:stone)
B(-12,-7,-4,minecraft:stone)
B(-12,-7,-3,minecraft:stone)
B(-12,-7,-2,minecraft:stone)
B(-12,-7,-1,minecraft:stone)
B(-12,-7,0,minecraft:stone)
B(-12,-7,1,minecraft:stone)
B(-12,-7,2,minecraft:stone)
B(-12,-7,3,minecraft:stone)
B(-12,-7,4,minecraft:stone)
B(-12,-7,5,minecraft:stone)
B(-12,-7,6,minecraft:stone)
B(-12,-7,7,minecraft:stone)
B(-12,-7,8,minecraft:stone)
B(-12,-6,-6,minecraft:stone)
B(-12,-6,-5,minecraft:stone)
B(-12,-6,-4,minecraft:stone)
B(-12,-6,-3,minecraft:stone)
B(-12,-6,-2,minecraft:stone)
B(-12,-6,-1,minecraft:stone)
B(-12,-6,0,minecraft:stone)
B(-12,-6,1,minecraft:stone)
B(-12,-6,2,minecraft:stone)
B(-12,-6,3,minecraft:stone)
B(-12,-6,4,minecraft:stone)
B(-12,-6,5,minecraft:stone)
B(-12,-6,6,minecraft:stone)
B(-12,-6,7,minecraft:stone)
B(-12,-5,-6,minecraft:stone)
B(-12,-5,-5,minecraft:stone)
B(-12,-5,-4,minecraft:stone)
B(-12,-5,-3,minecraft:stone)
B(-12,-5,-2,minecraft:stone)
B(-12,-5,-1,minecraft:stone)
B(-12,-5,0,minecraft:stone)
B(-12,-5,1,minecraft:stone)
B(-12,-5,2,minecraft:stone)
B(-12,-5,3,minecraft:stone)
B(-12,-5,4,minecraft:stone)
B(-12,-5,5,minecraft:stone)
B(-12,-5,6,minecraft:stone)
B(-12,-5,7,minecraft:stone)
B(-12,-4,-6,minecraft:stone)
B(-12,-4,-5,minecraft:stone)
B(-12,-4,-4,minecraft:stone)
B(-12,-4,-3,minecraft:stone)
B(-12,-4,-2,minecraft:stone)
B(-12,-4,-1,minecraft:stone)
B(-12,-4,0,minecraft:stone)
B(-12,-4,1,minecraft:stone)
B(-12,-4,2,minecraft:stone)
B(-12,-4,3,minecraft:stone)
B(-12,-4,4,minecraft:stone)
B(-12,-4,5,minecraft:stone)
B(-12,-4,6,minecraft:stone)
B(-12,-3,-6,minecraft:stone)
B(-12,-3,-5,minecraft:stone)
B(-12,-3,-4,minecraft:stone)
B(-12,-3,-3,minecraft:stone)
B(-12,-3,-2,minecraft:stone)
B(-12,-3,-1,minecraft:stone)
B(-12,-3,0,minecraft:stone)
B(-12,-3,1,minecraft:stone)
B(-12,-3,2,minecraft:stone)
B(-12,-3,3,minecraft:stone)
B(-12,-3,4,minecraft:stone)
B(-12,-3,5,minecraft:stone)
B(-12,-2,-6,minecraft:stone)
B(-12,-2,-5,minecraft:stone)
B(-12,-2,-4,minecraft:stone)
B(-12,-2,-3,minecraft:stone)
B(-12,-2,-2,minecraft:stone)
B(-12,-2,-1,minecraft:stone)
B(-12,-2,0,minecraft:stone)
B(-12,-2,1,minecraft:stone)
B(-12,-2,2,minecraft:stone)
B(-12,-2,3,minecraft:stone)
B(-12,-2,4,minecraft:stone)
B(-12,-1,-6,minecraft:stone)
B(-12,-1,-5,minecraft:stone)
B(-12,-1,-4,minecraft:stone)
B(-12,-1,-3,minecraft:stone)
B(-12,-1,-2,minecraft:stone)
B(-12,-1,-1,minecraft:stone)
B(-12,-1,0,minecraft:stone)
B(-12,-1,1,minecraft:stone)
B(-12,-1,2,minecraft:stone)
B(-12,-1,3,minecraft:stone)
B(-12,0,-6,minecraft:stone)
B(-12,0,-5,minecraft:stone)
B(-12,0,-4,minecraft:stone)
B(-12,0,-3,minecraft:stone)
B(-12,0,-2,minecraft:stone)
B(-12,0,-1,minecraft:stone)
B(-12,0,0,minecraft:stone)
B(-12,0,1,minecraft:stone)
B(-12,0,2,minecraft:stone)
B(-12,1,-6,minecraft:stone)
B(-12,1,-5,minecraft:stone)
B(-12,1,-4,minecraft:stone)
B(-12,1,-3,minecraft:stone)
B(-12,1,-2,minecraft:stone)
B(-12,1,-1,minecraft:stone)
B(-12,1,0,minecraft:stone)
B(-12,1,1,minecraft:stone)
B(-12,2,-5,minecraft:stone)
B(-12,2,-4,minecraft:stone)
B(-12,2,-3,minecraft:stone)
B(-12,2,-2,minecraft:stone)
B(-12,2,-1,minecraft:stone)
B(-12,2,0,minecraft:stone)
B(-12,3,-5,minecraft:stone)
B(-12,3,-4,minecraft:stone)
B(-12,3,-3,minecraft:stone)
B(-12,3,-2,minecraft:stone)
B(-12,3,-1,minecraft:stone)
B(-12,4,-5,minecraft:stone)
B(-12,4,-4,minecraft:stone)
B(-12,4,-3,minecraft:stone)
B(-12,4,-2,minecraft:stone)
B(-12,5,-4,minecraft:stone)
B(-12,5,-3,minecraft:stone)
B(-11,-12,1,minecraft:stone)
B(-11,-12,2,minecraft:stone)
B(-11,-12,3,minecraft:stone)
B(-11,-12,4,minecraft:stone)
B(-11,-11,-4,minecraft:stone)
B(-11,-11,-3,minecraft:stone)
B(-11,-11,-2,minecraft:stone)
B(-11,-11,-1,minecraft:stone)
B(-11,-11,0,minecraft:stone)
B(-11,-11,1,minecraft:stone)
B(-11,-11,2,minecraft:stone)
B(-11,-11,3,minecraft:stone)
B(-11,-11,4,minecraft:stone)
B(-11,-11,5,minecraft:stone)
B(-11,-11,6,minecraft:stone)
B(-11,-11,7,minecraft:stone)
B(-11,-11,8,minecraft:stone)
B(-11,-11,9,minecraft:stone)
B(-11,-10,-5,minecraft:stone)
B(-11,-10,-4,minecraft:stone)
B(-11,-10,-3,minecraft:stone)
B(-11,-10,-2,minecraft:stone)
B(-11,-10,-1,minecraft:stone)
B(-11,-10,0,minecraft:stone)
B(-11,-10,1,minecraft:stone)
B(-11,-10,2,minecraft:stone)
B(-11,-10,3,minecraft:stone)
B(-11,-10,4,minecraft:stone)
B(-11,-10,5,minecraft:stone)
B(-11,-10,6,minecraft:stone)
B(-11,-10,7,minecraft:stone)
B(-11,-10,8,minecraft:stone)
B(-11,-10,9,minecraft:stone)
B(-11,-9,-6,minecraft:stone)
B(-11,-9,-5,minecraft:stone)
B(-11,-9,-4,minecraft:stone)
B(-11,-9,-3,minecraft:stone)
B(-11,-9,-2,minecraft:stone)
B(-11,-9,-1,minecraft:stone)
B(-11,-9,0,minecraft:stone)
B(-11,-9,1,minecraft:stone)
B(-11,-9,2,minecraft:stone)
B(-11,-9,3,minecraft:stone)
B(-11,-9,4,minecraft:stone)
B(-11,-9,5,minecraft:stone)
B(-11,-9,6,minecraft:stone)
B(-11,-9,7,minecraft:stone)
B(-11,-9,8,minecraft:stone)
B(-11,-9,9,minecraft:stone)
B(-11,-8,-6,minecraft:stone)
B(-11,-8,-5,minecraft:stone)
B(-11,-8,-4,minecraft:stone)
B(-11,-8,-3,minecraft:stone)
B(-11,-8,-2,minecraft:stone)
B(-11,-8,-1,minecraft:stone)
B(-11,-8,0,minecraft:stone)
B(-11,-8,1,minecraft:stone)
B(-11,-8,2,minecraft:stone)
B(-11,-8,3,minecraft:stone)
B(-11,-8,4,minecraft:stone)
B(-11,-8,5,minecraft:stone)
B(-11,-8,6,minecraft:stone)
B(-11,-8,7,minecraft:stone)
B(-11,-8,8,minecraft:stone)
B(-11,-8,9,minecraft:stone)
B(-11,-7,-7,minecraft:stone)
B(-11,-7,-6,minecraft:stone)
B(-11,-7,-5,minecraft:stone)
B(-11,-7,-4,minecraft:stone)
B(-11,-7,-3,minecraft:stone)
B(-11,-7,-2,minecraft:stone)
B(-11,-7,-1,minecraft:stone)
B(-11,-7,0,minecraft:stone)
B(-11,-7,1,minecraft:stone)
B(-11,-7,2,minecraft:stone)
B(-11,-7,3,minecraft:stone)
B(-11,-7,4,minecraft:stone)
B(-11,-7,5,minecraft:stone)
B(-11,-7,6,minecraft:stone)
B(-11,-7,7,minecraft:stone)
B(-11,-7,8,minecraft:stone)
B(-11,-7,9,minecraft:stone)
B(-11,-6,-7,minecraft:stone)
B(-11,-6,-6,minecraft:stone)
B(-11,-6,-5,minecraft:stone)
B(-11,-6,-4,minecraft:stone)
B(-11,-6,-3,minecraft:stone)
B(-11,-6,-2,minecraft:stone)
B(-11,-6,-1,minecraft:stone)
B(-11,-6,0,minecraft:stone)
B(-11,-6,1,minecraft:stone)
B(-11,-6,2,minecraft:stone)
B(-11,-6,3,minecraft:stone)
B(-11,-6,4,minecraft:stone)
B(-11,-6,5,minecraft:stone)
B(-11,-6,6,minecraft:stone)
B(-11,-6,7,minecraft:stone)
B(-11,-6,8,minecraft:stone)
B(-11,-5,-7,minecraft:stone)
B(-11,-5,-6,minecraft:stone)
B(-11,-5,-5,minecraft:stone)
B(-11,-5,-4,minecraft:stone)
B(-11,-5,-3,minecraft:stone)
B(-11,-5,-2,minecraft:stone)
B(-11,-5,-1,minecraft:stone)
B(-11,-5,0,minecraft:stone)
B(-11,-5,1,minecraft:stone)
B(-11,-5,2,minecraft:stone)
B(-11,-5,3,minecraft:stone)
B(-11,-5,4,minecraft:stone)
B(-11,-5,5,minecraft:stone)
B(-11,-5,6,minecraft:stone)
B(-11,-5,7,minecraft:stone)
B(-11,-5,8,minecraft:stone)
B(-11,-4,-7,minecraft:stone)
B(-11,-4,-6,minecraft:stone)
B(-11,-4,-5,minecraft:stone)
B(-11,-4,-4,minecraft:stone)
B(-11,-4,-3,minecraft:stone)
B(-11,-4,-2,minecraft:stone)
B(-11,-4,-1,minecraft:stone)
B(-11,-4,0,minecraft:stone)
B(-11,-4,1,minecraft:stone)
B(-11,-4,2,minecraft:stone)
B(-11,-4,3,minecraft:stone)
B(-11,-4,4,minecraft:stone)
B(-11,-4,5,minecraft:stone)
B(-11,-4,6,minecraft:stone)
B(-11,-4,7,minecraft:stone)
B(-11,-3,-7,minecraft:stone)
B(-11,-3,-6,minecraft:stone)
B(-11,-3,-5,minecraft:stone)
B(-11,-3,-4,minecraft:stone)
B(-11,-3,-3,minecraft:stone)
B(-11,-3,-2,minecraft:stone)
B(-11,-3,-1,minecraft:stone)
B(-11,-3,0,minecraft:stone)
B(-11,-3,1,minecraft:stone)
B(-11,-3,2,minecraft:stone)
B(-11,-3,3,minecraft:stone)
B(-11,-3,4,minecraft:stone)
B(-11,-3,5,minecraft:stone)
B(-11,-3,6,minecraft:stone)
B(-11,-2,-7,minecraft:stone)
B(-11,-2,-6,minecraft:stone)
B(-11,-2,-5,minecraft:stone)
B(-11,-2,-4,minecraft:stone)
B(-11,-2,-3,minecraft:stone)
B(-11,-2,-2,minecraft:stone)
B(-11,-2,-1,minecraft:stone)
B(-11,-2,0,minecraft:stone)
B(-11,-2,1,minecraft:stone)
B(-11,-2,2,minecraft:stone)
B(-11,-2,3,minecraft:stone)
B(-11,-2,4,minecraft:stone)
B(-11,-2,5,minecraft:stone)
B(-11,-1,-7,minecraft:stone)
B(-11,-1,-6,minecraft:stone)
B(-11,-1,-5,minecraft:stone)
B(-11,-1,-4,minecraft:stone)
B(-11,-1,-3,minecraft:stone)
B(-11,-1,-2,minecraft:stone)
B(-11,-1,-1,minecraft:stone)
B(-11,-1,0,minecraft:stone)
B(-11,-1,1,minecraft:stone)
B(-11,-1,2,minecraft:stone)
B(-11,-1,3,minecraft:stone)
B(-11,-1,4,minecraft:stone)
B(-11,-1,5,minecraft:stone)
B(-11,0,-7,minecraft:stone)
B(-11,0,-6,minecraft:stone)
B(-11,0,-5,minecraft:stone)
B(-11,0,-4,minecraft:stone)
B(-11,0,-3,minecraft:stone)
B(-11,0,-2,minecraft:stone)
B(-11,0,-1,minecraft:stone)
B(-11,0,0,minecraft:stone)
B(-11,0,1,minecraft:stone)
B(-11,0,2,minecraft:stone)
B(-11,0,3,minecraft:stone)
B(-11,0,4,minecraft:stone)
B(-11,1,-6,minecraft:stone)
B(-11,1,-5,minecraft:stone)
B(-11,1,-4,minecraft:stone)
B(-11,1,-3,minecraft:stone)
B(-11,1,-2,minecraft:stone)
B(-11,1,-1,minecraft:stone)
B(-11,1,0,minecraft:stone)
B(-11,1,1,minecraft:stone)
B(-11,1,2,minecraft:stone)
B(-11,1,3,minecraft:stone)
B(-11,2,-6,minecraft:stone)
B(-11,2,-5,minecraft:stone)
B(-11,2,-4,minecraft:stone)
B(-11,2,-3,minecraft:stone)
B(-11,2,-2,minecraft:stone)
B(-11,2,-1,minecraft:stone)
B(-11,2,0,minecraft:stone)
B(-11,2,1,minecraft:stone)
B(-11,2,2,minecraft:stone)
B(-11,3,-6,minecraft:stone)
B(-11,3,-5,minecraft:stone)
B(-11,3,-4,minecraft:stone)
B(-11,3,-3,minecraft:stone)
B(-11,3,-2,minecraft:stone)
B(-11,3,-1,minecraft:stone)
B(-11,3,0,minecraft:stone)
B(-11,3,1,minecraft:stone)
B(-11,4,-5,minecraft:stone)
B(-11,4,-4,minecraft:stone)
B(-11,4,-3,minecraft:stone)
B(-11,4,-2,minecraft:stone)
B(-11,4,-1,minecraft:stone)
B(-11,4,0,minecraft:stone)
B(-11,5,-5,minecraft:stone)
B(-11,5,-4,minecraft:stone)
B(-11,5,-3,minecraft:stone)
B(-11,5,-2,minecraft:stone)
B(-11,6,-5,minecraft:stone)
B(-11,6,-4,minecraft:stone)
B(-11,6,-3,minecraft:stone)
B(-10,-12,0,minecraft:stone)
B(-10,-12,1,minecraft:stone)
B(-10,-12,2,minecraft:stone)
B(-10,-12,3,minecraft:stone)
B(-10,-12,4,minecraft:stone)
B(-10,-12,5,minecraft:stone)
B(-10,-12,6,minecraft:stone)
B(-10,-12,7,minecraft:stone)
B(-10,-12,8,minecraft:stone)
B(-10,-11,-5,minecraft:stone)
B(-10,-11,-4,minecraft:stone)
B(-10,-11,-3,minecraft:stone)
B(-10,-11,-2,minecraft:stone)
B(-10,-11,-1,minecraft:stone)
B(-10,-11,0,minecraft:stone)
B(-10,-11,1,minecraft:stone)
B(-10,-11,2,minecraft:stone)
B(-10,-11,3,minecraft:stone)
B(-10,-11,4,minecraft:stone)
B(-10,-11,5,minecraft:stone)
B(-10,-11,6,minecraft:stone)
B(-10,-11,7,minecraft:stone)
B(-10,-11,8,minecraft:stone)
B(-10,-11,9,minecraft:stone)
B(-10,-11,10,minecraft:stone)
B(-10,-10,-5,minecraft:stone)
B(-10,-10,-4,minecraft:stone)
B(-10,-10,-3,minecraft:stone)
B(-10,-10,-2,minecraft:stone)
B(-10,-10,-1,minecraft:stone)
B(-10,-10,0,minecraft:stone)
B(-10,-10,1,minecraft:stone)
B(-10,-10,2,minecraft:stone)
B(-10,-10,3,minecraft:stone)
B(-10,-10,4,minecraft:stone)
B(-10,-10,5,minecraft:stone)
B(-10,-10,6,minecraft:stone)
B(-10,-10,7,minecraft:stone)
B(-10,-10,8,minecraft:stone)
B(-10,-10,9,minecraft:stone)
B(-10,-10,10,minecraft:stone)
B(-10,-9,-6,minecraft:stone)
B(-10,-9,-5,minecraft:stone)
B(-10,-9,-4,minecraft:stone)
B(-10,-9,-3,minecraft:stone)
B(-10,-9,-2,minecraft:stone)
B(-10,-9,-1,minecraft:stone)
B(-10,-9,0,minecraft:stone)
B(-10,-9,1,minecraft:stone)
B(-10,-9,2,minecraft:stone)
B(-10,-9,3,minecraft:stone)
B(-10,-9,4,minecraft:stone)
B(-10,-9,5,minecraft:stone)
B(-10,-9,6,minecraft:stone)
B(-10,-9,7,minecraft:stone)
B(-10,-9,8,minecraft:stone)
B(-10,-9,9,minecraft:stone)
B(-10,-9,10,minecraft:stone)
B(-10,-8,-6,minecraft:stone)
B(-10,-8,-5,minecraft:stone)
B(-10,-8,-4,minecraft:stone)
B(-10,-8,-3,minecraft:stone)
B(-10,-8,-2,minecraft:stone)
B(-10,-8,-1,minecraft:stone)
B(-10,-8,0,minecraft:stone)
B(-10,-8,1,minecraft:stone)
B(-10,-8,2,minecraft:stone)
B(-10,-8,3,minecraft:stone)
B(-10,-8,4,minecraft:stone)
B(-10,-8,5,minecraft:stone)
B(-10,-8,6,minecraft:stone)
B(-10,-8,7,minecraft:stone)
B(-10,-8,8,minecraft:stone)
B(-10,-8,9,minecraft:stone)
B(-10,-8,10,minecraft:stone)
B(-10,-7,-7,minecraft:stone)
B(-10,-7,-6,minecraft:stone)
B(-10,-7,-5,minecraft:stone)
B(-10,-7,-4,minecraft:stone)
B(-10,-7,-3,minecraft:stone)
B(-10,-7,-2,minecraft:stone)
B(-10,-7,-1,minecraft:stone)
B(-10,-7,0,minecraft:stone)
B(-10,-7,1,minecraft:stone)
B(-10,-7,2,minecraft:stone)
B(-10,-7,3,minecraft:stone)
B(-10,-7,4,minecraft:stone)
B(-10,-7,5,minecraft:stone)
B(-10,-7,6,minecraft:stone)
B(-10,-7,7,minecraft:stone)
B(-10,-7,8,minecraft:stone)
B(-10,-7,9,minecraft:stone)
B(-10,-7,10,minecraft:stone)
B(-10,-6,-7,minecraft:stone)
B(-10,-6,-6,minecraft:stone)
B(-10,-6,-5,minecraft:stone)
B(-10,-6,-4,minecraft:stone)
B(-10,-6,-3,minecraft:stone)
B(-10,-6,-2,minecraft:stone)
B(-10,-6,-1,minecraft:stone)
B(-10,-6,0,minecraft:stone)
B(-10,-6,1,minecraft:stone)
B(-10,-6,2,minecraft:stone)
B(-10,-6,3,minecraft:stone)
B(-10,-6,4,minecraft:stone)
B(-10,-6,5,minecraft:stone)
B(-10,-6,6,minecraft:stone)
B(-10,-6,7,minecraft:stone)
B(-10,-6,8,minecraft:stone)
B(-10,-6,9,minecraft:stone)
B(-10,-5,-7,minecraft:stone)
B(-10,-5,-6,minecraft:stone)
B(-10,-5,-5,minecraft:stone)
B(-10,-5,-4,minecraft:stone)
B(-10,-5,-3,minecraft:stone)
B(-10,-5,-2,minecraft:stone)
B(-10,-5,-1,minecraft:stone)
B(-10,-5,0,minecraft:stone)
B(-10,-5,1,minecraft:stone)
B(-10,-5,2,minecraft:stone)
B(-10,-5,3,minecraft:stone)
B(-10,-5,4,minecraft:stone)
B(-10,-5,5,minecraft:stone)
B(-10,-5,6,minecraft:stone)
B(-10,-5,7,minecraft:stone)
B(-10,-5,8,minecraft:stone)
B(-10,-5,9,minecraft:stone)
B(-10,-4,-7,minecraft:stone)
B(-10,-4,-6,minecraft:stone)
B(-10,-4,-5,minecraft:stone)
B(-10,-4,-4,minecraft:stone)
B(-10,-4,-3,minecraft:stone)
B(-10,-4,-2,minecraft:stone)
B(-10,-4,-1,minecraft:stone)
B(-10,-4,0,minecraft:stone)
B(-10,-4,1,minecraft:stone)
B(-10,-4,2,minecraft:stone)
B(-10,-4,3,minecraft:stone)
B(-10,-4,4,minecraft:stone)
B(-10,-4,5,minecraft:stone)
B(-10,-4,6,minecraft:stone)
B(-10,-4,7,minecraft:stone)
B(-10,-4,8,minecraft:stone)
B(-10,-3,-7,minecraft:stone)
B(-10,-3,-6,minecraft:stone)
B(-10,-3,-5,minecraft:stone)
B(-10,-3,-4,minecraft:stone)
B(-10,-3,-3,minecraft:stone)
B(-10,-3,-2,minecraft:stone)
B(-10,-3,-1,minecraft:stone)
B(-10,-3,0,minecraft:stone)
B(-10,-3,1,minecraft:stone)
B(-10,-3,2,minecraft:stone)
B(-10,-3,3,minecraft:stone)
B(-10,-3,4,minecraft:stone)
B(-10,-3,5,minecraft:stone)
B(-10,-3,6,minecraft:stone)
B(-10,-3,7,minecraft:stone)
B(-10,-3,8,minecraft:stone)
B(-10,-2,-7,minecraft:stone)
B(-10,-2,-6,minecraft:stone)
B(-10,-2,-5,minecraft:stone)
B(-10,-2,-4,minecraft:stone)
B(-10,-2,-3,minecraft:stone)
B(-10,-2,-2,minecraft:stone)
B(-10,-2,-1,minecraft:stone)
B(-10,-2,0,minecraft:stone)
B(-10,-2,1,minecraft:stone)
B(-10,-2,2,minecraft:stone)
B(-10,-2,3,minecraft:stone)
B(-10,-2,4,minecraft:stone)
B(-10,-2,5,minecraft:stone)
B(-10,-2,6,minecraft:stone)
B(-10,-2,7,minecraft:stone)
B(-10,-1,-7,minecraft:stone)
B(-10,-1,-6,minecraft:stone)
B(-10,-1,-5,minecraft:stone)
B(-10,-1,-4,minecraft:stone)
B(-10,-1,-3,minecraft:stone)
B(-10,-1,-2,minecraft:stone)
B(-10,-1,-1,minecraft:stone)
B(-10,-1,0,minecraft:stone)
B(-10,-1,1,minecraft:stone)
B(-10,-1,2,minecraft:stone)
B(-10,-1,3,minecraft:stone)
B(-10,-1,4,minecraft:stone)
B(-10,-1,5,minecraft:stone)
B(-10,-1,6,minecraft:stone)
B(-10,0,-7,minecraft:stone)
B(-10,0,-6,minecraft:stone)
B(-10,0,-5,minecraft:stone)
B(-10,0,-4,minecraft:stone)
B(-10,0,-3,minecraft:stone)
B(-10,0,-2,minecraft:stone)
B(-10,0,-1,minecraft:stone)
B(-10,0,0,minecraft:stone)
B(-10,0,1,minecraft:stone)
B(-10,0,2,minecraft:stone)
B(-10,0,3,minecraft:stone)
B(-10,0,4,minecraft:stone)
B(-10,0,5,minecraft:stone)
B(-10,1,-7,minecraft:stone)
B(-10,1,-6,minecraft:stone)
B(-10,1,-5,minecraft:stone)
B(-10,1,-4,minecraft:stone)
B(-10,1,-3,minecraft:stone)
B(-10,1,-2,minecraft:stone)
B(-10,1,-1,minecraft:stone)
B(-10,1,0,minecraft:stone)
B(-10,1,1,minecraft:stone)
B(-10,1,2,minecraft:stone)
B(-10,1,3,minecraft:stone)
B(-10,1,4,minecraft:stone)
B(-10,2,-7,minecraft:stone)
B(-10,2,-6,minecraft:stone)
B(-10,2,-5,minecraft:stone)
B(-10,2,-4,minecraft:stone)
B(-10,2,-3,minecraft:stone)
B(-10,2,-2,minecraft:stone)
B(-10,2,-1,minecraft:stone)
B(-10,2,0,minecraft:stone)
B(-10,2,1,minecraft:stone)
B(-10,2,2,minecraft:stone)
B(-10,2,3,minecraft:stone)
B(-10,3,-6,minecraft:stone)
B(-10,3,-5,minecraft:stone)
B(-10,3,-4,minecraft:stone)
B(-10,3,-3,minecraft:stone)
B(-10,3,-2,minecraft:stone)
B(-10,3,-1,minecraft:stone)
B(-10,3,0,minecraft:stone)
B(-10,3,1,minecraft:stone)
B(-10,3,2,minecraft:stone)
B(-10,4,-6,minecraft:stone)
B(-10,4,-5,minecraft:stone)
B(-10,4,-4,minecraft:stone)
B(-10,4,-3,minecraft:stone)
B(-10,4,-2,minecraft:stone)
B(-10,4,-1,minecraft:stone)
B(-10,4,0,minecraft:stone)
B(-10,4,1,minecraft:stone)
B(-10,5,-6,minecraft:stone)
B(-10,5,-5,minecraft:stone)
B(-10,5,-4,minecraft:stone)
B(-10,5,-3,minecraft:stone)
B(-10,5,-2,minecraft:stone)
B(-10,5,-1,minecraft:stone)
B(-10,5,0,minecraft:stone)
B(-10,6,-5,minecraft:stone)
B(-10,6,-4,minecraft:stone)
B(-10,6,-3,minecraft:stone)
B(-10,6,-2,minecraft:stone)
B(-10,7,-5,minecraft:stone)
B(-10,7,-4,minecraft:stone)
B(-10,7,-3,minecraft:stone)
B(-9,-12,-1,minecraft:stone)
B(-9,-12,0,minecraft:stone)
B(-9,-12,1,minecraft:stone)
B(-9,-12,2,minecraft:stone)
B(-9,-12,3,minecraft:stone)
B(-9,-12,4,minecraft:stone)
B(-9,-12,5,minecraft:stone)
B(-9,-12,6,minecraft:stone)
B(-9,-12,7,minecraft:stone)
B(-9,-12,8,minecraft:stone)
B(-9,-12,9,minecraft:stone)
B(-9,-11,-6,minecraft:stone)
B(-9,-11,-5,minecraft:stone)
B(-9,-11,-4,minecraft:stone)
B(-9,-11,-3,minecraft:stone)
B(-9,-11,-2,minecraft:stone)
B(-9,-11,-1,minecraft:stone)
B(-9,-11,0,minecraft:stone)
B(-9,-11,1,minecraft:stone)
B(-9,-11,2,minecraft:stone)
B(-9,-11,3,minecraft:stone)
B(-9,-11,4,minecraft:stone)
B(-9,-11,5,minecraft:stone)
B(-9,-11,6,minecraft:stone)
B(-9,-11,7,minecraft:stone)
B(-9,-11,8,minecraft:stone)
B(-9,-11,9,minecraft:stone)
B(-9,-11,10,minecraft:stone)
B(-9,-11,11,minecraft:stone)
B(-9,-10,-6,minecraft:stone)
B(-9,-10,-5,minecraft:stone)
B(-9,-10,-4,minecraft:stone)
B(-9,-10,-3,minecraft:stone)
B(-9,-10,-2,minecraft:stone)
B(-9,-10,-1,minecraft:stone)
B(-9,-10,0,minecraft:stone)
B(-9,-10,1,minecraft:stone)
B(-9,-10,2,minecraft:stone)
B(-9,-10,3,minecraft:stone)
B(-9,-10,4,minecraft:stone)
B(-9,-10,5,minecraft:stone)
B(-9,-10,6,minecraft:stone)
B(-9,-10,7,minecraft:stone)
B(-9,-10,8,minecraft:stone)
B(-9,-10,9,minecraft:stone)
B(-9,-10,10,minecraft:stone)
B(-9,-10,11,minecraft:stone)
B(-9,-9,-6,minecraft:stone)
B(-9,-9,-5,minecraft:stone)
B(-9,-9,-4,minecraft:stone)
B(-9,-9,-3,minecraft:stone)
B(-9,-9,-2,minecraft:stone)
B(-9,-9,-1,minecraft:stone)
B(-9,-9,0,minecraft:stone)
B(-9,-9,1,minecraft:stone)
B(-9,-9,2,minecraft:stone)
B(-9,-9,3,minecraft:stone)
B(-9,-9,4,minecraft:stone)
B(-9,-9,5,minecraft:stone)
B(-9,-9,6,minecraft:stone)
B(-9,-9,7,minecraft:stone)
B(-9,-9,8,minecraft:stone)
B(-9,-9,9,minecraft:stone)
B(-9,-9,10,minecraft:stone)
B(-9,-9,11,minecraft:stone)
B(-9,-8,-7,minecraft:stone)
B(-9,-8,-6,minecraft:stone)
B(-9,-8,-5,minecraft:stone)
B(-9,-8,-4,minecraft:stone)
B(-9,-8,-3,minecraft:stone)
B(-9,-8,-2,minecraft:stone)
B(-9,-8,-1,minecraft:stone)
B(-9,-8,0,minecraft:stone)
B(-9,-8,1,minecraft:stone)
B(-9,-8,2,minecraft:stone)
B(-9,-8,3,minecraft:stone)
B(-9,-8,4,minecraft:stone)
B(-9,-8,5,minecraft:stone)
B(-9,-8,6,minecraft:stone)
B(-9,-8,7,minecraft:stone)
B(-9,-8,8,minecraft:stone)
B(-9,-8,9,minecraft:stone)
B(-9,-8,10,minecraft:stone)
B(-9,-8,11,minecraft:stone)
B(-9,-7,-7,minecraft:stone)
B(-9,-7,-6,minecraft:stone)
B(-9,-7,-5,minecraft:stone)
B(-9,-7,-4,minecraft:stone)
B(-9,-7,-3,minecraft:stone)
B(-9,-7,-2,minecraft:stone)
B(-9,-7,-1,minecraft:stone)
B(-9,-7,0,minecraft:stone)
B(-9,-7,1,minecraft:stone)
B(-9,-7,2,minecraft:stone)
B(-9,-7,3,minecraft:stone)
B(-9,-7,4,minecraft:stone)
B(-9,-7,5,minecraft:stone)
B(-9,-7,6,minecraft:stone)
B(-9,-7,7,minecraft:stone)
B(-9,-7,8,minecraft:stone)
B(-9,-7,9,minecraft:stone)
B(-9,-7,10,minecraft:stone)
B(-9,-6,-8,minecraft:stone)
B(-9,-6,-7,minecraft:stone)
B(-9,-6,-6,minecraft:stone)
B(-9,-6,-5,minecraft:stone)
B(-9,-6,-4,minecraft:stone)
B(-9,-6,-3,minecraft:stone)
B(-9,-6,-2,minecraft:stone)
B(-9,-6,-1,minecraft:stone)
B(-9,-6,0,minecraft:stone)
B(-9,-6,1,minecraft:stone)
B(-9,-6,2,minecraft:stone)
B(-9,-6,3,minecraft:stone)
B(-9,-6,4,minecraft:stone)
B(-9,-6,5,minecraft:stone)
B(-9,-6,6,minecraft:stone)
B(-9,-6,7,minecraft:stone)
B(-9,-6,8,minecraft:stone)
B(-9,-6,9,minecraft:stone)
B(-9,-6,10,minecraft:stone)
B(-9,-5,-8,minecraft:stone)
B(-9,-5,-7,minecraft:stone)
B(-9,-5,-6,minecraft:stone)
B(-9,-5,-5,minecraft:stone)
B(-9,-5,-4,minecraft:stone)
B(-9,-5,-3,minecraft:stone)
B(-9,-5,-2,minecraft:stone)
B(-9,-5,-1,minecraft:stone)
B(-9,-5,0,minecraft:stone)
B(-9,-5,1,minecraft:stone)
B(-9,-5,2,minecraft:stone)
B(-9,-5,3,minecraft:stone)
B(-9,-5,4,minecraft:stone)
B(-9,-5,5,minecraft:stone)
B(-9,-5,6,minecraft:stone)
B(-9,-5,7,minecraft:stone)
B(-9,-5,8,minecraft:stone)
B(-9,-5,9,minecraft:stone)
B(-9,-5,10,minecraft:stone)
B(-9,-4,-8,minecraft:stone)
B(-9,-4,-7,minecraft:stone)
B(-9,-4,-6,minecraft:stone)
B(-9,-4,-5,minecraft:stone)
B(-9,-4,-4,minecraft:stone)
B(-9,-4,-3,minecraft:stone)
B(-9,-4,-2,minecraft:stone)
B(-9,-4,-1,minecraft:stone)
B(-9,-4,0,minecraft:stone)
B(-9,-4,1,minecraft:stone)
B(-9,-4,2,minecraft:stone)
B(-9,-4,3,minecraft:stone)
B(-9,-4,4,minecraft:stone)
B(-9,-4,5,minecraft:stone)
B(-9,-4,6,minecraft:stone)
B(-9,-4,7,minecraft:stone)
B(-9,-4,8,minecraft:stone)
B(-9,-4,9,minecraft:stone)
B(-9,-3,-8,minecraft:stone)
B(-9,-3,-7,minecraft:stone)
B(-9,-3,-6,minecraft:stone)
B(-9,-3,-5,minecraft:stone)
B(-9,-3,-4,minecraft:stone)
B(-9,-3,-3,minecraft:stone)
B(-9,-3,-2,minecraft:stone)
B(-9,-3,-1,minecraft:stone)
B(-9,-3,0,minecraft:stone)
B(-9,-3,1,minecraft:stone)
B(-9,-3,2,minecraft:stone)
B(-9,-3,3,minecraft:stone)
B(-9,-3,4,minecraft:stone)
B(-9,-3,5,minecraft:stone)
B(-9,-3,6,minecraft:stone)
B(-9,-3,7,minecraft:stone)
B(-9,-3,8,minecraft:stone)
B(-9,-3,9,minecraft:stone)
B(-9,-2,-8,minecraft:stone)
B(-9,-2,-7,minecraft:stone)
B(-9,-2,-6,minecraft:stone)
B(-9,-2,-5,minecraft:stone)
B(-9,-2,-4,minecraft:stone)
B(-9,-2,-3,minecraft:stone)
B(-9,-2,-2,minecraft:stone)
B(-9,-2,-1,minecraft:stone)
B(-9,-2,0,minecraft:stone)
B(-9,-2,1,minecraft:stone)
B(-9,-2,2,minecraft:stone)
B(-9,-2,3,minecraft:stone)
B(-9,-2,4,minecraft:stone)
B(-9,-2,5,minecraft:stone)
B(-9,-2,6,minecraft:stone)
B(-9,-2,7,minecraft:stone)
B(-9,-2,8,minecraft:stone)
B(-9,-1,-8,minecraft:stone)
B(-9,-1,-7,minecraft:stone)
B(-9,-1,-6,minecraft:stone)
B(-9,-1,-5,minecraft:stone)
B(-9,-1,-4,minecraft:stone)
B(-9,-1,-3,minecraft:stone)
B(-9,-1,-2,minecraft:stone)
B(-9,-1,-1,minecraft:stone)
B(-9,-1,0,minecraft:stone)
B(-9,-1,1,minecraft:stone)
B(-9,-1,2,minecraft:stone)
B(-9,-1,3,minecraft:stone)
B(-9,-1,4,minecraft:stone)
B(-9,-1,5,minecraft:stone)
B(-9,-1,6,minecraft:stone)
B(-9,-1,7,minecraft:stone)
B(-9,0,-8,minecraft:stone)
B(-9,0,-7,minecraft:stone)
B(-9,0,-6,minecraft:stone)
B(-9,0,-5,minecraft:stone)
B(-9,0,-4,minecraft:stone)
B(-9,0,-3,minecraft:stone)
B(-9,0,-2,minecraft:stone)
B(-9,0,-1,minecraft:stone)
B(-9,0,0,minecraft:stone)
B(-9,0,1,minecraft:stone)
B(-9,0,2,minecraft:stone)
B(-9,0,3,minecraft:stone)
B(-9,0,4,minecraft:stone)
B(-9,0,5,minecraft:stone)
B(-9,0,6,minecraft:stone)
B(-9,1,-7,minecraft:stone)
B(-9,1,-6,minecraft:stone)
B(-9,1,-5,minecraft:stone)
B(-9,1,-4,minecraft:stone)
B(-9,1,-3,minecraft:stone)
B(-9,1,-2,minecraft:stone)
B(-9,1,-1,minecraft:stone)
B(-9,1,0,minecraft:stone)
B(-9,1,1,minecraft:stone)
B(-9,1,2,minecraft:stone)
B(-9,1,3,minecraft:stone)
B(-9,1,4,minecraft:stone)
B(-9,1,5,minecraft:stone)
B(-9,2,-7,minecraft:stone)
B(-9,2,-6,minecraft:stone)
B(-9,2,-5,minecraft:stone)
B(-9,2,-4,minecraft:stone)
B(-9,2,-3,minecraft:stone)
B(-9,2,-2,minecraft:stone)
B(-9,2,-1,minecraft:stone)
B(-9,2,0,minecraft:stone)
B(-9,2,1,minecraft:stone)
B(-9,2,2,minecraft:stone)
B(-9,2,3,minecraft:stone)
B(-9,2,4,minecraft:stone)
B(-9,2,5,minecraft:stone)
B(-9,3,-7,minecraft:stone)
B(-9,3,-6,minecraft:stone)
B(-9,3,-5,minecraft:stone)
B(-9,3,-4,minecraft:stone)
B(-9,3,-3,minecraft:stone)
B(-9,3,-2,minecraft:stone)
B(-9,3,-1,minecraft:stone)
B(-9,3,0,minecraft:stone)
B(-9,3,1,minecraft:stone)
B(-9,3,2,minecraft:stone)
B(-9,3,3,minecraft:stone)
B(-9,3,4,minecraft:stone)
B(-9,4,-7,minecraft:stone)
B(-9,4,-6,minecraft:stone)
B(-9,4,-5,minecraft:stone)
B(-9,4,-4,minecraft:stone)
B(-9,4,-3,minecraft:stone)
B(-9,4,-2,minecraft:stone)
B(-9,4,-1,minecraft:stone)
B(-9,4,0,minecraft:stone)
B(-9,4,1,minecraft:stone)
B(-9,4,2,minecraft:stone)
B(-9,5,-6,minecraft:stone)
B(-9,5,-5,minecraft:stone)
B(-9,5,-4,minecraft:stone)
B(-9,5,-3,minecraft:stone)
B(-9,5,-2,minecraft:stone)
B(-9,5,-1,minecraft:stone)
B(-9,5,0,minecraft:stone)
B(-9,5,1,minecraft:stone)
B(-9,6,-6,minecraft:stone)
B(-9,6,-5,minecraft:stone)
B(-9,6,-4,minecraft:stone)
B(-9,6,-3,minecraft:stone)
B(-9,6,-2,minecraft:stone)
B(-9,6,-1,minecraft:stone)
B(-9,6,0,minecraft:stone)
B(-9,7,-5,minecraft:stone)
B(-9,7,-4,minecraft:stone)
B(-9,7,-3,minecraft:stone)
B(-9,7,-2,minecraft:stone)
B(-9,8,-4,minecraft:stone)
B(-9,8,-3,minecraft:stone)
B(-8,-13,4,minecraft:stone)
B(-8,-13,5,minecraft:stone)
B(-8,-12,-2,minecraft:stone)
B(-8,-12,-1,minecraft:stone)
B(-8,-12,0,minecraft:stone)
B(-8,-12,1,minecraft:stone)
B(-8,-12,2,minecraft:stone)
B(-8,-12,3,minecraft:stone)
B(-8,-12,4,minecraft:stone)
B(-8,-12,5,minecraft:stone)
B(-8,-12,6,minecraft:stone)
B(-8,-12,7,minecraft:stone)
B(-8,-12,8,minecraft:stone)
B(-8,-12,9,minecraft:stone)
B(-8,-11,-6,minecraft:stone)
B(-8,-11,-5,minecraft:stone)
B(-8,-11,-4,minecraft:stone)
B(-8,-11,-3,minecraft:stone)
B(-8,-11,-2,minecraft:stone)
B(-8,-11,-1,minecraft:stone)
B(-8,-11,0,minecraft:stone)
B(-8,-11,1,minecraft:stone)
B(-8,-11,2,minecraft:stone)
B(-8,-11,3,minecraft:stone)
B(-8,-11,4,minecraft:stone)
B(-8,-11,5,minecraft:stone)
B(-8,-11,6,minecraft:stone)
B(-8,-11,7,minecraft:stone)
B(-8,-11,8,minecraft:stone)
B(-8,-11,9,minecraft:stone)
B(-8,-11,10,minecraft:stone)
B(-8,-11,11,minecraft:stone)
B(-8,-11,12,minecraft:stone)
B(-8,-10,-6,minecraft:stone)
B(-8,-10,-5,minecraft:stone)
B(-8,-10,-4,minecraft:stone)
B(-8,-10,-3,minecraft:stone)
B(-8,-10,-2,minecraft:stone)
B(-8,-10,-1,minecraft:stone)
B(-8,-10,0,minecraft:stone)
B(-8,-10,1,minecraft:stone)
B(-8,-10,2,minecraft:stone)
B(-8,-10,3,minecraft:stone)
B(-8,-10,4,minecraft:stone)
B(-8,-10,5,minecraft:stone)
B(-8,-10,6,minecraft:stone)
B(-8,-10,7,minecraft:stone)
B(-8,-10,8,minecraft:stone)
B(-8,-10,9,minecraft:stone)
B(-8,-10,10,minecraft:stone)
B(-8,-10,11,minecraft:stone)
B(-8,-10,12,minecraft:stone)
B(-8,-9,-7,minecraft:stone)
B(-8,-9,-6,minecraft:stone)
B(-8,-9,-5,minecraft:stone)
B(-8,-9,-4,minecraft:stone)
B(-8,-9,-3,minecraft:stone)
B(-8,-9,-2,minecraft:stone)
B(-8,-9,-1,minecraft:stone)
B(-8,-9,0,minecraft:stone)
B(-8,-9,1,minecraft:stone)
B(-8,-9,2,minecraft:stone)
B(-8,-9,3,minecraft:stone)
B(-8,-9,4,minecraft:stone)
B(-8,-9,5,minecraft:stone)
B(-8,-9,6,minecraft:stone)
B(-8,-9,7,minecraft:stone)
B(-8,-9,8,minecraft:stone)
B(-8,-9,9,minecraft:stone)
B(-8,-9,10,minecraft:stone)
B(-8,-9,11,minecraft:stone)
B(-8,-9,12,minecraft:stone)
B(-8,-8,-7,minecraft:stone)
B(-8,-8,-6,minecraft:stone)
B(-8,-8,-5,minecraft:stone)
B(-8,-8,-4,minecraft:stone)
B(-8,-8,-3,minecraft:stone)
B(-8,-8,-2,minecraft:stone)
B(-8,-8,-1,minecraft:stone)
B(-8,-8,0,minecraft:stone)
B(-8,-8,1,minecraft:stone)
B(-8,-8,2,minecraft:stone)
B(-8,-8,3,minecraft:stone)
B(-8,-8,4,minecraft:stone)
B(-8,-8,5,minecraft:stone)
B(-8,-8,6,minecraft:stone)
B(-8,-8,7,minecraft:stone)
B(-8,-8,8,minecraft:stone)
B(-8,-8,9,minecraft:stone)
B(-8,-8,10,minecraft:stone)
B(-8,-8,11,minecraft:stone)
B(-8,-7,-7,minecraft:stone)
B(-8,-7,-6,minecraft:stone)
B(-8,-7,-5,minecraft:stone)
B(-8,-7,-4,minecraft:stone)
B(-8,-7,-3,minecraft:stone)
B(-8,-7,-2,minecraft:stone)
B(-8,-7,-1,minecraft:stone)
B(-8,-7,0,minecraft:stone)
B(-8,-7,1,minecraft:stone)
B(-8,-7,2,minecraft:stone)
B(-8,-7,3,minecraft:stone)
B(-8,-7,4,minecraft:stone)
B(-8,-7,5,minecraft:stone)
B(-8,-7,6,minecraft:stone)
B(-8,-7,7,minecraft:stone)
B(-8,-7,8,minecraft:stone)
B(-8,-7,9,minecraft:stone)
B(-8,-7,10,minecraft:stone)
B(-8,-7,11,minecraft:stone)
B(-8,-6,-8,minecraft:stone)
B(-8,-6,-7,minecraft:stone)
B(-8,-6,-6,minecraft:stone)
B(-8,-6,-5,minecraft:stone)
B(-8,-6,-4,minecraft:stone)
B(-8,-6,-3,minecraft:stone)
B(-8,-6,-2,minecraft:stone)
B(-8,-6,-1,minecraft:stone)
B(-8,-6,0,minecraft:stone)
B(-8,-6,1,minecraft:stone)
B(-8,-6,2,minecraft:stone)
B(-8,-6,3,minecraft:stone)
B(-8,-6,4,minecraft:stone)
B(-8,-6,5,minecraft:stone)
B(-8,-6,6,minecraft:stone)
B(-8,-6,7,minecraft:stone)
B(-8,-6,8,minecraft:stone)
B(-8,-6,9,minecraft:stone)
B(-8,-6,10,minecraft:stone)
B(-8,-6,11,minecraft:stone)
B(-8,-5,-8,minecraft:stone)
B(-8,-5,-7,minecraft:stone)
B(-8,-5,-6,minecraft:stone)
B(-8,-5,-5,minecraft:stone)
B(-8,-5,-4,minecraft:stone)
B(-8,-5,-3,minecraft:stone)
B(-8,-5,-2,minecraft:stone)
B(-8,-5,-1,minecraft:stone)
B(-8,-5,0,minecraft:stone)
B(-8,-5,1,minecraft:stone)
B(-8,-5,2,minecraft:stone)
B(-8,-5,3,minecraft:stone)
B(-8,-5,4,minecraft:stone)
B(-8,-5,5,minecraft:stone)
B(-8,-5,6,minecraft:stone)
B(-8,-5,7,minecraft:stone)
B(-8,-5,8,minecraft:stone)
B(-8,-5,9,minecraft:stone)
B(-8,-5,10,minecraft:stone)
B(-8,-4,-8,minecraft:stone)
B(-8,-4,-7,minecraft:stone)
B(-8,-4,-6,minecraft:stone)
B(-8,-4,-5,minecraft:stone)
B(-8,-4,-4,minecraft:stone)
B(-8,-4,-3,minecraft:stone)
B(-8,-4,-2,minecraft:stone)
B(-8,-4,-1,minecraft:stone)
B(-8,-4,0,minecraft:stone)
B(-8,-4,1,minecraft:stone)
B(-8,-4,2,minecraft:stone)
B(-8,-4,3,minecraft:stone)
B(-8,-4,4,minecraft:stone)
B(-8,-4,5,minecraft:stone)
B(-8,-4,6,minecraft:stone)
B(-8,-4,7,minecraft:stone)
B(-8,-4,8,minecraft:stone)
B(-8,-4,9,minecraft:stone)
B(-8,-4,10,minecraft:stone)
B(-8,-3,-8,minecraft:stone)
B(-8,-3,-7,minecraft:stone)
B(-8,-3,-6,minecraft:stone)
B(-8,-3,-5,minecraft:stone)
B(-8,-3,-4,minecraft:stone)
B(-8,-3,-3,minecraft:stone)
B(-8,-3,-2,minecraft:stone)
B(-8,-3,-1,minecraft:stone)
B(-8,-3,0,minecraft:stone)
B(-8,-3,1,minecraft:stone)
B(-8,-3,2,minecraft:stone)
B(-8,-3,3,minecraft:stone)
B(-8,-3,4,minecraft:stone)
B(-8,-3,5,minecraft:stone)
B(-8,-3,6,minecraft:stone)
B(-8,-3,7,minecraft:stone)
B(-8,-3,8,minecraft:stone)
B(-8,-3,9,minecraft:stone)
B(-8,-3,10,minecraft:stone)
B(-8,-2,-8,minecraft:stone)
B(-8,-2,-7,minecraft:stone)
B(-8,-2,-6,minecraft:stone)
B(-8,-2,-5,minecraft:stone)
B(-8,-2,-4,minecraft:stone)
B(-8,-2,-3,minecraft:stone)
B(-8,-2,-2,minecraft:stone)
B(-8,-2,-1,minecraft:stone)
B(-8,-2,0,minecraft:stone)
B(-8,-2,1,minecraft:stone)
B(-8,-2,2,minecraft:stone)
B(-8,-2,3,minecraft:stone)
B(-8,-2,4,minecraft:stone)
B(-8,-2,5,minecraft:stone)
B(-8,-2,6,minecraft:stone)
B(-8,-2,7,minecraft:stone)
B(-8,-2,8,minecraft:stone)
B(-8,-2,9,minecraft:stone)
B(-8,-1,-8,minecraft:stone)
B(-8,-1,-7,minecraft:stone)
B(-8,-1,-6,minecraft:stone)
B(-8,-1,-5,minecraft:stone)
B(-8,-1,-4,minecraft:stone)
B(-8,-1,-3,minecraft:stone)
B(-8,-1,-2,minecraft:stone)
B(-8,-1,-1,minecraft:stone)
B(-8,-1,0,minecraft:stone)
B(-8,-1,1,minecraft:stone)
B(-8,-1,2,minecraft:stone)
B(-8,-1,3,minecraft:stone)
B(-8,-1,4,minecraft:stone)
B(-8,-1,5,minecraft:stone)
B(-8,-1,6,minecraft:stone)
B(-8,-1,7,minecraft:stone)
B(-8,-1,8,minecraft:stone)
B(-8,0,-8,minecraft:stone)
B(-8,0,-7,minecraft:stone)
B(-8,0,-6,minecraft:stone)
B(-8,0,-5,minecraft:stone)
B(-8,0,-4,minecraft:stone)
B(-8,0,-3,minecraft:stone)
B(-8,0,-2,minecraft:stone)
B(-8,0,-1,minecraft:stone)
B(-8,0,0,minecraft:stone)
B(-8,0,1,minecraft:stone)
B(-8,0,2,minecraft:stone)
B(-8,0,3,minecraft:stone)
B(-8,0,4,minecraft:stone)
B(-8,0,5,minecraft:stone)
B(-8,0,6,minecraft:stone)
B(-8,0,7,minecraft:stone)
B(-8,1,-8,minecraft:stone)
B(-8,1,-7,minecraft:stone)
B(-8,1,-6,minecraft:stone)
B(-8,1,-5,minecraft:stone)
B(-8,1,-4,minecraft:stone)
B(-8,1,-3,minecraft:stone)
B(-8,1,-2,minecraft:stone)
B(-8,1,-1,minecraft:stone)
B(-8,1,0,minecraft:stone)
B(-8,1,1,minecraft:stone)
B(-8,1,2,minecraft:stone)
B(-8,1,3,minecraft:stone)
B(-8,1,4,minecraft:stone)
B(-8,1,5,minecraft:stone)
B(-8,1,6,minecraft:stone)
B(-8,1,7,minecraft:stone)
B(-8,2,-8,minecraft:stone)
B(-8,2,-7,minecraft:stone)
B(-8,2,-6,minecraft:stone)
B(-8,2,-5,minecraft:stone)
B(-8,2,-4,minecraft:stone)
B(-8,2,-3,minecraft:stone)
B(-8,2,-2,minecraft:stone)
B(-8,2,-1,minecraft:stone)
B(-8,2,0,minecraft:stone)
B(-8,2,1,minecraft:stone)
B(-8,2,2,minecraft:stone)
B(-8,2,3,minecraft:stone)
B(-8,2,4,minecraft:stone)
B(-8,2,5,minecraft:stone)
B(-8,2,6,minecraft:stone)
B(-8,3,-7,minecraft:stone)
B(-8,3,-6,minecraft:stone)
B(-8,3,-5,minecraft:stone)
B(-8,3,-4,minecraft:stone)
B(-8,3,-3,minecraft:stone)
B(-8,3,-2,minecraft:stone)
B(-8,3,-1,minecraft:stone)
B(-8,3,0,minecraft:stone)
B(-8,3,1,minecraft:stone)
B(-8,3,2,minecraft:stone)
B(-8,3,3,minecraft:stone)
B(-8,3,4,minecraft:stone)
B(-8,3,5,minecraft:stone)
B(-8,4,-7,minecraft:stone)
B(-8,4,-6,minecraft:stone)
B(-8,4,-5,minecraft:stone)
B(-8,4,-4,minecraft:stone)
B(-8,4,-3,minecraft:stone)
B(-8,4,-2,minecraft:stone)
B(-8,4,-1,minecraft:stone)
B(-8,4,0,minecraft:stone)
B(-8,4,1,minecraft:stone)
B(-8,4,2,minecraft:stone)
B(-8,4,3,minecraft:stone)
B(-8,4,4,minecraft:stone)
B(-8,5,-7,minecraft:stone)
B(-8,5,-6,minecraft:stone)
B(-8,5,-5,minecraft:stone)
B(-8,5,-4,minecraft:stone)
B(-8,5,-3,minecraft:stone)
B(-8,5,-2,minecraft:stone)
B(-8,5,-1,minecraft:stone)
B(-8,5,0,minecraft:stone)
B(-8,5,1,minecraft:stone)
B(-8,5,2,minecraft:stone)
B(-8,5,3,minecraft:stone)
B(-8,6,-7,minecraft:stone)
B(-8,6,-6,minecraft:stone)
B(-8,6,-5,minecraft:stone)
B(-8,6,-4,minecraft:stone)
B(-8,6,-3,minecraft:stone)
B(-8,6,-2,minecraft:stone)
B(-8,6,-1,minecraft:stone)
B(-8,6,0,minecraft:stone)
B(-8,6,1,minecraft:stone)
B(-8,6,2,minecraft:stone)
B(-8,7,-6,minecraft:stone)
B(-8,7,-5,minecraft:stone)
B(-8,7,-4,minecraft:stone)
B(-8,7,-3,minecraft:stone)
B(-8,7,-2,minecraft:stone)
B(-8,7,-1,minecraft:stone)
B(-8,7,0,minecraft:stone)
B(-8,8,-5,minecraft:stone)
B(-8,8,-4,minecraft:stone)
B(-8,8,-3,minecraft:stone)
B(-8,8,-2,minecraft:stone)
B(-7,-13,3,minecraft:stone)
B(-7,-13,4,minecraft:stone)
B(-7,-13,5,minecraft:stone)
B(-7,-13,6,minecraft:stone)
B(-7,-12,-3,minecraft:stone)
B(-7,-12,-2,minecraft:stone)
B(-7,-12,-1,minecraft:stone)
B(-7,-12,0,minecraft:stone)
B(-7,-12,1,minecraft:stone)
B(-7,-12,2,minecraft:stone)
B(-7,-12,3,minecraft:stone)
B(-7,-12,4,minecraft:stone)
B(-7,-12,5,minecraft:stone)
B(-7,-12,6,minecraft:stone)
B(-7,-12,7,minecraft:stone)
B(-7,-12,8,minecraft:stone)
B(-7,-12,9,minecraft:stone)
B(-7,-12,10,minecraft:stone)
B(-7,-11,-7,minecraft:stone)
B(-7,-11,-6,minecraft:stone)
B(-7,-11,-5,minecraft:stone)
B(-7,-11,-4,minecraft:stone)
B(-7,-11,-3,minecraft:stone)
B(-7,-11,-2,minecraft:stone)
B(-7,-11,-1,minecraft:stone)
B(-7,-11,0,minecraft:stone)
B(-7,-11,1,minecraft:stone)
B(-7,-11,2,minecraft:stone)
B(-7,-11,3,minecraft:stone)
B(-7,-11,4,minecraft:stone)
B(-7,-11,5,minecraft:stone)
B(-7,-11,6,minecraft:stone)
B(-7,-11,7,minecraft:stone)
B(-7,-11,8,minecraft:stone)
B(-7,-11,9,minecraft:stone)
B(-7,-11,10,minecraft:stone)
B(-7,-11,11,minecraft:stone)
B(-7,-11,12,minecraft:stone)
B(-7,-10,-7,minecraft:stone)
B(-7,-10,-6,minecraft:stone)
B(-7,-10,-5,minecraft:stone)
B(-7,-10,-4,minecraft:stone)
B(-7,-10,-3,minecraft:stone)
B(-7,-10,-2,minecraft:stone)
B(-7,-10,-1,minecraft:stone)
B(-7,-10,0,minecraft:stone)
B(-7,-10,1,minecraft:stone)
B(-7,-10,2,minecraft:stone)
B(-7,-10,3,minecraft:stone)
B(-7,-10,4,minecraft:stone)
B(-7,-10,5,minecraft:stone)
B(-7,-10,6,minecraft:stone)
B(-7,-10,7,minecraft:stone)
B(-7,-10,8,minecraft:stone)
B(-7,-10,9,minecraft:stone)
B(-7,-10,10,minecraft:stone)
B(-7,-10,11,minecraft:stone)
B(-7,-10,12,minecraft:stone)
B(-7,-9,-7,minecraft:stone)
B(-7,-9,-6,minecraft:stone)
B(-7,-9,-5,minecraft:stone)
B(-7,-9,-4,minecraft:stone)
B(-7,-9,-3,minecraft:stone)
B(-7,-9,-2,minecraft:stone)
B(-7,-9,-1,minecraft:stone)
B(-7,-9,0,minecraft:stone)
B(-7,-9,1,minecraft:stone)
B(-7,-9,2,minecraft:stone)
B(-7,-9,3,minecraft:stone)
B(-7,-9,4,minecraft:stone)
B(-7,-9,5,minecraft:stone)
B(-7,-9,6,minecraft:stone)
B(-7,-9,7,minecraft:stone)
B(-7,-9,8,minecraft:stone)
B(-7,-9,9,minecraft:stone)
B(-7,-9,10,minecraft:stone)
B(-7,-9,11,minecraft:stone)
B(-7,-9,12,minecraft:stone)
B(-7,-8,-7,minecraft:stone)
B(-7,-8,-6,minecraft:stone)
B(-7,-8,-5,minecraft:stone)
B(-7,-8,-4,minecraft:stone)
B(-7,-8,-3,minecraft:stone)
B(-7,-8,-2,minecraft:stone)
B(-7,-8,-1,minecraft:stone)
B(-7,-8,0,minecraft:stone)
B(-7,-8,1,minecraft:stone)
B(-7,-8,2,minecraft:stone)
B(-7,-8,3,minecraft:stone)
B(-7,-8,4,minecraft:stone)
B(-7,-8,5,minecraft:stone)
B(-7,-8,6,minecraft:stone)
B(-7,-8,7,minecraft:stone)
B(-7,-8,8,minecraft:stone)
B(-7,-8,9,minecraft:stone)
B(-7,-8,10,minecraft:stone)
B(-7,-8,11,minecraft:stone)
B(-7,-8,12,minecraft:stone)
B(-7,-7,-8,minecraft:stone)
B(-7,-7,-7,minecraft:stone)
B(-7,-7,-6,minecraft:stone)
B(-7,-7,-5,minecraft:stone)
B(-7,-7,-4,minecraft:stone)
B(-7,-7,-3,minecraft:stone)
B(-7,-7,-2,minecraft:stone)
B(-7,-7,-1,minecraft:stone)
B(-7,-7,0,minecraft:stone)
B(-7,-7,1,minecraft:stone)
B(-7,-7,2,minecraft:stone)
B(-7,-7,3,minecraft:stone)
B(-7,-7,4,minecraft:stone)
B(-7,-7,5,minecraft:stone)
B(-7,-7,6,minecraft:stone)
B(-7,-7,7,minecraft:stone)
B(-7,-7,8,minecraft:stone)
B(-7,-7,9,minecraft:stone)
B(-7,-7,10,minecraft:stone)
B(-7,-7,11,minecraft:stone)
B(-7,-7,12,minecraft:stone)
B(-7,-6,-8,minecraft:stone)
B(-7,-6,-7,minecraft:stone)
B(-7,-6,-6,minecraft:stone)
B(-7,-6,-5,minecraft:stone)
B(-7,-6,-4,minecraft:stone)
B(-7,-6,-3,minecraft:stone)
B(-7,-6,-2,minecraft:stone)
B(-7,-6,-1,minecraft:stone)
B(-7,-6,0,minecraft:stone)
B(-7,-6,1,minecraft:stone)
B(-7,-6,2,minecraft:stone)
B(-7,-6,3,minecraft:stone)
B(-7,-6,4,minecraft:stone)
B(-7,-6,5,minecraft:stone)
B(-7,-6,6,minecraft:stone)
B(-7,-6,7,minecraft:stone)
B(-7,-6,8,minecraft:stone)
B(-7,-6,9,minecraft:stone)
B(-7,-6,10,minecraft:stone)
B(-7,-6,11,minecraft:stone)
B(-7,-5,-9,minecraft:stone)
B(-7,-5,-8,minecraft:stone)
B(-7,-5,-7,minecraft:stone)
B(-7,-5,-6,minecraft:stone)
B(-7,-5,-5,minecraft:stone)
B(-7,-5,-4,minecraft:stone)
B(-7,-5,-3,minecraft:stone)
B(-7,-5,-2,minecraft:stone)
B(-7,-5,-1,minecraft:stone)
B(-7,-5,0,minecraft:stone)
B(-7,-5,1,minecraft:stone)
B(-7,-5,2,minecraft:stone)
B(-7,-5,3,minecraft:stone)
B(-7,-5,4,minecraft:stone)
B(-7,-5,5,minecraft:stone)
B(-7,-5,6,minecraft:stone)
B(-7,-5,7,minecraft:stone)
B(-7,-5,8,minecraft:stone)
B(-7,-5,9,minecraft:stone)
B(-7,-5,10,minecraft:stone)
B(-7,-5,11,minecraft:stone)
B(-7,-4,-9,minecraft:stone)
B(-7,-4,-8,minecraft:stone)
B(-7,-4,-7,minecraft:stone)
B(-7,-4,-6,minecraft:stone)
B(-7,-4,-5,minecraft:stone)
B(-7,-4,-4,minecraft:stone)
B(-7,-4,-3,minecraft:stone)
B(-7,-4,-2,minecraft:stone)
B(-7,-4,-1,minecraft:stone)
B(-7,-4,0,minecraft:stone)
B(-7,-4,1,minecraft:stone)
B(-7,-4,2,minecraft:stone)
B(-7,-4,3,minecraft:stone)
B(-7,-4,4,minecraft:stone)
B(-7,-4,5,minecraft:stone)
B(-7,-4,6,minecraft:stone)
B(-7,-4,7,minecraft:stone)
B(-7,-4,8,minecraft:stone)
B(-7,-4,9,minecraft:stone)
B(-7,-4,10,minecraft:stone)
B(-7,-4,11,minecraft:stone)
B(-7,-3,-9,minecraft:stone)
B(-7,-3,-8,minecraft:stone)
B(-7,-3,-7,minecraft:stone)
B(-7,-3,-6,minecraft:stone)
B(-7,-3,-5,minecraft:stone)
B(-7,-3,-4,minecraft:stone)
B(-7,-3,-3,minecraft:stone)
B(-7,-3,-2,minecraft:stone)
B(-7,-3,-1,minecraft:stone)
B(-7,-3,0,minecraft:stone)
B(-7,-3,1,minecraft:stone)
B(-7,-3,2,minecraft:stone)
B(-7,-3,3,minecraft:stone)
B(-7,-3,4,minecraft:stone)
B(-7,-3,5,minecraft:stone)
B(-7,-3,6,minecraft:stone)
B(-7,-3,7,minecraft:stone)
B(-7,-3,8,minecraft:stone)
B(-7,-3,9,minecraft:stone)
B(-7,-3,10,minecraft:stone)
B(-7,-2,-9,minecraft:stone)
B(-7,-2,-8,minecraft:stone)
B(-7,-2,-7,minecraft:stone)
B(-7,-2,-6,minecraft:stone)
B(-7,-2,-5,minecraft:stone)
B(-7,-2,-4,minecraft:stone)
B(-7,-2,-3,minecraft:stone)
B(-7,-2,-2,minecraft:stone)
B(-7,-2,-1,minecraft:stone)
B(-7,-2,0,minecraft:stone)
B(-7,-2,1,minecraft:stone)
B(-7,-2,2,minecraft:stone)
B(-7,-2,3,minecraft:stone)
B(-7,-2,4,minecraft:stone)
B(-7,-2,5,minecraft:stone)
B(-7,-2,6,minecraft:stone)
B(-7,-2,7,minecraft:stone)
B(-7,-2,8,minecraft:stone)
B(-7,-2,9,minecraft:stone)
B(-7,-2,10,minecraft:stone)
B(-7,-1,-9,minecraft:stone)
B(-7,-1,-8,minecraft:stone)
B(-7,-1,-7,minecraft:stone)
B(-7,-1,-6,minecraft:stone)
B(-7,-1,-5,minecraft:stone)
B(-7,-1,-4,minecraft:stone)
B(-7,-1,-3,minecraft:stone)
B(-7,-1,-2,minecraft:stone)
B(-7,-1,-1,minecraft:stone)
B(-7,-1,0,minecraft:stone)
B(-7,-1,1,minecraft:stone)
B(-7,-1,2,minecraft:stone)
B(-7,-1,3,minecraft:stone)
B(-7,-1,4,minecraft:stone)
B(-7,-1,5,minecraft:stone)
B(-7,-1,6,minecraft:stone)
B(-7,-1,7,minecraft:stone)
B(-7,-1,8,minecraft:stone)
B(-7,-1,9,minecraft:stone)
B(-7,0,-8,minecraft:stone)
B(-7,0,-7,minecraft:stone)
B(-7,0,-6,minecraft:stone)
B(-7,0,-5,minecraft:stone)
B(-7,0,-4,minecraft:stone)
B(-7,0,-3,minecraft:stone)
B(-7,0,-2,minecraft:stone)
B(-7,0,-1,minecraft:stone)
B(-7,0,0,minecraft:stone)
B(-7,0,1,minecraft:stone)
B(-7,0,2,minecraft:stone)
B(-7,0,3,minecraft:stone)
B(-7,0,4,minecraft:stone)
B(-7,0,5,minecraft:stone)
B(-7,0,6,minecraft:stone)
B(-7,0,7,minecraft:stone)
B(-7,0,8,minecraft:stone)
B(-7,0,9,minecraft:stone)
B(-7,1,-8,minecraft:stone)
B(-7,1,-7,minecraft:stone)
B(-7,1,-6,minecraft:stone)
B(-7,1,-5,minecraft:stone)
B(-7,1,-4,minecraft:stone)
B(-7,1,-3,minecraft:stone)
B(-7,1,-2,minecraft:stone)
B(-7,1,-1,minecraft:stone)
B(-7,1,0,minecraft:stone)
B(-7,1,1,minecraft:stone)
B(-7,1,2,minecraft:stone)
B(-7,1,3,minecraft:stone)
B(-7,1,4,minecraft:stone)
B(-7,1,5,minecraft:stone)
B(-7,1,6,minecraft:stone)
B(-7,1,7,minecraft:stone)
B(-7,1,8,minecraft:stone)
B(-7,2,-8,minecraft:stone)
B(-7,2,-7,minecraft:stone)
B(-7,2,-6,minecraft:stone)
B(-7,2,-5,minecraft:stone)
B(-7,2,-4,minecraft:stone)
B(-7,2,-3,minecraft:stone)
B(-7,2,-2,minecraft:stone)
B(-7,2,-1,minecraft:stone)
B(-7,2,0,minecraft:stone)
B(-7,2,1,minecraft:stone)
B(-7,2,2,minecraft:stone)
B(-7,2,3,minecraft:stone)
B(-7,2,4,minecraft:stone)
B(-7,2,5,minecraft:stone)
B(-7,2,6,minecraft:stone)
B(-7,2,7,minecraft:stone)
B(-7,3,-8,minecraft:stone)
B(-7,3,-7,minecraft:stone)
B(-7,3,-6,minecraft:stone)
B(-7,3,-5,minecraft:stone)
B(-7,3,-4,minecraft:stone)
B(-7,3,-3,minecraft:stone)
B(-7,3,-2,minecraft:stone)
B(-7,3,-1,minecraft:stone)
B(-7,3,0,minecraft:stone)
B(-7,3,1,minecraft:stone)
B(-7,3,2,minecraft:stone)
B(-7,3,3,minecraft:stone)
B(-7,3,4,minecraft:stone)
B(-7,3,5,minecraft:stone)
B(-7,3,6,minecraft:stone)
B(-7,4,-8,minecraft:stone)
B(-7,4,-7,minecraft:stone)
B(-7,4,-6,minecraft:stone)
B(-7,4,-5,minecraft:stone)
B(-7,4,-4,minecraft:stone)
B(-7,4,-3,minecraft:stone)
B(-7,4,-2,minecraft:stone)
B(-7,4,-1,minecraft:stone)
B(-7,4,0,minecraft:stone)
B(-7,4,1,minecraft:stone)
B(-7,4,2,minecraft:stone)
B(-7,4,3,minecraft:stone)
B(-7,4,4,minecraft:stone)
B(-7,4,5,minecraft:stone)
B(-7,5,-7,minecraft:stone)
B(-7,5,-6,minecraft:stone)
B(-7,5,-5,minecraft:stone)
B(-7,5,-4,minecraft:stone)
B(-7,5,-3,minecraft:stone)
B(-7,5,-2,minecraft:stone)
B(-7,5,-1,minecraft:stone)
B(-7,5,0,minecraft:stone)
B(-7,5,1,minecraft:stone)
B(-7,5,2,minecraft:stone)
B(-7,5,3,minecraft:stone)
B(-7,5,4,minecraft:stone)
B(-7,6,-7,minecraft:stone)
B(-7,6,-6,minecraft:stone)
B(-7,6,-5,minecraft:stone)
B(-7,6,-4,minecraft:stone)
B(-7,6,-3,minecraft:stone)
B(-7,6,-2,minecraft:stone)
B(-7,6,-1,minecraft:stone)
B(-7,6,0,minecraft:stone)
B(-7,6,1,minecraft:stone)
B(-7,6,2,minecraft:stone)
B(-7,6,3,minecraft:stone)
B(-7,7,-6,minecraft:stone)
B(-7,7,-5,minecraft:stone)
B(-7,7,-4,minecraft:stone)
B(-7,7,-3,minecraft:stone)
B(-7,7,-2,minecraft:stone)
B(-7,7,-1,minecraft:stone)
B(-7,7,0,minecraft:stone)
B(-7,7,1,minecraft:stone)
B(-7,7,2,minecraft:stone)
B(-7,8,-5,minecraft:stone)
B(-7,8,-4,minecraft:stone)
B(-7,8,-3,minecraft:stone)
B(-7,8,-2,minecraft:stone)
B(-7,8,-1,minecraft:stone)
B(-7,8,0,minecraft:stone)
B(-6,-13,3,minecraft:stone)
B(-6,-13,4,minecraft:stone)
B(-6,-13,5,minecraft:stone)
B(-6,-13,6,minecraft:stone)
B(-6,-13,7,minecraft:stone)
B(-6,-12,-4,minecraft:stone)
B(-6,-12,-3,minecraft:stone)
B(-6,-12,-2,minecraft:stone)
B(-6,-12,-1,minecraft:stone)
B(-6,-12,0,minecraft:stone)
B(-6,-12,1,minecraft:stone)
B(-6,-12,2,minecraft:stone)
B(-6,-12,3,minecraft:stone)
B(-6,-12,4,minecraft:stone)
B(-6,-12,5,minecraft:stone)
B(-6,-12,6,minecraft:stone)
B(-6,-12,7,minecraft:stone)
B(-6,-12,8,minecraft:stone)
B(-6,-12,9,minecraft:stone)
B(-6,-12,10,minecraft:stone)
B(-6,-12,11,minecraft:stone)
B(-6,-11,-7,minecraft:stone)
B(-6,-11,-6,minecraft:stone)
B(-6,-11,-5,minecraft:stone)
B(-6,-11,-4,minecraft:stone)
B(-6,-11,-3,minecraft:stone)
B(-6,-11,-2,minecraft:stone)
B(-6,-11,-1,minecraft:stone)
B(-6,-11,0,minecraft:stone)
B(-6,-11,1,minecraft:stone)
B(-6,-11,2,minecraft:stone)
B(-6,-11,3,minecraft:stone)
B(-6,-11,4,minecraft:stone)
B(-6,-11,5,minecraft:stone)
B(-6,-11,6,minecraft:stone)
B(-6,-11,7,minecraft:stone)
B(-6,-11,8,minecraft:stone)
B(-6,-11,9,minecraft:stone)
B(-6,-11,10,minecraft:stone)
B(-6,-11,11,minecraft:stone)
B(-6,-11,12,minecraft:stone)
B(-6,-10,-7,minecraft:stone)
B(-6,-10,-6,minecraft:stone)
B(-6,-10,-5,minecraft:stone)
B(-6,-10,-4,minecraft:stone)
B(-6,-10,-3,minecraft:stone)
B(-6,-10,-2,minecraft:stone)
B(-6,-10,-1,minecraft:stone)
B(-6,-10,0,minecraft:stone)
B(-6,-10,1,minecraft:stone)
B(-6,-10,2,minecraft:stone)
B(-6,-10,3,minecraft:stone)
B(-6,-10,4,minecraft:stone)
B(-6,-10,5,minecraft:stone)
B(-6,-10,6,minecraft:stone)
B(-6,-10,7,minecraft:stone)
B(-6,-10,8,minecraft:stone)
B(-6,-10,9,minecraft:stone)
B(-6,-10,10,minecraft:stone)
B(-6,-10,11,minecraft:stone)
B(-6,-10,12,minecraft:stone)
B(-6,-9,-8,minecraft:stone)
B(-6,-9,-7,minecraft:stone)
B(-6,-9,-6,minecraft:stone)
B(-6,-9,-5,minecraft:stone)
B(-6,-9,-4,minecraft:stone)
B(-6,-9,-3,minecraft:stone)
B(-6,-9,-2,minecraft:stone)
B(-6,-9,-1,minecraft:stone)
B(-6,-9,0,minecraft:stone)
B(-6,-9,1,minecraft:stone)
B(-6,-9,2,minecraft:stone)
B(-6,-9,3,minecraft:stone)
B(-6,-9,4,minecraft:stone)
B(-6,-9,5,minecraft:stone)
B(-6,-9,6,minecraft:stone)
B(-6,-9,7,minecraft:stone)
B(-6,-9,8,minecraft:stone)
B(-6,-9,9,minecraft:stone)
B(-6,-9,10,minecraft:stone)
B(-6,-9,11,minecraft:stone)
B(-6,-9,12,minecraft:stone)
B(-6,-8,-8,minecraft:stone)
B(-6,-8,-7,minecraft:stone)
B(-6,-8,-6,minecraft:stone)
B(-6,-8,-5,minecraft:stone)
B(-6,-8,-4,minecraft:stone)
B(-6,-8,-3,minecraft:stone)
B(-6,-8,-2,minecraft:stone)
B(-6,-8,-1,minecraft:stone)
B(-6,-8,0,minecraft:stone)
B(-6,-8,1,minecraft:stone)
B(-6,-8,2,minecraft:stone)
B(-6,-8,3,minecraft:stone)
B(-6,-8,4,minecraft:stone)
B(-6,-8,5,minecraft:stone)
B(-6,-8,6,minecraft:stone)
B(-6,-8,7,minecraft:stone)
B(-6,-8,8,minecraft:stone)
B(-6,-8,9,minecraft:stone)
B(-6,-8,10,minecraft:stone)
B(-6,-8,11,minecraft:stone)
B(-6,-8,12,minecraft:stone)
B(-6,-7,-8,minecraft:stone)
B(-6,-7,-7,minecraft:stone)
B(-6,-7,-6,minecraft:stone)
B(-6,-7,-5,minecraft:stone)
B(-6,-7,-4,minecraft:stone)
B(-6,-7,-3,minecraft:stone)
B(-6,-7,-2,minecraft:stone)
B(-6,-7,-1,minecraft:stone)
B(-6,-7,0,minecraft:stone)
B(-6,-7,1,minecraft:stone)
B(-6,-7,2,minecraft:stone)
B(-6,-7,3,minecraft:stone)
B(-6,-7,4,minecraft:stone)
B(-6,-7,5,minecraft:stone)
B(-6,-7,6,minecraft:stone)
B(-6,-7,7,minecraft:stone)
B(-6,-7,8,minecraft:stone)
B(-6,-7,9,minecraft:stone)
B(-6,-7,10,minecraft:stone)
B(-6,-7,11,minecraft:stone)
B(-6,-7,12,minecraft:stone)
B(-6,-6,-9,minecraft:stone)
B(-6,-6,-8,minecraft:stone)
B(-6,-6,-7,minecraft:stone)
B(-6,-6,-6,minecraft:stone)
B(-6,-6,-5,minecraft:stone)
B(-6,-6,-4,minecraft:stone)
B(-6,-6,-3,minecraft:stone)
B(-6,-6,-2,minecraft:stone)
B(-6,-6,-1,minecraft:stone)
B(-6,-6,0,minecraft:stone)
B(-6,-6,1,minecraft:stone)
B(-6,-6,2,minecraft:stone)
B(-6,-6,3,minecraft:stone)
B(-6,-6,4,minecraft:stone)
B(-6,-6,5,minecraft:stone)
B(-6,-6,6,minecraft:stone)
B(-6,-6,7,minecraft:stone)
B(-6,-6,8,minecraft:stone)
B(-6,-6,9,minecraft:stone)
B(-6,-6,10,minecraft:stone)
B(-6,-6,11,minecraft:stone)
B(-6,-6,12,minecraft:stone)
B(-6,-5,-9,minecraft:stone)
B(-6,-5,-8,minecraft:stone)
B(-6,-5,-7,minecraft:stone)
B(-6,-5,-6,minecraft:stone)
B(-6,-5,-5,minecraft:stone)
B(-6,-5,-4,minecraft:stone)
B(-6,-5,-3,minecraft:stone)
B(-6,-5,-2,minecraft:stone)
B(-6,-5,-1,minecraft:stone)
B(-6,-5,0,minecraft:stone)
B(-6,-5,1,minecraft:stone)
B(-6,-5,2,minecraft:stone)
B(-6,-5,3,minecraft:stone)
B(-6,-5,4,minecraft:stone)
B(-6,-5,5,minecraft:stone)
B(-6,-5,6,minecraft:stone)
B(-6,-5,7,minecraft:stone)
B(-6,-5,8,minecraft:stone)
B(-6,-5,9,minecraft:stone)
B(-6,-5,10,minecraft:stone)
B(-6,-5,11,minecraft:stone)
B(-6,-5,12,minecraft:stone)
B(-6,-4,-9,minecraft:stone)
B(-6,-4,-8,minecraft:stone)
B(-6,-4,-7,minecraft:stone)
B(-6,-4,-6,minecraft:stone)
B(-6,-4,-5,minecraft:stone)
B(-6,-4,-4,minecraft:stone)
B(-6,-4,-3,minecraft:stone)
B(-6,-4,-2,minecraft:stone)
B(-6,-4,-1,minecraft:stone)
B(-6,-4,0,minecraft:stone)
B(-6,-4,1,minecraft:stone)
B(-6,-4,2,minecraft:stone)
B(-6,-4,3,minecraft:stone)
B(-6,-4,4,minecraft:stone)
B(-6,-4,5,minecraft:stone)
B(-6,-4,6,minecraft:stone)
B(-6,-4,7,minecraft:stone)
B(-6,-4,8,minecraft:stone)
B(-6,-4,9,minecraft:stone)
B(-6,-4,10,minecraft:stone)
B(-6,-4,11,minecraft:stone)
B(-6,-3,-9,minecraft:stone)
B(-6,-3,-8,minecraft:stone)
B(-6,-3,-7,minecraft:stone)
B(-6,-3,-6,minecraft:stone)
B(-6,-3,-5,minecraft:stone)
B(-6,-3,-4,minecraft:stone)
B(-6,-3,-3,minecraft:stone)
B(-6,-3,-2,minecraft:stone)
B(-6,-3,-1,minecraft:stone)
B(-6,-3,0,minecraft:stone)
B(-6,-3,1,minecraft:stone)
B(-6,-3,2,minecraft:stone)
B(-6,-3,3,minecraft:stone)
B(-6,-3,4,minecraft:stone)
B(-6,-3,5,minecraft:stone)
B(-6,-3,6,minecraft:stone)
B(-6,-3,7,minecraft:stone)
B(-6,-3,8,minecraft:stone)
B(-6,-3,9,minecraft:stone)
B(-6,-3,10,minecraft:stone)
B(-6,-3,11,minecraft:stone)
B(-6,-2,-9,minecraft:stone)
B(-6,-2,-8,minecraft:stone)
B(-6,-2,-7,minecraft:stone)
B(-6,-2,-6,minecraft:stone)
B(-6,-2,-5,minecraft:stone)
B(-6,-2,-4,minecraft:stone)
B(-6,-2,-3,minecraft:stone)
B(-6,-2,-2,minecraft:stone)
B(-6,-2,-1,minecraft:stone)
B(-6,-2,0,minecraft:stone)
B(-6,-2,1,minecraft:stone)
B(-6,-2,2,minecraft:stone)
B(-6,-2,3,minecraft:stone)
B(-6,-2,4,minecraft:stone)
B(-6,-2,5,minecraft:stone)
B(-6,-2,6,minecraft:stone)
B(-6,-2,7,minecraft:stone)
B(-6,-2,8,minecraft:stone)
B(-6,-2,9,minecraft:stone)
B(-6,-2,10,minecraft:stone)
B(-6,-1,-9,minecraft:stone)
B(-6,-1,-8,minecraft:stone)
B(-6,-1,-7,minecraft:stone)
B(-6,-1,-6,minecraft:stone)
B(-6,-1,-5,minecraft:stone)
B(-6,-1,-4,minecraft:stone)
B(-6,-1,-3,minecraft:stone)
B(-6,-1,-2,minecraft:stone)
B(-6,-1,-1,minecraft:stone)
B(-6,-1,0,minecraft:stone)
B(-6,-1,1,minecraft:stone)
B(-6,-1,2,minecraft:stone)
B(-6,-1,3,minecraft:stone)
B(-6,-1,4,minecraft:stone)
B(-6,-1,5,minecraft:stone)
B(-6,-1,6,minecraft:stone)
B(-6,-1,7,minecraft:stone)
B(-6,-1,8,minecraft:stone)
B(-6,-1,9,minecraft:stone)
B(-6,-1,10,minecraft:stone)
B(-6,0,-9,minecraft:stone)
B(-6,0,-8,minecraft:stone)
B(-6,0,-7,minecraft:stone)
B(-6,0,-6,minecraft:stone)
B(-6,0,-5,minecraft:stone)
B(-6,0,-4,minecraft:stone)
B(-6,0,-3,minecraft:stone)
B(-6,0,-2,minecraft:stone)
B(-6,0,-1,minecraft:stone)
B(-6,0,0,minecraft:stone)
B(-6,0,1,minecraft:stone)
B(-6,0,2,minecraft:stone)
B(-6,0,3,minecraft:stone)
B(-6,0,4,minecraft:stone)
B(-6,0,5,minecraft:stone)
B(-6,0,6,minecraft:stone)
B(-6,0,7,minecraft:stone)
B(-6,0,8,minecraft:stone)
B(-6,0,9,minecraft:stone)
B(-6,1,-9,minecraft:stone)
B(-6,1,-8,minecraft:stone)
B(-6,1,-7,minecraft:stone)
B(-6,1,-6,minecraft:stone)
B(-6,1,-5,minecraft:stone)
B(-6,1,-4,minecraft:stone)
B(-6,1,-3,minecraft:stone)
B(-6,1,-2,minecraft:stone)
B(-6,1,-1,minecraft:stone)
B(-6,1,0,minecraft:stone)
B(-6,1,1,minecraft:stone)
B(-6,1,2,minecraft:stone)
B(-6,1,3,minecraft:stone)
B(-6,1,4,minecraft:stone)
B(-6,1,5,minecraft:stone)
B(-6,1,6,minecraft:stone)
B(-6,1,7,minecraft:stone)
B(-6,1,8,minecraft:stone)
B(-6,1,9,minecraft:stone)
B(-6,2,-9,minecraft:stone)
B(-6,2,-8,minecraft:stone)
B(-6,2,-7,minecraft:stone)
B(-6,2,-6,minecraft:stone)
B(-6,2,-5,minecraft:stone)
B(-6,2,-4,minecraft:stone)
B(-6,2,-3,minecraft:stone)
B(-6,2,-2,minecraft:stone)
B(-6,2,-1,minecraft:stone)
B(-6,2,0,minecraft:stone)
B(-6,2,1,minecraft:stone)
B(-6,2,2,minecraft:stone)
B(-6,2,3,minecraft:stone)
B(-6,2,4,minecraft:stone)
B(-6,2,5,minecraft:stone)
B(-6,2,6,minecraft:stone)
B(-6,2,7,minecraft:stone)
B(-6,2,8,minecraft:stone)
B(-6,3,-8,minecraft:stone)
B(-6,3,-7,minecraft:stone)
B(-6,3,-6,minecraft:stone)
B(-6,3,-5,minecraft:stone)
B(-6,3,-4,minecraft:stone)
B(-6,3,-3,minecraft:stone)
B(-6,3,-2,minecraft:stone)
B(-6,3,-1,minecraft:stone)
B(-6,3,0,minecraft:stone)
B(-6,3,1,minecraft:stone)
B(-6,3,2,minecraft:stone)
B(-6,3,3,minecraft:stone)
B(-6,3,4,minecraft:stone)
B(-6,3,5,minecraft:stone)
B(-6,3,6,minecraft:stone)
B(-6,3,7,minecraft:stone)
B(-6,4,-8,minecraft:stone)
B(-6,4,-7,minecraft:stone)
B(-6,4,-6,minecraft:stone)
B(-6,4,-5,minecraft:stone)
B(-6,4,-4,minecraft:stone)
B(-6,4,-3,minecraft:stone)
B(-6,4,-2,minecraft:stone)
B(-6,4,-1,minecraft:stone)
B(-6,4,0,minecraft:stone)
B(-6,4,1,minecraft:stone)
B(-6,4,2,minecraft:stone)
B(-6,4,3,minecraft:stone)
B(-6,4,4,minecraft:stone)
B(-6,4,5,minecraft:stone)
B(-6,4,6,minecraft:stone)
B(-6,5,-8,minecraft:stone)
B(-6,5,-7,minecraft:stone)
B(-6,5,-6,minecraft:stone)
B(-6,5,-5,minecraft:stone)
B(-6,5,-4,minecraft:stone)
B(-6,5,-3,minecraft:stone)
B(-6,5,-2,minecraft:stone)
B(-6,5,-1,minecraft:stone)
B(-6,5,0,minecraft:stone)
B(-6,5,1,minecraft:stone)
B(-6,5,2,minecraft:stone)
B(-6,5,3,minecraft:stone)
B(-6,5,4,minecraft:stone)
B(-6,5,5,minecraft:stone)
B(-6,6,-7,minecraft:stone)
B(-6,6,-6,minecraft:stone)
B(-6,6,-5,minecraft:stone)
B(-6,6,-4,minecraft:stone)
B(-6,6,-3,minecraft:stone)
B(-6,6,-2,minecraft:stone)
B(-6,6,-1,minecraft:stone)
B(-6,6,0,minecraft:stone)
B(-6,6,1,minecraft:stone)
B(-6,6,2,minecraft:stone)
B(-6,6,3,minecraft:stone)
B(-6,6,4,minecraft:stone)
B(-6,7,-6,minecraft:stone)
B(-6,7,-5,minecraft:stone)
B(-6,7,-4,minecraft:stone)
B(-6,7,-3,minecraft:stone)
B(-6,7,-2,minecraft:stone)
B(-6,7,-1,minecraft:stone)
B(-6,7,0,minecraft:stone)
B(-6,7,1,minecraft:stone)
B(-6,7,2,minecraft:stone)
B(-6,7,3,minecraft:stone)
B(-6,8,-5,minecraft:stone)
B(-6,8,-4,minecraft:stone)
B(-6,8,-3,minecraft:stone)
B(-6,8,-2,minecraft:stone)
B(-6,8,-1,minecraft:stone)
B(-6,8,0,minecraft:stone)
B(-6,8,1,minecraft:stone)
B(-6,9,-2,minecraft:stone)
B(-6,9,-1,minecraft:stone)
B(-6,9,0,minecraft:stone)
B(-5,-13,3,minecraft:stone)
B(-5,-13,4,minecraft:stone)
B(-5,-13,5,minecraft:stone)
B(-5,-13,6,minecraft:stone)
B(-5,-13,7,minecraft:stone)
B(-5,-13,8,minecraft:stone)
B(-5,-12,-4,minecraft:stone)
B(-5,-12,-3,minecraft:stone)
B(-5,-12,-2,minecraft:stone)
B(-5,-12,-1,minecraft:stone)
B(-5,-12,0,minecraft:stone)
B(-5,-12,1,minecraft:stone)
B(-5,-12,2,minecraft:stone)
B(-5,-12,3,minecraft:stone)
B(-5,-12,4,minecraft:stone)
B(-5,-12,5,minecraft:stone)
B(-5,-12,6,minecraft:stone)
B(-5,-12,7,minecraft:stone)
B(-5,-12,8,minecraft:stone)
B(-5,-12,9,minecraft:stone)
B(-5,-12,10,minecraft:stone)
B(-5,-12,11,minecraft:stone)
B(-5,-11,-7,minecraft:stone)
B(-5,-11,-6,minecraft:stone)
B(-5,-11,-5,minecraft:stone)
B(-5,-11,-4,minecraft:stone)
B(-5,-11,-3,minecraft:stone)
B(-5,-11,-2,minecraft:stone)
B(-5,-11,-1,minecraft:stone)
B(-5,-11,0,minecraft:stone)
B(-5,-11,1,minecraft:stone)
B(-5,-11,2,minecraft:stone)
B(-5,-11,3,minecraft:stone)
B(-5,-11,4,minecraft:stone)
B(-5,-11,5,minecraft:stone)
B(-5,-11,6,minecraft:stone)
B(-5,-11,7,minecraft:stone)
B(-5,-11,8,minecraft:stone)
B(-5,-11,9,minecraft:stone)
B(-5,-11,10,minecraft:stone)
B(-5,-11,11,minecraft:stone)
B(-5,-11,12,minecraft:stone)
B(-5,-10,-8,minecraft:stone)
B(-5,-10,-7,minecraft:stone)
B(-5,-10,-6,minecraft:stone)
B(-5,-10,-5,minecraft:stone)
B(-5,-10,-4,minecraft:stone)
B(-5,-10,-3,minecraft:stone)
B(-5,-10,-2,minecraft:stone)
B(-5,-10,-1,minecraft:stone)
B(-5,-10,0,minecraft:stone)
B(-5,-10,1,minecraft:stone)
B(-5,-10,2,minecraft:stone)
B(-5,-10,3,minecraft:stone)
B(-5,-10,4,minecraft:stone)
B(-5,-10,5,minecraft:stone)
B(-5,-10,6,minecraft:stone)
B(-5,-10,7,minecraft:stone)
B(-5,-10,8,minecraft:stone)
B(-5,-10,9,minecraft:stone)
B(-5,-10,10,minecraft:stone)
B(-5,-10,11,minecraft:stone)
B(-5,-10,12,minecraft:stone)
B(-5,-9,-8,minecraft:stone)
B(-5,-9,-7,minecraft:stone)
B(-5,-9,-6,minecraft:stone)
B(-5,-9,-5,minecraft:stone)
B(-5,-9,-4,minecraft:stone)
B(-5,-9,-3,minecraft:stone)
B(-5,-9,-2,minecraft:stone)
B(-5,-9,-1,minecraft:stone)
B(-5,-9,0,minecraft:stone)
B(-5,-9,1,minecraft:stone)
B(-5,-9,2,minecraft:stone)
B(-5,-9,3,minecraft:stone)
B(-5,-9,4,minecraft:stone)
B(-5,-9,5,minecraft:stone)
B(-5,-9,6,minecraft:stone)
B(-5,-9,7,minecraft:stone)
B(-5,-9,8,minecraft:stone)
B(-5,-9,9,minecraft:stone)
B(-5,-9,10,minecraft:stone)
B(-5,-9,11,minecraft:stone)
B(-5,-9,12,minecraft:stone)
B(-5,-8,-8,minecraft:stone)
B(-5,-8,-7,minecraft:stone)
B(-5,-8,-6,minecraft:stone)
B(-5,-8,-5,minecraft:stone)
B(-5,-8,-4,minecraft:stone)
B(-5,-8,-3,minecraft:stone)
B(-5,-8,-2,minecraft:stone)
B(-5,-8,-1,minecraft:stone)
B(-5,-8,0,minecraft:stone)
B(-5,-8,1,minecraft:stone)
B(-5,-8,2,minecraft:stone)
B(-5,-8,3,minecraft:stone)
B(-5,-8,4,minecraft:stone)
B(-5,-8,5,minecraft:stone)
B(-5,-8,6,minecraft:stone)
B(-5,-8,7,minecraft:stone)
B(-5,-8,8,minecraft:stone)
B(-5,-8,9,minecraft:stone)
B(-5,-8,10,minecraft:stone)
B(-5,-8,11,minecraft:stone)
B(-5,-8,12,minecraft:stone)
B(-5,-7,-9,minecraft:stone)
B(-5,-7,-8,minecraft:stone)
B(-5,-7,-7,minecraft:stone)
B(-5,-7,-6,minecraft:stone)
B(-5,-7,-5,minecraft:stone)
B(-5,-7,-4,minecraft:stone)
B(-5,-7,-3,minecraft:stone)
B(-5,-7,-2,minecraft:stone)
B(-5,-7,-1,minecraft:stone)
B(-5,-7,0,minecraft:stone)
B(-5,-7,1,minecraft:stone)
B(-5,-7,2,minecraft:stone)
B(-5,-7,3,minecraft:stone)
B(-5,-7,4,minecraft:stone)
B(-5,-7,5,minecraft:stone)
B(-5,-7,6,minecraft:stone)
B(-5,-7,7,minecraft:stone)
B(-5,-7,8,minecraft:stone)
B(-5,-7,9,minecraft:stone)
B(-5,-7,10,minecraft:stone)
B(-5,-7,11,minecraft:stone)
B(-5,-7,12,minecraft:stone)
B(-5,-6,-9,minecraft:stone)
B(-5,-6,-8,minecraft:stone)
B(-5,-6,-7,minecraft:stone)
B(-5,-6,-6,minecraft:stone)
B(-5,-6,-5,minecraft:stone)
B(-5,-6,-4,minecraft:stone)
B(-5,-6,-3,minecraft:stone)
B(-5,-6,-2,minecraft:stone)
B(-5,-6,-1,minecraft:stone)
B(-5,-6,0,minecraft:stone)
B(-5,-6,1,minecraft:stone)
B(-5,-6,2,minecraft:stone)
B(-5,-6,3,minecraft:stone)
B(-5,-6,4,minecraft:stone)
B(-5,-6,5,minecraft:stone)
B(-5,-6,6,minecraft:stone)
B(-5,-6,7,minecraft:stone)
B(-5,-6,8,minecraft:stone)
B(-5,-6,9,minecraft:stone)
B(-5,-6,10,minecraft:stone)
B(-5,-6,11,minecraft:stone)
B(-5,-6,12,minecraft:stone)
B(-5,-5,-10,minecraft:stone)
B(-5,-5,-9,minecraft:stone)
B(-5,-5,-8,minecraft:stone)
B(-5,-5,-7,minecraft:stone)
B(-5,-5,-6,minecraft:stone)
B(-5,-5,-5,minecraft:stone)
B(-5,-5,-4,minecraft:stone)
B(-5,-5,-3,minecraft:stone)
B(-5,-5,-2,minecraft:stone)
B(-5,-5,-1,minecraft:stone)
B(-5,-5,0,minecraft:stone)
B(-5,-5,1,minecraft:stone)
B(-5,-5,2,minecraft:stone)
B(-5,-5,3,minecraft:stone)
B(-5,-5,4,minecraft:stone)
B(-5,-5,5,minecraft:stone)
B(-5,-5,6,minecraft:stone)
B(-5,-5,7,minecraft:stone)
B(-5,-5,8,minecraft:stone)
B(-5,-5,9,minecraft:stone)
B(-5,-5,10,minecraft:stone)
B(-5,-5,11,minecraft:stone)
B(-5,-5,12,minecraft:stone)
B(-5,-4,-10,minecraft:stone)
B(-5,-4,-9,minecraft:stone)
B(-5,-4,-8,minecraft:stone)
B(-5,-4,-7,minecraft:stone)
B(-5,-4,-6,minecraft:stone)
B(-5,-4,-5,minecraft:stone)
B(-5,-4,-4,minecraft:stone)
B(-5,-4,-3,minecraft:stone)
B(-5,-4,-2,minecraft:stone)
B(-5,-4,-1,minecraft:stone)
B(-5,-4,0,minecraft:stone)
B(-5,-4,1,minecraft:stone)
B(-5,-4,2,minecraft:stone)
B(-5,-4,3,minecraft:stone)
B(-5,-4,4,minecraft:stone)
B(-5,-4,5,minecraft:stone)
B(-5,-4,6,minecraft:stone)
B(-5,-4,7,minecraft:stone)
B(-5,-4,8,minecraft:stone)
B(-5,-4,9,minecraft:stone)
B(-5,-4,10,minecraft:stone)
B(-5,-4,11,minecraft:stone)
B(-5,-4,12,minecraft:stone)
B(-5,-3,-10,minecraft:stone)
B(-5,-3,-9,minecraft:stone)
B(-5,-3,-8,minecraft:stone)
B(-5,-3,-7,minecraft:stone)
B(-5,-3,-6,minecraft:stone)
B(-5,-3,-5,minecraft:stone)
B(-5,-3,-4,minecraft:stone)
B(-5,-3,-3,minecraft:stone)
B(-5,-3,-2,minecraft:stone)
B(-5,-3,-1,minecraft:stone)
B(-5,-3,0,minecraft:stone)
B(-5,-3,1,minecraft:stone)
B(-5,-3,2,minecraft:stone)
B(-5,-3,3,minecraft:stone)
B(-5,-3,4,minecraft:stone)
B(-5,-3,5,minecraft:stone)
B(-5,-3,6,minecraft:stone)
B(-5,-3,7,minecraft:stone)
B(-5,-3,8,minecraft:stone)
B(-5,-3,9,minecraft:stone)
B(-5,-3,10,minecraft:stone)
B(-5,-3,11,minecraft:stone)
B(-5,-2,-10,minecraft:stone)
B(-5,-2,-9,minecraft:stone)
B(-5,-2,-8,minecraft:stone)
B(-5,-2,-7,minecraft:stone)
B(-5,-2,-6,minecraft:stone)
B(-5,-2,-5,minecraft:stone)
B(-5,-2,-4,minecraft:stone)
B(-5,-2,-3,minecraft:stone)
B(-5,-2,-2,minecraft:stone)
B(-5,-2,-1,minecraft:stone)
B(-5,-2,0,minecraft:stone)
B(-5,-2,1,minecraft:stone)
B(-5,-2,2,minecraft:stone)
B(-5,-2,3,minecraft:stone)
B(-5,-2,4,minecraft:stone)
B(-5,-2,5,minecraft:stone)
B(-5,-2,6,minecraft:stone)
B(-5,-2,7,minecraft:stone)
B(-5,-2,8,minecraft:stone)
B(-5,-2,9,minecraft:stone)
B(-5,-2,10,minecraft:stone)
B(-5,-2,11,minecraft:stone)
B(-5,-1,-9,minecraft:stone)
B(-5,-1,-8,minecraft:stone)
B(-5,-1,-7,minecraft:stone)
B(-5,-1,-6,minecraft:stone)
B(-5,-1,-5,minecraft:stone)
B(-5,-1,-4,minecraft:stone)
B(-5,-1,-3,minecraft:stone)
B(-5,-1,-2,minecraft:stone)
B(-5,-1,-1,minecraft:stone)
B(-5,-1,0,minecraft:stone)
B(-5,-1,1,minecraft:stone)
B(-5,-1,2,minecraft:stone)
B(-5,-1,3,minecraft:stone)
B(-5,-1,4,minecraft:stone)
B(-5,-1,5,minecraft:stone)
B(-5,-1,6,minecraft:stone)
B(-5,-1,7,minecraft:stone)
B(-5,-1,8,minecraft:stone)
B(-5,-1,9,minecraft:stone)
B(-5,-1,10,minecraft:stone)
B(-5,-1,11,minecraft:stone)
B(-5,0,-9,minecraft:stone)
B(-5,0,-8,minecraft:stone)
B(-5,0,-7,minecraft:stone)
B(-5,0,-6,minecraft:stone)
B(-5,0,-5,minecraft:stone)
B(-5,0,-4,minecraft:stone)
B(-5,0,-3,minecraft:stone)
B(-5,0,-2,minecraft:stone)
B(-5,0,-1,minecraft:stone)
B(-5,0,0,minecraft:stone)
B(-5,0,1,minecraft:stone)
B(-5,0,2,minecraft:stone)
B(-5,0,3,minecraft:stone)
B(-5,0,4,minecraft:stone)
B(-5,0,5,minecraft:stone)
B(-5,0,6,minecraft:stone)
B(-5,0,7,minecraft:stone)
B(-5,0,8,minecraft:stone)
B(-5,0,9,minecraft:stone)
B(-5,0,10,minecraft:stone)
B(-5,1,-9,minecraft:stone)
B(-5,1,-8,minecraft:stone)
B(-5,1,-7,minecraft:stone)
B(-5,1,-6,minecraft:stone)
B(-5,1,-5,minecraft:stone)
B(-5,1,-4,minecraft:stone)
B(-5,1,-3,minecraft:stone)
B(-5,1,-2,minecraft:stone)
B(-5,1,-1,minecraft:stone)
B(-5,1,0,minecraft:stone)
B(-5,1,1,minecraft:stone)
B(-5,1,2,minecraft:stone)
B(-5,1,3,minecraft:stone)
B(-5,1,4,minecraft:stone)
B(-5,1,5,minecraft:stone)
B(-5,1,6,minecraft:stone)
B(-5,1,7,minecraft:stone)
B(-5,1,8,minecraft:stone)
B(-5,1,9,minecraft:stone)
B(-5,2,-9,minecraft:stone)
B(-5,2,-8,minecraft:stone)
B(-5,2,-7,minecraft:stone)
B(-5,2,-6,minecraft:stone)
B(-5,2,-5,minecraft:stone)
B(-5,2,-4,minecraft:stone)
B(-5,2,-3,minecraft:stone)
B(-5,2,-2,minecraft:stone)
B(-5,2,-1,minecraft:stone)
B(-5,2,0,minecraft:stone)
B(-5,2,1,minecraft:stone)
B(-5,2,2,minecraft:stone)
B(-5,2,3,minecraft:stone)
B(-5,2,4,minecraft:stone)
B(-5,2,5,minecraft:stone)
B(-5,2,6,minecraft:stone)
B(-5,2,7,minecraft:stone)
B(-5,2,8,minecraft:stone)
B(-5,3,-9,minecraft:stone)
B(-5,3,-8,minecraft:stone)
B(-5,3,-7,minecraft:stone)
B(-5,3,-6,minecraft:stone)
B(-5,3,-5,minecraft:stone)
B(-5,3,-4,minecraft:stone)
B(-5,3,-3,minecraft:stone)
B(-5,3,-2,minecraft:stone)
B(-5,3,-1,minecraft:stone)
B(-5,3,0,minecraft:stone)
B(-5,3,1,minecraft:stone)
B(-5,3,2,minecraft:stone)
B(-5,3,3,minecraft:stone)
B(-5,3,4,minecraft:stone)
B(-5,3,5,minecraft:stone)
B(-5,3,6,minecraft:stone)
B(-5,3,7,minecraft:stone)
B(-5,4,-8,minecraft:stone)
B(-5,4,-7,minecraft:stone)
B(-5,4,-6,minecraft:stone)
B(-5,4,-5,minecraft:stone)
B(-5,4,-4,minecraft:stone)
B(-5,4,-3,minecraft:stone)
B(-5,4,-2,minecraft:stone)
B(-5,4,-1,minecraft:stone)
B(-5,4,0,minecraft:stone)
B(-5,4,1,minecraft:stone)
B(-5,4,2,minecraft:stone)
B(-5,4,3,minecraft:stone)
B(-5,4,4,minecraft:stone)
B(-5,4,5,minecraft:stone)
B(-5,4,6,minecraft:stone)
B(-5,4,7,minecraft:stone)
B(-5,5,-8,minecraft:stone)
B(-5,5,-7,minecraft:stone)
B(-5,5,-6,minecraft:stone)
B(-5,5,-5,minecraft:stone)
B(-5,5,-4,minecraft:stone)
B(-5,5,-3,minecraft:stone)
B(-5,5,-2,minecraft:stone)
B(-5,5,-1,minecraft:stone)
B(-5,5,0,minecraft:stone)
B(-5,5,1,minecraft:stone)
B(-5,5,2,minecraft:stone)
B(-5,5,3,minecraft:stone)
B(-5,5,4,minecraft:stone)
B(-5,5,5,minecraft:stone)
B(-5,5,6,minecraft:stone)
B(-5,6,-7,minecraft:stone)
B(-5,6,-6,minecraft:stone)
B(-5,6,-5,minecraft:stone)
B(-5,6,-4,minecraft:stone)
B(-5,6,-3,minecraft:stone)
B(-5,6,-2,minecraft:stone)
B(-5,6,-1,minecraft:stone)
B(-5,6,0,minecraft:stone)
B(-5,6,1,minecraft:stone)
B(-5,6,2,minecraft:stone)
B(-5,6,3,minecraft:stone)
B(-5,6,4,minecraft:stone)
B(-5,6,5,minecraft:stone)
B(-5,7,-6,minecraft:stone)
B(-5,7,-5,minecraft:stone)
B(-5,7,-4,minecraft:stone)
B(-5,7,-3,minecraft:stone)
B(-5,7,-2,minecraft:stone)
B(-5,7,-1,minecraft:stone)
B(-5,7,0,minecraft:stone)
B(-5,7,1,minecraft:stone)
B(-5,7,2,minecraft:stone)
B(-5,7,3,minecraft:stone)
B(-5,7,4,minecraft:stone)
B(-5,8,-6,minecraft:stone)
B(-5,8,-5,minecraft:stone)
B(-5,8,-4,minecraft:stone)
B(-5,8,-3,minecraft:stone)
B(-5,8,-2,minecraft:stone)
B(-5,8,-1,minecraft:stone)
B(-5,8,0,minecraft:stone)
B(-5,8,1,minecraft:stone)
B(-5,8,2,minecraft:stone)
B(-5,9,-1,minecraft:stone)
B(-5,9,0,minecraft:stone)
B(-5,9,1,minecraft:stone)
B(-4,-13,3,minecraft:stone)
B(-4,-13,4,minecraft:stone)
B(-4,-13,5,minecraft:stone)
B(-4,-13,6,minecraft:stone)
B(-4,-13,7,minecraft:stone)
B(-4,-13,8,minecraft:stone)
B(-4,-12,-3,minecraft:stone)
B(-4,-12,-2,minecraft:stone)
B(-4,-12,-1,minecraft:stone)
B(-4,-12,0,minecraft:stone)
B(-4,-12,1,minecraft:stone)
B(-4,-12,2,minecraft:stone)
B(-4,-12,3,minecraft:stone)
B(-4,-12,4,minecraft:stone)
B(-4,-12,5,minecraft:stone)
B(-4,-12,6,minecraft:stone)
B(-4,-12,7,minecraft:stone)
B(-4,-12,8,minecraft:stone)
B(-4,-12,9,minecraft:stone)
B(-4,-12,10,minecraft:stone)
B(-4,-12,11,minecraft:stone)
B(-4,-11,-7,minecraft:stone)
B(-4,-11,-6,minecraft:stone)
B(-4,-11,-5,minecraft:stone)
B(-4,-11,-4,minecraft:stone)
B(-4,-11,-3,minecraft:stone)
B(-4,-11,-2,minecraft:stone)
B(-4,-11,-1,minecraft:stone)
B(-4,-11,0,minecraft:stone)
B(-4,-11,1,minecraft:stone)
B(-4,-11,2,minecraft:stone)
B(-4,-11,3,minecraft:stone)
B(-4,-11,4,minecraft:stone)
B(-4,-11,5,minecraft:stone)
B(-4,-11,6,minecraft:stone)
B(-4,-11,7,minecraft:stone)
B(-4,-11,8,minecraft:stone)
B(-4,-11,9,minecraft:stone)
B(-4,-11,10,minecraft:stone)
B(-4,-11,11,minecraft:stone)
B(-4,-11,12,minecraft:stone)
B(-4,-10,-8,minecraft:stone)
B(-4,-10,-7,minecraft:stone)
B(-4,-10,-6,minecraft:stone)
B(-4,-10,-5,minecraft:stone)
B(-4,-10,-4,minecraft:stone)
B(-4,-10,-3,minecraft:stone)
B(-4,-10,-2,minecraft:stone)
B(-4,-10,-1,minecraft:stone)
B(-4,-10,0,minecraft:stone)
B(-4,-10,1,minecraft:stone)
B(-4,-10,2,minecraft:stone)
B(-4,-10,3,minecraft:stone)
B(-4,-10,4,minecraft:stone)
B(-4,-10,5,minecraft:stone)
B(-4,-10,6,minecraft:stone)
B(-4,-10,7,minecraft:stone)
B(-4,-10,8,minecraft:stone)
B(-4,-10,9,minecraft:stone)
B(-4,-10,10,minecraft:stone)
B(-4,-10,11,minecraft:stone)
B(-4,-10,12,minecraft:stone)
B(-4,-9,-8,minecraft:stone)
B(-4,-9,-7,minecraft:stone)
B(-4,-9,-6,minecraft:stone)
B(-4,-9,-5,minecraft:stone)
B(-4,-9,-4,minecraft:stone)
B(-4,-9,-3,minecraft:stone)
B(-4,-9,-2,minecraft:stone)
B(-4,-9,-1,minecraft:stone)
B(-4,-9,0,minecraft:stone)
B(-4,-9,1,minecraft:stone)
B(-4,-9,2,minecraft:stone)
B(-4,-9,3,minecraft:stone)
B(-4,-9,4,minecraft:stone)
B(-4,-9,5,minecraft:stone)
B(-4,-9,6,minecraft:stone)
B(-4,-9,7,minecraft:stone)
B(-4,-9,8,minecraft:stone)
B(-4,-9,9,minecraft:stone)
B(-4,-9,10,minecraft:stone)
B(-4,-9,11,minecraft:stone)
B(-4,-9,12,minecraft:stone)
B(-4,-8,-9,minecraft:stone)
B(-4,-8,-8,minecraft:stone)
B(-4,-8,-7,minecraft:stone)
B(-4,-8,-6,minecraft:stone)
B(-4,-8,-5,minecraft:stone)
B(-4,-8,-4,minecraft:stone)
B(-4,-8,-3,minecraft:stone)
B(-4,-8,-2,minecraft:stone)
B(-4,-8,-1,minecraft:stone)
B(-4,-8,0,minecraft:stone)
B(-4,-8,1,minecraft:stone)
B(-4,-8,2,minecraft:stone)
B(-4,-8,3,minecraft:stone)
B(-4,-8,4,minecraft:stone)
B(-4,-8,5,minecraft:stone)
B(-4,-8,6,minecraft:stone)
B(-4,-8,7,minecraft:stone)
B(-4,-8,8,minecraft:stone)
B(-4,-8,9,minecraft:stone)
B(-4,-8,10,minecraft:stone)
B(-4,-8,11,minecraft:stone)
B(-4,-8,12,minecraft:stone)
B(-4,-7,-9,minecraft:stone)
B(-4,-7,-8,minecraft:stone)
B(-4,-7,-7,minecraft:stone)
B(-4,-7,-6,minecraft:stone)
B(-4,-7,-5,minecraft:stone)
B(-4,-7,-4,minecraft:stone)
B(-4,-7,-3,minecraft:stone)
B(-4,-7,-2,minecraft:stone)
B(-4,-7,-1,minecraft:stone)
B(-4,-7,0,minecraft:stone)
B(-4,-7,1,minecraft:stone)
B(-4,-7,2,minecraft:stone)
B(-4,-7,3,minecraft:stone)
B(-4,-7,4,minecraft:stone)
B(-4,-7,5,minecraft:stone)
B(-4,-7,6,minecraft:stone)
B(-4,-7,7,minecraft:stone)
B(-4,-7,8,minecraft:stone)
B(-4,-7,9,minecraft:stone)
B(-4,-7,10,minecraft:stone)
B(-4,-7,11,minecraft:stone)
B(-4,-7,12,minecraft:stone)
B(-4,-6,-10,minecraft:stone)
B(-4,-6,-9,minecraft:stone)
B(-4,-6,-8,minecraft:stone)
B(-4,-6,-7,minecraft:stone)
B(-4,-6,-6,minecraft:stone)
B(-4,-6,-5,minecraft:stone)
B(-4,-6,-4,minecraft:stone)
B(-4,-6,-3,minecraft:stone)
B(-4,-6,-2,minecraft:stone)
B(-4,-6,-1,minecraft:stone)
B(-4,-6,0,minecraft:stone)
B(-4,-6,1,minecraft:stone)
B(-4,-6,2,minecraft:stone)
B(-4,-6,3,minecraft:stone)
B(-4,-6,4,minecraft:stone)
B(-4,-6,5,minecraft:stone)
B(-4,-6,6,minecraft:stone)
B(-4,-6,7,minecraft:stone)
B(-4,-6,8,minecraft:stone)
B(-4,-6,9,minecraft:stone)
B(-4,-6,10,minecraft:stone)
B(-4,-6,11,minecraft:stone)
B(-4,-6,12,minecraft:stone)
B(-4,-5,-10,minecraft:stone)
B(-4,-5,-9,minecraft:stone)
B(-4,-5,-8,minecraft:stone)
B(-4,-5,-7,minecraft:stone)
B(-4,-5,-6,minecraft:stone)
B(-4,-5,-5,minecraft:stone)
B(-4,-5,-4,minecraft:stone)
B(-4,-5,-3,minecraft:stone)
B(-4,-5,-2,minecraft:stone)
B(-4,-5,-1,minecraft:stone)
B(-4,-5,0,minecraft:stone)
B(-4,-5,1,minecraft:stone)
B(-4,-5,2,minecraft:stone)
B(-4,-5,3,minecraft:stone)
B(-4,-5,4,minecraft:stone)
B(-4,-5,5,minecraft:stone)
B(-4,-5,6,minecraft:stone)
B(-4,-5,7,minecraft:stone)
B(-4,-5,8,minecraft:stone)
B(-4,-5,9,minecraft:stone)
B(-4,-5,10,minecraft:stone)
B(-4,-5,11,minecraft:stone)
B(-4,-5,12,minecraft:stone)
B(-4,-4,-10,minecraft:stone)
B(-4,-4,-9,minecraft:stone)
B(-4,-4,-8,minecraft:stone)
B(-4,-4,-7,minecraft:stone)
B(-4,-4,-6,minecraft:stone)
B(-4,-4,-5,minecraft:stone)
B(-4,-4,-4,minecraft:stone)
B(-4,-4,-3,minecraft:stone)
B(-4,-4,-2,minecraft:stone)
B(-4,-4,-1,minecraft:stone)
B(-4,-4,0,minecraft:stone)
B(-4,-4,1,minecraft:stone)
B(-4,-4,2,minecraft:stone)
B(-4,-4,3,minecraft:stone)
B(-4,-4,4,minecraft:stone)
B(-4,-4,5,minecraft:stone)
B(-4,-4,6,minecraft:stone)
B(-4,-4,7,minecraft:stone)
B(-4,-4,8,minecraft:stone)
B(-4,-4,9,minecraft:stone)
B(-4,-4,10,minecraft:stone)
B(-4,-4,11,minecraft:stone)
B(-4,-4,12,minecraft:stone)
B(-4,-3,-10,minecraft:stone)
B(-4,-3,-9,minecraft:stone)
B(-4,-3,-8,minecraft:stone)
B(-4,-3,-7,minecraft:stone)
B(-4,-3,-6,minecraft:stone)
B(-4,-3,-5,minecraft:stone)
B(-4,-3,-4,minecraft:stone)
B(-4,-3,-3,minecraft:stone)
B(-4,-3,-2,minecraft:stone)
B(-4,-3,-1,minecraft:stone)
B(-4,-3,0,minecraft:stone)
B(-4,-3,1,minecraft:stone)
B(-4,-3,2,minecraft:stone)
B(-4,-3,3,minecraft:stone)
B(-4,-3,4,minecraft:stone)
B(-4,-3,5,minecraft:stone)
B(-4,-3,6,minecraft:stone)
B(-4,-3,7,minecraft:stone)
B(-4,-3,8,minecraft:stone)
B(-4,-3,9,minecraft:stone)
B(-4,-3,10,minecraft:stone)
B(-4,-3,11,minecraft:stone)
B(-4,-2,-10,minecraft:stone)
B(-4,-2,-9,minecraft:stone)
B(-4,-2,-8,minecraft:stone)
B(-4,-2,-7,minecraft:stone)
B(-4,-2,-6,minecraft:stone)
B(-4,-2,-5,minecraft:stone)
B(-4,-2,-4,minecraft:stone)
B(-4,-2,-3,minecraft:stone)
B(-4,-2,-2,minecraft:stone)
B(-4,-2,-1,minecraft:stone)
B(-4,-2,0,minecraft:stone)
B(-4,-2,1,minecraft:stone)
B(-4,-2,2,minecraft:stone)
B(-4,-2,3,minecraft:stone)
B(-4,-2,4,minecraft:stone)
B(-4,-2,5,minecraft:stone)
B(-4,-2,6,minecraft:stone)
B(-4,-2,7,minecraft:stone)
B(-4,-2,8,minecraft:stone)
B(-4,-2,9,minecraft:stone)
B(-4,-2,10,minecraft:stone)
B(-4,-2,11,minecraft:stone)
B(-4,-1,-10,minecraft:stone)
B(-4,-1,-9,minecraft:stone)
B(-4,-1,-8,minecraft:stone)
B(-4,-1,-7,minecraft:stone)
B(-4,-1,-6,minecraft:stone)
B(-4,-1,-5,minecraft:stone)
B(-4,-1,-4,minecraft:stone)
B(-4,-1,-3,minecraft:stone)
B(-4,-1,-2,minecraft:stone)
B(-4,-1,-1,minecraft:stone)
B(-4,-1,0,minecraft:stone)
B(-4,-1,1,minecraft:stone)
B(-4,-1,2,minecraft:stone)
B(-4,-1,3,minecraft:stone)
B(-4,-1,4,minecraft:stone)
B(-4,-1,5,minecraft:stone)
B(-4,-1,6,minecraft:stone)
B(-4,-1,7,minecraft:stone)
B(-4,-1,8,minecraft:stone)
B(-4,-1,9,minecraft:stone)
B(-4,-1,10,minecraft:stone)
B(-4,-1,11,minecraft:stone)
B(-4,0,-10,minecraft:stone)
B(-4,0,-9,minecraft:stone)
B(-4,0,-8,minecraft:stone)
B(-4,0,-7,minecraft:stone)
B(-4,0,-6,minecraft:stone)
B(-4,0,-5,minecraft:stone)
B(-4,0,-4,minecraft:stone)
B(-4,0,-3,minecraft:stone)
B(-4,0,-2,minecraft:stone)
B(-4,0,-1,minecraft:stone)
B(-4,0,0,minecraft:stone)
B(-4,0,1,minecraft:stone)
B(-4,0,2,minecraft:stone)
B(-4,0,3,minecraft:stone)
B(-4,0,4,minecraft:stone)
B(-4,0,5,minecraft:stone)
B(-4,0,6,minecraft:stone)
B(-4,0,7,minecraft:stone)
B(-4,0,8,minecraft:stone)
B(-4,0,9,minecraft:stone)
B(-4,0,10,minecraft:stone)
B(-4,0,11,minecraft:stone)
B(-4,1,-9,minecraft:stone)
B(-4,1,-8,minecraft:stone)
B(-4,1,-7,minecraft:stone)
B(-4,1,-6,minecraft:stone)
B(-4,1,-5,minecraft:stone)
B(-4,1,-4,minecraft:stone)
B(-4,1,-3,minecraft:stone)
B(-4,1,-2,minecraft:stone)
B(-4,1,-1,minecraft:stone)
B(-4,1,0,minecraft:stone)
B(-4,1,1,minecraft:stone)
B(-4,1,2,minecraft:stone)
B(-4,1,3,minecraft:stone)
B(-4,1,4,minecraft:stone)
B(-4,1,5,minecraft:stone)
B(-4,1,6,minecraft:stone)
B(-4,1,7,minecraft:stone)
B(-4,1,8,minecraft:stone)
B(-4,1,9,minecraft:stone)
B(-4,1,10,minecraft:stone)
B(-4,2,-9,minecraft:stone)
B(-4,2,-8,minecraft:stone)
B(-4,2,-7,minecraft:stone)
B(-4,2,-6,minecraft:stone)
B(-4,2,-5,minecraft:stone)
B(-4,2,-4,minecraft:stone)
B(-4,2,-3,minecraft:stone)
B(-4,2,-2,minecraft:stone)
B(-4,2,-1,minecraft:stone)
B(-4,2,0,minecraft:stone)
B(-4,2,1,minecraft:stone)
B(-4,2,2,minecraft:stone)
B(-4,2,3,minecraft:stone)
B(-4,2,4,minecraft:stone)
B(-4,2,5,minecraft:stone)
B(-4,2,6,minecraft:stone)
B(-4,2,7,minecraft:stone)
B(-4,2,8,minecraft:stone)
B(-4,2,9,minecraft:stone)
B(-4,3,-8,minecraft:stone)
B(-4,3,-7,minecraft:stone)
B(-4,3,-6,minecraft:stone)
B(-4,3,-5,minecraft:stone)
B(-4,3,-4,minecraft:stone)
B(-4,3,-3,minecraft:stone)
B(-4,3,-2,minecraft:stone)
B(-4,3,-1,minecraft:stone)
B(-4,3,0,minecraft:stone)
B(-4,3,1,minecraft:stone)
B(-4,3,2,minecraft:stone)
B(-4,3,3,minecraft:stone)
B(-4,3,4,minecraft:stone)
B(-4,3,5,minecraft:stone)
B(-4,3,6,minecraft:stone)
B(-4,3,7,minecraft:stone)
B(-4,3,8,minecraft:stone)
B(-4,4,-8,minecraft:stone)
B(-4,4,-7,minecraft:stone)
B(-4,4,-6,minecraft:stone)
B(-4,4,-5,minecraft:stone)
B(-4,4,-4,minecraft:stone)
B(-4,4,-3,minecraft:stone)
B(-4,4,-2,minecraft:stone)
B(-4,4,-1,minecraft:stone)
B(-4,4,0,minecraft:stone)
B(-4,4,1,minecraft:stone)
B(-4,4,2,minecraft:stone)
B(-4,4,3,minecraft:stone)
B(-4,4,4,minecraft:stone)
B(-4,4,5,minecraft:stone)
B(-4,4,6,minecraft:stone)
B(-4,4,7,minecraft:stone)
B(-4,5,-8,minecraft:stone)
B(-4,5,-7,minecraft:stone)
B(-4,5,-6,minecraft:stone)
B(-4,5,-5,minecraft:stone)
B(-4,5,-4,minecraft:stone)
B(-4,5,-3,minecraft:stone)
B(-4,5,-2,minecraft:stone)
B(-4,5,-1,minecraft:stone)
B(-4,5,0,minecraft:stone)
B(-4,5,1,minecraft:stone)
B(-4,5,2,minecraft:stone)
B(-4,5,3,minecraft:stone)
B(-4,5,4,minecraft:stone)
B(-4,5,5,minecraft:stone)
B(-4,5,6,minecraft:stone)
B(-4,5,7,minecraft:stone)
B(-4,6,-7,minecraft:stone)
B(-4,6,-6,minecraft:stone)
B(-4,6,-5,minecraft:stone)
B(-4,6,-4,minecraft:stone)
B(-4,6,-3,minecraft:stone)
B(-4,6,-2,minecraft:stone)
B(-4,6,-1,minecraft:stone)
B(-4,6,0,minecraft:stone)
B(-4,6,1,minecraft:stone)
B(-4,6,2,minecraft:stone)
B(-4,6,3,minecraft:stone)
B(-4,6,4,minecraft:stone)
B(-4,6,5,minecraft:stone)
B(-4,6,6,minecraft:stone)
B(-4,7,-6,minecraft:stone)
B(-4,7,-5,minecraft:stone)
B(-4,7,-4,minecraft:stone)
B(-4,7,-3,minecraft:stone)
B(-4,7,-2,minecraft:stone)
B(-4,7,-1,minecraft:stone)
B(-4,7,0,minecraft:stone)
B(-4,7,1,minecraft:stone)
B(-4,7,2,minecraft:stone)
B(-4,7,3,minecraft:stone)
B(-4,7,4,minecraft:stone)
B(-4,8,-5,minecraft:stone)
B(-4,8,-4,minecraft:stone)
B(-4,8,-3,minecraft:stone)
B(-4,8,-2,minecraft:stone)
B(-4,8,-1,minecraft:stone)
B(-4,8,0,minecraft:stone)
B(-4,8,1,minecraft:stone)
B(-4,8,2,minecraft:stone)
B(-4,8,3,minecraft:stone)
B(-4,9,0,minecraft:stone)
B(-4,9,1,minecraft:stone)
B(-4,9,2,minecraft:stone)
B(-3,-13,3,minecraft:stone)
B(-3,-13,4,minecraft:stone)
B(-3,-13,5,minecraft:stone)
B(-3,-13,6,minecraft:stone)
B(-3,-13,7,minecraft:stone)
B(-3,-13,8,minecraft:stone)
B(-3,-13,9,minecraft:stone)
B(-3,-12,-3,minecraft:stone)
B(-3,-12,-2,minecraft:stone)
B(-3,-12,-1,minecraft:stone)
B(-3,-12,0,minecraft:stone)
B(-3,-12,1,minecraft:stone)
B(-3,-12,2,minecraft:stone)
B(-3,-12,3,minecraft:stone)
B(-3,-12,4,minecraft:stone)
B(-3,-12,5,minecraft:stone)
B(-3,-12,6,minecraft:stone)
B(-3,-12,7,minecraft:stone)
B(-3,-12,8,minecraft:stone)
B(-3,-12,9,minecraft:stone)
B(-3,-12,10,minecraft:stone)
B(-3,-12,11,minecraft:stone)
B(-3,-11,-7,minecraft:stone)
B(-3,-11,-6,minecraft:stone)
B(-3,-11,-5,minecraft:stone)
B(-3,-11,-4,minecraft:stone)
B(-3,-11,-3,minecraft:stone)
B(-3,-11,-2,minecraft:stone)
B(-3,-11,-1,minecraft:stone)
B(-3,-11,0,minecraft:stone)
B(-3,-11,1,minecraft:stone)
B(-3,-11,2,minecraft:stone)
B(-3,-11,3,minecraft:stone)
B(-3,-11,4,minecraft:stone)
B(-3,-11,5,minecraft:stone)
B(-3,-11,6,minecraft:stone)
B(-3,-11,7,minecraft:stone)
B(-3,-11,8,minecraft:stone)
B(-3,-11,9,minecraft:stone)
B(-3,-11,10,minecraft:stone)
B(-3,-11,11,minecraft:stone)
B(-3,-11,12,minecraft:stone)
B(-3,-10,-8,minecraft:stone)
B(-3,-10,-7,minecraft:stone)
B(-3,-10,-6,minecraft:stone)
B(-3,-10,-5,minecraft:stone)
B(-3,-10,-4,minecraft:stone)
B(-3,-10,-3,minecraft:stone)
B(-3,-10,-2,minecraft:stone)
B(-3,-10,-1,minecraft:stone)
B(-3,-10,0,minecraft:stone)
B(-3,-10,1,minecraft:stone)
B(-3,-10,2,minecraft:stone)
B(-3,-10,3,minecraft:stone)
B(-3,-10,4,minecraft:stone)
B(-3,-10,5,minecraft:stone)
B(-3,-10,6,minecraft:stone)
B(-3,-10,7,minecraft:stone)
B(-3,-10,8,minecraft:stone)
B(-3,-10,9,minecraft:stone)
B(-3,-10,10,minecraft:stone)
B(-3,-10,11,minecraft:stone)
B(-3,-10,12,minecraft:stone)
B(-3,-9,-9,minecraft:stone)
B(-3,-9,-8,minecraft:stone)
B(-3,-9,-7,minecraft:stone)
B(-3,-9,-6,minecraft:stone)
B(-3,-9,-5,minecraft:stone)
B(-3,-9,-4,minecraft:stone)
B(-3,-9,-3,minecraft:stone)
B(-3,-9,-2,minecraft:stone)
B(-3,-9,-1,minecraft:stone)
B(-3,-9,0,minecraft:stone)
B(-3,-9,1,minecraft:stone)
B(-3,-9,2,minecraft:stone)
B(-3,-9,3,minecraft:stone)
B(-3,-9,4,minecraft:stone)
B(-3,-9,5,minecraft:stone)
B(-3,-9,6,minecraft:stone)
B(-3,-9,7,minecraft:stone)
B(-3,-9,8,minecraft:stone)
B(-3,-9,9,minecraft:stone)
B(-3,-9,10,minecraft:stone)
B(-3,-9,11,minecraft:stone)
B(-3,-9,12,minecraft:stone)
B(-3,-8,-9,minecraft:stone)
B(-3,-8,-8,minecraft:stone)
B(-3,-8,-7,minecraft:stone)
B(-3,-8,-6,minecraft:stone)
B(-3,-8,-5,minecraft:stone)
B(-3,-8,-4,minecraft:stone)
B(-3,-8,-3,minecraft:stone)
B(-3,-8,-2,minecraft:stone)
B(-3,-8,-1,minecraft:stone)
B(-3,-8,0,minecraft:stone)
B(-3,-8,1,minecraft:stone)
B(-3,-8,2,minecraft:stone)
B(-3,-8,3,minecraft:stone)
B(-3,-8,4,minecraft:stone)
B(-3,-8,5,minecraft:stone)
B(-3,-8,6,minecraft:stone)
B(-3,-8,7,minecraft:stone)
B(-3,-8,8,minecraft:stone)
B(-3,-8,9,minecraft:stone)
B(-3,-8,10,minecraft:stone)
B(-3,-8,11,minecraft:stone)
B(-3,-7,-10,minecraft:stone)
B(-3,-7,-9,minecraft:stone)
B(-3,-7,-8,minecraft:stone)
B(-3,-7,-7,minecraft:stone)
B(-3,-7,-6,minecraft:stone)
B(-3,-7,-5,minecraft:stone)
B(-3,-7,-4,minecraft:stone)
B(-3,-7,-3,minecraft:stone)
B(-3,-7,-2,minecraft:stone)
B(-3,-7,-1,minecraft:stone)
B(-3,-7,0,minecraft:stone)
B(-3,-7,1,minecraft:stone)
B(-3,-7,2,minecraft:stone)
B(-3,-7,3,minecraft:stone)
B(-3,-7,4,minecraft:stone)
B(-3,-7,5,minecraft:stone)
B(-3,-7,6,minecraft:stone)
B(-3,-7,7,minecraft:stone)
B(-3,-7,8,minecraft:stone)
B(-3,-7,9,minecraft:stone)
B(-3,-7,10,minecraft:stone)
B(-3,-7,11,minecraft:stone)
B(-3,-6,-10,minecraft:stone)
B(-3,-6,-9,minecraft:stone)
B(-3,-6,-8,minecraft:stone)
B(-3,-6,-7,minecraft:stone)
B(-3,-6,-6,minecraft:stone)
B(-3,-6,-5,minecraft:stone)
B(-3,-6,-4,minecraft:stone)
B(-3,-6,-3,minecraft:stone)
B(-3,-6,-2,minecraft:stone)
B(-3,-6,-1,minecraft:stone)
B(-3,-6,0,minecraft:stone)
B(-3,-6,1,minecraft:stone)
B(-3,-6,2,minecraft:stone)
B(-3,-6,3,minecraft:stone)
B(-3,-6,4,minecraft:stone)
B(-3,-6,5,minecraft:stone)
B(-3,-6,6,minecraft:stone)
B(-3,-6,7,minecraft:stone)
B(-3,-6,8,minecraft:stone)
B(-3,-6,9,minecraft:stone)
B(-3,-6,10,minecraft:stone)
B(-3,-6,11,minecraft:stone)
B(-3,-5,-10,minecraft:stone)
B(-3,-5,-9,minecraft:stone)
B(-3,-5,-8,minecraft:stone)
B(-3,-5,-7,minecraft:stone)
B(-3,-5,-6,minecraft:stone)
B(-3,-5,-5,minecraft:stone)
B(-3,-5,-4,minecraft:stone)
B(-3,-5,-3,minecraft:stone)
B(-3,-5,-2,minecraft:stone)
B(-3,-5,-1,minecraft:stone)
B(-3,-5,0,minecraft:stone)
B(-3,-5,1,minecraft:stone)
B(-3,-5,2,minecraft:stone)
B(-3,-5,3,minecraft:stone)
B(-3,-5,4,minecraft:stone)
B(-3,-5,5,minecraft:stone)
B(-3,-5,6,minecraft:stone)
B(-3,-5,7,minecraft:stone)
B(-3,-5,8,minecraft:stone)
B(-3,-5,9,minecraft:stone)
B(-3,-5,10,minecraft:stone)
B(-3,-5,11,minecraft:stone)
B(-3,-4,-10,minecraft:stone)
B(-3,-4,-9,minecraft:stone)
B(-3,-4,-8,minecraft:stone)
B(-3,-4,-7,minecraft:stone)
B(-3,-4,-6,minecraft:stone)
B(-3,-4,-5,minecraft:stone)
B(-3,-4,-4,minecraft:stone)
B(-3,-4,-3,minecraft:stone)
B(-3,-4,-2,minecraft:stone)
B(-3,-4,-1,minecraft:stone)
B(-3,-4,0,minecraft:stone)
B(-3,-4,1,minecraft:stone)
B(-3,-4,2,minecraft:stone)
B(-3,-4,3,minecraft:stone)
B(-3,-4,4,minecraft:stone)
B(-3,-4,5,minecraft:stone)
B(-3,-4,6,minecraft:stone)
B(-3,-4,7,minecraft:stone)
B(-3,-4,8,minecraft:stone)
B(-3,-4,9,minecraft:stone)
B(-3,-4,10,minecraft:stone)
B(-3,-4,11,minecraft:stone)
B(-3,-3,-10,minecraft:stone)
B(-3,-3,-9,minecraft:stone)
B(-3,-3,-8,minecraft:stone)
B(-3,-3,-7,minecraft:stone)
B(-3,-3,-6,minecraft:stone)
B(-3,-3,-5,minecraft:stone)
B(-3,-3,-4,minecraft:stone)
B(-3,-3,-3,minecraft:stone)
B(-3,-3,-2,minecraft:stone)
B(-3,-3,-1,minecraft:stone)
B(-3,-3,0,minecraft:stone)
B(-3,-3,1,minecraft:stone)
B(-3,-3,2,minecraft:stone)
B(-3,-3,3,minecraft:stone)
B(-3,-3,4,minecraft:stone)
B(-3,-3,5,minecraft:stone)
B(-3,-3,6,minecraft:stone)
B(-3,-3,7,minecraft:stone)
B(-3,-3,8,minecraft:stone)
B(-3,-3,9,minecraft:stone)
B(-3,-3,10,minecraft:stone)
B(-3,-3,11,minecraft:stone)
B(-3,-2,-10,minecraft:stone)
B(-3,-2,-9,minecraft:stone)
B(-3,-2,-8,minecraft:stone)
B(-3,-2,-7,minecraft:stone)
B(-3,-2,-6,minecraft:stone)
B(-3,-2,-5,minecraft:stone)
B(-3,-2,-4,minecraft:stone)
B(-3,-2,-3,minecraft:stone)
B(-3,-2,-2,minecraft:stone)
B(-3,-2,-1,minecraft:stone)
B(-3,-2,0,minecraft:stone)
B(-3,-2,1,minecraft:stone)
B(-3,-2,2,minecraft:stone)
B(-3,-2,3,minecraft:stone)
B(-3,-2,4,minecraft:stone)
B(-3,-2,5,minecraft:stone)
B(-3,-2,6,minecraft:stone)
B(-3,-2,7,minecraft:stone)
B(-3,-2,8,minecraft:stone)
B(-3,-2,9,minecraft:stone)
B(-3,-2,10,minecraft:stone)
B(-3,-2,11,minecraft:stone)
B(-3,-1,-10,minecraft:stone)
B(-3,-1,-9,minecraft:stone)
B(-3,-1,-8,minecraft:stone)
B(-3,-1,-7,minecraft:stone)
B(-3,-1,-6,minecraft:stone)
B(-3,-1,-5,minecraft:stone)
B(-3,-1,-4,minecraft:stone)
B(-3,-1,-3,minecraft:stone)
B(-3,-1,-2,minecraft:stone)
B(-3,-1,-1,minecraft:stone)
B(-3,-1,0,minecraft:stone)
B(-3,-1,1,minecraft:stone)
B(-3,-1,2,minecraft:stone)
B(-3,-1,3,minecraft:stone)
B(-3,-1,4,minecraft:stone)
B(-3,-1,5,minecraft:stone)
B(-3,-1,6,minecraft:stone)
B(-3,-1,7,minecraft:stone)
B(-3,-1,8,minecraft:stone)
B(-3,-1,9,minecraft:stone)
B(-3,-1,10,minecraft:stone)
B(-3,-1,11,minecraft:stone)
B(-3,0,-10,minecraft:stone)
B(-3,0,-9,minecraft:stone)
B(-3,0,-8,minecraft:stone)
B(-3,0,-7,minecraft:stone)
B(-3,0,-6,minecraft:stone)
B(-3,0,-5,minecraft:stone)
B(-3,0,-4,minecraft:stone)
B(-3,0,-3,minecraft:stone)
B(-3,0,-2,minecraft:stone)
B(-3,0,-1,minecraft:stone)
B(-3,0,0,minecraft:stone)
B(-3,0,1,minecraft:stone)
B(-3,0,2,minecraft:stone)
B(-3,0,3,minecraft:stone)
B(-3,0,4,minecraft:stone)
B(-3,0,5,minecraft:stone)
B(-3,0,6,minecraft:stone)
B(-3,0,7,minecraft:stone)
B(-3,0,8,minecraft:stone)
B(-3,0,9,minecraft:stone)
B(-3,0,10,minecraft:stone)
B(-3,0,11,minecraft:stone)
B(-3,1,-9,minecraft:stone)
B(-3,1,-8,minecraft:stone)
B(-3,1,-7,minecraft:stone)
B(-3,1,-6,minecraft:stone)
B(-3,1,-5,minecraft:stone)
B(-3,1,-4,minecraft:stone)
B(-3,1,-3,minecraft:stone)
B(-3,1,-2,minecraft:stone)
B(-3,1,-1,minecraft:stone)
B(-3,1,0,minecraft:stone)
B(-3,1,1,minecraft:stone)
B(-3,1,2,minecraft:stone)
B(-3,1,3,minecraft:stone)
B(-3,1,4,minecraft:stone)
B(-3,1,5,minecraft:stone)
B(-3,1,6,minecraft:stone)
B(-3,1,7,minecraft:stone)
B(-3,1,8,minecraft:stone)
B(-3,1,9,minecraft:stone)
B(-3,1,10,minecraft:stone)
B(-3,2,-9,minecraft:stone)
B(-3,2,-8,minecraft:stone)
B(-3,2,-7,minecraft:stone)
B(-3,2,-6,minecraft:stone)
B(-3,2,-5,minecraft:stone)
B(-3,2,-4,minecraft:stone)
B(-3,2,-3,minecraft:stone)
B(-3,2,-2,minecraft:stone)
B(-3,2,-1,minecraft:stone)
B(-3,2,0,minecraft:stone)
B(-3,2,1,minecraft:stone)
B(-3,2,2,minecraft:stone)
B(-3,2,3,minecraft:stone)
B(-3,2,4,minecraft:stone)
B(-3,2,5,minecraft:stone)
B(-3,2,6,minecraft:stone)
B(-3,2,7,minecraft:stone)
B(-3,2,8,minecraft:stone)
B(-3,2,9,minecraft:stone)
B(-3,2,10,minecraft:stone)
B(-3,3,-8,minecraft:stone)
B(-3,3,-7,minecraft:stone)
B(-3,3,-6,minecraft:stone)
B(-3,3,-5,minecraft:stone)
B(-3,3,-4,minecraft:stone)
B(-3,3,-3,minecraft:stone)
B(-3,3,-2,minecraft:stone)
B(-3,3,-1,minecraft:stone)
B(-3,3,0,minecraft:stone)
B(-3,3,1,minecraft:stone)
B(-3,3,2,minecraft:stone)
B(-3,3,3,minecraft:stone)
B(-3,3,4,minecraft:stone)
B(-3,3,5,minecraft:stone)
B(-3,3,6,minecraft:stone)
B(-3,3,7,minecraft:stone)
B(-3,3,8,minecraft:stone)
B(-3,3,9,minecraft:stone)
B(-3,4,-8,minecraft:stone)
B(-3,4,-7,minecraft:stone)
B(-3,4,-6,minecraft:stone)
B(-3,4,-5,minecraft:stone)
B(-3,4,-4,minecraft:stone)
B(-3,4,-3,minecraft:stone)
B(-3,4,-2,minecraft:stone)
B(-3,4,-1,minecraft:stone)
B(-3,4,0,minecraft:stone)
B(-3,4,1,minecraft:stone)
B(-3,4,2,minecraft:stone)
B(-3,4,3,minecraft:stone)
B(-3,4,4,minecraft:stone)
B(-3,4,5,minecraft:stone)
B(-3,4,6,minecraft:stone)
B(-3,4,7,minecraft:stone)
B(-3,4,8,minecraft:stone)
B(-3,5,-7,minecraft:stone)
B(-3,5,-6,minecraft:stone)
B(-3,5,-5,minecraft:stone)
B(-3,5,-4,minecraft:stone)
B(-3,5,-3,minecraft:stone)
B(-3,5,-2,minecraft:stone)
B(-3,5,-1,minecraft:stone)
B(-3,5,0,minecraft:stone)
B(-3,5,1,minecraft:stone)
B(-3,5,2,minecraft:stone)
B(-3,5,3,minecraft:stone)
B(-3,5,4,minecraft:stone)
B(-3,5,5,minecraft:stone)
B(-3,5,6,minecraft:stone)
B(-3,5,7,minecraft:stone)
B(-3,6,-7,minecraft:stone)
B(-3,6,-6,minecraft:stone)
B(-3,6,-5,minecraft:stone)
B(-3,6,-4,minecraft:stone)
B(-3,6,-3,minecraft:stone)
B(-3,6,-2,minecraft:stone)
B(-3,6,-1,minecraft:stone)
B(-3,6,0,minecraft:stone)
B(-3,6,1,minecraft:stone)
B(-3,6,2,minecraft:stone)
B(-3,6,3,minecraft:stone)
B(-3,6,4,minecraft:stone)
B(-3,6,5,minecraft:stone)
B(-3,6,6,minecraft:stone)
B(-3,6,7,minecraft:stone)
B(-3,7,-6,minecraft:stone)
B(-3,7,-5,minecraft:stone)
B(-3,7,-4,minecraft:stone)
B(-3,7,-3,minecraft:stone)
B(-3,7,-2,minecraft:stone)
B(-3,7,-1,minecraft:stone)
B(-3,7,0,minecraft:stone)
B(-3,7,1,minecraft:stone)
B(-3,7,2,minecraft:stone)
B(-3,7,3,minecraft:stone)
B(-3,7,4,minecraft:stone)
B(-3,7,5,minecraft:stone)
B(-3,8,-3,minecraft:stone)
B(-3,8,-2,minecraft:stone)
