
#######################################################################
# +-----------------------------------------------------------------+ #
# |                            BO3 object                           | #
# +-----------------------------------------------------------------+ #
#######################################################################

Author: MC_Pitman

Description: No description given

Version: 3

SettingsMode: WriteWithoutComments


#######################################################################
# +-----------------------------------------------------------------+ #
# |                          Main settings                          | #
# +-----------------------------------------------------------------+ #
#######################################################################

Tree: false

Frequency: 1

Rarity: 1.0

MaxSpawn: 0

RotateRandomly: true

SpawnHeight: highestSolidBlock

SpawnHeightOffset: 0

SpawnHeightVariance: 0

##############################
# Height Limits for the BO3. #
##############################

MinHeight: 52

MaxHeight: 100

######################
# Extrusion settings #
######################

ExtrudeMode: None

ExtrudeThroughBlocks: otg:air

MaxBranchDepth: 10


#######################################################################
# +-----------------------------------------------------------------+ #
# |                      Source block settings                      | #
# +-----------------------------------------------------------------+ #
#######################################################################

SourceBlocks: otg:dirt,minecraft:sand,otg:stained_clay,otg:sandstone,otg:air,otg:stone,otg:long_grass,minecraft:granite,minecraft:diorite,minecraft:andesite,minecraft:coarse_dirt,minecraft:grass_block,minecraft:podzol,minecraft:water,minecraft:terracotta,minecraft:clay,minecraft:red_sand,minecraft:gravel,minecraft:grass,minecraft:fern,minecraft:dead_bush,minecraft:dandelion,minecraft:poppy,minecraft:brown_mushroom,minecraft:red_mushroom

MaxPercentageOutsideSourceBlock: 100

OutsideSourceBlock: placeAnyway

DoReplaceBlocks: true

IsOTGPlus: false


#######################################################################
# +-----------------------------------------------------------------+ #
# |                              Blocks                             | #
# +-----------------------------------------------------------------+ #
#######################################################################

B(-10,-6,-3,minecraft:stone)
B(-10,-5,-3,minecraft:stone)
B(-9,-8,-2,minecraft:stone)
B(-9,-8,-1,minecraft:stone)
B(-9,-8,0,minecraft:stone)
B(-9,-8,1,minecraft:stone)
B(-9,-7,-6,minecraft:stone)
B(-9,-7,-5,minecraft:stone)
B(-9,-7,-4,minecraft:stone)
B(-9,-7,-3,minecraft:stone)
B(-9,-7,-2,minecraft:stone)
B(-9,-7,-1,minecraft:stone)
B(-9,-7,0,minecraft:stone)
B(-9,-7,1,minecraft:stone)
B(-9,-6,-5,minecraft:stone)
B(-9,-6,-4,minecraft:stone)
B(-9,-6,-3,minecraft:stone)
B(-9,-6,-2,minecraft:stone)
B(-9,-6,-1,minecraft:stone)
B(-9,-6,0,minecraft:stone)
B(-9,-6,1,minecraft:stone)
B(-9,-5,-5,minecraft:stone)
B(-9,-5,-4,minecraft:stone)
B(-9,-5,-3,minecraft:stone)
B(-9,-5,-2,minecraft:stone)
B(-9,-5,-1,minecraft:stone)
B(-9,-5,0,minecraft:stone)
B(-9,-5,1,minecraft:stone)
B(-9,-4,-5,minecraft:stone)
B(-9,-4,-4,minecraft:stone)
B(-9,-4,-3,minecraft:stone)
B(-9,-4,-2,minecraft:stone)
B(-9,-4,-1,minecraft:stone)
B(-9,-4,0,minecraft:stone)
B(-9,-4,1,minecraft:stone)
B(-9,-3,-4,minecraft:stone)
B(-9,-3,-3,minecraft:stone)
B(-9,-3,-2,minecraft:stone)
B(-9,-3,-1,minecraft:stone)
B(-9,-2,-4,minecraft:stone)
B(-9,-2,-3,minecraft:stone)
B(-9,-2,-2,minecraft:stone)
B(-9,-2,-1,minecraft:stone)
B(-9,-1,-2,minecraft:stone)
B(-9,-1,-1,minecraft:stone)
B(-9,0,-1,minecraft:stone)
B(-9,0,0,minecraft:stone)
B(-9,1,0,minecraft:stone)
B(-9,2,1,minecraft:stone)
B(-8,-9,-1,minecraft:stone)
B(-8,-9,0,minecraft:stone)
B(-8,-9,1,minecraft:stone)
B(-8,-8,-8,minecraft:stone)
B(-8,-8,-7,minecraft:stone)
B(-8,-8,-6,minecraft:stone)
B(-8,-8,-5,minecraft:stone)
B(-8,-8,-4,minecraft:stone)
B(-8,-8,-3,minecraft:stone)
B(-8,-8,-2,minecraft:stone)
B(-8,-8,-1,minecraft:stone)
B(-8,-8,0,minecraft:stone)
B(-8,-8,1,minecraft:stone)
B(-8,-8,2,minecraft:stone)
B(-8,-7,-8,minecraft:stone)
B(-8,-7,-7,minecraft:stone)
B(-8,-7,-6,minecraft:stone)
B(-8,-7,-5,minecraft:stone)
B(-8,-7,-4,minecraft:stone)
B(-8,-7,-3,minecraft:stone)
B(-8,-7,-2,minecraft:stone)
B(-8,-7,-1,minecraft:stone)
B(-8,-7,0,minecraft:stone)
B(-8,-7,1,minecraft:stone)
B(-8,-7,2,minecraft:stone)
B(-8,-6,-8,minecraft:stone)
B(-8,-6,-7,minecraft:stone)
B(-8,-6,-6,minecraft:stone)
B(-8,-6,-5,minecraft:stone)
B(-8,-6,-4,minecraft:stone)
B(-8,-6,-3,minecraft:stone)
B(-8,-6,-2,minecraft:stone)
B(-8,-6,-1,minecraft:stone)
B(-8,-6,0,minecraft:stone)
B(-8,-6,1,minecraft:stone)
B(-8,-6,2,minecraft:stone)
B(-8,-6,3,minecraft:stone)
B(-8,-5,-7,minecraft:stone)
B(-8,-5,-6,minecraft:stone)
B(-8,-5,-5,minecraft:stone)
B(-8,-5,-4,minecraft:stone)
B(-8,-5,-3,minecraft:stone)
B(-8,-5,-2,minecraft:stone)
B(-8,-5,-1,minecraft:stone)
B(-8,-5,0,minecraft:stone)
B(-8,-5,1,minecraft:stone)
B(-8,-5,2,minecraft:stone)
B(-8,-5,3,minecraft:stone)
B(-8,-5,4,minecraft:stone)
B(-8,-4,-7,minecraft:stone)
B(-8,-4,-6,minecraft:stone)
B(-8,-4,-5,minecraft:stone)
B(-8,-4,-4,minecraft:stone)
B(-8,-4,-3,minecraft:stone)
B(-8,-4,-2,minecraft:stone)
B(-8,-4,-1,minecraft:stone)
B(-8,-4,0,minecraft:stone)
B(-8,-4,1,minecraft:stone)
B(-8,-4,2,minecraft:stone)
B(-8,-4,3,minecraft:stone)
B(-8,-4,4,minecraft:stone)
B(-8,-3,-6,minecraft:stone)
B(-8,-3,-5,minecraft:stone)
B(-8,-3,-4,minecraft:stone)
B(-8,-3,-3,minecraft:stone)
B(-8,-3,-2,minecraft:stone)
B(-8,-3,-1,minecraft:stone)
B(-8,-3,0,minecraft:stone)
B(-8,-3,1,minecraft:stone)
B(-8,-3,2,minecraft:stone)
B(-8,-3,3,minecraft:stone)
B(-8,-3,4,minecraft:stone)
B(-8,-2,-6,minecraft:stone)
B(-8,-2,-5,minecraft:stone)
B(-8,-2,-4,minecraft:stone)
B(-8,-2,-3,minecraft:stone)
B(-8,-2,-2,minecraft:stone)
B(-8,-2,-1,minecraft:stone)
B(-8,-2,0,minecraft:stone)
B(-8,-2,1,minecraft:stone)
B(-8,-2,2,minecraft:stone)
B(-8,-2,3,minecraft:stone)
B(-8,-2,4,minecraft:stone)
B(-8,-2,5,minecraft:stone)
B(-8,-1,-5,minecraft:stone)
B(-8,-1,-4,minecraft:stone)
B(-8,-1,-3,minecraft:stone)
B(-8,-1,-2,minecraft:stone)
B(-8,-1,-1,minecraft:stone)
B(-8,-1,0,minecraft:stone)
B(-8,-1,1,minecraft:stone)
B(-8,-1,2,minecraft:stone)
B(-8,-1,3,minecraft:stone)
B(-8,-1,4,minecraft:stone)
B(-8,-1,5,minecraft:stone)
B(-8,0,-4,minecraft:stone)
B(-8,0,-3,minecraft:stone)
B(-8,0,-2,minecraft:stone)
B(-8,0,-1,minecraft:stone)
B(-8,0,0,minecraft:stone)
B(-8,0,1,minecraft:stone)
B(-8,0,2,minecraft:stone)
B(-8,0,3,minecraft:stone)
B(-8,0,4,minecraft:stone)
B(-8,0,5,minecraft:stone)
B(-8,1,-3,minecraft:stone)
B(-8,1,-2,minecraft:stone)
B(-8,1,-1,minecraft:stone)
B(-8,1,0,minecraft:stone)
B(-8,1,1,minecraft:stone)
B(-8,1,2,minecraft:stone)
B(-8,1,3,minecraft:stone)
B(-8,1,4,minecraft:stone)
B(-8,1,5,minecraft:stone)
B(-8,2,-1,minecraft:stone)
B(-8,2,0,minecraft:stone)
B(-8,2,1,minecraft:stone)
B(-8,2,2,minecraft:stone)
B(-8,2,3,minecraft:stone)
B(-8,2,4,minecraft:stone)
B(-8,3,0,minecraft:stone)
B(-8,3,1,minecraft:stone)
B(-8,3,2,minecraft:stone)
B(-7,-10,0,minecraft:stone)
B(-7,-10,1,minecraft:stone)
B(-7,-9,-6,minecraft:stone)
B(-7,-9,-5,minecraft:stone)
B(-7,-9,-4,minecraft:stone)
B(-7,-9,-3,minecraft:stone)
B(-7,-9,-2,minecraft:stone)
B(-7,-9,-1,minecraft:stone)
B(-7,-9,0,minecraft:stone)
B(-7,-9,1,minecraft:stone)
B(-7,-9,2,minecraft:stone)
B(-7,-8,-8,minecraft:stone)
B(-7,-8,-7,minecraft:stone)
B(-7,-8,-6,minecraft:stone)
B(-7,-8,-5,minecraft:stone)
B(-7,-8,-4,minecraft:stone)
B(-7,-8,-3,minecraft:stone)
B(-7,-8,-2,minecraft:stone)
B(-7,-8,-1,minecraft:stone)
B(-7,-8,0,minecraft:stone)
B(-7,-8,1,minecraft:stone)
B(-7,-8,2,minecraft:stone)
B(-7,-7,-9,minecraft:stone)
B(-7,-7,-8,minecraft:stone)
B(-7,-7,-7,minecraft:stone)
B(-7,-7,-6,minecraft:stone)
B(-7,-7,-5,minecraft:stone)
B(-7,-7,-4,minecraft:stone)
B(-7,-7,-3,minecraft:stone)
B(-7,-7,-2,minecraft:stone)
B(-7,-7,-1,minecraft:stone)
B(-7,-7,0,minecraft:stone)
B(-7,-7,1,minecraft:stone)
B(-7,-7,2,minecraft:stone)
B(-7,-7,3,minecraft:stone)
B(-7,-6,-9,minecraft:stone)
B(-7,-6,-8,minecraft:stone)
B(-7,-6,-7,minecraft:stone)
B(-7,-6,-6,minecraft:stone)
B(-7,-6,-5,minecraft:stone)
B(-7,-6,-4,minecraft:stone)
B(-7,-6,-3,minecraft:stone)
B(-7,-6,-2,minecraft:stone)
B(-7,-6,-1,minecraft:stone)
B(-7,-6,0,minecraft:stone)
B(-7,-6,1,minecraft:stone)
B(-7,-6,2,minecraft:stone)
B(-7,-6,3,minecraft:stone)
B(-7,-5,-9,minecraft:stone)
B(-7,-5,-8,minecraft:stone)
B(-7,-5,-7,minecraft:stone)
B(-7,-5,-6,minecraft:stone)
B(-7,-5,-5,minecraft:stone)
B(-7,-5,-4,minecraft:stone)
B(-7,-5,-3,minecraft:stone)
B(-7,-5,-2,minecraft:stone)
B(-7,-5,-1,minecraft:stone)
B(-7,-5,0,minecraft:stone)
B(-7,-5,1,minecraft:stone)
B(-7,-5,2,minecraft:stone)
B(-7,-5,3,minecraft:stone)
B(-7,-5,4,minecraft:stone)
B(-7,-4,-8,minecraft:stone)
B(-7,-4,-7,minecraft:stone)
B(-7,-4,-6,minecraft:stone)
B(-7,-4,-5,minecraft:stone)
B(-7,-4,-4,minecraft:stone)
B(-7,-4,-3,minecraft:stone)
B(-7,-4,-2,minecraft:stone)
B(-7,-4,-1,minecraft:stone)
B(-7,-4,0,minecraft:stone)
B(-7,-4,1,minecraft:stone)
B(-7,-4,2,minecraft:stone)
B(-7,-4,3,minecraft:stone)
B(-7,-4,4,minecraft:stone)
B(-7,-4,5,minecraft:stone)
B(-7,-3,-8,minecraft:stone)
B(-7,-3,-7,minecraft:stone)
B(-7,-3,-6,minecraft:stone)
B(-7,-3,-5,minecraft:stone)
B(-7,-3,-4,minecraft:stone)
B(-7,-3,-3,minecraft:stone)
B(-7,-3,-2,minecraft:stone)
B(-7,-3,-1,minecraft:stone)
B(-7,-3,0,minecraft:stone)
B(-7,-3,1,minecraft:stone)
B(-7,-3,2,minecraft:stone)
B(-7,-3,3,minecraft:stone)
B(-7,-3,4,minecraft:stone)
B(-7,-3,5,minecraft:stone)
B(-7,-2,-8,minecraft:stone)
B(-7,-2,-7,minecraft:stone)
B(-7,-2,-6,minecraft:stone)
B(-7,-2,-5,minecraft:stone)
B(-7,-2,-4,minecraft:stone)
B(-7,-2,-3,minecraft:stone)
B(-7,-2,-2,minecraft:stone)
B(-7,-2,-1,minecraft:stone)
B(-7,-2,0,minecraft:stone)
B(-7,-2,1,minecraft:stone)
B(-7,-2,2,minecraft:stone)
B(-7,-2,3,minecraft:stone)
B(-7,-2,4,minecraft:stone)
B(-7,-2,5,minecraft:stone)
B(-7,-1,-7,minecraft:stone)
B(-7,-1,-6,minecraft:stone)
B(-7,-1,-5,minecraft:stone)
B(-7,-1,-4,minecraft:stone)
B(-7,-1,-3,minecraft:stone)
B(-7,-1,-2,minecraft:stone)
B(-7,-1,-1,minecraft:stone)
B(-7,-1,0,minecraft:stone)
B(-7,-1,1,minecraft:stone)
B(-7,-1,2,minecraft:stone)
B(-7,-1,3,minecraft:stone)
B(-7,-1,4,minecraft:stone)
B(-7,-1,5,minecraft:stone)
B(-7,0,-6,minecraft:stone)
B(-7,0,-5,minecraft:stone)
B(-7,0,-4,minecraft:stone)
B(-7,0,-3,minecraft:stone)
B(-7,0,-2,minecraft:stone)
B(-7,0,-1,minecraft:stone)
B(-7,0,0,minecraft:stone)
B(-7,0,1,minecraft:stone)
B(-7,0,2,minecraft:stone)
B(-7,0,3,minecraft:stone)
B(-7,0,4,minecraft:stone)
B(-7,0,5,minecraft:stone)
B(-7,1,-5,minecraft:stone)
B(-7,1,-4,minecraft:stone)
B(-7,1,-3,minecraft:stone)
B(-7,1,-2,minecraft:stone)
B(-7,1,-1,minecraft:stone)
B(-7,1,0,minecraft:stone)
B(-7,1,1,minecraft:stone)
B(-7,1,2,minecraft:stone)
B(-7,1,3,minecraft:stone)
B(-7,1,4,minecraft:stone)
B(-7,1,5,minecraft:stone)
B(-7,2,-4,minecraft:stone)
B(-7,2,-3,minecraft:stone)
B(-7,2,-2,minecraft:stone)
B(-7,2,-1,minecraft:stone)
B(-7,2,0,minecraft:stone)
B(-7,2,1,minecraft:stone)
B(-7,2,2,minecraft:stone)
B(-7,2,3,minecraft:stone)
B(-7,2,4,minecraft:stone)
B(-7,3,-3,minecraft:stone)
B(-7,3,-2,minecraft:stone)
B(-7,3,-1,minecraft:stone)
B(-7,3,0,minecraft:stone)
B(-7,3,1,minecraft:stone)
B(-7,3,2,minecraft:stone)
B(-7,3,3,minecraft:stone)
B(-7,3,4,minecraft:stone)
B(-7,4,-2,minecraft:stone)
B(-7,4,-1,minecraft:stone)
B(-7,4,0,minecraft:stone)
B(-7,4,1,minecraft:stone)
B(-6,-10,0,minecraft:stone)
B(-6,-10,1,minecraft:stone)
B(-6,-10,2,minecraft:stone)
B(-6,-9,-5,minecraft:stone)
B(-6,-9,-4,minecraft:stone)
B(-6,-9,-3,minecraft:stone)
B(-6,-9,-2,minecraft:stone)
B(-6,-9,-1,minecraft:stone)
B(-6,-9,0,minecraft:stone)
B(-6,-9,1,minecraft:stone)
B(-6,-9,2,minecraft:stone)
B(-6,-8,-8,minecraft:stone)
B(-6,-8,-7,minecraft:stone)
B(-6,-8,-6,minecraft:stone)
B(-6,-8,-5,minecraft:stone)
B(-6,-8,-4,minecraft:stone)
B(-6,-8,-3,minecraft:stone)
B(-6,-8,-2,minecraft:stone)
B(-6,-8,-1,minecraft:stone)
B(-6,-8,0,minecraft:stone)
B(-6,-8,1,minecraft:stone)
B(-6,-8,2,minecraft:stone)
B(-6,-8,3,minecraft:stone)
B(-6,-7,-9,minecraft:stone)
B(-6,-7,-8,minecraft:stone)
B(-6,-7,-7,minecraft:stone)
B(-6,-7,-6,minecraft:stone)
B(-6,-7,-5,minecraft:stone)
B(-6,-7,-4,minecraft:stone)
B(-6,-7,-3,minecraft:stone)
B(-6,-7,-2,minecraft:stone)
B(-6,-7,-1,minecraft:stone)
B(-6,-7,0,minecraft:stone)
B(-6,-7,1,minecraft:stone)
B(-6,-7,2,minecraft:stone)
B(-6,-7,3,minecraft:stone)
B(-6,-6,-10,minecraft:stone)
B(-6,-6,-9,minecraft:stone)
B(-6,-6,-8,minecraft:stone)
B(-6,-6,-7,minecraft:stone)
B(-6,-6,-6,minecraft:stone)
B(-6,-6,-5,minecraft:stone)
B(-6,-6,-4,minecraft:stone)
B(-6,-6,-3,minecraft:stone)
B(-6,-6,-2,minecraft:stone)
B(-6,-6,-1,minecraft:stone)
B(-6,-6,0,minecraft:stone)
B(-6,-6,1,minecraft:stone)
B(-6,-6,2,minecraft:stone)
B(-6,-6,3,minecraft:stone)
B(-6,-6,4,minecraft:stone)
B(-6,-5,-10,minecraft:stone)
B(-6,-5,-9,minecraft:stone)
B(-6,-5,-8,minecraft:stone)
B(-6,-5,-7,minecraft:stone)
B(-6,-5,-6,minecraft:stone)
B(-6,-5,-5,minecraft:stone)
B(-6,-5,-4,minecraft:stone)
B(-6,-5,-3,minecraft:stone)
B(-6,-5,-2,minecraft:stone)
B(-6,-5,-1,minecraft:stone)
B(-6,-5,0,minecraft:stone)
B(-6,-5,1,minecraft:stone)
B(-6,-5,2,minecraft:stone)
B(-6,-5,3,minecraft:stone)
B(-6,-5,4,minecraft:stone)
B(-6,-5,5,minecraft:stone)
B(-6,-4,-9,minecraft:stone)
B(-6,-4,-8,minecraft:stone)
B(-6,-4,-7,minecraft:stone)
B(-6,-4,-6,minecraft:stone)
B(-6,-4,-5,minecraft:stone)
B(-6,-4,-4,minecraft:stone)
B(-6,-4,-3,minecraft:stone)
B(-6,-4,-2,minecraft:stone)
B(-6,-4,-1,minecraft:stone)
B(-6,-4,0,minecraft:stone)
B(-6,-4,1,minecraft:stone)
B(-6,-4,2,minecraft:stone)
B(-6,-4,3,minecraft:stone)
B(-6,-4,4,minecraft:stone)
B(-6,-4,5,minecraft:stone)
B(-6,-3,-9,minecraft:stone)
B(-6,-3,-8,minecraft:stone)
B(-6,-3,-7,minecraft:stone)
B(-6,-3,-6,minecraft:stone)
B(-6,-3,-5,minecraft:stone)
B(-6,-3,-4,minecraft:stone)
B(-6,-3,-3,minecraft:stone)
B(-6,-3,-2,minecraft:stone)
B(-6,-3,-1,minecraft:stone)
B(-6,-3,0,minecraft:stone)
B(-6,-3,1,minecraft:stone)
B(-6,-3,2,minecraft:stone)
B(-6,-3,3,minecraft:stone)
B(-6,-3,4,minecraft:stone)
B(-6,-3,5,minecraft:stone)
B(-6,-2,-9,minecraft:stone)
B(-6,-2,-8,minecraft:stone)
B(-6,-2,-7,minecraft:stone)
B(-6,-2,-6,minecraft:stone)
B(-6,-2,-5,minecraft:stone)
B(-6,-2,-4,minecraft:stone)
B(-6,-2,-3,minecraft:stone)
B(-6,-2,-2,minecraft:stone)
B(-6,-2,-1,minecraft:stone)
B(-6,-2,0,minecraft:stone)
B(-6,-2,1,minecraft:stone)
B(-6,-2,2,minecraft:stone)
B(-6,-2,3,minecraft:stone)
B(-6,-2,4,minecraft:stone)
B(-6,-2,5,minecraft:stone)
B(-6,-2,6,minecraft:stone)
B(-6,-1,-8,minecraft:stone)
B(-6,-1,-7,minecraft:stone)
B(-6,-1,-6,minecraft:stone)
B(-6,-1,-5,minecraft:stone)
B(-6,-1,-4,minecraft:stone)
B(-6,-1,-3,minecraft:stone)
B(-6,-1,-2,minecraft:stone)
B(-6,-1,-1,minecraft:stone)
B(-6,-1,0,minecraft:stone)
B(-6,-1,1,minecraft:stone)
B(-6,-1,2,minecraft:stone)
B(-6,-1,3,minecraft:stone)
B(-6,-1,4,minecraft:stone)
B(-6,-1,5,minecraft:stone)
B(-6,-1,6,minecraft:stone)
B(-6,0,-7,minecraft:stone)
B(-6,0,-6,minecraft:stone)
B(-6,0,-5,minecraft:stone)
B(-6,0,-4,minecraft:stone)
B(-6,0,-3,minecraft:stone)
B(-6,0,-2,minecraft:stone)
B(-6,0,-1,minecraft:stone)
B(-6,0,0,minecraft:stone)
B(-6,0,1,minecraft:stone)
B(-6,0,2,minecraft:stone)
B(-6,0,3,minecraft:stone)
B(-6,0,4,minecraft:stone)
B(-6,0,5,minecraft:stone)
B(-6,0,6,minecraft:stone)
B(-6,1,-7,minecraft:stone)
B(-6,1,-6,minecraft:stone)
B(-6,1,-5,minecraft:stone)
B(-6,1,-4,minecraft:stone)
B(-6,1,-3,minecraft:stone)
B(-6,1,-2,minecraft:stone)
B(-6,1,-1,minecraft:stone)
B(-6,1,0,minecraft:stone)
B(-6,1,1,minecraft:stone)
B(-6,1,2,minecraft:stone)
B(-6,1,3,minecraft:stone)
B(-6,1,4,minecraft:stone)
B(-6,1,5,minecraft:stone)
B(-6,2,-6,minecraft:stone)
B(-6,2,-5,minecraft:stone)
B(-6,2,-4,minecraft:stone)
B(-6,2,-3,minecraft:stone)
B(-6,2,-2,minecraft:stone)
B(-6,2,-1,minecraft:stone)
B(-6,2,0,minecraft:stone)
B(-6,2,1,minecraft:stone)
B(-6,2,2,minecraft:stone)
B(-6,2,3,minecraft:stone)
B(-6,2,4,minecraft:stone)
B(-6,2,5,minecraft:stone)
B(-6,3,-5,minecraft:stone)
B(-6,3,-4,minecraft:stone)
B(-6,3,-3,minecraft:stone)
B(-6,3,-2,minecraft:stone)
B(-6,3,-1,minecraft:stone)
B(-6,3,0,minecraft:stone)
B(-6,3,1,minecraft:stone)
B(-6,3,2,minecraft:stone)
B(-6,3,3,minecraft:stone)
B(-6,3,4,minecraft:stone)
B(-6,4,-4,minecraft:stone)
B(-6,4,-3,minecraft:stone)
B(-6,4,-2,minecraft:stone)
B(-6,4,-1,minecraft:stone)
B(-6,4,0,minecraft:stone)
B(-6,4,1,minecraft:stone)
B(-6,4,2,minecraft:stone)
B(-6,4,3,minecraft:stone)
B(-6,5,-3,minecraft:stone)
B(-6,5,-2,minecraft:stone)
B(-6,5,-1,minecraft:stone)
B(-5,-10,0,minecraft:stone)
B(-5,-10,1,minecraft:stone)
B(-5,-10,2,minecraft:stone)
B(-5,-9,-5,minecraft:stone)
B(-5,-9,-4,minecraft:stone)
B(-5,-9,-3,minecraft:stone)
B(-5,-9,-2,minecraft:stone)
B(-5,-9,-1,minecraft:stone)
B(-5,-9,0,minecraft:stone)
B(-5,-9,1,minecraft:stone)
B(-5,-9,2,minecraft:stone)
B(-5,-9,3,minecraft:stone)
B(-5,-8,-7,minecraft:stone)
B(-5,-8,-6,minecraft:stone)
B(-5,-8,-5,minecraft:stone)
B(-5,-8,-4,minecraft:stone)
B(-5,-8,-3,minecraft:stone)
B(-5,-8,-2,minecraft:stone)
B(-5,-8,-1,minecraft:stone)
B(-5,-8,0,minecraft:stone)
B(-5,-8,1,minecraft:stone)
B(-5,-8,2,minecraft:stone)
B(-5,-8,3,minecraft:stone)
B(-5,-7,-9,minecraft:stone)
B(-5,-7,-8,minecraft:stone)
B(-5,-7,-7,minecraft:stone)
B(-5,-7,-6,minecraft:stone)
B(-5,-7,-5,minecraft:stone)
B(-5,-7,-4,minecraft:stone)
B(-5,-7,-3,minecraft:stone)
B(-5,-7,-2,minecraft:stone)
B(-5,-7,-1,minecraft:stone)
B(-5,-7,0,minecraft:stone)
B(-5,-7,1,minecraft:stone)
B(-5,-7,2,minecraft:stone)
B(-5,-7,3,minecraft:stone)
B(-5,-7,4,minecraft:stone)
B(-5,-6,-10,minecraft:stone)
B(-5,-6,-9,minecraft:stone)
B(-5,-6,-8,minecraft:stone)
B(-5,-6,-7,minecraft:stone)
B(-5,-6,-6,minecraft:stone)
B(-5,-6,-5,minecraft:stone)
B(-5,-6,-4,minecraft:stone)
B(-5,-6,-3,minecraft:stone)
B(-5,-6,-2,minecraft:stone)
B(-5,-6,-1,minecraft:stone)
B(-5,-6,0,minecraft:stone)
B(-5,-6,1,minecraft:stone)
B(-5,-6,2,minecraft:stone)
B(-5,-6,3,minecraft:stone)
B(-5,-6,4,minecraft:stone)
B(-5,-5,-10,minecraft:stone)
B(-5,-5,-9,minecraft:stone)
B(-5,-5,-8,minecraft:stone)
B(-5,-5,-7,minecraft:stone)
B(-5,-5,-6,minecraft:stone)
B(-5,-5,-5,minecraft:stone)
B(-5,-5,-4,minecraft:stone)
B(-5,-5,-3,minecraft:stone)
B(-5,-5,-2,minecraft:stone)
B(-5,-5,-1,minecraft:stone)
B(-5,-5,0,minecraft:stone)
B(-5,-5,1,minecraft:stone)
B(-5,-5,2,minecraft:stone)
B(-5,-5,3,minecraft:stone)
B(-5,-5,4,minecraft:stone)
B(-5,-5,5,minecraft:stone)
B(-5,-4,-10,minecraft:stone)
B(-5,-4,-9,minecraft:stone)
B(-5,-4,-8,minecraft:stone)
B(-5,-4,-7,minecraft:stone)
B(-5,-4,-6,minecraft:stone)
B(-5,-4,-5,minecraft:stone)
B(-5,-4,-4,minecraft:stone)
B(-5,-4,-3,minecraft:stone)
B(-5,-4,-2,minecraft:stone)
B(-5,-4,-1,minecraft:stone)
B(-5,-4,0,minecraft:stone)
B(-5,-4,1,minecraft:stone)
B(-5,-4,2,minecraft:stone)
B(-5,-4,3,minecraft:stone)
B(-5,-4,4,minecraft:stone)
B(-5,-4,5,minecraft:stone)
B(-5,-4,6,minecraft:stone)
B(-5,-3,-10,minecraft:stone)
B(-5,-3,-9,minecraft:stone)
B(-5,-3,-8,minecraft:stone)
B(-5,-3,-7,minecraft:stone)
B(-5,-3,-6,minecraft:stone)
B(-5,-3,-5,minecraft:stone)
B(-5,-3,-4,minecraft:stone)
B(-5,-3,-3,minecraft:stone)
B(-5,-3,-2,minecraft:stone)
B(-5,-3,-1,minecraft:stone)
B(-5,-3,0,minecraft:stone)
B(-5,-3,1,minecraft:stone)
B(-5,-3,2,minecraft:stone)
B(-5,-3,3,minecraft:stone)
B(-5,-3,4,minecraft:stone)
B(-5,-3,5,minecraft:stone)
B(-5,-3,6,minecraft:stone)
B(-5,-2,-10,minecraft:stone)
B(-5,-2,-9,minecraft:stone)
B(-5,-2,-8,minecraft:stone)
B(-5,-2,-7,minecraft:stone)
B(-5,-2,-6,minecraft:stone)
B(-5,-2,-5,minecraft:stone)
B(-5,-2,-4,minecraft:stone)
B(-5,-2,-3,minecraft:stone)
B(-5,-2,-2,minecraft:stone)
B(-5,-2,-1,minecraft:stone)
B(-5,-2,0,minecraft:stone)
B(-5,-2,1,minecraft:stone)
B(-5,-2,2,minecraft:stone)
B(-5,-2,3,minecraft:stone)
B(-5,-2,4,minecraft:stone)
B(-5,-2,5,minecraft:stone)
B(-5,-2,6,minecraft:stone)
B(-5,-1,-9,minecraft:stone)
B(-5,-1,-8,minecraft:stone)
B(-5,-1,-7,minecraft:stone)
B(-5,-1,-6,minecraft:stone)
B(-5,-1,-5,minecraft:stone)
B(-5,-1,-4,minecraft:stone)
B(-5,-1,-3,minecraft:stone)
B(-5,-1,-2,minecraft:stone)
B(-5,-1,-1,minecraft:stone)
B(-5,-1,0,minecraft:stone)
B(-5,-1,1,minecraft:stone)
B(-5,-1,2,minecraft:stone)
B(-5,-1,3,minecraft:stone)
B(-5,-1,4,minecraft:stone)
B(-5,-1,5,minecraft:stone)
B(-5,-1,6,minecraft:stone)
B(-5,0,-8,minecraft:stone)
B(-5,0,-7,minecraft:stone)
B(-5,0,-6,minecraft:stone)
B(-5,0,-5,minecraft:stone)
B(-5,0,-4,minecraft:stone)
B(-5,0,-3,minecraft:stone)
B(-5,0,-2,minecraft:stone)
B(-5,0,-1,minecraft:stone)
B(-5,0,0,minecraft:stone)
B(-5,0,1,minecraft:stone)
B(-5,0,2,minecraft:stone)
B(-5,0,3,minecraft:stone)
B(-5,0,4,minecraft:stone)
B(-5,0,5,minecraft:stone)
B(-5,0,6,minecraft:stone)
B(-5,1,-8,minecraft:stone)
B(-5,1,-7,minecraft:stone)
B(-5,1,-6,minecraft:stone)
B(-5,1,-5,minecraft:stone)
B(-5,1,-4,minecraft:stone)
B(-5,1,-3,minecraft:stone)
B(-5,1,-2,minecraft:stone)
B(-5,1,-1,minecraft:stone)
B(-5,1,0,minecraft:stone)
B(-5,1,1,minecraft:stone)
B(-5,1,2,minecraft:stone)
B(-5,1,3,minecraft:stone)
B(-5,1,4,minecraft:stone)
B(-5,1,5,minecraft:stone)
B(-5,1,6,minecraft:stone)
B(-5,2,-7,minecraft:stone)
B(-5,2,-6,minecraft:stone)
B(-5,2,-5,minecraft:stone)
B(-5,2,-4,minecraft:stone)
B(-5,2,-3,minecraft:stone)
B(-5,2,-2,minecraft:stone)
B(-5,2,-1,minecraft:stone)
B(-5,2,0,minecraft:stone)
B(-5,2,1,minecraft:stone)
B(-5,2,2,minecraft:stone)
B(-5,2,3,minecraft:stone)
B(-5,2,4,minecraft:stone)
B(-5,2,5,minecraft:stone)
B(-5,3,-6,minecraft:stone)
B(-5,3,-5,minecraft:stone)
B(-5,3,-4,minecraft:stone)
B(-5,3,-3,minecraft:stone)
B(-5,3,-2,minecraft:stone)
B(-5,3,-1,minecraft:stone)
B(-5,3,0,minecraft:stone)
B(-5,3,1,minecraft:stone)
B(-5,3,2,minecraft:stone)
B(-5,3,3,minecraft:stone)
B(-5,3,4,minecraft:stone)
B(-5,3,5,minecraft:stone)
B(-5,4,-6,minecraft:stone)
B(-5,4,-5,minecraft:stone)
B(-5,4,-4,minecraft:stone)
B(-5,4,-3,minecraft:stone)
B(-5,4,-2,minecraft:stone)
B(-5,4,-1,minecraft:stone)
B(-5,4,0,minecraft:stone)
B(-5,4,1,minecraft:stone)
B(-5,4,2,minecraft:stone)
B(-5,4,3,minecraft:stone)
B(-5,4,4,minecraft:stone)
B(-5,5,-5,minecraft:stone)
B(-5,5,-4,minecraft:stone)
B(-5,5,-3,minecraft:stone)
B(-5,5,-2,minecraft:stone)
B(-5,5,-1,minecraft:stone)
B(-5,5,0,minecraft:stone)
B(-5,5,1,minecraft:stone)
B(-5,5,2,minecraft:stone)
B(-5,6,-3,minecraft:stone)
B(-4,-10,0,minecraft:stone)
B(-4,-10,1,minecraft:stone)
B(-4,-10,2,minecraft:stone)
B(-4,-10,3,minecraft:stone)
B(-4,-9,-5,minecraft:stone)
B(-4,-9,-4,minecraft:stone)
B(-4,-9,-3,minecraft:stone)
B(-4,-9,-2,minecraft:stone)
B(-4,-9,-1,minecraft:stone)
B(-4,-9,0,minecraft:stone)
B(-4,-9,1,minecraft:stone)
B(-4,-9,2,minecraft:stone)
B(-4,-9,3,minecraft:stone)
B(-4,-9,4,minecraft:stone)
B(-4,-8,-8,minecraft:stone)
B(-4,-8,-7,minecraft:stone)
B(-4,-8,-6,minecraft:stone)
B(-4,-8,-5,minecraft:stone)
B(-4,-8,-4,minecraft:stone)
B(-4,-8,-3,minecraft:stone)
B(-4,-8,-2,minecraft:stone)
B(-4,-8,-1,minecraft:stone)
B(-4,-8,0,minecraft:stone)
B(-4,-8,1,minecraft:stone)
B(-4,-8,2,minecraft:stone)
B(-4,-8,3,minecraft:stone)
B(-4,-8,4,minecraft:stone)
B(-4,-7,-9,minecraft:stone)
B(-4,-7,-8,minecraft:stone)
B(-4,-7,-7,minecraft:stone)
B(-4,-7,-6,minecraft:stone)
B(-4,-7,-5,minecraft:stone)
B(-4,-7,-4,minecraft:stone)
B(-4,-7,-3,minecraft:stone)
B(-4,-7,-2,minecraft:stone)
B(-4,-7,-1,minecraft:stone)
B(-4,-7,0,minecraft:stone)
B(-4,-7,1,minecraft:stone)
B(-4,-7,2,minecraft:stone)
B(-4,-7,3,minecraft:stone)
B(-4,-7,4,minecraft:stone)
B(-4,-7,5,minecraft:stone)
B(-4,-6,-10,minecraft:stone)
B(-4,-6,-9,minecraft:stone)
B(-4,-6,-8,minecraft:stone)
B(-4,-6,-7,minecraft:stone)
B(-4,-6,-6,minecraft:stone)
B(-4,-6,-5,minecraft:stone)
B(-4,-6,-4,minecraft:stone)
B(-4,-6,-3,minecraft:stone)
B(-4,-6,-2,minecraft:stone)
B(-4,-6,-1,minecraft:stone)
B(-4,-6,0,minecraft:stone)
B(-4,-6,1,minecraft:stone)
B(-4,-6,2,minecraft:stone)
B(-4,-6,3,minecraft:stone)
B(-4,-6,4,minecraft:stone)
B(-4,-6,5,minecraft:stone)
B(-4,-5,-10,minecraft:stone)
B(-4,-5,-9,minecraft:stone)
B(-4,-5,-8,minecraft:stone)
B(-4,-5,-7,minecraft:stone)
B(-4,-5,-6,minecraft:stone)
B(-4,-5,-5,minecraft:stone)
B(-4,-5,-4,minecraft:stone)
B(-4,-5,-3,minecraft:stone)
B(-4,-5,-2,minecraft:stone)
B(-4,-5,-1,minecraft:stone)
B(-4,-5,0,minecraft:stone)
B(-4,-5,1,minecraft:stone)
B(-4,-5,2,minecraft:stone)
B(-4,-5,3,minecraft:stone)
B(-4,-5,4,minecraft:stone)
B(-4,-5,5,minecraft:stone)
B(-4,-5,6,minecraft:stone)
B(-4,-4,-10,minecraft:stone)
B(-4,-4,-9,minecraft:stone)
B(-4,-4,-8,minecraft:stone)
B(-4,-4,-7,minecraft:stone)
B(-4,-4,-6,minecraft:stone)
B(-4,-4,-5,minecraft:stone)
B(-4,-4,-4,minecraft:stone)
B(-4,-4,-3,minecraft:stone)
B(-4,-4,-2,minecraft:stone)
B(-4,-4,-1,minecraft:stone)
B(-4,-4,0,minecraft:stone)
B(-4,-4,1,minecraft:stone)
B(-4,-4,2,minecraft:stone)
B(-4,-4,3,minecraft:stone)
B(-4,-4,4,minecraft:stone)
B(-4,-4,5,minecraft:stone)
B(-4,-4,6,minecraft:stone)
B(-4,-3,-10,minecraft:stone)
B(-4,-3,-9,minecraft:stone)
B(-4,-3,-8,minecraft:stone)
B(-4,-3,-7,minecraft:stone)
B(-4,-3,-6,minecraft:stone)
B(-4,-3,-5,minecraft:stone)
B(-4,-3,-4,minecraft:stone)
B(-4,-3,-3,minecraft:stone)
B(-4,-3,-2,minecraft:stone)
B(-4,-3,-1,minecraft:stone)
B(-4,-3,0,minecraft:stone)
B(-4,-3,1,minecraft:stone)
B(-4,-3,2,minecraft:stone)
B(-4,-3,3,minecraft:stone)
B(-4,-3,4,minecraft:stone)
B(-4,-3,5,minecraft:stone)
B(-4,-3,6,minecraft:stone)
B(-4,-2,-9,minecraft:stone)
B(-4,-2,-8,minecraft:stone)
B(-4,-2,-7,minecraft:stone)
B(-4,-2,-6,minecraft:stone)
B(-4,-2,-5,minecraft:stone)
B(-4,-2,-4,minecraft:stone)
B(-4,-2,-3,minecraft:stone)
B(-4,-2,-2,minecraft:stone)
B(-4,-2,-1,minecraft:stone)
B(-4,-2,0,minecraft:stone)
B(-4,-2,1,minecraft:stone)
B(-4,-2,2,minecraft:stone)
B(-4,-2,3,minecraft:stone)
B(-4,-2,4,minecraft:stone)
B(-4,-2,5,minecraft:stone)
B(-4,-2,6,minecraft:stone)
B(-4,-1,-9,minecraft:stone)
B(-4,-1,-8,minecraft:stone)
B(-4,-1,-7,minecraft:stone)
B(-4,-1,-6,minecraft:stone)
B(-4,-1,-5,minecraft:stone)
B(-4,-1,-4,minecraft:stone)
B(-4,-1,-3,minecraft:stone)
B(-4,-1,-2,minecraft:stone)
B(-4,-1,-1,minecraft:stone)
B(-4,-1,0,minecraft:stone)
B(-4,-1,1,minecraft:stone)
B(-4,-1,2,minecraft:stone)
B(-4,-1,3,minecraft:stone)
B(-4,-1,4,minecraft:stone)
B(-4,-1,5,minecraft:stone)
B(-4,-1,6,minecraft:stone)
B(-4,0,-9,minecraft:stone)
B(-4,0,-8,minecraft:stone)
B(-4,0,-7,minecraft:stone)
B(-4,0,-6,minecraft:stone)
B(-4,0,-5,minecraft:stone)
B(-4,0,-4,minecraft:stone)
B(-4,0,-3,minecraft:stone)
B(-4,0,-2,minecraft:stone)
B(-4,0,-1,minecraft:stone)
B(-4,0,0,minecraft:stone)
B(-4,0,1,minecraft:stone)
B(-4,0,2,minecraft:stone)
B(-4,0,3,minecraft:stone)
B(-4,0,4,minecraft:stone)
B(-4,0,5,minecraft:stone)
B(-4,0,6,minecraft:stone)
B(-4,1,-8,minecraft:stone)
B(-4,1,-7,minecraft:stone)
B(-4,1,-6,minecraft:stone)
B(-4,1,-5,minecraft:stone)
B(-4,1,-4,minecraft:stone)
B(-4,1,-3,minecraft:stone)
B(-4,1,-2,minecraft:stone)
B(-4,1,-1,minecraft:stone)
B(-4,1,0,minecraft:stone)
B(-4,1,1,minecraft:stone)
B(-4,1,2,minecraft:stone)
B(-4,1,3,minecraft:stone)
B(-4,1,4,minecraft:stone)
B(-4,1,5,minecraft:stone)
B(-4,1,6,minecraft:stone)
B(-4,2,-7,minecraft:stone)
B(-4,2,-6,minecraft:stone)
B(-4,2,-5,minecraft:stone)
B(-4,2,-4,minecraft:stone)
B(-4,2,-3,minecraft:stone)
B(-4,2,-2,minecraft:stone)
B(-4,2,-1,minecraft:stone)
B(-4,2,0,minecraft:stone)
B(-4,2,1,minecraft:stone)
B(-4,2,2,minecraft:stone)
B(-4,2,3,minecraft:stone)
B(-4,2,4,minecraft:stone)
B(-4,2,5,minecraft:stone)
B(-4,3,-7,minecraft:stone)
B(-4,3,-6,minecraft:stone)
B(-4,3,-5,minecraft:stone)
B(-4,3,-4,minecraft:stone)
B(-4,3,-3,minecraft:stone)
B(-4,3,-2,minecraft:stone)
B(-4,3,-1,minecraft:stone)
B(-4,3,0,minecraft:stone)
B(-4,3,1,minecraft:stone)
B(-4,3,2,minecraft:stone)
B(-4,3,3,minecraft:stone)
B(-4,3,4,minecraft:stone)
B(-4,3,5,minecraft:stone)
B(-4,4,-6,minecraft:stone)
B(-4,4,-5,minecraft:stone)
B(-4,4,-4,minecraft:stone)
B(-4,4,-3,minecraft:stone)
B(-4,4,-2,minecraft:stone)
B(-4,4,-1,minecraft:stone)
B(-4,4,0,minecraft:stone)
B(-4,4,1,minecraft:stone)
B(-4,4,2,minecraft:stone)
B(-4,4,3,minecraft:stone)
B(-4,4,4,minecraft:stone)
B(-4,5,-5,minecraft:stone)
B(-4,5,-4,minecraft:stone)
B(-4,5,-3,minecraft:stone)
B(-4,5,-2,minecraft:stone)
B(-4,5,-1,minecraft:stone)
B(-4,5,0,minecraft:stone)
B(-4,5,1,minecraft:stone)
B(-4,5,2,minecraft:stone)
B(-4,5,3,minecraft:stone)
B(-4,6,-4,minecraft:stone)
B(-4,6,-3,minecraft:stone)
B(-4,6,-2,minecraft:stone)
B(-4,6,-1,minecraft:stone)
B(-4,6,0,minecraft:stone)
B(-3,-10,0,minecraft:stone)
B(-3,-10,1,minecraft:stone)
B(-3,-10,2,minecraft:stone)
B(-3,-10,3,minecraft:stone)
B(-3,-10,4,minecraft:stone)
B(-3,-9,-4,minecraft:stone)
B(-3,-9,-3,minecraft:stone)
B(-3,-9,-2,minecraft:stone)
B(-3,-9,-1,minecraft:stone)
B(-3,-9,0,minecraft:stone)
B(-3,-9,1,minecraft:stone)
B(-3,-9,2,minecraft:stone)
B(-3,-9,3,minecraft:stone)
B(-3,-9,4,minecraft:stone)
B(-3,-8,-8,minecraft:stone)
B(-3,-8,-7,minecraft:stone)
B(-3,-8,-6,minecraft:stone)
B(-3,-8,-5,minecraft:stone)
B(-3,-8,-4,minecraft:stone)
B(-3,-8,-3,minecraft:stone)
B(-3,-8,-2,minecraft:stone)
B(-3,-8,-1,minecraft:stone)
B(-3,-8,0,minecraft:stone)
B(-3,-8,1,minecraft:stone)
B(-3,-8,2,minecraft:stone)
B(-3,-8,3,minecraft:stone)
B(-3,-8,4,minecraft:stone)
B(-3,-8,5,minecraft:stone)
B(-3,-7,-9,minecraft:stone)
B(-3,-7,-8,minecraft:stone)
B(-3,-7,-7,minecraft:stone)
B(-3,-7,-6,minecraft:stone)
B(-3,-7,-5,minecraft:stone)
B(-3,-7,-4,minecraft:stone)
B(-3,-7,-3,minecraft:stone)
B(-3,-7,-2,minecraft:stone)
B(-3,-7,-1,minecraft:stone)
B(-3,-7,0,minecraft:stone)
B(-3,-7,1,minecraft:stone)
B(-3,-7,2,minecraft:stone)
B(-3,-7,3,minecraft:stone)
B(-3,-7,4,minecraft:stone)
B(-3,-7,5,minecraft:stone)
B(-3,-6,-10,minecraft:stone)
B(-3,-6,-9,minecraft:stone)
B(-3,-6,-8,minecraft:stone)
B(-3,-6,-7,minecraft:stone)
B(-3,-6,-6,minecraft:stone)
B(-3,-6,-5,minecraft:stone)
B(-3,-6,-4,minecraft:stone)
B(-3,-6,-3,minecraft:stone)
B(-3,-6,-2,minecraft:stone)
B(-3,-6,-1,minecraft:stone)
B(-3,-6,0,minecraft:stone)
B(-3,-6,1,minecraft:stone)
B(-3,-6,2,minecraft:stone)
B(-3,-6,3,minecraft:stone)
B(-3,-6,4,minecraft:stone)
B(-3,-6,5,minecraft:stone)
B(-3,-6,6,minecraft:stone)
B(-3,-5,-10,minecraft:stone)
B(-3,-5,-9,minecraft:stone)
B(-3,-5,-8,minecraft:stone)
B(-3,-5,-7,minecraft:stone)
B(-3,-5,-6,minecraft:stone)
B(-3,-5,-5,minecraft:stone)
B(-3,-5,-4,minecraft:stone)
B(-3,-5,-3,minecraft:stone)
B(-3,-5,-2,minecraft:stone)
B(-3,-5,-1,minecraft:stone)
B(-3,-5,0,minecraft:stone)
B(-3,-5,1,minecraft:stone)
B(-3,-5,2,minecraft:stone)
B(-3,-5,3,minecraft:stone)
B(-3,-5,4,minecraft:stone)
B(-3,-5,5,minecraft:stone)
B(-3,-5,6,minecraft:stone)
B(-3,-5,7,minecraft:stone)
B(-3,-4,-9,minecraft:stone)
B(-3,-4,-8,minecraft:stone)
B(-3,-4,-7,minecraft:stone)
B(-3,-4,-6,minecraft:stone)
B(-3,-4,-5,minecraft:stone)
B(-3,-4,-4,minecraft:stone)
B(-3,-4,-3,minecraft:stone)
B(-3,-4,-2,minecraft:stone)
B(-3,-4,-1,minecraft:stone)
B(-3,-4,0,minecraft:stone)
B(-3,-4,1,minecraft:stone)
B(-3,-4,2,minecraft:stone)
B(-3,-4,3,minecraft:stone)
B(-3,-4,4,minecraft:stone)
B(-3,-4,5,minecraft:stone)
B(-3,-4,6,minecraft:stone)
B(-3,-4,7,minecraft:stone)
B(-3,-3,-9,minecraft:stone)
B(-3,-3,-8,minecraft:stone)
B(-3,-3,-7,minecraft:stone)
B(-3,-3,-6,minecraft:stone)
B(-3,-3,-5,minecraft:stone)
B(-3,-3,-4,minecraft:stone)
B(-3,-3,-3,minecraft:stone)
B(-3,-3,-2,minecraft:stone)
B(-3,-3,-1,minecraft:stone)
B(-3,-3,0,minecraft:stone)
B(-3,-3,1,minecraft:stone)
B(-3,-3,2,minecraft:stone)
B(-3,-3,3,minecraft:stone)
B(-3,-3,4,minecraft:stone)
B(-3,-3,5,minecraft:stone)
B(-3,-3,6,minecraft:stone)
B(-3,-3,7,minecraft:stone)
B(-3,-2,-9,minecraft:stone)
B(-3,-2,-8,minecraft:stone)
B(-3,-2,-7,minecraft:stone)
B(-3,-2,-6,minecraft:stone)
B(-3,-2,-5,minecraft:stone)
B(-3,-2,-4,minecraft:stone)
B(-3,-2,-3,minecraft:stone)
B(-3,-2,-2,minecraft:stone)
B(-3,-2,-1,minecraft:stone)
B(-3,-2,0,minecraft:stone)
B(-3,-2,1,minecraft:stone)
B(-3,-2,2,minecraft:stone)
B(-3,-2,3,minecraft:stone)
B(-3,-2,4,minecraft:stone)
B(-3,-2,5,minecraft:stone)
B(-3,-2,6,minecraft:stone)
B(-3,-2,7,minecraft:stone)
B(-3,-1,-9,minecraft:stone)
B(-3,-1,-8,minecraft:stone)
B(-3,-1,-7,minecraft:stone)
B(-3,-1,-6,minecraft:stone)
B(-3,-1,-5,minecraft:stone)
B(-3,-1,-4,minecraft:stone)
B(-3,-1,-3,minecraft:stone)
B(-3,-1,-2,minecraft:stone)
B(-3,-1,-1,minecraft:stone)
B(-3,-1,0,minecraft:stone)
B(-3,-1,1,minecraft:stone)
B(-3,-1,2,minecraft:stone)
B(-3,-1,3,minecraft:stone)
B(-3,-1,4,minecraft:stone)
B(-3,-1,5,minecraft:stone)
B(-3,-1,6,minecraft:stone)
B(-3,-1,7,minecraft:stone)
B(-3,0,-9,minecraft:stone)
B(-3,0,-8,minecraft:stone)
B(-3,0,-7,minecraft:stone)
B(-3,0,-6,minecraft:stone)
B(-3,0,-5,minecraft:stone)
B(-3,0,-4,minecraft:stone)
B(-3,0,-3,minecraft:stone)
B(-3,0,-2,minecraft:stone)
B(-3,0,-1,minecraft:stone)
B(-3,0,0,minecraft:stone)
B(-3,0,1,minecraft:stone)
B(-3,0,2,minecraft:stone)
B(-3,0,3,minecraft:stone)
B(-3,0,4,minecraft:stone)
B(-3,0,5,minecraft:stone)
B(-3,0,6,minecraft:stone)
B(-3,1,-8,minecraft:stone)
B(-3,1,-7,minecraft:stone)
B(-3,1,-6,minecraft:stone)
B(-3,1,-5,minecraft:stone)
B(-3,1,-4,minecraft:stone)
B(-3,1,-3,minecraft:stone)
B(-3,1,-2,minecraft:stone)
B(-3,1,-1,minecraft:stone)
B(-3,1,0,minecraft:stone)
B(-3,1,1,minecraft:stone)
B(-3,1,2,minecraft:stone)
B(-3,1,3,minecraft:stone)
B(-3,1,4,minecraft:stone)
B(-3,1,5,minecraft:stone)
B(-3,1,6,minecraft:stone)
B(-3,2,-8,minecraft:stone)
B(-3,2,-7,minecraft:stone)
B(-3,2,-6,minecraft:stone)
B(-3,2,-5,minecraft:stone)
B(-3,2,-4,minecraft:stone)
B(-3,2,-3,minecraft:stone)
B(-3,2,-2,minecraft:stone)
B(-3,2,-1,minecraft:stone)
B(-3,2,0,minecraft:stone)
B(-3,2,1,minecraft:stone)
B(-3,2,2,minecraft:stone)
B(-3,2,3,minecraft:stone)
B(-3,2,4,minecraft:stone)
B(-3,2,5,minecraft:stone)
B(-3,2,6,minecraft:stone)
B(-3,3,-7,minecraft:stone)
B(-3,3,-6,minecraft:stone)
B(-3,3,-5,minecraft:stone)
B(-3,3,-4,minecraft:stone)
B(-3,3,-3,minecraft:stone)
B(-3,3,-2,minecraft:stone)
B(-3,3,-1,minecraft:stone)
B(-3,3,0,minecraft:stone)
B(-3,3,1,minecraft:stone)
B(-3,3,2,minecraft:stone)
B(-3,3,3,minecraft:stone)
B(-3,3,4,minecraft:stone)
B(-3,3,5,minecraft:stone)
B(-3,4,-6,minecraft:stone)
B(-3,4,-5,minecraft:stone)
B(-3,4,-4,minecraft:stone)
B(-3,4,-3,minecraft:stone)
B(-3,4,-2,minecraft:stone)
B(-3,4,-1,minecraft:stone)
B(-3,4,0,minecraft:stone)
B(-3,4,1,minecraft:stone)
B(-3,4,2,minecraft:stone)
B(-3,4,3,minecraft:stone)
B(-3,4,4,minecraft:stone)
B(-3,5,-6,minecraft:stone)
B(-3,5,-5,minecraft:stone)
B(-3,5,-4,minecraft:stone)
B(-3,5,-3,minecraft:stone)
B(-3,5,-2,minecraft:stone)
B(-3,5,-1,minecraft:stone)
B(-3,5,0,minecraft:stone)
B(-3,5,1,minecraft:stone)
B(-3,5,2,minecraft:stone)
B(-3,5,3,minecraft:stone)
B(-3,5,4,minecraft:stone)
B(-3,6,-5,minecraft:stone)
B(-3,6,-4,minecraft:stone)
B(-3,6,-3,minecraft:stone)
B(-3,6,-2,minecraft:stone)
B(-3,6,-1,minecraft:stone)
B(-3,6,0,minecraft:stone)
B(-3,6,1,minecraft:stone)
B(-3,6,2,minecraft:stone)
B(-3,6,3,minecraft:stone)
B(-2,-10,0,minecraft:stone)
B(-2,-10,1,minecraft:stone)
B(-2,-10,2,minecraft:stone)
B(-2,-10,3,minecraft:stone)
B(-2,-10,4,minecraft:stone)
B(-2,-9,-3,minecraft:stone)
B(-2,-9,-2,minecraft:stone)
B(-2,-9,-1,minecraft:stone)
B(-2,-9,0,minecraft:stone)
B(-2,-9,1,minecraft:stone)
B(-2,-9,2,minecraft:stone)
B(-2,-9,3,minecraft:stone)
B(-2,-9,4,minecraft:stone)
B(-2,-9,5,minecraft:stone)
B(-2,-8,-8,minecraft:stone)
B(-2,-8,-7,minecraft:stone)
B(-2,-8,-6,minecraft:stone)
B(-2,-8,-5,minecraft:stone)
B(-2,-8,-4,minecraft:stone)
B(-2,-8,-3,minecraft:stone)
B(-2,-8,-2,minecraft:stone)
B(-2,-8,-1,minecraft:stone)
B(-2,-8,0,minecraft:stone)
B(-2,-8,1,minecraft:stone)
B(-2,-8,2,minecraft:stone)
B(-2,-8,3,minecraft:stone)
B(-2,-8,4,minecraft:stone)
B(-2,-8,5,minecraft:stone)
B(-2,-8,6,minecraft:stone)
B(-2,-7,-10,minecraft:stone)
B(-2,-7,-9,minecraft:stone)
B(-2,-7,-8,minecraft:stone)
B(-2,-7,-7,minecraft:stone)
B(-2,-7,-6,minecraft:stone)
B(-2,-7,-5,minecraft:stone)
B(-2,-7,-4,minecraft:stone)
B(-2,-7,-3,minecraft:stone)
B(-2,-7,-2,minecraft:stone)
B(-2,-7,-1,minecraft:stone)
B(-2,-7,0,minecraft:stone)
B(-2,-7,1,minecraft:stone)
B(-2,-7,2,minecraft:stone)
B(-2,-7,3,minecraft:stone)
B(-2,-7,4,minecraft:stone)
B(-2,-7,5,minecraft:stone)
B(-2,-7,6,minecraft:stone)
B(-2,-6,-9,minecraft:stone)
B(-2,-6,-8,minecraft:stone)
B(-2,-6,-7,minecraft:stone)
B(-2,-6,-6,minecraft:stone)
B(-2,-6,-5,minecraft:stone)
B(-2,-6,-4,minecraft:stone)
B(-2,-6,-3,minecraft:stone)
B(-2,-6,-2,minecraft:stone)
B(-2,-6,-1,minecraft:stone)
B(-2,-6,0,minecraft:stone)
B(-2,-6,1,minecraft:stone)
B(-2,-6,2,minecraft:stone)
B(-2,-6,3,minecraft:stone)
B(-2,-6,4,minecraft:stone)
B(-2,-6,5,minecraft:stone)
B(-2,-6,6,minecraft:stone)
B(-2,-6,7,minecraft:stone)
B(-2,-5,-9,minecraft:stone)
B(-2,-5,-8,minecraft:stone)
B(-2,-5,-7,minecraft:stone)
B(-2,-5,-6,minecraft:stone)
B(-2,-5,-5,minecraft:stone)
B(-2,-5,-4,minecraft:stone)
B(-2,-5,-3,minecraft:stone)
B(-2,-5,-2,minecraft:stone)
B(-2,-5,-1,minecraft:stone)
B(-2,-5,0,minecraft:stone)
B(-2,-5,1,minecraft:stone)
B(-2,-5,2,minecraft:stone)
B(-2,-5,3,minecraft:stone)
B(-2,-5,4,minecraft:stone)
B(-2,-5,5,minecraft:stone)
B(-2,-5,6,minecraft:stone)
B(-2,-5,7,minecraft:stone)
B(-2,-4,-9,minecraft:stone)
B(-2,-4,-8,minecraft:stone)
B(-2,-4,-7,minecraft:stone)
B(-2,-4,-6,minecraft:stone)
B(-2,-4,-5,minecraft:stone)
B(-2,-4,-4,minecraft:stone)
B(-2,-4,-3,minecraft:stone)
B(-2,-4,-2,minecraft:stone)
B(-2,-4,-1,minecraft:stone)
B(-2,-4,0,minecraft:stone)
B(-2,-4,1,minecraft:stone)
B(-2,-4,2,minecraft:stone)
B(-2,-4,3,minecraft:stone)
B(-2,-4,4,minecraft:stone)
B(-2,-4,5,minecraft:stone)
B(-2,-4,6,minecraft:stone)
B(-2,-4,7,minecraft:stone)
B(-2,-3,-9,minecraft:stone)
B(-2,-3,-8,minecraft:stone)
B(-2,-3,-7,minecraft:stone)
B(-2,-3,-6,minecraft:stone)
B(-2,-3,-5,minecraft:stone)
B(-2,-3,-4,minecraft:stone)
B(-2,-3,-3,minecraft:stone)
B(-2,-3,-2,minecraft:stone)
B(-2,-3,-1,minecraft:stone)
B(-2,-3,0,minecraft:stone)
B(-2,-3,1,minecraft:stone)
B(-2,-3,2,minecraft:stone)
B(-2,-3,3,minecraft:stone)
B(-2,-3,4,minecraft:stone)
B(-2,-3,5,minecraft:stone)
B(-2,-3,6,minecraft:stone)
B(-2,-3,7,minecraft:stone)
B(-2,-2,-9,minecraft:stone)
B(-2,-2,-8,minecraft:stone)
B(-2,-2,-7,minecraft:stone)
B(-2,-2,-6,minecraft:stone)
B(-2,-2,-5,minecraft:stone)
B(-2,-2,-4,minecraft:stone)
B(-2,-2,-3,minecraft:stone)
B(-2,-2,-2,minecraft:stone)
B(-2,-2,-1,minecraft:stone)
B(-2,-2,0,minecraft:stone)
B(-2,-2,1,minecraft:stone)
B(-2,-2,2,minecraft:stone)
B(-2,-2,3,minecraft:stone)
B(-2,-2,4,minecraft:stone)
B(-2,-2,5,minecraft:stone)
B(-2,-2,6,minecraft:stone)
B(-2,-2,7,minecraft:stone)
B(-2,-1,-9,minecraft:stone)
B(-2,-1,-8,minecraft:stone)
B(-2,-1,-7,minecraft:stone)
B(-2,-1,-6,minecraft:stone)
B(-2,-1,-5,minecraft:stone)
B(-2,-1,-4,minecraft:stone)
B(-2,-1,-3,minecraft:stone)
B(-2,-1,-2,minecraft:stone)
B(-2,-1,-1,minecraft:stone)
B(-2,-1,0,minecraft:stone)
B(-2,-1,1,minecraft:stone)
B(-2,-1,2,minecraft:stone)
B(-2,-1,3,minecraft:stone)
B(-2,-1,4,minecraft:stone)
B(-2,-1,5,minecraft:stone)
B(-2,-1,6,minecraft:stone)
B(-2,-1,7,minecraft:stone)
B(-2,0,-9,minecraft:stone)
B(-2,0,-8,minecraft:stone)
B(-2,0,-7,minecraft:stone)
B(-2,0,-6,minecraft:stone)
B(-2,0,-5,minecraft:stone)
B(-2,0,-4,minecraft:stone)
B(-2,0,-3,minecraft:stone)
B(-2,0,-2,minecraft:stone)
B(-2,0,-1,minecraft:stone)
B(-2,0,0,minecraft:stone)
B(-2,0,1,minecraft:stone)
B(-2,0,2,minecraft:stone)
B(-2,0,3,minecraft:stone)
B(-2,0,4,minecraft:stone)
B(-2,0,5,minecraft:stone)
B(-2,0,6,minecraft:stone)
B(-2,1,-9,minecraft:stone)
B(-2,1,-8,minecraft:stone)
B(-2,1,-7,minecraft:stone)
B(-2,1,-6,minecraft:stone)
B(-2,1,-5,minecraft:stone)
B(-2,1,-4,minecraft:stone)
B(-2,1,-3,minecraft:stone)
B(-2,1,-2,minecraft:stone)
B(-2,1,-1,minecraft:stone)
B(-2,1,0,minecraft:stone)
B(-2,1,1,minecraft:stone)
B(-2,1,2,minecraft:stone)
B(-2,1,3,minecraft:stone)
B(-2,1,4,minecraft:stone)
B(-2,1,5,minecraft:stone)
B(-2,1,6,minecraft:stone)
B(-2,2,-8,minecraft:stone)
B(-2,2,-7,minecraft:stone)
B(-2,2,-6,minecraft:stone)
B(-2,2,-5,minecraft:stone)
B(-2,2,-4,minecraft:stone)
B(-2,2,-3,minecraft:stone)
B(-2,2,-2,minecraft:stone)
B(-2,2,-1,minecraft:stone)
B(-2,2,0,minecraft:stone)
B(-2,2,1,minecraft:stone)
B(-2,2,2,minecraft:stone)
B(-2,2,3,minecraft:stone)
B(-2,2,4,minecraft:stone)
B(-2,2,5,minecraft:stone)
B(-2,2,6,minecraft:stone)
B(-2,3,-7,minecraft:stone)
B(-2,3,-6,minecraft:stone)
B(-2,3,-5,minecraft:stone)
B(-2,3,-4,minecraft:stone)
B(-2,3,-3,minecraft:stone)
B(-2,3,-2,minecraft:stone)
B(-2,3,-1,minecraft:stone)
B(-2,3,0,minecraft:stone)
B(-2,3,1,minecraft:stone)
B(-2,3,2,minecraft:stone)
B(-2,3,3,minecraft:stone)
B(-2,3,4,minecraft:stone)
B(-2,3,5,minecraft:stone)
B(-2,4,-7,minecraft:stone)
B(-2,4,-6,minecraft:stone)
B(-2,4,-5,minecraft:stone)
B(-2,4,-4,minecraft:stone)
B(-2,4,-3,minecraft:stone)
B(-2,4,-2,minecraft:stone)
B(-2,4,-1,minecraft:stone)
B(-2,4,0,minecraft:stone)
B(-2,4,1,minecraft:stone)
B(-2,4,2,minecraft:stone)
B(-2,4,3,minecraft:stone)
B(-2,4,4,minecraft:stone)
B(-2,5,-6,minecraft:stone)
B(-2,5,-5,minecraft:stone)
B(-2,5,-4,minecraft:stone)
B(-2,5,-3,minecraft:stone)
B(-2,5,-2,minecraft:stone)
B(-2,5,-1,minecraft:stone)
B(-2,5,0,minecraft:stone)
B(-2,5,1,minecraft:stone)
B(-2,5,2,minecraft:stone)
B(-2,5,3,minecraft:stone)
B(-2,5,4,minecraft:stone)
B(-2,6,-5,minecraft:stone)
B(-2,6,-4,minecraft:stone)
B(-2,6,-3,minecraft:stone)
B(-2,6,-2,minecraft:stone)
B(-2,6,-1,minecraft:stone)
B(-2,6,0,minecraft:stone)
B(-2,6,1,minecraft:stone)
B(-2,6,2,minecraft:stone)
B(-2,6,3,minecraft:stone)
B(-2,7,-4,minecraft:stone)
B(-2,7,-3,minecraft:stone)
B(-1,-10,1,minecraft:stone)
B(-1,-10,2,minecraft:stone)
B(-1,-10,3,minecraft:stone)
B(-1,-10,4,minecraft:stone)
B(-1,-10,5,minecraft:stone)
B(-1,-9,-2,minecraft:stone)
B(-1,-9,-1,minecraft:stone)
B(-1,-9,0,minecraft:stone)
B(-1,-9,1,minecraft:stone)
B(-1,-9,2,minecraft:stone)
B(-1,-9,3,minecraft:stone)
B(-1,-9,4,minecraft:stone)
B(-1,-9,5,minecraft:stone)
B(-1,-9,6,minecraft:stone)
B(-1,-8,-8,minecraft:stone)
B(-1,-8,-7,minecraft:stone)
B(-1,-8,-6,minecraft:stone)
B(-1,-8,-5,minecraft:stone)
B(-1,-8,-4,minecraft:stone)
B(-1,-8,-3,minecraft:stone)
B(-1,-8,-2,minecraft:stone)
B(-1,-8,-1,minecraft:stone)
B(-1,-8,0,minecraft:stone)
B(-1,-8,1,minecraft:stone)
B(-1,-8,2,minecraft:stone)
B(-1,-8,3,minecraft:stone)
B(-1,-8,4,minecraft:stone)
B(-1,-8,5,minecraft:stone)
B(-1,-8,6,minecraft:stone)
B(-1,-7,-9,minecraft:stone)
B(-1,-7,-8,minecraft:stone)
B(-1,-7,-7,minecraft:stone)
B(-1,-7,-6,minecraft:stone)
B(-1,-7,-5,minecraft:stone)
B(-1,-7,-4,minecraft:stone)
B(-1,-7,-3,minecraft:stone)
B(-1,-7,-2,minecraft:stone)
B(-1,-7,-1,minecraft:stone)
B(-1,-7,0,minecraft:stone)
B(-1,-7,1,minecraft:stone)
B(-1,-7,2,minecraft:stone)
B(-1,-7,3,minecraft:stone)
B(-1,-7,4,minecraft:stone)
B(-1,-7,5,minecraft:stone)
B(-1,-7,6,minecraft:stone)
B(-1,-7,7,minecraft:stone)
B(-1,-6,-9,minecraft:stone)
B(-1,-6,-8,minecraft:stone)
B(-1,-6,-7,minecraft:stone)
B(-1,-6,-6,minecraft:stone)
B(-1,-6,-5,minecraft:stone)
B(-1,-6,-4,minecraft:stone)
B(-1,-6,-3,minecraft:stone)
B(-1,-6,-2,minecraft:stone)
B(-1,-6,-1,minecraft:stone)
B(-1,-6,0,minecraft:stone)
B(-1,-6,1,minecraft:stone)
B(-1,-6,2,minecraft:stone)
B(-1,-6,3,minecraft:stone)
B(-1,-6,4,minecraft:stone)
B(-1,-6,5,minecraft:stone)
B(-1,-6,6,minecraft:stone)
B(-1,-6,7,minecraft:stone)
B(-1,-5,-9,minecraft:stone)
B(-1,-5,-8,minecraft:stone)
B(-1,-5,-7,minecraft:stone)
B(-1,-5,-6,minecraft:stone)
B(-1,-5,-5,minecraft:stone)
B(-1,-5,-4,minecraft:stone)
B(-1,-5,-3,minecraft:stone)
B(-1,-5,-2,minecraft:stone)
B(-1,-5,-1,minecraft:stone)
B(-1,-5,0,minecraft:stone)
B(-1,-5,1,minecraft:stone)
B(-1,-5,2,minecraft:stone)
B(-1,-5,3,minecraft:stone)
B(-1,-5,4,minecraft:stone)
B(-1,-5,5,minecraft:stone)
B(-1,-5,6,minecraft:stone)
B(-1,-5,7,minecraft:stone)
B(-1,-4,-9,minecraft:stone)
B(-1,-4,-8,minecraft:stone)
B(-1,-4,-7,minecraft:stone)
B(-1,-4,-6,minecraft:stone)
B(-1,-4,-5,minecraft:stone)
B(-1,-4,-4,minecraft:stone)
B(-1,-4,-3,minecraft:stone)
B(-1,-4,-2,minecraft:stone)
B(-1,-4,-1,minecraft:stone)
B(-1,-4,0,minecraft:stone)
B(-1,-4,1,minecraft:stone)
B(-1,-4,2,minecraft:stone)
B(-1,-4,3,minecraft:stone)
B(-1,-4,4,minecraft:stone)
B(-1,-4,5,minecraft:stone)
B(-1,-4,6,minecraft:stone)
B(-1,-4,7,minecraft:stone)
B(-1,-3,-9,minecraft:stone)
B(-1,-3,-8,minecraft:stone)
B(-1,-3,-7,minecraft:stone)
B(-1,-3,-6,minecraft:stone)
B(-1,-3,-5,minecraft:stone)
B(-1,-3,-4,minecraft:stone)
B(-1,-3,-3,minecraft:stone)
B(-1,-3,-2,minecraft:stone)
B(-1,-3,-1,minecraft:stone)
B(-1,-3,0,minecraft:stone)
B(-1,-3,1,minecraft:stone)
B(-1,-3,2,minecraft:stone)
B(-1,-3,3,minecraft:stone)
B(-1,-3,4,minecraft:stone)
B(-1,-3,5,minecraft:stone)
B(-1,-3,6,minecraft:stone)
B(-1,-3,7,minecraft:stone)
B(-1,-2,-9,minecraft:stone)
B(-1,-2,-8,minecraft:stone)
B(-1,-2,-7,minecraft:stone)
B(-1,-2,-6,minecraft:stone)
B(-1,-2,-5,minecraft:stone)
B(-1,-2,-4,minecraft:stone)
B(-1,-2,-3,minecraft:stone)
B(-1,-2,-2,minecraft:stone)
B(-1,-2,-1,minecraft:stone)
B(-1,-2,0,minecraft:stone)
B(-1,-2,1,minecraft:stone)
B(-1,-2,2,minecraft:stone)
B(-1,-2,3,minecraft:stone)
B(-1,-2,4,minecraft:stone)
B(-1,-2,5,minecraft:stone)
B(-1,-2,6,minecraft:stone)
B(-1,-2,7,minecraft:stone)
B(-1,-1,-9,minecraft:stone)
B(-1,-1,-8,minecraft:stone)
B(-1,-1,-7,minecraft:stone)
B(-1,-1,-6,minecraft:stone)
B(-1,-1,-5,minecraft:stone)
B(-1,-1,-4,minecraft:stone)
B(-1,-1,-3,minecraft:stone)
B(-1,-1,-2,minecraft:stone)
B(-1,-1,-1,minecraft:stone)
B(-1,-1,0,minecraft:stone)
B(-1,-1,1,minecraft:stone)
B(-1,-1,2,minecraft:stone)
B(-1,-1,3,minecraft:stone)
B(-1,-1,4,minecraft:stone)
B(-1,-1,5,minecraft:stone)
B(-1,-1,6,minecraft:stone)
B(-1,-1,7,minecraft:stone)
B(-1,0,-9,minecraft:stone)
B(-1,0,-8,minecraft:stone)
B(-1,0,-7,minecraft:stone)
B(-1,0,-6,minecraft:stone)
B(-1,0,-5,minecraft:stone)
B(-1,0,-4,minecraft:stone)
B(-1,0,-3,minecraft:stone)
B(-1,0,-2,minecraft:stone)
B(-1,0,-1,minecraft:stone)
B(-1,0,0,minecraft:stone)
B(-1,0,1,minecraft:stone)
B(-1,0,2,minecraft:stone)
B(-1,0,3,minecraft:stone)
B(-1,0,4,minecraft:stone)
B(-1,0,5,minecraft:stone)
B(-1,0,6,minecraft:stone)
B(-1,1,-9,minecraft:stone)
B(-1,1,-8,minecraft:stone)
B(-1,1,-7,minecraft:stone)
B(-1,1,-6,minecraft:stone)
B(-1,1,-5,minecraft:stone)
B(-1,1,-4,minecraft:stone)
B(-1,1,-3,minecraft:stone)
B(-1,1,-2,minecraft:stone)
B(-1,1,-1,minecraft:stone)
B(-1,1,0,minecraft:stone)
B(-1,1,1,minecraft:stone)
B(-1,1,2,minecraft:stone)
B(-1,1,3,minecraft:stone)
B(-1,1,4,minecraft:stone)
B(-1,1,5,minecraft:stone)
B(-1,1,6,minecraft:stone)
B(-1,2,-8,minecraft:stone)
B(-1,2,-7,minecraft:stone)
B(-1,2,-6,minecraft:stone)
B(-1,2,-5,minecraft:stone)
B(-1,2,-4,minecraft:stone)
B(-1,2,-3,minecraft:stone)
B(-1,2,-2,minecraft:stone)
B(-1,2,-1,minecraft:stone)
B(-1,2,0,minecraft:stone)
B(-1,2,1,minecraft:stone)
B(-1,2,2,minecraft:stone)
B(-1,2,3,minecraft:stone)
B(-1,2,4,minecraft:stone)
B(-1,2,5,minecraft:stone)
B(-1,2,6,minecraft:stone)
B(-1,3,-8,minecraft:stone)
B(-1,3,-7,minecraft:stone)
B(-1,3,-6,minecraft:stone)
B(-1,3,-5,minecraft:stone)
B(-1,3,-4,minecraft:stone)
B(-1,3,-3,minecraft:stone)
B(-1,3,-2,minecraft:stone)
B(-1,3,-1,minecraft:stone)
B(-1,3,0,minecraft:stone)
B(-1,3,1,minecraft:stone)
B(-1,3,2,minecraft:stone)
B(-1,3,3,minecraft:stone)
B(-1,3,4,minecraft:stone)
B(-1,3,5,minecraft:stone)
B(-1,4,-7,minecraft:stone)
B(-1,4,-6,minecraft:stone)
B(-1,4,-5,minecraft:stone)
B(-1,4,-4,minecraft:stone)
B(-1,4,-3,minecraft:stone)
B(-1,4,-2,minecraft:stone)
B(-1,4,-1,minecraft:stone)
B(-1,4,0,minecraft:stone)
B(-1,4,1,minecraft:stone)
B(-1,4,2,minecraft:stone)
B(-1,4,3,minecraft:stone)
B(-1,4,4,minecraft:stone)
B(-1,4,5,minecraft:stone)
B(-1,5,-6,minecraft:stone)
B(-1,5,-5,minecraft:stone)
B(-1,5,-4,minecraft:stone)
B(-1,5,-3,minecraft:stone)
B(-1,5,-2,minecraft:stone)
B(-1,5,-1,minecraft:stone)
B(-1,5,0,minecraft:stone)
B(-1,5,1,minecraft:stone)
B(-1,5,2,minecraft:stone)
B(-1,5,3,minecraft:stone)
B(-1,5,4,minecraft:stone)
B(-1,6,-5,minecraft:stone)
B(-1,6,-4,minecraft:stone)
B(-1,6,-3,minecraft:stone)
B(-1,6,-2,minecraft:stone)
B(-1,6,-1,minecraft:stone)
B(-1,6,0,minecraft:stone)
B(-1,6,1,minecraft:stone)
B(-1,6,2,minecraft:stone)
B(-1,6,3,minecraft:stone)
B(-1,7,-5,minecraft:stone)
B(-1,7,-4,minecraft:stone)
B(-1,7,-3,minecraft:stone)
B(-1,7,-2,minecraft:stone)
B(-1,7,-1,minecraft:stone)
B(-1,7,0,minecraft:stone)
B(-1,7,1,minecraft:stone)
B(-1,7,2,minecraft:stone)
B(0,-10,1,minecraft:stone)
B(0,-10,2,minecraft:stone)
B(0,-10,3,minecraft:stone)
B(0,-10,4,minecraft:stone)
B(0,-10,5,minecraft:stone)
B(0,-9,-2,minecraft:stone)
B(0,-9,-1,minecraft:stone)
B(0,-9,0,minecraft:stone)
B(0,-9,1,minecraft:stone)
B(0,-9,2,minecraft:stone)
B(0,-9,3,minecraft:stone)
B(0,-9,4,minecraft:stone)
B(0,-9,5,minecraft:stone)
B(0,-9,6,minecraft:stone)
B(0,-8,-6,minecraft:stone)
B(0,-8,-5,minecraft:stone)
B(0,-8,-4,minecraft:stone)
B(0,-8,-3,minecraft:stone)
B(0,-8,-2,minecraft:stone)
B(0,-8,-1,minecraft:stone)
B(0,-8,0,minecraft:stone)
B(0,-8,1,minecraft:stone)
B(0,-8,2,minecraft:stone)
B(0,-8,3,minecraft:stone)
B(0,-8,4,minecraft:stone)
B(0,-8,5,minecraft:stone)
B(0,-8,6,minecraft:stone)
B(0,-8,7,minecraft:stone)
B(0,-7,-9,minecraft:stone)
B(0,-7,-8,minecraft:stone)
B(0,-7,-7,minecraft:stone)
B(0,-7,-6,minecraft:stone)
B(0,-7,-5,minecraft:stone)
B(0,-7,-4,minecraft:stone)
B(0,-7,-3,minecraft:stone)
B(0,-7,-2,minecraft:stone)
B(0,-7,-1,minecraft:stone)
B(0,-7,0,minecraft:stone)
B(0,-7,1,minecraft:stone)
B(0,-7,2,minecraft:stone)
B(0,-7,3,minecraft:stone)
B(0,-7,4,minecraft:stone)
B(0,-7,5,minecraft:stone)
B(0,-7,6,minecraft:stone)
B(0,-7,7,minecraft:stone)
B(0,-7,8,minecraft:stone)
B(0,-6,-9,minecraft:stone)
B(0,-6,-8,minecraft:stone)
B(0,-6,-7,minecraft:stone)
B(0,-6,-6,minecraft:stone)
B(0,-6,-5,minecraft:stone)
B(0,-6,-4,minecraft:stone)
B(0,-6,-3,minecraft:stone)
B(0,-6,-2,minecraft:stone)
B(0,-6,-1,minecraft:stone)
B(0,-6,0,minecraft:stone)
B(0,-6,1,minecraft:stone)
B(0,-6,2,minecraft:stone)
B(0,-6,3,minecraft:stone)
B(0,-6,4,minecraft:stone)
B(0,-6,5,minecraft:stone)
B(0,-6,6,minecraft:stone)
B(0,-6,7,minecraft:stone)
B(0,-5,-9,minecraft:stone)
B(0,-5,-8,minecraft:stone)
B(0,-5,-7,minecraft:stone)
B(0,-5,-6,minecraft:stone)
B(0,-5,-5,minecraft:stone)
B(0,-5,-4,minecraft:stone)
B(0,-5,-3,minecraft:stone)
B(0,-5,-2,minecraft:stone)
B(0,-5,-1,minecraft:stone)
B(0,-5,0,minecraft:stone)
B(0,-5,1,minecraft:stone)
B(0,-5,2,minecraft:stone)
B(0,-5,3,minecraft:stone)
B(0,-5,4,minecraft:stone)
B(0,-5,5,minecraft:stone)
B(0,-5,6,minecraft:stone)
B(0,-5,7,minecraft:stone)
B(0,-4,-9,minecraft:stone)
B(0,-4,-8,minecraft:stone)
B(0,-4,-7,minecraft:stone)
B(0,-4,-6,minecraft:stone)
B(0,-4,-5,minecraft:stone)
B(0,-4,-4,minecraft:stone)
B(0,-4,-3,minecraft:stone)
B(0,-4,-2,minecraft:stone)
B(0,-4,-1,minecraft:stone)
B(0,-4,0,minecraft:stone)
B(0,-4,1,minecraft:stone)
B(0,-4,2,minecraft:stone)
B(0,-4,3,minecraft:stone)
B(0,-4,4,minecraft:stone)
B(0,-4,5,minecraft:stone)
B(0,-4,6,minecraft:stone)
B(0,-4,7,minecraft:stone)
B(0,-4,8,minecraft:stone)
B(0,-3,-9,minecraft:stone)
B(0,-3,-8,minecraft:stone)
B(0,-3,-7,minecraft:stone)
B(0,-3,-6,minecraft:stone)
B(0,-3,-5,minecraft:stone)
B(0,-3,-4,minecraft:stone)
B(0,-3,-3,minecraft:stone)
B(0,-3,-2,minecraft:stone)
B(0,-3,-1,minecraft:stone)
B(0,-3,0,minecraft:stone)
B(0,-3,1,minecraft:stone)
B(0,-3,2,minecraft:stone)
B(0,-3,3,minecraft:stone)
B(0,-3,4,minecraft:stone)
B(0,-3,5,minecraft:stone)
B(0,-3,6,minecraft:stone)
B(0,-3,7,minecraft:stone)
B(0,-3,8,minecraft:stone)
B(0,-2,-9,minecraft:stone)
B(0,-2,-8,minecraft:stone)
B(0,-2,-7,minecraft:stone)
B(0,-2,-6,minecraft:stone)
B(0,-2,-5,minecraft:stone)
B(0,-2,-4,minecraft:stone)
B(0,-2,-3,minecraft:stone)
B(0,-2,-2,minecraft:stone)
B(0,-2,-1,minecraft:stone)
B(0,-2,0,minecraft:stone)
B(0,-2,1,minecraft:stone)
B(0,-2,2,minecraft:stone)
B(0,-2,3,minecraft:stone)
B(0,-2,4,minecraft:stone)
B(0,-2,5,minecraft:stone)
B(0,-2,6,minecraft:stone)
B(0,-2,7,minecraft:stone)
B(0,-1,-9,minecraft:stone)
B(0,-1,-8,minecraft:stone)
B(0,-1,-7,minecraft:stone)
B(0,-1,-6,minecraft:stone)
B(0,-1,-5,minecraft:stone)
B(0,-1,-4,minecraft:stone)
B(0,-1,-3,minecraft:stone)
B(0,-1,-2,minecraft:stone)
B(0,-1,-1,minecraft:stone)
B(0,-1,0,minecraft:stone)
B(0,-1,1,minecraft:stone)
B(0,-1,2,minecraft:stone)
B(0,-1,3,minecraft:stone)
B(0,-1,4,minecraft:stone)
B(0,-1,5,minecraft:stone)
B(0,-1,6,minecraft:stone)
B(0,0,-8,minecraft:stone)
B(0,0,-7,minecraft:stone)
B(0,0,-6,minecraft:stone)
B(0,0,-5,minecraft:stone)
B(0,0,-4,minecraft:stone)
B(0,0,-3,minecraft:stone)
B(0,0,-2,minecraft:stone)
B(0,0,-1,minecraft:stone)
B(0,0,0,minecraft:stone)
B(0,0,1,minecraft:stone)
B(0,0,2,minecraft:stone)
B(0,0,3,minecraft:stone)
B(0,0,4,minecraft:stone)
B(0,0,5,minecraft:stone)
B(0,0,6,minecraft:stone)
B(0,1,-8,minecraft:stone)
B(0,1,-7,minecraft:stone)
B(0,1,-6,minecraft:stone)
B(0,1,-5,minecraft:stone)
B(0,1,-4,minecraft:stone)
B(0,1,-3,minecraft:stone)
B(0,1,-2,minecraft:stone)
B(0,1,-1,minecraft:stone)
B(0,1,0,minecraft:stone)
B(0,1,1,minecraft:stone)
B(0,1,2,minecraft:stone)
B(0,1,3,minecraft:stone)
B(0,1,4,minecraft:stone)
B(0,1,5,minecraft:stone)
B(0,1,6,minecraft:stone)
B(0,2,-8,minecraft:stone)
B(0,2,-7,minecraft:stone)
B(0,2,-6,minecraft:stone)
B(0,2,-5,minecraft:stone)
B(0,2,-4,minecraft:stone)
B(0,2,-3,minecraft:stone)
B(0,2,-2,minecraft:stone)
B(0,2,-1,minecraft:stone)
B(0,2,0,minecraft:stone)
B(0,2,1,minecraft:stone)
B(0,2,2,minecraft:stone)
B(0,2,3,minecraft:stone)
B(0,2,4,minecraft:stone)
B(0,2,5,minecraft:stone)
B(0,2,6,minecraft:stone)
B(0,3,-8,minecraft:stone)
B(0,3,-7,minecraft:stone)
B(0,3,-6,minecraft:stone)
B(0,3,-5,minecraft:stone)
B(0,3,-4,minecraft:stone)
B(0,3,-3,minecraft:stone)
B(0,3,-2,minecraft:stone)
B(0,3,-1,minecraft:stone)
B(0,3,0,minecraft:stone)
B(0,3,1,minecraft:stone)
B(0,3,2,minecraft:stone)
B(0,3,3,minecraft:stone)
B(0,3,4,minecraft:stone)
B(0,3,5,minecraft:stone)
B(0,4,-7,minecraft:stone)
B(0,4,-6,minecraft:stone)
B(0,4,-5,minecraft:stone)
B(0,4,-4,minecraft:stone)
B(0,4,-3,minecraft:stone)
B(0,4,-2,minecraft:stone)
B(0,4,-1,minecraft:stone)
B(0,4,0,minecraft:stone)
B(0,4,1,minecraft:stone)
B(0,4,2,minecraft:stone)
B(0,4,3,minecraft:stone)
B(0,4,4,minecraft:stone)
B(0,4,5,minecraft:stone)
B(0,5,-6,minecraft:stone)
B(0,5,-5,minecraft:stone)
B(0,5,-4,minecraft:stone)
B(0,5,-3,minecraft:stone)
B(0,5,-2,minecraft:stone)
B(0,5,-1,minecraft:stone)
B(0,5,0,minecraft:stone)
B(0,5,1,minecraft:stone)
B(0,5,2,minecraft:stone)
B(0,5,3,minecraft:stone)
B(0,5,4,minecraft:stone)
B(0,6,-6,minecraft:stone)
B(0,6,-5,minecraft:stone)
B(0,6,-4,minecraft:stone)
B(0,6,-3,minecraft:stone)
B(0,6,-2,minecraft:stone)
B(0,6,-1,minecraft:stone)
B(0,6,0,minecraft:stone)
B(0,6,1,minecraft:stone)
B(0,6,2,minecraft:stone)
B(0,6,3,minecraft:stone)
B(0,7,-5,minecraft:stone)
B(0,7,-4,minecraft:stone)
B(0,7,-3,minecraft:stone)
B(0,7,-2,minecraft:stone)
B(0,7,-1,minecraft:stone)
B(0,7,0,minecraft:stone)
B(0,7,1,minecraft:stone)
B(0,7,2,minecraft:stone)
B(1,-10,2,minecraft:stone)
B(1,-10,3,minecraft:stone)
B(1,-10,4,minecraft:stone)
B(1,-10,5,minecraft:stone)
B(1,-9,-2,minecraft:stone)
B(1,-9,-1,minecraft:stone)
B(1,-9,0,minecraft:stone)
B(1,-9,1,minecraft:stone)
B(1,-9,2,minecraft:stone)
B(1,-9,3,minecraft:stone)
B(1,-9,4,minecraft:stone)
B(1,-9,5,minecraft:stone)
B(1,-9,6,minecraft:stone)
B(1,-8,-6,minecraft:stone)
B(1,-8,-5,minecraft:stone)
B(1,-8,-4,minecraft:stone)
B(1,-8,-3,minecraft:stone)
B(1,-8,-2,minecraft:stone)
B(1,-8,-1,minecraft:stone)
B(1,-8,0,minecraft:stone)
B(1,-8,1,minecraft:stone)
B(1,-8,2,minecraft:stone)
B(1,-8,3,minecraft:stone)
B(1,-8,4,minecraft:stone)
B(1,-8,5,minecraft:stone)
B(1,-8,6,minecraft:stone)
B(1,-8,7,minecraft:stone)
B(1,-7,-9,minecraft:stone)
B(1,-7,-8,minecraft:stone)
B(1,-7,-7,minecraft:stone)
B(1,-7,-6,minecraft:stone)
B(1,-7,-5,minecraft:stone)
B(1,-7,-4,minecraft:stone)
B(1,-7,-3,minecraft:stone)
B(1,-7,-2,minecraft:stone)
B(1,-7,-1,minecraft:stone)
B(1,-7,0,minecraft:stone)
B(1,-7,1,minecraft:stone)
B(1,-7,2,minecraft:stone)
B(1,-7,3,minecraft:stone)
B(1,-7,4,minecraft:stone)
B(1,-7,5,minecraft:stone)
B(1,-7,6,minecraft:stone)
B(1,-7,7,minecraft:stone)
B(1,-7,8,minecraft:stone)
B(1,-6,-9,minecraft:stone)
B(1,-6,-8,minecraft:stone)
B(1,-6,-7,minecraft:stone)
B(1,-6,-6,minecraft:stone)
B(1,-6,-5,minecraft:stone)
B(1,-6,-4,minecraft:stone)
B(1,-6,-3,minecraft:stone)
B(1,-6,-2,minecraft:stone)
B(1,-6,-1,minecraft:stone)
B(1,-6,0,minecraft:stone)
B(1,-6,1,minecraft:stone)
B(1,-6,2,minecraft:stone)
B(1,-6,3,minecraft:stone)
B(1,-6,4,minecraft:stone)
B(1,-6,5,minecraft:stone)
B(1,-6,6,minecraft:stone)
B(1,-6,7,minecraft:stone)
B(1,-6,8,minecraft:stone)
B(1,-5,-9,minecraft:stone)
B(1,-5,-8,minecraft:stone)
B(1,-5,-7,minecraft:stone)
B(1,-5,-6,minecraft:stone)
B(1,-5,-5,minecraft:stone)
B(1,-5,-4,minecraft:stone)
B(1,-5,-3,minecraft:stone)
B(1,-5,-2,minecraft:stone)
B(1,-5,-1,minecraft:stone)
B(1,-5,0,minecraft:stone)
B(1,-5,1,minecraft:stone)
B(1,-5,2,minecraft:stone)
B(1,-5,3,minecraft:stone)
B(1,-5,4,minecraft:stone)
B(1,-5,5,minecraft:stone)
B(1,-5,6,minecraft:stone)
B(1,-5,7,minecraft:stone)
B(1,-5,8,minecraft:stone)
B(1,-4,-9,minecraft:stone)
B(1,-4,-8,minecraft:stone)
B(1,-4,-7,minecraft:stone)
B(1,-4,-6,minecraft:stone)
B(1,-4,-5,minecraft:stone)
B(1,-4,-4,minecraft:stone)
B(1,-4,-3,minecraft:stone)
B(1,-4,-2,minecraft:stone)
B(1,-4,-1,minecraft:stone)
B(1,-4,0,minecraft:stone)
B(1,-4,1,minecraft:stone)
B(1,-4,2,minecraft:stone)
B(1,-4,3,minecraft:stone)
B(1,-4,4,minecraft:stone)
B(1,-4,5,minecraft:stone)
B(1,-4,6,minecraft:stone)
B(1,-4,7,minecraft:stone)
B(1,-4,8,minecraft:stone)
B(1,-3,-9,minecraft:stone)
B(1,-3,-8,minecraft:stone)
B(1,-3,-7,minecraft:stone)
B(1,-3,-6,minecraft:stone)
B(1,-3,-5,minecraft:stone)
B(1,-3,-4,minecraft:stone)
B(1,-3,-3,minecraft:stone)
B(1,-3,-2,minecraft:stone)
B(1,-3,-1,minecraft:stone)
B(1,-3,0,minecraft:stone)
B(1,-3,1,minecraft:stone)
B(1,-3,2,minecraft:stone)
B(1,-3,3,minecraft:stone)
B(1,-3,4,minecraft:stone)
B(1,-3,5,minecraft:stone)
B(1,-3,6,minecraft:stone)
B(1,-3,7,minecraft:stone)
B(1,-3,8,minecraft:stone)
B(1,-2,-9,minecraft:stone)
B(1,-2,-8,minecraft:stone)
B(1,-2,-7,minecraft:stone)
B(1,-2,-6,minecraft:stone)
B(1,-2,-5,minecraft:stone)
B(1,-2,-4,minecraft:stone)
B(1,-2,-3,minecraft:stone)
B(1,-2,-2,minecraft:stone)
B(1,-2,-1,minecraft:stone)
B(1,-2,0,minecraft:stone)
B(1,-2,1,minecraft:stone)
B(1,-2,2,minecraft:stone)
B(1,-2,3,minecraft:stone)
B(1,-2,4,minecraft:stone)
B(1,-2,5,minecraft:stone)
B(1,-2,6,minecraft:stone)
B(1,-2,7,minecraft:stone)
B(1,-1,-8,minecraft:stone)
B(1,-1,-7,minecraft:stone)
B(1,-1,-6,minecraft:stone)
B(1,-1,-5,minecraft:stone)
B(1,-1,-4,minecraft:stone)
B(1,-1,-3,minecraft:stone)
B(1,-1,-2,minecraft:stone)
B(1,-1,-1,minecraft:stone)
B(1,-1,0,minecraft:stone)
B(1,-1,1,minecraft:stone)
B(1,-1,2,minecraft:stone)
B(1,-1,3,minecraft:stone)
B(1,-1,4,minecraft:stone)
B(1,-1,5,minecraft:stone)
B(1,-1,6,minecraft:stone)
B(1,0,-8,minecraft:stone)
B(1,0,-7,minecraft:stone)
B(1,0,-6,minecraft:stone)
B(1,0,-5,minecraft:stone)
B(1,0,-4,minecraft:stone)
B(1,0,-3,minecraft:stone)
B(1,0,-2,minecraft:stone)
B(1,0,-1,minecraft:stone)
B(1,0,0,minecraft:stone)
B(1,0,1,minecraft:stone)
B(1,0,2,minecraft:stone)
B(1,0,3,minecraft:stone)
B(1,0,4,minecraft:stone)
B(1,0,5,minecraft:stone)
B(1,0,6,minecraft:stone)
B(1,1,-8,minecraft:stone)
B(1,1,-7,minecraft:stone)
B(1,1,-6,minecraft:stone)
B(1,1,-5,minecraft:stone)
B(1,1,-4,minecraft:stone)
B(1,1,-3,minecraft:stone)
B(1,1,-2,minecraft:stone)
B(1,1,-1,minecraft:stone)
B(1,1,0,minecraft:stone)
B(1,1,1,minecraft:stone)
B(1,1,2,minecraft:stone)
B(1,1,3,minecraft:stone)
B(1,1,4,minecraft:stone)
B(1,1,5,minecraft:stone)
B(1,1,6,minecraft:stone)
B(1,2,-8,minecraft:stone)
B(1,2,-7,minecraft:stone)
B(1,2,-6,minecraft:stone)
B(1,2,-5,minecraft:stone)
B(1,2,-4,minecraft:stone)
B(1,2,-3,minecraft:stone)
B(1,2,-2,minecraft:stone)
B(1,2,-1,minecraft:stone)
B(1,2,0,minecraft:stone)
B(1,2,1,minecraft:stone)
B(1,2,2,minecraft:stone)
B(1,2,3,minecraft:stone)
B(1,2,4,minecraft:stone)
B(1,2,5,minecraft:stone)
B(1,2,6,minecraft:stone)
B(1,3,-8,minecraft:stone)
B(1,3,-7,minecraft:stone)
B(1,3,-6,minecraft:stone)
B(1,3,-5,minecraft:stone)
B(1,3,-4,minecraft:stone)
B(1,3,-3,minecraft:stone)
B(1,3,-2,minecraft:stone)
B(1,3,-1,minecraft:stone)
B(1,3,0,minecraft:stone)
B(1,3,1,minecraft:stone)
B(1,3,2,minecraft:stone)
B(1,3,3,minecraft:stone)
B(1,3,4,minecraft:stone)
B(1,3,5,minecraft:stone)
B(1,3,6,minecraft:stone)
B(1,4,-7,minecraft:stone)
B(1,4,-6,minecraft:stone)
B(1,4,-5,minecraft:stone)
B(1,4,-4,minecraft:stone)
B(1,4,-3,minecraft:stone)
B(1,4,-2,minecraft:stone)
B(1,4,-1,minecraft:stone)
B(1,4,0,minecraft:stone)
B(1,4,1,minecraft:stone)
B(1,4,2,minecraft:stone)
B(1,4,3,minecraft:stone)
B(1,4,4,minecraft:stone)
B(1,4,5,minecraft:stone)
B(1,5,-7,minecraft:stone)
B(1,5,-6,minecraft:stone)
B(1,5,-5,minecraft:stone)
B(1,5,-4,minecraft:stone)
B(1,5,-3,minecraft:stone)
B(1,5,-2,minecraft:stone)
B(1,5,-1,minecraft:stone)
B(1,5,0,minecraft:stone)
B(1,5,1,minecraft:stone)
B(1,5,2,minecraft:stone)
B(1,5,3,minecraft:stone)
B(1,5,4,minecraft:stone)
B(1,6,-6,minecraft:stone)
B(1,6,-5,minecraft:stone)
B(1,6,-4,minecraft:stone)
B(1,6,-3,minecraft:stone)
B(1,6,-2,minecraft:stone)
B(1,6,-1,minecraft:stone)
B(1,6,0,minecraft:stone)
B(1,6,1,minecraft:stone)
B(1,6,2,minecraft:stone)
B(1,6,3,minecraft:stone)
B(1,7,-4,minecraft:stone)
B(1,7,-3,minecraft:stone)
B(1,7,-2,minecraft:stone)
B(1,7,-1,minecraft:stone)
B(1,7,0,minecraft:stone)
B(2,-10,2,minecraft:stone)
B(2,-10,3,minecraft:stone)
B(2,-10,4,minecraft:stone)
B(2,-10,5,minecraft:stone)
B(2,-9,-2,minecraft:stone)
B(2,-9,-1,minecraft:stone)
B(2,-9,0,minecraft:stone)
B(2,-9,1,minecraft:stone)
B(2,-9,2,minecraft:stone)
B(2,-9,3,minecraft:stone)
B(2,-9,4,minecraft:stone)
B(2,-9,5,minecraft:stone)
B(2,-9,6,minecraft:stone)
B(2,-8,-7,minecraft:stone)
B(2,-8,-6,minecraft:stone)
B(2,-8,-5,minecraft:stone)
B(2,-8,-4,minecraft:stone)
B(2,-8,-3,minecraft:stone)
B(2,-8,-2,minecraft:stone)
B(2,-8,-1,minecraft:stone)
B(2,-8,0,minecraft:stone)
B(2,-8,1,minecraft:stone)
B(2,-8,2,minecraft:stone)
B(2,-8,3,minecraft:stone)
B(2,-8,4,minecraft:stone)
B(2,-8,5,minecraft:stone)
B(2,-8,6,minecraft:stone)
B(2,-8,7,minecraft:stone)
B(2,-7,-9,minecraft:stone)
B(2,-7,-8,minecraft:stone)
B(2,-7,-7,minecraft:stone)
B(2,-7,-6,minecraft:stone)
B(2,-7,-5,minecraft:stone)
B(2,-7,-4,minecraft:stone)
B(2,-7,-3,minecraft:stone)
B(2,-7,-2,minecraft:stone)
B(2,-7,-1,minecraft:stone)
B(2,-7,0,minecraft:stone)
B(2,-7,1,minecraft:stone)
B(2,-7,2,minecraft:stone)
B(2,-7,3,minecraft:stone)
B(2,-7,4,minecraft:stone)
B(2,-7,5,minecraft:stone)
B(2,-7,6,minecraft:stone)
B(2,-7,7,minecraft:stone)
B(2,-7,8,minecraft:stone)
B(2,-6,-9,minecraft:stone)
B(2,-6,-8,minecraft:stone)
B(2,-6,-7,minecraft:stone)
B(2,-6,-6,minecraft:stone)
B(2,-6,-5,minecraft:stone)
B(2,-6,-4,minecraft:stone)
B(2,-6,-3,minecraft:stone)
B(2,-6,-2,minecraft:stone)
B(2,-6,-1,minecraft:stone)
B(2,-6,0,minecraft:stone)
B(2,-6,1,minecraft:stone)
B(2,-6,2,minecraft:stone)
B(2,-6,3,minecraft:stone)
B(2,-6,4,minecraft:stone)
B(2,-6,5,minecraft:stone)
B(2,-6,6,minecraft:stone)
B(2,-6,7,minecraft:stone)
B(2,-6,8,minecraft:stone)
B(2,-5,-9,minecraft:stone)
B(2,-5,-8,minecraft:stone)
B(2,-5,-7,minecraft:stone)
B(2,-5,-6,minecraft:stone)
B(2,-5,-5,minecraft:stone)
B(2,-5,-4,minecraft:stone)
B(2,-5,-3,minecraft:stone)
B(2,-5,-2,minecraft:stone)
B(2,-5,-1,minecraft:stone)
B(2,-5,0,minecraft:stone)
B(2,-5,1,minecraft:stone)
B(2,-5,2,minecraft:stone)
B(2,-5,3,minecraft:stone)
B(2,-5,4,minecraft:stone)
B(2,-5,5,minecraft:stone)
B(2,-5,6,minecraft:stone)
B(2,-5,7,minecraft:stone)
B(2,-5,8,minecraft:stone)
B(2,-4,-9,minecraft:stone)
B(2,-4,-8,minecraft:stone)
B(2,-4,-7,minecraft:stone)
B(2,-4,-6,minecraft:stone)
B(2,-4,-5,minecraft:stone)
B(2,-4,-4,minecraft:stone)
B(2,-4,-3,minecraft:stone)
B(2,-4,-2,minecraft:stone)
B(2,-4,-1,minecraft:stone)
B(2,-4,0,minecraft:stone)
B(2,-4,1,minecraft:stone)
B(2,-4,2,minecraft:stone)
B(2,-4,3,minecraft:stone)
B(2,-4,4,minecraft:stone)
B(2,-4,5,minecraft:stone)
B(2,-4,6,minecraft:stone)
B(2,-4,7,minecraft:stone)
B(2,-4,8,minecraft:stone)
B(2,-3,-9,minecraft:stone)
B(2,-3,-8,minecraft:stone)
B(2,-3,-7,minecraft:stone)
B(2,-3,-6,minecraft:stone)
B(2,-3,-5,minecraft:stone)
B(2,-3,-4,minecraft:stone)
B(2,-3,-3,minecraft:stone)
B(2,-3,-2,minecraft:stone)
B(2,-3,-1,minecraft:stone)
B(2,-3,0,minecraft:stone)
B(2,-3,1,minecraft:stone)
B(2,-3,2,minecraft:stone)
B(2,-3,3,minecraft:stone)
B(2,-3,4,minecraft:stone)
B(2,-3,5,minecraft:stone)
B(2,-3,6,minecraft:stone)
B(2,-3,7,minecraft:stone)
B(2,-3,8,minecraft:stone)
B(2,-2,-8,minecraft:stone)
B(2,-2,-7,minecraft:stone)
B(2,-2,-6,minecraft:stone)
B(2,-2,-5,minecraft:stone)
B(2,-2,-4,minecraft:stone)
B(2,-2,-3,minecraft:stone)
B(2,-2,-2,minecraft:stone)
B(2,-2,-1,minecraft:stone)
B(2,-2,0,minecraft:stone)
B(2,-2,1,minecraft:stone)
B(2,-2,2,minecraft:stone)
B(2,-2,3,minecraft:stone)
B(2,-2,4,minecraft:stone)
B(2,-2,5,minecraft:stone)
B(2,-2,6,minecraft:stone)
B(2,-2,7,minecraft:stone)
B(2,-1,-8,minecraft:stone)
B(2,-1,-7,minecraft:stone)
B(2,-1,-6,minecraft:stone)
B(2,-1,-5,minecraft:stone)
B(2,-1,-4,minecraft:stone)
B(2,-1,-3,minecraft:stone)
B(2,-1,-2,minecraft:stone)
B(2,-1,-1,minecraft:stone)
B(2,-1,0,minecraft:stone)
B(2,-1,1,minecraft:stone)
B(2,-1,2,minecraft:stone)
B(2,-1,3,minecraft:stone)
B(2,-1,4,minecraft:stone)
B(2,-1,5,minecraft:stone)
B(2,-1,6,minecraft:stone)
B(2,0,-8,minecraft:stone)
B(2,0,-7,minecraft:stone)
B(2,0,-6,minecraft:stone)
B(2,0,-5,minecraft:stone)
B(2,0,-4,minecraft:stone)
B(2,0,-3,minecraft:stone)
B(2,0,-2,minecraft:stone)
B(2,0,-1,minecraft:stone)
B(2,0,0,minecraft:stone)
B(2,0,1,minecraft:stone)
B(2,0,2,minecraft:stone)
B(2,0,3,minecraft:stone)
B(2,0,4,minecraft:stone)
B(2,0,5,minecraft:stone)
B(2,0,6,minecraft:stone)
B(2,1,-8,minecraft:stone)
B(2,1,-7,minecraft:stone)
B(2,1,-6,minecraft:stone)
B(2,1,-5,minecraft:stone)
B(2,1,-4,minecraft:stone)
B(2,1,-3,minecraft:stone)
B(2,1,-2,minecraft:stone)
B(2,1,-1,minecraft:stone)
B(2,1,0,minecraft:stone)
B(2,1,1,minecraft:stone)
B(2,1,2,minecraft:stone)
B(2,1,3,minecraft:stone)
B(2,1,4,minecraft:stone)
B(2,1,5,minecraft:stone)
B(2,1,6,minecraft:stone)
B(2,2,-8,minecraft:stone)
B(2,2,-7,minecraft:stone)
B(2,2,-6,minecraft:stone)
B(2,2,-5,minecraft:stone)
B(2,2,-4,minecraft:stone)
B(2,2,-3,minecraft:stone)
B(2,2,-2,minecraft:stone)
B(2,2,-1,minecraft:stone)
B(2,2,0,minecraft:stone)
B(2,2,1,minecraft:stone)
B(2,2,2,minecraft:stone)
B(2,2,3,minecraft:stone)
B(2,2,4,minecraft:stone)
B(2,2,5,minecraft:stone)
B(2,2,6,minecraft:stone)
B(2,3,-7,minecraft:stone)
B(2,3,-6,minecraft:stone)
B(2,3,-5,minecraft:stone)
B(2,3,-4,minecraft:stone)
B(2,3,-3,minecraft:stone)
B(2,3,-2,minecraft:stone)
B(2,3,-1,minecraft:stone)
B(2,3,0,minecraft:stone)
B(2,3,1,minecraft:stone)
B(2,3,2,minecraft:stone)
B(2,3,3,minecraft:stone)
B(2,3,4,minecraft:stone)
B(2,3,5,minecraft:stone)
B(2,3,6,minecraft:stone)
B(2,4,-7,minecraft:stone)
B(2,4,-6,minecraft:stone)
B(2,4,-5,minecraft:stone)
B(2,4,-4,minecraft:stone)
B(2,4,-3,minecraft:stone)
B(2,4,-2,minecraft:stone)
B(2,4,-1,minecraft:stone)
B(2,4,0,minecraft:stone)
B(2,4,1,minecraft:stone)
B(2,4,2,minecraft:stone)
B(2,4,3,minecraft:stone)
B(2,4,4,minecraft:stone)
B(2,4,5,minecraft:stone)
B(2,5,-7,minecraft:stone)
B(2,5,-6,minecraft:stone)
B(2,5,-5,minecraft:stone)
B(2,5,-4,minecraft:stone)
B(2,5,-3,minecraft:stone)
B(2,5,-2,minecraft:stone)
B(2,5,-1,minecraft:stone)
B(2,5,0,minecraft:stone)
B(2,5,1,minecraft:stone)
B(2,5,2,minecraft:stone)
B(2,5,3,minecraft:stone)
B(2,5,4,minecraft:stone)
B(2,6,-6,minecraft:stone)
B(2,6,-5,minecraft:stone)
B(2,6,-4,minecraft:stone)
B(2,6,-3,minecraft:stone)
B(2,6,-2,minecraft:stone)
B(2,6,-1,minecraft:stone)
B(2,6,0,minecraft:stone)
B(2,6,1,minecraft:stone)
B(2,6,2,minecraft:stone)
B(2,6,3,minecraft:stone)
B(3,-10,2,minecraft:stone)
B(3,-10,3,minecraft:stone)
B(3,-10,4,minecraft:stone)
B(3,-10,5,minecraft:stone)
B(3,-9,-1,minecraft:stone)
B(3,-9,0,minecraft:stone)
B(3,-9,1,minecraft:stone)
B(3,-9,2,minecraft:stone)
B(3,-9,3,minecraft:stone)
B(3,-9,4,minecraft:stone)
B(3,-9,5,minecraft:stone)
B(3,-9,6,minecraft:stone)
B(3,-8,-6,minecraft:stone)
B(3,-8,-5,minecraft:stone)
B(3,-8,-4,minecraft:stone)
B(3,-8,-3,minecraft:stone)
B(3,-8,-2,minecraft:stone)
B(3,-8,-1,minecraft:stone)
B(3,-8,0,minecraft:stone)
B(3,-8,1,minecraft:stone)
B(3,-8,2,minecraft:stone)
B(3,-8,3,minecraft:stone)
B(3,-8,4,minecraft:stone)
B(3,-8,5,minecraft:stone)
B(3,-8,6,minecraft:stone)
B(3,-8,7,minecraft:stone)
B(3,-7,-8,minecraft:stone)
B(3,-7,-7,minecraft:stone)
B(3,-7,-6,minecraft:stone)
B(3,-7,-5,minecraft:stone)
B(3,-7,-4,minecraft:stone)
B(3,-7,-3,minecraft:stone)
B(3,-7,-2,minecraft:stone)
B(3,-7,-1,minecraft:stone)
B(3,-7,0,minecraft:stone)
B(3,-7,1,minecraft:stone)
B(3,-7,2,minecraft:stone)
B(3,-7,3,minecraft:stone)
B(3,-7,4,minecraft:stone)
B(3,-7,5,minecraft:stone)
B(3,-7,6,minecraft:stone)
B(3,-7,7,minecraft:stone)
B(3,-7,8,minecraft:stone)
B(3,-6,-8,minecraft:stone)
B(3,-6,-7,minecraft:stone)
B(3,-6,-6,minecraft:stone)
B(3,-6,-5,minecraft:stone)
B(3,-6,-4,minecraft:stone)
B(3,-6,-3,minecraft:stone)
B(3,-6,-2,minecraft:stone)
B(3,-6,-1,minecraft:stone)
B(3,-6,0,minecraft:stone)
B(3,-6,1,minecraft:stone)
B(3,-6,2,minecraft:stone)
B(3,-6,3,minecraft:stone)
B(3,-6,4,minecraft:stone)
B(3,-6,5,minecraft:stone)
B(3,-6,6,minecraft:stone)
B(3,-6,7,minecraft:stone)
B(3,-6,8,minecraft:stone)
B(3,-5,-9,minecraft:stone)
B(3,-5,-8,minecraft:stone)
B(3,-5,-7,minecraft:stone)
B(3,-5,-6,minecraft:stone)
B(3,-5,-5,minecraft:stone)
B(3,-5,-4,minecraft:stone)
B(3,-5,-3,minecraft:stone)
B(3,-5,-2,minecraft:stone)
B(3,-5,-1,minecraft:stone)
B(3,-5,0,minecraft:stone)
B(3,-5,1,minecraft:stone)
B(3,-5,2,minecraft:stone)
B(3,-5,3,minecraft:stone)
B(3,-5,4,minecraft:stone)
B(3,-5,5,minecraft:stone)
B(3,-5,6,minecraft:stone)
B(3,-5,7,minecraft:stone)
B(3,-5,8,minecraft:stone)
B(3,-4,-9,minecraft:stone)
B(3,-4,-8,minecraft:stone)
B(3,-4,-7,minecraft:stone)
B(3,-4,-6,minecraft:stone)
B(3,-4,-5,minecraft:stone)
B(3,-4,-4,minecraft:stone)
B(3,-4,-3,minecraft:stone)
B(3,-4,-2,minecraft:stone)
B(3,-4,-1,minecraft:stone)
B(3,-4,0,minecraft:stone)
B(3,-4,1,minecraft:stone)
B(3,-4,2,minecraft:stone)
B(3,-4,3,minecraft:stone)
B(3,-4,4,minecraft:stone)
B(3,-4,5,minecraft:stone)
B(3,-4,6,minecraft:stone)
B(3,-4,7,minecraft:stone)
B(3,-4,8,minecraft:stone)
B(3,-3,-8,minecraft:stone)
B(3,-3,-7,minecraft:stone)
B(3,-3,-6,minecraft:stone)
B(3,-3,-5,minecraft:stone)
B(3,-3,-4,minecraft:stone)
B(3,-3,-3,minecraft:stone)
B(3,-3,-2,minecraft:stone)
B(3,-3,-1,minecraft:stone)
B(3,-3,0,minecraft:stone)
B(3,-3,1,minecraft:stone)
B(3,-3,2,minecraft:stone)
B(3,-3,3,minecraft:stone)
B(3,-3,4,minecraft:stone)
B(3,-3,5,minecraft:stone)
B(3,-3,6,minecraft:stone)
B(3,-3,7,minecraft:stone)
B(3,-3,8,minecraft:stone)
B(3,-2,-8,minecraft:stone)
B(3,-2,-7,minecraft:stone)
B(3,-2,-6,minecraft:stone)
B(3,-2,-5,minecraft:stone)
B(3,-2,-4,minecraft:stone)
B(3,-2,-3,minecraft:stone)
B(3,-2,-2,minecraft:stone)
B(3,-2,-1,minecraft:stone)
B(3,-2,0,minecraft:stone)
B(3,-2,1,minecraft:stone)
B(3,-2,2,minecraft:stone)
B(3,-2,3,minecraft:stone)
B(3,-2,4,minecraft:stone)
B(3,-2,5,minecraft:stone)
B(3,-2,6,minecraft:stone)
B(3,-2,7,minecraft:stone)
B(3,-1,-8,minecraft:stone)
B(3,-1,-7,minecraft:stone)
B(3,-1,-6,minecraft:stone)
B(3,-1,-5,minecraft:stone)
B(3,-1,-4,minecraft:stone)
B(3,-1,-3,minecraft:stone)
B(3,-1,-2,minecraft:stone)
B(3,-1,-1,minecraft:stone)
B(3,-1,0,minecraft:stone)
B(3,-1,1,minecraft:stone)
B(3,-1,2,minecraft:stone)
B(3,-1,3,minecraft:stone)
B(3,-1,4,minecraft:stone)
B(3,-1,5,minecraft:stone)
B(3,-1,6,minecraft:stone)
B(3,0,-8,minecraft:stone)
B(3,0,-7,minecraft:stone)
B(3,0,-6,minecraft:stone)
B(3,0,-5,minecraft:stone)
B(3,0,-4,minecraft:stone)
B(3,0,-3,minecraft:stone)
B(3,0,-2,minecraft:stone)
B(3,0,-1,minecraft:stone)
B(3,0,0,minecraft:stone)
B(3,0,1,minecraft:stone)
B(3,0,2,minecraft:stone)
B(3,0,3,minecraft:stone)
B(3,0,4,minecraft:stone)
B(3,0,5,minecraft:stone)
B(3,0,6,minecraft:stone)
B(3,1,-8,minecraft:stone)
B(3,1,-7,minecraft:stone)
B(3,1,-6,minecraft:stone)
B(3,1,-5,minecraft:stone)
B(3,1,-4,minecraft:stone)
B(3,1,-3,minecraft:stone)
B(3,1,-2,minecraft:stone)
B(3,1,-1,minecraft:stone)
B(3,1,0,minecraft:stone)
B(3,1,1,minecraft:stone)
B(3,1,2,minecraft:stone)
B(3,1,3,minecraft:stone)
B(3,1,4,minecraft:stone)
B(3,1,5,minecraft:stone)
B(3,1,6,minecraft:stone)
B(3,2,-8,minecraft:stone)
B(3,2,-7,minecraft:stone)
B(3,2,-6,minecraft:stone)
B(3,2,-5,minecraft:stone)
B(3,2,-4,minecraft:stone)
B(3,2,-3,minecraft:stone)
B(3,2,-2,minecraft:stone)
B(3,2,-1,minecraft:stone)
B(3,2,0,minecraft:stone)
B(3,2,1,minecraft:stone)
B(3,2,2,minecraft:stone)
B(3,2,3,minecraft:stone)
B(3,2,4,minecraft:stone)
B(3,2,5,minecraft:stone)
B(3,2,6,minecraft:stone)
B(3,3,-7,minecraft:stone)
B(3,3,-6,minecraft:stone)
B(3,3,-5,minecraft:stone)
B(3,3,-4,minecraft:stone)
B(3,3,-3,minecraft:stone)
B(3,3,-2,minecraft:stone)
B(3,3,-1,minecraft:stone)
B(3,3,0,minecraft:stone)
B(3,3,1,minecraft:stone)
B(3,3,2,minecraft:stone)
B(3,3,3,minecraft:stone)
B(3,3,4,minecraft:stone)
B(3,3,5,minecraft:stone)
B(3,3,6,minecraft:stone)
B(3,4,-7,minecraft:stone)
B(3,4,-6,minecraft:stone)
B(3,4,-5,minecraft:stone)
B(3,4,-4,minecraft:stone)
B(3,4,-3,minecraft:stone)
B(3,4,-2,minecraft:stone)
B(3,4,-1,minecraft:stone)
B(3,4,0,minecraft:stone)
B(3,4,1,minecraft:stone)
B(3,4,2,minecraft:stone)
B(3,4,3,minecraft:stone)
B(3,4,4,minecraft:stone)
B(3,4,5,minecraft:stone)
B(3,5,-6,minecraft:stone)
B(3,5,-5,minecraft:stone)
B(3,5,-4,minecraft:stone)
B(3,5,-3,minecraft:stone)
B(3,5,-2,minecraft:stone)
B(3,5,-1,minecraft:stone)
B(3,5,0,minecraft:stone)
B(3,5,1,minecraft:stone)
B(3,5,2,minecraft:stone)
B(3,5,3,minecraft:stone)
B(3,5,4,minecraft:stone)
B(3,6,-5,minecraft:stone)
B(3,6,-4,minecraft:stone)
B(3,6,-3,minecraft:stone)
B(3,6,-2,minecraft:stone)
B(3,6,-1,minecraft:stone)
B(3,6,0,minecraft:stone)
B(3,6,1,minecraft:stone)
B(4,-10,2,minecraft:stone)
B(4,-10,3,minecraft:stone)
B(4,-10,4,minecraft:stone)
B(4,-10,5,minecraft:stone)
B(4,-9,-1,minecraft:stone)
B(4,-9,0,minecraft:stone)
B(4,-9,1,minecraft:stone)
B(4,-9,2,minecraft:stone)
B(4,-9,3,minecraft:stone)
B(4,-9,4,minecraft:stone)
B(4,-9,5,minecraft:stone)
B(4,-9,6,minecraft:stone)
B(4,-8,-6,minecraft:stone)
B(4,-8,-5,minecraft:stone)
B(4,-8,-4,minecraft:stone)
B(4,-8,-3,minecraft:stone)
B(4,-8,-2,minecraft:stone)
B(4,-8,-1,minecraft:stone)
B(4,-8,0,minecraft:stone)
B(4,-8,1,minecraft:stone)
B(4,-8,2,minecraft:stone)
B(4,-8,3,minecraft:stone)
B(4,-8,4,minecraft:stone)
B(4,-8,5,minecraft:stone)
B(4,-8,6,minecraft:stone)
B(4,-8,7,minecraft:stone)
B(4,-7,-8,minecraft:stone)
B(4,-7,-7,minecraft:stone)
B(4,-7,-6,minecraft:stone)
B(4,-7,-5,minecraft:stone)
B(4,-7,-4,minecraft:stone)
B(4,-7,-3,minecraft:stone)
B(4,-7,-2,minecraft:stone)
B(4,-7,-1,minecraft:stone)
B(4,-7,0,minecraft:stone)
B(4,-7,1,minecraft:stone)
B(4,-7,2,minecraft:stone)
B(4,-7,3,minecraft:stone)
B(4,-7,4,minecraft:stone)
B(4,-7,5,minecraft:stone)
B(4,-7,6,minecraft:stone)
B(4,-7,7,minecraft:stone)
B(4,-7,8,minecraft:stone)
B(4,-6,-8,minecraft:stone)
B(4,-6,-7,minecraft:stone)
B(4,-6,-6,minecraft:stone)
B(4,-6,-5,minecraft:stone)
B(4,-6,-4,minecraft:stone)
B(4,-6,-3,minecraft:stone)
B(4,-6,-2,minecraft:stone)
B(4,-6,-1,minecraft:stone)
B(4,-6,0,minecraft:stone)
B(4,-6,1,minecraft:stone)
B(4,-6,2,minecraft:stone)
B(4,-6,3,minecraft:stone)
B(4,-6,4,minecraft:stone)
B(4,-6,5,minecraft:stone)
B(4,-6,6,minecraft:stone)
B(4,-6,7,minecraft:stone)
B(4,-6,8,minecraft:stone)
B(4,-5,-8,minecraft:stone)
B(4,-5,-7,minecraft:stone)
B(4,-5,-6,minecraft:stone)
B(4,-5,-5,minecraft:stone)
B(4,-5,-4,minecraft:stone)
B(4,-5,-3,minecraft:stone)
B(4,-5,-2,minecraft:stone)
B(4,-5,-1,minecraft:stone)
B(4,-5,0,minecraft:stone)
B(4,-5,1,minecraft:stone)
B(4,-5,2,minecraft:stone)
B(4,-5,3,minecraft:stone)
B(4,-5,4,minecraft:stone)
B(4,-5,5,minecraft:stone)
B(4,-5,6,minecraft:stone)
B(4,-5,7,minecraft:stone)
B(4,-5,8,minecraft:stone)
B(4,-4,-8,minecraft:stone)
B(4,-4,-7,minecraft:stone)
B(4,-4,-6,minecraft:stone)
B(4,-4,-5,minecraft:stone)
B(4,-4,-4,minecraft:stone)
B(4,-4,-3,minecraft:stone)
B(4,-4,-2,minecraft:stone)
B(4,-4,-1,minecraft:stone)
B(4,-4,0,minecraft:stone)
B(4,-4,1,minecraft:stone)
B(4,-4,2,minecraft:stone)
B(4,-4,3,minecraft:stone)
B(4,-4,4,minecraft:stone)
B(4,-4,5,minecraft:stone)
B(4,-4,6,minecraft:stone)
B(4,-4,7,minecraft:stone)
B(4,-4,8,minecraft:stone)
B(4,-3,-8,minecraft:stone)
B(4,-3,-7,minecraft:stone)
B(4,-3,-6,minecraft:stone)
B(4,-3,-5,minecraft:stone)
B(4,-3,-4,minecraft:stone)
B(4,-3,-3,minecraft:stone)
B(4,-3,-2,minecraft:stone)
B(4,-3,-1,minecraft:stone)
B(4,-3,0,minecraft:stone)
B(4,-3,1,minecraft:stone)
B(4,-3,2,minecraft:stone)
B(4,-3,3,minecraft:stone)
B(4,-3,4,minecraft:stone)
B(4,-3,5,minecraft:stone)
B(4,-3,6,minecraft:stone)
B(4,-3,7,minecraft:stone)
B(4,-2,-8,minecraft:stone)
B(4,-2,-7,minecraft:stone)
B(4,-2,-6,minecraft:stone)
B(4,-2,-5,minecraft:stone)
B(4,-2,-4,minecraft:stone)
B(4,-2,-3,minecraft:stone)
B(4,-2,-2,minecraft:stone)
B(4,-2,-1,minecraft:stone)
B(4,-2,0,minecraft:stone)
B(4,-2,1,minecraft:stone)
B(4,-2,2,minecraft:stone)
B(4,-2,3,minecraft:stone)
B(4,-2,4,minecraft:stone)
B(4,-2,5,minecraft:stone)
B(4,-2,6,minecraft:stone)
B(4,-2,7,minecraft:stone)
B(4,-1,-8,minecraft:stone)
B(4,-1,-7,minecraft:stone)
B(4,-1,-6,minecraft:stone)
B(4,-1,-5,minecraft:stone)
B(4,-1,-4,minecraft:stone)
B(4,-1,-3,minecraft:stone)
B(4,-1,-2,minecraft:stone)
B(4,-1,-1,minecraft:stone)
B(4,-1,0,minecraft:stone)
B(4,-1,1,minecraft:stone)
B(4,-1,2,minecraft:stone)
B(4,-1,3,minecraft:stone)
B(4,-1,4,minecraft:stone)
B(4,-1,5,minecraft:stone)
B(4,-1,6,minecraft:stone)
B(4,0,-8,minecraft:stone)
B(4,0,-7,minecraft:stone)
B(4,0,-6,minecraft:stone)
B(4,0,-5,minecraft:stone)
B(4,0,-4,minecraft:stone)
B(4,0,-3,minecraft:stone)
B(4,0,-2,minecraft:stone)
B(4,0,-1,minecraft:stone)
B(4,0,0,minecraft:stone)
B(4,0,1,minecraft:stone)
B(4,0,2,minecraft:stone)
B(4,0,3,minecraft:stone)
B(4,0,4,minecraft:stone)
B(4,0,5,minecraft:stone)
B(4,0,6,minecraft:stone)
B(4,1,-8,minecraft:stone)
B(4,1,-7,minecraft:stone)
B(4,1,-6,minecraft:stone)
B(4,1,-5,minecraft:stone)
B(4,1,-4,minecraft:stone)
B(4,1,-3,minecraft:stone)
B(4,1,-2,minecraft:stone)
B(4,1,-1,minecraft:stone)
B(4,1,0,minecraft:stone)
B(4,1,1,minecraft:stone)
B(4,1,2,minecraft:stone)
B(4,1,3,minecraft:stone)
B(4,1,4,minecraft:stone)
B(4,1,5,minecraft:stone)
B(4,1,6,minecraft:stone)
B(4,2,-7,minecraft:stone)
B(4,2,-6,minecraft:stone)
B(4,2,-5,minecraft:stone)
B(4,2,-4,minecraft:stone)
B(4,2,-3,minecraft:stone)
B(4,2,-2,minecraft:stone)
B(4,2,-1,minecraft:stone)
B(4,2,0,minecraft:stone)
B(4,2,1,minecraft:stone)
B(4,2,2,minecraft:stone)
B(4,2,3,minecraft:stone)
B(4,2,4,minecraft:stone)
B(4,2,5,minecraft:stone)
B(4,2,6,minecraft:stone)
B(4,3,-7,minecraft:stone)
B(4,3,-6,minecraft:stone)
B(4,3,-5,minecraft:stone)
B(4,3,-4,minecraft:stone)
B(4,3,-3,minecraft:stone)
B(4,3,-2,minecraft:stone)
B(4,3,-1,minecraft:stone)
B(4,3,0,minecraft:stone)
B(4,3,1,minecraft:stone)
B(4,3,2,minecraft:stone)
B(4,3,3,minecraft:stone)
B(4,3,4,minecraft:stone)
B(4,3,5,minecraft:stone)
B(4,3,6,minecraft:stone)
B(4,4,-7,minecraft:stone)
B(4,4,-6,minecraft:stone)
B(4,4,-5,minecraft:stone)
B(4,4,-4,minecraft:stone)
B(4,4,-3,minecraft:stone)
B(4,4,-2,minecraft:stone)
B(4,4,-1,minecraft:stone)
B(4,4,0,minecraft:stone)
B(4,4,1,minecraft:stone)
B(4,4,2,minecraft:stone)
B(4,4,3,minecraft:stone)
B(4,4,4,minecraft:stone)
B(4,4,5,minecraft:stone)
B(4,5,-6,minecraft:stone)
B(4,5,-5,minecraft:stone)
B(4,5,-4,minecraft:stone)
B(4,5,-3,minecraft:stone)
B(4,5,-2,minecraft:stone)
B(4,5,-1,minecraft:stone)
B(4,5,0,minecraft:stone)
B(4,5,1,minecraft:stone)
B(4,5,2,minecraft:stone)
B(4,5,3,minecraft:stone)
B(4,5,4,minecraft:stone)
B(5,-10,3,minecraft:stone)
B(5,-10,4,minecraft:stone)
B(5,-10,5,minecraft:stone)
B(5,-9,-1,minecraft:stone)
B(5,-9,0,minecraft:stone)
B(5,-9,1,minecraft:stone)
B(5,-9,2,minecraft:stone)
B(5,-9,3,minecraft:stone)
B(5,-9,4,minecraft:stone)
B(5,-9,5,minecraft:stone)
B(5,-9,6,minecraft:stone)
B(5,-8,-6,minecraft:stone)
B(5,-8,-5,minecraft:stone)
B(5,-8,-4,minecraft:stone)
B(5,-8,-3,minecraft:stone)
B(5,-8,-2,minecraft:stone)
B(5,-8,-1,minecraft:stone)
B(5,-8,0,minecraft:stone)
B(5,-8,1,minecraft:stone)
B(5,-8,2,minecraft:stone)
B(5,-8,3,minecraft:stone)
B(5,-8,4,minecraft:stone)
B(5,-8,5,minecraft:stone)
B(5,-8,6,minecraft:stone)
B(5,-8,7,minecraft:stone)
B(5,-7,-8,minecraft:stone)
B(5,-7,-7,minecraft:stone)
B(5,-7,-6,minecraft:stone)
B(5,-7,-5,minecraft:stone)
B(5,-7,-4,minecraft:stone)
B(5,-7,-3,minecraft:stone)
B(5,-7,-2,minecraft:stone)
B(5,-7,-1,minecraft:stone)
B(5,-7,0,minecraft:stone)
B(5,-7,1,minecraft:stone)
B(5,-7,2,minecraft:stone)
B(5,-7,3,minecraft:stone)
B(5,-7,4,minecraft:stone)
B(5,-7,5,minecraft:stone)
B(5,-7,6,minecraft:stone)
B(5,-7,7,minecraft:stone)
B(5,-7,8,minecraft:stone)
B(5,-6,-8,minecraft:stone)
B(5,-6,-7,minecraft:stone)
B(5,-6,-6,minecraft:stone)
B(5,-6,-5,minecraft:stone)
B(5,-6,-4,minecraft:stone)
B(5,-6,-3,minecraft:stone)
B(5,-6,-2,minecraft:stone)
B(5,-6,-1,minecraft:stone)
B(5,-6,0,minecraft:stone)
B(5,-6,1,minecraft:stone)
B(5,-6,2,minecraft:stone)
B(5,-6,3,minecraft:stone)
B(5,-6,4,minecraft:stone)
B(5,-6,5,minecraft:stone)
B(5,-6,6,minecraft:stone)
B(5,-6,7,minecraft:stone)
B(5,-6,8,minecraft:stone)
B(5,-5,-8,minecraft:stone)
B(5,-5,-7,minecraft:stone)
B(5,-5,-6,minecraft:stone)
B(5,-5,-5,minecraft:stone)
B(5,-5,-4,minecraft:stone)
B(5,-5,-3,minecraft:stone)
B(5,-5,-2,minecraft:stone)
B(5,-5,-1,minecraft:stone)
B(5,-5,0,minecraft:stone)
B(5,-5,1,minecraft:stone)
B(5,-5,2,minecraft:stone)
B(5,-5,3,minecraft:stone)
B(5,-5,4,minecraft:stone)
B(5,-5,5,minecraft:stone)
B(5,-5,6,minecraft:stone)
B(5,-5,7,minecraft:stone)
B(5,-5,8,minecraft:stone)
B(5,-4,-8,minecraft:stone)
B(5,-4,-7,minecraft:stone)
B(5,-4,-6,minecraft:stone)
B(5,-4,-5,minecraft:stone)
B(5,-4,-4,minecraft:stone)
B(5,-4,-3,minecraft:stone)
B(5,-4,-2,minecraft:stone)
B(5,-4,-1,minecraft:stone)
B(5,-4,0,minecraft:stone)
B(5,-4,1,minecraft:stone)
B(5,-4,2,minecraft:stone)
B(5,-4,3,minecraft:stone)
B(5,-4,4,minecraft:stone)
B(5,-4,5,minecraft:stone)
B(5,-4,6,minecraft:stone)
B(5,-4,7,minecraft:stone)
B(5,-4,8,minecraft:stone)
B(5,-3,-8,minecraft:stone)
B(5,-3,-7,minecraft:stone)
B(5,-3,-6,minecraft:stone)
B(5,-3,-5,minecraft:stone)
B(5,-3,-4,minecraft:stone)
B(5,-3,-3,minecraft:stone)
B(5,-3,-2,minecraft:stone)
B(5,-3,-1,minecraft:stone)
B(5,-3,0,minecraft:stone)
B(5,-3,1,minecraft:stone)
B(5,-3,2,minecraft:stone)
B(5,-3,3,minecraft:stone)
B(5,-3,4,minecraft:stone)
B(5,-3,5,minecraft:stone)
B(5,-3,6,minecraft:stone)
B(5,-3,7,minecraft:stone)
B(5,-2,-8,minecraft:stone)
B(5,-2,-7,minecraft:stone)
B(5,-2,-6,minecraft:stone)
B(5,-2,-5,minecraft:stone)
B(5,-2,-4,minecraft:stone)
B(5,-2,-3,minecraft:stone)
B(5,-2,-2,minecraft:stone)
B(5,-2,-1,minecraft:stone)
B(5,-2,0,minecraft:stone)
B(5,-2,1,minecraft:stone)
B(5,-2,2,minecraft:stone)
B(5,-2,3,minecraft:stone)
B(5,-2,4,minecraft:stone)
B(5,-2,5,minecraft:stone)
B(5,-2,6,minecraft:stone)
B(5,-2,7,minecraft:stone)
B(5,-1,-8,minecraft:stone)
B(5,-1,-7,minecraft:stone)
B(5,-1,-6,minecraft:stone)
B(5,-1,-5,minecraft:stone)
B(5,-1,-4,minecraft:stone)
B(5,-1,-3,minecraft:stone)
B(5,-1,-2,minecraft:stone)
B(5,-1,-1,minecraft:stone)
B(5,-1,0,minecraft:stone)
B(5,-1,1,minecraft:stone)
B(5,-1,2,minecraft:stone)
B(5,-1,3,minecraft:stone)
B(5,-1,4,minecraft:stone)
B(5,-1,5,minecraft:stone)
B(5,-1,6,minecraft:stone)
B(5,0,-8,minecraft:stone)
B(5,0,-7,minecraft:stone)
B(5,0,-6,minecraft:stone)
B(5,0,-5,minecraft:stone)
B(5,0,-4,minecraft:stone)
B(5,0,-3,minecraft:stone)
B(5,0,-2,minecraft:stone)
B(5,0,-1,minecraft:stone)
B(5,0,0,minecraft:stone)
B(5,0,1,minecraft:stone)
B(5,0,2,minecraft:stone)
B(5,0,3,minecraft:stone)
B(5,0,4,minecraft:stone)
B(5,0,5,minecraft:stone)
B(5,0,6,minecraft:stone)
B(5,1,-7,minecraft:stone)
B(5,1,-6,minecraft:stone)
B(5,1,-5,minecraft:stone)
B(5,1,-4,minecraft:stone)
B(5,1,-3,minecraft:stone)
B(5,1,-2,minecraft:stone)
B(5,1,-1,minecraft:stone)
B(5,1,0,minecraft:stone)
B(5,1,1,minecraft:stone)
B(5,1,2,minecraft:stone)
B(5,1,3,minecraft:stone)
B(5,1,4,minecraft:stone)
B(5,1,5,minecraft:stone)
B(5,1,6,minecraft:stone)
B(5,2,-7,minecraft:stone)
B(5,2,-6,minecraft:stone)
B(5,2,-5,minecraft:stone)
B(5,2,-4,minecraft:stone)
B(5,2,-3,minecraft:stone)
B(5,2,-2,minecraft:stone)
B(5,2,-1,minecraft:stone)
B(5,2,0,minecraft:stone)
B(5,2,1,minecraft:stone)
B(5,2,2,minecraft:stone)
B(5,2,3,minecraft:stone)
B(5,2,4,minecraft:stone)
B(5,2,5,minecraft:stone)
B(5,2,6,minecraft:stone)
B(5,3,-7,minecraft:stone)
B(5,3,-6,minecraft:stone)
B(5,3,-5,minecraft:stone)
B(5,3,-4,minecraft:stone)
B(5,3,-3,minecraft:stone)
B(5,3,-2,minecraft:stone)
B(5,3,-1,minecraft:stone)
B(5,3,0,minecraft:stone)
B(5,3,1,minecraft:stone)
B(5,3,2,minecraft:stone)
B(5,3,3,minecraft:stone)
B(5,3,4,minecraft:stone)
B(5,3,5,minecraft:stone)
B(5,3,6,minecraft:stone)
B(5,4,-6,minecraft:stone)
B(5,4,-5,minecraft:stone)
B(5,4,-4,minecraft:stone)
B(5,4,-3,minecraft:stone)
B(5,4,-2,minecraft:stone)
B(5,4,-1,minecraft:stone)
B(5,4,0,minecraft:stone)
B(5,4,1,minecraft:stone)
B(5,4,2,minecraft:stone)
B(5,4,3,minecraft:stone)
B(5,4,4,minecraft:stone)
B(5,4,5,minecraft:stone)
B(6,-10,5,minecraft:stone)
B(6,-9,-1,minecraft:stone)
B(6,-9,0,minecraft:stone)
B(6,-9,1,minecraft:stone)
B(6,-9,2,minecraft:stone)
B(6,-9,3,minecraft:stone)
B(6,-9,4,minecraft:stone)
B(6,-9,5,minecraft:stone)
B(6,-9,6,minecraft:stone)
B(6,-8,-6,minecraft:stone)
B(6,-8,-5,minecraft:stone)
B(6,-8,-4,minecraft:stone)
B(6,-8,-3,minecraft:stone)
B(6,-8,-2,minecraft:stone)
B(6,-8,-1,minecraft:stone)
B(6,-8,0,minecraft:stone)
B(6,-8,1,minecraft:stone)
B(6,-8,2,minecraft:stone)
B(6,-8,3,minecraft:stone)
B(6,-8,4,minecraft:stone)
B(6,-8,5,minecraft:stone)
B(6,-8,6,minecraft:stone)
B(6,-8,7,minecraft:stone)
B(6,-7,-8,minecraft:stone)
B(6,-7,-7,minecraft:stone)
B(6,-7,-6,minecraft:stone)
B(6,-7,-5,minecraft:stone)
B(6,-7,-4,minecraft:stone)
B(6,-7,-3,minecraft:stone)
B(6,-7,-2,minecraft:stone)
B(6,-7,-1,minecraft:stone)
B(6,-7,0,minecraft:stone)
B(6,-7,1,minecraft:stone)
B(6,-7,2,minecraft:stone)
B(6,-7,3,minecraft:stone)
B(6,-7,4,minecraft:stone)
B(6,-7,5,minecraft:stone)
B(6,-7,6,minecraft:stone)
B(6,-7,7,minecraft:stone)
B(6,-7,8,minecraft:stone)
B(6,-6,-8,minecraft:stone)
B(6,-6,-7,minecraft:stone)
B(6,-6,-6,minecraft:stone)
B(6,-6,-5,minecraft:stone)
B(6,-6,-4,minecraft:stone)
B(6,-6,-3,minecraft:stone)
B(6,-6,-2,minecraft:stone)
B(6,-6,-1,minecraft:stone)
B(6,-6,0,minecraft:stone)
B(6,-6,1,minecraft:stone)
B(6,-6,2,minecraft:stone)
B(6,-6,3,minecraft:stone)
B(6,-6,4,minecraft:stone)
B(6,-6,5,minecraft:stone)
B(6,-6,6,minecraft:stone)
B(6,-6,7,minecraft:stone)
B(6,-6,8,minecraft:stone)
B(6,-5,-8,minecraft:stone)
B(6,-5,-7,minecraft:stone)
B(6,-5,-6,minecraft:stone)
B(6,-5,-5,minecraft:stone)
B(6,-5,-4,minecraft:stone)
B(6,-5,-3,minecraft:stone)
B(6,-5,-2,minecraft:stone)
B(6,-5,-1,minecraft:stone)
B(6,-5,0,minecraft:stone)
B(6,-5,1,minecraft:stone)
B(6,-5,2,minecraft:stone)
B(6,-5,3,minecraft:stone)
B(6,-5,4,minecraft:stone)
B(6,-5,5,minecraft:stone)
B(6,-5,6,minecraft:stone)
B(6,-5,7,minecraft:stone)
B(6,-5,8,minecraft:stone)
B(6,-4,-8,minecraft:stone)
B(6,-4,-7,minecraft:stone)
B(6,-4,-6,minecraft:stone)
B(6,-4,-5,minecraft:stone)
B(6,-4,-4,minecraft:stone)
B(6,-4,-3,minecraft:stone)
B(6,-4,-2,minecraft:stone)
B(6,-4,-1,minecraft:stone)
B(6,-4,0,minecraft:stone)
B(6,-4,1,minecraft:stone)
B(6,-4,2,minecraft:stone)
B(6,-4,3,minecraft:stone)
B(6,-4,4,minecraft:stone)
B(6,-4,5,minecraft:stone)
B(6,-4,6,minecraft:stone)
B(6,-4,7,minecraft:stone)
B(6,-4,8,minecraft:stone)
B(6,-3,-8,minecraft:stone)
B(6,-3,-7,minecraft:stone)
B(6,-3,-6,minecraft:stone)
B(6,-3,-5,minecraft:stone)
B(6,-3,-4,minecraft:stone)
B(6,-3,-3,minecraft:stone)
B(6,-3,-2,minecraft:stone)
B(6,-3,-1,minecraft:stone)
B(6,-3,0,minecraft:stone)
B(6,-3,1,minecraft:stone)
B(6,-3,2,minecraft:stone)
B(6,-3,3,minecraft:stone)
B(6,-3,4,minecraft:stone)
B(6,-3,5,minecraft:stone)
B(6,-3,6,minecraft:stone)
B(6,-3,7,minecraft:stone)
B(6,-3,8,minecraft:stone)
B(6,-2,-7,minecraft:stone)
B(6,-2,-6,minecraft:stone)
B(6,-2,-5,minecraft:stone)
B(6,-2,-4,minecraft:stone)
B(6,-2,-3,minecraft:stone)
B(6,-2,-2,minecraft:stone)
B(6,-2,-1,minecraft:stone)
B(6,-2,0,minecraft:stone)
B(6,-2,1,minecraft:stone)
B(6,-2,2,minecraft:stone)
B(6,-2,3,minecraft:stone)
B(6,-2,4,minecraft:stone)
B(6,-2,5,minecraft:stone)
B(6,-2,6,minecraft:stone)
B(6,-2,7,minecraft:stone)
B(6,-1,-7,minecraft:stone)
B(6,-1,-6,minecraft:stone)
B(6,-1,-5,minecraft:stone)
B(6,-1,-4,minecraft:stone)
B(6,-1,-3,minecraft:stone)
B(6,-1,-2,minecraft:stone)
B(6,-1,-1,minecraft:stone)
B(6,-1,0,minecraft:stone)
B(6,-1,1,minecraft:stone)
B(6,-1,2,minecraft:stone)
B(6,-1,3,minecraft:stone)
B(6,-1,4,minecraft:stone)
B(6,-1,5,minecraft:stone)
B(6,-1,6,minecraft:stone)
B(6,-1,7,minecraft:stone)
B(6,0,-7,minecraft:stone)
B(6,0,-6,minecraft:stone)
B(6,0,-5,minecraft:stone)
B(6,0,-4,minecraft:stone)
B(6,0,-3,minecraft:stone)
B(6,0,-2,minecraft:stone)
B(6,0,-1,minecraft:stone)
B(6,0,0,minecraft:stone)
B(6,0,1,minecraft:stone)
B(6,0,2,minecraft:stone)
B(6,0,3,minecraft:stone)
B(6,0,4,minecraft:stone)
B(6,0,5,minecraft:stone)
B(6,0,6,minecraft:stone)
B(6,1,-7,minecraft:stone)
B(6,1,-6,minecraft:stone)
B(6,1,-5,minecraft:stone)
B(6,1,-4,minecraft:stone)
B(6,1,-3,minecraft:stone)
B(6,1,-2,minecraft:stone)
B(6,1,-1,minecraft:stone)
B(6,1,0,minecraft:stone)
B(6,1,1,minecraft:stone)
B(6,1,2,minecraft:stone)
B(6,1,3,minecraft:stone)
B(6,1,4,minecraft:stone)
B(6,1,5,minecraft:stone)
B(6,1,6,minecraft:stone)
B(6,2,-7,minecraft:stone)
B(6,2,-6,minecraft:stone)
B(6,2,-5,minecraft:stone)
B(6,2,-4,minecraft:stone)
B(6,2,-3,minecraft:stone)
B(6,2,-2,minecraft:stone)
B(6,2,-1,minecraft:stone)
B(6,2,0,minecraft:stone)
B(6,2,1,minecraft:stone)
B(6,2,2,minecraft:stone)
B(6,2,3,minecraft:stone)
B(6,2,4,minecraft:stone)
B(6,2,5,minecraft:stone)
B(6,2,6,minecraft:stone)
B(6,3,-6,minecraft:stone)
B(6,3,-5,minecraft:stone)
B(6,3,-4,minecraft:stone)
B(6,3,-3,minecraft:stone)
B(6,3,-2,minecraft:stone)
B(6,3,-1,minecraft:stone)
B(6,3,0,minecraft:stone)
B(6,3,1,minecraft:stone)
B(6,3,2,minecraft:stone)
B(6,3,3,minecraft:stone)
B(6,3,4,minecraft:stone)
B(6,3,5,minecraft:stone)
B(6,4,-5,minecraft:stone)
B(6,4,-4,minecraft:stone)
B(6,4,-3,minecraft:stone)
B(6,4,-2,minecraft:stone)
B(6,4,-1,minecraft:stone)
B(6,4,0,minecraft:stone)
B(7,-9,-1,minecraft:stone)
B(7,-9,0,minecraft:stone)
B(7,-9,1,minecraft:stone)
B(7,-9,2,minecraft:stone)
B(7,-9,3,minecraft:stone)
B(7,-9,4,minecraft:stone)
B(7,-9,5,minecraft:stone)
B(7,-9,6,minecraft:stone)
B(7,-8,-5,minecraft:stone)
B(7,-8,-4,minecraft:stone)
B(7,-8,-3,minecraft:stone)
B(7,-8,-2,minecraft:stone)
B(7,-8,-1,minecraft:stone)
B(7,-8,0,minecraft:stone)
B(7,-8,1,minecraft:stone)
B(7,-8,2,minecraft:stone)
B(7,-8,3,minecraft:stone)
B(7,-8,4,minecraft:stone)
B(7,-8,5,minecraft:stone)
B(7,-8,6,minecraft:stone)
B(7,-8,7,minecraft:stone)
B(7,-7,-7,minecraft:stone)
B(7,-7,-6,minecraft:stone)
B(7,-7,-5,minecraft:stone)
B(7,-7,-4,minecraft:stone)
B(7,-7,-3,minecraft:stone)
B(7,-7,-2,minecraft:stone)
B(7,-7,-1,minecraft:stone)
B(7,-7,0,minecraft:stone)
B(7,-7,1,minecraft:stone)
B(7,-7,2,minecraft:stone)
B(7,-7,3,minecraft:stone)
B(7,-7,4,minecraft:stone)
B(7,-7,5,minecraft:stone)
B(7,-7,6,minecraft:stone)
B(7,-7,7,minecraft:stone)
B(7,-7,8,minecraft:stone)
B(7,-6,-7,minecraft:stone)
B(7,-6,-6,minecraft:stone)
B(7,-6,-5,minecraft:stone)
B(7,-6,-4,minecraft:stone)
B(7,-6,-3,minecraft:stone)
B(7,-6,-2,minecraft:stone)
B(7,-6,-1,minecraft:stone)
B(7,-6,0,minecraft:stone)
B(7,-6,1,minecraft:stone)
B(7,-6,2,minecraft:stone)
B(7,-6,3,minecraft:stone)
B(7,-6,4,minecraft:stone)
B(7,-6,5,minecraft:stone)
B(7,-6,6,minecraft:stone)
B(7,-6,7,minecraft:stone)
B(7,-5,-7,minecraft:stone)
B(7,-5,-6,minecraft:stone)
B(7,-5,-5,minecraft:stone)
B(7,-5,-4,minecraft:stone)
B(7,-5,-3,minecraft:stone)
B(7,-5,-2,minecraft:stone)
B(7,-5,-1,minecraft:stone)
B(7,-5,0,minecraft:stone)
B(7,-5,1,minecraft:stone)
B(7,-5,2,minecraft:stone)
B(7,-5,3,minecraft:stone)
B(7,-5,4,minecraft:stone)
B(7,-5,5,minecraft:stone)
B(7,-5,6,minecraft:stone)
B(7,-5,7,minecraft:stone)
B(7,-4,-7,minecraft:stone)
B(7,-4,-6,minecraft:stone)
B(7,-4,-5,minecraft:stone)
B(7,-4,-4,minecraft:stone)
B(7,-4,-3,minecraft:stone)
B(7,-4,-2,minecraft:stone)
B(7,-4,-1,minecraft:stone)
B(7,-4,0,minecraft:stone)
B(7,-4,1,minecraft:stone)
B(7,-4,2,minecraft:stone)
B(7,-4,3,minecraft:stone)
B(7,-4,4,minecraft:stone)
B(7,-4,5,minecraft:stone)
B(7,-4,6,minecraft:stone)
B(7,-4,7,minecraft:stone)
B(7,-3,-7,minecraft:stone)
B(7,-3,-6,minecraft:stone)
B(7,-3,-5,minecraft:stone)
B(7,-3,-4,minecraft:stone)
B(7,-3,-3,minecraft:stone)
B(7,-3,-2,minecraft:stone)
B(7,-3,-1,minecraft:stone)
B(7,-3,0,minecraft:stone)
B(7,-3,1,minecraft:stone)
B(7,-3,2,minecraft:stone)
B(7,-3,3,minecraft:stone)
B(7,-3,4,minecraft:stone)
B(7,-3,5,minecraft:stone)
B(7,-3,6,minecraft:stone)
B(7,-3,7,minecraft:stone)
B(7,-2,-7,minecraft:stone)
B(7,-2,-6,minecraft:stone)
B(7,-2,-5,minecraft:stone)
B(7,-2,-4,minecraft:stone)
B(7,-2,-3,minecraft:stone)
B(7,-2,-2,minecraft:stone)
B(7,-2,-1,minecraft:stone)
B(7,-2,0,minecraft:stone)
B(7,-2,1,minecraft:stone)
B(7,-2,2,minecraft:stone)
B(7,-2,3,minecraft:stone)
B(7,-2,4,minecraft:stone)
B(7,-2,5,minecraft:stone)
B(7,-2,6,minecraft:stone)
B(7,-2,7,minecraft:stone)
B(7,-1,-7,minecraft:stone)
B(7,-1,-6,minecraft:stone)
B(7,-1,-5,minecraft:stone)
B(7,-1,-4,minecraft:stone)
B(7,-1,-3,minecraft:stone)
B(7,-1,-2,minecraft:stone)
B(7,-1,-1,minecraft:stone)
B(7,-1,0,minecraft:stone)
B(7,-1,1,minecraft:stone)
B(7,-1,2,minecraft:stone)
B(7,-1,3,minecraft:stone)
B(7,-1,4,minecraft:stone)
B(7,-1,5,minecraft:stone)
B(7,-1,6,minecraft:stone)
B(7,-1,7,minecraft:stone)
B(7,0,-6,minecraft:stone)
B(7,0,-5,minecraft:stone)
B(7,0,-4,minecraft:stone)
B(7,0,-3,minecraft:stone)
B(7,0,-2,minecraft:stone)
B(7,0,-1,minecraft:stone)
B(7,0,0,minecraft:stone)
B(7,0,1,minecraft:stone)
B(7,0,2,minecraft:stone)
B(7,0,3,minecraft:stone)
B(7,0,4,minecraft:stone)
B(7,0,5,minecraft:stone)
B(7,0,6,minecraft:stone)
B(7,1,-6,minecraft:stone)
B(7,1,-5,minecraft:stone)
B(7,1,-4,minecraft:stone)
B(7,1,-3,minecraft:stone)
B(7,1,-2,minecraft:stone)
B(7,1,-1,minecraft:stone)
B(7,1,0,minecraft:stone)
B(7,1,1,minecraft:stone)
B(7,1,2,minecraft:stone)
B(7,1,3,minecraft:stone)
B(7,1,4,minecraft:stone)
B(7,1,5,minecraft:stone)
B(7,1,6,minecraft:stone)
B(7,2,-6,minecraft:stone)
B(7,2,-5,minecraft:stone)
B(7,2,-4,minecraft:stone)
B(7,2,-3,minecraft:stone)
B(7,2,-2,minecraft:stone)
B(7,2,-1,minecraft:stone)
B(7,2,0,minecraft:stone)
B(7,2,1,minecraft:stone)
B(7,2,2,minecraft:stone)
B(7,2,3,minecraft:stone)
B(7,2,4,minecraft:stone)
B(7,2,5,minecraft:stone)
B(7,3,-4,minecraft:stone)
B(7,3,-3,minecraft:stone)
B(7,3,-2,minecraft:stone)
B(7,3,-1,minecraft:stone)
B(7,3,0,minecraft:stone)
B(8,-9,-1,minecraft:stone)
B(8,-9,0,minecraft:stone)
B(8,-9,1,minecraft:stone)
B(8,-9,2,minecraft:stone)
B(8,-8,-3,minecraft:stone)
B(8,-8,-2,minecraft:stone)
B(8,-8,-1,minecraft:stone)
B(8,-8,0,minecraft:stone)
B(8,-8,1,minecraft:stone)
B(8,-8,2,minecraft:stone)
B(8,-7,-6,minecraft:stone)
B(8,-7,-5,minecraft:stone)
B(8,-7,-4,minecraft:stone)
B(8,-7,-3,minecraft:stone)
B(8,-7,-2,minecraft:stone)
B(8,-7,-1,minecraft:stone)
B(8,-7,0,minecraft:stone)
B(8,-7,1,minecraft:stone)
B(8,-6,-7,minecraft:stone)
B(8,-6,-6,minecraft:stone)
B(8,-6,-5,minecraft:stone)
B(8,-6,-4,minecraft:stone)
B(8,-6,-3,minecraft:stone)
B(8,-6,-2,minecraft:stone)
B(8,-6,-1,minecraft:stone)
B(8,-6,0,minecraft:stone)
B(8,-6,1,minecraft:stone)
B(8,-6,2,minecraft:stone)
B(8,-5,-7,minecraft:stone)
B(8,-5,-6,minecraft:stone)
B(8,-5,-5,minecraft:stone)
B(8,-5,-4,minecraft:stone)
B(8,-5,-3,minecraft:stone)
B(8,-5,-2,minecraft:stone)
B(8,-5,-1,minecraft:stone)
B(8,-5,0,minecraft:stone)
B(8,-5,1,minecraft:stone)
B(8,-5,2,minecraft:stone)
B(8,-4,-7,minecraft:stone)
B(8,-4,-6,minecraft:stone)
B(8,-4,-5,minecraft:stone)
B(8,-4,-4,minecraft:stone)
B(8,-4,-3,minecraft:stone)
B(8,-4,-2,minecraft:stone)
B(8,-4,-1,minecraft:stone)
B(8,-4,0,minecraft:stone)
B(8,-4,1,minecraft:stone)
B(8,-4,2,minecraft:stone)
B(8,-3,-6,minecraft:stone)
B(8,-3,-5,minecraft:stone)
B(8,-3,-4,minecraft:stone)
B(8,-3,-3,minecraft:stone)
B(8,-3,-2,minecraft:stone)
B(8,-3,-1,minecraft:stone)
B(8,-3,0,minecraft:stone)
B(8,-3,1,minecraft:stone)
B(8,-3,2,minecraft:stone)
B(8,-2,-6,minecraft:stone)
B(8,-2,-5,minecraft:stone)
B(8,-2,-4,minecraft:stone)
B(8,-2,-3,minecraft:stone)
B(8,-2,-2,minecraft:stone)
B(8,-2,-1,minecraft:stone)
B(8,-2,0,minecraft:stone)
B(8,-2,1,minecraft:stone)
B(8,-2,2,minecraft:stone)
B(8,-1,-6,minecraft:stone)
B(8,-1,-5,minecraft:stone)
B(8,-1,-4,minecraft:stone)
B(8,-1,-3,minecraft:stone)
B(8,-1,-2,minecraft:stone)
B(8,-1,-1,minecraft:stone)
B(8,-1,0,minecraft:stone)
B(8,-1,1,minecraft:stone)
B(8,0,-6,minecraft:stone)
B(8,0,-5,minecraft:stone)
B(8,0,-4,minecraft:stone)
B(8,0,-3,minecraft:stone)
B(8,0,-2,minecraft:stone)
B(8,0,-1,minecraft:stone)
B(8,0,0,minecraft:stone)
B(8,0,1,minecraft:stone)
B(8,1,-6,minecraft:stone)
B(8,1,-5,minecraft:stone)
B(8,1,-4,minecraft:stone)
B(8,1,-3,minecraft:stone)
B(8,1,-2,minecraft:stone)
B(8,1,-1,minecraft:stone)
B(8,1,0,minecraft:stone)
B(8,1,1,minecraft:stone)
B(8,2,-3,minecraft:stone)
B(8,2,-2,minecraft:stone)
B(8,2,-1,minecraft:stone)
B(8,2,0,minecraft:stone)
B(9,-7,-2,minecraft:stone)
B(9,-6,-5,minecraft:stone)
B(9,-6,-4,minecraft:stone)
B(9,-6,-3,minecraft:stone)
B(9,-6,-2,minecraft:stone)
B(9,-5,-6,minecraft:stone)
B(9,-5,-5,minecraft:stone)
B(9,-5,-4,minecraft:stone)
B(9,-5,-3,minecraft:stone)
B(9,-5,-2,minecraft:stone)
B(9,-4,-6,minecraft:stone)
B(9,-4,-5,minecraft:stone)
B(9,-4,-4,minecraft:stone)
B(9,-4,-3,minecraft:stone)
B(9,-4,-2,minecraft:stone)
B(9,-3,-6,minecraft:stone)
B(9,-3,-5,minecraft:stone)
B(9,-3,-4,minecraft:stone)
B(9,-3,-3,minecraft:stone)
B(9,-3,-2,minecraft:stone)
B(9,-2,-6,minecraft:stone)
B(9,-2,-5,minecraft:stone)
B(9,-2,-4,minecraft:stone)
B(9,-2,-3,minecraft:stone)
B(9,-2,-2,minecraft:stone)
B(9,-1,-5,minecraft:stone)
B(9,-1,-4,minecraft:stone)
B(9,-1,-3,minecraft:stone)
B(9,-1,-2,minecraft:stone)
B(9,0,-5,minecraft:stone)
B(9,0,-4,minecraft:stone)
B(9,0,-3,minecraft:stone)

#######################################################################
# +-----------------------------------------------------------------+ #
# |                            BO3 checks                           | #
# +-----------------------------------------------------------------+ #
#######################################################################

BlockCheck(0,-1,0,otg:dirt,minecraft:sand,minecraft:grass_block,minecraft:gravel)

#######################################################################
# +-----------------------------------------------------------------+ #
# |                             Branches                            | #
# +-----------------------------------------------------------------+ #
#######################################################################


#######################################################################
# +-----------------------------------------------------------------+ #
# |                             Entities                            | #
# +-----------------------------------------------------------------+ #
#######################################################################

