
#######################################################################
# +-----------------------------------------------------------------+ #
# |                            BO3 object                           | #
# +-----------------------------------------------------------------+ #
#######################################################################

Author: Unknown

Description: No description given

Version: 3

SettingsMode: WriteWithoutComments


#######################################################################
# +-----------------------------------------------------------------+ #
# |                          Main settings                          | #
# +-----------------------------------------------------------------+ #
#######################################################################

Tree: true

Frequency: 5

Rarity: 10.0

MaxSpawn: 0

RotateRandomly: true

SpawnHeight: highestSolidBlock

SpawnHeightOffset: -18

SpawnHeightVariance: 0

##############################
# Height Limits for the BO3. #
##############################

MinHeight: 100

MaxHeight: 255

######################
# Extrusion settings #
######################

ExtrudeMode: None

ExtrudeThroughBlocks: otg:air

MaxBranchDepth: 10


#######################################################################
# +-----------------------------------------------------------------+ #
# |                      Source block settings                      | #
# +-----------------------------------------------------------------+ #
#######################################################################

SourceBlocks: otg:air

MaxPercentageOutsideSourceBlock: 100

OutsideSourceBlock: dontPlace

DoReplaceBlocks: true

IsOTGPlus: false


#######################################################################
# +-----------------------------------------------------------------+ #
# |                              Blocks                             | #
# +-----------------------------------------------------------------+ #
#######################################################################

B(-14,13,0,minecraft:dirt)
B(-14,14,-3,minecraft:grass_block)
B(-14,14,-2,minecraft:grass_block)
B(-14,14,-1,minecraft:dirt)
B(-14,14,0,minecraft:grass_block)
B(-14,15,-1,minecraft:grass_block)
B(-13,12,0,minecraft:dirt)
B(-13,12,2,minecraft:dirt)
B(-13,13,-3,minecraft:dirt)
B(-13,13,-2,minecraft:dirt)
B(-13,13,-1,minecraft:dirt)
B(-13,13,0,minecraft:dirt)
B(-13,13,1,minecraft:dirt)
B(-13,13,2,minecraft:dirt)
B(-13,13,3,minecraft:dirt)
B(-13,13,4,minecraft:dirt)
B(-13,14,-4,minecraft:grass_block)
B(-13,14,-3,minecraft:dirt)
B(-13,14,-2,minecraft:dirt)
B(-13,14,-1,minecraft:dirt)
B(-13,14,0,minecraft:dirt)
B(-13,14,1,minecraft:dirt)
B(-13,14,2,minecraft:grass_block)
B(-13,14,3,minecraft:grass_block)
B(-13,14,4,minecraft:grass_block)
B(-13,14,5,minecraft:dirt)
B(-13,14,6,minecraft:grass_block)
B(-13,15,-3,minecraft:grass_block)
B(-13,15,-2,minecraft:grass_block)
B(-13,15,-1,minecraft:grass_block)
B(-13,15,0,minecraft:grass_block)
B(-13,15,1,minecraft:grass_block)
B(-13,15,5,minecraft:grass_block)
B(-12,12,-2,minecraft:dirt)
B(-12,12,-1,minecraft:dirt)
B(-12,12,0,minecraft:dirt)
B(-12,12,1,minecraft:dirt)
B(-12,12,2,minecraft:dirt)
B(-12,12,3,minecraft:dirt)
B(-12,12,4,minecraft:dirt)
B(-12,13,-4,minecraft:dirt)
B(-12,13,-3,minecraft:dirt)
B(-12,13,-2,minecraft:dirt)
B(-12,13,-1,minecraft:dirt)
B(-12,13,0,minecraft:dirt)
B(-12,13,1,minecraft:dirt)
B(-12,13,2,minecraft:dirt)
B(-12,13,3,minecraft:dirt)
B(-12,13,4,minecraft:dirt)
B(-12,13,5,minecraft:dirt)
B(-12,13,6,minecraft:dirt)
B(-12,14,-5,minecraft:grass_block)
B(-12,14,-4,minecraft:dirt)
B(-12,14,-3,minecraft:dirt)
B(-12,14,-2,minecraft:dirt)
B(-12,14,-1,minecraft:dirt)
B(-12,14,0,minecraft:dirt)
B(-12,14,1,minecraft:dirt)
B(-12,14,2,minecraft:dirt)
B(-12,14,3,minecraft:dirt)
B(-12,14,4,minecraft:dirt)
B(-12,14,5,minecraft:dirt)
B(-12,14,6,minecraft:dirt)
B(-12,14,7,minecraft:grass_block)
B(-12,15,-4,minecraft:grass_block)
B(-12,15,-3,minecraft:grass_block)
B(-12,15,-2,minecraft:grass_block)
B(-12,15,-1,minecraft:grass_block)
B(-12,15,0,minecraft:grass_block)
B(-12,15,1,minecraft:grass_block)
B(-12,15,2,minecraft:grass_block)
B(-12,15,3,minecraft:grass_block)
B(-12,15,4,minecraft:grass_block)
B(-12,15,5,minecraft:grass_block)
B(-12,15,6,minecraft:grass_block)
B(-11,11,-1,minecraft:stone)
B(-11,11,0,minecraft:stone)
B(-11,11,1,minecraft:stone)
B(-11,11,2,minecraft:stone)
B(-11,11,3,minecraft:stone)
B(-11,11,4,minecraft:stone)
B(-11,12,-4,minecraft:dirt)
B(-11,12,-3,minecraft:dirt)
B(-11,12,-2,minecraft:dirt)
B(-11,12,-1,minecraft:dirt)
B(-11,12,0,minecraft:dirt)
B(-11,12,1,minecraft:dirt)
B(-11,12,2,minecraft:dirt)
B(-11,12,3,minecraft:dirt)
B(-11,12,4,minecraft:dirt)
B(-11,12,5,minecraft:dirt)
B(-11,13,-5,minecraft:dirt)
B(-11,13,-4,minecraft:dirt)
B(-11,13,-3,minecraft:dirt)
B(-11,13,-2,minecraft:dirt)
B(-11,13,-1,minecraft:dirt)
B(-11,13,0,minecraft:dirt)
B(-11,13,1,minecraft:dirt)
B(-11,13,2,minecraft:dirt)
B(-11,13,3,minecraft:dirt)
B(-11,13,4,minecraft:dirt)
B(-11,13,5,minecraft:dirt)
B(-11,13,6,minecraft:dirt)
B(-11,14,-6,minecraft:grass_block)
B(-11,14,-5,minecraft:dirt)
B(-11,14,-4,minecraft:dirt)
B(-11,14,-3,minecraft:dirt)
B(-11,14,-2,minecraft:dirt)
B(-11,14,-1,minecraft:dirt)
B(-11,14,0,minecraft:dirt)
B(-11,14,1,minecraft:dirt)
B(-11,14,2,minecraft:dirt)
B(-11,14,3,minecraft:dirt)
B(-11,14,4,minecraft:dirt)
B(-11,14,5,minecraft:dirt)
B(-11,14,6,minecraft:dirt)
B(-11,14,7,minecraft:grass_block)
B(-11,15,-5,minecraft:grass_block)
B(-11,15,-4,minecraft:grass_block)
B(-11,15,-3,minecraft:grass_block)
B(-11,15,-2,minecraft:grass_block)
B(-11,15,-1,minecraft:grass_block)
B(-11,15,0,minecraft:grass_block)
B(-11,15,1,minecraft:grass_block)
B(-11,15,2,minecraft:grass_block)
B(-11,15,3,minecraft:grass_block)
B(-11,15,4,minecraft:grass_block)
B(-11,15,5,minecraft:grass_block)
B(-11,15,6,minecraft:grass_block)
B(-10,10,-1,minecraft:stone)
B(-10,10,0,minecraft:stone)
B(-10,10,3,minecraft:stone)
B(-10,10,4,minecraft:stone)
B(-10,11,-3,minecraft:stone)
B(-10,11,-2,minecraft:stone)
B(-10,11,-1,minecraft:stone)
B(-10,11,0,minecraft:stone)
B(-10,11,1,minecraft:stone)
B(-10,11,2,minecraft:stone)
B(-10,11,3,minecraft:stone)
B(-10,11,4,minecraft:stone)
B(-10,11,5,minecraft:stone)
B(-10,12,-6,minecraft:dirt)
B(-10,12,-5,minecraft:dirt)
B(-10,12,-4,minecraft:dirt)
B(-10,12,-3,minecraft:stone)
B(-10,12,-2,minecraft:stone)
B(-10,12,-1,minecraft:dirt)
B(-10,12,0,minecraft:dirt)
B(-10,12,1,minecraft:dirt)
B(-10,12,2,minecraft:stone)
B(-10,12,3,minecraft:stone)
B(-10,12,4,minecraft:stone)
B(-10,12,5,minecraft:dirt)
B(-10,12,6,minecraft:dirt)
B(-10,13,-7,minecraft:dirt)
B(-10,13,-6,minecraft:dirt)
B(-10,13,-5,minecraft:dirt)
B(-10,13,-4,minecraft:dirt)
B(-10,13,-3,minecraft:dirt)
B(-10,13,-2,minecraft:dirt)
B(-10,13,-1,minecraft:dirt)
B(-10,13,0,minecraft:dirt)
B(-10,13,1,minecraft:dirt)
B(-10,13,2,minecraft:dirt)
B(-10,13,3,minecraft:dirt)
B(-10,13,4,minecraft:dirt)
B(-10,13,5,minecraft:dirt)
B(-10,13,6,minecraft:dirt)
B(-10,14,-8,minecraft:grass_block)
B(-10,14,-7,minecraft:grass_block)
B(-10,14,-6,minecraft:dirt)
B(-10,14,-5,minecraft:dirt)
B(-10,14,-4,minecraft:dirt)
B(-10,14,-3,minecraft:dirt)
B(-10,14,-2,minecraft:dirt)
B(-10,14,-1,minecraft:dirt)
B(-10,14,0,minecraft:dirt)
B(-10,14,1,minecraft:dirt)
B(-10,14,2,minecraft:dirt)
B(-10,14,3,minecraft:dirt)
B(-10,14,4,minecraft:dirt)
B(-10,14,5,minecraft:dirt)
B(-10,14,6,minecraft:dirt)
B(-10,14,7,minecraft:dirt)
B(-10,15,-6,minecraft:grass_block)
B(-10,15,-5,minecraft:grass_block)
B(-10,15,-4,minecraft:grass_block)
B(-10,15,-3,minecraft:dirt)
B(-10,15,-2,minecraft:dirt)
B(-10,15,-1,minecraft:grass_block)
B(-10,15,0,minecraft:grass_block)
B(-10,15,1,minecraft:grass_block)
B(-10,15,2,minecraft:dirt)
B(-10,15,3,minecraft:dirt)
B(-10,15,4,minecraft:dirt)
B(-10,15,5,minecraft:grass_block)
B(-10,15,6,minecraft:grass_block)
B(-10,15,7,minecraft:grass_block)
B(-10,16,-3,minecraft:grass_block)
B(-10,16,-2,minecraft:grass_block)
B(-10,16,2,minecraft:grass_block)
B(-10,16,3,minecraft:grass_block)
B(-10,16,4,minecraft:grass_block)
B(-9,9,-1,minecraft:stone)
B(-9,9,0,minecraft:stone)
B(-9,9,1,minecraft:stone)
B(-9,9,2,minecraft:stone)
B(-9,9,3,minecraft:stone)
B(-9,9,4,minecraft:stone)
B(-9,10,-3,minecraft:stone)
B(-9,10,-2,minecraft:stone)
B(-9,10,-1,minecraft:stone)
B(-9,10,0,minecraft:stone)
B(-9,10,1,minecraft:stone)
B(-9,10,2,minecraft:stone)
B(-9,10,3,minecraft:stone)
B(-9,10,4,minecraft:stone)
B(-9,10,5,minecraft:stone)
B(-9,11,-5,minecraft:stone)
B(-9,11,-4,minecraft:stone)
B(-9,11,-3,minecraft:stone)
B(-9,11,-2,minecraft:stone)
B(-9,11,-1,minecraft:stone)
B(-9,11,0,minecraft:stone)
B(-9,11,1,minecraft:stone)
B(-9,11,2,minecraft:stone)
B(-9,11,3,minecraft:stone)
B(-9,11,4,minecraft:stone)
B(-9,11,5,minecraft:stone)
B(-9,12,-9,minecraft:dirt)
B(-9,12,-8,minecraft:dirt)
B(-9,12,-7,minecraft:dirt)
B(-9,12,-6,minecraft:dirt)
B(-9,12,-5,minecraft:dirt)
B(-9,12,-4,minecraft:stone)
B(-9,12,-3,minecraft:stone)
B(-9,12,-2,minecraft:stone)
B(-9,12,-1,minecraft:stone)
B(-9,12,0,minecraft:stone)
B(-9,12,1,minecraft:stone)
B(-9,12,2,minecraft:stone)
B(-9,12,3,minecraft:stone)
B(-9,12,4,minecraft:stone)
B(-9,12,5,minecraft:stone)
B(-9,12,6,minecraft:dirt)
B(-9,13,-10,minecraft:dirt)
B(-9,13,-9,minecraft:dirt)
B(-9,13,-8,minecraft:dirt)
B(-9,13,-7,minecraft:dirt)
B(-9,13,-6,minecraft:dirt)
B(-9,13,-5,minecraft:dirt)
B(-9,13,-4,minecraft:dirt)
B(-9,13,-3,minecraft:dirt)
B(-9,13,-2,minecraft:dirt)
B(-9,13,-1,minecraft:dirt)
B(-9,13,0,minecraft:dirt)
B(-9,13,1,minecraft:dirt)
B(-9,13,2,minecraft:dirt)
B(-9,13,3,minecraft:dirt)
B(-9,13,4,minecraft:dirt)
B(-9,13,5,minecraft:dirt)
B(-9,13,6,minecraft:dirt)
B(-9,13,7,minecraft:dirt)
B(-9,14,-10,minecraft:grass_block)
B(-9,14,-9,minecraft:grass_block)
B(-9,14,-8,minecraft:dirt)
B(-9,14,-7,minecraft:dirt)
B(-9,14,-6,minecraft:dirt)
B(-9,14,-5,minecraft:dirt)
B(-9,14,-4,minecraft:dirt)
B(-9,14,-3,minecraft:dirt)
B(-9,14,-2,minecraft:dirt)
B(-9,14,-1,minecraft:dirt)
B(-9,14,0,minecraft:dirt)
B(-9,14,1,minecraft:dirt)
B(-9,14,2,minecraft:dirt)
B(-9,14,3,minecraft:dirt)
B(-9,14,4,minecraft:dirt)
B(-9,14,5,minecraft:dirt)
B(-9,14,6,minecraft:dirt)
B(-9,14,7,minecraft:dirt)
B(-9,15,-8,minecraft:grass_block)
B(-9,15,-7,minecraft:grass_block)
B(-9,15,-6,minecraft:grass_block)
B(-9,15,-5,minecraft:grass_block)
B(-9,15,-4,minecraft:dirt)
B(-9,15,-3,minecraft:dirt)
B(-9,15,-2,minecraft:dirt)
B(-9,15,-1,minecraft:dirt)
B(-9,15,0,minecraft:dirt)
B(-9,15,1,minecraft:dirt)
B(-9,15,2,minecraft:dirt)
B(-9,15,3,minecraft:dirt)
B(-9,15,4,minecraft:dirt)
B(-9,15,5,minecraft:dirt)
B(-9,15,6,minecraft:grass_block)
B(-9,15,7,minecraft:grass_block)
B(-9,16,-4,minecraft:grass_block)
B(-9,16,-3,minecraft:grass_block)
B(-9,16,-2,minecraft:grass_block)
B(-9,16,-1,minecraft:grass_block)
B(-9,16,0,minecraft:grass_block)
B(-9,16,1,minecraft:grass_block)
B(-9,16,2,minecraft:grass_block)
B(-9,16,3,minecraft:grass_block)
B(-9,16,4,minecraft:grass_block)
B(-9,16,5,minecraft:grass_block)
B(-8,7,2,minecraft:stone)
B(-8,7,3,minecraft:stone)
B(-8,8,-1,minecraft:stone)
B(-8,8,0,minecraft:stone)
B(-8,8,1,minecraft:stone)
B(-8,8,2,minecraft:stone)
B(-8,8,3,minecraft:stone)
B(-8,8,4,minecraft:stone)
B(-8,9,-3,minecraft:stone)
B(-8,9,-2,minecraft:stone)
B(-8,9,-1,minecraft:stone)
B(-8,9,0,minecraft:stone)
B(-8,9,1,minecraft:stone)
B(-8,9,2,minecraft:stone)
B(-8,9,3,minecraft:stone)
B(-8,9,4,minecraft:stone)
B(-8,9,5,minecraft:stone)
B(-8,10,-4,minecraft:stone)
B(-8,10,-3,minecraft:stone)
B(-8,10,-2,minecraft:stone)
B(-8,10,-1,minecraft:stone)
B(-8,10,0,minecraft:stone)
B(-8,10,1,minecraft:stone)
B(-8,10,2,minecraft:stone)
B(-8,10,3,minecraft:stone)
B(-8,10,4,minecraft:stone)
B(-8,10,5,minecraft:stone)
B(-8,11,-9,minecraft:stone)
B(-8,11,-8,minecraft:stone)
B(-8,11,-7,minecraft:stone)
B(-8,11,-6,minecraft:stone)
B(-8,11,-5,minecraft:stone)
B(-8,11,-4,minecraft:stone)
B(-8,11,-3,minecraft:stone)
B(-8,11,-2,minecraft:stone)
B(-8,11,-1,minecraft:stone)
B(-8,11,0,minecraft:stone)
B(-8,11,1,minecraft:stone)
B(-8,11,2,minecraft:stone)
B(-8,11,3,minecraft:stone)
B(-8,11,4,minecraft:stone)
B(-8,11,5,minecraft:stone)
B(-8,11,6,minecraft:stone)
B(-8,12,-10,minecraft:dirt)
B(-8,12,-9,minecraft:dirt)
B(-8,12,-8,minecraft:dirt)
B(-8,12,-7,minecraft:stone)
B(-8,12,-6,minecraft:stone)
B(-8,12,-5,minecraft:stone)
B(-8,12,-4,minecraft:stone)
B(-8,12,-3,minecraft:stone)
B(-8,12,-2,minecraft:stone)
B(-8,12,-1,minecraft:stone)
B(-8,12,0,minecraft:stone)
B(-8,12,1,minecraft:stone)
B(-8,12,2,minecraft:stone)
B(-8,12,3,minecraft:stone)
B(-8,12,4,minecraft:stone)
B(-8,12,5,minecraft:stone)
B(-8,12,6,minecraft:stone)
B(-8,12,7,minecraft:dirt)
B(-8,13,-11,minecraft:dirt)
B(-8,13,-10,minecraft:dirt)
B(-8,13,-9,minecraft:dirt)
B(-8,13,-8,minecraft:dirt)
B(-8,13,-7,minecraft:dirt)
B(-8,13,-6,minecraft:dirt)
B(-8,13,-5,minecraft:dirt)
B(-8,13,-4,minecraft:dirt)
B(-8,13,-3,minecraft:dirt)
B(-8,13,-2,minecraft:dirt)
B(-8,13,-1,minecraft:dirt)
B(-8,13,0,minecraft:dirt)
B(-8,13,1,minecraft:dirt)
B(-8,13,2,minecraft:stone)
B(-8,13,3,minecraft:stone)
B(-8,13,4,minecraft:dirt)
B(-8,13,5,minecraft:dirt)
B(-8,13,6,minecraft:dirt)
B(-8,13,7,minecraft:dirt)
B(-8,14,-11,minecraft:grass_block)
B(-8,14,-10,minecraft:dirt)
B(-8,14,-9,minecraft:dirt)
B(-8,14,-8,minecraft:dirt)
B(-8,14,-7,minecraft:dirt)
B(-8,14,-6,minecraft:dirt)
B(-8,14,-5,minecraft:dirt)
B(-8,14,-4,minecraft:dirt)
B(-8,14,-3,minecraft:dirt)
B(-8,14,-2,minecraft:dirt)
B(-8,14,-1,minecraft:dirt)
B(-8,14,0,minecraft:dirt)
B(-8,14,1,minecraft:dirt)
B(-8,14,2,minecraft:dirt)
B(-8,14,3,minecraft:dirt)
B(-8,14,4,minecraft:dirt)
B(-8,14,5,minecraft:dirt)
B(-8,14,6,minecraft:dirt)
B(-8,14,7,minecraft:dirt)
B(-8,14,8,minecraft:dirt)
B(-8,15,-10,minecraft:grass_block)
B(-8,15,-9,minecraft:grass_block)
B(-8,15,-8,minecraft:grass_block)
B(-8,15,-7,minecraft:dirt)
B(-8,15,-6,minecraft:dirt)
B(-8,15,-5,minecraft:dirt)
B(-8,15,-4,minecraft:dirt)
B(-8,15,-3,minecraft:dirt)
B(-8,15,-2,minecraft:dirt)
B(-8,15,-1,minecraft:dirt)
B(-8,15,0,minecraft:dirt)
B(-8,15,1,minecraft:dirt)
B(-8,15,2,minecraft:dirt)
B(-8,15,3,minecraft:dirt)
B(-8,15,4,minecraft:dirt)
B(-8,15,5,minecraft:dirt)
B(-8,15,6,minecraft:dirt)
B(-8,15,7,minecraft:grass_block)
B(-8,15,8,minecraft:grass_block)
B(-8,16,-7,minecraft:grass_block)
B(-8,16,-6,minecraft:grass_block)
B(-8,16,-5,minecraft:grass_block)
B(-8,16,-4,minecraft:grass_block)
B(-8,16,-3,minecraft:grass_block)
B(-8,16,-2,minecraft:grass_block)
B(-8,16,-1,minecraft:grass_block)
B(-8,16,0,minecraft:grass_block)
B(-8,16,1,minecraft:grass_block)
B(-8,16,2,minecraft:dirt)
B(-8,16,3,minecraft:dirt)
B(-8,16,4,minecraft:grass_block)
B(-8,16,5,minecraft:grass_block)
B(-8,16,6,minecraft:grass_block)
B(-8,17,2,minecraft:grass_block)
B(-8,17,3,minecraft:grass_block)
B(-7,6,1,minecraft:stone)
B(-7,6,2,minecraft:stone)
B(-7,6,3,minecraft:stone)
B(-7,6,4,minecraft:stone)
B(-7,7,-2,minecraft:stone)
B(-7,7,-1,minecraft:stone)
B(-7,7,0,minecraft:stone)
B(-7,7,1,minecraft:stone)
B(-7,7,2,minecraft:stone)
B(-7,7,3,minecraft:stone)
B(-7,7,4,minecraft:stone)
B(-7,8,-3,minecraft:stone)
B(-7,8,-2,minecraft:stone)
B(-7,8,-1,minecraft:stone)
B(-7,8,0,minecraft:stone)
B(-7,8,1,minecraft:stone)
B(-7,8,2,minecraft:stone)
B(-7,8,3,minecraft:stone)
B(-7,8,4,minecraft:stone)
B(-7,8,5,minecraft:stone)
B(-7,9,-4,minecraft:stone)
B(-7,9,-3,minecraft:stone)
B(-7,9,-2,minecraft:stone)
B(-7,9,-1,minecraft:stone)
B(-7,9,0,minecraft:stone)
B(-7,9,1,minecraft:stone)
B(-7,9,2,minecraft:stone)
B(-7,9,3,minecraft:stone)
B(-7,9,4,minecraft:stone)
B(-7,9,5,minecraft:stone)
B(-7,10,-8,minecraft:stone)
B(-7,10,-7,minecraft:stone)
B(-7,10,-6,minecraft:stone)
B(-7,10,-5,minecraft:stone)
B(-7,10,-4,minecraft:stone)
B(-7,10,-3,minecraft:stone)
B(-7,10,-2,minecraft:stone)
B(-7,10,-1,minecraft:stone)
B(-7,10,0,minecraft:stone)
B(-7,10,1,minecraft:stone)
B(-7,10,2,minecraft:stone)
B(-7,10,3,minecraft:stone)
B(-7,10,4,minecraft:stone)
B(-7,10,5,minecraft:stone)
B(-7,10,6,minecraft:stone)
B(-7,11,-12,minecraft:dirt)
B(-7,11,-9,minecraft:stone)
B(-7,11,-8,minecraft:stone)
B(-7,11,-7,minecraft:stone)
B(-7,11,-6,minecraft:stone)
B(-7,11,-5,minecraft:stone)
B(-7,11,-4,minecraft:stone)
B(-7,11,-3,minecraft:stone)
B(-7,11,-2,minecraft:stone)
B(-7,11,-1,minecraft:stone)
B(-7,11,0,minecraft:stone)
B(-7,11,1,minecraft:stone)
B(-7,11,2,minecraft:stone)
B(-7,11,3,minecraft:stone)
B(-7,11,4,minecraft:stone)
B(-7,11,5,minecraft:stone)
B(-7,11,6,minecraft:stone)
B(-7,11,7,minecraft:stone)
B(-7,12,-12,minecraft:dirt)
B(-7,12,-11,minecraft:dirt)
B(-7,12,-10,minecraft:dirt)
B(-7,12,-9,minecraft:stone)
B(-7,12,-8,minecraft:stone)
B(-7,12,-7,minecraft:stone)
B(-7,12,-6,minecraft:stone)
B(-7,12,-5,minecraft:stone)
B(-7,12,-4,minecraft:stone)
B(-7,12,-3,minecraft:stone)
B(-7,12,-2,minecraft:stone)
B(-7,12,-1,minecraft:stone)
B(-7,12,0,minecraft:stone)
B(-7,12,1,minecraft:stone)
B(-7,12,2,minecraft:stone)
B(-7,12,3,minecraft:stone)
B(-7,12,4,minecraft:stone)
B(-7,12,5,minecraft:stone)
B(-7,12,6,minecraft:stone)
B(-7,12,7,minecraft:dirt)
B(-7,12,8,minecraft:dirt)
B(-7,13,-12,minecraft:dirt)
B(-7,13,-11,minecraft:dirt)
B(-7,13,-10,minecraft:dirt)
B(-7,13,-9,minecraft:dirt)
B(-7,13,-8,minecraft:dirt)
B(-7,13,-7,minecraft:stone)
B(-7,13,-6,minecraft:stone)
B(-7,13,-5,minecraft:stone)
B(-7,13,-4,minecraft:stone)
B(-7,13,-3,minecraft:stone)
B(-7,13,-2,minecraft:stone)
B(-7,13,-1,minecraft:stone)
B(-7,13,0,minecraft:stone)
B(-7,13,1,minecraft:stone)
B(-7,13,2,minecraft:stone)
B(-7,13,3,minecraft:stone)
B(-7,13,4,minecraft:stone)
B(-7,13,5,minecraft:dirt)
B(-7,13,6,minecraft:dirt)
B(-7,13,7,minecraft:dirt)
B(-7,13,8,minecraft:dirt)
B(-7,14,-12,minecraft:grass_block)
B(-7,14,-11,minecraft:dirt)
B(-7,14,-10,minecraft:dirt)
B(-7,14,-9,minecraft:dirt)
B(-7,14,-8,minecraft:dirt)
B(-7,14,-7,minecraft:dirt)
B(-7,14,-6,minecraft:dirt)
B(-7,14,-5,minecraft:dirt)
B(-7,14,-4,minecraft:dirt)
B(-7,14,-3,minecraft:dirt)
B(-7,14,-2,minecraft:dirt)
B(-7,14,-1,minecraft:dirt)
B(-7,14,0,minecraft:dirt)
B(-7,14,1,minecraft:dirt)
B(-7,14,2,minecraft:dirt)
B(-7,14,3,minecraft:dirt)
B(-7,14,4,minecraft:dirt)
B(-7,14,5,minecraft:dirt)
B(-7,14,6,minecraft:dirt)
B(-7,14,7,minecraft:dirt)
B(-7,14,8,minecraft:dirt)
B(-7,14,9,minecraft:grass_block)
B(-7,15,-11,minecraft:grass_block)
B(-7,15,-10,minecraft:grass_block)
B(-7,15,-9,minecraft:dirt)
B(-7,15,-8,minecraft:dirt)
B(-7,15,-7,minecraft:dirt)
B(-7,15,-6,minecraft:dirt)
B(-7,15,-5,minecraft:dirt)
B(-7,15,-4,minecraft:dirt)
B(-7,15,-3,minecraft:dirt)
B(-7,15,-2,minecraft:dirt)
B(-7,15,-1,minecraft:dirt)
B(-7,15,0,minecraft:dirt)
B(-7,15,1,minecraft:dirt)
B(-7,15,2,minecraft:dirt)
B(-7,15,3,minecraft:dirt)
B(-7,15,4,minecraft:dirt)
B(-7,15,5,minecraft:dirt)
B(-7,15,6,minecraft:dirt)
B(-7,15,7,minecraft:grass_block)
B(-7,15,8,minecraft:grass_block)
B(-7,16,-9,minecraft:grass_block)
B(-7,16,-8,minecraft:grass_block)
B(-7,16,-7,minecraft:dirt)
B(-7,16,-6,minecraft:dirt)
B(-7,16,-5,minecraft:dirt)
B(-7,16,-4,minecraft:dirt)
B(-7,16,-3,minecraft:dirt)
B(-7,16,-2,minecraft:dirt)
B(-7,16,-1,minecraft:dirt)
B(-7,16,0,minecraft:dirt)
B(-7,16,1,minecraft:dirt)
B(-7,16,2,minecraft:dirt)
B(-7,16,3,minecraft:dirt)
B(-7,16,4,minecraft:dirt)
B(-7,16,5,minecraft:grass_block)
B(-7,16,6,minecraft:grass_block)
B(-7,17,-7,minecraft:grass_block)
B(-7,17,-6,minecraft:grass_block)
B(-7,17,-5,minecraft:grass_block)
B(-7,17,-4,minecraft:grass_block)
B(-7,17,-3,minecraft:grass_block)
B(-7,17,-2,minecraft:grass_block)
B(-7,17,-1,minecraft:grass_block)
B(-7,17,0,minecraft:grass_block)
B(-7,17,1,minecraft:grass_block)
B(-7,17,2,minecraft:grass_block)
B(-7,17,3,minecraft:grass_block)
B(-7,17,4,minecraft:grass_block)
B(-6,4,3,minecraft:stone)
B(-6,4,4,minecraft:stone)
B(-6,5,0,minecraft:stone)
B(-6,5,1,minecraft:stone)
B(-6,5,2,minecraft:stone)
B(-6,5,3,minecraft:stone)
B(-6,5,4,minecraft:stone)
B(-6,6,-3,minecraft:stone)
B(-6,6,-2,minecraft:stone)
B(-6,6,-1,minecraft:stone)
B(-6,6,0,minecraft:stone)
B(-6,6,1,minecraft:stone)
B(-6,6,2,minecraft:stone)
B(-6,6,3,minecraft:stone)
B(-6,6,4,minecraft:stone)
B(-6,6,5,minecraft:stone)
B(-6,7,-4,minecraft:stone)
B(-6,7,-3,minecraft:stone)
B(-6,7,-2,minecraft:stone)
B(-6,7,-1,minecraft:stone)
B(-6,7,0,minecraft:stone)
B(-6,7,1,minecraft:stone)
B(-6,7,2,minecraft:stone)
B(-6,7,3,minecraft:stone)
B(-6,7,4,minecraft:stone)
B(-6,7,5,minecraft:stone)
B(-6,8,-5,minecraft:stone)
B(-6,8,-4,minecraft:stone)
B(-6,8,-3,minecraft:stone)
B(-6,8,-2,minecraft:stone)
B(-6,8,-1,minecraft:stone)
B(-6,8,0,minecraft:stone)
B(-6,8,1,minecraft:stone)
B(-6,8,2,minecraft:stone)
B(-6,8,3,minecraft:stone)
B(-6,8,4,minecraft:stone)
B(-6,8,5,minecraft:stone)
B(-6,8,6,minecraft:stone)
B(-6,9,-8,minecraft:stone)
B(-6,9,-7,minecraft:stone)
B(-6,9,-6,minecraft:stone)
B(-6,9,-5,minecraft:stone)
B(-6,9,-4,minecraft:stone)
B(-6,9,-3,minecraft:stone)
B(-6,9,-2,minecraft:stone)
B(-6,9,-1,minecraft:stone)
B(-6,9,0,minecraft:stone)
B(-6,9,1,minecraft:stone)
B(-6,9,2,minecraft:stone)
B(-6,9,3,minecraft:stone)
B(-6,9,4,minecraft:stone)
B(-6,9,5,minecraft:stone)
B(-6,9,6,minecraft:stone)
B(-6,10,-9,minecraft:stone)
B(-6,10,-8,minecraft:stone)
B(-6,10,-7,minecraft:stone)
B(-6,10,-6,minecraft:stone)
B(-6,10,-5,minecraft:stone)
B(-6,10,-4,minecraft:stone)
B(-6,10,-3,minecraft:stone)
B(-6,10,-2,minecraft:stone)
B(-6,10,-1,minecraft:stone)
B(-6,10,0,minecraft:stone)
B(-6,10,1,minecraft:stone)
B(-6,10,2,minecraft:stone)
B(-6,10,3,minecraft:stone)
B(-6,10,4,minecraft:stone)
B(-6,10,5,minecraft:stone)
B(-6,10,6,minecraft:stone)
B(-6,10,7,minecraft:stone)
B(-6,11,-12,minecraft:stone)
B(-6,11,-10,minecraft:stone)
B(-6,11,-9,minecraft:stone)
B(-6,11,-8,minecraft:stone)
B(-6,11,-7,minecraft:stone)
B(-6,11,-6,minecraft:stone)
B(-6,11,-5,minecraft:stone)
B(-6,11,-4,minecraft:stone)
B(-6,11,-3,minecraft:stone)
B(-6,11,-2,minecraft:stone)
B(-6,11,-1,minecraft:stone)
B(-6,11,0,minecraft:stone)
B(-6,11,1,minecraft:stone)
B(-6,11,2,minecraft:stone)
B(-6,11,3,minecraft:stone)
B(-6,11,4,minecraft:stone)
B(-6,11,5,minecraft:stone)
B(-6,11,6,minecraft:stone)
B(-6,11,7,minecraft:stone)
B(-6,11,8,minecraft:stone)
B(-6,12,-13,minecraft:dirt)
B(-6,12,-12,minecraft:dirt)
B(-6,12,-11,minecraft:dirt)
B(-6,12,-10,minecraft:stone)
B(-6,12,-9,minecraft:stone)
B(-6,12,-8,minecraft:stone)
B(-6,12,-7,minecraft:stone)
B(-6,12,-6,minecraft:stone)
B(-6,12,-5,minecraft:stone)
B(-6,12,-4,minecraft:stone)
B(-6,12,-3,minecraft:stone)
B(-6,12,-2,minecraft:stone)
B(-6,12,-1,minecraft:stone)
B(-6,12,0,minecraft:stone)
B(-6,12,1,minecraft:stone)
B(-6,12,2,minecraft:stone)
B(-6,12,3,minecraft:stone)
B(-6,12,4,minecraft:stone)
B(-6,12,5,minecraft:stone)
B(-6,12,6,minecraft:stone)
B(-6,12,7,minecraft:dirt)
B(-6,12,8,minecraft:dirt)
B(-6,13,-13,minecraft:dirt)
B(-6,13,-12,minecraft:dirt)
B(-6,13,-11,minecraft:dirt)
B(-6,13,-10,minecraft:dirt)
B(-6,13,-9,minecraft:stone)
B(-6,13,-8,minecraft:stone)
B(-6,13,-7,minecraft:stone)
B(-6,13,-6,minecraft:stone)
B(-6,13,-5,minecraft:stone)
B(-6,13,-4,minecraft:stone)
B(-6,13,-3,minecraft:stone)
B(-6,13,-2,minecraft:stone)
B(-6,13,-1,minecraft:stone)
B(-6,13,0,minecraft:stone)
B(-6,13,1,minecraft:stone)
B(-6,13,2,minecraft:stone)
B(-6,13,3,minecraft:stone)
B(-6,13,4,minecraft:stone)
B(-6,13,5,minecraft:dirt)
B(-6,13,6,minecraft:dirt)
B(-6,13,7,minecraft:dirt)
B(-6,13,8,minecraft:dirt)
B(-6,13,9,minecraft:dirt)
B(-6,14,-13,minecraft:grass_block)
B(-6,14,-12,minecraft:dirt)
B(-6,14,-11,minecraft:dirt)
B(-6,14,-10,minecraft:dirt)
B(-6,14,-9,minecraft:dirt)
B(-6,14,-8,minecraft:dirt)
B(-6,14,-7,minecraft:stone)
B(-6,14,-6,minecraft:stone)
B(-6,14,-5,minecraft:stone)
B(-6,14,-4,minecraft:stone)
B(-6,14,-3,minecraft:stone)
B(-6,14,-2,minecraft:dirt)
B(-6,14,-1,minecraft:dirt)
B(-6,14,0,minecraft:dirt)
B(-6,14,1,minecraft:dirt)
B(-6,14,2,minecraft:dirt)
B(-6,14,3,minecraft:dirt)
B(-6,14,4,minecraft:dirt)
B(-6,14,5,minecraft:dirt)
B(-6,14,6,minecraft:dirt)
B(-6,14,7,minecraft:dirt)
B(-6,14,8,minecraft:dirt)
B(-6,14,9,minecraft:dirt)
B(-6,15,-12,minecraft:grass_block)
B(-6,15,-11,minecraft:grass_block)
B(-6,15,-10,minecraft:dirt)
B(-6,15,-9,minecraft:dirt)
B(-6,15,-8,minecraft:dirt)
B(-6,15,-7,minecraft:dirt)
B(-6,15,-6,minecraft:dirt)
B(-6,15,-5,minecraft:dirt)
B(-6,15,-4,minecraft:dirt)
B(-6,15,-3,minecraft:dirt)
B(-6,15,-2,minecraft:dirt)
B(-6,15,-1,minecraft:dirt)
B(-6,15,0,minecraft:dirt)
B(-6,15,1,minecraft:dirt)
B(-6,15,2,minecraft:dirt)
B(-6,15,3,minecraft:dirt)
B(-6,15,4,minecraft:dirt)
B(-6,15,5,minecraft:dirt)
B(-6,15,6,minecraft:dirt)
B(-6,15,7,minecraft:grass_block)
B(-6,15,8,minecraft:grass_block)
B(-6,15,9,minecraft:grass_block)
B(-6,16,-10,minecraft:grass_block)
B(-6,16,-9,minecraft:dirt)
B(-6,16,-8,minecraft:dirt)
B(-6,16,-7,minecraft:dirt)
B(-6,16,-6,minecraft:dirt)
B(-6,16,-5,minecraft:dirt)
B(-6,16,-4,minecraft:dirt)
B(-6,16,-3,minecraft:dirt)
B(-6,16,-2,minecraft:dirt)
B(-6,16,-1,minecraft:dirt)
B(-6,16,0,minecraft:dirt)
B(-6,16,1,minecraft:dirt)
B(-6,16,2,minecraft:dirt)
B(-6,16,3,minecraft:dirt)
B(-6,16,4,minecraft:dirt)
B(-6,16,5,minecraft:grass_block)
B(-6,16,6,minecraft:grass_block)
B(-6,17,-9,minecraft:grass_block)
B(-6,17,-8,minecraft:grass_block)
B(-6,17,-7,minecraft:dirt)
B(-6,17,-6,minecraft:dirt)
B(-6,17,-5,minecraft:dirt)
B(-6,17,-4,minecraft:dirt)
B(-6,17,-3,minecraft:dirt)
B(-6,17,-2,minecraft:grass_block)
B(-6,17,-1,minecraft:grass_block)
B(-6,17,0,minecraft:grass_block)
B(-6,17,1,minecraft:grass_block)
B(-6,17,2,minecraft:grass_block)
B(-6,17,3,minecraft:grass_block)
B(-6,17,4,minecraft:grass_block)
B(-6,18,-7,minecraft:grass_block)
B(-6,18,-6,minecraft:grass_block)
B(-6,18,-5,minecraft:grass_block)
B(-6,18,-4,minecraft:grass_block)
B(-6,18,-3,minecraft:grass_block)
B(-5,3,3,minecraft:stone)
B(-5,3,4,minecraft:stone)
B(-5,4,-1,minecraft:stone)
B(-5,4,0,minecraft:stone)
B(-5,4,1,minecraft:stone)
B(-5,4,2,minecraft:stone)
B(-5,4,3,minecraft:stone)
B(-5,4,4,minecraft:stone)
B(-5,4,5,minecraft:stone)
B(-5,5,-3,minecraft:stone)
B(-5,5,-2,minecraft:stone)
B(-5,5,-1,minecraft:stone)
B(-5,5,0,minecraft:stone)
B(-5,5,1,minecraft:stone)
B(-5,5,2,minecraft:stone)
B(-5,5,3,minecraft:stone)
B(-5,5,4,minecraft:stone)
B(-5,5,5,minecraft:stone)
B(-5,6,-4,minecraft:stone)
B(-5,6,-3,minecraft:stone)
B(-5,6,-2,minecraft:stone)
B(-5,6,-1,minecraft:stone)
B(-5,6,0,minecraft:stone)
B(-5,6,1,minecraft:stone)
B(-5,6,2,minecraft:stone)
B(-5,6,3,minecraft:stone)
B(-5,6,4,minecraft:stone)
B(-5,6,5,minecraft:stone)
B(-5,7,-8,minecraft:stone)
B(-5,7,-7,minecraft:stone)
B(-5,7,-6,minecraft:stone)
B(-5,7,-5,minecraft:stone)
B(-5,7,-4,minecraft:stone)
B(-5,7,-3,minecraft:stone)
B(-5,7,-2,minecraft:stone)
B(-5,7,-1,minecraft:stone)
B(-5,7,0,minecraft:stone)
B(-5,7,1,minecraft:stone)
B(-5,7,2,minecraft:stone)
B(-5,7,3,minecraft:stone)
B(-5,7,4,minecraft:stone)
B(-5,7,5,minecraft:stone)
B(-5,7,6,minecraft:stone)
B(-5,8,-9,minecraft:stone)
B(-5,8,-8,minecraft:stone)
B(-5,8,-7,minecraft:stone)
B(-5,8,-6,minecraft:stone)
B(-5,8,-5,minecraft:stone)
B(-5,8,-4,minecraft:stone)
B(-5,8,-3,minecraft:stone)
B(-5,8,-2,minecraft:stone)
B(-5,8,-1,minecraft:stone)
B(-5,8,0,minecraft:stone)
B(-5,8,1,minecraft:stone)
B(-5,8,2,minecraft:stone)
B(-5,8,3,minecraft:stone)
B(-5,8,4,minecraft:stone)
B(-5,8,5,minecraft:stone)
B(-5,8,6,minecraft:stone)
B(-5,9,-9,minecraft:stone)
B(-5,9,-8,minecraft:stone)
B(-5,9,-7,minecraft:stone)
B(-5,9,-6,minecraft:stone)
B(-5,9,-5,minecraft:stone)
B(-5,9,-4,minecraft:stone)
B(-5,9,-3,minecraft:stone)
B(-5,9,-2,minecraft:stone)
B(-5,9,-1,minecraft:stone)
B(-5,9,0,minecraft:stone)
B(-5,9,1,minecraft:stone)
B(-5,9,2,minecraft:stone)
B(-5,9,3,minecraft:stone)
B(-5,9,4,minecraft:stone)
B(-5,9,5,minecraft:stone)
B(-5,9,6,minecraft:stone)
B(-5,9,7,minecraft:stone)
B(-5,10,-12,minecraft:stone)
B(-5,10,-11,minecraft:stone)
B(-5,10,-10,minecraft:stone)
B(-5,10,-9,minecraft:stone)
B(-5,10,-8,minecraft:stone)
B(-5,10,-7,minecraft:stone)
B(-5,10,-6,minecraft:stone)
B(-5,10,-5,minecraft:stone)
B(-5,10,-4,minecraft:stone)
B(-5,10,-3,minecraft:stone)
B(-5,10,-2,minecraft:stone)
B(-5,10,-1,minecraft:stone)
B(-5,10,0,minecraft:stone)
B(-5,10,1,minecraft:stone)
B(-5,10,2,minecraft:stone)
B(-5,10,3,minecraft:stone)
B(-5,10,4,minecraft:stone)
B(-5,10,5,minecraft:stone)
B(-5,10,6,minecraft:stone)
B(-5,10,7,minecraft:stone)
B(-5,11,-13,minecraft:stone)
B(-5,11,-12,minecraft:stone)
B(-5,11,-11,minecraft:stone)
B(-5,11,-10,minecraft:stone)
B(-5,11,-9,minecraft:stone)
B(-5,11,-8,minecraft:stone)
B(-5,11,-7,minecraft:stone)
B(-5,11,-6,minecraft:stone)
B(-5,11,-5,minecraft:stone)
B(-5,11,-4,minecraft:stone)
B(-5,11,-3,minecraft:stone)
B(-5,11,-2,minecraft:stone)
B(-5,11,-1,minecraft:stone)
B(-5,11,0,minecraft:stone)
B(-5,11,1,minecraft:stone)
B(-5,11,2,minecraft:stone)
B(-5,11,3,minecraft:stone)
B(-5,11,4,minecraft:stone)
B(-5,11,5,minecraft:stone)
B(-5,11,6,minecraft:stone)
B(-5,11,7,minecraft:stone)
B(-5,11,8,minecraft:stone)
B(-5,12,-14,minecraft:dirt)
B(-5,12,-13,minecraft:dirt)
B(-5,12,-12,minecraft:dirt)
B(-5,12,-11,minecraft:stone)
B(-5,12,-10,minecraft:stone)
B(-5,12,-9,minecraft:stone)
B(-5,12,-8,minecraft:stone)
B(-5,12,-7,minecraft:stone)
B(-5,12,-6,minecraft:stone)
B(-5,12,-5,minecraft:stone)
B(-5,12,-4,minecraft:stone)
B(-5,12,-3,minecraft:stone)
B(-5,12,-2,minecraft:stone)
B(-5,12,-1,minecraft:stone)
B(-5,12,0,minecraft:stone)
B(-5,12,1,minecraft:stone)
B(-5,12,2,minecraft:stone)
B(-5,12,3,minecraft:stone)
B(-5,12,4,minecraft:stone)
B(-5,12,5,minecraft:stone)
B(-5,12,6,minecraft:dirt)
B(-5,12,7,minecraft:dirt)
B(-5,12,8,minecraft:dirt)
B(-5,12,9,minecraft:dirt)
B(-5,13,-14,minecraft:dirt)
B(-5,13,-13,minecraft:dirt)
B(-5,13,-12,minecraft:dirt)
B(-5,13,-11,minecraft:dirt)
B(-5,13,-10,minecraft:stone)
B(-5,13,-9,minecraft:stone)
B(-5,13,-8,minecraft:stone)
B(-5,13,-7,minecraft:stone)
B(-5,13,-6,minecraft:stone)
B(-5,13,-5,minecraft:stone)
B(-5,13,-4,minecraft:stone)
B(-5,13,-3,minecraft:stone)
B(-5,13,-2,minecraft:stone)
B(-5,13,-1,minecraft:stone)
B(-5,13,0,minecraft:stone)
B(-5,13,1,minecraft:stone)
B(-5,13,2,minecraft:stone)
B(-5,13,3,minecraft:stone)
B(-5,13,4,minecraft:dirt)
B(-5,13,5,minecraft:dirt)
B(-5,13,6,minecraft:dirt)
B(-5,13,7,minecraft:dirt)
B(-5,13,8,minecraft:dirt)
B(-5,13,9,minecraft:dirt)
B(-5,14,-14,minecraft:grass_block)
B(-5,14,-13,minecraft:dirt)
B(-5,14,-12,minecraft:dirt)
B(-5,14,-11,minecraft:dirt)
B(-5,14,-10,minecraft:dirt)
B(-5,14,-9,minecraft:dirt)
B(-5,14,-8,minecraft:stone)
B(-5,14,-7,minecraft:stone)
B(-5,14,-6,minecraft:stone)
B(-5,14,-5,minecraft:stone)
B(-5,14,-4,minecraft:stone)
B(-5,14,-3,minecraft:stone)
B(-5,14,-2,minecraft:stone)
B(-5,14,-1,minecraft:dirt)
B(-5,14,0,minecraft:dirt)
B(-5,14,1,minecraft:dirt)
B(-5,14,2,minecraft:dirt)
B(-5,14,3,minecraft:dirt)
B(-5,14,4,minecraft:dirt)
B(-5,14,5,minecraft:dirt)
B(-5,14,6,minecraft:dirt)
B(-5,14,7,minecraft:dirt)
B(-5,14,8,minecraft:dirt)
B(-5,14,9,minecraft:dirt)
B(-5,14,10,minecraft:grass_block)
B(-5,15,-13,minecraft:grass_block)
B(-5,15,-12,minecraft:grass_block)
B(-5,15,-11,minecraft:dirt)
B(-5,15,-10,minecraft:dirt)
B(-5,15,-9,minecraft:dirt)
B(-5,15,-8,minecraft:dirt)
B(-5,15,-7,minecraft:dirt)
B(-5,15,-6,minecraft:stone)
B(-5,15,-5,minecraft:stone)
B(-5,15,-4,minecraft:stone)
B(-5,15,-3,minecraft:dirt)
B(-5,15,-2,minecraft:dirt)
B(-5,15,-1,minecraft:dirt)
B(-5,15,0,minecraft:dirt)
B(-5,15,1,minecraft:dirt)
B(-5,15,2,minecraft:dirt)
B(-5,15,3,minecraft:dirt)
B(-5,15,4,minecraft:dirt)
B(-5,15,5,minecraft:dirt)
B(-5,15,6,minecraft:grass_block)
B(-5,15,7,minecraft:grass_block)
B(-5,15,8,minecraft:grass_block)
B(-5,15,9,minecraft:grass_block)
B(-5,16,-11,minecraft:grass_block)
B(-5,16,-10,minecraft:dirt)
B(-5,16,-9,minecraft:dirt)
B(-5,16,-8,minecraft:dirt)
B(-5,16,-7,minecraft:dirt)
B(-5,16,-6,minecraft:dirt)
B(-5,16,-5,minecraft:dirt)
B(-5,16,-4,minecraft:dirt)
B(-5,16,-3,minecraft:dirt)
B(-5,16,-2,minecraft:dirt)
B(-5,16,-1,minecraft:dirt)
B(-5,16,0,minecraft:dirt)
B(-5,16,1,minecraft:dirt)
B(-5,16,2,minecraft:dirt)
B(-5,16,3,minecraft:dirt)
B(-5,16,4,minecraft:grass_block)
B(-5,16,5,minecraft:grass_block)
B(-5,17,-10,minecraft:grass_block)
B(-5,17,-9,minecraft:grass_block)
B(-5,17,-8,minecraft:dirt)
B(-5,17,-7,minecraft:dirt)
B(-5,17,-6,minecraft:dirt)
B(-5,17,-5,minecraft:dirt)
B(-5,17,-4,minecraft:dirt)
B(-5,17,-3,minecraft:dirt)
B(-5,17,-2,minecraft:dirt)
B(-5,17,-1,minecraft:grass_block)
B(-5,17,0,minecraft:grass_block)
B(-5,17,1,minecraft:grass_block)
B(-5,17,2,minecraft:grass_block)
B(-5,17,3,minecraft:grass_block)
B(-5,18,-8,minecraft:grass_block)
B(-5,18,-7,minecraft:grass_block)
B(-5,18,-6,minecraft:dirt)
B(-5,18,-5,minecraft:dirt)
B(-5,18,-4,minecraft:dirt)
B(-5,18,-3,minecraft:grass_block)
B(-5,18,-2,minecraft:grass_block)
B(-5,19,-6,minecraft:grass_block)
B(-5,19,-5,minecraft:grass_block)
B(-5,19,-4,minecraft:grass_block)
B(-4,2,2,minecraft:stone)
B(-4,2,3,minecraft:stone)
B(-4,2,4,minecraft:stone)
B(-4,3,-2,minecraft:stone)
B(-4,3,-1,minecraft:stone)
B(-4,3,0,minecraft:stone)
B(-4,3,1,minecraft:stone)
B(-4,3,2,minecraft:stone)
B(-4,3,3,minecraft:stone)
B(-4,3,4,minecraft:stone)
B(-4,3,5,minecraft:stone)
B(-4,4,-3,minecraft:stone)
B(-4,4,-2,minecraft:stone)
B(-4,4,-1,minecraft:stone)
B(-4,4,0,minecraft:stone)
B(-4,4,1,minecraft:stone)
B(-4,4,2,minecraft:stone)
B(-4,4,3,minecraft:stone)
B(-4,4,4,minecraft:stone)
B(-4,4,5,minecraft:stone)
B(-4,5,-4,minecraft:stone)
B(-4,5,-3,minecraft:stone)
B(-4,5,-2,minecraft:stone)
B(-4,5,-1,minecraft:stone)
B(-4,5,0,minecraft:stone)
B(-4,5,1,minecraft:stone)
B(-4,5,2,minecraft:stone)
B(-4,5,3,minecraft:stone)
B(-4,5,4,minecraft:stone)
B(-4,5,5,minecraft:stone)
B(-4,5,6,minecraft:stone)
B(-4,6,-9,minecraft:stone)
B(-4,6,-8,minecraft:stone)
B(-4,6,-7,minecraft:stone)
B(-4,6,-6,minecraft:stone)
B(-4,6,-5,minecraft:stone)
B(-4,6,-4,minecraft:stone)
B(-4,6,-3,minecraft:stone)
B(-4,6,-2,minecraft:stone)
B(-4,6,-1,minecraft:stone)
B(-4,6,0,minecraft:stone)
B(-4,6,1,minecraft:stone)
B(-4,6,2,minecraft:stone)
B(-4,6,3,minecraft:stone)
B(-4,6,4,minecraft:stone)
B(-4,6,5,minecraft:stone)
B(-4,6,6,minecraft:stone)
B(-4,7,-10,minecraft:stone)
B(-4,7,-9,minecraft:stone)
B(-4,7,-8,minecraft:stone)
B(-4,7,-7,minecraft:stone)
B(-4,7,-6,minecraft:stone)
B(-4,7,-5,minecraft:stone)
B(-4,7,-4,minecraft:stone)
B(-4,7,-3,minecraft:stone)
B(-4,7,-2,minecraft:stone)
B(-4,7,-1,minecraft:stone)
B(-4,7,0,minecraft:stone)
B(-4,7,1,minecraft:stone)
B(-4,7,2,minecraft:stone)
B(-4,7,3,minecraft:stone)
B(-4,7,4,minecraft:stone)
B(-4,7,5,minecraft:stone)
B(-4,7,6,minecraft:stone)
B(-4,7,7,minecraft:stone)
B(-4,8,-10,minecraft:stone)
B(-4,8,-9,minecraft:stone)
B(-4,8,-8,minecraft:stone)
B(-4,8,-7,minecraft:stone)
B(-4,8,-6,minecraft:stone)
B(-4,8,-5,minecraft:stone)
B(-4,8,-4,minecraft:stone)
B(-4,8,-3,minecraft:stone)
B(-4,8,-2,minecraft:stone)
B(-4,8,-1,minecraft:stone)
B(-4,8,0,minecraft:stone)
B(-4,8,1,minecraft:stone)
B(-4,8,2,minecraft:stone)
B(-4,8,3,minecraft:stone)
B(-4,8,4,minecraft:stone)
B(-4,8,5,minecraft:stone)
B(-4,8,6,minecraft:stone)
B(-4,8,7,minecraft:stone)
B(-4,9,-12,minecraft:stone)
B(-4,9,-11,minecraft:stone)
B(-4,9,-10,minecraft:stone)
B(-4,9,-9,minecraft:stone)
B(-4,9,-8,minecraft:stone)
B(-4,9,-7,minecraft:stone)
B(-4,9,-6,minecraft:stone)
B(-4,9,-5,minecraft:stone)
B(-4,9,-4,minecraft:stone)
B(-4,9,-3,minecraft:stone)
B(-4,9,-2,minecraft:stone)
B(-4,9,-1,minecraft:stone)
B(-4,9,0,minecraft:stone)
B(-4,9,1,minecraft:stone)
B(-4,9,2,minecraft:stone)
B(-4,9,3,minecraft:stone)
B(-4,9,4,minecraft:stone)
B(-4,9,5,minecraft:stone)
B(-4,9,6,minecraft:stone)
B(-4,9,7,minecraft:stone)
B(-4,9,8,minecraft:stone)
B(-4,10,-13,minecraft:stone)
B(-4,10,-12,minecraft:stone)
B(-4,10,-11,minecraft:stone)
B(-4,10,-10,minecraft:stone)
B(-4,10,-9,minecraft:stone)
B(-4,10,-8,minecraft:stone)
B(-4,10,-7,minecraft:stone)
B(-4,10,-6,minecraft:stone)
B(-4,10,-5,minecraft:stone)
B(-4,10,-4,minecraft:stone)
B(-4,10,-3,minecraft:stone)
B(-4,10,-2,minecraft:stone)
B(-4,10,-1,minecraft:stone)
B(-4,10,0,minecraft:stone)
B(-4,10,1,minecraft:stone)
B(-4,10,2,minecraft:stone)
B(-4,10,3,minecraft:stone)
B(-4,10,4,minecraft:stone)
B(-4,10,5,minecraft:stone)
B(-4,10,6,minecraft:stone)
B(-4,10,7,minecraft:stone)
B(-4,10,8,minecraft:stone)
B(-4,11,-14,minecraft:stone)
B(-4,11,-13,minecraft:stone)
B(-4,11,-12,minecraft:stone)
B(-4,11,-11,minecraft:stone)
B(-4,11,-10,minecraft:stone)
B(-4,11,-9,minecraft:stone)
B(-4,11,-8,minecraft:stone)
B(-4,11,-7,minecraft:stone)
B(-4,11,-6,minecraft:stone)
B(-4,11,-5,minecraft:stone)
B(-4,11,-4,minecraft:stone)
B(-4,11,-3,minecraft:stone)
B(-4,11,-2,minecraft:stone)
B(-4,11,-1,minecraft:stone)
B(-4,11,0,minecraft:stone)
B(-4,11,1,minecraft:stone)
B(-4,11,2,minecraft:stone)
B(-4,11,3,minecraft:stone)
B(-4,11,4,minecraft:stone)
B(-4,11,5,minecraft:stone)
B(-4,11,6,minecraft:stone)
B(-4,11,7,minecraft:stone)
B(-4,11,8,minecraft:stone)
B(-4,11,9,minecraft:stone)
B(-4,12,-14,minecraft:dirt)
B(-4,12,-13,minecraft:dirt)
B(-4,12,-12,minecraft:dirt)
B(-4,12,-11,minecraft:stone)
B(-4,12,-10,minecraft:stone)
B(-4,12,-9,minecraft:stone)
B(-4,12,-8,minecraft:stone)
B(-4,12,-7,minecraft:stone)
B(-4,12,-6,minecraft:stone)
B(-4,12,-5,minecraft:stone)
B(-4,12,-4,minecraft:stone)
B(-4,12,-3,minecraft:stone)
B(-4,12,-2,minecraft:stone)
B(-4,12,-1,minecraft:stone)
B(-4,12,0,minecraft:stone)
B(-4,12,1,minecraft:stone)
B(-4,12,2,minecraft:stone)
B(-4,12,3,minecraft:stone)
B(-4,12,4,minecraft:stone)
B(-4,12,5,minecraft:stone)
B(-4,12,6,minecraft:dirt)
B(-4,12,7,minecraft:dirt)
B(-4,12,8,minecraft:dirt)
B(-4,12,9,minecraft:dirt)
B(-4,13,-15,minecraft:dirt)
B(-4,13,-14,minecraft:dirt)
B(-4,13,-13,minecraft:dirt)
B(-4,13,-12,minecraft:dirt)
B(-4,13,-11,minecraft:dirt)
B(-4,13,-10,minecraft:stone)
B(-4,13,-9,minecraft:stone)
B(-4,13,-8,minecraft:stone)
B(-4,13,-7,minecraft:stone)
B(-4,13,-6,minecraft:stone)
B(-4,13,-5,minecraft:stone)
B(-4,13,-4,minecraft:stone)
B(-4,13,-3,minecraft:stone)
B(-4,13,-2,minecraft:stone)
B(-4,13,-1,minecraft:stone)
B(-4,13,0,minecraft:stone)
B(-4,13,1,minecraft:stone)
B(-4,13,2,minecraft:stone)
B(-4,13,3,minecraft:stone)
B(-4,13,4,minecraft:dirt)
B(-4,13,5,minecraft:dirt)
B(-4,13,6,minecraft:dirt)
B(-4,13,7,minecraft:dirt)
B(-4,13,8,minecraft:dirt)
B(-4,13,9,minecraft:dirt)
B(-4,13,10,minecraft:dirt)
B(-4,14,-15,minecraft:dirt)
B(-4,14,-14,minecraft:dirt)
B(-4,14,-13,minecraft:dirt)
B(-4,14,-12,minecraft:dirt)
B(-4,14,-11,minecraft:dirt)
B(-4,14,-10,minecraft:dirt)
B(-4,14,-9,minecraft:stone)
B(-4,14,-8,minecraft:stone)
B(-4,14,-7,minecraft:stone)
B(-4,14,-6,minecraft:stone)
B(-4,14,-5,minecraft:stone)
B(-4,14,-4,minecraft:stone)
B(-4,14,-3,minecraft:stone)
B(-4,14,-2,minecraft:stone)
B(-4,14,-1,minecraft:dirt)
B(-4,14,0,minecraft:dirt)
B(-4,14,1,minecraft:dirt)
B(-4,14,2,minecraft:dirt)
B(-4,14,3,minecraft:dirt)
B(-4,14,4,minecraft:dirt)
B(-4,14,5,minecraft:dirt)
B(-4,14,6,minecraft:dirt)
B(-4,14,7,minecraft:dirt)
B(-4,14,8,minecraft:dirt)
B(-4,14,9,minecraft:dirt)
B(-4,14,10,minecraft:dirt)
B(-4,14,11,minecraft:grass_block)
B(-4,15,-15,minecraft:grass_block)
B(-4,15,-14,minecraft:grass_block)
B(-4,15,-13,minecraft:grass_block)
B(-4,15,-12,minecraft:grass_block)
B(-4,15,-11,minecraft:dirt)
B(-4,15,-10,minecraft:dirt)
B(-4,15,-9,minecraft:dirt)
B(-4,15,-8,minecraft:dirt)
B(-4,15,-7,minecraft:stone)
B(-4,15,-6,minecraft:stone)
B(-4,15,-5,minecraft:stone)
B(-4,15,-4,minecraft:stone)
B(-4,15,-3,minecraft:stone)
B(-4,15,-2,minecraft:dirt)
B(-4,15,-1,minecraft:dirt)
B(-4,15,0,minecraft:dirt)
B(-4,15,1,minecraft:dirt)
B(-4,15,2,minecraft:dirt)
B(-4,15,3,minecraft:dirt)
B(-4,15,4,minecraft:dirt)
B(-4,15,5,minecraft:dirt)
B(-4,15,6,minecraft:grass_block)
B(-4,15,7,minecraft:grass_block)
B(-4,15,8,minecraft:grass_block)
B(-4,15,9,minecraft:grass_block)
B(-4,15,10,minecraft:grass_block)
B(-4,16,-11,minecraft:grass_block)
B(-4,16,-10,minecraft:dirt)
B(-4,16,-9,minecraft:dirt)
B(-4,16,-8,minecraft:dirt)
B(-4,16,-7,minecraft:dirt)
B(-4,16,-6,minecraft:dirt)
B(-4,16,-5,minecraft:dirt)
B(-4,16,-4,minecraft:dirt)
B(-4,16,-3,minecraft:dirt)
B(-4,16,-2,minecraft:dirt)
B(-4,16,-1,minecraft:dirt)
B(-4,16,0,minecraft:dirt)
B(-4,16,1,minecraft:dirt)
B(-4,16,2,minecraft:dirt)
B(-4,16,3,minecraft:dirt)
B(-4,16,4,minecraft:grass_block)
B(-4,16,5,minecraft:grass_block)
B(-4,17,-10,minecraft:grass_block)
B(-4,17,-9,minecraft:dirt)
B(-4,17,-8,minecraft:dirt)
B(-4,17,-7,minecraft:dirt)
B(-4,17,-6,minecraft:dirt)
B(-4,17,-5,minecraft:dirt)
B(-4,17,-4,minecraft:dirt)
B(-4,17,-3,minecraft:dirt)
B(-4,17,-2,minecraft:dirt)
B(-4,17,-1,minecraft:grass_block)
B(-4,17,0,minecraft:grass_block)
B(-4,17,1,minecraft:grass_block)
B(-4,17,2,minecraft:grass_block)
B(-4,17,3,minecraft:grass_block)
B(-4,18,-9,minecraft:grass_block)
B(-4,18,-8,minecraft:grass_block)
B(-4,18,-7,minecraft:dirt)
B(-4,18,-6,minecraft:dirt)
B(-4,18,-5,minecraft:dirt)
B(-4,18,-4,minecraft:dirt)
B(-4,18,-3,minecraft:dirt)
B(-4,18,-2,minecraft:grass_block)
B(-4,19,-7,minecraft:grass_block)
B(-4,19,-6,minecraft:grass_block)
B(-4,19,-5,minecraft:grass_block)
B(-4,19,-4,minecraft:grass_block)
B(-4,19,-3,minecraft:grass_block)
B(-3,1,1,minecraft:stone)
B(-3,1,2,minecraft:stone)
B(-3,1,3,minecraft:stone)
B(-3,1,4,minecraft:stone)
B(-3,2,-3,minecraft:stone)
B(-3,2,-2,minecraft:stone)
B(-3,2,-1,minecraft:stone)
B(-3,2,0,minecraft:stone)
B(-3,2,1,minecraft:stone)
B(-3,2,2,minecraft:stone)
B(-3,2,3,minecraft:stone)
B(-3,2,4,minecraft:stone)
B(-3,2,5,minecraft:stone)
B(-3,3,-4,minecraft:stone)
B(-3,3,-3,minecraft:stone)
B(-3,3,-2,minecraft:stone)
B(-3,3,-1,minecraft:stone)
B(-3,3,0,minecraft:stone)
B(-3,3,1,minecraft:stone)
B(-3,3,2,minecraft:stone)
B(-3,3,3,minecraft:stone)
B(-3,3,4,minecraft:stone)
B(-3,3,5,minecraft:stone)
B(-3,3,6,minecraft:stone)
B(-3,4,-8,minecraft:stone)
B(-3,4,-7,minecraft:stone)
B(-3,4,-6,minecraft:stone)
B(-3,4,-5,minecraft:stone)
B(-3,4,-4,minecraft:stone)
B(-3,4,-3,minecraft:stone)
B(-3,4,-2,minecraft:stone)
B(-3,4,-1,minecraft:stone)
B(-3,4,0,minecraft:stone)
B(-3,4,1,minecraft:stone)
B(-3,4,2,minecraft:stone)
B(-3,4,3,minecraft:stone)
B(-3,4,4,minecraft:stone)
B(-3,4,5,minecraft:stone)
B(-3,4,6,minecraft:stone)
B(-3,5,-9,minecraft:stone)
B(-3,5,-8,minecraft:stone)
B(-3,5,-7,minecraft:stone)
B(-3,5,-6,minecraft:stone)
B(-3,5,-5,minecraft:stone)
B(-3,5,-4,minecraft:stone)
B(-3,5,-3,minecraft:stone)
B(-3,5,-2,minecraft:stone)
B(-3,5,-1,minecraft:stone)
B(-3,5,0,minecraft:stone)
B(-3,5,1,minecraft:stone)
B(-3,5,2,minecraft:stone)
B(-3,5,3,minecraft:stone)
B(-3,5,4,minecraft:stone)
B(-3,5,5,minecraft:stone)
B(-3,5,6,minecraft:stone)
B(-3,6,-10,minecraft:stone)
B(-3,6,-9,minecraft:stone)
B(-3,6,-8,minecraft:stone)
B(-3,6,-7,minecraft:stone)
B(-3,6,-6,minecraft:stone)
B(-3,6,-5,minecraft:stone)
B(-3,6,-4,minecraft:stone)
B(-3,6,-3,minecraft:stone)
B(-3,6,-2,minecraft:stone)
B(-3,6,-1,minecraft:stone)
B(-3,6,0,minecraft:stone)
B(-3,6,1,minecraft:stone)
B(-3,6,2,minecraft:stone)
B(-3,6,3,minecraft:stone)
B(-3,6,4,minecraft:stone)
B(-3,6,5,minecraft:stone)
B(-3,6,6,minecraft:stone)
B(-3,6,7,minecraft:stone)
B(-3,7,-11,minecraft:stone)
B(-3,7,-10,minecraft:stone)
B(-3,7,-9,minecraft:stone)
B(-3,7,-8,minecraft:stone)
B(-3,7,-7,minecraft:stone)
B(-3,7,-6,minecraft:stone)
B(-3,7,-5,minecraft:stone)
B(-3,7,-4,minecraft:stone)
B(-3,7,-3,minecraft:stone)
B(-3,7,-2,minecraft:stone)
B(-3,7,-1,minecraft:stone)
B(-3,7,0,minecraft:stone)
B(-3,7,1,minecraft:stone)
B(-3,7,2,minecraft:stone)
B(-3,7,3,minecraft:stone)
B(-3,7,4,minecraft:stone)
B(-3,7,5,minecraft:stone)
B(-3,7,6,minecraft:stone)
B(-3,7,7,minecraft:stone)
B(-3,8,-12,minecraft:stone)
B(-3,8,-11,minecraft:stone)
B(-3,8,-10,minecraft:stone)
B(-3,8,-9,minecraft:stone)
B(-3,8,-8,minecraft:stone)
B(-3,8,-7,minecraft:stone)
B(-3,8,-6,minecraft:stone)
B(-3,8,-5,minecraft:stone)
B(-3,8,-4,minecraft:stone)
B(-3,8,-3,minecraft:stone)
B(-3,8,-2,minecraft:stone)
B(-3,8,-1,minecraft:stone)
B(-3,8,0,minecraft:stone)
B(-3,8,1,minecraft:stone)
B(-3,8,2,minecraft:stone)
B(-3,8,3,minecraft:stone)
B(-3,8,4,minecraft:stone)
B(-3,8,5,minecraft:stone)
B(-3,8,6,minecraft:stone)
B(-3,8,7,minecraft:stone)
B(-3,8,8,minecraft:stone)
B(-3,9,-13,minecraft:stone)
B(-3,9,-12,minecraft:stone)
B(-3,9,-11,minecraft:stone)
B(-3,9,-10,minecraft:stone)
B(-3,9,-9,minecraft:stone)
B(-3,9,-8,minecraft:stone)
B(-3,9,-7,minecraft:stone)
B(-3,9,-6,minecraft:stone)
B(-3,9,-5,minecraft:stone)
B(-3,9,-4,minecraft:stone)
B(-3,9,-3,minecraft:stone)
B(-3,9,-2,minecraft:stone)
B(-3,9,-1,minecraft:stone)
B(-3,9,0,minecraft:stone)
B(-3,9,1,minecraft:stone)
B(-3,9,2,minecraft:stone)
B(-3,9,3,minecraft:stone)
B(-3,9,4,minecraft:stone)
B(-3,9,5,minecraft:stone)
B(-3,9,6,minecraft:stone)
B(-3,9,7,minecraft:stone)
B(-3,9,8,minecraft:stone)
B(-3,10,-14,minecraft:stone)
B(-3,10,-13,minecraft:stone)
B(-3,10,-12,minecraft:stone)
B(-3,10,-11,minecraft:stone)
B(-3,10,-10,minecraft:stone)
B(-3,10,-9,minecraft:stone)
B(-3,10,-8,minecraft:stone)
B(-3,10,-7,minecraft:stone)
B(-3,10,-6,minecraft:stone)
B(-3,10,-5,minecraft:stone)
B(-3,10,-4,minecraft:stone)
B(-3,10,-3,minecraft:stone)
B(-3,10,-2,minecraft:stone)
B(-3,10,-1,minecraft:stone)
B(-3,10,0,minecraft:stone)
B(-3,10,1,minecraft:stone)
B(-3,10,2,minecraft:stone)
B(-3,10,3,minecraft:stone)
B(-3,10,4,minecraft:stone)
B(-3,10,5,minecraft:stone)
B(-3,10,6,minecraft:stone)
B(-3,10,7,minecraft:stone)
B(-3,10,8,minecraft:stone)
B(-3,11,-14,minecraft:stone)
B(-3,11,-13,minecraft:stone)
B(-3,11,-12,minecraft:stone)
B(-3,11,-11,minecraft:stone)
B(-3,11,-10,minecraft:stone)
B(-3,11,-9,minecraft:stone)
B(-3,11,-8,minecraft:stone)
B(-3,11,-7,minecraft:stone)
B(-3,11,-6,minecraft:stone)
B(-3,11,-5,minecraft:stone)
B(-3,11,-4,minecraft:stone)
B(-3,11,-3,minecraft:stone)
B(-3,11,-2,minecraft:stone)
B(-3,11,-1,minecraft:stone)
B(-3,11,0,minecraft:stone)
B(-3,11,1,minecraft:stone)
B(-3,11,2,minecraft:stone)
B(-3,11,3,minecraft:stone)
B(-3,11,4,minecraft:stone)
B(-3,11,5,minecraft:stone)
B(-3,11,6,minecraft:stone)
B(-3,11,7,minecraft:stone)
B(-3,11,8,minecraft:stone)
B(-3,11,9,minecraft:stone)
B(-3,12,-15,minecraft:dirt)
B(-3,12,-14,minecraft:dirt)
B(-3,12,-13,minecraft:dirt)
B(-3,12,-12,minecraft:dirt)
B(-3,12,-11,minecraft:stone)
B(-3,12,-10,minecraft:stone)
B(-3,12,-9,minecraft:stone)
B(-3,12,-8,minecraft:stone)
B(-3,12,-7,minecraft:stone)
B(-3,12,-6,minecraft:stone)
B(-3,12,-5,minecraft:stone)
B(-3,12,-4,minecraft:stone)
B(-3,12,-3,minecraft:stone)
B(-3,12,-2,minecraft:stone)
B(-3,12,-1,minecraft:stone)
B(-3,12,0,minecraft:stone)
B(-3,12,1,minecraft:stone)
B(-3,12,2,minecraft:stone)
B(-3,12,3,minecraft:stone)
B(-3,12,4,minecraft:stone)
B(-3,12,5,minecraft:stone)
B(-3,12,6,minecraft:stone)
B(-3,12,7,minecraft:dirt)
B(-3,12,8,minecraft:dirt)
B(-3,12,9,minecraft:dirt)
B(-3,12,10,minecraft:dirt)
B(-3,13,-15,minecraft:dirt)
B(-3,13,-14,minecraft:dirt)
B(-3,13,-13,minecraft:dirt)
B(-3,13,-12,minecraft:dirt)
B(-3,13,-11,minecraft:dirt)
B(-3,13,-10,minecraft:stone)
B(-3,13,-9,minecraft:stone)
B(-3,13,-8,minecraft:stone)
B(-3,13,-7,minecraft:stone)
B(-3,13,-6,minecraft:stone)
B(-3,13,-5,minecraft:stone)
B(-3,13,-4,minecraft:stone)
B(-3,13,-3,minecraft:stone)
B(-3,13,-2,minecraft:stone)
B(-3,13,-1,minecraft:stone)
B(-3,13,0,minecraft:stone)
B(-3,13,1,minecraft:stone)
B(-3,13,2,minecraft:stone)
B(-3,13,3,minecraft:stone)
B(-3,13,4,minecraft:stone)
B(-3,13,5,minecraft:dirt)
B(-3,13,6,minecraft:dirt)
B(-3,13,7,minecraft:dirt)
B(-3,13,8,minecraft:dirt)
B(-3,13,9,minecraft:dirt)
B(-3,13,10,minecraft:dirt)
B(-3,14,-16,minecraft:dirt)
B(-3,14,-15,minecraft:dirt)
B(-3,14,-14,minecraft:dirt)
B(-3,14,-13,minecraft:dirt)
B(-3,14,-12,minecraft:dirt)
B(-3,14,-11,minecraft:dirt)
B(-3,14,-10,minecraft:dirt)
B(-3,14,-9,minecraft:dirt)
B(-3,14,-8,minecraft:stone)
B(-3,14,-7,minecraft:stone)
B(-3,14,-6,minecraft:stone)
B(-3,14,-5,minecraft:stone)
B(-3,14,-4,minecraft:stone)
B(-3,14,-3,minecraft:stone)
B(-3,14,-2,minecraft:stone)
B(-3,14,-1,minecraft:dirt)
B(-3,14,0,minecraft:dirt)
B(-3,14,1,minecraft:dirt)
B(-3,14,2,minecraft:dirt)
B(-3,14,3,minecraft:dirt)
B(-3,14,4,minecraft:dirt)
B(-3,14,5,minecraft:dirt)
B(-3,14,6,minecraft:dirt)
B(-3,14,7,minecraft:dirt)
B(-3,14,8,minecraft:dirt)
B(-3,14,9,minecraft:dirt)
B(-3,14,10,minecraft:dirt)
B(-3,14,11,minecraft:dirt)
B(-3,15,-16,minecraft:grass_block)
B(-3,15,-15,minecraft:grass_block)
B(-3,15,-14,minecraft:grass_block)
B(-3,15,-13,minecraft:grass_block)
B(-3,15,-12,minecraft:grass_block)
B(-3,15,-11,minecraft:dirt)
B(-3,15,-10,minecraft:dirt)
B(-3,15,-9,minecraft:dirt)
B(-3,15,-8,minecraft:dirt)
B(-3,15,-7,minecraft:stone)
B(-3,15,-6,minecraft:stone)
B(-3,15,-5,minecraft:stone)
B(-3,15,-4,minecraft:stone)
B(-3,15,-3,minecraft:stone)
B(-3,15,-2,minecraft:dirt)
B(-3,15,-1,minecraft:dirt)
B(-3,15,0,minecraft:dirt)
B(-3,15,1,minecraft:dirt)
B(-3,15,2,minecraft:dirt)
B(-3,15,3,minecraft:dirt)
B(-3,15,4,minecraft:dirt)
B(-3,15,5,minecraft:dirt)
B(-3,15,6,minecraft:dirt)
B(-3,15,7,minecraft:grass_block)
B(-3,15,8,minecraft:grass_block)
B(-3,15,9,minecraft:grass_block)
B(-3,15,10,minecraft:grass_block)
B(-3,15,11,minecraft:grass_block)
B(-3,16,-11,minecraft:grass_block)
B(-3,16,-10,minecraft:dirt)
B(-3,16,-9,minecraft:dirt)
B(-3,16,-8,minecraft:dirt)
B(-3,16,-7,minecraft:dirt)
B(-3,16,-6,minecraft:dirt)
B(-3,16,-5,minecraft:dirt)
B(-3,16,-4,minecraft:dirt)
B(-3,16,-3,minecraft:dirt)
B(-3,16,-2,minecraft:dirt)
B(-3,16,-1,minecraft:dirt)
B(-3,16,0,minecraft:dirt)
B(-3,16,1,minecraft:dirt)
B(-3,16,2,minecraft:dirt)
B(-3,16,3,minecraft:dirt)
B(-3,16,4,minecraft:dirt)
B(-3,16,5,minecraft:grass_block)
B(-3,16,6,minecraft:grass_block)
B(-3,17,-10,minecraft:grass_block)
B(-3,17,-9,minecraft:grass_block)
B(-3,17,-8,minecraft:dirt)
B(-3,17,-7,minecraft:dirt)
B(-3,17,-6,minecraft:dirt)
B(-3,17,-5,minecraft:dirt)
B(-3,17,-4,minecraft:dirt)
B(-3,17,-3,minecraft:dirt)
B(-3,17,-2,minecraft:dirt)
B(-3,17,-1,minecraft:grass_block)
B(-3,17,0,minecraft:grass_block)
B(-3,17,1,minecraft:grass_block)
B(-3,17,2,minecraft:grass_block)
B(-3,17,3,minecraft:grass_block)
B(-3,17,4,minecraft:grass_block)
B(-3,18,-8,minecraft:grass_block)
B(-3,18,-7,minecraft:dirt)
B(-3,18,-6,minecraft:dirt)
B(-3,18,-5,minecraft:dirt)
B(-3,18,-4,minecraft:dirt)
B(-3,18,-3,minecraft:dirt)
B(-3,18,-2,minecraft:grass_block)
B(-3,19,-7,minecraft:grass_block)
B(-3,19,-6,minecraft:grass_block)
B(-3,19,-5,minecraft:grass_block)
B(-3,19,-4,minecraft:grass_block)
B(-3,19,-3,minecraft:grass_block)
B(-2,0,1,minecraft:stone)
B(-2,1,-3,minecraft:stone)
B(-2,1,-2,minecraft:stone)
B(-2,1,-1,minecraft:stone)
B(-2,1,0,minecraft:stone)
B(-2,1,1,minecraft:stone)
B(-2,1,2,minecraft:stone)
B(-2,1,3,minecraft:stone)
B(-2,1,4,minecraft:stone)
B(-2,1,5,minecraft:stone)
B(-2,2,-4,minecraft:stone)
B(-2,2,-3,minecraft:stone)
B(-2,2,-2,minecraft:stone)
B(-2,2,-1,minecraft:stone)
B(-2,2,0,minecraft:stone)
B(-2,2,1,minecraft:stone)
B(-2,2,2,minecraft:stone)
B(-2,2,3,minecraft:stone)
B(-2,2,4,minecraft:stone)
B(-2,2,5,minecraft:stone)
B(-2,2,6,minecraft:stone)
B(-2,3,-6,minecraft:stone)
B(-2,3,-5,minecraft:stone)
B(-2,3,-4,minecraft:stone)
B(-2,3,-3,minecraft:stone)
B(-2,3,-2,minecraft:stone)
B(-2,3,-1,minecraft:stone)
B(-2,3,0,minecraft:stone)
B(-2,3,1,minecraft:stone)
B(-2,3,2,minecraft:stone)
B(-2,3,3,minecraft:stone)
B(-2,3,4,minecraft:stone)
B(-2,3,5,minecraft:stone)
B(-2,3,6,minecraft:stone)
B(-2,4,-8,minecraft:stone)
B(-2,4,-7,minecraft:stone)
B(-2,4,-6,minecraft:stone)
B(-2,4,-5,minecraft:stone)
B(-2,4,-4,minecraft:stone)
B(-2,4,-3,minecraft:stone)
B(-2,4,-2,minecraft:stone)
B(-2,4,-1,minecraft:stone)
B(-2,4,0,minecraft:stone)
B(-2,4,1,minecraft:stone)
B(-2,4,2,minecraft:stone)
B(-2,4,3,minecraft:stone)
B(-2,4,4,minecraft:stone)
B(-2,4,5,minecraft:stone)
B(-2,4,6,minecraft:stone)
B(-2,4,7,minecraft:stone)
B(-2,5,-10,minecraft:stone)
B(-2,5,-9,minecraft:stone)
B(-2,5,-8,minecraft:stone)
B(-2,5,-7,minecraft:stone)
B(-2,5,-6,minecraft:stone)
B(-2,5,-5,minecraft:stone)
B(-2,5,-4,minecraft:stone)
B(-2,5,-3,minecraft:stone)
B(-2,5,-2,minecraft:stone)
B(-2,5,-1,minecraft:stone)
B(-2,5,0,minecraft:stone)
B(-2,5,1,minecraft:stone)
B(-2,5,2,minecraft:stone)
B(-2,5,3,minecraft:stone)
B(-2,5,4,minecraft:stone)
B(-2,5,5,minecraft:stone)
B(-2,5,6,minecraft:stone)
B(-2,5,7,minecraft:stone)
B(-2,6,-11,minecraft:stone)
B(-2,6,-10,minecraft:stone)
B(-2,6,-9,minecraft:stone)
B(-2,6,-8,minecraft:stone)
B(-2,6,-7,minecraft:stone)
B(-2,6,-6,minecraft:stone)
B(-2,6,-5,minecraft:stone)
B(-2,6,-4,minecraft:stone)
B(-2,6,-3,minecraft:stone)
B(-2,6,-2,minecraft:stone)
B(-2,6,-1,minecraft:stone)
B(-2,6,0,minecraft:stone)
B(-2,6,1,minecraft:stone)
B(-2,6,2,minecraft:stone)
B(-2,6,3,minecraft:stone)
B(-2,6,4,minecraft:stone)
B(-2,6,5,minecraft:stone)
B(-2,6,6,minecraft:stone)
B(-2,6,7,minecraft:stone)
B(-2,7,-12,minecraft:stone)
B(-2,7,-11,minecraft:stone)
B(-2,7,-10,minecraft:stone)
B(-2,7,-9,minecraft:stone)
B(-2,7,-8,minecraft:stone)
B(-2,7,-7,minecraft:stone)
B(-2,7,-6,minecraft:stone)
B(-2,7,-5,minecraft:stone)
B(-2,7,-4,minecraft:stone)
B(-2,7,-3,minecraft:stone)
B(-2,7,-2,minecraft:stone)
B(-2,7,-1,minecraft:stone)
B(-2,7,0,minecraft:stone)
B(-2,7,1,minecraft:stone)
B(-2,7,2,minecraft:stone)
B(-2,7,3,minecraft:stone)
B(-2,7,4,minecraft:stone)
B(-2,7,5,minecraft:stone)
B(-2,7,6,minecraft:stone)
B(-2,7,7,minecraft:stone)
B(-2,7,8,minecraft:stone)
B(-2,8,-12,minecraft:stone)
B(-2,8,-11,minecraft:stone)
B(-2,8,-10,minecraft:stone)
B(-2,8,-9,minecraft:stone)
B(-2,8,-8,minecraft:stone)
B(-2,8,-7,minecraft:stone)
B(-2,8,-6,minecraft:stone)
B(-2,8,-5,minecraft:stone)
B(-2,8,-4,minecraft:stone)
B(-2,8,-3,minecraft:stone)
B(-2,8,-2,minecraft:stone)
B(-2,8,-1,minecraft:stone)
B(-2,8,0,minecraft:stone)
B(-2,8,1,minecraft:stone)
B(-2,8,2,minecraft:stone)
B(-2,8,3,minecraft:stone)
B(-2,8,4,minecraft:stone)
B(-2,8,5,minecraft:stone)
B(-2,8,6,minecraft:stone)
B(-2,8,7,minecraft:stone)
B(-2,8,8,minecraft:stone)
B(-2,9,-13,minecraft:stone)
B(-2,9,-12,minecraft:stone)
B(-2,9,-11,minecraft:stone)
B(-2,9,-10,minecraft:stone)
B(-2,9,-9,minecraft:stone)
B(-2,9,-8,minecraft:stone)
B(-2,9,-7,minecraft:stone)
B(-2,9,-6,minecraft:stone)
B(-2,9,-5,minecraft:stone)
B(-2,9,-4,minecraft:stone)
B(-2,9,-3,minecraft:stone)
B(-2,9,-2,minecraft:stone)
B(-2,9,-1,minecraft:stone)
B(-2,9,0,minecraft:stone)
B(-2,9,1,minecraft:stone)
B(-2,9,2,minecraft:stone)
B(-2,9,3,minecraft:stone)
B(-2,9,4,minecraft:stone)
B(-2,9,5,minecraft:stone)
B(-2,9,6,minecraft:stone)
B(-2,9,7,minecraft:stone)
B(-2,9,8,minecraft:stone)
B(-2,10,-14,minecraft:stone)
B(-2,10,-13,minecraft:stone)
B(-2,10,-12,minecraft:stone)
B(-2,10,-11,minecraft:stone)
B(-2,10,-10,minecraft:stone)
B(-2,10,-9,minecraft:stone)
B(-2,10,-8,minecraft:stone)
B(-2,10,-7,minecraft:stone)
B(-2,10,-6,minecraft:stone)
B(-2,10,-5,minecraft:stone)
B(-2,10,-4,minecraft:stone)
B(-2,10,-3,minecraft:stone)
B(-2,10,-2,minecraft:stone)
B(-2,10,-1,minecraft:stone)
B(-2,10,0,minecraft:stone)
B(-2,10,1,minecraft:stone)
B(-2,10,2,minecraft:stone)
B(-2,10,3,minecraft:stone)
B(-2,10,4,minecraft:stone)
B(-2,10,5,minecraft:stone)
B(-2,10,6,minecraft:stone)
B(-2,10,7,minecraft:stone)
B(-2,10,8,minecraft:stone)
B(-2,10,9,minecraft:stone)
B(-2,11,-14,minecraft:stone)
B(-2,11,-13,minecraft:stone)
B(-2,11,-12,minecraft:stone)
B(-2,11,-11,minecraft:stone)
B(-2,11,-10,minecraft:stone)
B(-2,11,-9,minecraft:stone)
B(-2,11,-8,minecraft:stone)
B(-2,11,-7,minecraft:stone)
B(-2,11,-6,minecraft:stone)
B(-2,11,-5,minecraft:stone)
B(-2,11,-4,minecraft:stone)
B(-2,11,-3,minecraft:stone)
B(-2,11,-2,minecraft:stone)
B(-2,11,-1,minecraft:stone)
B(-2,11,0,minecraft:stone)
B(-2,11,1,minecraft:stone)
B(-2,11,2,minecraft:stone)
B(-2,11,3,minecraft:stone)
B(-2,11,4,minecraft:stone)
B(-2,11,5,minecraft:stone)
B(-2,11,6,minecraft:stone)
B(-2,11,7,minecraft:stone)
B(-2,11,8,minecraft:stone)
B(-2,11,9,minecraft:stone)
B(-2,11,10,minecraft:stone)
B(-2,12,-15,minecraft:dirt)
B(-2,12,-14,minecraft:dirt)
B(-2,12,-13,minecraft:dirt)
B(-2,12,-12,minecraft:dirt)
B(-2,12,-11,minecraft:stone)
B(-2,12,-10,minecraft:stone)
B(-2,12,-9,minecraft:stone)
B(-2,12,-8,minecraft:stone)
B(-2,12,-7,minecraft:stone)
B(-2,12,-6,minecraft:stone)
B(-2,12,-5,minecraft:stone)
B(-2,12,-4,minecraft:stone)
B(-2,12,-3,minecraft:stone)
B(-2,12,-2,minecraft:stone)
B(-2,12,-1,minecraft:stone)
B(-2,12,0,minecraft:stone)
B(-2,12,1,minecraft:stone)
B(-2,12,2,minecraft:stone)
B(-2,12,3,minecraft:stone)
B(-2,12,4,minecraft:stone)
B(-2,12,5,minecraft:stone)
B(-2,12,6,minecraft:stone)
B(-2,12,7,minecraft:stone)
B(-2,12,8,minecraft:dirt)
B(-2,12,9,minecraft:dirt)
B(-2,12,10,minecraft:dirt)
B(-2,13,-15,minecraft:dirt)
B(-2,13,-14,minecraft:dirt)
B(-2,13,-13,minecraft:dirt)
B(-2,13,-12,minecraft:dirt)
B(-2,13,-11,minecraft:dirt)
B(-2,13,-10,minecraft:dirt)
B(-2,13,-9,minecraft:stone)
B(-2,13,-8,minecraft:stone)
B(-2,13,-7,minecraft:stone)
B(-2,13,-6,minecraft:stone)
B(-2,13,-5,minecraft:stone)
B(-2,13,-4,minecraft:stone)
B(-2,13,-3,minecraft:stone)
B(-2,13,-2,minecraft:stone)
B(-2,13,-1,minecraft:stone)
B(-2,13,0,minecraft:stone)
B(-2,13,1,minecraft:stone)
B(-2,13,2,minecraft:stone)
B(-2,13,3,minecraft:stone)
B(-2,13,4,minecraft:stone)
B(-2,13,5,minecraft:stone)
B(-2,13,6,minecraft:dirt)
B(-2,13,7,minecraft:dirt)
B(-2,13,8,minecraft:dirt)
B(-2,13,9,minecraft:dirt)
B(-2,13,10,minecraft:dirt)
B(-2,13,11,minecraft:dirt)
B(-2,14,-16,minecraft:dirt)
B(-2,14,-15,minecraft:dirt)
B(-2,14,-14,minecraft:dirt)
B(-2,14,-13,minecraft:dirt)
B(-2,14,-12,minecraft:dirt)
B(-2,14,-11,minecraft:dirt)
B(-2,14,-10,minecraft:dirt)
B(-2,14,-9,minecraft:dirt)
B(-2,14,-8,minecraft:dirt)
B(-2,14,-7,minecraft:stone)
B(-2,14,-6,minecraft:stone)
B(-2,14,-5,minecraft:stone)
B(-2,14,-4,minecraft:stone)
B(-2,14,-3,minecraft:stone)
B(-2,14,-2,minecraft:stone)
B(-2,14,-1,minecraft:dirt)
B(-2,14,0,minecraft:dirt)
B(-2,14,1,minecraft:dirt)
B(-2,14,2,minecraft:dirt)
B(-2,14,3,minecraft:dirt)
B(-2,14,4,minecraft:dirt)
B(-2,14,5,minecraft:dirt)
B(-2,14,6,minecraft:dirt)
B(-2,14,7,minecraft:dirt)
B(-2,14,8,minecraft:dirt)
B(-2,14,9,minecraft:dirt)
B(-2,14,10,minecraft:dirt)
B(-2,14,11,minecraft:dirt)
B(-2,14,12,minecraft:dirt)
B(-2,15,-16,minecraft:grass_block)
B(-2,15,-15,minecraft:grass_block)
B(-2,15,-14,minecraft:grass_block)
B(-2,15,-13,minecraft:grass_block)
B(-2,15,-12,minecraft:grass_block)
B(-2,15,-11,minecraft:dirt)
B(-2,15,-10,minecraft:dirt)
B(-2,15,-9,minecraft:dirt)
B(-2,15,-8,minecraft:dirt)
B(-2,15,-7,minecraft:dirt)
B(-2,15,-6,minecraft:dirt)
B(-2,15,-5,minecraft:stone)
B(-2,15,-4,minecraft:stone)
B(-2,15,-3,minecraft:stone)
B(-2,15,-2,minecraft:dirt)
B(-2,15,-1,minecraft:dirt)
B(-2,15,0,minecraft:dirt)
B(-2,15,1,minecraft:dirt)
B(-2,15,2,minecraft:dirt)
B(-2,15,3,minecraft:dirt)
B(-2,15,4,minecraft:dirt)
B(-2,15,5,minecraft:dirt)
B(-2,15,6,minecraft:dirt)
B(-2,15,7,minecraft:dirt)
B(-2,15,8,minecraft:grass_block)
B(-2,15,9,minecraft:grass_block)
B(-2,15,10,minecraft:grass_block)
B(-2,15,11,minecraft:grass_block)
B(-2,15,12,minecraft:grass_block)
B(-2,16,-11,minecraft:grass_block)
B(-2,16,-10,minecraft:grass_block)
B(-2,16,-9,minecraft:dirt)
B(-2,16,-8,minecraft:dirt)
B(-2,16,-7,minecraft:dirt)
B(-2,16,-6,minecraft:dirt)
B(-2,16,-5,minecraft:dirt)
B(-2,16,-4,minecraft:dirt)
B(-2,16,-3,minecraft:dirt)
B(-2,16,-2,minecraft:dirt)
B(-2,16,-1,minecraft:dirt)
B(-2,16,0,minecraft:dirt)
B(-2,16,1,minecraft:dirt)
B(-2,16,2,minecraft:dirt)
B(-2,16,3,minecraft:dirt)
B(-2,16,4,minecraft:dirt)
B(-2,16,5,minecraft:dirt)
B(-2,16,6,minecraft:grass_block)
B(-2,16,7,minecraft:grass_block)
B(-2,17,-9,minecraft:grass_block)
B(-2,17,-8,minecraft:grass_block)
B(-2,17,-7,minecraft:dirt)
B(-2,17,-6,minecraft:dirt)
B(-2,17,-5,minecraft:dirt)
B(-2,17,-4,minecraft:dirt)
B(-2,17,-3,minecraft:dirt)
B(-2,17,-2,minecraft:dirt)
B(-2,17,-1,minecraft:grass_block)
B(-2,17,0,minecraft:grass_block)
B(-2,17,1,minecraft:grass_block)
B(-2,17,2,minecraft:grass_block)
B(-2,17,3,minecraft:grass_block)
B(-2,17,4,minecraft:grass_block)
B(-2,17,5,minecraft:grass_block)
B(-2,18,-7,minecraft:grass_block)
B(-2,18,-6,minecraft:grass_block)
B(-2,18,-5,minecraft:dirt)
B(-2,18,-4,minecraft:dirt)
B(-2,18,-3,minecraft:dirt)
B(-2,18,-2,minecraft:grass_block)
B(-2,19,-5,minecraft:grass_block)
B(-2,19,-4,minecraft:grass_block)
B(-2,19,-3,minecraft:grass_block)
B(-1,0,-3,minecraft:stone)
B(-1,0,-2,minecraft:stone)
B(-1,0,-1,minecraft:stone)
B(-1,0,0,minecraft:stone)
B(-1,0,1,minecraft:stone)
B(-1,1,-3,minecraft:stone)
B(-1,1,-2,minecraft:stone)
B(-1,1,-1,minecraft:stone)
B(-1,1,0,minecraft:stone)
B(-1,1,1,minecraft:stone)
B(-1,1,2,minecraft:stone)
B(-1,1,3,minecraft:stone)
B(-1,1,4,minecraft:stone)
B(-1,1,5,minecraft:stone)
B(-1,2,-5,minecraft:stone)
B(-1,2,-4,minecraft:stone)
B(-1,2,-3,minecraft:stone)
B(-1,2,-2,minecraft:stone)
B(-1,2,-1,minecraft:stone)
B(-1,2,0,minecraft:stone)
B(-1,2,1,minecraft:stone)
B(-1,2,2,minecraft:stone)
B(-1,2,3,minecraft:stone)
B(-1,2,4,minecraft:stone)
B(-1,2,5,minecraft:stone)
B(-1,2,6,minecraft:stone)
B(-1,3,-7,minecraft:stone)
B(-1,3,-6,minecraft:stone)
B(-1,3,-5,minecraft:stone)
B(-1,3,-4,minecraft:stone)
B(-1,3,-3,minecraft:stone)
B(-1,3,-2,minecraft:stone)
B(-1,3,-1,minecraft:stone)
B(-1,3,0,minecraft:stone)
B(-1,3,1,minecraft:stone)
B(-1,3,2,minecraft:stone)
B(-1,3,3,minecraft:stone)
B(-1,3,4,minecraft:stone)
B(-1,3,5,minecraft:stone)
B(-1,3,6,minecraft:stone)
B(-1,3,7,minecraft:stone)
B(-1,4,-8,minecraft:stone)
B(-1,4,-7,minecraft:stone)
B(-1,4,-6,minecraft:stone)
B(-1,4,-5,minecraft:stone)
B(-1,4,-4,minecraft:stone)
B(-1,4,-3,minecraft:stone)
B(-1,4,-2,minecraft:stone)
B(-1,4,-1,minecraft:stone)
B(-1,4,0,minecraft:stone)
B(-1,4,1,minecraft:stone)
B(-1,4,2,minecraft:stone)
B(-1,4,3,minecraft:stone)
B(-1,4,4,minecraft:stone)
B(-1,4,5,minecraft:stone)
B(-1,4,6,minecraft:stone)
B(-1,4,7,minecraft:stone)
B(-1,5,-9,minecraft:stone)
B(-1,5,-8,minecraft:stone)
B(-1,5,-7,minecraft:stone)
B(-1,5,-6,minecraft:stone)
B(-1,5,-5,minecraft:stone)
B(-1,5,-4,minecraft:stone)
B(-1,5,-3,minecraft:stone)
B(-1,5,-2,minecraft:stone)
B(-1,5,-1,minecraft:stone)
B(-1,5,0,minecraft:stone)
B(-1,5,1,minecraft:stone)
B(-1,5,2,minecraft:stone)
B(-1,5,3,minecraft:stone)
B(-1,5,4,minecraft:stone)
B(-1,5,5,minecraft:stone)
B(-1,5,6,minecraft:stone)
B(-1,5,7,minecraft:stone)
B(-1,6,-11,minecraft:stone)
B(-1,6,-10,minecraft:stone)
B(-1,6,-9,minecraft:stone)
B(-1,6,-8,minecraft:stone)
B(-1,6,-7,minecraft:stone)
B(-1,6,-6,minecraft:stone)
B(-1,6,-5,minecraft:stone)
B(-1,6,-4,minecraft:stone)
B(-1,6,-3,minecraft:stone)
B(-1,6,-2,minecraft:stone)
B(-1,6,-1,minecraft:stone)
B(-1,6,0,minecraft:stone)
B(-1,6,1,minecraft:stone)
B(-1,6,2,minecraft:stone)
B(-1,6,3,minecraft:stone)
B(-1,6,4,minecraft:stone)
B(-1,6,5,minecraft:stone)
B(-1,6,6,minecraft:stone)
B(-1,6,7,minecraft:stone)
B(-1,6,8,minecraft:stone)
B(-1,7,-11,minecraft:stone)
B(-1,7,-10,minecraft:stone)
B(-1,7,-9,minecraft:stone)
B(-1,7,-8,minecraft:stone)
B(-1,7,-7,minecraft:stone)
B(-1,7,-6,minecraft:stone)
B(-1,7,-5,minecraft:stone)
B(-1,7,-4,minecraft:stone)
B(-1,7,-3,minecraft:stone)
B(-1,7,-2,minecraft:stone)
B(-1,7,-1,minecraft:stone)
B(-1,7,0,minecraft:stone)
B(-1,7,1,minecraft:stone)
B(-1,7,2,minecraft:stone)
B(-1,7,3,minecraft:stone)
B(-1,7,4,minecraft:stone)
B(-1,7,5,minecraft:stone)
B(-1,7,6,minecraft:stone)
B(-1,7,7,minecraft:stone)
B(-1,7,8,minecraft:stone)
B(-1,8,-12,minecraft:stone)
B(-1,8,-11,minecraft:stone)
B(-1,8,-10,minecraft:stone)
B(-1,8,-9,minecraft:stone)
B(-1,8,-8,minecraft:stone)
B(-1,8,-7,minecraft:stone)
B(-1,8,-6,minecraft:stone)
B(-1,8,-5,minecraft:stone)
B(-1,8,-4,minecraft:stone)
B(-1,8,-3,minecraft:stone)
B(-1,8,-2,minecraft:stone)
B(-1,8,-1,minecraft:stone)
B(-1,8,0,minecraft:stone)
B(-1,8,1,minecraft:stone)
B(-1,8,2,minecraft:stone)
B(-1,8,3,minecraft:stone)
B(-1,8,4,minecraft:stone)
B(-1,8,5,minecraft:stone)
B(-1,8,6,minecraft:stone)
B(-1,8,7,minecraft:stone)
B(-1,8,8,minecraft:stone)
B(-1,9,-13,minecraft:stone)
B(-1,9,-12,minecraft:stone)
B(-1,9,-11,minecraft:stone)
B(-1,9,-10,minecraft:stone)
B(-1,9,-9,minecraft:stone)
B(-1,9,-8,minecraft:stone)
B(-1,9,-7,minecraft:stone)
B(-1,9,-6,minecraft:stone)
B(-1,9,-5,minecraft:stone)
B(-1,9,-4,minecraft:stone)
B(-1,9,-3,minecraft:stone)
B(-1,9,-2,minecraft:stone)
B(-1,9,-1,minecraft:stone)
B(-1,9,0,minecraft:stone)
B(-1,9,1,minecraft:stone)
B(-1,9,2,minecraft:stone)
B(-1,9,3,minecraft:stone)
B(-1,9,4,minecraft:stone)
B(-1,9,5,minecraft:stone)
B(-1,9,6,minecraft:stone)
B(-1,9,7,minecraft:stone)
B(-1,9,8,minecraft:stone)
B(-1,9,9,minecraft:stone)
B(-1,10,-14,minecraft:stone)
B(-1,10,-13,minecraft:stone)
B(-1,10,-12,minecraft:stone)
B(-1,10,-11,minecraft:stone)
B(-1,10,-10,minecraft:stone)
B(-1,10,-9,minecraft:stone)
B(-1,10,-8,minecraft:stone)
B(-1,10,-7,minecraft:stone)
B(-1,10,-6,minecraft:stone)
B(-1,10,-5,minecraft:stone)
B(-1,10,-4,minecraft:stone)
B(-1,10,-3,minecraft:stone)
B(-1,10,-2,minecraft:stone)
B(-1,10,-1,minecraft:stone)
B(-1,10,0,minecraft:stone)
B(-1,10,1,minecraft:stone)
B(-1,10,2,minecraft:stone)
B(-1,10,3,minecraft:stone)
B(-1,10,4,minecraft:stone)
B(-1,10,5,minecraft:stone)
B(-1,10,6,minecraft:stone)
B(-1,10,7,minecraft:stone)
B(-1,10,8,minecraft:stone)
B(-1,10,9,minecraft:stone)
B(-1,11,-15,minecraft:stone)
B(-1,11,-14,minecraft:stone)
B(-1,11,-13,minecraft:stone)
B(-1,11,-12,minecraft:stone)
B(-1,11,-11,minecraft:stone)
B(-1,11,-10,minecraft:stone)
B(-1,11,-9,minecraft:stone)
B(-1,11,-8,minecraft:stone)
B(-1,11,-7,minecraft:stone)
B(-1,11,-6,minecraft:stone)
B(-1,11,-5,minecraft:stone)
B(-1,11,-4,minecraft:stone)
B(-1,11,-3,minecraft:stone)
B(-1,11,-2,minecraft:stone)
B(-1,11,-1,minecraft:stone)
B(-1,11,0,minecraft:stone)
B(-1,11,1,minecraft:stone)
B(-1,11,2,minecraft:stone)
B(-1,11,3,minecraft:stone)
B(-1,11,4,minecraft:stone)
B(-1,11,5,minecraft:stone)
B(-1,11,6,minecraft:stone)
B(-1,11,7,minecraft:stone)
B(-1,11,8,minecraft:stone)
B(-1,11,9,minecraft:stone)
B(-1,11,10,minecraft:stone)
B(-1,12,-15,minecraft:dirt)
B(-1,12,-14,minecraft:dirt)
B(-1,12,-13,minecraft:dirt)
B(-1,12,-12,minecraft:dirt)
B(-1,12,-11,minecraft:dirt)
B(-1,12,-10,minecraft:stone)
B(-1,12,-9,minecraft:stone)
B(-1,12,-8,minecraft:stone)
B(-1,12,-7,minecraft:stone)
B(-1,12,-6,minecraft:stone)
B(-1,12,-5,minecraft:stone)
B(-1,12,-4,minecraft:stone)
B(-1,12,-3,minecraft:stone)
B(-1,12,-2,minecraft:stone)
B(-1,12,-1,minecraft:stone)
B(-1,12,0,minecraft:stone)
B(-1,12,1,minecraft:stone)
B(-1,12,2,minecraft:stone)
B(-1,12,3,minecraft:stone)
B(-1,12,4,minecraft:stone)
B(-1,12,5,minecraft:stone)
B(-1,12,6,minecraft:stone)
B(-1,12,7,minecraft:stone)
B(-1,12,8,minecraft:dirt)
B(-1,12,9,minecraft:dirt)
B(-1,12,10,minecraft:dirt)
B(-1,13,-15,minecraft:dirt)
B(-1,13,-14,minecraft:dirt)
B(-1,13,-13,minecraft:dirt)
B(-1,13,-12,minecraft:dirt)
B(-1,13,-11,minecraft:dirt)
B(-1,13,-10,minecraft:dirt)
B(-1,13,-9,minecraft:dirt)
B(-1,13,-8,minecraft:stone)
B(-1,13,-7,minecraft:stone)
B(-1,13,-6,minecraft:stone)
B(-1,13,-5,minecraft:stone)
B(-1,13,-4,minecraft:stone)
B(-1,13,-3,minecraft:stone)
B(-1,13,-2,minecraft:stone)
B(-1,13,-1,minecraft:stone)
B(-1,13,0,minecraft:stone)
B(-1,13,1,minecraft:stone)
B(-1,13,2,minecraft:stone)
B(-1,13,3,minecraft:stone)
B(-1,13,4,minecraft:stone)
B(-1,13,5,minecraft:stone)
B(-1,13,6,minecraft:dirt)
B(-1,13,7,minecraft:dirt)
B(-1,13,8,minecraft:dirt)
B(-1,13,9,minecraft:dirt)
B(-1,13,10,minecraft:dirt)
B(-1,13,11,minecraft:dirt)
B(-1,14,-16,minecraft:dirt)
B(-1,14,-15,minecraft:dirt)
B(-1,14,-14,minecraft:dirt)
B(-1,14,-13,minecraft:dirt)
B(-1,14,-12,minecraft:dirt)
B(-1,14,-11,minecraft:dirt)
B(-1,14,-10,minecraft:dirt)
B(-1,14,-9,minecraft:dirt)
B(-1,14,-8,minecraft:dirt)
B(-1,14,-7,minecraft:dirt)
B(-1,14,-6,minecraft:stone)
B(-1,14,-5,minecraft:stone)
B(-1,14,-4,minecraft:stone)
B(-1,14,-3,minecraft:stone)
B(-1,14,-2,minecraft:stone)
B(-1,14,-1,minecraft:dirt)
B(-1,14,0,minecraft:dirt)
B(-1,14,1,minecraft:dirt)
B(-1,14,2,minecraft:dirt)
B(-1,14,3,minecraft:dirt)
B(-1,14,4,minecraft:dirt)
B(-1,14,5,minecraft:dirt)
B(-1,14,6,minecraft:dirt)
B(-1,14,7,minecraft:dirt)
B(-1,14,8,minecraft:dirt)
B(-1,14,9,minecraft:dirt)
B(-1,14,10,minecraft:dirt)
B(-1,14,11,minecraft:dirt)
B(-1,14,12,minecraft:dirt)
B(-1,14,13,minecraft:grass_block)
B(-1,15,-16,minecraft:grass_block)
B(-1,15,-15,minecraft:grass_block)
B(-1,15,-14,minecraft:grass_block)
B(-1,15,-13,minecraft:grass_block)
B(-1,15,-12,minecraft:grass_block)
B(-1,15,-11,minecraft:grass_block)
B(-1,15,-10,minecraft:dirt)
B(-1,15,-9,minecraft:dirt)
B(-1,15,-8,minecraft:dirt)
B(-1,15,-7,minecraft:dirt)
B(-1,15,-6,minecraft:dirt)
B(-1,15,-5,minecraft:dirt)
B(-1,15,-4,minecraft:dirt)
B(-1,15,-3,minecraft:dirt)
B(-1,15,-2,minecraft:dirt)
B(-1,15,-1,minecraft:dirt)
B(-1,15,0,minecraft:dirt)
B(-1,15,1,minecraft:dirt)
B(-1,15,2,minecraft:dirt)
B(-1,15,3,minecraft:dirt)
B(-1,15,4,minecraft:dirt)
B(-1,15,5,minecraft:dirt)
B(-1,15,6,minecraft:dirt)
B(-1,15,7,minecraft:dirt)
B(-1,15,8,minecraft:grass_block)
B(-1,15,9,minecraft:grass_block)
B(-1,15,10,minecraft:grass_block)
B(-1,15,11,minecraft:grass_block)
B(-1,15,12,minecraft:grass_block)
B(-1,16,-10,minecraft:grass_block)
B(-1,16,-9,minecraft:grass_block)
B(-1,16,-8,minecraft:dirt)
B(-1,16,-7,minecraft:dirt)
B(-1,16,-6,minecraft:dirt)
B(-1,16,-5,minecraft:dirt)
B(-1,16,-4,minecraft:dirt)
B(-1,16,-3,minecraft:dirt)
B(-1,16,-2,minecraft:dirt)
B(-1,16,-1,minecraft:dirt)
B(-1,16,0,minecraft:dirt)
B(-1,16,1,minecraft:dirt)
B(-1,16,2,minecraft:dirt)
B(-1,16,3,minecraft:dirt)
B(-1,16,4,minecraft:dirt)
B(-1,16,5,minecraft:dirt)
B(-1,16,6,minecraft:grass_block)
B(-1,16,7,minecraft:grass_block)
B(-1,17,-8,minecraft:grass_block)
B(-1,17,-7,minecraft:grass_block)
B(-1,17,-6,minecraft:dirt)
B(-1,17,-5,minecraft:dirt)
B(-1,17,-4,minecraft:dirt)
B(-1,17,-3,minecraft:dirt)
B(-1,17,-2,minecraft:dirt)
B(-1,17,-1,minecraft:grass_block)
B(-1,17,0,minecraft:grass_block)
B(-1,17,1,minecraft:grass_block)
B(-1,17,2,minecraft:grass_block)
B(-1,17,3,minecraft:grass_block)
B(-1,17,4,minecraft:grass_block)
B(-1,17,5,minecraft:grass_block)
B(-1,18,-6,minecraft:grass_block)
B(-1,18,-5,minecraft:grass_block)
B(-1,18,-4,minecraft:grass_block)
B(-1,18,-3,minecraft:grass_block)
B(-1,18,-2,minecraft:grass_block)
B(0,0,-1,minecraft:stone)
B(0,0,0,minecraft:stone)
B(0,0,1,minecraft:stone)
B(0,1,-3,minecraft:stone)
B(0,1,-2,minecraft:stone)
B(0,1,-1,minecraft:stone)
B(0,1,0,minecraft:stone)
B(0,1,1,minecraft:stone)
B(0,1,2,minecraft:stone)
B(0,1,3,minecraft:stone)
B(0,1,4,minecraft:stone)
B(0,1,5,minecraft:stone)
B(0,2,-4,minecraft:stone)
B(0,2,-3,minecraft:stone)
B(0,2,-2,minecraft:stone)
B(0,2,-1,minecraft:stone)
B(0,2,0,minecraft:stone)
B(0,2,1,minecraft:stone)
B(0,2,2,minecraft:stone)
B(0,2,3,minecraft:stone)
B(0,2,4,minecraft:stone)
B(0,2,5,minecraft:stone)
B(0,2,6,minecraft:stone)
B(0,3,-5,minecraft:stone)
B(0,3,-4,minecraft:stone)
B(0,3,-3,minecraft:stone)
B(0,3,-2,minecraft:stone)
B(0,3,-1,minecraft:stone)
B(0,3,0,minecraft:stone)
B(0,3,1,minecraft:stone)
B(0,3,2,minecraft:stone)
B(0,3,3,minecraft:stone)
B(0,3,4,minecraft:stone)
B(0,3,5,minecraft:stone)
B(0,3,6,minecraft:stone)
B(0,3,7,minecraft:stone)
B(0,4,-7,minecraft:stone)
B(0,4,-6,minecraft:stone)
B(0,4,-5,minecraft:stone)
B(0,4,-4,minecraft:stone)
B(0,4,-3,minecraft:stone)
B(0,4,-2,minecraft:stone)
B(0,4,-1,minecraft:stone)
B(0,4,0,minecraft:stone)
B(0,4,1,minecraft:stone)
B(0,4,2,minecraft:stone)
B(0,4,3,minecraft:stone)
B(0,4,4,minecraft:stone)
B(0,4,5,minecraft:stone)
B(0,4,6,minecraft:stone)
B(0,4,7,minecraft:stone)
B(0,4,8,minecraft:stone)
B(0,5,-9,minecraft:stone)
B(0,5,-8,minecraft:stone)
B(0,5,-7,minecraft:stone)
B(0,5,-6,minecraft:stone)
B(0,5,-5,minecraft:stone)
B(0,5,-4,minecraft:stone)
B(0,5,-3,minecraft:stone)
B(0,5,-2,minecraft:stone)
B(0,5,-1,minecraft:stone)
B(0,5,0,minecraft:stone)
B(0,5,1,minecraft:stone)
B(0,5,2,minecraft:stone)
B(0,5,3,minecraft:stone)
B(0,5,4,minecraft:stone)
B(0,5,5,minecraft:stone)
B(0,5,6,minecraft:stone)
B(0,5,7,minecraft:stone)
B(0,5,8,minecraft:stone)
B(0,6,-10,minecraft:stone)
B(0,6,-9,minecraft:stone)
B(0,6,-8,minecraft:stone)
B(0,6,-7,minecraft:stone)
B(0,6,-6,minecraft:stone)
B(0,6,-5,minecraft:stone)
B(0,6,-4,minecraft:stone)
B(0,6,-3,minecraft:stone)
B(0,6,-2,minecraft:stone)
B(0,6,-1,minecraft:stone)
B(0,6,0,minecraft:stone)
B(0,6,1,minecraft:stone)
B(0,6,2,minecraft:stone)
B(0,6,3,minecraft:stone)
B(0,6,4,minecraft:stone)
B(0,6,5,minecraft:stone)
B(0,6,6,minecraft:stone)
B(0,6,7,minecraft:stone)
B(0,6,8,minecraft:stone)
B(0,7,-11,minecraft:stone)
B(0,7,-10,minecraft:stone)
B(0,7,-9,minecraft:stone)
B(0,7,-8,minecraft:stone)
B(0,7,-7,minecraft:stone)
B(0,7,-6,minecraft:stone)
B(0,7,-5,minecraft:stone)
B(0,7,-4,minecraft:stone)
B(0,7,-3,minecraft:stone)
B(0,7,-2,minecraft:stone)
B(0,7,-1,minecraft:stone)
B(0,7,0,minecraft:stone)
B(0,7,1,minecraft:stone)
B(0,7,2,minecraft:stone)
B(0,7,3,minecraft:stone)
B(0,7,4,minecraft:stone)
B(0,7,5,minecraft:stone)
B(0,7,6,minecraft:stone)
B(0,7,7,minecraft:stone)
B(0,7,8,minecraft:stone)
B(0,8,-12,minecraft:stone)
B(0,8,-11,minecraft:stone)
B(0,8,-10,minecraft:stone)
B(0,8,-9,minecraft:stone)
B(0,8,-8,minecraft:stone)
B(0,8,-7,minecraft:stone)
B(0,8,-6,minecraft:stone)
B(0,8,-5,minecraft:stone)
B(0,8,-4,minecraft:stone)
B(0,8,-3,minecraft:stone)
B(0,8,-2,minecraft:stone)
B(0,8,-1,minecraft:stone)
B(0,8,0,minecraft:stone)
B(0,8,1,minecraft:stone)
B(0,8,2,minecraft:stone)
B(0,8,3,minecraft:stone)
B(0,8,4,minecraft:stone)
B(0,8,5,minecraft:stone)
B(0,8,6,minecraft:stone)
B(0,8,7,minecraft:stone)
B(0,8,8,minecraft:stone)
B(0,9,-13,minecraft:stone)
B(0,9,-12,minecraft:stone)
B(0,9,-11,minecraft:stone)
B(0,9,-10,minecraft:stone)
B(0,9,-9,minecraft:stone)
B(0,9,-8,minecraft:stone)
B(0,9,-7,minecraft:stone)
B(0,9,-6,minecraft:stone)
B(0,9,-5,minecraft:stone)
B(0,9,-4,minecraft:stone)
B(0,9,-3,minecraft:stone)
B(0,9,-2,minecraft:stone)
B(0,9,-1,minecraft:stone)
B(0,9,0,minecraft:stone)
B(0,9,1,minecraft:stone)
B(0,9,2,minecraft:stone)
B(0,9,3,minecraft:stone)
B(0,9,4,minecraft:stone)
B(0,9,5,minecraft:stone)
B(0,9,6,minecraft:stone)
B(0,9,7,minecraft:stone)
B(0,9,8,minecraft:stone)
B(0,9,9,minecraft:stone)
B(0,10,-14,minecraft:stone)
B(0,10,-13,minecraft:stone)
B(0,10,-12,minecraft:stone)
B(0,10,-11,minecraft:stone)
B(0,10,-10,minecraft:stone)
B(0,10,-9,minecraft:stone)
B(0,10,-8,minecraft:stone)
B(0,10,-7,minecraft:stone)
B(0,10,-6,minecraft:stone)
B(0,10,-5,minecraft:stone)
B(0,10,-4,minecraft:stone)
B(0,10,-3,minecraft:stone)
B(0,10,-2,minecraft:stone)
B(0,10,-1,minecraft:stone)
B(0,10,0,minecraft:stone)
B(0,10,1,minecraft:stone)
B(0,10,2,minecraft:stone)
B(0,10,3,minecraft:stone)
B(0,10,4,minecraft:stone)
B(0,10,5,minecraft:stone)
B(0,10,6,minecraft:stone)
B(0,10,7,minecraft:stone)
B(0,10,8,minecraft:stone)
B(0,10,9,minecraft:stone)
B(0,10,10,minecraft:stone)
B(0,11,-15,minecraft:stone)
B(0,11,-14,minecraft:stone)
B(0,11,-13,minecraft:stone)
B(0,11,-12,minecraft:stone)
B(0,11,-11,minecraft:stone)
B(0,11,-10,minecraft:stone)
B(0,11,-9,minecraft:stone)
B(0,11,-8,minecraft:stone)
B(0,11,-7,minecraft:stone)
B(0,11,-6,minecraft:stone)
B(0,11,-5,minecraft:stone)
B(0,11,-4,minecraft:stone)
B(0,11,-3,minecraft:stone)
B(0,11,-2,minecraft:stone)
B(0,11,-1,minecraft:stone)
B(0,11,0,minecraft:stone)
B(0,11,1,minecraft:stone)
B(0,11,2,minecraft:stone)
B(0,11,3,minecraft:stone)
B(0,11,4,minecraft:stone)
B(0,11,5,minecraft:stone)
B(0,11,6,minecraft:stone)
B(0,11,7,minecraft:stone)
B(0,11,8,minecraft:stone)
B(0,11,9,minecraft:stone)
B(0,11,10,minecraft:stone)
B(0,12,-15,minecraft:dirt)
B(0,12,-14,minecraft:dirt)
B(0,12,-13,minecraft:dirt)
B(0,12,-12,minecraft:dirt)
B(0,12,-11,minecraft:dirt)
B(0,12,-10,minecraft:dirt)
B(0,12,-9,minecraft:stone)
B(0,12,-8,minecraft:stone)
B(0,12,-7,minecraft:stone)
B(0,12,-6,minecraft:stone)
B(0,12,-5,minecraft:stone)
B(0,12,-4,minecraft:stone)
B(0,12,-3,minecraft:stone)
B(0,12,-2,minecraft:stone)
B(0,12,-1,minecraft:stone)
B(0,12,0,minecraft:stone)
B(0,12,1,minecraft:stone)
B(0,12,2,minecraft:stone)
B(0,12,3,minecraft:stone)
B(0,12,4,minecraft:stone)
B(0,12,5,minecraft:stone)
B(0,12,6,minecraft:stone)
B(0,12,7,minecraft:stone)
B(0,12,8,minecraft:stone)
B(0,12,9,minecraft:dirt)
B(0,12,10,minecraft:dirt)
B(0,12,11,minecraft:dirt)
B(0,13,-15,minecraft:dirt)
B(0,13,-14,minecraft:dirt)
B(0,13,-13,minecraft:dirt)
B(0,13,-12,minecraft:dirt)
B(0,13,-11,minecraft:dirt)
B(0,13,-10,minecraft:dirt)
B(0,13,-9,minecraft:dirt)
B(0,13,-8,minecraft:dirt)
B(0,13,-7,minecraft:stone)
B(0,13,-6,minecraft:stone)
B(0,13,-5,minecraft:stone)
B(0,13,-4,minecraft:stone)
B(0,13,-3,minecraft:stone)
B(0,13,-2,minecraft:stone)
B(0,13,-1,minecraft:stone)
B(0,13,0,minecraft:stone)
B(0,13,1,minecraft:stone)
B(0,13,2,minecraft:stone)
B(0,13,3,minecraft:stone)
B(0,13,4,minecraft:stone)
B(0,13,5,minecraft:stone)
B(0,13,6,minecraft:stone)
B(0,13,7,minecraft:dirt)
B(0,13,8,minecraft:dirt)
B(0,13,9,minecraft:dirt)
B(0,13,10,minecraft:dirt)
B(0,13,11,minecraft:dirt)
B(0,13,12,minecraft:dirt)
B(0,14,-15,minecraft:dirt)
B(0,14,-14,minecraft:dirt)
B(0,14,-13,minecraft:dirt)
B(0,14,-12,minecraft:dirt)
B(0,14,-11,minecraft:dirt)
B(0,14,-10,minecraft:dirt)
B(0,14,-9,minecraft:dirt)
B(0,14,-8,minecraft:dirt)
B(0,14,-7,minecraft:dirt)
B(0,14,-6,minecraft:dirt)
B(0,14,-5,minecraft:stone)
B(0,14,-4,minecraft:stone)
B(0,14,-3,minecraft:stone)
B(0,14,-2,minecraft:stone)
B(0,14,-1,minecraft:dirt)
B(0,14,0,minecraft:dirt)
B(0,14,1,minecraft:dirt)
B(0,14,2,minecraft:dirt)
B(0,14,3,minecraft:dirt)
B(0,14,4,minecraft:dirt)
B(0,14,5,minecraft:dirt)
B(0,14,6,minecraft:dirt)
B(0,14,7,minecraft:dirt)
B(0,14,8,minecraft:dirt)
B(0,14,9,minecraft:dirt)
B(0,14,10,minecraft:dirt)
B(0,14,11,minecraft:dirt)
B(0,14,12,minecraft:dirt)
B(0,14,13,minecraft:dirt)
B(0,15,-15,minecraft:grass_block)
B(0,15,-14,minecraft:grass_block)
B(0,15,-13,minecraft:grass_block)
B(0,15,-12,minecraft:grass_block)
B(0,15,-11,minecraft:grass_block)
B(0,15,-10,minecraft:grass_block)
B(0,15,-9,minecraft:dirt)
B(0,15,-8,minecraft:dirt)
B(0,15,-7,minecraft:dirt)
B(0,15,-6,minecraft:dirt)
B(0,15,-5,minecraft:dirt)
B(0,15,-4,minecraft:dirt)
B(0,15,-3,minecraft:dirt)
B(0,15,-2,minecraft:dirt)
B(0,15,-1,minecraft:dirt)
B(0,15,0,minecraft:dirt)
B(0,15,1,minecraft:dirt)
B(0,15,2,minecraft:dirt)
B(0,15,3,minecraft:dirt)
B(0,15,4,minecraft:dirt)
B(0,15,5,minecraft:dirt)
B(0,15,6,minecraft:dirt)
B(0,15,7,minecraft:dirt)
B(0,15,8,minecraft:dirt)
B(0,15,9,minecraft:grass_block)
B(0,15,10,minecraft:grass_block)
B(0,15,11,minecraft:grass_block)
B(0,15,12,minecraft:grass_block)
B(0,15,13,minecraft:grass_block)
B(0,16,-9,minecraft:grass_block)
B(0,16,-8,minecraft:grass_block)
B(0,16,-7,minecraft:dirt)
B(0,16,-6,minecraft:dirt)
B(0,16,-5,minecraft:dirt)
B(0,16,-4,minecraft:dirt)
B(0,16,-3,minecraft:dirt)
B(0,16,-2,minecraft:dirt)
B(0,16,-1,minecraft:dirt)
B(0,16,0,minecraft:dirt)
B(0,16,1,minecraft:dirt)
B(0,16,2,minecraft:dirt)
B(0,16,3,minecraft:dirt)
B(0,16,4,minecraft:dirt)
B(0,16,5,minecraft:dirt)
B(0,16,6,minecraft:dirt)
B(0,16,7,minecraft:grass_block)
B(0,16,8,minecraft:grass_block)
B(0,17,-7,minecraft:grass_block)
B(0,17,-6,minecraft:grass_block)
B(0,17,-5,minecraft:dirt)
B(0,17,-4,minecraft:dirt)
B(0,17,-3,minecraft:dirt)
B(0,17,-2,minecraft:dirt)
B(0,17,-1,minecraft:grass_block)
B(0,17,0,minecraft:grass_block)
B(0,17,1,minecraft:grass_block)
B(0,17,2,minecraft:grass_block)
B(0,17,3,minecraft:grass_block)
B(0,17,4,minecraft:grass_block)
B(0,17,5,minecraft:grass_block)
B(0,17,6,minecraft:grass_block)
B(0,18,-5,minecraft:grass_block)
B(0,18,-4,minecraft:grass_block)
B(0,18,-3,minecraft:grass_block)
B(0,18,-2,minecraft:grass_block)
B(1,0,0,minecraft:stone)
B(1,0,1,minecraft:stone)
B(1,1,-1,minecraft:stone)
B(1,1,0,minecraft:stone)
B(1,1,1,minecraft:stone)
B(1,1,2,minecraft:stone)
B(1,1,3,minecraft:stone)
B(1,1,4,minecraft:stone)
B(1,1,5,minecraft:stone)
B(1,2,-4,minecraft:stone)
B(1,2,-3,minecraft:stone)
B(1,2,-2,minecraft:stone)
B(1,2,-1,minecraft:stone)
B(1,2,0,minecraft:stone)
B(1,2,1,minecraft:stone)
B(1,2,2,minecraft:stone)
B(1,2,3,minecraft:stone)
B(1,2,4,minecraft:stone)
B(1,2,5,minecraft:stone)
B(1,2,6,minecraft:stone)
B(1,3,-5,minecraft:stone)
B(1,3,-4,minecraft:stone)
B(1,3,-3,minecraft:stone)
B(1,3,-2,minecraft:stone)
B(1,3,-1,minecraft:stone)
B(1,3,0,minecraft:stone)
B(1,3,1,minecraft:stone)
B(1,3,2,minecraft:stone)
B(1,3,3,minecraft:stone)
B(1,3,4,minecraft:stone)
B(1,3,5,minecraft:stone)
B(1,3,6,minecraft:stone)
B(1,3,7,minecraft:stone)
B(1,4,-6,minecraft:stone)
B(1,4,-5,minecraft:stone)
B(1,4,-4,minecraft:stone)
B(1,4,-3,minecraft:stone)
B(1,4,-2,minecraft:stone)
B(1,4,-1,minecraft:stone)
B(1,4,0,minecraft:stone)
B(1,4,1,minecraft:stone)
B(1,4,2,minecraft:stone)
B(1,4,3,minecraft:stone)
B(1,4,4,minecraft:stone)
B(1,4,5,minecraft:stone)
B(1,4,6,minecraft:stone)
B(1,4,7,minecraft:stone)
B(1,4,8,minecraft:stone)
B(1,5,-8,minecraft:stone)
B(1,5,-7,minecraft:stone)
B(1,5,-6,minecraft:stone)
B(1,5,-5,minecraft:stone)
B(1,5,-4,minecraft:stone)
B(1,5,-3,minecraft:stone)
B(1,5,-2,minecraft:stone)
B(1,5,-1,minecraft:stone)
B(1,5,0,minecraft:stone)
B(1,5,1,minecraft:stone)
B(1,5,2,minecraft:stone)
B(1,5,3,minecraft:stone)
B(1,5,4,minecraft:stone)
B(1,5,5,minecraft:stone)
B(1,5,6,minecraft:stone)
B(1,5,7,minecraft:stone)
B(1,5,8,minecraft:stone)
B(1,6,-9,minecraft:stone)
B(1,6,-8,minecraft:stone)
B(1,6,-7,minecraft:stone)
B(1,6,-6,minecraft:stone)
B(1,6,-5,minecraft:stone)
B(1,6,-4,minecraft:stone)
B(1,6,-3,minecraft:stone)
B(1,6,-2,minecraft:stone)
B(1,6,-1,minecraft:stone)
B(1,6,0,minecraft:stone)
B(1,6,1,minecraft:stone)
B(1,6,2,minecraft:stone)
B(1,6,3,minecraft:stone)
B(1,6,4,minecraft:stone)
B(1,6,5,minecraft:stone)
B(1,6,6,minecraft:stone)
B(1,6,7,minecraft:stone)
B(1,6,8,minecraft:stone)
B(1,7,-11,minecraft:stone)
B(1,7,-10,minecraft:stone)
B(1,7,-9,minecraft:stone)
B(1,7,-8,minecraft:stone)
B(1,7,-7,minecraft:stone)
B(1,7,-6,minecraft:stone)
B(1,7,-5,minecraft:stone)
B(1,7,-4,minecraft:stone)
B(1,7,-3,minecraft:stone)
B(1,7,-2,minecraft:stone)
B(1,7,-1,minecraft:stone)
B(1,7,0,minecraft:stone)
B(1,7,1,minecraft:stone)
B(1,7,2,minecraft:stone)
B(1,7,3,minecraft:stone)
B(1,7,4,minecraft:stone)
B(1,7,5,minecraft:stone)
B(1,7,6,minecraft:stone)
B(1,7,7,minecraft:stone)
B(1,7,8,minecraft:stone)
B(1,7,9,minecraft:stone)
B(1,8,-11,minecraft:stone)
B(1,8,-10,minecraft:stone)
B(1,8,-9,minecraft:stone)
B(1,8,-8,minecraft:stone)
B(1,8,-7,minecraft:stone)
B(1,8,-6,minecraft:stone)
B(1,8,-5,minecraft:stone)
B(1,8,-4,minecraft:stone)
B(1,8,-3,minecraft:stone)
B(1,8,-2,minecraft:stone)
B(1,8,-1,minecraft:stone)
B(1,8,0,minecraft:stone)
B(1,8,1,minecraft:stone)
B(1,8,2,minecraft:stone)
B(1,8,3,minecraft:stone)
B(1,8,4,minecraft:stone)
B(1,8,5,minecraft:stone)
B(1,8,6,minecraft:stone)
B(1,8,7,minecraft:stone)
B(1,8,8,minecraft:stone)
B(1,8,9,minecraft:stone)
B(1,9,-12,minecraft:stone)
B(1,9,-11,minecraft:stone)
B(1,9,-10,minecraft:stone)
B(1,9,-9,minecraft:stone)
B(1,9,-8,minecraft:stone)
B(1,9,-7,minecraft:stone)
B(1,9,-6,minecraft:stone)
B(1,9,-5,minecraft:stone)
B(1,9,-4,minecraft:stone)
B(1,9,-3,minecraft:stone)
B(1,9,-2,minecraft:stone)
B(1,9,-1,minecraft:stone)
B(1,9,0,minecraft:stone)
B(1,9,1,minecraft:stone)
B(1,9,2,minecraft:stone)
B(1,9,3,minecraft:stone)
B(1,9,4,minecraft:stone)
B(1,9,5,minecraft:stone)
B(1,9,6,minecraft:stone)
B(1,9,7,minecraft:stone)
B(1,9,8,minecraft:stone)
B(1,9,9,minecraft:stone)
B(1,9,10,minecraft:stone)
B(1,10,-13,minecraft:stone)
B(1,10,-12,minecraft:stone)
B(1,10,-11,minecraft:stone)
B(1,10,-10,minecraft:stone)
B(1,10,-9,minecraft:stone)
B(1,10,-8,minecraft:stone)
B(1,10,-7,minecraft:stone)
B(1,10,-6,minecraft:stone)
B(1,10,-5,minecraft:stone)
B(1,10,-4,minecraft:stone)
B(1,10,-3,minecraft:stone)
B(1,10,-2,minecraft:stone)
B(1,10,-1,minecraft:stone)
B(1,10,0,minecraft:stone)
B(1,10,1,minecraft:stone)
B(1,10,2,minecraft:stone)
B(1,10,3,minecraft:stone)
B(1,10,4,minecraft:stone)
B(1,10,5,minecraft:stone)
B(1,10,6,minecraft:stone)
B(1,10,7,minecraft:stone)
B(1,10,8,minecraft:stone)
B(1,10,9,minecraft:stone)
B(1,10,10,minecraft:stone)
B(1,11,-14,minecraft:stone)
B(1,11,-13,minecraft:stone)
B(1,11,-12,minecraft:stone)
B(1,11,-11,minecraft:stone)
B(1,11,-10,minecraft:stone)
B(1,11,-9,minecraft:stone)
B(1,11,-8,minecraft:stone)
B(1,11,-7,minecraft:stone)
B(1,11,-6,minecraft:stone)
B(1,11,-5,minecraft:stone)
B(1,11,-4,minecraft:stone)
B(1,11,-3,minecraft:stone)
B(1,11,-2,minecraft:stone)
B(1,11,-1,minecraft:stone)
B(1,11,0,minecraft:stone)
B(1,11,1,minecraft:stone)
B(1,11,2,minecraft:stone)
B(1,11,3,minecraft:stone)
B(1,11,4,minecraft:stone)
B(1,11,5,minecraft:stone)
B(1,11,6,minecraft:stone)
B(1,11,7,minecraft:stone)
B(1,11,8,minecraft:stone)
B(1,11,9,minecraft:stone)
B(1,11,10,minecraft:stone)
B(1,11,11,minecraft:stone)
B(1,12,-14,minecraft:dirt)
B(1,12,-13,minecraft:dirt)
B(1,12,-12,minecraft:dirt)
B(1,12,-11,minecraft:dirt)
B(1,12,-10,minecraft:dirt)
B(1,12,-9,minecraft:stone)
B(1,12,-8,minecraft:stone)
B(1,12,-7,minecraft:stone)
B(1,12,-6,minecraft:stone)
B(1,12,-5,minecraft:stone)
B(1,12,-4,minecraft:stone)
B(1,12,-3,minecraft:stone)
B(1,12,-2,minecraft:stone)
B(1,12,-1,minecraft:stone)
B(1,12,0,minecraft:stone)
B(1,12,1,minecraft:stone)
B(1,12,2,minecraft:stone)
B(1,12,3,minecraft:stone)
B(1,12,4,minecraft:stone)
B(1,12,5,minecraft:stone)
B(1,12,6,minecraft:stone)
B(1,12,7,minecraft:stone)
B(1,12,8,minecraft:stone)
B(1,12,9,minecraft:dirt)
B(1,12,10,minecraft:dirt)
B(1,12,11,minecraft:dirt)
B(1,13,-14,minecraft:dirt)
B(1,13,-13,minecraft:dirt)
B(1,13,-12,minecraft:dirt)
B(1,13,-11,minecraft:dirt)
B(1,13,-10,minecraft:dirt)
B(1,13,-9,minecraft:dirt)
B(1,13,-8,minecraft:dirt)
B(1,13,-7,minecraft:stone)
B(1,13,-6,minecraft:stone)
B(1,13,-5,minecraft:stone)
B(1,13,-4,minecraft:stone)
B(1,13,-3,minecraft:stone)
B(1,13,-2,minecraft:stone)
B(1,13,-1,minecraft:stone)
B(1,13,0,minecraft:stone)
B(1,13,1,minecraft:stone)
B(1,13,2,minecraft:stone)
B(1,13,3,minecraft:stone)
B(1,13,4,minecraft:stone)
B(1,13,5,minecraft:stone)
B(1,13,6,minecraft:stone)
B(1,13,7,minecraft:stone)
B(1,13,8,minecraft:dirt)
B(1,13,9,minecraft:dirt)
B(1,13,10,minecraft:dirt)
B(1,13,11,minecraft:dirt)
B(1,13,12,minecraft:dirt)
B(1,14,-15,minecraft:dirt)
B(1,14,-14,minecraft:dirt)
B(1,14,-13,minecraft:dirt)
B(1,14,-12,minecraft:dirt)
B(1,14,-11,minecraft:dirt)
B(1,14,-10,minecraft:dirt)
B(1,14,-9,minecraft:dirt)
B(1,14,-8,minecraft:dirt)
B(1,14,-7,minecraft:dirt)
B(1,14,-6,minecraft:dirt)
B(1,14,-5,minecraft:dirt)
B(1,14,-4,minecraft:dirt)
B(1,14,-3,minecraft:stone)
B(1,14,-2,minecraft:stone)
B(1,14,-1,minecraft:stone)
B(1,14,0,minecraft:dirt)
B(1,14,1,minecraft:dirt)
B(1,14,2,minecraft:dirt)
B(1,14,3,minecraft:dirt)
B(1,14,4,minecraft:dirt)
B(1,14,5,minecraft:dirt)
B(1,14,6,minecraft:dirt)
B(1,14,7,minecraft:dirt)
B(1,14,8,minecraft:dirt)
B(1,14,9,minecraft:dirt)
B(1,14,10,minecraft:dirt)
B(1,14,11,minecraft:dirt)
B(1,14,12,minecraft:dirt)
B(1,14,13,minecraft:dirt)
B(1,15,-15,minecraft:grass_block)
B(1,15,-14,minecraft:grass_block)
B(1,15,-13,minecraft:grass_block)
B(1,15,-12,minecraft:grass_block)
B(1,15,-11,minecraft:grass_block)
B(1,15,-10,minecraft:grass_block)
B(1,15,-9,minecraft:dirt)
B(1,15,-8,minecraft:dirt)
B(1,15,-7,minecraft:dirt)
B(1,15,-6,minecraft:dirt)
B(1,15,-5,minecraft:dirt)
B(1,15,-4,minecraft:dirt)
B(1,15,-3,minecraft:dirt)
B(1,15,-2,minecraft:dirt)
B(1,15,-1,minecraft:dirt)
B(1,15,0,minecraft:dirt)
B(1,15,1,minecraft:dirt)
B(1,15,2,minecraft:dirt)
B(1,15,3,minecraft:dirt)
B(1,15,4,minecraft:dirt)
B(1,15,5,minecraft:dirt)
B(1,15,6,minecraft:dirt)
B(1,15,7,minecraft:dirt)
B(1,15,8,minecraft:dirt)
B(1,15,9,minecraft:grass_block)
B(1,15,10,minecraft:grass_block)
B(1,15,11,minecraft:grass_block)
B(1,15,12,minecraft:grass_block)
B(1,15,13,minecraft:grass_block)
B(1,15,14,minecraft:grass_block)
B(1,16,-9,minecraft:grass_block)
B(1,16,-8,minecraft:grass_block)
B(1,16,-7,minecraft:dirt)
B(1,16,-6,minecraft:dirt)
B(1,16,-5,minecraft:dirt)
B(1,16,-4,minecraft:dirt)
B(1,16,-3,minecraft:dirt)
B(1,16,-2,minecraft:dirt)
B(1,16,-1,minecraft:dirt)
B(1,16,0,minecraft:dirt)
B(1,16,1,minecraft:dirt)
B(1,16,2,minecraft:dirt)
B(1,16,3,minecraft:dirt)
B(1,16,4,minecraft:dirt)
B(1,16,5,minecraft:dirt)
B(1,16,6,minecraft:dirt)
B(1,16,7,minecraft:dirt)
B(1,16,8,minecraft:grass_block)
B(1,17,-7,minecraft:grass_block)
B(1,17,-6,minecraft:grass_block)
B(1,17,-5,minecraft:grass_block)
B(1,17,-4,minecraft:grass_block)
B(1,17,-3,minecraft:dirt)
B(1,17,-2,minecraft:dirt)
B(1,17,-1,minecraft:dirt)
B(1,17,0,minecraft:grass_block)
B(1,17,1,minecraft:grass_block)
B(1,17,2,minecraft:grass_block)
B(1,17,3,minecraft:grass_block)
B(1,17,4,minecraft:grass_block)
B(1,17,5,minecraft:grass_block)
B(1,17,6,minecraft:grass_block)
B(1,17,7,minecraft:grass_block)
B(1,18,-3,minecraft:grass_block)
B(1,18,-2,minecraft:grass_block)
B(1,18,-1,minecraft:grass_block)
B(2,0,0,minecraft:stone)
B(2,0,1,minecraft:stone)
B(2,1,-1,minecraft:stone)
B(2,1,0,minecraft:stone)
B(2,1,1,minecraft:stone)
B(2,1,2,minecraft:stone)
B(2,1,3,minecraft:stone)
B(2,1,4,minecraft:stone)
B(2,2,-3,minecraft:stone)
B(2,2,-2,minecraft:stone)
B(2,2,-1,minecraft:stone)
B(2,2,0,minecraft:stone)
B(2,2,1,minecraft:stone)
B(2,2,2,minecraft:stone)
B(2,2,3,minecraft:stone)
B(2,2,4,minecraft:stone)
B(2,2,5,minecraft:stone)
B(2,2,6,minecraft:stone)
B(2,3,-4,minecraft:stone)
B(2,3,-3,minecraft:stone)
B(2,3,-2,minecraft:stone)
B(2,3,-1,minecraft:stone)
B(2,3,0,minecraft:stone)
B(2,3,1,minecraft:stone)
B(2,3,2,minecraft:stone)
B(2,3,3,minecraft:stone)
B(2,3,4,minecraft:stone)
B(2,3,5,minecraft:stone)
B(2,3,6,minecraft:stone)
B(2,3,7,minecraft:stone)
B(2,4,-6,minecraft:stone)
B(2,4,-5,minecraft:stone)
B(2,4,-4,minecraft:stone)
B(2,4,-3,minecraft:stone)
B(2,4,-2,minecraft:stone)
B(2,4,-1,minecraft:stone)
B(2,4,0,minecraft:stone)
B(2,4,1,minecraft:stone)
B(2,4,2,minecraft:stone)
B(2,4,3,minecraft:stone)
B(2,4,4,minecraft:stone)
B(2,4,5,minecraft:stone)
B(2,4,6,minecraft:stone)
B(2,4,7,minecraft:stone)
B(2,4,8,minecraft:stone)
B(2,5,-7,minecraft:stone)
B(2,5,-6,minecraft:stone)
B(2,5,-5,minecraft:stone)
B(2,5,-4,minecraft:stone)
B(2,5,-3,minecraft:stone)
B(2,5,-2,minecraft:stone)
B(2,5,-1,minecraft:stone)
B(2,5,0,minecraft:stone)
B(2,5,1,minecraft:stone)
B(2,5,2,minecraft:stone)
B(2,5,3,minecraft:stone)
B(2,5,4,minecraft:stone)
B(2,5,5,minecraft:stone)
B(2,5,6,minecraft:stone)
B(2,5,7,minecraft:stone)
B(2,5,8,minecraft:stone)
B(2,6,-8,minecraft:stone)
B(2,6,-7,minecraft:stone)
B(2,6,-6,minecraft:stone)
B(2,6,-5,minecraft:stone)
B(2,6,-4,minecraft:stone)
B(2,6,-3,minecraft:stone)
B(2,6,-2,minecraft:stone)
B(2,6,-1,minecraft:stone)
B(2,6,0,minecraft:stone)
B(2,6,1,minecraft:stone)
B(2,6,2,minecraft:stone)
B(2,6,3,minecraft:stone)
B(2,6,4,minecraft:stone)
B(2,6,5,minecraft:stone)
B(2,6,6,minecraft:stone)
B(2,6,7,minecraft:stone)
B(2,6,8,minecraft:stone)
B(2,7,-10,minecraft:stone)
B(2,7,-9,minecraft:stone)
B(2,7,-8,minecraft:stone)
B(2,7,-7,minecraft:stone)
B(2,7,-6,minecraft:stone)
B(2,7,-5,minecraft:stone)
B(2,7,-4,minecraft:stone)
B(2,7,-3,minecraft:stone)
B(2,7,-2,minecraft:stone)
B(2,7,-1,minecraft:stone)
B(2,7,0,minecraft:stone)
B(2,7,1,minecraft:stone)
B(2,7,2,minecraft:stone)
B(2,7,3,minecraft:stone)
B(2,7,4,minecraft:stone)
B(2,7,5,minecraft:stone)
B(2,7,6,minecraft:stone)
B(2,7,7,minecraft:stone)
B(2,7,8,minecraft:stone)
B(2,8,-11,minecraft:stone)
B(2,8,-10,minecraft:stone)
B(2,8,-9,minecraft:stone)
B(2,8,-8,minecraft:stone)
B(2,8,-7,minecraft:stone)
B(2,8,-6,minecraft:stone)
B(2,8,-5,minecraft:stone)
B(2,8,-4,minecraft:stone)
B(2,8,-3,minecraft:stone)
B(2,8,-2,minecraft:stone)
B(2,8,-1,minecraft:stone)
B(2,8,0,minecraft:stone)
B(2,8,1,minecraft:stone)
B(2,8,2,minecraft:stone)
B(2,8,3,minecraft:stone)
B(2,8,4,minecraft:stone)
B(2,8,5,minecraft:stone)
B(2,8,6,minecraft:stone)
B(2,8,7,minecraft:stone)
B(2,8,8,minecraft:stone)
B(2,8,9,minecraft:stone)
B(2,9,-11,minecraft:stone)
B(2,9,-10,minecraft:stone)
B(2,9,-9,minecraft:stone)
B(2,9,-8,minecraft:stone)
B(2,9,-7,minecraft:stone)
B(2,9,-6,minecraft:stone)
B(2,9,-5,minecraft:stone)
B(2,9,-4,minecraft:stone)
B(2,9,-3,minecraft:stone)
B(2,9,-2,minecraft:stone)
B(2,9,-1,minecraft:stone)
B(2,9,0,minecraft:stone)
B(2,9,1,minecraft:stone)
B(2,9,2,minecraft:stone)
B(2,9,3,minecraft:stone)
B(2,9,4,minecraft:stone)
B(2,9,5,minecraft:stone)
B(2,9,6,minecraft:stone)
B(2,9,7,minecraft:stone)
B(2,9,8,minecraft:stone)
B(2,9,9,minecraft:stone)
B(2,9,10,minecraft:stone)
B(2,10,-12,minecraft:stone)
B(2,10,-11,minecraft:stone)
B(2,10,-10,minecraft:stone)
B(2,10,-9,minecraft:stone)
B(2,10,-8,minecraft:stone)
B(2,10,-7,minecraft:stone)
B(2,10,-6,minecraft:stone)
B(2,10,-5,minecraft:stone)
B(2,10,-4,minecraft:stone)
B(2,10,-3,minecraft:stone)
B(2,10,-2,minecraft:stone)
B(2,10,-1,minecraft:stone)
B(2,10,0,minecraft:stone)
B(2,10,1,minecraft:stone)
B(2,10,2,minecraft:stone)
B(2,10,3,minecraft:stone)
B(2,10,4,minecraft:stone)
B(2,10,5,minecraft:stone)
B(2,10,6,minecraft:stone)
B(2,10,7,minecraft:stone)
B(2,10,8,minecraft:stone)
B(2,10,9,minecraft:stone)
B(2,10,10,minecraft:stone)
B(2,10,11,minecraft:stone)
B(2,11,-13,minecraft:stone)
B(2,11,-12,minecraft:stone)
B(2,11,-11,minecraft:stone)
B(2,11,-10,minecraft:stone)
B(2,11,-9,minecraft:stone)
B(2,11,-8,minecraft:stone)
B(2,11,-7,minecraft:stone)
B(2,11,-6,minecraft:stone)
B(2,11,-5,minecraft:stone)
B(2,11,-4,minecraft:stone)
B(2,11,-3,minecraft:stone)
B(2,11,-2,minecraft:stone)
B(2,11,-1,minecraft:stone)
B(2,11,0,minecraft:stone)
B(2,11,1,minecraft:stone)
B(2,11,2,minecraft:stone)
B(2,11,3,minecraft:stone)
B(2,11,4,minecraft:stone)
B(2,11,5,minecraft:stone)
B(2,11,6,minecraft:stone)
B(2,11,7,minecraft:stone)
B(2,11,8,minecraft:stone)
B(2,11,9,minecraft:stone)
B(2,11,10,minecraft:stone)
B(2,11,11,minecraft:stone)
B(2,12,-13,minecraft:dirt)
B(2,12,-12,minecraft:dirt)
B(2,12,-11,minecraft:dirt)
B(2,12,-10,minecraft:dirt)
B(2,12,-9,minecraft:stone)
B(2,12,-8,minecraft:stone)
B(2,12,-7,minecraft:stone)
B(2,12,-6,minecraft:stone)
B(2,12,-5,minecraft:stone)
B(2,12,-4,minecraft:stone)
B(2,12,-3,minecraft:stone)
B(2,12,-2,minecraft:stone)
B(2,12,-1,minecraft:stone)
B(2,12,0,minecraft:stone)
B(2,12,1,minecraft:stone)
B(2,12,2,minecraft:stone)
B(2,12,3,minecraft:stone)
B(2,12,4,minecraft:stone)
B(2,12,5,minecraft:stone)
B(2,12,6,minecraft:stone)
B(2,12,7,minecraft:stone)
B(2,12,8,minecraft:stone)
B(2,12,9,minecraft:stone)
B(2,12,10,minecraft:dirt)
B(2,12,11,minecraft:dirt)
B(2,12,12,minecraft:dirt)
B(2,13,-13,minecraft:dirt)
B(2,13,-12,minecraft:dirt)
B(2,13,-11,minecraft:dirt)
B(2,13,-10,minecraft:dirt)
B(2,13,-9,minecraft:dirt)
B(2,13,-8,minecraft:dirt)
B(2,13,-7,minecraft:stone)
B(2,13,-6,minecraft:stone)
B(2,13,-5,minecraft:stone)
B(2,13,-4,minecraft:stone)
B(2,13,-3,minecraft:stone)
B(2,13,-2,minecraft:stone)
B(2,13,-1,minecraft:stone)
B(2,13,0,minecraft:stone)
B(2,13,1,minecraft:stone)
B(2,13,2,minecraft:stone)
B(2,13,3,minecraft:stone)
B(2,13,4,minecraft:stone)
B(2,13,5,minecraft:stone)
B(2,13,6,minecraft:stone)
B(2,13,7,minecraft:stone)
B(2,13,8,minecraft:dirt)
B(2,13,9,minecraft:dirt)
B(2,13,10,minecraft:dirt)
B(2,13,11,minecraft:dirt)
B(2,13,12,minecraft:dirt)
B(2,13,13,minecraft:dirt)
B(2,14,-14,minecraft:dirt)
B(2,14,-13,minecraft:dirt)
B(2,14,-12,minecraft:dirt)
B(2,14,-11,minecraft:dirt)
B(2,14,-10,minecraft:dirt)
B(2,14,-9,minecraft:dirt)
B(2,14,-8,minecraft:dirt)
B(2,14,-7,minecraft:dirt)
B(2,14,-6,minecraft:dirt)
B(2,14,-5,minecraft:dirt)
B(2,14,-4,minecraft:dirt)
B(2,14,-3,minecraft:dirt)
B(2,14,-2,minecraft:stone)
B(2,14,-1,minecraft:stone)
B(2,14,0,minecraft:stone)
B(2,14,1,minecraft:dirt)
B(2,14,2,minecraft:dirt)
B(2,14,3,minecraft:stone)
B(2,14,4,minecraft:stone)
B(2,14,5,minecraft:dirt)
B(2,14,6,minecraft:dirt)
B(2,14,7,minecraft:dirt)
B(2,14,8,minecraft:dirt)
B(2,14,9,minecraft:dirt)
B(2,14,10,minecraft:dirt)
B(2,14,11,minecraft:dirt)
B(2,14,12,minecraft:dirt)
B(2,14,13,minecraft:dirt)
B(2,14,14,minecraft:dirt)
B(2,15,-14,minecraft:grass_block)
B(2,15,-13,minecraft:grass_block)
B(2,15,-12,minecraft:grass_block)
B(2,15,-11,minecraft:grass_block)
B(2,15,-10,minecraft:grass_block)
B(2,15,-9,minecraft:dirt)
B(2,15,-8,minecraft:dirt)
B(2,15,-7,minecraft:dirt)
B(2,15,-6,minecraft:dirt)
B(2,15,-5,minecraft:dirt)
B(2,15,-4,minecraft:dirt)
B(2,15,-3,minecraft:dirt)
B(2,15,-2,minecraft:dirt)
B(2,15,-1,minecraft:dirt)
B(2,15,0,minecraft:dirt)
B(2,15,1,minecraft:dirt)
B(2,15,2,minecraft:dirt)
B(2,15,3,minecraft:dirt)
B(2,15,4,minecraft:dirt)
B(2,15,5,minecraft:dirt)
B(2,15,6,minecraft:dirt)
B(2,15,7,minecraft:dirt)
B(2,15,8,minecraft:dirt)
B(2,15,9,minecraft:dirt)
B(2,15,10,minecraft:grass_block)
B(2,15,11,minecraft:grass_block)
B(2,15,12,minecraft:grass_block)
B(2,15,13,minecraft:grass_block)
B(2,15,14,minecraft:grass_block)
B(2,16,-9,minecraft:grass_block)
B(2,16,-8,minecraft:grass_block)
B(2,16,-7,minecraft:dirt)
B(2,16,-6,minecraft:dirt)
B(2,16,-5,minecraft:dirt)
B(2,16,-4,minecraft:dirt)
B(2,16,-3,minecraft:dirt)
B(2,16,-2,minecraft:dirt)
B(2,16,-1,minecraft:dirt)
B(2,16,0,minecraft:dirt)
B(2,16,1,minecraft:dirt)
B(2,16,2,minecraft:dirt)
B(2,16,3,minecraft:dirt)
B(2,16,4,minecraft:dirt)
B(2,16,5,minecraft:dirt)
B(2,16,6,minecraft:dirt)
B(2,16,7,minecraft:dirt)
B(2,16,8,minecraft:grass_block)
B(2,16,9,minecraft:grass_block)
B(2,17,-7,minecraft:grass_block)
B(2,17,-6,minecraft:grass_block)
B(2,17,-5,minecraft:grass_block)
B(2,17,-4,minecraft:grass_block)
B(2,17,-3,minecraft:grass_block)
B(2,17,-2,minecraft:dirt)
B(2,17,-1,minecraft:dirt)
B(2,17,0,minecraft:dirt)
B(2,17,1,minecraft:grass_block)
B(2,17,2,minecraft:grass_block)
B(2,17,3,minecraft:dirt)
B(2,17,4,minecraft:dirt)
B(2,17,5,minecraft:grass_block)
B(2,17,6,minecraft:grass_block)
B(2,17,7,minecraft:grass_block)
B(2,18,-2,minecraft:grass_block)
B(2,18,-1,minecraft:grass_block)
B(2,18,0,minecraft:grass_block)
B(2,18,3,minecraft:grass_block)
B(2,18,4,minecraft:grass_block)
B(3,0,1,minecraft:stone)
B(3,1,-1,minecraft:stone)
B(3,1,0,minecraft:stone)
B(3,1,1,minecraft:stone)
B(3,1,2,minecraft:stone)
B(3,1,3,minecraft:stone)
B(3,1,4,minecraft:stone)
B(3,2,-1,minecraft:stone)
B(3,2,0,minecraft:stone)
B(3,2,1,minecraft:stone)
B(3,2,2,minecraft:stone)
B(3,2,3,minecraft:stone)
B(3,2,4,minecraft:stone)
B(3,2,5,minecraft:stone)
B(3,3,-3,minecraft:stone)
B(3,3,-2,minecraft:stone)
B(3,3,-1,minecraft:stone)
B(3,3,0,minecraft:stone)
B(3,3,1,minecraft:stone)
B(3,3,2,minecraft:stone)
B(3,3,3,minecraft:stone)
B(3,3,4,minecraft:stone)
B(3,3,5,minecraft:stone)
B(3,3,6,minecraft:stone)
B(3,4,-5,minecraft:stone)
B(3,4,-4,minecraft:stone)
B(3,4,-3,minecraft:stone)
B(3,4,-2,minecraft:stone)
B(3,4,-1,minecraft:stone)
B(3,4,0,minecraft:stone)
B(3,4,1,minecraft:stone)
B(3,4,2,minecraft:stone)
B(3,4,3,minecraft:stone)
B(3,4,4,minecraft:stone)
B(3,4,5,minecraft:stone)
B(3,4,6,minecraft:stone)
B(3,4,7,minecraft:stone)
B(3,5,-6,minecraft:stone)
B(3,5,-5,minecraft:stone)
B(3,5,-4,minecraft:stone)
B(3,5,-3,minecraft:stone)
B(3,5,-2,minecraft:stone)
B(3,5,-1,minecraft:stone)
B(3,5,0,minecraft:stone)
B(3,5,1,minecraft:stone)
B(3,5,2,minecraft:stone)
B(3,5,3,minecraft:stone)
B(3,5,4,minecraft:stone)
B(3,5,5,minecraft:stone)
B(3,5,6,minecraft:stone)
B(3,5,7,minecraft:stone)
B(3,6,-7,minecraft:stone)
B(3,6,-6,minecraft:stone)
B(3,6,-5,minecraft:stone)
B(3,6,-4,minecraft:stone)
B(3,6,-3,minecraft:stone)
B(3,6,-2,minecraft:stone)
B(3,6,-1,minecraft:stone)
B(3,6,0,minecraft:stone)
B(3,6,1,minecraft:stone)
B(3,6,2,minecraft:stone)
B(3,6,3,minecraft:stone)
B(3,6,4,minecraft:stone)
B(3,6,5,minecraft:stone)
B(3,6,6,minecraft:stone)
B(3,6,7,minecraft:stone)
B(3,6,8,minecraft:stone)
B(3,7,-9,minecraft:stone)
B(3,7,-8,minecraft:stone)
B(3,7,-7,minecraft:stone)
B(3,7,-6,minecraft:stone)
B(3,7,-5,minecraft:stone)
B(3,7,-4,minecraft:stone)
B(3,7,-3,minecraft:stone)
B(3,7,-2,minecraft:stone)
B(3,7,-1,minecraft:stone)
B(3,7,0,minecraft:stone)
B(3,7,1,minecraft:stone)
B(3,7,2,minecraft:stone)
B(3,7,3,minecraft:stone)
B(3,7,4,minecraft:stone)
B(3,7,5,minecraft:stone)
B(3,7,6,minecraft:stone)
B(3,7,7,minecraft:stone)
B(3,7,8,minecraft:stone)
B(3,8,-10,minecraft:stone)
B(3,8,-9,minecraft:stone)
B(3,8,-8,minecraft:stone)
B(3,8,-7,minecraft:stone)
B(3,8,-6,minecraft:stone)
B(3,8,-5,minecraft:stone)
B(3,8,-4,minecraft:stone)
B(3,8,-3,minecraft:stone)
B(3,8,-2,minecraft:stone)
B(3,8,-1,minecraft:stone)
B(3,8,0,minecraft:stone)
B(3,8,1,minecraft:stone)
B(3,8,2,minecraft:stone)
B(3,8,3,minecraft:stone)
B(3,8,4,minecraft:stone)
B(3,8,5,minecraft:stone)
B(3,8,6,minecraft:stone)
B(3,8,7,minecraft:stone)
B(3,8,8,minecraft:stone)
B(3,9,-11,minecraft:stone)
B(3,9,-10,minecraft:stone)
B(3,9,-9,minecraft:stone)
