
#######################################################################
# +-----------------------------------------------------------------+ #
# |                            BO4 object                           | #
# +-----------------------------------------------------------------+ #
#######################################################################

# This is the config file of a custom object.
# If you add this object correctly to your BiomeConfigs, it will spawn in the world.

# This is the creator of this BO4 object
Author: Unknown

# A short description of this BO4 object
Description: No description

# Legacy setting, always true for BO4's. Only used if the file has a .BO3 extension.
# Rename your file to .BO4 and remove this setting.
IsOTGPlus: true

# The settings mode, WriteAll, WriteWithoutComments or WriteDisable. See WorldConfig.
SettingsMode: WriteAll


#######################################################################
# +-----------------------------------------------------------------+ #
# |                          Main settings                          | #
# +-----------------------------------------------------------------+ #
#######################################################################

# If this BO4 should spawn with a fixed rotation, set it here.
# For example: NORTH, EAST, SOUTH or WEST. Empty by default
FixedRotation: 

# This BO4 can only spawn at least Frequency chunks distance away from any other BO4 with the exact same name.
# You can use this to make this BO4 spawn in groups or make sure that this BO4 only spawns once every X chunks.
Frequency: 0

# The spawn height of the BO4: randomY, highestBlock or highestSolidBlock.
SpawnHeight: highestBlock

# When set to true, uses the center of the structure (determined by minimum structure size) when checking the highestBlock to spawn at.
UseCenterForHighestBlock: true

##############################
# Height Limits for the BO4. #
##############################

# When in randomY mode used as the minimum Y or in atMinY mode as the actual Y to spawn this BO4 at.
MinHeight: 0

# When in randomY mode used as the maximum Y to spawn this BO4 at.
MaxHeight: 255

# Copies the blocks and branches of an existing BO4 into this BO4. You can still add blocks and branches in this BO4, they will be added on top of the inherited blocks and branches.
InheritBO3: 

# Rotates the inheritedBO3's resources (blocks, spawners, checks etc) and branches, defaults to NORTH (no rotation).
InheritBO3Rotation: NORTH

# Defaults to true, if true and this is the starting BO4 for this branching structure then this BO4's smoothing and height settings are used for all children (branches).
OverrideChildSettings: true

# Defaults to false, if true then this branch uses it's own height settings (SpawnHeight, minHeight, maxHeight, spawnAtWaterLevel) instead of those defined in the starting BO4 for this branching structure.
OverrideParentHeight: false

# If this is set to true then this BO4 can spawn on top of or inside an existing BO4. If this is set to false then this BO4 will use a bounding box to detect collisions with other BO4's, if a collision is detected then this BO4 won't spawn and the current branch is rolled back.
CanOverride: true

# This branch can only spawn at least branchFrequency chunks (x,z) distance away from any other branch with the exact same name.
BranchFrequency: 0

# Define groups that this branch belongs to along with a minimum (x,z) range in chunks that this branch must have between it and any other members of this group if it is to be allowed to spawn. Syntax is "GroupName:Frequency, GoupName2:Frequency2" etc so for example a branch that belongs to 3 groups: "BranchFrequencyGroup: Ships:10, Vehicles:5, FloatingThings:3".
BranchFrequencyGroup: 

# If this is set to true then this BO4 can only spawn underneath an existing BO4. Used to make sure that dungeons only appear underneath buildings.
MustBeBelowOther: false

# Used with CanOverride: true. A comma-seperated list of BO4s, this BO4's bounding box must collide with one of the BO4's in the list or this BO4 fails to spawn and the current branch is rolled back. AND/OR is supported, comma is OR, space is AND, f.e: branch1, branch2 branch3, branch 4.
MustBeInside: 

# Used with CanOverride: true. A comma-seperated list of BO4s, this BO4's bounding box cannot collide with any of the BO4's in the list or this BO4 fails to spawn and the current branch is rolled back.
CannotBeInside: 

# Used with CanOverride: true. A comma-seperated list of BO4s, if this BO4's bounding box collides with any of the BO4's in the list then those BO4's won't spawn any blocks. This does not remove or roll back any BO4's.
ReplacesBO3: 

# If this is set to true then this BO4 can only spawn inside world borders. Used to make sure that dungeons only appear inside the world borders.
MustBeInsideWorldBorders: false

# Defaults to true. Set to false if the BO4 is not allowed to spawn on a water block
CanSpawnOnWater: true

# Defaults to false. Set to true if the BO4 is allowed to spawn only on a water block
SpawnOnWaterOnly: false

# Defaults to false. Set to true if the BO4 and its smoothing area should ignore water when looking for the highest block to spawn on. Defaults to false (things spawn on top of water)
SpawnUnderWater: false

# Defaults to false. Set to true if the BO4 should spawn at water level
SpawnAtWaterLevel: false

# Spawns the BO4 at a Y offset of this value. Handy when using highestBlock for lowering BO4s into the surrounding terrain when there are layers of ground included in the BO4, also handy when using SpawnAtWaterLevel to lower objects like ships into the water.
HeightOffset: 0

# If set to true removes all AIR blocks from the BO4 so that it can be flooded or buried.
RemoveAir: true

# Replaces all the non-air blocks that are above this BO4 or its smoothing area with the given block material (should be WATER or AIR or NONE), also applies to smoothing areas although OTG intentionally leaves some of the terrain above them intact. WATER can be used in combination with SpawnUnderWater to fill any air blocks underneath waterlevel with water (and any above waterlevel with air).
ReplaceAbove: 

# Replaces all air blocks underneath the BO4 (but not its smoothing area) with the specified material until a solid block is found.
ReplaceBelow: 

# Defaults to true. If set to true then every block in the BO4 of the materials defined in ReplaceWithGroundBlock or ReplaceWithSurfaceBlock will be replaced by the GroundBlock or SurfaceBlock materials configured for the biome the block is spawned in.
ReplaceWithBiomeBlocks: true

# Defaults to GRASS, Replaces all the blocks of the given material in the BO4 with the SurfaceBlock configured for the biome it spawns in.
ReplaceWithSurfaceBlock: GRASS

# Defaults to DIRT, Replaces all the blocks of the given material in the BO4 with the GroundBlock configured for the biome it spawns in.
ReplaceWithGroundBlock: DIRT

# Defaults to STONE, Replaces all the blocks of the given material in the BO4 with the StoneBlock configured for the biome it spawns in.
ReplaceWithStoneBlock: STONE

# Makes the terrain around the BO4 slope evenly towards the edges of the BO4. The given value is the distance in blocks around the BO4 from where the slope should start and can be any positive number.
SmoothRadius: 0

# Moves the smoothing area up or down relative to the BO4 (at the points where the smoothing area is connected to the BO4). Handy when using SmoothStartTop: false and the BO4 has some layers of ground included, in that case we can set the HeightOffset to a negative value to lower the BO4 into the ground and we can set the SmoothHeightOffset to a positive value to move the smoothing area starting height up.
SmoothHeightOffset: 0

# Should the smoothing area be attached at the bottom or the top of the edges of the BO4? Defaults to false (bottom). Using this setting can make things slower so try to avoid using it and use SmoothHeightOffset instead if for instance you have a BO4 with some ground layers included. The only reason you should need to use this setting is if you have a BO4 with edges that have an irregular height (like some hills).
SmoothStartTop: false

# Should the smoothing area attach itself to "log" block or ignore them? Defaults to false (ignore logs).
SmoothStartWood: false

# The block used for smoothing area surface blocks, defaults to biome SurfaceBlock.
SmoothingSurfaceBlock: 

# The block used for smoothing area ground blocks, defaults to biome GroundBlock.
SmoothingGroundBlock: 

# Define groups that this BO4 belongs to along with a minimum range in chunks that this BO4 must have between it and any other members of this group if it is to be allowed to spawn. Syntax is "GroupName:Frequency, GoupName2:Frequency2" etc so for example a BO4 that belongs to 3 groups: "BO4Group: Ships:10, Vehicles:5, FloatingThings:3".
BO3Group: 

# Defaults to false. Set to true if this BO4 should spawn at the player spawn point. When the server starts the spawn point is determined and the BO4's for the biome it is in are loaded, one of these BO4s that has IsSpawnPoint set to true (if any) is selected randomly and is spawned at the spawn point regardless of its rarity (so even Rarity:0, IsSpawnPoint: true BO4's can get spawned as the spawn point!).
IsSpawnPoint: false

# Defaults to true. Set to false to make the BO4 ignore any ReplacedBlocks settings in Biome Configs.
DoReplaceBlocks: true


#######################################################################
# +-----------------------------------------------------------------+ #
# |                              Blocks                             | #
# +-----------------------------------------------------------------+ #
#######################################################################

# All the blocks used in the BO4 are listed here. Possible blocks:
# Block(x,y,z,id[.data][,nbtfile.nbt)
# RandomBlock(x,y,z,id[:data][,nbtfile.nbt],chance[,id[:data][,nbtfile.nbt],chance[,...]])
#  So RandomBlock(0,0,0,CHEST,chest.nbt,50,CHEST,anotherchest.nbt,100) will spawn a chest at
#  the BO4 origin, and give it a 50% chance to have the contents of chest.nbt, or, if that
#  fails, a 100% percent chance to have the contents of anotherchest.nbt.
# MinecraftObject(x,y,z,name) (TODO: This may not work anymore and needs to be tested.
#  Spawns an object in the Mojang NBT structure format. For example, 
#  MinecraftObject(0,0,0,minecraft:igloo/igloo_bottom)
#  spawns the bottom part of an igloo.
B(-8,0,-7,minecraft:stone)
B(-8,0,-6,minecraft:stone)
B(-8,0,-5,minecraft:stone)
B(-8,0,-4,minecraft:stone)
B(-8,0,-3,minecraft:stone)
B(-8,0,-2,minecraft:stone)
B(-8,0,-1,minecraft:polished_andesite)
B(-8,0,0,minecraft:spruce_planks)
B(-8,0,1,minecraft:spruce_planks)
B(-8,0,2,minecraft:polished_andesite)
B(-8,0,3,minecraft:stone)
B(-8,0,4,minecraft:stone)
B(-8,0,5,minecraft:stone)
B(-8,0,6,minecraft:stone)
B(-8,0,7,minecraft:stone)
B(-8,0,8,minecraft:stone)
B(-8,1,-7,minecraft:stone)
B(-8,1,-6,minecraft:stone)
B(-8,1,-5,minecraft:stone)
B(-8,1,-4,minecraft:stone)
B(-8,1,-3,minecraft:stone)
B(-8,1,-2,minecraft:stone)
B(-8,1,-1,minecraft:polished_andesite)
B(-8,1,0,minecraft:glass)
B(-8,1,1,minecraft:glass)
B(-8,1,2,minecraft:polished_andesite)
B(-8,1,3,minecraft:stone)
B(-8,1,4,minecraft:stone)
B(-8,1,5,minecraft:stone)
B(-8,1,6,minecraft:stone)
B(-8,1,7,minecraft:stone)
B(-8,1,8,minecraft:stone)
B(-8,2,-7,minecraft:stone)
B(-8,2,-6,minecraft:stone)
B(-8,2,-5,minecraft:stone)
B(-8,2,-4,minecraft:stone)
B(-8,2,-3,minecraft:stone)
B(-8,2,-2,minecraft:stone)
B(-8,2,-1,minecraft:stone)
B(-8,2,0,minecraft:glass)
B(-8,2,1,minecraft:glass)
B(-8,2,2,minecraft:polished_andesite)
B(-8,2,3,minecraft:stone)
B(-8,2,4,minecraft:stone)
B(-8,2,5,minecraft:stone)
B(-8,2,6,minecraft:stone)
B(-8,2,7,minecraft:stone)
B(-8,2,8,minecraft:stone)
B(-8,3,-7,minecraft:stone)
B(-8,3,-6,minecraft:stone)
B(-8,3,-5,minecraft:stone)
B(-8,3,-4,minecraft:stone)
B(-8,3,-3,minecraft:stone)
B(-8,3,-2,minecraft:stone)
B(-8,3,-1,minecraft:stone)
B(-8,3,0,minecraft:glass)
B(-8,3,1,minecraft:glass)
B(-8,3,2,minecraft:cracked_stone_bricks)
B(-8,3,3,minecraft:stone)
B(-8,3,4,minecraft:stone)
B(-8,3,5,minecraft:stone)
B(-8,3,6,minecraft:stone)
B(-8,3,7,minecraft:stone)
B(-8,3,8,minecraft:stone)
B(-8,4,-7,minecraft:stone)
B(-8,4,-6,minecraft:stone)
B(-8,4,-5,minecraft:stone)
B(-8,4,-4,minecraft:stone)
B(-8,4,-3,minecraft:stone)
B(-8,4,-2,minecraft:stone)
B(-8,4,-1,minecraft:stone)
B(-8,4,0,minecraft:glass)
B(-8,4,1,minecraft:glass)
B(-8,4,2,minecraft:cracked_stone_bricks)
B(-8,4,3,minecraft:stone)
B(-8,4,4,minecraft:stone)
B(-8,4,5,minecraft:stone)
B(-8,4,6,minecraft:stone)
B(-8,4,7,minecraft:stone)
B(-8,4,8,minecraft:stone)
B(-8,5,-7,minecraft:stone)
B(-8,5,-6,minecraft:stone)
B(-8,5,-5,minecraft:stone)
B(-8,5,-4,minecraft:stone)
B(-8,5,-3,minecraft:stone)
B(-8,5,-2,minecraft:stone)
B(-8,5,-1,minecraft:polished_andesite)
B(-8,5,0,minecraft:glass)
B(-8,5,1,minecraft:glass)
B(-8,5,2,minecraft:stone)
B(-8,5,3,minecraft:stone)
B(-8,5,4,minecraft:stone)
B(-8,5,5,minecraft:stone)
B(-8,5,6,minecraft:stone)
B(-8,5,7,minecraft:stone)
B(-8,5,8,minecraft:stone)
B(-8,6,-7,minecraft:stone)
B(-8,6,-6,minecraft:stone)
B(-8,6,-5,minecraft:stone)
B(-8,6,-4,minecraft:stone)
B(-8,6,-3,minecraft:stone)
B(-8,6,-2,minecraft:stone)
B(-8,6,-1,minecraft:polished_andesite)
B(-8,6,0,minecraft:glass)
B(-8,6,1,minecraft:glass)
B(-8,6,2,minecraft:polished_andesite)
B(-8,6,3,minecraft:stone)
B(-8,6,4,minecraft:stone)
B(-8,6,5,minecraft:stone)
B(-8,6,6,minecraft:stone)
B(-8,6,7,minecraft:stone)
B(-8,6,8,minecraft:stone)
B(-8,7,-7,minecraft:stone)
B(-8,7,-6,minecraft:stone)
B(-8,7,-5,minecraft:stone)
B(-8,7,-4,minecraft:stone)
B(-8,7,-3,minecraft:stone)
B(-8,7,-2,minecraft:stone)
B(-8,7,-1,minecraft:polished_andesite)
B(-8,7,0,minecraft:polished_andesite)
B(-8,7,1,minecraft:polished_andesite)
B(-8,7,2,minecraft:polished_andesite)
B(-8,7,3,minecraft:stone)
B(-8,7,4,minecraft:stone)
B(-8,7,5,minecraft:stone)
B(-8,7,6,minecraft:stone)
B(-8,7,7,minecraft:stone)
B(-8,7,8,minecraft:stone)
B(-8,8,-7,minecraft:stone)
B(-8,8,-6,minecraft:stone)
B(-8,8,-5,minecraft:stone)
B(-8,8,-4,minecraft:stone)
B(-8,8,-3,minecraft:stone)
B(-8,8,-2,minecraft:stone)
B(-8,8,-1,minecraft:stone)
B(-8,8,0,minecraft:stone)
B(-8,8,1,minecraft:stone)
B(-8,8,2,minecraft:stone)
B(-8,8,3,minecraft:stone)
B(-8,8,4,minecraft:stone)
B(-8,8,5,minecraft:stone)
B(-8,8,6,minecraft:stone)
B(-8,8,7,minecraft:stone)
B(-8,8,8,minecraft:stone)
B(-7,0,-7,minecraft:stone)
B(-7,0,-6,minecraft:stone)
B(-7,0,-5,minecraft:stone)
B(-7,0,-4,minecraft:stone)
B(-7,0,-3,minecraft:stone)
B(-7,0,-2,minecraft:stone)
B(-7,0,-1,minecraft:spruce_planks)
B(-7,0,0,minecraft:spruce_planks)
B(-7,0,1,minecraft:spruce_planks)
B(-7,0,2,minecraft:spruce_planks)
B(-7,0,3,minecraft:spruce_planks)
B(-7,0,4,minecraft:stone)
B(-7,0,5,minecraft:stone)
B(-7,0,6,minecraft:stone)
B(-7,0,7,minecraft:stone)
B(-7,0,8,minecraft:stone)
B(-7,1,-7,minecraft:stone)
B(-7,1,-6,minecraft:stone)
B(-7,1,-5,minecraft:stone)
B(-7,1,-4,minecraft:stone)
B(-7,1,-3,minecraft:stone)
B(-7,1,-2,minecraft:polished_andesite)
B(-7,1,-1,minecraft:glass)
B(-7,1,0,minecraft:oak_button[face=floor,facing=east,powered=false])
B(-7,1,1,minecraft:glass)
B(-7,1,2,minecraft:glass)
B(-7,1,3,minecraft:polished_andesite)
B(-7,1,4,minecraft:stone)
B(-7,1,5,minecraft:stone)
B(-7,1,6,minecraft:stone)
B(-7,1,7,minecraft:stone)
B(-7,1,8,minecraft:stone)
B(-7,2,-7,minecraft:stone)
B(-7,2,-6,minecraft:stone)
B(-7,2,-5,minecraft:stone)
B(-7,2,-4,minecraft:stone)
B(-7,2,-3,minecraft:stone)
B(-7,2,-2,minecraft:stone_brick_stairs)
B(-7,2,-1,minecraft:glass)
B(-7,2,0,minecraft:glass)
B(-7,2,1,minecraft:glass)
B(-7,2,2,minecraft:glass)
B(-7,2,3,minecraft:stone_brick_stairs[facing=south,half=bottom,shape=straight,waterlogged=false])
B(-7,2,4,minecraft:stone)
B(-7,2,5,minecraft:stone)
B(-7,2,6,minecraft:stone)
B(-7,2,7,minecraft:stone)
B(-7,2,8,minecraft:stone)
B(-7,3,-7,minecraft:stone)
B(-7,3,-6,minecraft:stone)
B(-7,3,-5,minecraft:stone)
B(-7,3,-4,minecraft:stone)
B(-7,3,-3,minecraft:stone)
B(-7,3,-2,minecraft:stone_brick_stairs[facing=north,half=top,shape=straight,waterlogged=false])
B(-7,3,-1,minecraft:glass)
B(-7,3,0,minecraft:glass)
B(-7,3,1,minecraft:glass)
B(-7,3,2,minecraft:glass)
B(-7,3,3,minecraft:stone_brick_stairs[facing=south,half=top,shape=straight,waterlogged=false])
B(-7,3,4,minecraft:stone)
B(-7,3,5,minecraft:stone)
B(-7,3,6,minecraft:stone)
B(-7,3,7,minecraft:stone)
B(-7,3,8,minecraft:stone)
B(-7,4,-7,minecraft:stone)
B(-7,4,-6,minecraft:stone)
B(-7,4,-5,minecraft:stone)
B(-7,4,-4,minecraft:stone)
B(-7,4,-3,minecraft:stone)
B(-7,4,-2,minecraft:cracked_stone_bricks)
B(-7,4,-1,minecraft:glass)
B(-7,4,0,minecraft:glass)
B(-7,4,1,minecraft:glass)
B(-7,4,2,minecraft:glass)
B(-7,4,3,minecraft:cracked_stone_bricks)
B(-7,4,4,minecraft:stone)
B(-7,4,5,minecraft:stone)
B(-7,4,6,minecraft:stone)
B(-7,4,7,minecraft:stone)
B(-7,4,8,minecraft:stone)
B(-7,5,-7,minecraft:stone)
B(-7,5,-6,minecraft:stone)
B(-7,5,-5,minecraft:stone)
B(-7,5,-4,minecraft:stone)
B(-7,5,-3,minecraft:stone)
B(-7,5,-2,minecraft:cracked_stone_bricks)
B(-7,5,-1,minecraft:glass)
B(-7,5,0,minecraft:glass)
B(-7,5,1,minecraft:glass)
B(-7,5,2,minecraft:glass)
B(-7,5,3,minecraft:polished_andesite)
B(-7,5,4,minecraft:stone)
B(-7,5,5,minecraft:stone)
B(-7,5,6,minecraft:stone)
B(-7,5,7,minecraft:stone)
B(-7,5,8,minecraft:stone)
B(-7,6,-7,minecraft:stone)
B(-7,6,-6,minecraft:stone)
B(-7,6,-5,minecraft:stone)
B(-7,6,-4,minecraft:stone)
B(-7,6,-3,minecraft:stone)
B(-7,6,-2,minecraft:polished_andesite)
B(-7,6,-1,minecraft:glass)
B(-7,6,0,minecraft:glass)
B(-7,6,1,minecraft:glass)
B(-7,6,2,minecraft:spruce_log[axis=x])
B(-7,6,3,minecraft:cracked_stone_bricks)
B(-7,6,4,minecraft:stone)
B(-7,6,5,minecraft:stone)
B(-7,6,6,minecraft:stone)
B(-7,6,7,minecraft:stone)
B(-7,6,8,minecraft:stone)
B(-7,7,-7,minecraft:stone)
B(-7,7,-6,minecraft:stone)
B(-7,7,-5,minecraft:stone)
B(-7,7,-4,minecraft:stone)
B(-7,7,-3,minecraft:stone)
B(-7,7,-2,minecraft:spruce_log[axis=z])
B(-7,7,-1,minecraft:spruce_log[axis=z])
B(-7,7,0,minecraft:spruce_log[axis=z])
B(-7,7,1,minecraft:spruce_log[axis=z])
B(-7,7,2,minecraft:spruce_log[axis=z])
B(-7,7,3,minecraft:spruce_log[axis=z])
B(-7,7,4,minecraft:stone)
B(-7,7,5,minecraft:stone)
B(-7,7,6,minecraft:stone)
B(-7,7,7,minecraft:stone)
B(-7,7,8,minecraft:stone)
B(-7,8,-7,minecraft:stone)
B(-7,8,-6,minecraft:stone)
B(-7,8,-5,minecraft:stone)
B(-7,8,-4,minecraft:stone)
B(-7,8,-3,minecraft:stone)
B(-7,8,-2,minecraft:stone)
B(-7,8,-1,minecraft:stone)
B(-7,8,0,minecraft:stone)
B(-7,8,1,minecraft:stone)
B(-7,8,2,minecraft:stone)
B(-7,8,3,minecraft:stone)
B(-7,8,4,minecraft:stone)
B(-7,8,5,minecraft:stone)
B(-7,8,6,minecraft:stone)
B(-7,8,7,minecraft:stone)
B(-7,8,8,minecraft:stone)
B(-6,0,-7,minecraft:stone)
B(-6,0,-6,minecraft:stone)
B(-6,0,-5,minecraft:stone)
B(-6,0,-4,minecraft:stone)
B(-6,0,-3,minecraft:stone)
B(-6,0,-2,minecraft:spruce_planks)
B(-6,0,-1,minecraft:spruce_stairs[facing=east,half=bottom,shape=straight,waterlogged=false])
B(-6,0,0,minecraft:spruce_planks)
B(-6,0,1,minecraft:spruce_slab)
B(-6,0,2,minecraft:spruce_planks)
B(-6,0,3,minecraft:spruce_planks)
B(-6,0,4,minecraft:stone)
B(-6,0,5,minecraft:stone)
B(-6,0,6,minecraft:stone)
B(-6,0,7,minecraft:stone)
B(-6,0,8,minecraft:stone)
B(-6,1,-7,minecraft:stone)
B(-6,1,-6,minecraft:stone)
B(-6,1,-5,minecraft:stone)
B(-6,1,-4,minecraft:stone)
B(-6,1,-3,minecraft:light_gray_wool)
B(-6,1,-2,minecraft:dark_oak_stairs[facing=north,half=top,shape=straight,waterlogged=false])
B(-6,1,-1,minecraft:glass)
B(-6,1,0,minecraft:glass)
B(-6,1,1,minecraft:glass)
B(-6,1,2,minecraft:glass)
B(-6,1,3,minecraft:dark_oak_stairs[facing=south,half=top,shape=straight,waterlogged=false])
B(-6,1,4,minecraft:light_gray_wool)
B(-6,1,5,minecraft:stone)
B(-6,1,6,minecraft:stone)
B(-6,1,7,minecraft:stone)
B(-6,1,8,minecraft:stone)
B(-6,2,-7,minecraft:stone)
B(-6,2,-6,minecraft:stone)
B(-6,2,-5,minecraft:stone)
B(-6,2,-4,minecraft:stone)
B(-6,2,-3,minecraft:diorite)
B(-6,2,-2,minecraft:glass)
B(-6,2,-1,minecraft:glass)
B(-6,2,0,minecraft:glass)
B(-6,2,1,minecraft:glass)
B(-6,2,2,minecraft:glass)
B(-6,2,3,minecraft:glass)
B(-6,2,4,minecraft:diorite)
B(-6,2,5,minecraft:stone)
B(-6,2,6,minecraft:stone)
B(-6,2,7,minecraft:stone)
B(-6,2,8,minecraft:stone)
B(-6,3,-7,minecraft:stone)
B(-6,3,-6,minecraft:stone)
B(-6,3,-5,minecraft:stone)
B(-6,3,-4,minecraft:stone)
B(-6,3,-3,minecraft:diorite)
B(-6,3,-2,minecraft:glass)
B(-6,3,-1,minecraft:glass)
B(-6,3,0,minecraft:glass)
B(-6,3,1,minecraft:glass)
B(-6,3,2,minecraft:glass)
B(-6,3,3,minecraft:glass)
B(-6,3,4,minecraft:diorite)
B(-6,3,5,minecraft:stone)
B(-6,3,6,minecraft:stone)
B(-6,3,7,minecraft:stone)
B(-6,3,8,minecraft:stone)
B(-6,4,-7,minecraft:stone)
B(-6,4,-6,minecraft:stone)
B(-6,4,-5,minecraft:stone)
B(-6,4,-4,minecraft:stone)
B(-6,4,-3,minecraft:diorite)
B(-6,4,-2,minecraft:glass)
B(-6,4,-1,minecraft:glass)
B(-6,4,0,minecraft:glass)
B(-6,4,1,minecraft:glass)
B(-6,4,2,minecraft:glass)
B(-6,4,3,minecraft:glass)
B(-6,4,4,minecraft:diorite)
B(-6,4,5,minecraft:stone)
B(-6,4,6,minecraft:stone)
B(-6,4,7,minecraft:stone)
B(-6,4,8,minecraft:stone)
B(-6,5,-7,minecraft:stone)
B(-6,5,-6,minecraft:stone)
B(-6,5,-5,minecraft:stone)
B(-6,5,-4,minecraft:stone)
B(-6,5,-3,minecraft:light_gray_wool)
B(-6,5,-2,minecraft:glass)
B(-6,5,-1,minecraft:glass)
B(-6,5,0,minecraft:glass)
B(-6,5,1,minecraft:glass)
B(-6,5,2,minecraft:glass)
B(-6,5,3,minecraft:glass)
B(-6,5,4,minecraft:light_gray_wool)
B(-6,5,5,minecraft:stone)
B(-6,5,6,minecraft:stone)
B(-6,5,7,minecraft:stone)
B(-6,5,8,minecraft:stone)
B(-6,6,-7,minecraft:stone)
B(-6,6,-6,minecraft:stone)
B(-6,6,-5,minecraft:stone)
B(-6,6,-4,minecraft:stone)
B(-6,6,-3,minecraft:light_gray_wool)
B(-6,6,-2,minecraft:glass)
B(-6,6,-1,minecraft:glass)
B(-6,6,0,minecraft:glass)
B(-6,6,1,minecraft:glass)
B(-6,6,2,minecraft:spruce_log[axis=x])
B(-6,6,3,minecraft:glass)
B(-6,6,4,minecraft:light_gray_wool)
B(-6,6,5,minecraft:stone)
B(-6,6,6,minecraft:stone)
B(-6,6,7,minecraft:stone)
B(-6,6,8,minecraft:stone)
B(-6,7,-7,minecraft:stone)
B(-6,7,-6,minecraft:stone)
B(-6,7,-5,minecraft:stone)
B(-6,7,-4,minecraft:stone)
B(-6,7,-3,minecraft:light_gray_wool)
B(-6,7,-2,minecraft:dark_oak_slab[type=top,waterlogged=false])
B(-6,7,-1,minecraft:dark_oak_slab[type=top,waterlogged=false])
B(-6,7,0,minecraft:dark_oak_slab[type=top,waterlogged=false])
B(-6,7,1,minecraft:dark_oak_slab[type=top,waterlogged=false])
B(-6,7,2,minecraft:dark_oak_slab[type=top,waterlogged=false])
B(-6,7,3,minecraft:dark_oak_slab[type=top,waterlogged=false])
B(-6,7,4,minecraft:light_gray_wool)
B(-6,7,5,minecraft:stone)
B(-6,7,6,minecraft:stone)
B(-6,7,7,minecraft:stone)
B(-6,7,8,minecraft:stone)
B(-6,8,-7,minecraft:stone)
B(-6,8,-6,minecraft:stone)
B(-6,8,-5,minecraft:stone)
B(-6,8,-4,minecraft:stone)
B(-6,8,-3,minecraft:stone)
B(-6,8,-2,minecraft:stone)
B(-6,8,-1,minecraft:stone)
B(-6,8,0,minecraft:stone)
B(-6,8,1,minecraft:stone)
B(-6,8,2,minecraft:stone)
B(-6,8,3,minecraft:stone)
B(-6,8,4,minecraft:stone)
B(-6,8,5,minecraft:stone)
B(-6,8,6,minecraft:stone)
B(-6,8,7,minecraft:stone)
B(-6,8,8,minecraft:stone)
B(-5,0,-7,minecraft:stone)
B(-5,0,-6,minecraft:stone)
B(-5,0,-5,minecraft:stone)
B(-5,0,-4,minecraft:stone)
B(-5,0,-3,minecraft:stone)
B(-5,0,-2,minecraft:spruce_planks)
B(-5,0,-1,minecraft:spruce_planks)
B(-5,0,0,minecraft:spruce_planks)
B(-5,0,1,minecraft:spruce_slab)
B(-5,0,2,minecraft:spruce_planks)
B(-5,0,3,minecraft:spruce_planks)
B(-5,0,4,minecraft:stone)
B(-5,0,5,minecraft:stone)
B(-5,0,6,minecraft:stone)
B(-5,0,7,minecraft:stone)
B(-5,0,8,minecraft:stone)
B(-5,1,-7,minecraft:stone)
B(-5,1,-6,minecraft:stone)
B(-5,1,-5,minecraft:stone)
B(-5,1,-4,minecraft:stone)
B(-5,1,-3,minecraft:light_gray_wool)
B(-5,1,-2,minecraft:dark_oak_stairs[facing=north,half=top,shape=straight,waterlogged=false])
B(-5,1,-1,minecraft:glass)
B(-5,1,0,minecraft:glass)
B(-5,1,1,minecraft:glass)
B(-5,1,2,minecraft:glass)
B(-5,1,3,minecraft:dark_oak_stairs[facing=south,half=top,shape=straight,waterlogged=false])
B(-5,1,4,minecraft:light_gray_wool)
B(-5,1,5,minecraft:stone)
B(-5,1,6,minecraft:stone)
B(-5,1,7,minecraft:stone)
B(-5,1,8,minecraft:stone)
B(-5,2,-7,minecraft:stone)
B(-5,2,-6,minecraft:stone)
B(-5,2,-5,minecraft:stone)
B(-5,2,-4,minecraft:stone)
B(-5,2,-3,minecraft:polished_diorite)
B(-5,2,-2,minecraft:glass)
B(-5,2,-1,minecraft:glass)
B(-5,2,0,minecraft:glass)
B(-5,2,1,minecraft:glass)
B(-5,2,2,minecraft:glass)
B(-5,2,3,minecraft:glass)
B(-5,2,4,minecraft:diorite)
B(-5,2,5,minecraft:stone)
B(-5,2,6,minecraft:stone)
B(-5,2,7,minecraft:stone)
B(-5,2,8,minecraft:stone)
B(-5,3,-7,minecraft:stone)
B(-5,3,-6,minecraft:stone)
B(-5,3,-5,minecraft:stone)
B(-5,3,-4,minecraft:stone)
B(-5,3,-3,minecraft:diorite)
B(-5,3,-2,minecraft:glass)
B(-5,3,-1,minecraft:glass)
B(-5,3,0,minecraft:glass)
B(-5,3,1,minecraft:glass)
B(-5,3,2,minecraft:glass)
B(-5,3,3,minecraft:glass)
B(-5,3,4,minecraft:polished_diorite)
B(-5,3,5,minecraft:stone)
B(-5,3,6,minecraft:stone)
B(-5,3,7,minecraft:stone)
B(-5,3,8,minecraft:stone)
B(-5,4,-7,minecraft:stone)
B(-5,4,-6,minecraft:stone)
B(-5,4,-5,minecraft:stone)
B(-5,4,-4,minecraft:stone)
B(-5,4,-3,minecraft:diorite)
B(-5,4,-2,minecraft:glass)
B(-5,4,-1,minecraft:glass)
B(-5,4,0,minecraft:glass)
B(-5,4,1,minecraft:glass)
B(-5,4,2,minecraft:glass)
B(-5,4,3,minecraft:glass)
B(-5,4,4,minecraft:diorite)
B(-5,4,5,minecraft:stone)
B(-5,4,6,minecraft:stone)
B(-5,4,7,minecraft:stone)
B(-5,4,8,minecraft:stone)
B(-5,5,-7,minecraft:stone)
B(-5,5,-6,minecraft:stone)
B(-5,5,-5,minecraft:stone)
B(-5,5,-4,minecraft:stone)
B(-5,5,-3,minecraft:light_gray_wool)
B(-5,5,-2,minecraft:glass)
B(-5,5,-1,minecraft:glass)
B(-5,5,0,minecraft:glass)
B(-5,5,1,minecraft:glass)
B(-5,5,2,minecraft:glass)
B(-5,5,3,minecraft:glass)
B(-5,5,4,minecraft:light_gray_wool)
B(-5,5,5,minecraft:stone)
B(-5,5,6,minecraft:stone)
B(-5,5,7,minecraft:stone)
B(-5,5,8,minecraft:stone)
B(-5,6,-7,minecraft:stone)
B(-5,6,-6,minecraft:stone)
B(-5,6,-5,minecraft:stone)
B(-5,6,-4,minecraft:stone)
B(-5,6,-3,minecraft:light_gray_wool)
B(-5,6,-2,minecraft:glass)
B(-5,6,-1,minecraft:glass)
B(-5,6,0,minecraft:glass)
B(-5,6,1,minecraft:glass)
B(-5,6,2,minecraft:spruce_log[axis=x])
B(-5,6,3,minecraft:glass)
B(-5,6,4,minecraft:light_gray_wool)
B(-5,6,5,minecraft:stone)
B(-5,6,6,minecraft:stone)
B(-5,6,7,minecraft:stone)
B(-5,6,8,minecraft:stone)
B(-5,7,-7,minecraft:stone)
B(-5,7,-6,minecraft:stone)
B(-5,7,-5,minecraft:stone)
B(-5,7,-4,minecraft:stone)
B(-5,7,-3,minecraft:light_gray_wool)
B(-5,7,-2,minecraft:spruce_log[axis=z])
B(-5,7,-1,minecraft:spruce_log[axis=z])
B(-5,7,0,minecraft:spruce_log[axis=z])
B(-5,7,1,minecraft:spruce_log[axis=z])
B(-5,7,2,minecraft:spruce_log[axis=z])
B(-5,7,3,minecraft:spruce_log[axis=z])
B(-5,7,4,minecraft:spruce_log)
B(-5,7,5,minecraft:stone)
B(-5,7,6,minecraft:stone)
B(-5,7,7,minecraft:stone)
B(-5,7,8,minecraft:stone)
B(-5,8,-7,minecraft:stone)
B(-5,8,-6,minecraft:stone)
B(-5,8,-5,minecraft:stone)
B(-5,8,-4,minecraft:stone)
B(-5,8,-3,minecraft:stone)
B(-5,8,-2,minecraft:stone)
B(-5,8,-1,minecraft:stone)
B(-5,8,0,minecraft:stone)
B(-5,8,1,minecraft:stone)
B(-5,8,2,minecraft:stone)
B(-5,8,3,minecraft:stone)
B(-5,8,4,minecraft:stone)
B(-5,8,5,minecraft:stone)
B(-5,8,6,minecraft:stone)
B(-5,8,7,minecraft:stone)
B(-5,8,8,minecraft:stone)
B(-4,0,-7,minecraft:stone)
B(-4,0,-6,minecraft:stone)
B(-4,0,-5,minecraft:stone)
B(-4,0,-4,minecraft:stone)
B(-4,0,-3,minecraft:stone)
B(-4,0,-2,minecraft:spruce_planks)
B(-4,0,-1,minecraft:spruce_planks)
B(-4,0,0,minecraft:spruce_planks)
B(-4,0,1,minecraft:spruce_planks)
B(-4,0,2,minecraft:spruce_slab)
B(-4,0,3,minecraft:spruce_planks)
B(-4,0,4,minecraft:spruce_planks)
B(-4,0,5,minecraft:spruce_planks)
B(-4,0,6,minecraft:spruce_planks)
B(-4,0,7,minecraft:stone)
B(-4,0,8,minecraft:stone)
B(-4,1,-7,minecraft:stone)
B(-4,1,-6,minecraft:stone)
B(-4,1,-5,minecraft:stone)
B(-4,1,-4,minecraft:stone)
B(-4,1,-3,minecraft:light_gray_wool)
B(-4,1,-2,minecraft:dark_oak_stairs[facing=north,half=top,shape=straight,waterlogged=false])
B(-4,1,-1,minecraft:glass)
B(-4,1,0,minecraft:glass)
B(-4,1,1,minecraft:glass)
B(-4,1,2,minecraft:glass)
B(-4,1,3,minecraft:dark_oak_stairs[facing=south,half=top,shape=straight,waterlogged=false])
B(-4,1,4,minecraft:light_gray_wool)
B(-4,1,5,minecraft:light_gray_wool)
B(-4,1,6,minecraft:light_gray_wool)
B(-4,1,7,minecraft:stone)
B(-4,1,8,minecraft:stone)
B(-4,2,-7,minecraft:stone)
B(-4,2,-6,minecraft:stone)
B(-4,2,-5,minecraft:stone)
B(-4,2,-4,minecraft:stone)
B(-4,2,-3,minecraft:polished_diorite)
B(-4,2,-2,minecraft:glass)
B(-4,2,-1,minecraft:glass)
B(-4,2,0,minecraft:glass)
B(-4,2,1,minecraft:glass)
B(-4,2,2,minecraft:glass)
B(-4,2,3,minecraft:glass)
B(-4,2,4,minecraft:diorite)
B(-4,2,5,minecraft:diorite)
B(-4,2,6,minecraft:diorite)
B(-4,2,7,minecraft:stone)
B(-4,2,8,minecraft:stone)
B(-4,3,-7,minecraft:stone)
B(-4,3,-6,minecraft:stone)
B(-4,3,-5,minecraft:stone)
B(-4,3,-4,minecraft:stone)
B(-4,3,-3,minecraft:diorite)
B(-4,3,-2,minecraft:glass)
B(-4,3,-1,minecraft:glass)
B(-4,3,0,minecraft:glass)
B(-4,3,1,minecraft:glass)
B(-4,3,2,minecraft:glass)
B(-4,3,3,minecraft:glass)
B(-4,3,4,minecraft:diorite)
B(-4,3,5,minecraft:diorite)
B(-4,3,6,minecraft:polished_diorite)
B(-4,3,7,minecraft:stone)
B(-4,3,8,minecraft:stone)
B(-4,4,-7,minecraft:stone)
B(-4,4,-6,minecraft:stone)
B(-4,4,-5,minecraft:stone)
B(-4,4,-4,minecraft:stone)
B(-4,4,-3,minecraft:diorite)
B(-4,4,-2,minecraft:glass)
B(-4,4,-1,minecraft:glass)
B(-4,4,0,minecraft:glass)
B(-4,4,1,minecraft:glass)
B(-4,4,2,minecraft:glass)
B(-4,4,3,minecraft:glass)
B(-4,4,4,minecraft:polished_diorite)
B(-4,4,5,minecraft:diorite)
B(-4,4,6,minecraft:polished_diorite)
B(-4,4,7,minecraft:stone)
B(-4,4,8,minecraft:stone)
B(-4,5,-7,minecraft:stone)
B(-4,5,-6,minecraft:stone)
B(-4,5,-5,minecraft:stone)
B(-4,5,-4,minecraft:stone)
B(-4,5,-3,minecraft:light_gray_wool)
B(-4,5,-2,minecraft:glass)
B(-4,5,-1,minecraft:glass)
B(-4,5,0,minecraft:glass)
B(-4,5,1,minecraft:glass)
B(-4,5,2,minecraft:glass)
B(-4,5,3,minecraft:glass)
B(-4,5,4,minecraft:light_gray_wool)
B(-4,5,5,minecraft:light_gray_wool)
B(-4,5,6,minecraft:light_gray_wool)
B(-4,5,7,minecraft:stone)
B(-4,5,8,minecraft:stone)
B(-4,6,-7,minecraft:stone)
B(-4,6,-6,minecraft:stone)
B(-4,6,-5,minecraft:stone)
B(-4,6,-4,minecraft:stone)
B(-4,6,-3,minecraft:light_gray_wool)
B(-4,6,-2,minecraft:glass)
B(-4,6,-1,minecraft:glass)
B(-4,6,0,minecraft:glass)
B(-4,6,1,minecraft:glass)
B(-4,6,2,minecraft:spruce_log[axis=x])
B(-4,6,3,minecraft:glass)
B(-4,6,4,minecraft:light_gray_wool)
B(-4,6,5,minecraft:light_gray_wool)
B(-4,6,6,minecraft:spruce_log)
B(-4,6,7,minecraft:stone)
B(-4,6,8,minecraft:stone)
B(-4,7,-7,minecraft:stone)
B(-4,7,-6,minecraft:stone)
B(-4,7,-5,minecraft:stone)
B(-4,7,-4,minecraft:stone)
B(-4,7,-3,minecraft:light_gray_wool)
B(-4,7,-2,minecraft:dark_oak_slab[type=top,waterlogged=false])
B(-4,7,-1,minecraft:dark_oak_slab[type=top,waterlogged=false])
B(-4,7,0,minecraft:dark_oak_slab[type=top,waterlogged=false])
B(-4,7,1,minecraft:dark_oak_slab[type=top,waterlogged=false])
B(-4,7,2,minecraft:dark_oak_slab[type=top,waterlogged=false])
B(-4,7,3,minecraft:dark_oak_slab[type=top,waterlogged=false])
B(-4,7,4,minecraft:light_gray_wool)
B(-4,7,5,minecraft:stone)
B(-4,7,6,minecraft:stone)
B(-4,7,7,minecraft:stone)
B(-4,7,8,minecraft:stone)
B(-4,8,-7,minecraft:stone)
B(-4,8,-6,minecraft:stone)
B(-4,8,-5,minecraft:stone)
B(-4,8,-4,minecraft:stone)
B(-4,8,-3,minecraft:stone)
B(-4,8,-2,minecraft:stone)
B(-4,8,-1,minecraft:stone)
B(-4,8,0,minecraft:stone)
B(-4,8,1,minecraft:stone)
B(-4,8,2,minecraft:stone)
B(-4,8,3,minecraft:stone)
B(-4,8,4,minecraft:stone)
B(-4,8,5,minecraft:stone)
B(-4,8,6,minecraft:stone)
B(-4,8,7,minecraft:stone)
B(-4,8,8,minecraft:stone)
B(-3,0,-7,minecraft:stone)
B(-3,0,-6,minecraft:stone)
B(-3,0,-5,minecraft:stone)
B(-3,0,-4,minecraft:stone)
B(-3,0,-3,minecraft:stone)
B(-3,0,-2,minecraft:stone)
B(-3,0,-1,minecraft:spruce_planks)
B(-3,0,0,minecraft:spruce_stairs[facing=south,half=bottom,shape=straight,waterlogged=false])
B(-3,0,1,minecraft:spruce_stairs[facing=west,half=bottom,shape=straight,waterlogged=false])
B(-3,0,2,minecraft:spruce_planks)
B(-3,0,3,minecraft:spruce_planks)
B(-3,0,4,minecraft:spruce_planks)
B(-3,0,5,minecraft:spruce_planks)
B(-3,0,6,minecraft:spruce_planks)
B(-3,0,7,minecraft:stone)
B(-3,0,8,minecraft:stone)
B(-3,1,-7,minecraft:stone)
B(-3,1,-6,minecraft:stone)
B(-3,1,-5,minecraft:stone)
B(-3,1,-4,minecraft:stone)
B(-3,1,-3,minecraft:glass)
B(-3,1,-2,minecraft:polished_andesite)
B(-3,1,-1,minecraft:glass)
B(-3,1,0,minecraft:glass)
B(-3,1,1,minecraft:glass)
B(-3,1,2,minecraft:glass)
B(-3,1,3,minecraft:polished_andesite)
B(-3,1,4,minecraft:dark_oak_stairs[facing=west,half=top,shape=straight,waterlogged=false])
B(-3,1,5,minecraft:dark_oak_stairs[facing=west,half=top,shape=straight,waterlogged=false])
B(-3,1,6,minecraft:dark_oak_stairs[facing=west,half=top,shape=straight,waterlogged=false])
B(-3,1,7,minecraft:infested_chiseled_stone_bricks)
B(-3,1,8,minecraft:stone)
B(-3,2,-7,minecraft:stone)
B(-3,2,-6,minecraft:stone)
B(-3,2,-5,minecraft:stone)
B(-3,2,-4,minecraft:stone)
B(-3,2,-3,minecraft:glass)
B(-3,2,-2,minecraft:stone_brick_stairs)
B(-3,2,-1,minecraft:glass)
B(-3,2,0,minecraft:glass)
B(-3,2,1,minecraft:glass)
B(-3,2,2,minecraft:glass)
B(-3,2,3,minecraft:stone_brick_stairs[facing=south,half=bottom,shape=straight,waterlogged=false])
B(-3,2,4,minecraft:glass)
B(-3,2,5,minecraft:glass)
B(-3,2,6,minecraft:glass)
B(-3,2,7,minecraft:cobblestone)
B(-3,2,8,minecraft:stone)
B(-3,3,-7,minecraft:stone)
B(-3,3,-6,minecraft:stone)
B(-3,3,-5,minecraft:stone)
B(-3,3,-4,minecraft:stone)
B(-3,3,-3,minecraft:glass)
B(-3,3,-2,minecraft:stone_brick_stairs[facing=north,half=top,shape=straight,waterlogged=false])
B(-3,3,-1,minecraft:glass)
B(-3,3,0,minecraft:glass)
B(-3,3,1,minecraft:glass)
B(-3,3,2,minecraft:glass)
B(-3,3,3,minecraft:stone_brick_stairs[facing=south,half=top,shape=straight,waterlogged=false])
B(-3,3,4,minecraft:glass)
B(-3,3,5,minecraft:glass)
B(-3,3,6,minecraft:glass)
B(-3,3,7,minecraft:cobblestone)
B(-3,3,8,minecraft:stone)
B(-3,4,-7,minecraft:stone)
B(-3,4,-6,minecraft:stone)
B(-3,4,-5,minecraft:stone)
B(-3,4,-4,minecraft:stone)
B(-3,4,-3,minecraft:glass)
B(-3,4,-2,minecraft:cracked_stone_bricks)
B(-3,4,-1,minecraft:glass)
B(-3,4,0,minecraft:glass)
B(-3,4,1,minecraft:glass)
B(-3,4,2,minecraft:glass)
B(-3,4,3,minecraft:polished_andesite)
B(-3,4,4,minecraft:glass)
B(-3,4,5,minecraft:glass)
B(-3,4,6,minecraft:glass)
B(-3,4,7,minecraft:cobblestone)
B(-3,4,8,minecraft:stone)
B(-3,5,-7,minecraft:stone)
B(-3,5,-6,minecraft:stone)
B(-3,5,-5,minecraft:stone)
B(-3,5,-4,minecraft:stone)
B(-3,5,-3,minecraft:glass)
B(-3,5,-2,minecraft:polished_andesite)
B(-3,5,-1,minecraft:glass)
B(-3,5,0,minecraft:glass)
B(-3,5,1,minecraft:glass)
B(-3,5,2,minecraft:glass)
B(-3,5,3,minecraft:polished_andesite)
B(-3,5,4,minecraft:glass)
B(-3,5,5,minecraft:glass)
B(-3,5,6,minecraft:glass)
B(-3,5,7,minecraft:cobblestone)
B(-3,5,8,minecraft:stone)
B(-3,6,-7,minecraft:stone)
B(-3,6,-6,minecraft:stone)
B(-3,6,-5,minecraft:stone)
B(-3,6,-4,minecraft:stone)
B(-3,6,-3,minecraft:glass)
B(-3,6,-2,minecraft:cobblestone)
B(-3,6,-1,minecraft:glass)
B(-3,6,0,minecraft:glass)
B(-3,6,1,minecraft:glass)
B(-3,6,2,minecraft:spruce_log[axis=x])
B(-3,6,3,minecraft:polished_andesite)
B(-3,6,4,minecraft:spruce_log[axis=x])
B(-3,6,5,minecraft:glass)
B(-3,6,6,minecraft:spruce_log[axis=x])
B(-3,6,7,minecraft:cobblestone)
B(-3,6,8,minecraft:stone)
B(-3,7,-7,minecraft:stone)
B(-3,7,-6,minecraft:stone)
B(-3,7,-5,minecraft:stone)
B(-3,7,-4,minecraft:stone)
B(-3,7,-3,minecraft:stone)
B(-3,7,-2,minecraft:spruce_log[axis=z])
B(-3,7,-1,minecraft:spruce_log[axis=z])
B(-3,7,0,minecraft:spruce_log[axis=z])
B(-3,7,1,minecraft:spruce_log[axis=z])
B(-3,7,2,minecraft:spruce_log[axis=z])
B(-3,7,3,minecraft:cobblestone)
B(-3,7,4,minecraft:dark_oak_planks)
B(-3,7,5,minecraft:dark_oak_planks)
B(-3,7,6,minecraft:dark_oak_planks)
B(-3,7,7,minecraft:cobblestone)
B(-3,7,8,minecraft:stone)
B(-3,8,-7,minecraft:stone)
B(-3,8,-6,minecraft:stone)
B(-3,8,-5,minecraft:stone)
B(-3,8,-4,minecraft:stone)
B(-3,8,-3,minecraft:stone)
B(-3,8,-2,minecraft:stone)
B(-3,8,-1,minecraft:stone)
B(-3,8,0,minecraft:stone)
B(-3,8,1,minecraft:stone)
B(-3,8,2,minecraft:stone)
B(-3,8,3,minecraft:stone)
B(-3,8,4,minecraft:stone)
B(-3,8,5,minecraft:stone)
B(-3,8,6,minecraft:stone)
B(-3,8,7,minecraft:stone)
B(-3,8,8,minecraft:stone)
B(-2,0,-7,minecraft:stone)
B(-2,0,-6,minecraft:stone)
B(-2,0,-5,minecraft:stone)
B(-2,0,-4,minecraft:stone)
B(-2,0,-3,minecraft:stone)
B(-2,0,-2,minecraft:spruce_planks)
B(-2,0,-1,minecraft:spruce_stairs[facing=west,half=bottom,shape=straight,waterlogged=false])
B(-2,0,0,minecraft:spruce_stairs[facing=west,half=bottom,shape=straight,waterlogged=false])
B(-2,0,1,minecraft:spruce_planks)
B(-2,0,2,minecraft:spruce_planks)
B(-2,0,3,minecraft:spruce_planks)
B(-2,0,4,minecraft:spruce_planks)
B(-2,0,5,minecraft:spruce_planks)
B(-2,0,6,minecraft:spruce_planks)
B(-2,0,7,minecraft:spruce_planks)
B(-2,0,8,minecraft:polished_andesite)
B(-2,1,-7,minecraft:stone)
B(-2,1,-6,minecraft:stone)
B(-2,1,-5,minecraft:stone)
B(-2,1,-4,minecraft:stone)
B(-2,1,-3,minecraft:gray_wool)
B(-2,1,-2,minecraft:dark_oak_stairs[facing=north,half=top,shape=straight,waterlogged=false])
B(-2,1,-1,minecraft:glass)
B(-2,1,0,minecraft:glass)
B(-2,1,1,minecraft:glass)
B(-2,1,2,minecraft:glass)
B(-2,1,3,minecraft:glass)
B(-2,1,4,minecraft:glass)
B(-2,1,5,minecraft:glass)
B(-2,1,6,minecraft:glass)
B(-2,1,7,minecraft:glass)
B(-2,1,8,minecraft:polished_andesite)
B(-2,2,-7,minecraft:stone)
B(-2,2,-6,minecraft:stone)
B(-2,2,-5,minecraft:stone)
B(-2,2,-4,minecraft:stone)
B(-2,2,-3,minecraft:gray_wool)
B(-2,2,-2,minecraft:glass)
B(-2,2,-1,minecraft:glass)
B(-2,2,0,minecraft:glass)
B(-2,2,1,minecraft:glass)
B(-2,2,2,minecraft:glass)
B(-2,2,3,minecraft:glass)
B(-2,2,4,minecraft:glass)
B(-2,2,5,minecraft:glass)
B(-2,2,6,minecraft:glass)
B(-2,2,7,minecraft:glass)
B(-2,2,8,minecraft:polished_andesite)
B(-2,3,-7,minecraft:stone)
B(-2,3,-6,minecraft:stone)
B(-2,3,-5,minecraft:stone)
B(-2,3,-4,minecraft:stone)
B(-2,3,-3,minecraft:gray_wool)
B(-2,3,-2,minecraft:glass)
B(-2,3,-1,minecraft:glass)
B(-2,3,0,minecraft:glass)
B(-2,3,1,minecraft:glass)
B(-2,3,2,minecraft:glass)
B(-2,3,3,minecraft:glass)
B(-2,3,4,minecraft:glass)
B(-2,3,5,minecraft:glass)
B(-2,3,6,minecraft:glass)
B(-2,3,7,minecraft:glass)
B(-2,3,8,minecraft:stone)
B(-2,4,-7,minecraft:stone)
B(-2,4,-6,minecraft:stone)
B(-2,4,-5,minecraft:stone)
B(-2,4,-4,minecraft:stone)
B(-2,4,-3,minecraft:gray_wool)
B(-2,4,-2,minecraft:glass)
B(-2,4,-1,minecraft:glass)
B(-2,4,0,minecraft:glass)
B(-2,4,1,minecraft:glass)
B(-2,4,2,minecraft:stone_brick_slab[type=top,waterlogged=false])
B(-2,4,3,minecraft:glass)
B(-2,4,4,minecraft:glass)
B(-2,4,5,minecraft:glass)
B(-2,4,6,minecraft:glass)
B(-2,4,7,minecraft:glass)
B(-2,4,8,minecraft:cracked_stone_bricks)
B(-2,5,-7,minecraft:stone)
B(-2,5,-6,minecraft:stone)
B(-2,5,-5,minecraft:stone)
B(-2,5,-4,minecraft:stone)
B(-2,5,-3,minecraft:gray_wool)
B(-2,5,-2,minecraft:glass)
B(-2,5,-1,minecraft:glass)
B(-2,5,0,minecraft:glass)
B(-2,5,1,minecraft:glass)
B(-2,5,2,minecraft:polished_andesite)
B(-2,5,3,minecraft:glass)
B(-2,5,4,minecraft:glass)
B(-2,5,5,minecraft:glass)
B(-2,5,6,minecraft:glass)
B(-2,5,7,minecraft:glass)
B(-2,5,8,minecraft:cracked_stone_bricks)
B(-2,6,-7,minecraft:stone)
B(-2,6,-6,minecraft:stone)
B(-2,6,-5,minecraft:stone)
B(-2,6,-4,minecraft:stone)
B(-2,6,-3,minecraft:gray_wool)
B(-2,6,-2,minecraft:glass)
B(-2,6,-1,minecraft:glass)
B(-2,6,0,minecraft:glass)
B(-2,6,1,minecraft:glass)
B(-2,6,2,minecraft:spruce_log[axis=x])
B(-2,6,3,minecraft:glass)
B(-2,6,4,minecraft:spruce_log[axis=x])
B(-2,6,5,minecraft:glass)
B(-2,6,6,minecraft:spruce_log[axis=x])
B(-2,6,7,minecraft:glass)
B(-2,6,8,minecraft:stone)
B(-2,7,-7,minecraft:stone)
B(-2,7,-6,minecraft:stone)
B(-2,7,-5,minecraft:stone)
B(-2,7,-4,minecraft:stone)
B(-2,7,-3,minecraft:gray_wool)
B(-2,7,-2,minecraft:dark_oak_slab[type=top,waterlogged=false])
B(-2,7,-1,minecraft:dark_oak_slab[type=top,waterlogged=false])
B(-2,7,0,minecraft:dark_oak_slab[type=top,waterlogged=false])
B(-2,7,1,minecraft:dark_oak_slab[type=top,waterlogged=false])
B(-2,7,2,minecraft:dark_oak_planks)
B(-2,7,3,minecraft:dark_oak_planks)
B(-2,7,4,minecraft:dark_oak_planks)
B(-2,7,5,minecraft:dark_oak_planks)
B(-2,7,6,minecraft:dark_oak_planks)
B(-2,7,7,minecraft:dark_oak_planks)
B(-2,7,8,minecraft:stone)
B(-2,8,-7,minecraft:stone)
B(-2,8,-6,minecraft:stone)
B(-2,8,-5,minecraft:stone)
B(-2,8,-4,minecraft:stone)
B(-2,8,-3,minecraft:stone)
B(-2,8,-2,minecraft:stone)
B(-2,8,-1,minecraft:stone)
B(-2,8,0,minecraft:stone)
B(-2,8,1,minecraft:stone)
B(-2,8,2,minecraft:stone)
B(-2,8,3,minecraft:stone)
B(-2,8,4,minecraft:stone)
B(-2,8,5,minecraft:stone)
B(-2,8,6,minecraft:stone)
B(-2,8,7,minecraft:stone)
B(-2,8,8,minecraft:stone)
B(-1,0,-7,minecraft:stone)
B(-1,0,-6,minecraft:stone)
B(-1,0,-5,minecraft:stone)
B(-1,0,-4,minecraft:stone)
B(-1,0,-3,minecraft:stone)
B(-1,0,-2,minecraft:spruce_planks)
B(-1,0,-1,minecraft:spruce_planks)
B(-1,0,0,minecraft:spruce_planks)
B(-1,0,1,minecraft:spruce_planks)
B(-1,0,2,minecraft:spruce_slab)
B(-1,0,3,minecraft:spruce_planks)
B(-1,0,4,minecraft:spruce_planks)
B(-1,0,5,minecraft:spruce_stairs[facing=west,half=bottom,shape=straight,waterlogged=false])
B(-1,0,6,minecraft:spruce_stairs[facing=west,half=bottom,shape=straight,waterlogged=false])
B(-1,0,7,minecraft:spruce_planks)
B(-1,0,8,minecraft:spruce_planks)
B(-1,1,-7,minecraft:stone)
B(-1,1,-6,minecraft:stone)
B(-1,1,-5,minecraft:stone)
B(-1,1,-4,minecraft:stone)
B(-1,1,-3,minecraft:gray_wool)
B(-1,1,-2,minecraft:dark_oak_stairs[facing=north,half=top,shape=straight,waterlogged=false])
B(-1,1,-1,minecraft:glass)
B(-1,1,0,minecraft:glass)
B(-1,1,1,minecraft:glass)
B(-1,1,2,minecraft:glass)
B(-1,1,3,minecraft:glass)
B(-1,1,4,minecraft:oak_button[face=floor,facing=east,powered=false])
B(-1,1,5,minecraft:glass)
B(-1,1,6,minecraft:glass)
B(-1,1,7,minecraft:glass)
B(-1,1,8,minecraft:glass)
B(-1,2,-7,minecraft:stone)
B(-1,2,-6,minecraft:stone)
B(-1,2,-5,minecraft:stone)
B(-1,2,-4,minecraft:stone)
B(-1,2,-3,minecraft:gray_wool)
B(-1,2,-2,minecraft:glass)
B(-1,2,-1,minecraft:glass)
B(-1,2,0,minecraft:glass)
B(-1,2,1,minecraft:glass)
B(-1,2,2,minecraft:glass)
B(-1,2,3,minecraft:glass)
B(-1,2,4,minecraft:glass)
B(-1,2,5,minecraft:glass)
B(-1,2,6,minecraft:glass)
B(-1,2,7,minecraft:glass)
B(-1,2,8,minecraft:glass)
B(-1,3,-7,minecraft:stone)
B(-1,3,-6,minecraft:stone)
B(-1,3,-5,minecraft:stone)
B(-1,3,-4,minecraft:stone)
B(-1,3,-3,minecraft:gray_wool)
B(-1,3,-2,minecraft:glass)
B(-1,3,-1,minecraft:glass)
B(-1,3,0,minecraft:glass)
B(-1,3,1,minecraft:glass)
B(-1,3,2,minecraft:glass)
B(-1,3,3,minecraft:glass)
B(-1,3,4,minecraft:glass)
B(-1,3,5,minecraft:glass)
B(-1,3,6,minecraft:glass)
B(-1,3,7,minecraft:glass)
B(-1,3,8,minecraft:glass)
B(-1,4,-7,minecraft:stone)
B(-1,4,-6,minecraft:stone)
B(-1,4,-5,minecraft:stone)
B(-1,4,-4,minecraft:stone)
B(-1,4,-3,minecraft:gray_wool)
B(-1,4,-2,minecraft:glass)
B(-1,4,-1,minecraft:glass)
B(-1,4,0,minecraft:glass)
B(-1,4,1,minecraft:glass)
B(-1,4,2,minecraft:glass)
B(-1,4,3,minecraft:glass)
B(-1,4,4,minecraft:glass)
B(-1,4,5,minecraft:glass)
B(-1,4,6,minecraft:glass)
B(-1,4,7,minecraft:glass)
B(-1,4,8,minecraft:glass)
B(-1,5,-7,minecraft:stone)
B(-1,5,-6,minecraft:stone)
B(-1,5,-5,minecraft:stone)
B(-1,5,-4,minecraft:stone)
B(-1,5,-3,minecraft:gray_wool)
B(-1,5,-2,minecraft:glass)
B(-1,5,-1,minecraft:glass)
B(-1,5,0,minecraft:glass)
B(-1,5,1,minecraft:stone_brick_slab[type=double,waterlogged=false])
B(-1,5,2,minecraft:glass)
B(-1,5,3,minecraft:glass)
B(-1,5,4,minecraft:glass)
B(-1,5,5,minecraft:glass)
B(-1,5,6,minecraft:glass)
B(-1,5,7,minecraft:glass)
B(-1,5,8,minecraft:glass)
B(-1,6,-7,minecraft:stone)
B(-1,6,-6,minecraft:stone)
B(-1,6,-5,minecraft:stone)
B(-1,6,-4,minecraft:stone)
B(-1,6,-3,minecraft:gray_wool)
B(-1,6,-2,minecraft:glass)
B(-1,6,-1,minecraft:glass)
B(-1,6,0,minecraft:glass)
B(-1,6,1,minecraft:cracked_stone_bricks)
B(-1,6,2,minecraft:spruce_log[axis=x])
B(-1,6,3,minecraft:glass)
B(-1,6,4,minecraft:spruce_log[axis=x])
B(-1,6,5,minecraft:glass)
B(-1,6,6,minecraft:spruce_log[axis=x])
B(-1,6,7,minecraft:glass)
B(-1,6,8,minecraft:glass)
B(-1,7,-7,minecraft:stone)
B(-1,7,-6,minecraft:stone)
B(-1,7,-5,minecraft:stone)
B(-1,7,-4,minecraft:stone)
B(-1,7,-3,minecraft:spruce_log[axis=z])
B(-1,7,-2,minecraft:spruce_log[axis=z])
B(-1,7,-1,minecraft:spruce_log[axis=z])
B(-1,7,0,minecraft:spruce_log[axis=z])
B(-1,7,1,minecraft:cracked_stone_bricks)
B(-1,7,2,minecraft:dark_oak_planks)
B(-1,7,3,minecraft:dark_oak_planks)
B(-1,7,4,minecraft:dark_oak_planks)
B(-1,7,5,minecraft:dark_oak_planks)
B(-1,7,6,minecraft:dark_oak_planks)
B(-1,7,7,minecraft:dark_oak_planks)
B(-1,7,8,minecraft:stone)
B(-1,8,-7,minecraft:stone)
B(-1,8,-6,minecraft:stone)
B(-1,8,-5,minecraft:stone)
B(-1,8,-4,minecraft:stone)
B(-1,8,-3,minecraft:stone)
B(-1,8,-2,minecraft:stone)
B(-1,8,-1,minecraft:stone)
B(-1,8,0,minecraft:stone)
B(-1,8,1,minecraft:stone)
B(-1,8,2,minecraft:stone)
B(-1,8,3,minecraft:stone)
B(-1,8,4,minecraft:stone)
B(-1,8,5,minecraft:stone)
B(-1,8,6,minecraft:stone)
B(-1,8,7,minecraft:stone)
B(-1,8,8,minecraft:stone)
B(0,0,-7,minecraft:stone)
B(0,0,-6,minecraft:stone)
B(0,0,-5,minecraft:stone)
B(0,0,-4,minecraft:stone)
B(0,0,-3,minecraft:stone)
B(0,0,-2,minecraft:spruce_planks)
B(0,0,-1,minecraft:spruce_planks)
B(0,0,0,minecraft:spruce_planks)
B(0,0,1,minecraft:spruce_planks)
B(0,0,2,minecraft:spruce_slab)
B(0,0,3,minecraft:spruce_slab)
B(0,0,4,minecraft:spruce_planks)
B(0,0,5,minecraft:spruce_stairs)
B(0,0,6,minecraft:spruce_stairs[facing=east,half=bottom,shape=straight,waterlogged=false])
B(0,0,7,minecraft:spruce_planks)
B(0,0,8,minecraft:spruce_planks)
B(0,1,-7,minecraft:stone)
B(0,1,-6,minecraft:stone)
B(0,1,-5,minecraft:stone)
B(0,1,-4,minecraft:stone)
B(0,1,-3,minecraft:gray_wool)
B(0,1,-2,minecraft:dark_oak_stairs[facing=north,half=top,shape=straight,waterlogged=false])
B(0,1,-1,minecraft:glass)
B(0,1,0,minecraft:oak_button[face=floor,facing=east,powered=false])
B(0,1,1,minecraft:glass)
B(0,1,2,minecraft:glass)
B(0,1,3,minecraft:glass)
B(0,1,4,minecraft:glass)
B(0,1,5,minecraft:glass)
B(0,1,6,minecraft:glass)
B(0,1,7,minecraft:glass)
B(0,1,8,minecraft:glass)
B(0,2,-7,minecraft:stone)
B(0,2,-6,minecraft:stone)
B(0,2,-5,minecraft:stone)
B(0,2,-4,minecraft:stone)
B(0,2,-3,minecraft:gray_wool)
B(0,2,-2,minecraft:glass)
B(0,2,-1,minecraft:glass)
B(0,2,0,minecraft:glass)
B(0,2,1,minecraft:glass)
B(0,2,2,minecraft:glass)
B(0,2,3,minecraft:glass)
B(0,2,4,minecraft:glass)
B(0,2,5,minecraft:glass)
B(0,2,6,minecraft:glass)
B(0,2,7,minecraft:glass)
B(0,2,8,minecraft:glass)
B(0,3,-7,minecraft:stone)
B(0,3,-6,minecraft:stone)
B(0,3,-5,minecraft:stone)
B(0,3,-4,minecraft:stone)
B(0,3,-3,minecraft:gray_wool)
B(0,3,-2,minecraft:glass)
B(0,3,-1,minecraft:glass)
B(0,3,0,minecraft:glass)
B(0,3,1,minecraft:glass)
B(0,3,2,minecraft:glass)
B(0,3,3,minecraft:glass)
B(0,3,4,minecraft:glass)
B(0,3,5,minecraft:glass)
B(0,3,6,minecraft:glass)
B(0,3,7,minecraft:glass)
B(0,3,8,minecraft:glass)
B(0,4,-7,minecraft:stone)
B(0,4,-6,minecraft:stone)
B(0,4,-5,minecraft:stone)
B(0,4,-4,minecraft:stone)
B(0,4,-3,minecraft:gray_wool)
B(0,4,-2,minecraft:glass)
B(0,4,-1,minecraft:glass)
B(0,4,0,minecraft:stone_brick_slab[type=top,waterlogged=false])
B(0,4,1,minecraft:glass)
B(0,4,2,minecraft:glass)
B(0,4,3,minecraft:glass)
B(0,4,4,minecraft:glass)
B(0,4,5,minecraft:glass)
B(0,4,6,minecraft:glass)
B(0,4,7,minecraft:glass)
B(0,4,8,minecraft:glass)
B(0,5,-7,minecraft:stone)
B(0,5,-6,minecraft:stone)
B(0,5,-5,minecraft:stone)
B(0,5,-4,minecraft:stone)
B(0,5,-3,minecraft:gray_wool)
B(0,5,-2,minecraft:glass)
B(0,5,-1,minecraft:glass)
B(0,5,0,minecraft:polished_andesite)
B(0,5,1,minecraft:glass)
B(0,5,2,minecraft:glass)
B(0,5,3,minecraft:glass)
B(0,5,4,minecraft:glass)
B(0,5,5,minecraft:glass)
B(0,5,6,minecraft:glass)
B(0,5,7,minecraft:glass)
B(0,5,8,minecraft:glass)
B(0,6,-7,minecraft:stone)
B(0,6,-6,minecraft:stone)
B(0,6,-5,minecraft:stone)
B(0,6,-4,minecraft:stone)
B(0,6,-3,minecraft:gray_wool)
B(0,6,-2,minecraft:glass)
B(0,6,-1,minecraft:glass)
B(0,6,0,minecraft:polished_andesite)
B(0,6,1,minecraft:glass)
B(0,6,2,minecraft:spruce_log[axis=x])
B(0,6,3,minecraft:glass)
B(0,6,4,minecraft:spruce_log[axis=x])
B(0,6,5,minecraft:glass)
B(0,6,6,minecraft:spruce_log[axis=x])
B(0,6,7,minecraft:glass)
B(0,6,8,minecraft:glass)
B(0,7,-7,minecraft:stone)
B(0,7,-6,minecraft:stone)
B(0,7,-5,minecraft:stone)
B(0,7,-4,minecraft:stone)
B(0,7,-3,minecraft:gray_wool)
B(0,7,-2,minecraft:dark_oak_slab[type=top,waterlogged=false])
B(0,7,-1,minecraft:dark_oak_slab[type=top,waterlogged=false])
B(0,7,0,minecraft:cracked_stone_bricks)
B(0,7,1,minecraft:dark_oak_planks)
B(0,7,2,minecraft:dark_oak_planks)
B(0,7,3,minecraft:dark_oak_planks)
B(0,7,4,minecraft:dark_oak_planks)
B(0,7,5,minecraft:dark_oak_planks)
B(0,7,6,minecraft:dark_oak_planks)
B(0,7,7,minecraft:dark_oak_planks)
B(0,7,8,minecraft:stone)
B(0,8,-7,minecraft:stone)
B(0,8,-6,minecraft:stone)
B(0,8,-5,minecraft:stone)
B(0,8,-4,minecraft:stone)
B(0,8,-3,minecraft:stone)
B(0,8,-2,minecraft:stone)
B(0,8,-1,minecraft:stone)
B(0,8,0,minecraft:stone)
B(0,8,1,minecraft:stone)
B(0,8,2,minecraft:stone)
B(0,8,3,minecraft:stone)
B(0,8,4,minecraft:stone)
B(0,8,5,minecraft:stone)
B(0,8,6,minecraft:stone)
B(0,8,7,minecraft:stone)
B(0,8,8,minecraft:stone)
B(1,0,-7,minecraft:stone)
B(1,0,-6,minecraft:stone)
B(1,0,-5,minecraft:stone)
B(1,0,-4,minecraft:stone)
B(1,0,-3,minecraft:stone)
B(1,0,-2,minecraft:stone)
B(1,0,-1,minecraft:spruce_planks)
B(1,0,0,minecraft:spruce_planks)
B(1,0,1,minecraft:spruce_planks)
B(1,0,2,minecraft:spruce_planks)
B(1,0,3,minecraft:spruce_planks)
B(1,0,4,minecraft:spruce_planks)
B(1,0,5,minecraft:spruce_stairs)
B(1,0,6,minecraft:spruce_planks)
B(1,0,7,minecraft:spruce_planks)
B(1,0,8,minecraft:polished_andesite)
B(1,1,-7,minecraft:stone)
B(1,1,-6,minecraft:stone)
B(1,1,-5,minecraft:stone)
B(1,1,-4,minecraft:stone)
B(1,1,-3,minecraft:stone)
B(1,1,-2,minecraft:polished_andesite)
B(1,1,-1,minecraft:glass)
B(1,1,0,minecraft:glass)
B(1,1,1,minecraft:glass)
B(1,1,2,minecraft:glass)
B(1,1,3,minecraft:glass)
B(1,1,4,minecraft:glass)
B(1,1,5,minecraft:glass)
B(1,1,6,minecraft:glass)
B(1,1,7,minecraft:glass)
B(1,1,8,minecraft:polished_andesite)
B(1,2,-7,minecraft:stone)
B(1,2,-6,minecraft:stone)
B(1,2,-5,minecraft:stone)
B(1,2,-4,minecraft:stone)
B(1,2,-3,minecraft:stone)
B(1,2,-2,minecraft:cobblestone)
B(1,2,-1,minecraft:glass)
B(1,2,0,minecraft:glass)
B(1,2,1,minecraft:glass)
B(1,2,2,minecraft:glass)
B(1,2,3,minecraft:glass)
B(1,2,4,minecraft:glass)
B(1,2,5,minecraft:glass)
B(1,2,6,minecraft:glass)
B(1,2,7,minecraft:glass)
B(1,2,8,minecraft:stone)
B(1,3,-7,minecraft:stone)
B(1,3,-6,minecraft:stone)
B(1,3,-5,minecraft:stone)
B(1,3,-4,minecraft:stone)
B(1,3,-3,minecraft:stone)
B(1,3,-2,minecraft:cracked_stone_bricks)
B(1,3,-1,minecraft:stone_brick_slab[type=top,waterlogged=false])
B(1,3,0,minecraft:glass)
B(1,3,1,minecraft:glass)
B(1,3,2,minecraft:glass)
B(1,3,3,minecraft:glass)
B(1,3,4,minecraft:glass)
B(1,3,5,minecraft:glass)
B(1,3,6,minecraft:glass)
B(1,3,7,minecraft:glass)
B(1,3,8,minecraft:cracked_stone_bricks)
B(1,4,-7,minecraft:stone)
B(1,4,-6,minecraft:stone)
B(1,4,-5,minecraft:stone)
B(1,4,-4,minecraft:stone)
B(1,4,-3,minecraft:stone)
B(1,4,-2,minecraft:cracked_stone_bricks)
B(1,4,-1,minecraft:cracked_stone_bricks)
B(1,4,0,minecraft:glass)
B(1,4,1,minecraft:glass)
B(1,4,2,minecraft:glass)
B(1,4,3,minecraft:glass)
B(1,4,4,minecraft:glass)
B(1,4,5,minecraft:glass)
B(1,4,6,minecraft:glass)
B(1,4,7,minecraft:glass)
B(1,4,8,minecraft:stone)
B(1,5,-7,minecraft:stone)
B(1,5,-6,minecraft:stone)
B(1,5,-5,minecraft:stone)
B(1,5,-4,minecraft:stone)
B(1,5,-3,minecraft:stone)
B(1,5,-2,minecraft:cracked_stone_bricks)
B(1,5,-1,minecraft:cracked_stone_bricks)
B(1,5,0,minecraft:glass)
B(1,5,1,minecraft:glass)
B(1,5,2,minecraft:glass)
B(1,5,3,minecraft:glass)
B(1,5,4,minecraft:glass)
B(1,5,5,minecraft:glass)
B(1,5,6,minecraft:glass)
B(1,5,7,minecraft:glass)
B(1,5,8,minecraft:stone)
B(1,6,-7,minecraft:stone)
B(1,6,-6,minecraft:stone)
B(1,6,-5,minecraft:stone)
B(1,6,-4,minecraft:stone)
B(1,6,-3,minecraft:stone)
B(1,6,-2,minecraft:cobblestone)
B(1,6,-1,minecraft:cracked_stone_bricks)
B(1,6,0,minecraft:spruce_log[axis=x])
B(1,6,1,minecraft:glass)
B(1,6,2,minecraft:spruce_log[axis=x])
B(1,6,3,minecraft:glass)
B(1,6,4,minecraft:spruce_log[axis=x])
B(1,6,5,minecraft:glass)
B(1,6,6,minecraft:spruce_log[axis=x])
B(1,6,7,minecraft:glass)
B(1,6,8,minecraft:stone)
B(1,7,-7,minecraft:stone)
B(1,7,-6,minecraft:stone)
B(1,7,-5,minecraft:stone)
B(1,7,-4,minecraft:stone)
B(1,7,-3,minecraft:stone)
B(1,7,-2,minecraft:cobblestone)
B(1,7,-1,minecraft:cracked_stone_bricks)
B(1,7,0,minecraft:dark_oak_planks)
B(1,7,1,minecraft:dark_oak_planks)
B(1,7,2,minecraft:dark_oak_planks)
B(1,7,3,minecraft:dark_oak_planks)
B(1,7,4,minecraft:dark_oak_planks)
B(1,7,5,minecraft:dark_oak_planks)
B(1,7,6,minecraft:dark_oak_planks)
B(1,7,7,minecraft:dark_oak_planks)
B(1,7,8,minecraft:stone)
B(1,8,-7,minecraft:stone)
B(1,8,-6,minecraft:stone)
B(1,8,-5,minecraft:stone)
B(1,8,-4,minecraft:stone)
B(1,8,-3,minecraft:stone)
B(1,8,-2,minecraft:stone)
B(1,8,-1,minecraft:stone)
B(1,8,0,minecraft:stone)
B(1,8,1,minecraft:stone)
B(1,8,2,minecraft:stone)
B(1,8,3,minecraft:stone)
B(1,8,4,minecraft:stone)
B(1,8,5,minecraft:stone)
B(1,8,6,minecraft:stone)
B(1,8,7,minecraft:stone)
B(1,8,8,minecraft:stone)
B(2,0,-7,minecraft:stone)
B(2,0,-6,minecraft:stone)
B(2,0,-5,minecraft:stone)
B(2,0,-4,minecraft:stone)
B(2,0,-3,minecraft:stone)
B(2,0,-2,minecraft:stone)
B(2,0,-1,minecraft:stone)
B(2,0,0,minecraft:spruce_planks)
B(2,0,1,minecraft:spruce_planks)
B(2,0,2,minecraft:spruce_planks)
B(2,0,3,minecraft:stone)
B(2,0,4,minecraft:spruce_planks)
B(2,0,5,minecraft:spruce_stairs[facing=east,half=bottom,shape=straight,waterlogged=false])
B(2,0,6,minecraft:spruce_stairs[facing=east,half=bottom,shape=straight,waterlogged=false])
B(2,0,7,minecraft:stone)
B(2,0,8,minecraft:stone)
B(2,1,-7,minecraft:stone)
B(2,1,-6,minecraft:stone)
B(2,1,-5,minecraft:stone)
B(2,1,-4,minecraft:stone)
B(2,1,-3,minecraft:stone)
B(2,1,-2,minecraft:stone)
B(2,1,-1,minecraft:polished_andesite)
B(2,1,0,minecraft:dark_oak_stairs[facing=east,half=top,shape=straight,waterlogged=false])
B(2,1,1,minecraft:dark_oak_stairs[facing=east,half=top,shape=straight,waterlogged=false])
B(2,1,2,minecraft:dark_oak_stairs[facing=east,half=top,shape=straight,waterlogged=false])
B(2,1,3,minecraft:infested_cracked_stone_bricks)
B(2,1,4,minecraft:dark_oak_stairs[facing=east,half=top,shape=straight,waterlogged=false])
B(2,1,5,minecraft:dark_oak_stairs[facing=east,half=top,shape=straight,waterlogged=false])
B(2,1,6,minecraft:dark_oak_stairs[facing=east,half=top,shape=straight,waterlogged=false])
B(2,1,7,minecraft:infested_chiseled_stone_bricks)
B(2,1,8,minecraft:stone)
B(2,2,-7,minecraft:stone)
B(2,2,-6,minecraft:stone)
B(2,2,-5,minecraft:stone)
B(2,2,-4,minecraft:stone)
B(2,2,-3,minecraft:stone)
B(2,2,-2,minecraft:stone)
B(2,2,-1,minecraft:cobblestone)
B(2,2,0,minecraft:glass)
B(2,2,1,minecraft:glass)
B(2,2,2,minecraft:glass)
B(2,2,3,minecraft:stone_brick_stairs[facing=east,half=bottom,shape=straight,waterlogged=false])
B(2,2,4,minecraft:glass)
B(2,2,5,minecraft:glass)
B(2,2,6,minecraft:glass)
B(2,2,7,minecraft:stone_brick_stairs[facing=east,half=bottom,shape=straight,waterlogged=false])
B(2,2,8,minecraft:stone)
B(2,3,-7,minecraft:stone)
B(2,3,-6,minecraft:stone)
B(2,3,-5,minecraft:stone)
B(2,3,-4,minecraft:stone)
B(2,3,-3,minecraft:stone)
B(2,3,-2,minecraft:stone)
B(2,3,-1,minecraft:cobblestone)
B(2,3,0,minecraft:glass)
B(2,3,1,minecraft:glass)
B(2,3,2,minecraft:glass)
B(2,3,3,minecraft:stone_brick_stairs[facing=east,half=top,shape=straight,waterlogged=false])
B(2,3,4,minecraft:glass)
B(2,3,5,minecraft:glass)
B(2,3,6,minecraft:glass)
B(2,3,7,minecraft:stone_brick_stairs[facing=east,half=top,shape=straight,waterlogged=false])
B(2,3,8,minecraft:stone)
B(2,4,-7,minecraft:stone)
B(2,4,-6,minecraft:stone)
B(2,4,-5,minecraft:stone)
B(2,4,-4,minecraft:stone)
B(2,4,-3,minecraft:stone)
B(2,4,-2,minecraft:stone)
B(2,4,-1,minecraft:cobblestone)
B(2,4,0,minecraft:glass)
B(2,4,1,minecraft:glass)
B(2,4,2,minecraft:glass)
B(2,4,3,minecraft:cobblestone)
B(2,4,4,minecraft:glass)
B(2,4,5,minecraft:glass)
B(2,4,6,minecraft:glass)
B(2,4,7,minecraft:cobblestone)
B(2,4,8,minecraft:stone)
B(2,5,-7,minecraft:stone)
B(2,5,-6,minecraft:stone)
B(2,5,-5,minecraft:stone)
B(2,5,-4,minecraft:stone)
B(2,5,-3,minecraft:stone)
B(2,5,-2,minecraft:stone)
B(2,5,-1,minecraft:cobblestone)
B(2,5,0,minecraft:glass)
B(2,5,1,minecraft:glass)
B(2,5,2,minecraft:glass)
B(2,5,3,minecraft:polished_andesite)
B(2,5,4,minecraft:glass)
B(2,5,5,minecraft:glass)
B(2,5,6,minecraft:glass)
B(2,5,7,minecraft:cobblestone)
B(2,5,8,minecraft:stone)
B(2,6,-7,minecraft:stone)
B(2,6,-6,minecraft:stone)
B(2,6,-5,minecraft:stone)
B(2,6,-4,minecraft:stone)
B(2,6,-3,minecraft:stone)
B(2,6,-2,minecraft:stone)
B(2,6,-1,minecraft:cobblestone)
B(2,6,0,minecraft:spruce_log[axis=x])
B(2,6,1,minecraft:glass)
B(2,6,2,minecraft:spruce_log[axis=x])
B(2,6,3,minecraft:polished_andesite)
B(2,6,4,minecraft:spruce_log[axis=x])
B(2,6,5,minecraft:glass)
B(2,6,6,minecraft:spruce_log[axis=x])
B(2,6,7,minecraft:cobblestone)
B(2,6,8,minecraft:stone)
B(2,7,-7,minecraft:stone)
B(2,7,-6,minecraft:stone)
B(2,7,-5,minecraft:stone)
B(2,7,-4,minecraft:stone)
B(2,7,-3,minecraft:stone)
B(2,7,-2,minecraft:stone)
B(2,7,-1,minecraft:cobblestone)
B(2,7,0,minecraft:dark_oak_planks)
B(2,7,1,minecraft:dark_oak_planks)
B(2,7,2,minecraft:dark_oak_planks)
B(2,7,3,minecraft:cobblestone)
B(2,7,4,minecraft:dark_oak_planks)
B(2,7,5,minecraft:dark_oak_planks)
B(2,7,6,minecraft:dark_oak_planks)
B(2,7,7,minecraft:cobblestone)
B(2,7,8,minecraft:stone)
B(2,8,-7,minecraft:stone)
B(2,8,-6,minecraft:stone)
B(2,8,-5,minecraft:stone)
B(2,8,-4,minecraft:stone)
B(2,8,-3,minecraft:stone)
B(2,8,-2,minecraft:stone)
B(2,8,-1,minecraft:stone)
B(2,8,0,minecraft:stone)
B(2,8,1,minecraft:stone)
B(2,8,2,minecraft:stone)
B(2,8,3,minecraft:stone)
B(2,8,4,minecraft:stone)
B(2,8,5,minecraft:stone)
B(2,8,6,minecraft:stone)
B(2,8,7,minecraft:stone)
B(2,8,8,minecraft:stone)
B(3,0,-7,minecraft:stone)
B(3,0,-6,minecraft:stone)
B(3,0,-5,minecraft:stone)
B(3,0,-4,minecraft:stone)
B(3,0,-3,minecraft:stone)
B(3,0,-2,minecraft:stone)
B(3,0,-1,minecraft:stone)
B(3,0,0,minecraft:stone)
B(3,0,1,minecraft:stone)
B(3,0,2,minecraft:stone)
B(3,0,3,minecraft:stone)
B(3,0,4,minecraft:stone)
B(3,0,5,minecraft:stone)
B(3,0,6,minecraft:stone)
B(3,0,7,minecraft:stone)
B(3,0,8,minecraft:stone)
B(3,1,-7,minecraft:stone)
B(3,1,-6,minecraft:stone)
B(3,1,-5,minecraft:stone)
B(3,1,-4,minecraft:stone)
B(3,1,-3,minecraft:stone)
B(3,1,-2,minecraft:stone)
B(3,1,-1,minecraft:stone)
B(3,1,0,minecraft:gray_wool)
B(3,1,1,minecraft:gray_wool)
B(3,1,2,minecraft:gray_wool)
B(3,1,3,minecraft:stone)
B(3,1,4,minecraft:light_gray_wool)
B(3,1,5,minecraft:light_gray_wool)
B(3,1,6,minecraft:light_gray_wool)
B(3,1,7,minecraft:stone)
B(3,1,8,minecraft:stone)
B(3,2,-7,minecraft:stone)
B(3,2,-6,minecraft:stone)
B(3,2,-5,minecraft:stone)
B(3,2,-4,minecraft:stone)
B(3,2,-3,minecraft:stone)
B(3,2,-2,minecraft:stone)
B(3,2,-1,minecraft:stone)
B(3,2,0,minecraft:gray_wool)
B(3,2,1,minecraft:gray_wool)
B(3,2,2,minecraft:gray_wool)
B(3,2,3,minecraft:stone)
B(3,2,4,minecraft:diorite)
B(3,2,5,minecraft:diorite)
B(3,2,6,minecraft:diorite)
B(3,2,7,minecraft:stone)
B(3,2,8,minecraft:stone)
B(3,3,-7,minecraft:stone)
B(3,3,-6,minecraft:stone)
B(3,3,-5,minecraft:stone)
B(3,3,-4,minecraft:stone)
B(3,3,-3,minecraft:stone)
B(3,3,-2,minecraft:stone)
B(3,3,-1,minecraft:stone)
B(3,3,0,minecraft:gray_wool)
B(3,3,1,minecraft:gray_wool)
B(3,3,2,minecraft:gray_wool)
B(3,3,3,minecraft:stone)
B(3,3,4,minecraft:diorite)
B(3,3,5,minecraft:polished_diorite)
B(3,3,6,minecraft:diorite)
B(3,3,7,minecraft:stone)
B(3,3,8,minecraft:stone)
B(3,4,-7,minecraft:stone)
B(3,4,-6,minecraft:stone)
B(3,4,-5,minecraft:stone)
B(3,4,-4,minecraft:stone)
B(3,4,-3,minecraft:stone)
B(3,4,-2,minecraft:stone)
B(3,4,-1,minecraft:stone)
B(3,4,0,minecraft:gray_wool)
B(3,4,1,minecraft:gray_wool)
B(3,4,2,minecraft:gray_wool)
B(3,4,3,minecraft:stone)
B(3,4,4,minecraft:polished_diorite)
B(3,4,5,minecraft:polished_diorite)
B(3,4,6,minecraft:diorite)
B(3,4,7,minecraft:stone)
B(3,4,8,minecraft:stone)
B(3,5,-7,minecraft:stone)
B(3,5,-6,minecraft:stone)
B(3,5,-5,minecraft:stone)
B(3,5,-4,minecraft:stone)
B(3,5,-3,minecraft:stone)
B(3,5,-2,minecraft:stone)
B(3,5,-1,minecraft:stone)
B(3,5,0,minecraft:gray_wool)
B(3,5,1,minecraft:gray_wool)
B(3,5,2,minecraft:gray_wool)
B(3,5,3,minecraft:stone)
B(3,5,4,minecraft:light_gray_wool)
B(3,5,5,minecraft:light_gray_wool)
B(3,5,6,minecraft:light_gray_wool)
B(3,5,7,minecraft:stone)
B(3,5,8,minecraft:stone)
B(3,6,-7,minecraft:stone)
B(3,6,-6,minecraft:stone)
B(3,6,-5,minecraft:stone)
B(3,6,-4,minecraft:stone)
B(3,6,-3,minecraft:stone)
B(3,6,-2,minecraft:stone)
B(3,6,-1,minecraft:stone)
B(3,6,0,minecraft:spruce_log)
B(3,6,1,minecraft:gray_wool)
B(3,6,2,minecraft:spruce_log)
B(3,6,3,minecraft:stone)
B(3,6,4,minecraft:spruce_log)
B(3,6,5,minecraft:light_gray_wool)
B(3,6,6,minecraft:spruce_log)
B(3,6,7,minecraft:stone)
B(3,6,8,minecraft:stone)
B(3,7,-7,minecraft:stone)
B(3,7,-6,minecraft:stone)
B(3,7,-5,minecraft:stone)
B(3,7,-4,minecraft:stone)
B(3,7,-3,minecraft:stone)
B(3,7,-2,minecraft:stone)
B(3,7,-1,minecraft:stone)
B(3,7,0,minecraft:stone)
B(3,7,1,minecraft:stone)
B(3,7,2,minecraft:stone)
B(3,7,3,minecraft:stone)
B(3,7,4,minecraft:stone)
B(3,7,5,minecraft:stone)
B(3,7,6,minecraft:stone)
B(3,7,7,minecraft:stone)
B(3,7,8,minecraft:stone)
B(3,8,-7,minecraft:stone)
B(3,8,-6,minecraft:stone)
B(3,8,-5,minecraft:stone)
B(3,8,-4,minecraft:stone)
B(3,8,-3,minecraft:stone)
B(3,8,-2,minecraft:stone)
B(3,8,-1,minecraft:stone)
B(3,8,0,minecraft:stone)
B(3,8,1,minecraft:stone)
B(3,8,2,minecraft:stone)
B(3,8,3,minecraft:stone)
B(3,8,4,minecraft:stone)
B(3,8,5,minecraft:stone)
B(3,8,6,minecraft:stone)
B(3,8,7,minecraft:stone)
B(3,8,8,minecraft:stone)
B(4,0,-7,minecraft:stone)
B(4,0,-6,minecraft:stone)
B(4,0,-5,minecraft:stone)
B(4,0,-4,minecraft:stone)
B(4,0,-3,minecraft:stone)
B(4,0,-2,minecraft:stone)
B(4,0,-1,minecraft:stone)
B(4,0,0,minecraft:stone)
B(4,0,1,minecraft:stone)
B(4,0,2,minecraft:stone)
B(4,0,3,minecraft:stone)
B(4,0,4,minecraft:stone)
B(4,0,5,minecraft:stone)
B(4,0,6,minecraft:stone)
B(4,0,7,minecraft:stone)
B(4,0,8,minecraft:stone)
B(4,1,-7,minecraft:stone)
B(4,1,-6,minecraft:stone)
B(4,1,-5,minecraft:stone)
B(4,1,-4,minecraft:stone)
B(4,1,-3,minecraft:stone)
B(4,1,-2,minecraft:stone)
B(4,1,-1,minecraft:stone)
B(4,1,0,minecraft:stone)
B(4,1,1,minecraft:stone)
B(4,1,2,minecraft:stone)
B(4,1,3,minecraft:stone)
B(4,1,4,minecraft:stone)
B(4,1,5,minecraft:stone)
B(4,1,6,minecraft:stone)
B(4,1,7,minecraft:stone)
B(4,1,8,minecraft:stone)
B(4,2,-7,minecraft:stone)
B(4,2,-6,minecraft:stone)
B(4,2,-5,minecraft:stone)
B(4,2,-4,minecraft:stone)
B(4,2,-3,minecraft:stone)
B(4,2,-2,minecraft:stone)
B(4,2,-1,minecraft:stone)
B(4,2,0,minecraft:stone)
B(4,2,1,minecraft:stone)
B(4,2,2,minecraft:stone)
B(4,2,3,minecraft:stone)
B(4,2,4,minecraft:stone)
B(4,2,5,minecraft:stone)
B(4,2,6,minecraft:stone)
B(4,2,7,minecraft:stone)
B(4,2,8,minecraft:stone)
B(4,3,-7,minecraft:stone)
B(4,3,-6,minecraft:stone)
B(4,3,-5,minecraft:stone)
B(4,3,-4,minecraft:stone)
B(4,3,-3,minecraft:stone)
B(4,3,-2,minecraft:stone)
B(4,3,-1,minecraft:stone)
B(4,3,0,minecraft:stone)
B(4,3,1,minecraft:stone)
B(4,3,2,minecraft:stone)
B(4,3,3,minecraft:stone)
B(4,3,4,minecraft:stone)
B(4,3,5,minecraft:stone)
B(4,3,6,minecraft:stone)
B(4,3,7,minecraft:stone)
B(4,3,8,minecraft:stone)
B(4,4,-7,minecraft:stone)
B(4,4,-6,minecraft:stone)
B(4,4,-5,minecraft:stone)
B(4,4,-4,minecraft:stone)
B(4,4,-3,minecraft:stone)
B(4,4,-2,minecraft:stone)
B(4,4,-1,minecraft:stone)
B(4,4,0,minecraft:stone)
B(4,4,1,minecraft:stone)
B(4,4,2,minecraft:stone)
B(4,4,3,minecraft:stone)
B(4,4,4,minecraft:stone)
B(4,4,5,minecraft:stone)
B(4,4,6,minecraft:stone)
B(4,4,7,minecraft:stone)
B(4,4,8,minecraft:stone)
B(4,5,-7,minecraft:stone)
B(4,5,-6,minecraft:stone)
B(4,5,-5,minecraft:stone)
B(4,5,-4,minecraft:stone)
B(4,5,-3,minecraft:stone)
B(4,5,-2,minecraft:stone)
B(4,5,-1,minecraft:stone)
B(4,5,0,minecraft:stone)
B(4,5,1,minecraft:stone)
B(4,5,2,minecraft:stone)
B(4,5,3,minecraft:stone)
B(4,5,4,minecraft:stone)
B(4,5,5,minecraft:stone)
B(4,5,6,minecraft:stone)
B(4,5,7,minecraft:stone)
B(4,5,8,minecraft:stone)
B(4,6,-7,minecraft:stone)
B(4,6,-6,minecraft:stone)
B(4,6,-5,minecraft:stone)
B(4,6,-4,minecraft:stone)
B(4,6,-3,minecraft:stone)
B(4,6,-2,minecraft:stone)
B(4,6,-1,minecraft:stone)
B(4,6,0,minecraft:stone)
B(4,6,1,minecraft:stone)
B(4,6,2,minecraft:stone)
B(4,6,3,minecraft:stone)
B(4,6,4,minecraft:stone)
B(4,6,5,minecraft:stone)
B(4,6,6,minecraft:stone)
B(4,6,7,minecraft:stone)
B(4,6,8,minecraft:stone)
B(4,7,-7,minecraft:stone)
B(4,7,-6,minecraft:stone)
B(4,7,-5,minecraft:stone)
B(4,7,-4,minecraft:stone)
B(4,7,-3,minecraft:stone)
B(4,7,-2,minecraft:stone)
B(4,7,-1,minecraft:stone)
B(4,7,0,minecraft:stone)
B(4,7,1,minecraft:stone)
B(4,7,2,minecraft:stone)
B(4,7,3,minecraft:stone)
B(4,7,4,minecraft:stone)
B(4,7,5,minecraft:stone)
B(4,7,6,minecraft:stone)
B(4,7,7,minecraft:stone)
B(4,7,8,minecraft:stone)
B(4,8,-7,minecraft:stone)
B(4,8,-6,minecraft:stone)
B(4,8,-5,minecraft:stone)
B(4,8,-4,minecraft:stone)
B(4,8,-3,minecraft:stone)
B(4,8,-2,minecraft:stone)
B(4,8,-1,minecraft:stone)
B(4,8,0,minecraft:stone)
B(4,8,1,minecraft:stone)
B(4,8,2,minecraft:stone)
B(4,8,3,minecraft:stone)
B(4,8,4,minecraft:stone)
B(4,8,5,minecraft:stone)
B(4,8,6,minecraft:stone)
B(4,8,7,minecraft:stone)
B(4,8,8,minecraft:stone)
B(5,0,-7,minecraft:stone)
B(5,0,-6,minecraft:stone)
B(5,0,-5,minecraft:stone)
B(5,0,-4,minecraft:stone)
B(5,0,-3,minecraft:stone)
B(5,0,-2,minecraft:stone)
B(5,0,-1,minecraft:stone)
B(5,0,0,minecraft:stone)
B(5,0,1,minecraft:stone)
B(5,0,2,minecraft:stone)
B(5,0,3,minecraft:stone)
B(5,0,4,minecraft:stone)
B(5,0,5,minecraft:stone)
B(5,0,6,minecraft:stone)
B(5,0,7,minecraft:stone)
B(5,0,8,minecraft:stone)
B(5,1,-7,minecraft:stone)
B(5,1,-6,minecraft:stone)
B(5,1,-5,minecraft:stone)
B(5,1,-4,minecraft:stone)
B(5,1,-3,minecraft:stone)
B(5,1,-2,minecraft:stone)
B(5,1,-1,minecraft:stone)
B(5,1,0,minecraft:stone)
B(5,1,1,minecraft:stone)
B(5,1,2,minecraft:stone)
B(5,1,3,minecraft:stone)
B(5,1,4,minecraft:stone)
B(5,1,5,minecraft:stone)
B(5,1,6,minecraft:stone)
B(5,1,7,minecraft:stone)
B(5,1,8,minecraft:stone)
B(5,2,-7,minecraft:stone)
B(5,2,-6,minecraft:stone)
B(5,2,-5,minecraft:stone)
B(5,2,-4,minecraft:stone)
B(5,2,-3,minecraft:stone)
B(5,2,-2,minecraft:stone)
B(5,2,-1,minecraft:stone)
B(5,2,0,minecraft:stone)
B(5,2,1,minecraft:stone)
B(5,2,2,minecraft:stone)
B(5,2,3,minecraft:stone)
B(5,2,4,minecraft:stone)
B(5,2,5,minecraft:stone)
B(5,2,6,minecraft:stone)
B(5,2,7,minecraft:stone)
B(5,2,8,minecraft:stone)
B(5,3,-7,minecraft:stone)
B(5,3,-6,minecraft:stone)
B(5,3,-5,minecraft:stone)
B(5,3,-4,minecraft:stone)
B(5,3,-3,minecraft:stone)
B(5,3,-2,minecraft:stone)
B(5,3,-1,minecraft:stone)
B(5,3,0,minecraft:stone)
B(5,3,1,minecraft:stone)
B(5,3,2,minecraft:stone)
B(5,3,3,minecraft:stone)
B(5,3,4,minecraft:stone)
B(5,3,5,minecraft:stone)
B(5,3,6,minecraft:stone)
B(5,3,7,minecraft:stone)
B(5,3,8,minecraft:stone)
B(5,4,-7,minecraft:stone)
B(5,4,-6,minecraft:stone)
B(5,4,-5,minecraft:stone)
B(5,4,-4,minecraft:stone)
B(5,4,-3,minecraft:stone)
B(5,4,-2,minecraft:stone)
B(5,4,-1,minecraft:stone)
B(5,4,0,minecraft:stone)
B(5,4,1,minecraft:stone)
B(5,4,2,minecraft:stone)
B(5,4,3,minecraft:stone)
B(5,4,4,minecraft:stone)
B(5,4,5,minecraft:stone)
B(5,4,6,minecraft:stone)
B(5,4,7,minecraft:stone)
B(5,4,8,minecraft:stone)
B(5,5,-7,minecraft:stone)
B(5,5,-6,minecraft:stone)
B(5,5,-5,minecraft:stone)
B(5,5,-4,minecraft:stone)
B(5,5,-3,minecraft:stone)
B(5,5,-2,minecraft:stone)
B(5,5,-1,minecraft:stone)
B(5,5,0,minecraft:stone)
B(5,5,1,minecraft:stone)
B(5,5,2,minecraft:stone)
B(5,5,3,minecraft:stone)
B(5,5,4,minecraft:stone)
B(5,5,5,minecraft:stone)
B(5,5,6,minecraft:stone)
B(5,5,7,minecraft:stone)
B(5,5,8,minecraft:stone)
B(5,6,-7,minecraft:stone)
B(5,6,-6,minecraft:stone)
B(5,6,-5,minecraft:stone)
B(5,6,-4,minecraft:stone)
B(5,6,-3,minecraft:stone)
B(5,6,-2,minecraft:stone)
B(5,6,-1,minecraft:stone)
B(5,6,0,minecraft:stone)
B(5,6,1,minecraft:stone)
B(5,6,2,minecraft:stone)
B(5,6,3,minecraft:stone)
B(5,6,4,minecraft:stone)
B(5,6,5,minecraft:stone)
B(5,6,6,minecraft:stone)
B(5,6,7,minecraft:stone)
B(5,6,8,minecraft:stone)
B(5,7,-7,minecraft:stone)
B(5,7,-6,minecraft:stone)
B(5,7,-5,minecraft:stone)
B(5,7,-4,minecraft:stone)
B(5,7,-3,minecraft:stone)
B(5,7,-2,minecraft:stone)
B(5,7,-1,minecraft:stone)
B(5,7,0,minecraft:stone)
B(5,7,1,minecraft:stone)
B(5,7,2,minecraft:stone)
B(5,7,3,minecraft:stone)
B(5,7,4,minecraft:stone)
B(5,7,5,minecraft:stone)
B(5,7,6,minecraft:stone)
B(5,7,7,minecraft:stone)
B(5,7,8,minecraft:stone)
B(5,8,-7,minecraft:stone)
B(5,8,-6,minecraft:stone)
B(5,8,-5,minecraft:stone)
B(5,8,-4,minecraft:stone)
B(5,8,-3,minecraft:stone)
B(5,8,-2,minecraft:stone)
B(5,8,-1,minecraft:stone)
B(5,8,0,minecraft:stone)
B(5,8,1,minecraft:stone)
B(5,8,2,minecraft:stone)
B(5,8,3,minecraft:stone)
B(5,8,4,minecraft:stone)
B(5,8,5,minecraft:stone)
B(5,8,6,minecraft:stone)
B(5,8,7,minecraft:stone)
B(5,8,8,minecraft:stone)
B(6,0,-7,minecraft:stone)
B(6,0,-6,minecraft:stone)
B(6,0,-5,minecraft:stone)
B(6,0,-4,minecraft:stone)
B(6,0,-3,minecraft:stone)
B(6,0,-2,minecraft:stone)
B(6,0,-1,minecraft:stone)
B(6,0,0,minecraft:stone)
B(6,0,1,minecraft:stone)
B(6,0,2,minecraft:stone)
B(6,0,3,minecraft:stone)
B(6,0,4,minecraft:stone)
B(6,0,5,minecraft:stone)
B(6,0,6,minecraft:stone)
B(6,0,7,minecraft:stone)
B(6,0,8,minecraft:stone)
B(6,1,-7,minecraft:stone)
B(6,1,-6,minecraft:stone)
B(6,1,-5,minecraft:stone)
B(6,1,-4,minecraft:stone)
B(6,1,-3,minecraft:stone)
B(6,1,-2,minecraft:stone)
B(6,1,-1,minecraft:stone)
B(6,1,0,minecraft:stone)
B(6,1,1,minecraft:stone)
B(6,1,2,minecraft:stone)
B(6,1,3,minecraft:stone)
B(6,1,4,minecraft:stone)
B(6,1,5,minecraft:stone)
B(6,1,6,minecraft:stone)
B(6,1,7,minecraft:stone)
B(6,1,8,minecraft:stone)
B(6,2,-7,minecraft:stone)
B(6,2,-6,minecraft:stone)
B(6,2,-5,minecraft:stone)
B(6,2,-4,minecraft:stone)
B(6,2,-3,minecraft:stone)
B(6,2,-2,minecraft:stone)
B(6,2,-1,minecraft:stone)
B(6,2,0,minecraft:stone)
B(6,2,1,minecraft:stone)
B(6,2,2,minecraft:stone)
B(6,2,3,minecraft:stone)
B(6,2,4,minecraft:stone)
B(6,2,5,minecraft:stone)
B(6,2,6,minecraft:stone)
B(6,2,7,minecraft:stone)
B(6,2,8,minecraft:stone)
B(6,3,-7,minecraft:stone)
B(6,3,-6,minecraft:stone)
B(6,3,-5,minecraft:stone)
B(6,3,-4,minecraft:stone)
B(6,3,-3,minecraft:stone)
B(6,3,-2,minecraft:stone)
B(6,3,-1,minecraft:stone)
B(6,3,0,minecraft:stone)
B(6,3,1,minecraft:stone)
B(6,3,2,minecraft:stone)
B(6,3,3,minecraft:stone)
B(6,3,4,minecraft:stone)
B(6,3,5,minecraft:stone)
B(6,3,6,minecraft:stone)
B(6,3,7,minecraft:stone)
B(6,3,8,minecraft:stone)
B(6,4,-7,minecraft:stone)
B(6,4,-6,minecraft:stone)
B(6,4,-5,minecraft:stone)
B(6,4,-4,minecraft:stone)
B(6,4,-3,minecraft:stone)
B(6,4,-2,minecraft:stone)
B(6,4,-1,minecraft:stone)
B(6,4,0,minecraft:stone)
B(6,4,1,minecraft:stone)
B(6,4,2,minecraft:stone)
B(6,4,3,minecraft:stone)
B(6,4,4,minecraft:stone)
B(6,4,5,minecraft:stone)
B(6,4,6,minecraft:stone)
B(6,4,7,minecraft:stone)
B(6,4,8,minecraft:stone)
B(6,5,-7,minecraft:stone)
B(6,5,-6,minecraft:stone)
B(6,5,-5,minecraft:stone)
B(6,5,-4,minecraft:stone)
B(6,5,-3,minecraft:stone)
B(6,5,-2,minecraft:stone)
B(6,5,-1,minecraft:stone)
B(6,5,0,minecraft:stone)
B(6,5,1,minecraft:stone)
B(6,5,2,minecraft:stone)
B(6,5,3,minecraft:stone)
B(6,5,4,minecraft:stone)
B(6,5,5,minecraft:stone)
B(6,5,6,minecraft:stone)
B(6,5,7,minecraft:stone)
B(6,5,8,minecraft:stone)
B(6,6,-7,minecraft:stone)
B(6,6,-6,minecraft:stone)
B(6,6,-5,minecraft:stone)
B(6,6,-4,minecraft:stone)
B(6,6,-3,minecraft:stone)
B(6,6,-2,minecraft:stone)
B(6,6,-1,minecraft:stone)
B(6,6,0,minecraft:stone)
B(6,6,1,minecraft:stone)
B(6,6,2,minecraft:stone)
B(6,6,3,minecraft:stone)
B(6,6,4,minecraft:stone)
B(6,6,5,minecraft:stone)
B(6,6,6,minecraft:stone)
B(6,6,7,minecraft:stone)
B(6,6,8,minecraft:stone)
B(6,7,-7,minecraft:stone)
B(6,7,-6,minecraft:stone)
B(6,7,-5,minecraft:stone)
B(6,7,-4,minecraft:stone)
B(6,7,-3,minecraft:stone)
B(6,7,-2,minecraft:stone)
B(6,7,-1,minecraft:stone)
B(6,7,0,minecraft:stone)
B(6,7,1,minecraft:stone)
B(6,7,2,minecraft:stone)
B(6,7,3,minecraft:stone)
B(6,7,4,minecraft:stone)
B(6,7,5,minecraft:stone)
B(6,7,6,minecraft:stone)
B(6,7,7,minecraft:stone)
B(6,7,8,minecraft:stone)
B(6,8,-7,minecraft:stone)
B(6,8,-6,minecraft:stone)
B(6,8,-5,minecraft:stone)
B(6,8,-4,minecraft:stone)
B(6,8,-3,minecraft:stone)
B(6,8,-2,minecraft:stone)
B(6,8,-1,minecraft:stone)
B(6,8,0,minecraft:stone)
B(6,8,1,minecraft:stone)
B(6,8,2,minecraft:stone)
B(6,8,3,minecraft:stone)
B(6,8,4,minecraft:stone)
B(6,8,5,minecraft:stone)
B(6,8,6,minecraft:stone)
B(6,8,7,minecraft:stone)
B(6,8,8,minecraft:stone)
B(7,0,-7,minecraft:stone)
B(7,0,-6,minecraft:stone)
B(7,0,-5,minecraft:stone)
B(7,0,-4,minecraft:stone)
B(7,0,-3,minecraft:stone)
B(7,0,-2,minecraft:stone)
B(7,0,-1,minecraft:stone)
B(7,0,0,minecraft:stone)
B(7,0,1,minecraft:stone)
B(7,0,2,minecraft:stone)
B(7,0,3,minecraft:stone)
B(7,0,4,minecraft:stone)
B(7,0,5,minecraft:stone)
B(7,0,6,minecraft:stone)
B(7,0,7,minecraft:stone)
B(7,0,8,minecraft:stone)
B(7,1,-7,minecraft:stone)
B(7,1,-6,minecraft:stone)
B(7,1,-5,minecraft:stone)
B(7,1,-4,minecraft:stone)
B(7,1,-3,minecraft:stone)
B(7,1,-2,minecraft:stone)
B(7,1,-1,minecraft:stone)
B(7,1,0,minecraft:stone)
B(7,1,1,minecraft:stone)
B(7,1,2,minecraft:stone)
B(7,1,3,minecraft:stone)
B(7,1,4,minecraft:stone)
B(7,1,5,minecraft:stone)
B(7,1,6,minecraft:stone)
B(7,1,7,minecraft:stone)
B(7,1,8,minecraft:stone)
B(7,2,-7,minecraft:stone)
B(7,2,-6,minecraft:stone)
B(7,2,-5,minecraft:stone)
B(7,2,-4,minecraft:stone)
B(7,2,-3,minecraft:stone)
B(7,2,-2,minecraft:stone)
B(7,2,-1,minecraft:stone)
B(7,2,0,minecraft:stone)
B(7,2,1,minecraft:stone)
B(7,2,2,minecraft:stone)
B(7,2,3,minecraft:stone)
B(7,2,4,minecraft:stone)
B(7,2,5,minecraft:stone)
B(7,2,6,minecraft:stone)
B(7,2,7,minecraft:stone)
B(7,2,8,minecraft:stone)
B(7,3,-7,minecraft:stone)
B(7,3,-6,minecraft:stone)
B(7,3,-5,minecraft:stone)
B(7,3,-4,minecraft:stone)
B(7,3,-3,minecraft:stone)
B(7,3,-2,minecraft:stone)
B(7,3,-1,minecraft:stone)
B(7,3,0,minecraft:stone)
B(7,3,1,minecraft:stone)
B(7,3,2,minecraft:stone)
B(7,3,3,minecraft:stone)
B(7,3,4,minecraft:stone)
B(7,3,5,minecraft:stone)
B(7,3,6,minecraft:stone)
B(7,3,7,minecraft:stone)
B(7,3,8,minecraft:stone)
B(7,4,-7,minecraft:stone)
B(7,4,-6,minecraft:stone)
B(7,4,-5,minecraft:stone)
B(7,4,-4,minecraft:stone)
B(7,4,-3,minecraft:stone)
B(7,4,-2,minecraft:stone)
B(7,4,-1,minecraft:stone)
B(7,4,0,minecraft:stone)
B(7,4,1,minecraft:stone)
B(7,4,2,minecraft:stone)
B(7,4,3,minecraft:stone)
B(7,4,4,minecraft:stone)
B(7,4,5,minecraft:stone)
B(7,4,6,minecraft:stone)
B(7,4,7,minecraft:stone)
B(7,4,8,minecraft:stone)
B(7,5,-7,minecraft:stone)
B(7,5,-6,minecraft:stone)
B(7,5,-5,minecraft:stone)
B(7,5,-4,minecraft:stone)
B(7,5,-3,minecraft:stone)
B(7,5,-2,minecraft:stone)
B(7,5,-1,minecraft:stone)
B(7,5,0,minecraft:stone)
B(7,5,1,minecraft:stone)
B(7,5,2,minecraft:stone)
B(7,5,3,minecraft:stone)
B(7,5,4,minecraft:stone)
B(7,5,5,minecraft:stone)
B(7,5,6,minecraft:stone)
B(7,5,7,minecraft:stone)
B(7,5,8,minecraft:stone)
B(7,6,-7,minecraft:stone)
B(7,6,-6,minecraft:stone)
B(7,6,-5,minecraft:stone)
B(7,6,-4,minecraft:stone)
B(7,6,-3,minecraft:stone)
B(7,6,-2,minecraft:stone)
B(7,6,-1,minecraft:stone)
B(7,6,0,minecraft:stone)
B(7,6,1,minecraft:stone)
B(7,6,2,minecraft:stone)
B(7,6,3,minecraft:stone)
B(7,6,4,minecraft:stone)
B(7,6,5,minecraft:stone)
B(7,6,6,minecraft:stone)
B(7,6,7,minecraft:stone)
B(7,6,8,minecraft:stone)
B(7,7,-7,minecraft:stone)
B(7,7,-6,minecraft:stone)
B(7,7,-5,minecraft:stone)
B(7,7,-4,minecraft:stone)
B(7,7,-3,minecraft:stone)
B(7,7,-2,minecraft:stone)
B(7,7,-1,minecraft:stone)
B(7,7,0,minecraft:stone)
B(7,7,1,minecraft:stone)
B(7,7,2,minecraft:stone)
B(7,7,3,minecraft:stone)
B(7,7,4,minecraft:stone)
B(7,7,5,minecraft:stone)
B(7,7,6,minecraft:stone)
B(7,7,7,minecraft:stone)
B(7,7,8,minecraft:stone)
B(7,8,-7,minecraft:stone)
B(7,8,-6,minecraft:stone)
B(7,8,-5,minecraft:stone)
B(7,8,-4,minecraft:stone)
B(7,8,-3,minecraft:stone)
B(7,8,-2,minecraft:stone)
B(7,8,-1,minecraft:stone)
B(7,8,0,minecraft:stone)
B(7,8,1,minecraft:stone)
B(7,8,2,minecraft:stone)
B(7,8,3,minecraft:stone)
B(7,8,4,minecraft:stone)
B(7,8,5,minecraft:stone)
B(7,8,6,minecraft:stone)
B(7,8,7,minecraft:stone)
B(7,8,8,minecraft:stone)

#######################################################################
# +-----------------------------------------------------------------+ #
# |                             Branches                            | #
# +-----------------------------------------------------------------+ #
#######################################################################

# Branches are child-BO4's that spawn if this BO4 is configured to spawn as a
# CustomStructure resource in a biome config. Branches can have branches,
# making complex structures possible. See the wiki for more details.

# Regular Branches spawn each branch with an independent chance of spawning.
# Branch(x,y,z,isRequiredBranch,branchName,rotation,chance,branchDepth[,anotherBranchName,rotation,chance,branchDepth[,...]][IndividualChance])
# branchName - name of the object to spawn.
# rotation - NORTH, SOUTH, EAST or WEST.
# IndividualChance - The chance each branch has to spawn, assumed to be 100 when left blank
# isRequiredBranch - If this is set to true then at least one of the branches in this BO4 must spawn at these x,y,z coordinates. If no branch can spawn there then this BO4 fails to spawn and its branch is rolled back.
# isRequiredBranch:true branches must spawn or the current branch is rolled back entirely. This is useful for grouping BO4's that must spawn together, for instance a single room made of multiple BO4's/branches.
# If all parts of the room are connected together via isRequiredBranch:true branches then either the entire room will spawns or no part of it will spawn.
# *Note: When isRequiredBranch:true only one BO4 can be added per Branch() and it will automatically have a rarity of 100.0.
# isRequiredBranch:false branches are used to make optional parts of structures, for instance the middle section of a tunnel that has a beginning, middle and end BO4/branch and can have a variable length by repeating the middle BO4/branch.
# By making the start and end branches isRequiredBranch:true and the middle branch isRequiredbranch:false you can make it so that either:
# A. A tunnel spawns with at least a beginning and end branch
# B. A tunnel spawns with a beginning and end branch and as many middle branches as will fit in the available space.
# C. No tunnel spawns at all because there wasn't enough space to spawn at least a beginning and end branch.
# branchDepth - When creating a chain of branches that contains optional (isRequiredBranch:false) branches branch depth is configured for the first BO4 in the chain to determine the maximum length of the chain.
# branchDepth - 1 is inherited by each isRequiredBranch:false branch in the chain. When branchDepth is zero isRequiredBranch:false branches cannot spawn and the chain ends. In the case of the tunnel this means the last middle branch would be
# rolled back and an IsRequiredBranch:true end branch could be spawned in its place to make sure the tunnel has a proper ending.
# Instead of inheriting branchDepth - 1 from the parent branchDepth can be overridden by child branches if it is set higher than 0 (the default value).
# isRequiredBranch:true branches do inherit branchDepth and pass it on to their own branches, however they cannot be prevented from spawning by it and also don't subtract 1 from branchDepth when inheriting it.

# Weighted Branches spawn branches with a dependent chance of spawning.
# WeightedBranch(x,y,z,isRequiredBranch,branchName,rotation,chance,branchDepth[,anotherBranchName,rotation,chance,branchDepth[,...]][MaxChanceOutOf])
# *Note: isRequiredBranch must be set to false. It is not possible to use isRequiredBranch:true with WeightedBranch() since isRequired:true branches must spawn and automatically have a rarity of 100.0.
# MaxChanceOutOf - The chance all branches have to spawn out of, assumed to be 100 when left blank

#######################################################################
# +-----------------------------------------------------------------+ #
# |                             Entities                            | #
# +-----------------------------------------------------------------+ #
#######################################################################

# Forge only (this may have changed, check for updates).
# An EntityFunction spawns an entity instead of a block. The entity is spawned only once when the BO4 is spawned.
# Entities are persistent by default so they don't de-spawn when no player is near, they are only unloaded.
# Usage: Entity(x,y,z,entityName,groupSize,NameTagOrNBTFileName) or Entity(x,y,z,mobName,groupSize)
# Use /otg entities to get a list of entities that can be used as entityName, this includes entities added by other mods and non-living entities.
# NameTagOrNBTFileName can be either a nametag for the mob or an .txt file with nbt data (such as myentityinfo.txt).
# In the text file you can use the same mob spawning parameters used with the /summon command to equip the
# entity and give it custom attributes etc. You can copy the DATA part of a summon command including surrounding 
# curly braces to a .txt file, for instance for: "/summon Skeleton x y z {DATA}"
