
#######################################################################
# +-----------------------------------------------------------------+ #
# |                            BO3 object                           | #
# +-----------------------------------------------------------------+ #
#######################################################################

# This is the config file of a custom object.
# If you add this object correctly to your BiomeConfigs, it will spawn in the world.

# This is the creator of this BO3 object
Author: Zeddgrayhem

# A short description of this BO3 object
Description: No description given

# The BO3 version, don't change this! It can be used by external applications to do a version check.
Version: 3

# The settings mode, WriteAll, WriteWithoutComments or WriteDisable. See WorldConfig.
SettingsMode: WriteAll


#######################################################################
# +-----------------------------------------------------------------+ #
# |                          Main settings                          | #
# +-----------------------------------------------------------------+ #
#######################################################################

# This needs to be set to true to spawn the object in the Tree and Sapling resources.
Tree: true

# The frequency of the BO3 from 1 to 200. Tries this many times to spawn this BO3 when using the CustomObject(...) resource.
# Ignored by Tree(..), Sapling(..) and CustomStructure(..)
Frequency: 0

# The rarity of the BO3 from 0 to 100. Each spawn attempt has rarity% chance to succeed when using the CustomObject(...) resource.
# Ignored by Tree(..), Sapling(..) and CustomStructure(..)
Rarity: 100.0

# When using Frequency, after this many succesfull spawn attempts, abort spawning.
# For example, you can set 100 spawn attempts using Frequency, but stop spawning after 5 successfull spawns via MaxSpawn.
# 0 by default, which means ignore this setting.
# Ignored by Tree(..), Sapling(..) and CustomStructure(..)
MaxSpawn: 0

# If you set this to true, the BO3 will be placed with a random rotation.
RotateRandomly: true

# The spawn height of the BO3: randomY, highestBlock or highestSolidBlock.
SpawnHeight: randomY

# The offset from the spawn height to spawn this BO3
# Ex. SpawnHeight = highestSolidBlock, SpawnHeightOffset = 3; This object will spawn 3 blocks above the highest solid block
SpawnHeightOffset: 0

# A random amount to offset the spawn location from the spawn offset height
# Ex. SpawnHeightOffset = 3, SpawnHeightVariance = 3; This object will spawn 3 to 6 blocks above the original spot it would have spawned
SpawnHeightVariance: 0

##############################
# Height Limits for the BO3. #
##############################

# When in randomY mode used as the minimum Y or in atMinY mode as the actual Y to spawn this BO3 at.
MinHeight: 0

# When in randomY mode used as the maximum Y to spawn this BO3 at.
MaxHeight: 255

######################
# Extrusion settings #
######################

# The style of extrusion you wish to use - BottomDown, TopUp, None (Default)
ExtrudeMode: None

# The blocks to extrude your BO3 through
ExtrudeThroughBlocks: minecraft:air

# Objects can have other objects attacthed to it: branches. Branches can also
# have branches attached to it, which can also have branches, etc. This is the
# maximum branch depth for this objects.
MaxBranchDepth: 10


#######################################################################
# +-----------------------------------------------------------------+ #
# |                      Source block settings                      | #
# +-----------------------------------------------------------------+ #
#######################################################################

# The block(s) the BO3 should spawn in.
SourceBlocks: minecraft:air,minecraft:grass_block,minecraft:stone,minecraft:dirt

# The maximum percentage of the BO3 that can be outside the SourceBlock.
# The BO3 won't be placed on a location with more blocks outside the SourceBlock than this percentage.
MaxPercentageOutsideSourceBlock: 30

# What to do when a block is about to be placed outside the SourceBlock? (dontPlace, placeAnyway)
OutsideSourceBlock: placeAnyway

# Disable doReplaceBlocks to make this BO3 ignore any ReplacedBlocks settings in biome configs, improves performance.
DoReplaceBlocks: true

# OTG+ settings #
# Legacy setting, rename this file to .BO4 instead. Set this to true to enable the advanced customstructure features of OTG+.
IsOTGPlus: false


#######################################################################
# +-----------------------------------------------------------------+ #
# |                              Blocks                             | #
# +-----------------------------------------------------------------+ #
#######################################################################

# All the blocks used in the BO3 are listed here. Possible blocks:
# Block(x,y,z,id[.data][,nbtfile.nbt)
# RandomBlock(x,y,z,id[:data][,nbtfile.nbt],chance[,id[:data][,nbtfile.nbt],chance[,...]])
#  So RandomBlock(0,0,0,CHEST,chest.nbt,50,CHEST,anotherchest.nbt,100) will spawn a chest at
#  the BO3 origin, and give it a 50% chance to have the contents of chest.nbt, or, if that
#  fails, a 100% percent chance to have the contents of anotherchest.nbt.
# *Note: Unlike Entity() and Spawner(), for Block() .txt files don't work, only .nbt files work.
# MinecraftObject(x,y,z,name) (TODO: This may not work anymore and needs to be tested.
#  Spawns an object in the Mojang NBT structure format. For example, 
#  MinecraftObject(0,0,0,minecraft:igloo/igloo_bottom)
#  spawns the bottom part of an igloo.
B(-6,3,1,minecraft:stone)
B(-6,4,0,minecraft:cobblestone)
B(-6,4,1,minecraft:cobblestone)
B(-6,5,0,minecraft:cobblestone)
B(-6,5,1,minecraft:stone)
B(-6,5,2,minecraft:stone)
B(-6,6,-1,minecraft:cobblestone)
B(-6,6,0,minecraft:cobblestone)
B(-6,6,1,minecraft:stone)
B(-6,6,2,minecraft:obsidian)
B(-6,7,-1,minecraft:coal_ore)
B(-6,7,0,minecraft:cobblestone)
B(-6,7,1,minecraft:cobblestone)
B(-5,2,0,minecraft:cobblestone)
B(-5,2,1,minecraft:cobblestone)
B(-5,2,2,minecraft:stone)
B(-5,3,-1,minecraft:stone)
B(-5,3,0,minecraft:stone)
B(-5,3,1,minecraft:cobblestone)
B(-5,3,2,minecraft:stone)
B(-5,4,-2,minecraft:stone)
B(-5,4,-1,minecraft:stone)
B(-5,4,0,minecraft:stone)
B(-5,4,1,minecraft:cobblestone)
B(-5,4,2,minecraft:cobblestone)
B(-5,4,3,minecraft:obsidian)
B(-5,4,4,minecraft:stone)
B(-5,5,-2,minecraft:cobblestone)
B(-5,5,-1,minecraft:obsidian)
B(-5,5,0,minecraft:cobblestone)
B(-5,5,1,minecraft:lava)
B(-5,5,2,minecraft:stone)
B(-5,5,3,minecraft:obsidian)
B(-5,5,4,minecraft:stone)
B(-5,6,-3,minecraft:cobblestone)
B(-5,6,-2,minecraft:cobblestone)
B(-5,6,-1,minecraft:obsidian)
B(-5,6,0,minecraft:lava)
B(-5,6,1,minecraft:stone)
B(-5,6,2,minecraft:obsidian)
B(-5,6,3,minecraft:obsidian)
B(-5,7,-3,minecraft:coal_ore)
B(-5,7,-2,minecraft:cobblestone)
B(-5,7,-1,minecraft:obsidian)
B(-5,7,0,minecraft:stone)
B(-5,7,1,minecraft:stone)
B(-5,7,2,minecraft:obsidian)
B(-5,7,3,minecraft:obsidian)
B(-5,8,-2,minecraft:cobblestone)
B(-5,8,-1,minecraft:cobblestone)
B(-5,8,0,minecraft:cobblestone)
B(-5,8,1,minecraft:obsidian)
B(-5,8,2,minecraft:obsidian)
B(-5,8,3,minecraft:obsidian)
B(-5,9,1,minecraft:coal_ore)
B(-5,9,2,minecraft:cobblestone)
B(-5,10,2,minecraft:obsidian)
B(-4,2,-3,minecraft:obsidian)
B(-4,2,1,minecraft:stone)
B(-4,2,2,minecraft:stone)
B(-4,2,3,minecraft:stone)
B(-4,3,-3,minecraft:cobblestone)
B(-4,3,-2,minecraft:obsidian)
B(-4,3,-1,minecraft:stone)
B(-4,3,0,minecraft:stone)
B(-4,3,1,minecraft:obsidian)
B(-4,3,2,minecraft:stone)
B(-4,3,3,minecraft:stone)
B(-4,3,4,minecraft:stone)
B(-4,4,-3,minecraft:cobblestone)
B(-4,4,-2,minecraft:obsidian)
B(-4,4,-1,minecraft:stone)
B(-4,4,0,minecraft:obsidian)
B(-4,4,1,minecraft:obsidian)
B(-4,4,2,minecraft:lava)
B(-4,4,3,minecraft:obsidian)
B(-4,4,4,minecraft:cobblestone)
B(-4,4,5,minecraft:obsidian)
B(-4,5,-4,minecraft:obsidian)
B(-4,5,-3,minecraft:obsidian)
B(-4,5,-2,minecraft:stone)
B(-4,5,-1,minecraft:stone)
B(-4,5,0,minecraft:obsidian)
B(-4,5,1,minecraft:obsidian)
B(-4,5,2,minecraft:lava)
B(-4,5,3,minecraft:lava)
B(-4,5,4,minecraft:cobblestone)
B(-4,5,5,minecraft:obsidian)
B(-4,6,-5,minecraft:stone)
B(-4,6,-4,minecraft:stone)
B(-4,6,-3,minecraft:obsidian)
B(-4,6,-2,minecraft:lava)
B(-4,6,-1,minecraft:lava)
B(-4,6,0,minecraft:stone)
B(-4,6,1,minecraft:lava)
B(-4,6,2,minecraft:lava)
B(-4,6,3,minecraft:stone)
B(-4,6,4,minecraft:stone)
B(-4,7,-4,minecraft:cobblestone)
B(-4,7,-3,minecraft:stone)
B(-4,7,-2,minecraft:obsidian)
B(-4,7,-1,minecraft:stone)
B(-4,7,0,minecraft:stone)
B(-4,7,1,minecraft:stone)
B(-4,7,2,minecraft:stone)
B(-4,7,3,minecraft:stone)
B(-4,7,4,minecraft:obsidian)
B(-4,8,-4,minecraft:cobblestone)
B(-4,8,-3,minecraft:coal_ore)
B(-4,8,-2,minecraft:cobblestone)
B(-4,8,-1,minecraft:stone)
B(-4,8,0,minecraft:cobblestone)
B(-4,8,1,minecraft:obsidian)
B(-4,8,2,minecraft:obsidian)
B(-4,8,3,minecraft:cobblestone)
B(-4,8,4,minecraft:obsidian)
B(-4,9,-3,minecraft:coal_ore)
B(-4,9,-2,minecraft:cobblestone)
B(-4,9,-1,minecraft:stone)
B(-4,9,0,minecraft:cobblestone)
B(-4,9,1,minecraft:obsidian)
B(-4,9,2,minecraft:cobblestone)
B(-4,9,3,minecraft:obsidian)
B(-4,10,-1,minecraft:coal_ore)
B(-4,10,0,minecraft:coal_ore)
B(-4,10,1,minecraft:coal_ore)
B(-4,10,2,minecraft:obsidian)
B(-4,10,3,minecraft:obsidian)
B(-3,1,-2,minecraft:obsidian)
B(-3,1,0,minecraft:andesite)
B(-3,1,1,minecraft:stone)
B(-3,2,-4,minecraft:stone)
B(-3,2,-3,minecraft:stone)
B(-3,2,-2,minecraft:obsidian)
B(-3,2,-1,minecraft:stone)
B(-3,2,0,minecraft:stone)
B(-3,2,1,minecraft:stone)
B(-3,2,2,minecraft:stone)
B(-3,2,3,minecraft:stone)
B(-3,3,-4,minecraft:cobblestone)
B(-3,3,-3,minecraft:andesite)
B(-3,3,-2,minecraft:obsidian)
B(-3,3,-1,minecraft:lava)
B(-3,3,0,minecraft:stone)
B(-3,3,1,minecraft:andesite)
B(-3,3,2,minecraft:lava)
B(-3,3,3,minecraft:stone)
B(-3,3,4,minecraft:stone)
B(-3,3,5,minecraft:obsidian)
B(-3,4,-5,minecraft:cobblestone)
B(-3,4,-4,minecraft:cobblestone)
B(-3,4,-3,minecraft:cobblestone)
B(-3,4,-2,minecraft:obsidian)
B(-3,4,-1,minecraft:lava)
B(-3,4,0,minecraft:lava)
B(-3,4,1,minecraft:obsidian)
B(-3,4,2,minecraft:lava)
B(-3,4,3,minecraft:lava)
B(-3,4,4,minecraft:cobblestone)
B(-3,4,5,minecraft:obsidian)
B(-3,5,-5,minecraft:obsidian)
B(-3,5,-4,minecraft:obsidian)
B(-3,5,-3,minecraft:obsidian)
B(-3,5,-2,minecraft:lava)
B(-3,5,-1,minecraft:lava)
B(-3,5,0,minecraft:andesite)
B(-3,5,1,minecraft:lava)
B(-3,5,2,minecraft:lava)
B(-3,5,3,minecraft:lava)
B(-3,5,4,minecraft:stone)
B(-3,5,5,minecraft:stone)
B(-3,6,-5,minecraft:stone)
B(-3,6,-4,minecraft:cobblestone)
B(-3,6,-3,minecraft:obsidian)
B(-3,6,-2,minecraft:obsidian)
B(-3,6,-1,minecraft:andesite)
B(-3,6,0,minecraft:andesite)
B(-3,6,1,minecraft:lava)
B(-3,6,2,minecraft:lava)
B(-3,6,3,minecraft:lava)
B(-3,6,4,minecraft:stone)
B(-3,6,5,minecraft:cobblestone)
B(-3,6,6,minecraft:obsidian)
B(-3,7,-5,minecraft:cobblestone)
B(-3,7,-4,minecraft:andesite)
B(-3,7,-3,minecraft:stone)
B(-3,7,-2,minecraft:obsidian)
B(-3,7,-1,minecraft:stone)
B(-3,7,0,minecraft:stone)
B(-3,7,1,minecraft:andesite)
B(-3,7,2,minecraft:stone)
B(-3,7,3,minecraft:stone)
B(-3,7,4,minecraft:stone)
B(-3,7,5,minecraft:cobblestone)
B(-3,7,6,minecraft:obsidian)
B(-3,8,-5,minecraft:stone)
B(-3,8,-4,minecraft:stone)
B(-3,8,-3,minecraft:cobblestone)
B(-3,8,-2,minecraft:obsidian)
B(-3,8,-1,minecraft:obsidian)
B(-3,8,0,minecraft:stone)
B(-3,8,1,minecraft:stone)
B(-3,8,2,minecraft:obsidian)
B(-3,8,3,minecraft:obsidian)
B(-3,8,4,minecraft:obsidian)
B(-3,9,-4,minecraft:cobblestone)
B(-3,9,-3,minecraft:stone)
B(-3,9,-2,minecraft:cobblestone)
B(-3,9,-1,minecraft:stone)
B(-3,9,0,minecraft:cobblestone)
B(-3,9,1,minecraft:stone)
B(-3,9,2,minecraft:cobblestone)
B(-3,9,3,minecraft:cobblestone)
B(-3,9,4,minecraft:obsidian)
B(-3,10,-2,minecraft:stone)
B(-3,10,-1,minecraft:obsidian)
B(-3,10,0,minecraft:stone)
B(-3,10,1,minecraft:obsidian)
B(-3,10,2,minecraft:lava)
B(-3,10,3,minecraft:cobblestone)
B(-3,10,4,minecraft:obsidian)
B(-2,1,-2,minecraft:obsidian)
B(-2,1,-1,minecraft:obsidian)
B(-2,1,0,minecraft:stone)
B(-2,1,1,minecraft:stone)
B(-2,1,2,minecraft:stone)
B(-2,2,-4,minecraft:obsidian)
B(-2,2,-3,minecraft:obsidian)
B(-2,2,-2,minecraft:stone)
B(-2,2,-1,minecraft:andesite)
B(-2,2,0,minecraft:stone)
B(-2,2,1,minecraft:stone)
B(-2,2,2,minecraft:stone)
B(-2,2,3,minecraft:andesite)
B(-2,2,4,minecraft:obsidian)
B(-2,2,5,minecraft:obsidian)
B(-2,3,-6,minecraft:stone)
B(-2,3,-5,minecraft:stone)
B(-2,3,-4,minecraft:cobblestone)
B(-2,3,-3,minecraft:lava)
B(-2,3,-2,minecraft:lava)
B(-2,3,-1,minecraft:lava)
B(-2,3,0,minecraft:lava)
B(-2,3,1,minecraft:lava)
B(-2,3,2,minecraft:stone)
B(-2,3,3,minecraft:stone)
B(-2,3,4,minecraft:stone)
B(-2,3,5,minecraft:obsidian)
B(-2,3,6,minecraft:obsidian)
B(-2,4,-5,minecraft:cobblestone)
B(-2,4,-4,minecraft:cobblestone)
B(-2,4,-3,minecraft:lava)
B(-2,4,-2,minecraft:obsidian)
B(-2,4,-1,minecraft:obsidian)
B(-2,4,0,minecraft:obsidian)
B(-2,4,1,minecraft:obsidian)
B(-2,4,2,minecraft:obsidian)
B(-2,4,3,minecraft:obsidian)
B(-2,4,4,minecraft:lava)
B(-2,4,5,minecraft:stone)
B(-2,4,6,minecraft:obsidian)
B(-2,5,-5,minecraft:obsidian)
B(-2,5,-4,minecraft:lava)
B(-2,5,-3,minecraft:lava)
B(-2,5,-2,minecraft:stone)
B(-2,5,-1,minecraft:stone)
B(-2,5,0,minecraft:iron_ore)
B(-2,5,1,minecraft:lava)
B(-2,5,2,minecraft:obsidian)
B(-2,5,3,minecraft:obsidian)
B(-2,5,4,minecraft:lava)
B(-2,5,5,minecraft:stone)
B(-2,5,6,minecraft:obsidian)
B(-2,6,-6,minecraft:stone)
B(-2,6,-5,minecraft:stone)
B(-2,6,-4,minecraft:lava)
B(-2,6,-3,minecraft:lava)
B(-2,6,-2,minecraft:stone)
B(-2,6,-1,minecraft:stone)
B(-2,6,0,minecraft:iron_ore)
B(-2,6,1,minecraft:lava)
B(-2,6,2,minecraft:cobblestone)
B(-2,6,3,minecraft:lava)
B(-2,6,4,minecraft:lava)
B(-2,6,5,minecraft:lava)
B(-2,6,6,minecraft:stone)
B(-2,7,-5,minecraft:obsidian)
B(-2,7,-4,minecraft:stone)
B(-2,7,-3,minecraft:andesite)
B(-2,7,-2,minecraft:stone)
B(-2,7,-1,minecraft:cobblestone)
B(-2,7,0,minecraft:stone)
B(-2,7,1,minecraft:iron_ore)
B(-2,7,2,minecraft:cobblestone)
B(-2,7,3,minecraft:stone)
B(-2,7,4,minecraft:stone)
B(-2,7,5,minecraft:stone)
B(-2,7,6,minecraft:obsidian)
B(-2,8,-6,minecraft:coal_ore)
B(-2,8,-5,minecraft:coal_ore)
B(-2,8,-4,minecraft:stone)
B(-2,8,-3,minecraft:stone)
B(-2,8,-2,minecraft:stone)
B(-2,8,-1,minecraft:lava)
B(-2,8,0,minecraft:stone)
B(-2,8,1,minecraft:stone)
B(-2,8,2,minecraft:lava)
B(-2,8,3,minecraft:stone)
B(-2,8,4,minecraft:stone)
B(-2,8,5,minecraft:obsidian)
B(-2,9,-5,minecraft:coal_ore)
B(-2,9,-4,minecraft:cobblestone)
B(-2,9,-3,minecraft:stone)
B(-2,9,-2,minecraft:cobblestone)
B(-2,9,-1,minecraft:cobblestone)
B(-2,9,0,minecraft:cobblestone)
B(-2,9,1,minecraft:stone)
B(-2,9,2,minecraft:stone)
B(-2,9,3,minecraft:stone)
B(-2,9,4,minecraft:cobblestone)
B(-2,10,-4,minecraft:obsidian)
B(-2,10,-2,minecraft:stone)
B(-2,10,-1,minecraft:lava)
B(-2,10,0,minecraft:stone)
B(-2,10,1,minecraft:lava)
B(-2,10,2,minecraft:lava)
B(-2,10,3,minecraft:cobblestone)
B(-2,11,-2,minecraft:obsidian)
B(-2,11,0,minecraft:stone)
B(-1,1,-3,minecraft:andesite)
B(-1,1,-2,minecraft:stone)
B(-1,1,-1,minecraft:obsidian)
B(-1,1,0,minecraft:obsidian)
B(-1,1,1,minecraft:obsidian)
B(-1,1,2,minecraft:andesite)
B(-1,2,-6,minecraft:obsidian)
B(-1,2,-5,minecraft:obsidian)
B(-1,2,-4,minecraft:obsidian)
B(-1,2,-3,minecraft:obsidian)
B(-1,2,-2,minecraft:stone)
B(-1,2,-1,minecraft:obsidian)
B(-1,2,0,minecraft:obsidian)
B(-1,2,1,minecraft:stone)
B(-1,2,2,minecraft:lava)
B(-1,2,3,minecraft:andesite)
B(-1,2,4,minecraft:stone)
B(-1,2,5,minecraft:stone)
B(-1,3,-7,minecraft:obsidian)
B(-1,3,-6,minecraft:stone)
B(-1,3,-5,minecraft:obsidian)
B(-1,3,-4,minecraft:obsidian)
B(-1,3,-3,minecraft:obsidian)
B(-1,3,-2,minecraft:obsidian)
B(-1,3,-1,minecraft:stone)
B(-1,3,0,minecraft:lava)
B(-1,3,1,minecraft:cobblestone)
B(-1,3,2,minecraft:lava)
B(-1,3,3,minecraft:stone)
B(-1,3,4,minecraft:cobblestone)
B(-1,3,5,minecraft:stone)
B(-1,4,-7,minecraft:stone)
B(-1,4,-6,minecraft:stone)
B(-1,4,-5,minecraft:obsidian)
B(-1,4,-4,minecraft:obsidian)
B(-1,4,-3,minecraft:andesite)
B(-1,4,-2,minecraft:obsidian)
B(-1,4,-1,minecraft:stone)
B(-1,4,0,minecraft:obsidian)
B(-1,4,1,minecraft:stone)
B(-1,4,2,minecraft:obsidian)
B(-1,4,3,minecraft:lava)
B(-1,4,4,minecraft:cobblestone)
B(-1,4,5,minecraft:stone)
B(-1,4,6,minecraft:stone)
B(-1,5,-7,minecraft:stone)
B(-1,5,-6,minecraft:obsidian)
B(-1,5,-5,minecraft:obsidian)
B(-1,5,-4,minecraft:lava)
B(-1,5,-3,minecraft:iron_ore)
B(-1,5,-2,minecraft:cobblestone)
B(-1,5,-1,minecraft:lava)
B(-1,5,0,minecraft:coal_block)
B(-1,5,1,minecraft:stone)
B(-1,5,2,minecraft:obsidian)
B(-1,5,3,minecraft:coal_block)
B(-1,5,4,minecraft:stone)
B(-1,5,5,minecraft:iron_ore)
B(-1,5,6,minecraft:obsidian)
B(-1,6,-7,minecraft:obsidian)
B(-1,6,-6,minecraft:stone)
B(-1,6,-5,minecraft:lava)
B(-1,6,-4,minecraft:lava)
B(-1,6,-3,minecraft:cobblestone)
B(-1,6,-2,minecraft:stone)
B(-1,6,-1,minecraft:coal_block)
B(-1,6,0,minecraft:coal_block)
B(-1,6,1,minecraft:stone)
B(-1,6,2,minecraft:stone)
B(-1,6,3,minecraft:stone)
B(-1,6,4,minecraft:stone)
B(-1,6,5,minecraft:lava)
B(-1,6,6,minecraft:stone)
B(-1,6,7,minecraft:obsidian)
B(-1,7,-7,minecraft:coal_ore)
B(-1,7,-6,minecraft:stone)
B(-1,7,-5,minecraft:stone)
B(-1,7,-4,minecraft:stone)
B(-1,7,-3,minecraft:stone)
B(-1,7,-2,minecraft:stone)
B(-1,7,-1,minecraft:stone)
B(-1,7,0,minecraft:cobblestone)
B(-1,7,1,minecraft:stone)
B(-1,7,2,minecraft:stone)
B(-1,7,3,minecraft:stone)
B(-1,7,4,minecraft:stone)
B(-1,7,5,minecraft:stone)
B(-1,7,6,minecraft:andesite)
B(-1,8,-6,minecraft:obsidian)
B(-1,8,-5,minecraft:obsidian)
B(-1,8,-4,minecraft:obsidian)
B(-1,8,-3,minecraft:andesite)
B(-1,8,-2,minecraft:lava)
B(-1,8,-1,minecraft:lava)
B(-1,8,0,minecraft:lava)
B(-1,8,1,minecraft:lava)
B(-1,8,2,minecraft:lava)
B(-1,8,5,minecraft:stone)
B(-1,9,-5,minecraft:coal_ore)
B(-1,9,-4,minecraft:obsidian)
B(-1,9,-3,minecraft:stone)
B(-1,9,-2,minecraft:lava)
B(-1,9,-1,minecraft:lava)
B(-1,9,0,minecraft:lava)
B(-1,9,1,minecraft:stone)
B(-1,9,2,minecraft:lava)
B(-1,9,3,minecraft:stone)
B(-1,9,4,minecraft:obsidian)
B(-1,9,5,minecraft:cobblestone)
B(-1,10,-5,minecraft:coal_ore)
B(-1,10,-4,minecraft:obsidian)
B(-1,10,-3,minecraft:stone)
B(-1,10,-2,minecraft:stone)
B(-1,10,-1,minecraft:stone)
B(-1,10,0,minecraft:cobblestone)
B(-1,10,1,minecraft:lava)
B(-1,10,2,minecraft:stone)
B(-1,10,3,minecraft:stone)
B(-1,10,4,minecraft:obsidian)
B(-1,11,-4,minecraft:coal_ore)
B(-1,11,-3,minecraft:obsidian)
B(-1,11,-2,minecraft:stone)
B(-1,11,-1,minecraft:stone)
B(-1,11,0,minecraft:lava)
B(-1,11,1,minecraft:lava)
B(-1,11,2,minecraft:cobblestone)
B(0,1,-5,minecraft:stone)
B(0,1,-4,minecraft:stone)
B(0,1,-3,minecraft:obsidian)
B(0,1,-2,minecraft:stone)
B(0,1,-1,minecraft:cobblestone)
B(0,1,1,minecraft:stone)
B(0,1,2,minecraft:stone)
B(0,1,3,minecraft:stone)
B(0,1,4,minecraft:stone)
B(0,2,-6,minecraft:obsidian)
B(0,2,-5,minecraft:stone)
B(0,2,-4,minecraft:stone)
B(0,2,-3,minecraft:lava)
B(0,2,-2,minecraft:lava)
B(0,2,-1,minecraft:stone)
B(0,2,0,minecraft:stone)
B(0,2,1,minecraft:stone)
B(0,2,2,minecraft:obsidian)
B(0,2,3,minecraft:stone)
B(0,2,4,minecraft:stone)
B(0,2,5,minecraft:stone)
B(0,3,-7,minecraft:obsidian)
B(0,3,-6,minecraft:stone)
B(0,3,-5,minecraft:stone)
B(0,3,-4,minecraft:obsidian)
B(0,3,-3,minecraft:lava)
B(0,3,-2,minecraft:obsidian)
B(0,3,-1,minecraft:stone)
B(0,3,0,minecraft:stone)
B(0,3,1,minecraft:stone)
B(0,3,2,minecraft:stone)
B(0,3,3,minecraft:stone)
B(0,3,4,minecraft:stone)
B(0,3,5,minecraft:stone)
B(0,3,6,minecraft:obsidian)
B(0,4,-7,minecraft:stone)
B(0,4,-6,minecraft:stone)
B(0,4,-5,minecraft:lava)
B(0,4,-4,minecraft:stone)
B(0,4,-3,minecraft:obsidian)
B(0,4,-2,minecraft:obsidian)
B(0,4,-1,minecraft:stone)
B(0,4,0,minecraft:stone)
B(0,4,1,minecraft:stone)
B(0,4,2,minecraft:stone)
B(0,4,3,minecraft:coal_block)
B(0,4,4,minecraft:iron_ore)
B(0,4,5,minecraft:stone)
B(0,4,6,minecraft:obsidian)
B(0,5,-7,minecraft:obsidian)
B(0,5,-6,minecraft:obsidian)
B(0,5,-5,minecraft:lava)
B(0,5,-4,minecraft:cobblestone)
B(0,5,-3,minecraft:iron_ore)
B(0,5,-2,minecraft:stone)
B(0,5,-1,minecraft:obsidian)
B(0,5,0,minecraft:lava)
B(0,5,1,minecraft:lava)
B(0,5,2,minecraft:lava)
B(0,5,3,minecraft:coal_block)
B(0,5,4,minecraft:coal_ore)
B(0,5,5,minecraft:cobblestone)
B(0,5,6,minecraft:obsidian)
B(0,6,-7,minecraft:stone)
B(0,6,-6,minecraft:cobblestone)
B(0,6,-5,minecraft:lava)
B(0,6,-4,minecraft:stone)
B(0,6,-3,minecraft:stone)
B(0,6,-2,minecraft:stone)
B(0,6,-1,minecraft:coal_block)
B(0,6,0,minecraft:coal_block)
B(0,6,1,minecraft:obsidian)
B(0,6,2,minecraft:obsidian)
B(0,6,3,minecraft:stone)
B(0,6,4,minecraft:coal_block)
B(0,6,5,minecraft:cobblestone)
B(0,6,6,minecraft:obsidian)
B(0,6,7,minecraft:obsidian)
B(0,7,-7,minecraft:stone)
B(0,7,-6,minecraft:stone)
B(0,7,-5,minecraft:stone)
B(0,7,-4,minecraft:cobblestone)
B(0,7,-3,minecraft:cobblestone)
B(0,7,-2,minecraft:stone)
B(0,7,-1,minecraft:coal_block)
B(0,7,0,minecraft:coal_block)
B(0,7,1,minecraft:stone)
B(0,7,2,minecraft:cobblestone)
B(0,7,3,minecraft:stone)
B(0,7,4,minecraft:stone)
B(0,7,5,minecraft:stone)
B(0,7,6,minecraft:obsidian)
B(0,7,7,minecraft:coal_ore)
B(0,8,-6,minecraft:stone)
B(0,8,-5,minecraft:stone)
B(0,8,-4,minecraft:stone)
B(0,8,-3,minecraft:stone)
B(0,8,-2,minecraft:lava)
B(0,8,-1,minecraft:lava)
B(0,8,0,minecraft:coal_block)
B(0,8,1,minecraft:lava)
B(0,8,2,minecraft:lava)
B(0,8,3,minecraft:lava)
B(0,8,4,minecraft:lava)
B(0,8,5,minecraft:cobblestone)
B(0,8,6,minecraft:cobblestone)
B(0,9,-6,minecraft:coal_ore)
B(0,9,-5,minecraft:stone)
B(0,9,-4,minecraft:stone)
B(0,9,-3,minecraft:stone)
B(0,9,-2,minecraft:lava)
B(0,9,-1,minecraft:lava)
B(0,9,0,minecraft:lava)
B(0,9,1,minecraft:lava)
B(0,9,2,minecraft:lava)
B(0,9,3,minecraft:stone)
B(0,9,4,minecraft:stone)
B(0,9,5,minecraft:stone)
B(0,10,-6,minecraft:coal_ore)
B(0,10,-4,minecraft:stone)
B(0,10,-3,minecraft:stone)
B(0,10,-2,minecraft:stone)
B(0,10,-1,minecraft:stone)
B(0,10,0,minecraft:lava)
B(0,10,1,minecraft:lava)
B(0,10,2,minecraft:stone)
B(0,10,3,minecraft:stone)
B(0,10,4,minecraft:obsidian)
B(0,11,-4,minecraft:stone)
B(0,11,-3,minecraft:obsidian)
B(0,11,-2,minecraft:lava)
B(0,11,-1,minecraft:lava)
B(0,11,0,minecraft:lava)
B(0,11,1,minecraft:lava)
B(0,11,2,minecraft:stone)
B(0,12,-4,minecraft:obsidian)
B(1,1,-4,minecraft:stone)
B(1,1,-3,minecraft:stone)
B(1,1,-2,minecraft:stone)
B(1,1,-1,minecraft:stone)
B(1,1,0,minecraft:stone)
B(1,1,1,minecraft:stone)
B(1,1,2,minecraft:stone)
B(1,1,3,minecraft:stone)
B(1,1,4,minecraft:stone)
B(1,2,-6,minecraft:stone)
B(1,2,-5,minecraft:stone)
B(1,2,-4,minecraft:stone)
B(1,2,-3,minecraft:obsidian)
B(1,2,-2,minecraft:obsidian)
B(1,2,-1,minecraft:obsidian)
B(1,2,0,minecraft:stone)
B(1,2,1,minecraft:obsidian)
B(1,2,2,minecraft:stone)
B(1,2,3,minecraft:stone)
B(1,2,4,minecraft:cobblestone)
B(1,3,-7,minecraft:stone)
B(1,3,-6,minecraft:stone)
B(1,3,-5,minecraft:stone)
B(1,3,-4,minecraft:stone)
B(1,3,-3,minecraft:lava)
B(1,3,-2,minecraft:lava)
B(1,3,-1,minecraft:diamond_ore)
B(1,3,0,minecraft:stone)
B(1,3,1,minecraft:obsidian)
B(1,3,2,minecraft:cobblestone)
B(1,3,3,minecraft:stone)
B(1,3,4,minecraft:cobblestone)
B(1,3,5,minecraft:stone)
B(1,4,-7,minecraft:stone)
B(1,4,-6,minecraft:stone)
B(1,4,-5,minecraft:obsidian)
B(1,4,-4,minecraft:obsidian)
B(1,4,-3,minecraft:obsidian)
B(1,4,-2,minecraft:coal_block)
B(1,4,-1,minecraft:cobblestone)
B(1,4,0,minecraft:stone)
B(1,4,1,minecraft:stone)
B(1,4,2,minecraft:stone)
B(1,4,3,minecraft:obsidian)
B(1,4,4,minecraft:obsidian)
B(1,4,5,minecraft:stone)
B(1,4,6,minecraft:cobblestone)
B(1,5,-7,minecraft:stone)
B(1,5,-6,minecraft:stone)
B(1,5,-5,minecraft:cobblestone)
B(1,5,-4,minecraft:iron_ore)
B(1,5,-3,minecraft:obsidian)
B(1,5,-2,minecraft:cobblestone)
B(1,5,-1,minecraft:obsidian)
B(1,5,0,minecraft:lava)
B(1,5,1,minecraft:cobblestone)
B(1,5,2,minecraft:obsidian)
B(1,5,3,minecraft:obsidian)
B(1,5,4,minecraft:obsidian)
B(1,5,5,minecraft:cobblestone)
B(1,5,6,minecraft:stone)
B(1,5,7,minecraft:obsidian)
B(1,6,-7,minecraft:stone)
B(1,6,-6,minecraft:stone)
B(1,6,-5,minecraft:cobblestone)
B(1,6,-4,minecraft:iron_ore)
B(1,6,-3,minecraft:iron_ore)
B(1,6,-2,minecraft:stone)
B(1,6,-1,minecraft:stone)
B(1,6,0,minecraft:lava)
B(1,6,1,minecraft:cobblestone)
B(1,6,2,minecraft:obsidian)
B(1,6,3,minecraft:iron_ore)
B(1,6,4,minecraft:iron_ore)
B(1,6,5,minecraft:stone)
B(1,6,6,minecraft:obsidian)
B(1,6,7,minecraft:coal_ore)
B(1,7,-7,minecraft:stone)
B(1,7,-6,minecraft:cobblestone)
B(1,7,-5,minecraft:cobblestone)
B(1,7,-4,minecraft:stone)
B(1,7,-3,minecraft:stone)
B(1,7,-2,minecraft:stone)
B(1,7,-1,minecraft:lava)
B(1,7,0,minecraft:lava)
B(1,7,1,minecraft:stone)
B(1,7,2,minecraft:iron_ore)
B(1,7,3,minecraft:stone)
B(1,7,4,minecraft:iron_ore)
B(1,7,5,minecraft:cobblestone)
B(1,7,6,minecraft:stone)
B(1,7,7,minecraft:coal_ore)
B(1,8,-7,minecraft:stone)
B(1,8,-6,minecraft:stone)
B(1,8,-5,minecraft:stone)
B(1,8,-4,minecraft:stone)
B(1,8,-3,minecraft:lava)
B(1,8,-2,minecraft:lava)
B(1,8,-1,minecraft:lava)
B(1,8,0,minecraft:lava)
B(1,8,1,minecraft:lava)
B(1,8,2,minecraft:iron_ore)
B(1,8,3,minecraft:lava)
B(1,8,4,minecraft:lava)
B(1,8,5,minecraft:cobblestone)
B(1,8,6,minecraft:coal_ore)
B(1,9,-6,minecraft:stone)
B(1,9,-5,minecraft:stone)
B(1,9,-4,minecraft:stone)
B(1,9,-3,minecraft:lava)
B(1,9,-2,minecraft:lava)
B(1,9,-1,minecraft:lava)
B(1,9,0,minecraft:lava)
B(1,9,1,minecraft:lava)
B(1,9,2,minecraft:lava)
B(1,9,3,minecraft:stone)
B(1,9,4,minecraft:stone)
B(1,9,5,minecraft:cobblestone)
B(1,9,6,minecraft:coal_ore)
B(1,10,-6,minecraft:stone)
B(1,10,-5,minecraft:stone)
B(1,10,-3,minecraft:lava)
B(1,10,-2,minecraft:lava)
B(1,10,-1,minecraft:lava)
B(1,10,0,minecraft:lava)
B(1,10,1,minecraft:stone)
B(1,10,2,minecraft:stone)
B(1,10,3,minecraft:stone)
B(1,10,4,minecraft:stone)
B(1,11,-5,minecraft:coal_ore)
B(1,11,-4,minecraft:stone)
B(1,11,-3,minecraft:obsidian)
B(1,11,-2,minecraft:obsidian)
B(1,11,-1,minecraft:obsidian)
B(1,11,0,minecraft:obsidian)
B(1,11,1,minecraft:stone)
B(1,11,2,minecraft:lava)
B(1,11,3,minecraft:obsidian)
B(2,1,-5,minecraft:stone)
B(2,1,-4,minecraft:stone)
B(2,1,-3,minecraft:stone)
B(2,1,-2,minecraft:stone)
B(2,1,-1,minecraft:stone)
B(2,1,0,minecraft:stone)
B(2,1,1,minecraft:stone)
B(2,1,2,minecraft:stone)
B(2,2,-6,minecraft:stone)
B(2,2,-5,minecraft:stone)
B(2,2,-4,minecraft:stone)
B(2,2,-3,minecraft:obsidian)
B(2,2,-2,minecraft:iron_ore)
B(2,2,-1,minecraft:lava)
B(2,2,0,minecraft:obsidian)
B(2,2,1,minecraft:obsidian)
B(2,2,2,minecraft:stone)
B(2,2,3,minecraft:stone)
B(2,2,4,minecraft:cobblestone)
B(2,3,-7,minecraft:stone)
B(2,3,-6,minecraft:lava)
B(2,3,-5,minecraft:stone)
B(2,3,-4,minecraft:obsidian)
B(2,3,-3,minecraft:lava)
B(2,3,-2,minecraft:coal_block)
B(2,3,-1,minecraft:iron_ore)
B(2,3,0,minecraft:stone)
B(2,3,1,minecraft:stone)
B(2,3,2,minecraft:cobblestone)
B(2,3,3,minecraft:obsidian)
B(2,3,4,minecraft:cobblestone)
B(2,3,5,minecraft:cobblestone)
B(2,4,-7,minecraft:stone)
B(2,4,-6,minecraft:obsidian)
B(2,4,-5,minecraft:stone)
B(2,4,-4,minecraft:lava)
B(2,4,-3,minecraft:iron_ore)
B(2,4,-2,minecraft:coal_block)
B(2,4,-1,minecraft:iron_ore)
B(2,4,0,minecraft:stone)
B(2,4,1,minecraft:cobblestone)
B(2,4,2,minecraft:stone)
B(2,4,3,minecraft:stone)
B(2,4,4,minecraft:stone)
B(2,4,5,minecraft:cobblestone)
B(2,5,-7,minecraft:stone)
B(2,5,-6,minecraft:lava)
B(2,5,-5,minecraft:cobblestone)
B(2,5,-4,minecraft:coal_block)
B(2,5,-3,minecraft:iron_ore)
B(2,5,-2,minecraft:coal_block)
B(2,5,-1,minecraft:lava)
B(2,5,0,minecraft:obsidian)
B(2,5,1,minecraft:cobblestone)
B(2,5,2,minecraft:obsidian)
B(2,5,3,minecraft:lava)
B(2,5,4,minecraft:lava)
B(2,5,5,minecraft:cobblestone)
B(2,5,6,minecraft:stone)
B(2,6,-7,minecraft:stone)
B(2,6,-6,minecraft:lava)
B(2,6,-5,minecraft:cobblestone)
B(2,6,-4,minecraft:coal_block)
B(2,6,-3,minecraft:iron_ore)
B(2,6,-2,minecraft:coal_block)
B(2,6,-1,minecraft:obsidian)
B(2,6,0,minecraft:obsidian)
B(2,6,1,minecraft:stone)
B(2,6,2,minecraft:lava)
B(2,6,3,minecraft:iron_ore)
B(2,6,4,minecraft:iron_ore)
B(2,6,5,minecraft:stone)
B(2,6,6,minecraft:obsidian)
B(2,7,-7,minecraft:stone)
B(2,7,-6,minecraft:stone)
B(2,7,-5,minecraft:cobblestone)
B(2,7,-4,minecraft:cobblestone)
B(2,7,-3,minecraft:stone)
B(2,7,-2,minecraft:stone)
B(2,7,-1,minecraft:stone)
B(2,7,0,minecraft:cobblestone)
B(2,7,1,minecraft:cobblestone)
B(2,7,2,minecraft:iron_ore)
B(2,7,3,minecraft:cobblestone)
B(2,7,4,minecraft:stone)
B(2,7,5,minecraft:stone)
B(2,7,6,minecraft:obsidian)
B(2,8,-7,minecraft:stone)
B(2,8,-6,minecraft:stone)
B(2,8,-5,minecraft:stone)
B(2,8,-4,minecraft:lava)
B(2,8,-3,minecraft:lava)
B(2,8,-2,minecraft:lava)
B(2,8,-1,minecraft:lava)
B(2,8,0,minecraft:lava)
B(2,8,1,minecraft:stone)
B(2,8,2,minecraft:stone)
B(2,8,3,minecraft:lava)
B(2,8,4,minecraft:lava)
B(2,8,5,minecraft:cobblestone)
B(2,8,6,minecraft:cobblestone)
B(2,9,-7,minecraft:stone)
B(2,9,-6,minecraft:stone)
B(2,9,-5,minecraft:stone)
B(2,9,-4,minecraft:lava)
B(2,9,-3,minecraft:lava)
B(2,9,-2,minecraft:lava)
B(2,9,-1,minecraft:lava)
B(2,9,0,minecraft:lava)
B(2,9,1,minecraft:stone)
B(2,9,2,minecraft:stone)
B(2,9,4,minecraft:stone)
B(2,9,5,minecraft:cobblestone)
B(2,10,-6,minecraft:stone)
B(2,10,-5,minecraft:stone)
B(2,10,-3,minecraft:obsidian)
B(2,10,-2,minecraft:stone)
B(2,10,-1,minecraft:stone)
B(2,10,0,minecraft:stone)
B(2,10,1,minecraft:stone)
B(2,10,2,minecraft:cobblestone)
B(2,10,3,minecraft:stone)
B(2,10,4,minecraft:stone)
B(2,10,5,minecraft:stone)
B(2,11,-5,minecraft:coal_ore)
B(2,11,-4,minecraft:stone)
B(2,11,-3,minecraft:lava)
B(2,11,-2,minecraft:stone)
B(2,11,-1,minecraft:obsidian)
B(2,11,0,minecraft:obsidian)
B(2,11,1,minecraft:lava)
B(2,11,2,minecraft:stone)
B(2,11,3,minecraft:obsidian)
B(2,12,-1,minecraft:obsidian)
B(3,1,-5,minecraft:stone)
B(3,1,-4,minecraft:stone)
B(3,1,-3,minecraft:stone)
B(3,1,-2,minecraft:stone)
B(3,1,-1,minecraft:stone)
B(3,1,0,minecraft:stone)
B(3,1,1,minecraft:stone)
B(3,1,2,minecraft:stone)
B(3,2,-6,minecraft:stone)
B(3,2,-5,minecraft:stone)
B(3,2,-4,minecraft:lava)
B(3,2,-3,minecraft:obsidian)
B(3,2,-2,minecraft:obsidian)
B(3,2,-1,minecraft:obsidian)
B(3,2,0,minecraft:lava)
B(3,2,1,minecraft:lava)
B(3,2,2,minecraft:stone)
B(3,2,3,minecraft:obsidian)
B(3,3,-7,minecraft:obsidian)
B(3,3,-6,minecraft:stone)
B(3,3,-5,minecraft:stone)
B(3,3,-4,minecraft:obsidian)
B(3,3,-3,minecraft:lava)
B(3,3,-2,minecraft:lava)
B(3,3,-1,minecraft:obsidian)
B(3,3,0,minecraft:obsidian)
B(3,3,1,minecraft:lava)
B(3,3,2,minecraft:obsidian)
B(3,3,3,minecraft:obsidian)
B(3,3,4,minecraft:obsidian)
B(3,4,-7,minecraft:stone)
B(3,4,-6,minecraft:cobblestone)
B(3,4,-5,minecraft:obsidian)
B(3,4,-4,minecraft:obsidian)
B(3,4,-3,minecraft:obsidian)
B(3,4,-2,minecraft:lava)
B(3,4,-1,minecraft:obsidian)
B(3,4,0,minecraft:obsidian)
B(3,4,1,minecraft:lava)
B(3,4,2,minecraft:obsidian)
B(3,4,3,minecraft:obsidian)
B(3,4,4,minecraft:obsidian)
B(3,4,5,minecraft:obsidian)
B(3,5,-7,minecraft:stone)
B(3,5,-6,minecraft:stone)
B(3,5,-5,minecraft:coal_block)
B(3,5,-4,minecraft:coal_block)
B(3,5,-3,minecraft:obsidian)
B(3,5,-2,minecraft:lava)
B(3,5,-1,minecraft:stone)
B(3,5,0,minecraft:obsidian)
B(3,5,1,minecraft:lava)
B(3,5,2,minecraft:obsidian)
B(3,5,3,minecraft:obsidian)
B(3,5,4,minecraft:stone)
B(3,5,5,minecraft:stone)
B(3,6,-7,minecraft:stone)
B(3,6,-6,minecraft:stone)
B(3,6,-5,minecraft:stone)
B(3,6,-4,minecraft:stone)
B(3,6,-3,minecraft:obsidian)
B(3,6,-2,minecraft:obsidian)
B(3,6,-1,minecraft:stone)
B(3,6,0,minecraft:stone)
B(3,6,1,minecraft:obsidian)
B(3,6,2,minecraft:obsidian)
B(3,6,3,minecraft:lava)
B(3,6,4,minecraft:lava)
B(3,6,5,minecraft:stone)
B(3,6,6,minecraft:stone)
B(3,7,-7,minecraft:stone)
B(3,7,-6,minecraft:stone)
B(3,7,-5,minecraft:cobblestone)
B(3,7,-4,minecraft:cobblestone)
B(3,7,-3,minecraft:stone)
B(3,7,-2,minecraft:stone)
B(3,7,-1,minecraft:cobblestone)
B(3,7,0,minecraft:stone)
B(3,7,1,minecraft:obsidian)
B(3,7,2,minecraft:obsidian)
B(3,7,3,minecraft:iron_ore)
B(3,7,4,minecraft:cobblestone)
B(3,7,5,minecraft:cobblestone)
B(3,7,6,minecraft:stone)
B(3,8,-7,minecraft:stone)
B(3,8,-6,minecraft:stone)
B(3,8,-5,minecraft:stone)
B(3,8,-4,minecraft:lava)
B(3,8,-3,minecraft:lava)
B(3,8,-2,minecraft:stone)
B(3,8,-1,minecraft:coal_block)
B(3,8,0,minecraft:lava)
B(3,8,2,minecraft:iron_ore)
B(3,8,3,minecraft:iron_ore)
B(3,8,4,minecraft:stone)
B(3,8,5,minecraft:cobblestone)
B(3,8,6,minecraft:obsidian)
B(3,9,-6,minecraft:stone)
B(3,9,-5,minecraft:stone)
B(3,9,-4,minecraft:lava)
B(3,9,-3,minecraft:lava)
B(3,9,-2,minecraft:stone)
B(3,9,-1,minecraft:cobblestone)
B(3,9,0,minecraft:lava)
B(3,9,2,minecraft:stone)
B(3,9,3,minecraft:cobblestone)
B(3,9,4,minecraft:stone)
B(3,9,5,minecraft:cobblestone)
B(3,10,-5,minecraft:stone)
B(3,10,-4,minecraft:stone)
B(3,10,-3,minecraft:stone)
B(3,10,-2,minecraft:cobblestone)
B(3,10,-1,minecraft:cobblestone)
B(3,10,0,minecraft:stone)
B(3,10,1,minecraft:stone)
B(3,10,2,minecraft:stone)
B(3,10,3,minecraft:stone)
B(3,10,4,minecraft:cobblestone)
B(3,10,5,minecraft:stone)
B(3,11,-5,minecraft:coal_ore)
B(3,11,-4,minecraft:obsidian)
B(3,11,-3,minecraft:lava)
B(3,11,-2,minecraft:stone)
B(3,11,-1,minecraft:obsidian)
B(3,11,0,minecraft:obsidian)
B(3,11,1,minecraft:stone)
B(3,11,2,minecraft:obsidian)
B(3,11,3,minecraft:obsidian)
B(3,11,4,minecraft:obsidian)
B(4,1,-5,minecraft:obsidian)
B(4,1,-4,minecraft:stone)
B(4,1,-3,minecraft:stone)
B(4,1,-2,minecraft:stone)
B(4,1,-1,minecraft:stone)
B(4,1,0,minecraft:stone)
B(4,1,1,minecraft:stone)
B(4,2,-6,minecraft:obsidian)
B(4,2,-5,minecraft:obsidian)
B(4,2,-4,minecraft:stone)
B(4,2,-3,minecraft:lava)
B(4,2,-2,minecraft:lava)
B(4,2,-1,minecraft:obsidian)
B(4,2,0,minecraft:lava)
B(4,2,2,minecraft:stone)
B(4,2,3,minecraft:stone)
B(4,3,-6,minecraft:obsidian)
B(4,3,-5,minecraft:stone)
B(4,3,-4,minecraft:stone)
B(4,3,-3,minecraft:obsidian)
B(4,3,-2,minecraft:obsidian)
B(4,3,-1,minecraft:lava)
B(4,3,0,minecraft:lava)
B(4,3,1,minecraft:obsidian)
B(4,3,2,minecraft:lava)
B(4,3,3,minecraft:stone)
B(4,4,-7,minecraft:obsidian)
B(4,4,-6,minecraft:obsidian)
B(4,4,-5,minecraft:cobblestone)
B(4,4,-4,minecraft:obsidian)
B(4,4,-3,minecraft:obsidian)
B(4,4,-2,minecraft:obsidian)
B(4,4,-1,minecraft:coal_block)
B(4,4,0,minecraft:coal_block)
B(4,4,1,minecraft:obsidian)
B(4,4,2,minecraft:obsidian)
B(4,4,3,minecraft:stone)
B(4,4,4,minecraft:stone)
B(4,5,-7,minecraft:obsidian)
B(4,5,-6,minecraft:obsidian)
B(4,5,-5,minecraft:stone)
B(4,5,-4,minecraft:coal_block)
B(4,5,-3,minecraft:stone)
B(4,5,-2,minecraft:stone)
B(4,5,-1,minecraft:lava)
B(4,5,0,minecraft:lava)
B(4,5,1,minecraft:cobblestone)
B(4,5,2,minecraft:lava)
B(4,5,3,minecraft:stone)
B(4,5,4,minecraft:obsidian)
B(4,5,5,minecraft:stone)
B(4,6,-7,minecraft:obsidian)
B(4,6,-6,minecraft:stone)
B(4,6,-5,minecraft:stone)
B(4,6,-4,minecraft:stone)
B(4,6,-3,minecraft:cobblestone)
B(4,6,-2,minecraft:cobblestone)
B(4,6,-1,minecraft:coal_block)
B(4,6,0,minecraft:lava)
B(4,6,1,minecraft:stone)
B(4,6,2,minecraft:lava)
B(4,6,3,minecraft:stone)
B(4,6,4,minecraft:stone)
B(4,6,5,minecraft:stone)
B(4,7,-7,minecraft:obsidian)
B(4,7,-6,minecraft:stone)
B(4,7,-5,minecraft:cobblestone)
B(4,7,-4,minecraft:stone)
B(4,7,-3,minecraft:stone)
B(4,7,-2,minecraft:stone)
B(4,7,-1,minecraft:coal_block)
B(4,7,0,minecraft:iron_ore)
B(4,7,1,minecraft:stone)
B(4,7,2,minecraft:obsidian)
B(4,7,3,minecraft:stone)
B(4,7,4,minecraft:stone)
B(4,7,5,minecraft:stone)
B(4,7,6,minecraft:cobblestone)
B(4,8,-7,minecraft:obsidian)
B(4,8,-6,minecraft:stone)
B(4,8,-5,minecraft:stone)
B(4,8,-2,minecraft:stone)
B(4,8,-1,minecraft:coal_block)
B(4,8,0,minecraft:iron_ore)
B(4,8,1,minecraft:cobblestone)
B(4,8,2,minecraft:iron_ore)
B(4,8,3,minecraft:stone)
B(4,8,4,minecraft:cobblestone)
B(4,8,5,minecraft:obsidian)
B(4,8,6,minecraft:obsidian)
B(4,9,-5,minecraft:stone)
B(4,9,-4,minecraft:stone)
B(4,9,-3,minecraft:stone)
B(4,9,-2,minecraft:stone)
B(4,9,-1,minecraft:stone)
B(4,9,0,minecraft:stone)
B(4,9,1,minecraft:stone)
B(4,9,2,minecraft:cobblestone)
B(4,9,3,minecraft:stone)
B(4,9,4,minecraft:stone)
B(4,9,5,minecraft:obsidian)
B(4,10,-4,minecraft:stone)
B(4,10,-3,minecraft:stone)
B(4,10,-2,minecraft:stone)
B(4,10,-1,minecraft:cobblestone)
B(4,10,0,minecraft:stone)
B(4,10,1,minecraft:stone)
B(4,10,2,minecraft:stone)
B(4,10,3,minecraft:stone)
B(4,10,4,minecraft:stone)
B(4,11,-3,minecraft:obsidian)
B(4,11,-2,minecraft:obsidian)
B(4,11,-1,minecraft:obsidian)
B(4,11,0,minecraft:obsidian)
B(4,11,1,minecraft:obsidian)
B(4,11,2,minecraft:stone)
B(4,11,3,minecraft:obsidian)
B(5,1,-3,minecraft:stone)
B(5,1,-2,minecraft:stone)
B(5,1,-1,minecraft:stone)
B(5,1,0,minecraft:stone)
B(5,1,1,minecraft:stone)
B(5,2,-5,minecraft:stone)
B(5,2,-4,minecraft:cobblestone)
B(5,2,-3,minecraft:stone)
B(5,2,-2,minecraft:stone)
B(5,2,-1,minecraft:obsidian)
B(5,2,0,minecraft:stone)
B(5,2,1,minecraft:stone)
B(5,2,2,minecraft:stone)
B(5,3,-6,minecraft:obsidian)
B(5,3,-5,minecraft:stone)
B(5,3,-4,minecraft:stone)
B(5,3,-3,minecraft:stone)
B(5,3,-2,minecraft:stone)
B(5,3,-1,minecraft:coal_block)
B(5,3,0,minecraft:coal_block)
B(5,3,1,minecraft:stone)
B(5,3,2,minecraft:stone)
B(5,3,3,minecraft:stone)
B(5,4,-6,minecraft:cobblestone)
B(5,4,-5,minecraft:cobblestone)
B(5,4,-4,minecraft:stone)
B(5,4,-3,minecraft:iron_ore)
B(5,4,-2,minecraft:obsidian)
B(5,4,-1,minecraft:coal_block)
B(5,4,0,minecraft:coal_block)
B(5,4,1,minecraft:stone)
B(5,4,2,minecraft:stone)
B(5,4,3,minecraft:stone)
B(5,5,-7,minecraft:obsidian)
B(5,5,-6,minecraft:stone)
B(5,5,-5,minecraft:cobblestone)
B(5,5,-4,minecraft:stone)
B(5,5,-3,minecraft:iron_ore)
B(5,5,-2,minecraft:stone)
B(5,5,-1,minecraft:coal_block)
B(5,5,0,minecraft:lava)
B(5,5,1,minecraft:stone)
B(5,5,2,minecraft:stone)
B(5,5,3,minecraft:stone)
B(5,5,4,minecraft:stone)
B(5,6,-7,minecraft:obsidian)
B(5,6,-6,minecraft:obsidian)
B(5,6,-5,minecraft:obsidian)
B(5,6,-4,minecraft:stone)
B(5,6,-3,minecraft:iron_ore)
B(5,6,-2,minecraft:cobblestone)
B(5,6,-1,minecraft:coal_block)
B(5,6,0,minecraft:obsidian)
B(5,6,1,minecraft:stone)
B(5,6,2,minecraft:obsidian)
B(5,6,3,minecraft:cobblestone)
B(5,6,4,minecraft:stone)
B(5,6,5,minecraft:stone)
B(5,7,-6,minecraft:stone)
B(5,7,-5,minecraft:obsidian)
B(5,7,-4,minecraft:cobblestone)
B(5,7,-3,minecraft:stone)
B(5,7,-2,minecraft:stone)
B(5,7,-1,minecraft:coal_block)
B(5,7,0,minecraft:obsidian)
B(5,7,1,minecraft:stone)
B(5,7,2,minecraft:obsidian)
B(5,7,3,minecraft:stone)
B(5,7,4,minecraft:stone)
B(5,7,5,minecraft:obsidian)
B(5,8,-5,minecraft:obsidian)
B(5,8,-2,minecraft:stone)
B(5,8,-1,minecraft:stone)
B(5,8,0,minecraft:iron_ore)
B(5,8,1,minecraft:stone)
B(5,8,2,minecraft:stone)
B(5,8,3,minecraft:stone)
B(5,8,4,minecraft:stone)
B(5,8,5,minecraft:stone)
B(5,9,-5,minecraft:obsidian)
B(5,9,-4,minecraft:obsidian)
B(5,9,-3,minecraft:obsidian)
B(5,9,-2,minecraft:cobblestone)
B(5,9,-1,minecraft:stone)
B(5,9,0,minecraft:stone)
B(5,9,1,minecraft:stone)
B(5,9,2,minecraft:cobblestone)
B(5,9,3,minecraft:cobblestone)
B(5,9,4,minecraft:stone)
B(5,9,5,minecraft:stone)
B(5,10,-3,minecraft:stone)
B(5,10,-2,minecraft:stone)
B(5,10,-1,minecraft:cobblestone)
B(5,10,0,minecraft:obsidian)
B(5,10,1,minecraft:stone)
B(5,10,2,minecraft:stone)
B(5,10,3,minecraft:cobblestone)
B(5,10,4,minecraft:stone)
B(5,11,-2,minecraft:stone)
B(5,11,-1,minecraft:obsidian)
B(5,11,0,minecraft:obsidian)
B(5,11,1,minecraft:obsidian)
B(5,11,2,minecraft:stone)
B(5,11,3,minecraft:stone)
B(6,1,-2,minecraft:stone)
B(6,1,-1,minecraft:stone)
B(6,2,-4,minecraft:cobblestone)
B(6,2,-3,minecraft:stone)
B(6,2,-2,minecraft:stone)
B(6,2,-1,minecraft:stone)
B(6,2,0,minecraft:stone)
B(6,2,1,minecraft:stone)
B(6,3,-5,minecraft:cobblestone)
B(6,3,-4,minecraft:stone)
B(6,3,-3,minecraft:obsidian)
B(6,3,-2,minecraft:stone)
B(6,3,-1,minecraft:stone)
B(6,3,0,minecraft:stone)
B(6,3,1,minecraft:stone)
B(6,3,2,minecraft:obsidian)
B(6,3,3,minecraft:obsidian)
B(6,4,-5,minecraft:obsidian)
B(6,4,-4,minecraft:cobblestone)
B(6,4,-3,minecraft:stone)
B(6,4,-2,minecraft:iron_ore)
B(6,4,-1,minecraft:obsidian)
B(6,4,0,minecraft:lava)
B(6,4,1,minecraft:obsidian)
B(6,4,2,minecraft:obsidian)
B(6,4,3,minecraft:stone)
B(6,5,-5,minecraft:obsidian)
B(6,5,-4,minecraft:cobblestone)
B(6,5,-3,minecraft:iron_ore)
B(6,5,-2,minecraft:iron_ore)
B(6,5,-1,minecraft:obsidian)
B(6,5,0,minecraft:lava)
B(6,5,1,minecraft:obsidian)
B(6,5,2,minecraft:obsidian)
B(6,5,3,minecraft:stone)
B(6,5,4,minecraft:stone)
B(6,6,-5,minecraft:stone)
B(6,6,-4,minecraft:obsidian)
B(6,6,-3,minecraft:lava)
B(6,6,-2,minecraft:lava)
B(6,6,-1,minecraft:obsidian)
B(6,6,0,minecraft:obsidian)
B(6,6,1,minecraft:cobblestone)
B(6,6,2,minecraft:obsidian)
B(6,6,3,minecraft:obsidian)
B(6,6,4,minecraft:obsidian)
B(6,7,-5,minecraft:stone)
B(6,7,-4,minecraft:stone)
B(6,7,-3,minecraft:stone)
B(6,7,-2,minecraft:lava)
B(6,7,-1,minecraft:lava)
B(6,7,0,minecraft:lava)
B(6,7,1,minecraft:stone)
B(6,7,2,minecraft:stone)
B(6,7,3,minecraft:stone)
B(6,7,4,minecraft:obsidian)
B(6,8,-5,minecraft:obsidian)
B(6,8,-4,minecraft:stone)
B(6,8,-3,minecraft:stone)
B(6,8,-2,minecraft:obsidian)
B(6,8,-1,minecraft:lava)
B(6,8,0,minecraft:lava)
B(6,8,1,minecraft:stone)
B(6,8,2,minecraft:cobblestone)
B(6,8,3,minecraft:stone)
B(6,8,4,minecraft:obsidian)
B(6,8,5,minecraft:obsidian)
B(6,9,-4,minecraft:coal_ore)
B(6,9,-3,minecraft:obsidian)
B(6,9,-2,minecraft:obsidian)
B(6,9,1,minecraft:stone)
B(6,9,2,minecraft:stone)
B(6,9,3,minecraft:stone)
B(6,9,4,minecraft:obsidian)
B(6,9,5,minecraft:obsidian)
B(6,10,-3,minecraft:coal_ore)
B(6,10,-2,minecraft:obsidian)
B(6,10,-1,minecraft:stone)
B(6,10,0,minecraft:stone)
B(6,10,1,minecraft:stone)
B(6,10,2,minecraft:stone)
B(6,10,3,minecraft:obsidian)
B(6,11,-2,minecraft:obsidian)
B(6,11,0,minecraft:stone)
B(6,11,1,minecraft:stone)
B(6,11,2,minecraft:stone)
B(7,2,-3,minecraft:stone)
B(7,2,-2,minecraft:stone)
B(7,2,-1,minecraft:obsidian)
B(7,2,0,minecraft:stone)
B(7,3,-4,minecraft:stone)
B(7,3,-3,minecraft:obsidian)
B(7,3,-2,minecraft:cobblestone)
B(7,3,-1,minecraft:cobblestone)
B(7,3,0,minecraft:stone)
B(7,3,1,minecraft:stone)
B(7,4,-4,minecraft:cobblestone)
B(7,4,-3,minecraft:cobblestone)
B(7,4,-2,minecraft:cobblestone)
B(7,4,-1,minecraft:obsidian)
B(7,4,0,minecraft:stone)
B(7,4,1,minecraft:stone)
B(7,4,2,minecraft:stone)
B(7,5,-5,minecraft:stone)
B(7,5,-4,minecraft:stone)
B(7,5,-3,minecraft:obsidian)
B(7,5,-2,minecraft:iron_ore)
B(7,5,-1,minecraft:obsidian)
B(7,5,0,minecraft:lava)
B(7,5,1,minecraft:stone)
B(7,5,2,minecraft:obsidian)
B(7,5,3,minecraft:stone)
B(7,6,-4,minecraft:obsidian)
B(7,6,-3,minecraft:obsidian)
B(7,6,-2,minecraft:obsidian)
B(7,6,-1,minecraft:obsidian)
B(7,6,0,minecraft:lava)
B(7,6,1,minecraft:lava)
B(7,6,2,minecraft:lava)
B(7,6,3,minecraft:stone)
B(7,7,-4,minecraft:stone)
B(7,7,-3,minecraft:stone)
B(7,7,-2,minecraft:obsidian)
B(7,7,-1,minecraft:stone)
B(7,7,0,minecraft:lava)
B(7,7,1,minecraft:lava)
B(7,7,2,minecraft:lava)
B(7,7,3,minecraft:stone)
B(7,7,4,minecraft:stone)
B(7,8,-3,minecraft:stone)
B(7,8,-2,minecraft:obsidian)
B(7,8,0,minecraft:stone)
B(7,8,3,minecraft:stone)
B(7,8,4,minecraft:stone)
B(7,9,-3,minecraft:coal_ore)
B(7,9,-1,minecraft:stone)
B(7,9,0,minecraft:stone)
B(7,9,1,minecraft:stone)
B(7,9,3,minecraft:stone)
B(7,10,0,minecraft:stone)
B(7,10,1,minecraft:stone)
B(8,2,-1,minecraft:stone)
B(8,2,0,minecraft:stone)
B(8,3,-3,minecraft:obsidian)
B(8,3,-2,minecraft:cobblestone)
B(8,3,-1,minecraft:cobblestone)
B(8,3,0,minecraft:stone)
B(8,3,1,minecraft:stone)
B(8,4,-3,minecraft:cobblestone)
B(8,4,-2,minecraft:cobblestone)
B(8,4,-1,minecraft:stone)
B(8,4,0,minecraft:stone)
B(8,4,1,minecraft:obsidian)
B(8,4,2,minecraft:stone)
B(8,5,-3,minecraft:stone)
B(8,5,-2,minecraft:cobblestone)
B(8,5,-1,minecraft:obsidian)
B(8,5,0,minecraft:obsidian)
B(8,5,1,minecraft:obsidian)
B(8,5,2,minecraft:stone)
B(8,6,-3,minecraft:cobblestone)
B(8,6,-2,minecraft:obsidian)
B(8,6,-1,minecraft:obsidian)
B(8,6,0,minecraft:obsidian)
B(8,6,1,minecraft:stone)
B(8,6,2,minecraft:stone)
B(8,7,-3,minecraft:coal_ore)
B(8,7,-2,minecraft:cobblestone)
B(8,7,-1,minecraft:stone)
B(8,7,0,minecraft:obsidian)
B(8,7,1,minecraft:stone)
B(8,7,2,minecraft:stone)
B(8,7,3,minecraft:stone)
B(8,8,-2,minecraft:coal_ore)
B(8,8,-1,minecraft:stone)
B(8,8,0,minecraft:obsidian)
B(8,8,1,minecraft:obsidian)
B(8,8,2,minecraft:cobblestone)
B(8,8,3,minecraft:stone)
B(8,9,0,minecraft:obsidian)
B(8,9,1,minecraft:obsidian)
B(8,9,2,minecraft:cobblestone)
B(8,10,1,minecraft:obsidian)
B(9,3,-1,minecraft:cobblestone)
B(9,4,-1,minecraft:cobblestone)
B(9,4,0,minecraft:stone)
B(9,5,-2,minecraft:cobblestone)
B(9,5,-1,minecraft:cobblestone)
B(9,5,0,minecraft:stone)
B(9,5,1,minecraft:stone)
B(9,6,-2,minecraft:coal_ore)
B(9,6,-1,minecraft:cobblestone)
B(9,6,0,minecraft:cobblestone)
B(9,6,1,minecraft:stone)
B(9,7,-1,minecraft:coal_ore)
B(9,7,0,minecraft:cobblestone)
B(9,7,1,minecraft:cobblestone)
B(9,8,0,minecraft:stone)

#######################################################################
# +-----------------------------------------------------------------+ #
# |                            BO3 checks                           | #
# +-----------------------------------------------------------------+ #
#######################################################################

# Require a condition at a certain location in order for the BO3 to be spawned.
# BlockCheck(x,y,z,BlockName[,BlockName[,...]]) - one of the blocks must be at the location
# BlockCheckNot(x,y,z,BlockName[,BlockName[,...]]) - all the blocks must not be at the location
# LightCheck(x,y,z,minLightLevel,maxLightLevel) - light must be between min and max (inclusive)
# ModCheck(ModName[,ModName[,...]]) - all the mods listed must be loaded
# ModCheckNot(ModName[,ModName[,...]]) - all the mods listed must not be loaded

# You can use "Solid" as a BlockName for matching all solid blocks or "All" to match all blocks that aren't air.

# Examples:
#   BlockCheck(0,-1,0,GRASS,DIRT)  Require grass or dirt just below the object
#   BlockCheck(0,-1,0,Solid)		Require any solid block just below the object
#   BlockCheck(0,-1,0,WOOL)		Require any type of wool just below the object
#   BlockCheck(0,-1,0,WOOL:0)	  Require white wool just below the object
#   BlockCheckNot(0,-1,0,WOOL:0)	Require that there is no white wool below the object
#   LightCheck(0,0,0,0,1)		  Require almost complete darkness just below the object
BlockCheck(0,8,0,minecraft:air)
BlockCheck(0,6,0,minecraft:grass_block)
BlockCheck(1,-1,0,Solid)
BlockCheck(1,-1,-1,Solid)
BlockCheck(1,-1,1,Solid)
BlockCheck(0,-1,1,Solid)
BlockCheck(0,-1,-1,Solid)
BlockCheck(-1,-1,1,Solid)
BlockCheck(-1,-1,0,Solid)
BlockCheck(-1,-1,-1,Solid)
BlockCheck(2,-1,2,Solid)
BlockCheck(2,-1,1,Solid)
BlockCheck(2,-1,0,Solid)
BlockCheck(2,-1,-1,Solid)
BlockCheck(2,-1,-2,Solid)
BlockCheck(1,-1,2,Solid)
BlockCheck(1,-1,-2,Solid)
BlockCheck(0,-1,2,Solid)
BlockCheck(0,-1,-2,Solid)
BlockCheck(-1,-1,2,Solid)
BlockCheck(-1,-1,-2,Solid)
BlockCheck(-2,-1,2,Solid)
BlockCheck(-2,-1,1,Solid)
BlockCheck(-2,-1,0,Solid)
BlockCheck(-2,-1,-1,Solid)
BlockCheck(-2,-1,-2,Solid)
BlockCheck(4,-1,0,Solid)
BlockCheck(-4,-1,0,Solid)
BlockCheck(0,-1,4,Solid)
BlockCheck(0,-1,-4,Solid)
BlockCheck(4,-1,4,Solid)
BlockCheck(-4,-1,-4,Solid)
BlockCheck(-4,-1,4,Solid)
BlockCheck(4,-1,-4,Solid)
BlockCheck(6,-1,0,Solid)
BlockCheck(-6,-1,0,Solid)
BlockCheck(0,-1,6,Solid)
BlockCheck(0,-1,-6,Solid)
BlockCheck(6,-1,6,Solid)
BlockCheck(-6,-1,-6,Solid)
BlockCheck(-6,-1,6,Solid)
BlockCheck(6,-1,-6,Solid)

#######################################################################
# +-----------------------------------------------------------------+ #
# |                             Branches                            | #
# +-----------------------------------------------------------------+ #
#######################################################################

# Branches are child-BO3's that spawn if this BO3 is configured to spawn as a
# CustomStructure resource in a biome config. Branches can have branches,
# making complex structures possible. See the wiki for more details.

# Regular Branches spawn each branch with an independent chance of spawning.
# Branch(x,y,z,branchName,rotation,chance[,anotherBranchName,rotation,chance[,...]][IndividualChance])
# branchName - name of the object to spawn.
# rotation - NORTH, SOUTH, EAST or WEST.
# IndividualChance - The chance each branch has to spawn, assumed to be 100 when left blank
# isRequiredBranch - If this is set to true then at least one of the branches in this BO3 must spawn at these x,y,z coordinates. If no branch can spawn there then this BO3 fails to spawn and its branch is rolled back.
# isRequiredBranch:true branches must spawn or the current branch is rolled back entirely. This is useful for grouping BO3's that must spawn together, for instance a single room made of multiple BO3's/branches.
# If all parts of the room are connected together via isRequiredBranch:true branches then either the entire room will spawns or no part of it will spawn.
# *Note: When isRequiredBranch:true only one BO3 can be added per Branch() and it will automatically have a rarity of 100.0.
# isRequiredBranch:false branches are used to make optional parts of structures, for instance the middle section of a tunnel that has a beginning, middle and end BO3/branch and can have a variable length by repeating the middle BO3/branch.
# By making the start and end branches isRequiredBranch:true and the middle branch isRequiredbranch:false you can make it so that either:
# A. A tunnel spawns with at least a beginning and end branch
# B. A tunnel spawns with a beginning and end branch and as many middle branches as will fit in the available space.
# C. No tunnel spawns at all because there wasn't enough space to spawn at least a beginning and end branch.
# branchDepth - When creating a chain of branches that contains optional (isRequiredBranch:false) branches branch depth is configured for the first BO3 in the chain to determine the maximum length of the chain.
# branchDepth - 1 is inherited by each isRequiredBranch:false branch in the chain. When branchDepth is zero isRequiredBranch:false branches cannot spawn and the chain ends. In the case of the tunnel this means the last middle branch would be
# rolled back and an IsRequiredBranch:true end branch could be spawned in its place to make sure the tunnel has a proper ending.
# Instead of inheriting branchDepth - 1 from the parent branchDepth can be overridden by child branches if it is set higher than 0 (the default value).
# isRequiredBranch:true branches do inherit branchDepth and pass it on to their own branches, however they cannot be prevented from spawning by it and also don't subtract 1 from branchDepth when inheriting it.

# Weighted Branches spawn branches with a dependent chance of spawning.
# WeightedBranch(x,y,z,branchName,rotation,chance[,anotherBranchName,rotation,chance[,...]][MaxChanceOutOf])
# *Note: isRequiredBranch must be set to false. It is not possible to use isRequiredBranch:true with WeightedBranch() since isRequired:true branches must spawn and automatically have a rarity of 100.0.
# MaxChanceOutOf - The chance all branches have to spawn out of, assumed to be 100 when left blank

#######################################################################
# +-----------------------------------------------------------------+ #
# |                             Entities                            | #
# +-----------------------------------------------------------------+ #
#######################################################################

# Forge only (this may have changed, check for updates).
# An EntityFunction spawns an entity instead of a block. The entity is spawned only once when the BO3 is spawned.
# Entities are persistent by default so they don't de-spawn when no player is near, they are only unloaded.
# Usage: Entity(x,y,z,entityName,groupSize,NameTagOrNBTFileName) or Entity(x,y,z,mobName,groupSize)
# Use /otg entities to get a list of entities that can be used as entityName, this includes entities added by other mods and non-living entities.
# NameTagOrNBTFileName can be either a nametag for the mob or an .txt file with nbt data (such as myentityinfo.txt).
# In the text file you can use the same mob spawning parameters used with the /summon command to equip the
# entity and give it custom attributes etc. You can copy the DATA part of a summon command including surrounding 
# curly braces to a .txt file, for instance for: "/summon Skeleton x y z {DATA}"
# *Note: Unlike Block(), for Entity() .nbt files don't work, only .txt files work.
