
#######################################################################
# +-----------------------------------------------------------------+ #
# |                            BO4 object                           | #
# +-----------------------------------------------------------------+ #
#######################################################################

Author: Unknown

Description: No description given

SettingsMode: WriteWithoutComments


#######################################################################
# +-----------------------------------------------------------------+ #
# |                          Main settings                          | #
# +-----------------------------------------------------------------+ #
#######################################################################

FixedRotation: 

Frequency: 0

SpawnHeight: highestBlock

UseCenterForHighestBlock: true

##############################
# Height Limits for the BO4. #
##############################

MinHeight: 0

MaxHeight: 255

InheritBO3: 

InheritBO3Rotation: NORTH

OverrideChildSettings: true

OverrideParentHeight: false

CanOverride: false

BranchFrequency: 0

BranchFrequencyGroup: 

MustBeBelowOther: false

MustBeInside: 

CannotBeInside: 

ReplacesBO3: 

MustBeInsideWorldBorders: false

CanSpawnOnWater: true

SpawnOnWaterOnly: false

SpawnUnderWater: false

SpawnAtWaterLevel: false

HeightOffset: 0

RemoveAir: true

ReplaceAbove: 

ReplaceBelow: 

ReplaceWithBiomeBlocks: true

ReplaceWithSurfaceBlock: GRASS

ReplaceWithGroundBlock: DIRT

ReplaceWithStoneBlock: STONE

SmoothRadius: 0

SmoothHeightOffset: 0

SmoothStartTop: false

SmoothStartWood: false

SmoothingSurfaceBlock: 

SmoothingGroundBlock: 

BO3Group: 

IsSpawnPoint: false

DoReplaceBlocks: true


#######################################################################
# +-----------------------------------------------------------------+ #
# |                              Blocks                             | #
# +-----------------------------------------------------------------+ #
#######################################################################

B(-4,35,-6,minecraft:grass_block)
B(-4,35,-5,minecraft:grass_block)
B(-4,35,-4,minecraft:coarse_dirt)
B(-4,35,-2,minecraft:grass_block)
B(-4,35,-1,minecraft:coarse_dirt)
B(-3,35,-7,minecraft:grass_block)
B(-3,32,-6,minecraft:stone)
B(-3,33,-6,minecraft:dirt)
B(-3,34,-6,minecraft:dirt)
B(-3,35,-6,minecraft:grass_block)
B(-3,31,-5,minecraft:cobblestone)
B(-3,32,-5,minecraft:stone)
B(-3,33,-5,minecraft:dirt)
B(-3,34,-5,minecraft:dirt)
B(-3,35,-5,minecraft:coarse_dirt)
B(-3,32,-4,minecraft:cobblestone)
B(-3,33,-4,minecraft:dirt)
B(-3,34,-4,minecraft:dirt)
B(-3,35,-4,minecraft:coarse_dirt)
B(-3,32,-3,minecraft:cobblestone)
B(-3,33,-3,minecraft:cobblestone)
B(-3,34,-3,minecraft:dirt)
B(-3,35,-3,minecraft:dirt)
B(-3,36,-3,minecraft:grass_block)
B(-3,32,-2,minecraft:cobblestone)
B(-3,33,-2,minecraft:dirt)
B(-3,34,-2,minecraft:dirt)
B(-3,35,-2,minecraft:coarse_dirt)
B(-3,33,-1,minecraft:dirt)
B(-3,34,-1,minecraft:dirt)
B(-3,35,-1,minecraft:coarse_dirt)
B(-3,34,0,minecraft:dirt)
B(-3,35,0,minecraft:grass_block)
B(-3,35,1,minecraft:coarse_dirt)
B(-2,32,-7,minecraft:stone)
B(-2,33,-7,minecraft:dirt)
B(-2,34,-7,minecraft:dirt)
B(-2,35,-7,minecraft:grass_block)
B(-2,27,-6,minecraft:cobblestone)
B(-2,28,-6,minecraft:cobblestone)
B(-2,29,-6,minecraft:cobblestone)
B(-2,30,-6,minecraft:stone)
B(-2,31,-6,minecraft:stone)
B(-2,32,-6,minecraft:stone)
B(-2,33,-6,minecraft:stone)
B(-2,34,-6,minecraft:dirt)
B(-2,35,-6,minecraft:grass_block)
B(-2,25,-5,minecraft:cobblestone)
B(-2,26,-5,minecraft:cobblestone)
B(-2,27,-5,minecraft:cobblestone)
B(-2,28,-5,minecraft:cobblestone)
B(-2,29,-5,minecraft:cobblestone)
B(-2,30,-5,minecraft:cobblestone)
B(-2,31,-5,minecraft:stone)
B(-2,32,-5,minecraft:stone)
B(-2,33,-5,minecraft:stone)
B(-2,34,-5,minecraft:dirt)
B(-2,35,-5,minecraft:grass_block)
B(-2,26,-4,minecraft:cobblestone)
B(-2,27,-4,minecraft:cobblestone)
B(-2,28,-4,minecraft:stone)
B(-2,29,-4,minecraft:stone)
B(-2,30,-4,minecraft:cobblestone)
B(-2,31,-4,minecraft:cobblestone)
B(-2,32,-4,minecraft:stone)
B(-2,33,-4,minecraft:stone)
B(-2,34,-4,minecraft:dirt)
B(-2,35,-4,minecraft:dirt)
B(-2,36,-4,minecraft:grass_block)
B(-2,25,-3,minecraft:cobblestone)
B(-2,26,-3,minecraft:cobblestone)
B(-2,27,-3,minecraft:stone)
B(-2,28,-3,minecraft:stone)
B(-2,29,-3,minecraft:stone)
B(-2,30,-3,minecraft:stone)
B(-2,31,-3,minecraft:cobblestone)
B(-2,32,-3,minecraft:stone)
B(-2,33,-3,minecraft:stone)
B(-2,34,-3,minecraft:stone)
B(-2,35,-3,minecraft:stone)
B(-2,36,-3,minecraft:grass_block)
B(-2,27,-2,minecraft:stone)
B(-2,28,-2,minecraft:stone)
B(-2,29,-2,minecraft:stone)
B(-2,30,-2,minecraft:stone)
B(-2,31,-2,minecraft:cobblestone)
B(-2,32,-2,minecraft:stone)
B(-2,33,-2,minecraft:dirt)
B(-2,34,-2,minecraft:dirt)
B(-2,35,-2,minecraft:dirt)
B(-2,36,-2,minecraft:grass_block)
B(-2,30,-1,minecraft:stone)
B(-2,31,-1,minecraft:cobblestone)
B(-2,32,-1,minecraft:dirt)
B(-2,33,-1,minecraft:dirt)
B(-2,34,-1,minecraft:dirt)
B(-2,35,-1,minecraft:grass_block)
B(-2,30,0,minecraft:stone)
B(-2,31,0,minecraft:dirt)
B(-2,32,0,minecraft:dirt)
B(-2,33,0,minecraft:dirt)
B(-2,34,0,minecraft:dirt)
B(-2,35,0,minecraft:grass_block)
B(-2,33,1,minecraft:dirt)
B(-2,34,1,minecraft:dirt)
B(-2,35,1,minecraft:coarse_dirt)
B(-1,27,-7,minecraft:cobblestone)
B(-1,28,-7,minecraft:cobblestone)
B(-1,29,-7,minecraft:cobblestone)
B(-1,30,-7,minecraft:cobblestone)
B(-1,31,-7,minecraft:cobblestone)
B(-1,32,-7,minecraft:cobblestone)
B(-1,33,-7,minecraft:stone)
B(-1,34,-7,minecraft:dirt)
B(-1,35,-7,minecraft:grass_block)
B(-1,20,-6,minecraft:cobblestone)
B(-1,21,-6,minecraft:cobblestone)
B(-1,22,-6,minecraft:stone)
B(-1,23,-6,minecraft:stone)
B(-1,24,-6,minecraft:stone)
B(-1,25,-6,minecraft:stone)
B(-1,26,-6,minecraft:cobblestone)
B(-1,27,-6,minecraft:stone)
B(-1,28,-6,minecraft:stone)
B(-1,29,-6,minecraft:stone)
B(-1,30,-6,minecraft:stone)
B(-1,31,-6,minecraft:stone)
B(-1,32,-6,minecraft:stone)
B(-1,33,-6,minecraft:stone)
B(-1,34,-6,minecraft:dirt)
B(-1,35,-6,minecraft:grass_block)
B(-1,18,-5,minecraft:stone)
B(-1,19,-5,minecraft:stone)
B(-1,20,-5,minecraft:cobblestone)
B(-1,21,-5,minecraft:cobblestone)
B(-1,22,-5,minecraft:stone)
B(-1,23,-5,minecraft:stone)
B(-1,24,-5,minecraft:stone)
B(-1,25,-5,minecraft:stone)
B(-1,26,-5,minecraft:stone)
B(-1,27,-5,minecraft:stone)
B(-1,28,-5,minecraft:stone)
B(-1,29,-5,minecraft:stone)
B(-1,30,-5,minecraft:stone)
B(-1,31,-5,minecraft:stone)
B(-1,32,-5,minecraft:stone)
B(-1,33,-5,minecraft:stone)
B(-1,34,-5,minecraft:dirt)
B(-1,35,-5,minecraft:grass_block)
B(-1,17,-4,minecraft:stone)
B(-1,18,-4,minecraft:stone)
B(-1,19,-4,minecraft:stone)
B(-1,20,-4,minecraft:stone)
B(-1,21,-4,minecraft:cobblestone)
B(-1,22,-4,minecraft:stone)
B(-1,23,-4,minecraft:stone)
B(-1,24,-4,minecraft:cobblestone)
B(-1,25,-4,minecraft:cobblestone)
B(-1,26,-4,minecraft:stone)
B(-1,27,-4,minecraft:stone)
B(-1,28,-4,minecraft:stone)
B(-1,29,-4,minecraft:stone)
B(-1,30,-4,minecraft:stone)
B(-1,31,-4,minecraft:stone)
B(-1,32,-4,minecraft:stone)
B(-1,33,-4,minecraft:stone)
B(-1,34,-4,minecraft:stone)
B(-1,35,-4,minecraft:stone)
B(-1,36,-4,minecraft:grass_block)
B(-1,18,-3,minecraft:stone)
B(-1,19,-3,minecraft:stone)
B(-1,20,-3,minecraft:stone)
B(-1,21,-3,minecraft:cobblestone)
B(-1,22,-3,minecraft:stone)
B(-1,23,-3,minecraft:stone)
B(-1,24,-3,minecraft:cobblestone)
B(-1,25,-3,minecraft:stone)
B(-1,26,-3,minecraft:stone)
B(-1,27,-3,minecraft:stone)
B(-1,28,-3,minecraft:stone)
B(-1,29,-3,minecraft:stone)
B(-1,30,-3,minecraft:stone)
B(-1,31,-3,minecraft:stone)
B(-1,32,-3,minecraft:stone)
B(-1,33,-3,minecraft:stone)
B(-1,34,-3,minecraft:dirt)
B(-1,35,-3,minecraft:dirt)
B(-1,36,-3,minecraft:stone)
B(-1,37,-3,minecraft:stone)
B(-1,19,-2,minecraft:cobblestone)
B(-1,20,-2,minecraft:cobblestone)
B(-1,21,-2,minecraft:cobblestone)
B(-1,22,-2,minecraft:cobblestone)
B(-1,23,-2,minecraft:stone)
B(-1,24,-2,minecraft:cobblestone)
B(-1,25,-2,minecraft:cobblestone)
B(-1,26,-2,minecraft:cobblestone)
B(-1,27,-2,minecraft:stone)
B(-1,28,-2,minecraft:stone)
B(-1,29,-2,minecraft:stone)
B(-1,30,-2,minecraft:stone)
B(-1,31,-2,minecraft:stone)
B(-1,32,-2,minecraft:stone)
B(-1,33,-2,minecraft:stone)
B(-1,34,-2,minecraft:dirt)
B(-1,35,-2,minecraft:dirt)
B(-1,36,-2,minecraft:grass_block)
B(-1,26,-1,minecraft:stone)
B(-1,27,-1,minecraft:stone)
B(-1,28,-1,minecraft:stone)
B(-1,29,-1,minecraft:stone)
B(-1,30,-1,minecraft:stone)
B(-1,31,-1,minecraft:stone)
B(-1,32,-1,minecraft:dirt)
B(-1,33,-1,minecraft:dirt)
B(-1,34,-1,minecraft:dirt)
B(-1,35,-1,minecraft:grass_block)
B(-1,30,0,minecraft:stone)
B(-1,31,0,minecraft:dirt)
B(-1,32,0,minecraft:dirt)
B(-1,33,0,minecraft:dirt)
B(-1,34,0,minecraft:dirt)
B(-1,35,0,minecraft:coarse_dirt)
B(-1,32,1,minecraft:dirt)
B(-1,33,1,minecraft:dirt)
B(-1,34,1,minecraft:dirt)
B(-1,35,1,minecraft:coarse_dirt)
B(-1,35,2,minecraft:grass_block)
B(0,22,-7,minecraft:stone)
B(0,23,-7,minecraft:stone)
B(0,24,-7,minecraft:stone)
B(0,25,-7,minecraft:stone)
B(0,26,-7,minecraft:cobblestone)
B(0,27,-7,minecraft:stone)
B(0,28,-7,minecraft:stone)
B(0,29,-7,minecraft:stone)
B(0,30,-7,minecraft:stone)
B(0,31,-7,minecraft:stone)
B(0,32,-7,minecraft:stone)
B(0,33,-7,minecraft:dirt)
B(0,34,-7,minecraft:dirt)
B(0,35,-7,minecraft:grass_block)
B(0,14,-6,minecraft:stone)
B(0,15,-6,minecraft:stone)
B(0,16,-6,minecraft:stone)
B(0,17,-6,minecraft:stone)
B(0,18,-6,minecraft:stone)
B(0,19,-6,minecraft:cobblestone)
B(0,20,-6,minecraft:cobblestone)
B(0,21,-6,minecraft:cobblestone)
B(0,22,-6,minecraft:stone)
B(0,23,-6,minecraft:stone)
B(0,24,-6,minecraft:stone)
B(0,25,-6,minecraft:stone)
B(0,26,-6,minecraft:stone)
B(0,27,-6,minecraft:stone)
B(0,28,-6,minecraft:stone)
B(0,29,-6,minecraft:stone)
B(0,30,-6,minecraft:stone)
B(0,31,-6,minecraft:stone)
B(0,32,-6,minecraft:stone)
B(0,33,-6,minecraft:dirt)
B(0,34,-6,minecraft:dirt)
B(0,35,-6,minecraft:dirt)
B(0,36,-6,minecraft:grass_block)
B(0,11,-5,minecraft:stone)
B(0,12,-5,minecraft:stone)
B(0,13,-5,minecraft:cobblestone)
B(0,14,-5,minecraft:cobblestone)
B(0,15,-5,minecraft:stone)
B(0,16,-5,minecraft:stone)
B(0,17,-5,minecraft:stone)
B(0,18,-5,minecraft:stone)
B(0,19,-5,minecraft:stone)
B(0,20,-5,minecraft:stone)
B(0,21,-5,minecraft:stone)
B(0,22,-5,minecraft:stone)
B(0,23,-5,minecraft:stone)
B(0,24,-5,minecraft:stone)
B(0,25,-5,minecraft:stone)
B(0,26,-5,minecraft:stone)
B(0,27,-5,minecraft:stone)
B(0,28,-5,minecraft:stone)
B(0,29,-5,minecraft:stone)
B(0,30,-5,minecraft:stone)
B(0,31,-5,minecraft:stone)
B(0,32,-5,minecraft:stone)
B(0,33,-5,minecraft:dirt)
B(0,34,-5,minecraft:dirt)
B(0,35,-5,minecraft:dirt)
B(0,36,-5,minecraft:grass_block)
B(0,13,-4,minecraft:cobblestone)
B(0,14,-4,minecraft:cobblestone)
B(0,15,-4,minecraft:cobblestone)
B(0,16,-4,minecraft:stone)
B(0,17,-4,minecraft:stone)
B(0,18,-4,minecraft:stone)
B(0,19,-4,minecraft:cobblestone)
B(0,20,-4,minecraft:stone)
B(0,21,-4,minecraft:stone)
B(0,22,-4,minecraft:stone)
B(0,23,-4,minecraft:stone)
B(0,24,-4,minecraft:stone)
B(0,25,-4,minecraft:stone)
B(0,26,-4,minecraft:stone)
B(0,27,-4,minecraft:stone)
B(0,28,-4,minecraft:stone)
B(0,29,-4,minecraft:stone)
B(0,30,-4,minecraft:stone)
B(0,31,-4,minecraft:stone)
B(0,32,-4,minecraft:stone)
B(0,33,-4,minecraft:stone)
B(0,34,-4,minecraft:dirt)
B(0,35,-4,minecraft:dirt)
B(0,36,-4,minecraft:dirt)
B(0,37,-4,minecraft:grass_block)
B(0,20,-3,minecraft:cobblestone)
B(0,21,-3,minecraft:cobblestone)
B(0,22,-3,minecraft:stone)
B(0,23,-3,minecraft:stone)
B(0,24,-3,minecraft:stone)
B(0,25,-3,minecraft:stone)
B(0,26,-3,minecraft:stone)
B(0,27,-3,minecraft:stone)
B(0,28,-3,minecraft:stone)
B(0,29,-3,minecraft:stone)
B(0,30,-3,minecraft:stone)
B(0,31,-3,minecraft:stone)
B(0,32,-3,minecraft:stone)
B(0,33,-3,minecraft:dirt)
B(0,34,-3,minecraft:dirt)
B(0,35,-3,minecraft:dirt)
B(0,36,-3,minecraft:dirt)
B(0,37,-3,minecraft:dirt)
B(0,38,-3,minecraft:stone)
B(0,23,-2,minecraft:stone)
B(0,24,-2,minecraft:stone)
B(0,25,-2,minecraft:stone)
B(0,26,-2,minecraft:stone)
B(0,27,-2,minecraft:stone)
B(0,28,-2,minecraft:stone)
B(0,29,-2,minecraft:stone)
B(0,30,-2,minecraft:stone)
B(0,31,-2,minecraft:stone)
B(0,32,-2,minecraft:stone)
B(0,33,-2,minecraft:dirt)
B(0,34,-2,minecraft:dirt)
B(0,35,-2,minecraft:dirt)
B(0,36,-2,minecraft:stone)
B(0,37,-2,minecraft:stone)
B(0,38,-2,minecraft:stone)
B(0,39,-2,minecraft:stone)
B(0,40,-2,minecraft:stone)
B(0,41,-2,minecraft:stone)
B(0,25,-1,minecraft:stone)
B(0,26,-1,minecraft:stone)
B(0,27,-1,minecraft:stone)
B(0,28,-1,minecraft:stone)
B(0,29,-1,minecraft:stone)
B(0,30,-1,minecraft:stone)
B(0,31,-1,minecraft:stone)
B(0,32,-1,minecraft:dirt)
B(0,33,-1,minecraft:dirt)
B(0,34,-1,minecraft:dirt)
B(0,35,-1,minecraft:dirt)
B(0,36,-1,minecraft:grass_block)
B(0,32,0,minecraft:dirt)
B(0,33,0,minecraft:dirt)
B(0,34,0,minecraft:dirt)
B(0,35,0,minecraft:dirt)
B(0,36,0,minecraft:grass_block)
B(0,34,1,minecraft:dirt)
B(0,35,1,minecraft:grass_block)
B(0,35,2,minecraft:grass_block)
B(1,15,-7,minecraft:stone)
B(1,16,-7,minecraft:stone)
B(1,17,-7,minecraft:stone)
B(1,18,-7,minecraft:stone)
B(1,19,-7,minecraft:cobblestone)
B(1,20,-7,minecraft:cobblestone)
B(1,21,-7,minecraft:cobblestone)
B(1,22,-7,minecraft:stone)
B(1,23,-7,minecraft:stone)
B(1,24,-7,minecraft:stone)
B(1,25,-7,minecraft:stone)
B(1,26,-7,minecraft:stone)
B(1,27,-7,minecraft:stone)
B(1,28,-7,minecraft:stone)
B(1,29,-7,minecraft:stone)
B(1,30,-7,minecraft:stone)
B(1,31,-7,minecraft:stone)
B(1,32,-7,minecraft:stone)
B(1,33,-7,minecraft:dirt)
B(1,34,-7,minecraft:dirt)
B(1,35,-7,minecraft:dirt)
B(1,36,-7,minecraft:stone)
B(1,37,-7,minecraft:stone)
B(1,10,-6,minecraft:stone)
B(1,11,-6,minecraft:stone)
B(1,12,-6,minecraft:stone)
B(1,13,-6,minecraft:stone)
B(1,14,-6,minecraft:stone)
B(1,15,-6,minecraft:stone)
B(1,16,-6,minecraft:stone)
B(1,17,-6,minecraft:stone)
B(1,18,-6,minecraft:stone)
B(1,19,-6,minecraft:stone)
B(1,20,-6,minecraft:stone)
B(1,21,-6,minecraft:stone)
B(1,22,-6,minecraft:stone)
B(1,23,-6,minecraft:stone)
B(1,24,-6,minecraft:stone)
B(1,25,-6,minecraft:stone)
B(1,26,-6,minecraft:stone)
B(1,27,-6,minecraft:stone)
B(1,28,-6,minecraft:stone)
B(1,29,-6,minecraft:stone)
B(1,30,-6,minecraft:stone)
B(1,31,-6,minecraft:stone)
B(1,32,-6,minecraft:stone)
B(1,33,-6,minecraft:dirt)
B(1,34,-6,minecraft:dirt)
B(1,35,-6,minecraft:dirt)
B(1,36,-6,minecraft:grass_block)
B(1,11,-5,minecraft:stone)
B(1,12,-5,minecraft:stone)
B(1,13,-5,minecraft:stone)
B(1,14,-5,minecraft:cobblestone)
B(1,15,-5,minecraft:cobblestone)
B(1,16,-5,minecraft:stone)
B(1,17,-5,minecraft:stone)
B(1,18,-5,minecraft:stone)
B(1,19,-5,minecraft:stone)
B(1,20,-5,minecraft:stone)
B(1,21,-5,minecraft:stone)
B(1,22,-5,minecraft:stone)
B(1,23,-5,minecraft:stone)
B(1,24,-5,minecraft:stone)
B(1,25,-5,minecraft:stone)
B(1,26,-5,minecraft:stone)
B(1,27,-5,minecraft:stone)
B(1,28,-5,minecraft:stone)
B(1,29,-5,minecraft:stone)
B(1,30,-5,minecraft:stone)
B(1,31,-5,minecraft:stone)
B(1,32,-5,minecraft:stone)
B(1,33,-5,minecraft:dirt)
B(1,34,-5,minecraft:dirt)
B(1,35,-5,minecraft:dirt)
B(1,36,-5,minecraft:grass_block)
B(1,18,-4,minecraft:stone)
B(1,19,-4,minecraft:cobblestone)
B(1,20,-4,minecraft:cobblestone)
B(1,21,-4,minecraft:stone)
B(1,22,-4,minecraft:stone)
B(1,23,-4,minecraft:stone)
B(1,24,-4,minecraft:stone)
B(1,25,-4,minecraft:stone)
B(1,26,-4,minecraft:stone)
B(1,27,-4,minecraft:stone)
B(1,28,-4,minecraft:stone)
B(1,29,-4,minecraft:stone)
B(1,30,-4,minecraft:stone)
B(1,31,-4,minecraft:stone)
B(1,32,-4,minecraft:stone)
B(1,33,-4,minecraft:stone)
B(1,34,-4,minecraft:dirt)
B(1,35,-4,minecraft:dirt)
B(1,36,-4,minecraft:grass_block)
B(1,24,-3,minecraft:cobblestone)
B(1,25,-3,minecraft:cobblestone)
B(1,26,-3,minecraft:stone)
B(1,27,-3,minecraft:stone)
B(1,28,-3,minecraft:stone)
B(1,29,-3,minecraft:stone)
B(1,30,-3,minecraft:stone)
B(1,31,-3,minecraft:stone)
B(1,32,-3,minecraft:stone)
B(1,33,-3,minecraft:dirt)
B(1,34,-3,minecraft:dirt)
B(1,35,-3,minecraft:dirt)
B(1,36,-3,minecraft:stone)
B(1,37,-3,minecraft:stone)
B(1,38,-3,minecraft:stone)
B(1,39,-3,minecraft:stone)
B(1,29,-2,minecraft:stone)
B(1,30,-2,minecraft:stone)
B(1,31,-2,minecraft:stone)
B(1,32,-2,minecraft:cobblestone)
B(1,33,-2,minecraft:dirt)
B(1,34,-2,minecraft:dirt)
B(1,35,-2,minecraft:dirt)
B(1,36,-2,minecraft:stone)
B(1,37,-2,minecraft:dirt)
B(1,38,-2,minecraft:stone)
B(1,39,-2,minecraft:stone)
B(1,31,-1,minecraft:stone)
B(1,32,-1,minecraft:dirt)
B(1,33,-1,minecraft:dirt)
B(1,34,-1,minecraft:dirt)
B(1,35,-1,minecraft:dirt)
B(1,36,-1,minecraft:coarse_dirt)
B(1,37,-1,minecraft:coarse_dirt)
B(1,33,0,minecraft:dirt)
B(1,34,0,minecraft:dirt)
B(1,35,0,minecraft:grass_block)
B(2,5,-7,minecraft:cobblestone)
B(2,6,-7,minecraft:cobblestone)
B(2,7,-7,minecraft:stone)
B(2,8,-7,minecraft:stone)
B(2,9,-7,minecraft:cobblestone)
B(2,10,-7,minecraft:cobblestone)
B(2,11,-7,minecraft:cobblestone)
B(2,12,-7,minecraft:cobblestone)
B(2,13,-7,minecraft:stone)
B(2,14,-7,minecraft:stone)
B(2,15,-7,minecraft:stone)
B(2,16,-7,minecraft:stone)
B(2,17,-7,minecraft:stone)
B(2,18,-7,minecraft:stone)
B(2,19,-7,minecraft:stone)
B(2,20,-7,minecraft:stone)
B(2,21,-7,minecraft:stone)
B(2,22,-7,minecraft:stone)
B(2,23,-7,minecraft:stone)
B(2,24,-7,minecraft:stone)
B(2,25,-7,minecraft:stone)
B(2,26,-7,minecraft:stone)
B(2,27,-7,minecraft:stone)
B(2,28,-7,minecraft:stone)
B(2,29,-7,minecraft:stone)
B(2,30,-7,minecraft:stone)
B(2,31,-7,minecraft:stone)
B(2,32,-7,minecraft:stone)
B(2,33,-7,minecraft:dirt)
B(2,34,-7,minecraft:dirt)
B(2,35,-7,minecraft:grass_block)
B(2,37,-7,minecraft:stone)
B(2,38,-7,minecraft:stone)
B(2,39,-7,minecraft:stone)
B(2,7,-6,minecraft:stone)
B(2,8,-6,minecraft:stone)
B(2,9,-6,minecraft:stone)
B(2,10,-6,minecraft:stone)
B(2,11,-6,minecraft:stone)
B(2,12,-6,minecraft:stone)
B(2,13,-6,minecraft:stone)
B(2,14,-6,minecraft:stone)
B(2,15,-6,minecraft:stone)
B(2,16,-6,minecraft:stone)
B(2,17,-6,minecraft:stone)
B(2,18,-6,minecraft:stone)
B(2,19,-6,minecraft:stone)
B(2,20,-6,minecraft:stone)
B(2,21,-6,minecraft:stone)
B(2,22,-6,minecraft:coal_ore)
B(2,23,-6,minecraft:coal_ore)
B(2,24,-6,minecraft:stone)
B(2,25,-6,minecraft:stone)
B(2,26,-6,minecraft:stone)
B(2,27,-6,minecraft:stone)
B(2,28,-6,minecraft:stone)
B(2,29,-6,minecraft:stone)
B(2,30,-6,minecraft:stone)
B(2,31,-6,minecraft:stone)
B(2,32,-6,minecraft:stone)
B(2,33,-6,minecraft:dirt)
B(2,34,-6,minecraft:dirt)
B(2,35,-6,minecraft:dirt)
B(2,36,-6,minecraft:stone)
B(2,37,-6,minecraft:stone)
B(2,38,-6,minecraft:stone)
B(2,8,-5,minecraft:cobblestone)
B(2,9,-5,minecraft:stone)
B(2,10,-5,minecraft:stone)
B(2,11,-5,minecraft:stone)
B(2,12,-5,minecraft:stone)
B(2,13,-5,minecraft:cobblestone)
B(2,14,-5,minecraft:stone)
B(2,15,-5,minecraft:stone)
B(2,16,-5,minecraft:stone)
B(2,17,-5,minecraft:stone)
B(2,18,-5,minecraft:stone)
B(2,19,-5,minecraft:stone)
B(2,20,-5,minecraft:stone)
B(2,21,-5,minecraft:stone)
B(2,22,-5,minecraft:stone)
B(2,23,-5,minecraft:stone)
B(2,24,-5,minecraft:stone)
B(2,25,-5,minecraft:stone)
B(2,26,-5,minecraft:stone)
B(2,27,-5,minecraft:stone)
B(2,28,-5,minecraft:stone)
B(2,29,-5,minecraft:stone)
B(2,30,-5,minecraft:stone)
B(2,31,-5,minecraft:stone)
B(2,32,-5,minecraft:stone)
B(2,33,-5,minecraft:dirt)
B(2,34,-5,minecraft:dirt)
B(2,35,-5,minecraft:grass_block)
B(2,14,-4,minecraft:cobblestone)
B(2,15,-4,minecraft:cobblestone)
B(2,16,-4,minecraft:cobblestone)
B(2,17,-4,minecraft:stone)
B(2,18,-4,minecraft:cobblestone)
B(2,19,-4,minecraft:cobblestone)
B(2,20,-4,minecraft:stone)
B(2,21,-4,minecraft:stone)
B(2,22,-4,minecraft:stone)
B(2,23,-4,minecraft:stone)
B(2,24,-4,minecraft:stone)
B(2,25,-4,minecraft:stone)
B(2,26,-4,minecraft:stone)
B(2,27,-4,minecraft:stone)
B(2,28,-4,minecraft:stone)
B(2,29,-4,minecraft:stone)
B(2,30,-4,minecraft:stone)
B(2,31,-4,minecraft:stone)
B(2,32,-4,minecraft:stone)
B(2,33,-4,minecraft:stone)
B(2,34,-4,minecraft:dirt)
B(2,35,-4,minecraft:grass_block)
B(2,20,-3,minecraft:cobblestone)
B(2,21,-3,minecraft:cobblestone)
B(2,22,-3,minecraft:stone)
B(2,23,-3,minecraft:cobblestone)
B(2,24,-3,minecraft:cobblestone)
B(2,25,-3,minecraft:cobblestone)
B(2,26,-3,minecraft:cobblestone)
B(2,27,-3,minecraft:stone)
B(2,28,-3,minecraft:stone)
B(2,29,-3,minecraft:stone)
B(2,30,-3,minecraft:stone)
B(2,31,-3,minecraft:stone)
B(2,32,-3,minecraft:stone)
B(2,33,-3,minecraft:dirt)
B(2,34,-3,minecraft:dirt)
B(2,35,-3,minecraft:dirt)
B(2,36,-3,minecraft:grass_block)
B(2,28,-2,minecraft:stone)
B(2,29,-2,minecraft:stone)
B(2,30,-2,minecraft:stone)
B(2,31,-2,minecraft:stone)
B(2,32,-2,minecraft:stone)
B(2,33,-2,minecraft:dirt)
B(2,34,-2,minecraft:dirt)
B(2,35,-2,minecraft:dirt)
B(2,36,-2,minecraft:stone)
B(2,37,-2,minecraft:coarse_dirt)
B(2,33,-1,minecraft:dirt)
B(2,34,-1,minecraft:dirt)
B(2,35,-1,minecraft:dirt)
B(2,36,-1,minecraft:coarse_dirt)
B(2,37,-1,minecraft:coarse_dirt)
B(2,35,0,minecraft:dirt)
B(2,36,0,minecraft:coarse_dirt)
B(3,7,-7,minecraft:cobblestone)
B(3,8,-7,minecraft:cobblestone)
B(3,9,-7,minecraft:cobblestone)
B(3,10,-7,minecraft:cobblestone)
B(3,11,-7,minecraft:cobblestone)
B(3,12,-7,minecraft:cobblestone)
B(3,13,-7,minecraft:stone)
B(3,14,-7,minecraft:stone)
B(3,15,-7,minecraft:stone)
B(3,16,-7,minecraft:stone)
B(3,17,-7,minecraft:stone)
B(3,18,-7,minecraft:stone)
B(3,19,-7,minecraft:stone)
B(3,20,-7,minecraft:stone)
B(3,21,-7,minecraft:stone)
B(3,22,-7,minecraft:stone)
B(3,23,-7,minecraft:stone)
B(3,24,-7,minecraft:stone)
B(3,25,-7,minecraft:stone)
B(3,26,-7,minecraft:stone)
B(3,27,-7,minecraft:stone)
B(3,28,-7,minecraft:stone)
B(3,29,-7,minecraft:stone)
B(3,30,-7,minecraft:stone)
B(3,31,-7,minecraft:stone)
B(3,32,-7,minecraft:stone)
B(3,33,-7,minecraft:dirt)
B(3,34,-7,minecraft:coal_ore)
B(3,35,-7,minecraft:coal_ore)
B(3,36,-7,minecraft:stone)
B(3,37,-7,minecraft:stone)
B(3,38,-7,minecraft:stone)
B(3,39,-7,minecraft:stone)
B(3,40,-7,minecraft:stone)
B(3,13,-6,minecraft:stone)
B(3,14,-6,minecraft:cobblestone)
B(3,15,-6,minecraft:cobblestone)
B(3,16,-6,minecraft:stone)
B(3,17,-6,minecraft:stone)
B(3,18,-6,minecraft:stone)
B(3,19,-6,minecraft:stone)
B(3,20,-6,minecraft:stone)
B(3,21,-6,minecraft:stone)
B(3,22,-6,minecraft:stone)
B(3,23,-6,minecraft:stone)
B(3,24,-6,minecraft:stone)
B(3,25,-6,minecraft:stone)
B(3,26,-6,minecraft:stone)
B(3,27,-6,minecraft:stone)
B(3,28,-6,minecraft:stone)
B(3,29,-6,minecraft:stone)
B(3,30,-6,minecraft:stone)
B(3,31,-6,minecraft:stone)
B(3,32,-6,minecraft:stone)
B(3,33,-6,minecraft:dirt)
B(3,34,-6,minecraft:dirt)
B(3,35,-6,minecraft:dirt)
B(3,36,-6,minecraft:stone)
B(3,37,-6,minecraft:stone)
B(3,14,-5,minecraft:cobblestone)
B(3,15,-5,minecraft:cobblestone)
B(3,16,-5,minecraft:cobblestone)
B(3,17,-5,minecraft:stone)
B(3,18,-5,minecraft:stone)
B(3,19,-5,minecraft:cobblestone)
B(3,20,-5,minecraft:stone)
B(3,21,-5,minecraft:stone)
B(3,22,-5,minecraft:stone)
B(3,23,-5,minecraft:stone)
B(3,24,-5,minecraft:stone)
B(3,25,-5,minecraft:stone)
B(3,26,-5,minecraft:stone)
B(3,27,-5,minecraft:stone)
B(3,28,-5,minecraft:stone)
B(3,29,-5,minecraft:stone)
B(3,30,-5,minecraft:stone)
B(3,31,-5,minecraft:stone)
B(3,32,-5,minecraft:stone)
B(3,33,-5,minecraft:stone)
B(3,34,-5,minecraft:dirt)
B(3,35,-5,minecraft:dirt)
B(3,36,-5,minecraft:grass_block)
B(3,15,-4,minecraft:cobblestone)
B(3,16,-4,minecraft:cobblestone)
B(3,17,-4,minecraft:stone)
B(3,18,-4,minecraft:cobblestone)
B(3,19,-4,minecraft:cobblestone)
B(3,20,-4,minecraft:cobblestone)
B(3,21,-4,minecraft:stone)
B(3,22,-4,minecraft:stone)
B(3,23,-4,minecraft:stone)
B(3,24,-4,minecraft:stone)
B(3,25,-4,minecraft:stone)
B(3,26,-4,minecraft:stone)
B(3,27,-4,minecraft:stone)
B(3,28,-4,minecraft:stone)
B(3,29,-4,minecraft:stone)
B(3,30,-4,minecraft:stone)
B(3,31,-4,minecraft:stone)
B(3,32,-4,minecraft:stone)
B(3,33,-4,minecraft:stone)
B(3,34,-4,minecraft:dirt)
B(3,35,-4,minecraft:grass_block)
B(3,20,-3,minecraft:cobblestone)
B(3,21,-3,minecraft:cobblestone)
B(3,22,-3,minecraft:cobblestone)
B(3,23,-3,minecraft:cobblestone)
B(3,24,-3,minecraft:cobblestone)
B(3,25,-3,minecraft:cobblestone)
B(3,26,-3,minecraft:cobblestone)
B(3,27,-3,minecraft:stone)
B(3,28,-3,minecraft:stone)
B(3,29,-3,minecraft:stone)
B(3,30,-3,minecraft:stone)
B(3,31,-3,minecraft:stone)
B(3,32,-3,minecraft:stone)
B(3,33,-3,minecraft:dirt)
B(3,34,-3,minecraft:dirt)
B(3,35,-3,minecraft:dirt)
B(3,36,-3,minecraft:coarse_dirt)
B(3,26,-2,minecraft:stone)
B(3,27,-2,minecraft:stone)
B(3,28,-2,minecraft:stone)
B(3,29,-2,minecraft:cobblestone)
B(3,30,-2,minecraft:cobblestone)
B(3,31,-2,minecraft:stone)
B(3,32,-2,minecraft:stone)
B(3,33,-2,minecraft:dirt)
B(3,34,-2,minecraft:dirt)
B(3,35,-2,minecraft:dirt)
B(3,36,-2,minecraft:coarse_dirt)
B(3,32,-1,minecraft:stone)
B(3,33,-1,minecraft:dirt)
B(3,34,-1,minecraft:dirt)
B(3,35,-1,minecraft:dirt)
B(3,36,-1,minecraft:coarse_dirt)
B(3,35,0,minecraft:grass_block)
B(4,7,-7,minecraft:cobblestone)
B(4,8,-7,minecraft:stone)
B(4,9,-7,minecraft:stone)
B(4,10,-7,minecraft:cobblestone)
B(4,11,-7,minecraft:cobblestone)
B(4,12,-7,minecraft:cobblestone)
B(4,13,-7,minecraft:cobblestone)
B(4,14,-7,minecraft:cobblestone)
B(4,15,-7,minecraft:cobblestone)
B(4,16,-7,minecraft:cobblestone)
B(4,17,-7,minecraft:stone)
B(4,18,-7,minecraft:stone)
B(4,19,-7,minecraft:stone)
B(4,20,-7,minecraft:stone)
B(4,21,-7,minecraft:stone)
B(4,22,-7,minecraft:stone)
B(4,23,-7,minecraft:stone)
B(4,24,-7,minecraft:stone)
B(4,25,-7,minecraft:stone)
B(4,26,-7,minecraft:stone)
B(4,27,-7,minecraft:stone)
B(4,28,-7,minecraft:stone)
B(4,29,-7,minecraft:stone)
B(4,30,-7,minecraft:stone)
B(4,31,-7,minecraft:stone)
B(4,32,-7,minecraft:stone)
B(4,33,-7,minecraft:dirt)
B(4,34,-7,minecraft:coal_ore)
B(4,35,-7,minecraft:coal_ore)
B(4,36,-7,minecraft:stone)
B(4,37,-7,minecraft:stone)
B(4,38,-7,minecraft:stone)
B(4,39,-7,minecraft:stone)
B(4,40,-7,minecraft:stone)
B(4,41,-7,minecraft:stone)
B(4,42,-7,minecraft:stone)
B(4,43,-7,minecraft:stone)
B(4,44,-7,minecraft:stone)
B(4,17,-6,minecraft:stone)
B(4,18,-6,minecraft:stone)
B(4,19,-6,minecraft:stone)
B(4,20,-6,minecraft:stone)
B(4,21,-6,minecraft:stone)
B(4,22,-6,minecraft:stone)
B(4,23,-6,minecraft:stone)
B(4,24,-6,minecraft:stone)
B(4,25,-6,minecraft:stone)
B(4,26,-6,minecraft:stone)
B(4,27,-6,minecraft:stone)
B(4,28,-6,minecraft:stone)
B(4,29,-6,minecraft:stone)
B(4,30,-6,minecraft:stone)
B(4,31,-6,minecraft:stone)
B(4,32,-6,minecraft:stone)
B(4,33,-6,minecraft:dirt)
B(4,34,-6,minecraft:dirt)
B(4,35,-6,minecraft:dirt)
B(4,36,-6,minecraft:stone)
B(4,37,-6,minecraft:dirt)
B(4,38,-6,minecraft:dirt)
B(4,39,-6,minecraft:stone)
B(4,22,-5,minecraft:stone)
B(4,23,-5,minecraft:stone)
B(4,24,-5,minecraft:stone)
B(4,25,-5,minecraft:stone)
B(4,26,-5,minecraft:cobblestone)
B(4,27,-5,minecraft:stone)
B(4,28,-5,minecraft:stone)
B(4,29,-5,minecraft:stone)
B(4,30,-5,minecraft:stone)
B(4,31,-5,minecraft:stone)
B(4,32,-5,minecraft:stone)
B(4,33,-5,minecraft:stone)
B(4,34,-5,minecraft:dirt)
B(4,35,-5,minecraft:dirt)
B(4,36,-5,minecraft:coarse_dirt)
B(4,23,-4,minecraft:stone)
B(4,24,-4,minecraft:stone)
B(4,25,-4,minecraft:cobblestone)
B(4,26,-4,minecraft:cobblestone)
B(4,27,-4,minecraft:cobblestone)
B(4,28,-4,minecraft:cobblestone)
B(4,29,-4,minecraft:stone)
B(4,30,-4,minecraft:stone)
B(4,31,-4,minecraft:stone)
B(4,32,-4,minecraft:stone)
B(4,33,-4,minecraft:stone)
B(4,34,-4,minecraft:dirt)
B(4,35,-4,minecraft:grass_block)
B(4,27,-3,minecraft:cobblestone)
B(4,28,-3,minecraft:cobblestone)
B(4,29,-3,minecraft:cobblestone)
B(4,30,-3,minecraft:cobblestone)
B(4,31,-3,minecraft:cobblestone)
B(4,32,-3,minecraft:stone)
B(4,33,-3,minecraft:stone)
B(4,34,-3,minecraft:dirt)
B(4,35,-3,minecraft:grass_block)
B(4,30,-2,minecraft:cobblestone)
B(4,31,-2,minecraft:cobblestone)
B(4,32,-2,minecraft:stone)
B(4,33,-2,minecraft:dirt)
B(4,34,-2,minecraft:dirt)
B(4,35,-2,minecraft:coarse_dirt)
B(4,33,-1,minecraft:dirt)
B(4,34,-1,minecraft:dirt)
B(4,35,-1,minecraft:coarse_dirt)
B(5,13,-7,minecraft:stone)
B(5,14,-7,minecraft:stone)
B(5,15,-7,minecraft:stone)
B(5,16,-7,minecraft:stone)
B(5,17,-7,minecraft:stone)
B(5,18,-7,minecraft:cobblestone)
B(5,19,-7,minecraft:cobblestone)
B(5,20,-7,minecraft:stone)
B(5,21,-7,minecraft:stone)
B(5,22,-7,minecraft:stone)
B(5,23,-7,minecraft:stone)
B(5,24,-7,minecraft:stone)
B(5,25,-7,minecraft:stone)
B(5,26,-7,minecraft:stone)
B(5,27,-7,minecraft:stone)
B(5,28,-7,minecraft:stone)
B(5,29,-7,minecraft:stone)
B(5,30,-7,minecraft:stone)
B(5,31,-7,minecraft:stone)
B(5,32,-7,minecraft:stone)
B(5,33,-7,minecraft:dirt)
B(5,34,-7,minecraft:dirt)
B(5,35,-7,minecraft:dirt)
B(5,36,-7,minecraft:stone)
B(5,37,-7,minecraft:dirt)
B(5,38,-7,minecraft:stone)
B(5,39,-7,minecraft:stone)
B(5,40,-7,minecraft:stone)
B(5,41,-7,minecraft:stone)
B(5,14,-6,minecraft:stone)
B(5,15,-6,minecraft:stone)
B(5,16,-6,minecraft:stone)
B(5,17,-6,minecraft:stone)
B(5,18,-6,minecraft:stone)
B(5,19,-6,minecraft:stone)
B(5,20,-6,minecraft:stone)
B(5,21,-6,minecraft:stone)
B(5,22,-6,minecraft:stone)
B(5,23,-6,minecraft:stone)
B(5,24,-6,minecraft:stone)
B(5,25,-6,minecraft:stone)
B(5,26,-6,minecraft:stone)
B(5,27,-6,minecraft:stone)
B(5,28,-6,minecraft:stone)
B(5,29,-6,minecraft:stone)
B(5,30,-6,minecraft:stone)
B(5,31,-6,minecraft:stone)
B(5,32,-6,minecraft:stone)
B(5,33,-6,minecraft:stone)
B(5,34,-6,minecraft:dirt)
B(5,35,-6,minecraft:dirt)
B(5,36,-6,minecraft:dirt)
B(5,37,-6,minecraft:dirt)
B(5,24,-5,minecraft:stone)
B(5,25,-5,minecraft:stone)
B(5,26,-5,minecraft:stone)
B(5,27,-5,minecraft:stone)
B(5,28,-5,minecraft:cobblestone)
B(5,29,-5,minecraft:stone)
B(5,30,-5,minecraft:stone)
B(5,31,-5,minecraft:stone)
B(5,32,-5,minecraft:stone)
B(5,33,-5,minecraft:dirt)
B(5,34,-5,minecraft:dirt)
B(5,35,-5,minecraft:coarse_dirt)
B(5,29,-4,minecraft:cobblestone)
B(5,30,-4,minecraft:cobblestone)
B(5,31,-4,minecraft:cobblestone)
B(5,32,-4,minecraft:cobblestone)
B(5,33,-4,minecraft:dirt)
B(5,34,-4,minecraft:dirt)
B(5,35,-4,minecraft:grass_block)
B(5,31,-3,minecraft:cobblestone)
B(5,32,-3,minecraft:stone)
B(5,33,-3,minecraft:dirt)
B(5,34,-3,minecraft:dirt)
B(5,35,-3,minecraft:grass_block)
B(5,33,-2,minecraft:dirt)
B(5,34,-2,minecraft:dirt)
B(5,35,-2,minecraft:coarse_dirt)
B(5,35,-1,minecraft:grass_block)
B(6,22,-7,minecraft:stone)
B(6,23,-7,minecraft:stone)
B(6,24,-7,minecraft:stone)
B(6,25,-7,minecraft:stone)
B(6,26,-7,minecraft:cobblestone)
B(6,27,-7,minecraft:cobblestone)
B(6,28,-7,minecraft:cobblestone)
B(6,29,-7,minecraft:stone)
B(6,30,-7,minecraft:stone)
B(6,31,-7,minecraft:stone)
B(6,32,-7,minecraft:stone)
B(6,33,-7,minecraft:dirt)
B(6,34,-7,minecraft:dirt)
B(6,35,-7,minecraft:dirt)
B(6,36,-7,minecraft:stone)
B(6,37,-7,minecraft:stone)
B(6,38,-7,minecraft:stone)
B(6,39,-7,minecraft:stone)
B(6,19,-6,minecraft:stone)
B(6,20,-6,minecraft:stone)
B(6,21,-6,minecraft:stone)
B(6,22,-6,minecraft:stone)
B(6,23,-6,minecraft:stone)
B(6,24,-6,minecraft:stone)
B(6,25,-6,minecraft:stone)
B(6,26,-6,minecraft:coal_ore)
B(6,27,-6,minecraft:stone)
B(6,28,-6,minecraft:stone)
B(6,29,-6,minecraft:stone)
B(6,30,-6,minecraft:stone)
B(6,31,-6,minecraft:stone)
B(6,32,-6,minecraft:stone)
B(6,33,-6,minecraft:stone)
B(6,34,-6,minecraft:dirt)
B(6,35,-6,minecraft:dirt)
B(6,36,-6,minecraft:coarse_dirt)
B(6,23,-5,minecraft:stone)
B(6,24,-5,minecraft:stone)
B(6,25,-5,minecraft:cobblestone)
B(6,26,-5,minecraft:cobblestone)
B(6,27,-5,minecraft:stone)
B(6,28,-5,minecraft:stone)
B(6,29,-5,minecraft:cobblestone)
B(6,30,-5,minecraft:cobblestone)
B(6,31,-5,minecraft:stone)
B(6,32,-5,minecraft:stone)
B(6,33,-5,minecraft:dirt)
B(6,34,-5,minecraft:dirt)
B(6,35,-5,minecraft:grass_block)
B(6,31,-4,minecraft:cobblestone)
B(6,32,-4,minecraft:cobblestone)
B(6,33,-4,minecraft:dirt)
B(6,34,-4,minecraft:dirt)
B(6,35,-4,minecraft:coarse_dirt)
B(6,34,-3,minecraft:dirt)
B(6,35,-3,minecraft:coarse_dirt)
B(6,35,-2,minecraft:grass_block)
B(7,29,-7,minecraft:stone)
B(7,30,-7,minecraft:stone)
B(7,31,-7,minecraft:stone)
B(7,32,-7,minecraft:cobblestone)
B(7,33,-7,minecraft:dirt)
B(7,34,-7,minecraft:dirt)
B(7,35,-7,minecraft:dirt)
B(7,36,-7,minecraft:dirt)
B(7,37,-7,minecraft:grass_block)
B(7,26,-6,minecraft:cobblestone)
B(7,27,-6,minecraft:cobblestone)
B(7,28,-6,minecraft:cobblestone)
B(7,29,-6,minecraft:cobblestone)
B(7,30,-6,minecraft:cobblestone)
B(7,31,-6,minecraft:cobblestone)
B(7,32,-6,minecraft:stone)
B(7,33,-6,minecraft:stone)
B(7,34,-6,minecraft:dirt)
B(7,35,-6,minecraft:dirt)
B(7,36,-6,minecraft:coarse_dirt)
B(7,27,-5,minecraft:stone)
B(7,28,-5,minecraft:stone)
B(7,29,-5,minecraft:cobblestone)
B(7,30,-5,minecraft:cobblestone)
B(7,31,-5,minecraft:cobblestone)
B(7,32,-5,minecraft:stone)
B(7,33,-5,minecraft:dirt)
B(7,34,-5,minecraft:dirt)
B(7,35,-5,minecraft:grass_block)
B(7,29,-4,minecraft:cobblestone)
B(7,30,-4,minecraft:cobblestone)
B(7,31,-4,minecraft:cobblestone)
B(7,32,-4,minecraft:cobblestone)
B(7,33,-4,minecraft:dirt)
B(7,34,-4,minecraft:dirt)
B(7,35,-4,minecraft:coarse_dirt)
B(7,34,-3,minecraft:dirt)
B(7,35,-3,minecraft:coarse_dirt)

#######################################################################
# +-----------------------------------------------------------------+ #
# |                             Branches                            | #
# +-----------------------------------------------------------------+ #
#######################################################################

Branch(16,0,0,true,afloatingisland3_C1_R1,NORTH,100.0,0)

#######################################################################
# +-----------------------------------------------------------------+ #
# |                             Entities                            | #
# +-----------------------------------------------------------------+ #
#######################################################################

