
#######################################################################
# +-----------------------------------------------------------------+ #
# |                            BO3 object                           | #
# +-----------------------------------------------------------------+ #
#######################################################################

Author: Unknown

Description: No description given

Version: 3

SettingsMode: WriteWithoutComments


#######################################################################
# +-----------------------------------------------------------------+ #
# |                          Main settings                          | #
# +-----------------------------------------------------------------+ #
#######################################################################

Tree: true

Frequency: 1

Rarity: 10.0

MaxSpawn: 0

RotateRandomly: true

SpawnHeight: highestSolidBlock

SpawnHeightOffset: -3

SpawnHeightVariance: 0

##############################
# Height Limits for the BO3. #
##############################

MinHeight: 52

MaxHeight: 62

######################
# Extrusion settings #
######################

ExtrudeMode: BottomDown

ExtrudeThroughBlocks: otg:air,minecraft:water

MaxBranchDepth: 10


#######################################################################
# +-----------------------------------------------------------------+ #
# |                      Source block settings                      | #
# +-----------------------------------------------------------------+ #
#######################################################################

SourceBlocks: otg:air

MaxPercentageOutsideSourceBlock: 100

OutsideSourceBlock: placeAnyway

DoReplaceBlocks: true

IsOTGPlus: false


#######################################################################
# +-----------------------------------------------------------------+ #
# |                              Blocks                             | #
# +-----------------------------------------------------------------+ #
#######################################################################

B(-11,0,-10,minecraft:stone)
B(-11,0,-9,minecraft:stone)
B(-11,0,-8,minecraft:stone)
B(-11,0,-7,minecraft:stone)
B(-11,0,5,minecraft:stone)
B(-11,0,6,minecraft:stone)
B(-11,0,7,minecraft:stone)
B(-11,0,8,minecraft:stone)
B(-11,1,-9,minecraft:stone)
B(-11,1,-8,minecraft:stone)
B(-11,1,6,minecraft:stone)
B(-11,1,7,minecraft:stone)
B(-10,0,-11,minecraft:stone)
B(-10,0,-10,minecraft:stone)
B(-10,0,-9,minecraft:stone)
B(-10,0,-8,minecraft:stone)
B(-10,0,-7,minecraft:stone)
B(-10,0,-6,minecraft:stone)
B(-10,0,4,minecraft:stone)
B(-10,0,5,minecraft:stone)
B(-10,0,6,minecraft:stone)
B(-10,0,7,minecraft:stone)
B(-10,0,8,minecraft:stone)
B(-10,1,-10,minecraft:stone)
B(-10,1,-9,minecraft:stone)
B(-10,1,-8,minecraft:stone)
B(-10,1,-7,minecraft:stone)
B(-10,1,5,minecraft:stone)
B(-10,1,6,minecraft:stone)
B(-10,1,7,minecraft:stone)
B(-10,1,8,minecraft:stone)
B(-10,2,-10,minecraft:stone)
B(-10,2,-9,minecraft:stone)
B(-10,2,-8,minecraft:stone)
B(-10,2,5,minecraft:stone)
B(-10,2,6,minecraft:stone)
B(-10,2,7,minecraft:stone)
B(-9,0,-11,minecraft:stone)
B(-9,0,-10,minecraft:stone)
B(-9,0,-9,minecraft:stone)
B(-9,0,-8,minecraft:stone)
B(-9,0,-7,minecraft:stone)
B(-9,0,-6,minecraft:stone)
B(-9,0,-5,minecraft:stone)
B(-9,0,4,minecraft:stone)
B(-9,0,5,minecraft:stone)
B(-9,0,6,minecraft:stone)
B(-9,0,7,minecraft:stone)
B(-9,0,8,minecraft:stone)
B(-9,0,9,minecraft:stone)
B(-9,0,10,minecraft:stone)
B(-9,1,-10,minecraft:stone)
B(-9,1,-9,minecraft:stone)
B(-9,1,-8,minecraft:stone)
B(-9,1,-7,minecraft:stone)
B(-9,1,-6,minecraft:stone)
B(-9,1,5,minecraft:stone)
B(-9,1,6,minecraft:stone)
B(-9,1,7,minecraft:stone)
B(-9,1,8,minecraft:stone)
B(-9,2,-10,minecraft:stone)
B(-9,2,-9,minecraft:stone)
B(-9,2,-8,minecraft:stone)
B(-9,2,-7,minecraft:stone)
B(-9,2,5,minecraft:stone)
B(-9,2,6,minecraft:stone)
B(-9,2,7,minecraft:stone)
B(-9,2,8,minecraft:stone)
B(-9,3,-9,minecraft:stone)
B(-9,3,-8,minecraft:stone)
B(-9,3,-7,minecraft:stone)
B(-9,3,6,minecraft:stone)
B(-9,3,7,minecraft:stone)
B(-8,0,-13,minecraft:stone)
B(-8,0,-12,minecraft:stone)
B(-8,0,-11,minecraft:stone)
B(-8,0,-10,minecraft:stone)
B(-8,0,-9,minecraft:stone)
B(-8,0,-8,minecraft:stone)
B(-8,0,-7,minecraft:stone)
B(-8,0,-6,minecraft:stone)
B(-8,0,-5,minecraft:stone)
B(-8,0,-4,minecraft:stone)
B(-8,0,-3,minecraft:stone)
B(-8,0,-2,minecraft:stone)
B(-8,0,4,minecraft:stone)
B(-8,0,5,minecraft:stone)
B(-8,0,6,minecraft:stone)
B(-8,0,7,minecraft:stone)
B(-8,0,8,minecraft:stone)
B(-8,0,9,minecraft:stone)
B(-8,0,10,minecraft:stone)
B(-8,0,11,minecraft:stone)
B(-8,0,12,minecraft:stone)
B(-8,0,13,minecraft:stone)
B(-8,1,-10,minecraft:stone)
B(-8,1,-9,minecraft:stone)
B(-8,1,-8,minecraft:stone)
B(-8,1,-7,minecraft:stone)
B(-8,1,-6,minecraft:stone)
B(-8,1,-5,minecraft:stone)
B(-8,1,5,minecraft:stone)
B(-8,1,6,minecraft:stone)
B(-8,1,7,minecraft:stone)
B(-8,1,8,minecraft:stone)
B(-8,1,9,minecraft:stone)
B(-8,1,10,minecraft:stone)
B(-8,2,-9,minecraft:stone)
B(-8,2,-8,minecraft:stone)
B(-8,2,-7,minecraft:stone)
B(-8,2,-6,minecraft:stone)
B(-8,2,6,minecraft:stone)
B(-8,2,7,minecraft:stone)
B(-8,2,8,minecraft:stone)
B(-8,2,9,minecraft:stone)
B(-8,3,-9,minecraft:stone)
B(-8,3,-8,minecraft:stone)
B(-8,3,-7,minecraft:stone)
B(-8,3,6,minecraft:stone)
B(-8,3,7,minecraft:stone)
B(-8,3,8,minecraft:stone)
B(-8,4,-9,minecraft:stone)
B(-8,4,-8,minecraft:stone)
B(-8,4,-7,minecraft:stone)
B(-8,4,6,minecraft:stone)
B(-8,4,7,minecraft:stone)
B(-8,4,8,minecraft:stone)
B(-7,0,-13,minecraft:stone)
B(-7,0,-12,minecraft:stone)
B(-7,0,-11,minecraft:stone)
B(-7,0,-10,minecraft:stone)
B(-7,0,-9,minecraft:stone)
B(-7,0,-8,minecraft:stone)
B(-7,0,-7,minecraft:stone)
B(-7,0,-6,minecraft:stone)
B(-7,0,-5,minecraft:stone)
B(-7,0,-4,minecraft:stone)
B(-7,0,-3,minecraft:stone)
B(-7,0,-2,minecraft:stone)
B(-7,0,2,minecraft:stone)
B(-7,0,3,minecraft:stone)
B(-7,0,4,minecraft:stone)
B(-7,0,5,minecraft:stone)
B(-7,0,6,minecraft:stone)
B(-7,0,7,minecraft:stone)
B(-7,0,8,minecraft:stone)
B(-7,0,9,minecraft:stone)
B(-7,0,10,minecraft:stone)
B(-7,0,11,minecraft:stone)
B(-7,0,12,minecraft:stone)
B(-7,0,13,minecraft:stone)
B(-7,1,-13,minecraft:stone)
B(-7,1,-12,minecraft:stone)
B(-7,1,-10,minecraft:stone)
B(-7,1,-9,minecraft:stone)
B(-7,1,-8,minecraft:stone)
B(-7,1,-7,minecraft:stone)
B(-7,1,-6,minecraft:stone)
B(-7,1,-5,minecraft:stone)
B(-7,1,-4,minecraft:stone)
B(-7,1,-3,minecraft:stone)
B(-7,1,2,minecraft:stone)
B(-7,1,3,minecraft:stone)
B(-7,1,5,minecraft:stone)
B(-7,1,6,minecraft:stone)
B(-7,1,7,minecraft:stone)
B(-7,1,8,minecraft:stone)
B(-7,1,9,minecraft:stone)
B(-7,1,10,minecraft:stone)
B(-7,1,11,minecraft:stone)
B(-7,2,-9,minecraft:stone)
B(-7,2,-8,minecraft:stone)
B(-7,2,-7,minecraft:stone)
B(-7,2,-6,minecraft:stone)
B(-7,2,6,minecraft:stone)
B(-7,2,7,minecraft:stone)
B(-7,2,8,minecraft:stone)
B(-7,2,9,minecraft:stone)
B(-7,3,-9,minecraft:stone)
B(-7,3,-8,minecraft:stone)
B(-7,3,-7,minecraft:stone)
B(-7,3,6,minecraft:stone)
B(-7,3,7,minecraft:stone)
B(-7,3,8,minecraft:stone)
B(-7,4,-8,minecraft:stone)
B(-7,4,-7,minecraft:stone)
B(-7,4,7,minecraft:stone)
B(-7,4,8,minecraft:stone)
B(-6,0,-13,minecraft:stone)
B(-6,0,-12,minecraft:stone)
B(-6,0,-11,minecraft:stone)
B(-6,0,-10,minecraft:stone)
B(-6,0,-9,minecraft:stone)
B(-6,0,-8,minecraft:stone)
B(-6,0,-7,minecraft:stone)
B(-6,0,-6,minecraft:stone)
B(-6,0,-5,minecraft:stone)
B(-6,0,-4,minecraft:stone)
B(-6,0,-3,minecraft:stone)
B(-6,0,-2,minecraft:stone)
B(-6,0,2,minecraft:stone)
B(-6,0,3,minecraft:stone)
B(-6,0,4,minecraft:stone)
B(-6,0,5,minecraft:stone)
B(-6,0,6,minecraft:stone)
B(-6,0,7,minecraft:stone)
B(-6,0,8,minecraft:stone)
B(-6,0,9,minecraft:stone)
B(-6,0,10,minecraft:stone)
B(-6,0,11,minecraft:stone)
B(-6,0,12,minecraft:stone)
B(-6,0,13,minecraft:stone)
B(-6,1,-13,minecraft:stone)
B(-6,1,-12,minecraft:stone)
B(-6,1,-11,minecraft:stone)
B(-6,1,-10,minecraft:stone)
B(-6,1,-9,minecraft:stone)
B(-6,1,-8,minecraft:stone)
B(-6,1,-7,minecraft:stone)
B(-6,1,-6,minecraft:stone)
B(-6,1,-5,minecraft:stone)
B(-6,1,-4,minecraft:stone)
B(-6,1,-3,minecraft:stone)
B(-6,1,3,minecraft:stone)
B(-6,1,4,minecraft:stone)
B(-6,1,5,minecraft:stone)
B(-6,1,6,minecraft:stone)
B(-6,1,7,minecraft:stone)
B(-6,1,8,minecraft:stone)
B(-6,1,9,minecraft:stone)
B(-6,1,10,minecraft:stone)
B(-6,1,11,minecraft:stone)
B(-6,1,12,minecraft:stone)
B(-6,2,-12,minecraft:stone)
B(-6,2,-11,minecraft:stone)
B(-6,2,-10,minecraft:stone)
B(-6,2,-9,minecraft:stone)
B(-6,2,-8,minecraft:stone)
B(-6,2,-7,minecraft:stone)
B(-6,2,-6,minecraft:stone)
B(-6,2,-5,minecraft:stone)
B(-6,2,-4,minecraft:stone)
B(-6,2,3,minecraft:stone)
B(-6,2,4,minecraft:stone)
B(-6,2,5,minecraft:stone)
B(-6,2,6,minecraft:stone)
B(-6,2,7,minecraft:stone)
B(-6,2,8,minecraft:stone)
B(-6,2,9,minecraft:stone)
B(-6,2,10,minecraft:stone)
B(-6,2,11,minecraft:stone)
B(-6,3,-10,minecraft:stone)
B(-6,3,-8,minecraft:stone)
B(-6,3,-7,minecraft:stone)
B(-6,3,-6,minecraft:stone)
B(-6,3,-5,minecraft:stone)
B(-6,3,-4,minecraft:stone)
B(-6,3,5,minecraft:stone)
B(-6,3,7,minecraft:stone)
B(-6,3,8,minecraft:stone)
B(-6,3,9,minecraft:stone)
B(-6,3,10,minecraft:stone)
B(-6,3,11,minecraft:stone)
B(-6,4,-8,minecraft:stone)
B(-6,4,-7,minecraft:stone)
B(-6,4,-5,minecraft:stone)
B(-6,4,7,minecraft:stone)
B(-6,4,8,minecraft:stone)
B(-5,0,-14,minecraft:stone)
B(-5,0,-13,minecraft:stone)
B(-5,0,-12,minecraft:stone)
B(-5,0,-11,minecraft:stone)
B(-5,0,-10,minecraft:stone)
B(-5,0,-9,minecraft:stone)
B(-5,0,-8,minecraft:stone)
B(-5,0,-7,minecraft:stone)
B(-5,0,-6,minecraft:stone)
B(-5,0,-5,minecraft:stone)
B(-5,0,-4,minecraft:stone)
B(-5,0,-3,minecraft:stone)
B(-5,0,-2,minecraft:stone)
B(-5,0,1,minecraft:stone)
B(-5,0,2,minecraft:stone)
B(-5,0,3,minecraft:stone)
B(-5,0,4,minecraft:stone)
B(-5,0,5,minecraft:stone)
B(-5,0,6,minecraft:stone)
B(-5,0,7,minecraft:stone)
B(-5,0,8,minecraft:stone)
B(-5,0,9,minecraft:stone)
B(-5,0,10,minecraft:stone)
B(-5,0,11,minecraft:stone)
B(-5,0,12,minecraft:stone)
B(-5,0,13,minecraft:stone)
B(-5,1,-13,minecraft:stone)
B(-5,1,-12,minecraft:stone)
B(-5,1,-11,minecraft:stone)
B(-5,1,-10,minecraft:stone)
B(-5,1,-9,minecraft:stone)
B(-5,1,-8,minecraft:stone)
B(-5,1,-7,minecraft:stone)
B(-5,1,-6,minecraft:stone)
B(-5,1,-5,minecraft:stone)
B(-5,1,-4,minecraft:stone)
B(-5,1,-3,minecraft:stone)
B(-5,1,2,minecraft:stone)
B(-5,1,3,minecraft:stone)
B(-5,1,4,minecraft:stone)
B(-5,1,5,minecraft:stone)
B(-5,1,6,minecraft:stone)
B(-5,1,7,minecraft:stone)
B(-5,1,8,minecraft:stone)
B(-5,1,9,minecraft:stone)
B(-5,1,10,minecraft:stone)
B(-5,1,11,minecraft:stone)
B(-5,1,12,minecraft:stone)
B(-5,2,-12,minecraft:stone)
B(-5,2,-11,minecraft:stone)
B(-5,2,-10,minecraft:stone)
B(-5,2,-9,minecraft:stone)
B(-5,2,-8,minecraft:stone)
B(-5,2,-7,minecraft:stone)
B(-5,2,-6,minecraft:stone)
B(-5,2,-5,minecraft:stone)
B(-5,2,-4,minecraft:stone)
B(-5,2,-3,minecraft:stone)
B(-5,2,3,minecraft:stone)
B(-5,2,4,minecraft:stone)
B(-5,2,5,minecraft:stone)
B(-5,2,6,minecraft:stone)
B(-5,2,7,minecraft:stone)
B(-5,2,8,minecraft:stone)
B(-5,2,9,minecraft:stone)
B(-5,2,10,minecraft:stone)
B(-5,2,11,minecraft:stone)
B(-5,2,12,minecraft:stone)
B(-5,3,-12,minecraft:stone)
B(-5,3,-11,minecraft:stone)
B(-5,3,-10,minecraft:stone)
B(-5,3,-9,minecraft:stone)
B(-5,3,-8,minecraft:stone)
B(-5,3,-7,minecraft:stone)
B(-5,3,-6,minecraft:stone)
B(-5,3,-5,minecraft:stone)
B(-5,3,-4,minecraft:stone)
B(-5,3,-3,minecraft:stone)
B(-5,3,4,minecraft:stone)
B(-5,3,5,minecraft:stone)
B(-5,3,6,minecraft:stone)
B(-5,3,7,minecraft:stone)
B(-5,3,8,minecraft:stone)
B(-5,3,9,minecraft:stone)
B(-5,3,10,minecraft:stone)
B(-5,3,11,minecraft:stone)
B(-5,4,-10,minecraft:stone)
B(-5,4,-9,minecraft:stone)
B(-5,4,-8,minecraft:stone)
B(-5,4,-7,minecraft:stone)
B(-5,4,-6,minecraft:stone)
B(-5,4,-5,minecraft:stone)
B(-5,4,-4,minecraft:stone)
B(-5,4,5,minecraft:stone)
B(-5,4,6,minecraft:stone)
B(-5,4,9,minecraft:stone)
B(-5,4,10,minecraft:stone)
B(-5,4,11,minecraft:stone)
B(-5,5,-10,minecraft:stone)
B(-5,5,5,minecraft:stone)
B(-4,0,-14,minecraft:stone)
B(-4,0,-13,minecraft:stone)
B(-4,0,-12,minecraft:stone)
B(-4,0,-11,minecraft:stone)
B(-4,0,-10,minecraft:stone)
B(-4,0,-9,minecraft:stone)
B(-4,0,-8,minecraft:stone)
B(-4,0,-7,minecraft:stone)
B(-4,0,-6,minecraft:stone)
B(-4,0,-5,minecraft:stone)
B(-4,0,-4,minecraft:stone)
B(-4,0,-3,minecraft:stone)
B(-4,0,-2,minecraft:stone)
B(-4,0,-1,minecraft:stone)
B(-4,0,1,minecraft:stone)
B(-4,0,2,minecraft:stone)
B(-4,0,3,minecraft:stone)
B(-4,0,4,minecraft:stone)
B(-4,0,5,minecraft:stone)
B(-4,0,6,minecraft:stone)
B(-4,0,7,minecraft:stone)
B(-4,0,8,minecraft:stone)
B(-4,0,9,minecraft:stone)
B(-4,0,10,minecraft:stone)
B(-4,0,11,minecraft:stone)
B(-4,0,12,minecraft:stone)
B(-4,0,13,minecraft:stone)
B(-4,0,14,minecraft:stone)
B(-4,1,-13,minecraft:stone)
B(-4,1,-12,minecraft:stone)
B(-4,1,-11,minecraft:stone)
B(-4,1,-10,minecraft:stone)
B(-4,1,-9,minecraft:stone)
B(-4,1,-8,minecraft:stone)
B(-4,1,-7,minecraft:stone)
B(-4,1,-6,minecraft:stone)
B(-4,1,-5,minecraft:stone)
B(-4,1,-4,minecraft:stone)
B(-4,1,-3,minecraft:stone)
B(-4,1,-2,minecraft:stone)
B(-4,1,2,minecraft:stone)
B(-4,1,3,minecraft:stone)
B(-4,1,4,minecraft:stone)
B(-4,1,5,minecraft:stone)
B(-4,1,6,minecraft:stone)
B(-4,1,7,minecraft:stone)
B(-4,1,8,minecraft:stone)
B(-4,1,9,minecraft:stone)
B(-4,1,10,minecraft:stone)
B(-4,1,11,minecraft:stone)
B(-4,1,12,minecraft:stone)
B(-4,2,-13,minecraft:stone)
B(-4,2,-12,minecraft:stone)
B(-4,2,-11,minecraft:stone)
B(-4,2,-10,minecraft:stone)
B(-4,2,-9,minecraft:stone)
B(-4,2,-8,minecraft:stone)
B(-4,2,-7,minecraft:stone)
B(-4,2,-6,minecraft:stone)
B(-4,2,-5,minecraft:stone)
B(-4,2,-4,minecraft:stone)
B(-4,2,-3,minecraft:stone)
B(-4,2,2,minecraft:stone)
B(-4,2,3,minecraft:stone)
B(-4,2,4,minecraft:stone)
B(-4,2,5,minecraft:stone)
B(-4,2,6,minecraft:stone)
B(-4,2,7,minecraft:stone)
B(-4,2,8,minecraft:stone)
B(-4,2,9,minecraft:stone)
B(-4,2,10,minecraft:stone)
B(-4,2,11,minecraft:stone)
B(-4,2,12,minecraft:stone)
B(-4,3,-11,minecraft:stone)
B(-4,3,-10,minecraft:stone)
B(-4,3,-9,minecraft:stone)
B(-4,3,-8,minecraft:stone)
B(-4,3,-7,minecraft:stone)
B(-4,3,-6,minecraft:stone)
B(-4,3,-5,minecraft:stone)
B(-4,3,-4,minecraft:stone)
B(-4,3,3,minecraft:stone)
B(-4,3,4,minecraft:stone)
B(-4,3,5,minecraft:stone)
B(-4,3,6,minecraft:stone)
B(-4,3,7,minecraft:stone)
B(-4,3,8,minecraft:stone)
B(-4,3,9,minecraft:stone)
B(-4,3,10,minecraft:stone)
B(-4,3,11,minecraft:stone)
B(-4,4,-10,minecraft:stone)
B(-4,4,-7,minecraft:stone)
B(-4,4,-6,minecraft:stone)
B(-4,4,-5,minecraft:stone)
B(-4,4,-4,minecraft:stone)
B(-4,4,3,minecraft:stone)
B(-4,4,4,minecraft:stone)
B(-4,4,5,minecraft:stone)
B(-4,4,8,minecraft:stone)
B(-4,4,9,minecraft:stone)
B(-4,4,10,minecraft:stone)
B(-4,4,11,minecraft:stone)
B(-4,5,-6,minecraft:stone)
B(-4,5,-5,minecraft:stone)
B(-4,5,4,minecraft:stone)
B(-4,5,5,minecraft:stone)
B(-3,0,-14,minecraft:stone)
B(-3,0,-13,minecraft:stone)
B(-3,0,-12,minecraft:stone)
B(-3,0,-11,minecraft:stone)
B(-3,0,-10,minecraft:stone)
B(-3,0,-9,minecraft:stone)
B(-3,0,-8,minecraft:stone)
B(-3,0,-7,minecraft:stone)
B(-3,0,-6,minecraft:stone)
B(-3,0,-5,minecraft:stone)
B(-3,0,-4,minecraft:stone)
B(-3,0,-3,minecraft:stone)
B(-3,0,-2,minecraft:stone)
B(-3,0,-1,minecraft:stone)
B(-3,0,1,minecraft:stone)
B(-3,0,2,minecraft:stone)
B(-3,0,3,minecraft:stone)
B(-3,0,4,minecraft:stone)
B(-3,0,5,minecraft:stone)
B(-3,0,6,minecraft:stone)
B(-3,0,7,minecraft:stone)
B(-3,0,8,minecraft:stone)
B(-3,0,9,minecraft:stone)
B(-3,0,10,minecraft:stone)
B(-3,0,11,minecraft:stone)
B(-3,0,12,minecraft:stone)
B(-3,0,13,minecraft:stone)
B(-3,0,14,minecraft:stone)
B(-3,1,-11,minecraft:stone)
B(-3,1,-10,minecraft:stone)
B(-3,1,-9,minecraft:stone)
B(-3,1,-8,minecraft:stone)
B(-3,1,-7,minecraft:stone)
B(-3,1,-6,minecraft:stone)
B(-3,1,-5,minecraft:stone)
B(-3,1,-4,minecraft:stone)
B(-3,1,-3,minecraft:stone)
B(-3,1,-2,minecraft:stone)
B(-3,1,2,minecraft:stone)
B(-3,1,3,minecraft:stone)
B(-3,1,4,minecraft:stone)
B(-3,1,5,minecraft:stone)
B(-3,1,6,minecraft:stone)
B(-3,1,7,minecraft:stone)
B(-3,1,8,minecraft:stone)
B(-3,1,9,minecraft:stone)
B(-3,1,10,minecraft:stone)
B(-3,1,11,minecraft:stone)
B(-3,1,12,minecraft:stone)
B(-3,1,13,minecraft:stone)
B(-3,2,-9,minecraft:stone)
B(-3,2,-8,minecraft:stone)
B(-3,2,-7,minecraft:stone)
B(-3,2,-6,minecraft:stone)
B(-3,2,-5,minecraft:stone)
B(-3,2,-4,minecraft:stone)
B(-3,2,-3,minecraft:stone)
B(-3,2,2,minecraft:stone)
B(-3,2,3,minecraft:stone)
B(-3,2,4,minecraft:stone)
B(-3,2,5,minecraft:stone)
B(-3,2,6,minecraft:stone)
B(-3,2,7,minecraft:stone)
B(-3,2,8,minecraft:stone)
B(-3,2,9,minecraft:stone)
B(-3,2,10,minecraft:stone)
B(-3,2,11,minecraft:stone)
B(-3,2,12,minecraft:stone)
B(-3,3,-8,minecraft:stone)
B(-3,3,-7,minecraft:stone)
B(-3,3,-6,minecraft:stone)
B(-3,3,-5,minecraft:stone)
B(-3,3,-4,minecraft:stone)
B(-3,3,-3,minecraft:stone)
B(-3,3,2,minecraft:stone)
B(-3,3,3,minecraft:stone)
B(-3,3,4,minecraft:stone)
B(-3,3,5,minecraft:stone)
B(-3,3,6,minecraft:stone)
B(-3,3,7,minecraft:stone)
B(-3,3,8,minecraft:stone)
B(-3,3,9,minecraft:stone)
B(-3,3,10,minecraft:stone)
B(-3,3,11,minecraft:stone)
B(-3,3,12,minecraft:stone)
B(-3,4,-6,minecraft:stone)
B(-3,4,-5,minecraft:stone)
B(-3,4,-4,minecraft:stone)
B(-3,4,-3,minecraft:stone)
B(-3,4,3,minecraft:stone)
B(-3,4,4,minecraft:stone)
B(-3,4,9,minecraft:stone)
B(-3,4,10,minecraft:stone)
B(-3,4,11,minecraft:stone)
B(-3,5,-6,minecraft:stone)
B(-3,5,-5,minecraft:stone)
B(-3,5,-4,minecraft:stone)
B(-3,5,4,minecraft:stone)
B(-2,0,-11,minecraft:stone)
B(-2,0,-10,minecraft:stone)
B(-2,0,-9,minecraft:stone)
B(-2,0,-8,minecraft:stone)
B(-2,0,-7,minecraft:stone)
B(-2,0,-6,minecraft:stone)
B(-2,0,-5,minecraft:stone)
B(-2,0,-4,minecraft:stone)
B(-2,0,-3,minecraft:stone)
B(-2,0,-2,minecraft:stone)
B(-2,0,-1,minecraft:stone)
B(-2,0,0,minecraft:stone)
B(-2,0,1,minecraft:stone)
B(-2,0,2,minecraft:stone)
B(-2,0,3,minecraft:stone)
B(-2,0,4,minecraft:stone)
B(-2,0,5,minecraft:stone)
B(-2,0,6,minecraft:stone)
B(-2,0,7,minecraft:stone)
B(-2,0,8,minecraft:stone)
B(-2,0,9,minecraft:stone)
B(-2,0,10,minecraft:stone)
B(-2,0,11,minecraft:stone)
B(-2,0,12,minecraft:stone)
B(-2,0,13,minecraft:stone)
B(-2,1,-9,minecraft:stone)
B(-2,1,-8,minecraft:stone)
B(-2,1,-7,minecraft:stone)
B(-2,1,-6,minecraft:stone)
B(-2,1,-5,minecraft:stone)
B(-2,1,-4,minecraft:stone)
B(-2,1,-3,minecraft:stone)
B(-2,1,-2,minecraft:stone)
B(-2,1,2,minecraft:stone)
B(-2,1,3,minecraft:stone)
B(-2,1,4,minecraft:stone)
B(-2,1,5,minecraft:stone)
B(-2,1,6,minecraft:stone)
B(-2,1,7,minecraft:stone)
B(-2,1,8,minecraft:stone)
B(-2,1,9,minecraft:stone)
B(-2,1,10,minecraft:stone)
B(-2,1,11,minecraft:stone)
B(-2,1,12,minecraft:stone)
B(-2,2,-8,minecraft:stone)
B(-2,2,-6,minecraft:stone)
B(-2,2,-5,minecraft:stone)
B(-2,2,-4,minecraft:stone)
B(-2,2,-3,minecraft:stone)
B(-2,2,-2,minecraft:stone)
B(-2,2,2,minecraft:stone)
B(-2,2,3,minecraft:stone)
B(-2,2,4,minecraft:stone)
B(-2,2,5,minecraft:stone)
B(-2,2,6,minecraft:stone)
B(-2,2,7,minecraft:stone)
B(-2,2,8,minecraft:stone)
B(-2,2,9,minecraft:stone)
B(-2,2,10,minecraft:stone)
B(-2,2,11,minecraft:stone)
B(-2,2,12,minecraft:stone)
B(-2,3,-6,minecraft:stone)
B(-2,3,-5,minecraft:stone)
B(-2,3,-4,minecraft:stone)
B(-2,3,-3,minecraft:stone)
B(-2,3,3,minecraft:stone)
B(-2,3,4,minecraft:stone)
B(-2,3,5,minecraft:stone)
B(-2,3,6,minecraft:stone)
B(-2,4,-5,minecraft:stone)
B(-2,4,-4,minecraft:stone)
B(-2,4,5,minecraft:stone)
B(-1,0,-11,minecraft:stone)
B(-1,0,-10,minecraft:stone)
B(-1,0,-9,minecraft:stone)
B(-1,0,-8,minecraft:stone)
B(-1,0,-7,minecraft:stone)
B(-1,0,-6,minecraft:stone)
B(-1,0,-5,minecraft:stone)
B(-1,0,-4,minecraft:stone)
B(-1,0,-3,minecraft:stone)
B(-1,0,-2,minecraft:stone)
B(-1,0,-1,minecraft:stone)
B(-1,0,0,minecraft:stone)
B(-1,0,1,minecraft:stone)
B(-1,0,2,minecraft:stone)
B(-1,0,3,minecraft:stone)
B(-1,0,4,minecraft:stone)
B(-1,0,5,minecraft:stone)
B(-1,0,6,minecraft:stone)
B(-1,0,7,minecraft:stone)
B(-1,0,8,minecraft:stone)
B(-1,0,9,minecraft:stone)
B(-1,0,10,minecraft:stone)
B(-1,0,11,minecraft:stone)
B(-1,0,12,minecraft:stone)
B(-1,0,13,minecraft:stone)
B(-1,1,-9,minecraft:stone)
B(-1,1,-8,minecraft:stone)
B(-1,1,-7,minecraft:stone)
B(-1,1,-6,minecraft:stone)
B(-1,1,-5,minecraft:stone)
B(-1,1,-4,minecraft:stone)
B(-1,1,-3,minecraft:stone)
B(-1,1,-2,minecraft:stone)
B(-1,1,-1,minecraft:stone)
B(-1,1,0,minecraft:stone)
B(-1,1,1,minecraft:stone)
B(-1,1,2,minecraft:stone)
B(-1,1,3,minecraft:stone)
B(-1,1,4,minecraft:stone)
B(-1,1,5,minecraft:stone)
B(-1,1,6,minecraft:stone)
B(-1,1,7,minecraft:stone)
B(-1,1,8,minecraft:stone)
B(-1,1,9,minecraft:stone)
B(-1,1,10,minecraft:stone)
B(-1,1,11,minecraft:stone)
B(-1,1,13,minecraft:stone)
B(-1,2,-5,minecraft:stone)
B(-1,2,-4,minecraft:stone)
B(-1,2,-3,minecraft:stone)
B(-1,2,-2,minecraft:stone)
B(-1,2,-1,minecraft:stone)
B(-1,2,0,minecraft:stone)
B(-1,2,3,minecraft:stone)
B(-1,2,4,minecraft:stone)
B(-1,2,5,minecraft:stone)
B(-1,2,6,minecraft:stone)
B(-1,2,7,minecraft:stone)
B(-1,3,3,minecraft:stone)
B(-1,3,4,minecraft:stone)
B(-1,3,5,minecraft:stone)
B(-1,3,6,minecraft:stone)
B(-1,3,7,minecraft:stone)
B(-1,4,3,minecraft:stone)
B(-1,4,4,minecraft:stone)
B(-1,4,5,minecraft:stone)
B(-1,4,6,minecraft:stone)
B(-1,5,4,minecraft:stone)
B(0,0,-9,minecraft:stone)
B(0,0,-8,minecraft:stone)
B(0,0,-7,minecraft:stone)
B(0,0,-6,minecraft:stone)
B(0,0,-5,minecraft:stone)
B(0,0,-4,minecraft:stone)
B(0,0,-3,minecraft:stone)
B(0,0,-2,minecraft:stone)
B(0,0,-1,minecraft:stone)
B(0,0,0,minecraft:stone)
B(0,0,1,minecraft:stone)
B(0,0,2,minecraft:stone)
B(0,0,3,minecraft:stone)
B(0,0,4,minecraft:stone)
B(0,0,5,minecraft:stone)
B(0,0,6,minecraft:stone)
B(0,0,7,minecraft:stone)
B(0,0,8,minecraft:stone)
B(0,0,9,minecraft:stone)
B(0,0,10,minecraft:stone)
B(0,0,11,minecraft:stone)
B(0,0,12,minecraft:stone)
B(0,0,13,minecraft:stone)
B(0,1,-5,minecraft:stone)
B(0,1,-4,minecraft:stone)
B(0,1,-3,minecraft:stone)
B(0,1,-2,minecraft:stone)
B(0,1,-1,minecraft:stone)
B(0,1,0,minecraft:stone)
B(0,1,1,minecraft:stone)
B(0,1,2,minecraft:stone)
B(0,1,3,minecraft:stone)
B(0,1,4,minecraft:stone)
B(0,1,5,minecraft:stone)
B(0,1,6,minecraft:stone)
B(0,1,7,minecraft:stone)
B(0,1,8,minecraft:stone)
B(0,1,9,minecraft:stone)
B(0,2,-4,minecraft:stone)
B(0,2,-3,minecraft:stone)
B(0,2,-2,minecraft:stone)
B(0,2,-1,minecraft:stone)
B(0,2,0,minecraft:stone)
B(0,2,1,minecraft:stone)
B(0,2,3,minecraft:stone)
B(0,2,4,minecraft:stone)
B(0,2,5,minecraft:stone)
B(0,2,6,minecraft:stone)
B(0,2,7,minecraft:stone)
B(0,2,8,minecraft:stone)
B(0,3,-3,minecraft:stone)
B(0,3,-2,minecraft:stone)
B(0,3,-1,minecraft:stone)
B(0,3,3,minecraft:stone)
B(0,3,4,minecraft:stone)
B(0,3,5,minecraft:stone)
B(0,4,4,minecraft:stone)
B(0,4,5,minecraft:stone)
B(1,0,-7,minecraft:stone)
B(1,0,-6,minecraft:stone)
B(1,0,-5,minecraft:stone)
B(1,0,-4,minecraft:stone)
B(1,0,-3,minecraft:stone)
B(1,0,-2,minecraft:stone)
B(1,0,-1,minecraft:stone)
B(1,0,0,minecraft:stone)
B(1,0,1,minecraft:stone)
B(1,0,2,minecraft:stone)
B(1,0,3,minecraft:stone)
B(1,0,4,minecraft:stone)
B(1,0,5,minecraft:stone)
B(1,0,6,minecraft:stone)
B(1,0,7,minecraft:stone)
B(1,0,8,minecraft:stone)
B(1,0,9,minecraft:stone)
B(1,0,10,minecraft:stone)
B(1,0,11,minecraft:stone)
B(1,1,-5,minecraft:stone)
B(1,1,-4,minecraft:stone)
B(1,1,-3,minecraft:stone)
B(1,1,-2,minecraft:stone)
B(1,1,-1,minecraft:stone)
B(1,1,0,minecraft:stone)
B(1,1,1,minecraft:stone)
B(1,1,2,minecraft:stone)
B(1,1,3,minecraft:stone)
B(1,1,4,minecraft:stone)
B(1,1,5,minecraft:stone)
B(1,1,6,minecraft:stone)
B(1,1,7,minecraft:stone)
B(1,1,8,minecraft:stone)
B(1,1,9,minecraft:stone)
B(1,2,-4,minecraft:stone)
B(1,2,-3,minecraft:stone)
B(1,2,-2,minecraft:stone)
B(1,2,-1,minecraft:stone)
B(1,2,0,minecraft:stone)
B(1,2,1,minecraft:stone)
B(1,2,2,minecraft:stone)
B(1,2,3,minecraft:stone)
B(1,2,4,minecraft:stone)
B(1,2,5,minecraft:stone)
B(1,2,6,minecraft:stone)
B(1,2,7,minecraft:stone)
B(1,2,8,minecraft:stone)
B(1,2,9,minecraft:stone)
B(1,3,-4,minecraft:stone)
B(1,3,-3,minecraft:stone)
B(1,3,-2,minecraft:stone)
B(1,3,2,minecraft:stone)
B(1,3,3,minecraft:stone)
B(1,3,4,minecraft:stone)
B(1,3,5,minecraft:stone)
B(1,3,6,minecraft:stone)
B(1,3,7,minecraft:stone)
B(1,3,8,minecraft:stone)
B(1,4,4,minecraft:stone)
B(1,4,5,minecraft:stone)
B(1,4,7,minecraft:stone)
B(2,0,-7,minecraft:stone)
B(2,0,-6,minecraft:stone)
B(2,0,-5,minecraft:stone)
B(2,0,-4,minecraft:stone)
B(2,0,-3,minecraft:stone)
B(2,0,-2,minecraft:stone)
B(2,0,-1,minecraft:stone)
B(2,0,0,minecraft:stone)
B(2,0,1,minecraft:stone)
B(2,0,2,minecraft:stone)
B(2,0,3,minecraft:stone)
B(2,0,4,minecraft:stone)
B(2,0,5,minecraft:stone)
B(2,0,6,minecraft:stone)
B(2,0,7,minecraft:stone)
B(2,0,8,minecraft:stone)
B(2,0,9,minecraft:stone)
B(2,0,10,minecraft:stone)
B(2,0,11,minecraft:stone)
B(2,1,-6,minecraft:stone)
B(2,1,-5,minecraft:stone)
B(2,1,-4,minecraft:stone)
B(2,1,-3,minecraft:stone)
B(2,1,-2,minecraft:stone)
B(2,1,-1,minecraft:stone)
B(2,1,0,minecraft:stone)
B(2,1,1,minecraft:stone)
B(2,1,2,minecraft:stone)
B(2,1,3,minecraft:stone)
B(2,1,4,minecraft:stone)
B(2,1,5,minecraft:stone)
B(2,1,6,minecraft:stone)
B(2,1,7,minecraft:stone)
B(2,1,8,minecraft:stone)
B(2,1,9,minecraft:stone)
B(2,2,-5,minecraft:stone)
B(2,2,-4,minecraft:stone)
B(2,2,-3,minecraft:stone)
B(2,2,-2,minecraft:stone)
B(2,2,-1,minecraft:stone)
B(2,2,0,minecraft:stone)
B(2,2,1,minecraft:stone)
B(2,2,2,minecraft:stone)
B(2,2,3,minecraft:stone)
B(2,2,4,minecraft:stone)
B(2,2,5,minecraft:stone)
B(2,2,6,minecraft:stone)
B(2,2,7,minecraft:stone)
B(2,2,8,minecraft:stone)
B(2,2,9,minecraft:stone)
B(2,3,-4,minecraft:stone)
B(2,3,-3,minecraft:stone)
B(2,3,-2,minecraft:stone)
B(2,3,2,minecraft:stone)
B(2,3,3,minecraft:stone)
B(2,3,4,minecraft:stone)
B(2,3,5,minecraft:stone)
B(2,3,6,minecraft:stone)
B(2,3,7,minecraft:stone)
B(2,3,8,minecraft:stone)
B(2,3,9,minecraft:stone)
B(2,4,3,minecraft:stone)
B(2,4,4,minecraft:stone)
B(2,4,5,minecraft:stone)
B(2,4,6,minecraft:stone)
B(2,4,7,minecraft:stone)
B(2,4,8,minecraft:stone)
B(3,0,-11,minecraft:stone)
B(3,0,-10,minecraft:stone)
B(3,0,-9,minecraft:stone)
B(3,0,-8,minecraft:stone)
B(3,0,-7,minecraft:stone)
B(3,0,-6,minecraft:stone)
B(3,0,-5,minecraft:stone)
B(3,0,-4,minecraft:stone)
B(3,0,-3,minecraft:stone)
B(3,0,-2,minecraft:stone)
B(3,0,-1,minecraft:stone)
B(3,0,0,minecraft:stone)
B(3,0,1,minecraft:stone)
B(3,0,2,minecraft:stone)
B(3,0,3,minecraft:stone)
B(3,0,4,minecraft:stone)
B(3,0,5,minecraft:stone)
B(3,0,6,minecraft:stone)
B(3,0,7,minecraft:stone)
B(3,0,8,minecraft:stone)
B(3,0,9,minecraft:stone)
B(3,0,10,minecraft:stone)
B(3,0,11,minecraft:stone)
B(3,1,-7,minecraft:stone)
B(3,1,-6,minecraft:stone)
B(3,1,-5,minecraft:stone)
B(3,1,-4,minecraft:stone)
B(3,1,-3,minecraft:stone)
B(3,1,-2,minecraft:stone)
B(3,1,-1,minecraft:stone)
B(3,1,0,minecraft:stone)
B(3,1,1,minecraft:stone)
B(3,1,2,minecraft:stone)
B(3,1,3,minecraft:stone)
B(3,1,4,minecraft:stone)
B(3,1,5,minecraft:stone)
B(3,1,6,minecraft:stone)
B(3,1,7,minecraft:stone)
B(3,1,8,minecraft:stone)
B(3,1,9,minecraft:stone)
B(3,1,10,minecraft:stone)
B(3,2,-6,minecraft:stone)
B(3,2,-5,minecraft:stone)
B(3,2,-4,minecraft:stone)
B(3,2,-3,minecraft:stone)
B(3,2,-2,minecraft:stone)
B(3,2,-1,minecraft:stone)
B(3,2,0,minecraft:stone)
B(3,2,1,minecraft:stone)
B(3,2,2,minecraft:stone)
B(3,2,3,minecraft:stone)
B(3,2,4,minecraft:stone)
B(3,2,5,minecraft:stone)
B(3,2,6,minecraft:stone)
B(3,2,7,minecraft:stone)
B(3,2,8,minecraft:stone)
B(3,2,9,minecraft:stone)
B(3,3,-4,minecraft:stone)
B(3,3,-3,minecraft:stone)
B(3,3,-2,minecraft:stone)
B(3,3,2,minecraft:stone)
B(3,3,3,minecraft:stone)
B(3,3,4,minecraft:stone)
B(3,3,5,minecraft:stone)
B(3,3,6,minecraft:stone)
B(3,3,7,minecraft:stone)
B(3,3,8,minecraft:stone)
B(3,3,9,minecraft:stone)
B(3,4,-3,minecraft:stone)
B(3,4,5,minecraft:stone)
B(3,4,6,minecraft:stone)
B(3,4,7,minecraft:stone)
B(3,4,8,minecraft:stone)
B(4,0,-12,minecraft:stone)
B(4,0,-11,minecraft:stone)
B(4,0,-10,minecraft:stone)
B(4,0,-9,minecraft:stone)
B(4,0,-8,minecraft:stone)
B(4,0,-7,minecraft:stone)
B(4,0,-6,minecraft:stone)
B(4,0,-5,minecraft:stone)
B(4,0,-4,minecraft:stone)
B(4,0,-3,minecraft:stone)
B(4,0,-2,minecraft:stone)
B(4,0,-1,minecraft:stone)
B(4,0,0,minecraft:stone)
B(4,0,1,minecraft:stone)
B(4,0,2,minecraft:stone)
B(4,0,3,minecraft:stone)
B(4,0,4,minecraft:stone)
B(4,0,5,minecraft:stone)
B(4,0,6,minecraft:stone)
B(4,0,7,minecraft:stone)
B(4,0,8,minecraft:stone)
B(4,0,9,minecraft:stone)
B(4,0,10,minecraft:stone)
B(4,0,11,minecraft:stone)
B(4,1,-9,minecraft:stone)
B(4,1,-8,minecraft:stone)
B(4,1,-7,minecraft:stone)
B(4,1,-6,minecraft:stone)
B(4,1,-5,minecraft:stone)
B(4,1,-4,minecraft:stone)
B(4,1,-3,minecraft:stone)
B(4,1,-2,minecraft:stone)
B(4,1,-1,minecraft:stone)
B(4,1,0,minecraft:stone)
B(4,1,1,minecraft:stone)
B(4,1,2,minecraft:stone)
B(4,1,3,minecraft:stone)
B(4,1,4,minecraft:stone)
B(4,1,5,minecraft:stone)
B(4,1,6,minecraft:stone)
B(4,1,7,minecraft:stone)
B(4,1,8,minecraft:stone)
B(4,1,9,minecraft:stone)
B(4,1,10,minecraft:stone)
B(4,2,-8,minecraft:stone)
B(4,2,-7,minecraft:stone)
B(4,2,-6,minecraft:stone)
B(4,2,-5,minecraft:stone)
B(4,2,-4,minecraft:stone)
B(4,2,-3,minecraft:stone)
B(4,2,-2,minecraft:stone)
B(4,2,-1,minecraft:stone)
B(4,2,0,minecraft:stone)
B(4,2,1,minecraft:stone)
B(4,2,2,minecraft:stone)
B(4,2,3,minecraft:stone)
B(4,2,4,minecraft:stone)
B(4,2,5,minecraft:stone)
B(4,2,6,minecraft:stone)
B(4,2,7,minecraft:stone)
B(4,2,8,minecraft:stone)
B(4,2,9,minecraft:stone)
B(4,3,-7,minecraft:stone)
B(4,3,-6,minecraft:stone)
B(4,3,-5,minecraft:stone)
B(4,3,-4,minecraft:stone)
B(4,3,-3,minecraft:stone)
B(4,3,-2,minecraft:stone)
B(4,3,4,minecraft:stone)
B(4,3,5,minecraft:stone)
B(4,3,6,minecraft:stone)
B(4,3,7,minecraft:stone)
B(4,3,8,minecraft:stone)
B(4,3,9,minecraft:stone)
B(4,4,-7,minecraft:stone)
B(4,4,-6,minecraft:stone)
B(4,4,-5,minecraft:stone)
B(4,4,-4,minecraft:stone)
B(4,4,-3,minecraft:stone)
B(4,4,6,minecraft:stone)
B(4,4,7,minecraft:stone)
B(4,4,8,minecraft:stone)
B(4,4,9,minecraft:stone)
B(4,5,-6,minecraft:stone)
B(4,5,6,minecraft:stone)
B(4,5,7,minecraft:stone)
B(4,5,8,minecraft:stone)
B(4,5,9,minecraft:stone)
B(4,6,7,minecraft:stone)
B(4,6,8,minecraft:stone)
B(4,7,8,minecraft:stone)
B(5,0,-12,minecraft:stone)
B(5,0,-11,minecraft:stone)
B(5,0,-10,minecraft:stone)
B(5,0,-9,minecraft:stone)
B(5,0,-8,minecraft:stone)
B(5,0,-7,minecraft:stone)
B(5,0,-6,minecraft:stone)
B(5,0,-5,minecraft:stone)
B(5,0,-4,minecraft:stone)
B(5,0,-3,minecraft:stone)
B(5,0,-2,minecraft:stone)
B(5,0,-1,minecraft:stone)
B(5,0,0,minecraft:stone)
B(5,0,1,minecraft:stone)
B(5,0,2,minecraft:stone)
B(5,0,3,minecraft:stone)
B(5,0,4,minecraft:stone)
B(5,0,5,minecraft:stone)
B(5,0,6,minecraft:stone)
B(5,0,7,minecraft:stone)
B(5,0,8,minecraft:stone)
B(5,0,9,minecraft:stone)
B(5,0,10,minecraft:stone)
B(5,1,-9,minecraft:stone)
B(5,1,-8,minecraft:stone)
B(5,1,-7,minecraft:stone)
B(5,1,-6,minecraft:stone)
B(5,1,-5,minecraft:stone)
B(5,1,-4,minecraft:stone)
B(5,1,-3,minecraft:stone)
B(5,1,-2,minecraft:stone)
B(5,1,-1,minecraft:stone)
B(5,1,0,minecraft:stone)
B(5,1,1,minecraft:stone)
B(5,1,2,minecraft:stone)
B(5,1,3,minecraft:stone)
B(5,1,4,minecraft:stone)
B(5,1,5,minecraft:stone)
B(5,1,6,minecraft:stone)
B(5,1,7,minecraft:stone)
B(5,1,8,minecraft:stone)
B(5,1,9,minecraft:stone)
B(5,1,10,minecraft:stone)
B(5,2,-9,minecraft:stone)
B(5,2,-8,minecraft:stone)
B(5,2,-7,minecraft:stone)
B(5,2,-6,minecraft:stone)
B(5,2,-5,minecraft:stone)
B(5,2,-4,minecraft:stone)
B(5,2,-3,minecraft:stone)
B(5,2,-2,minecraft:stone)
B(5,2,-1,minecraft:stone)
B(5,2,0,minecraft:stone)
B(5,2,1,minecraft:stone)
B(5,2,4,minecraft:stone)
B(5,2,5,minecraft:stone)
B(5,2,6,minecraft:stone)
B(5,2,7,minecraft:stone)
B(5,2,8,minecraft:stone)
B(5,2,9,minecraft:stone)
B(5,2,10,minecraft:stone)
B(5,3,-8,minecraft:stone)
B(5,3,-7,minecraft:stone)
B(5,3,-6,minecraft:stone)
B(5,3,-5,minecraft:stone)
B(5,3,-4,minecraft:stone)
B(5,3,-3,minecraft:stone)
B(5,3,-2,minecraft:stone)
B(5,3,6,minecraft:stone)
B(5,3,7,minecraft:stone)
B(5,3,8,minecraft:stone)
B(5,3,9,minecraft:stone)
B(5,4,-8,minecraft:stone)
B(5,4,-7,minecraft:stone)
B(5,4,-6,minecraft:stone)
B(5,4,-5,minecraft:stone)
B(5,4,-4,minecraft:stone)
B(5,4,-3,minecraft:stone)
B(5,4,6,minecraft:stone)
B(5,4,7,minecraft:stone)
B(5,4,8,minecraft:stone)
B(5,4,9,minecraft:stone)
B(5,5,-8,minecraft:stone)
B(5,5,-7,minecraft:stone)
B(5,5,-6,minecraft:stone)
B(5,5,-5,minecraft:stone)
B(5,5,6,minecraft:stone)
B(5,5,7,minecraft:stone)
B(5,5,8,minecraft:stone)
B(5,6,-6,minecraft:stone)
B(5,6,-5,minecraft:stone)
B(5,6,7,minecraft:stone)
B(5,6,8,minecraft:stone)
B(6,0,-13,minecraft:stone)
B(6,0,-12,minecraft:stone)
B(6,0,-11,minecraft:stone)
B(6,0,-10,minecraft:stone)
B(6,0,-9,minecraft:stone)
B(6,0,-8,minecraft:stone)
B(6,0,-7,minecraft:stone)
B(6,0,-6,minecraft:stone)
B(6,0,-5,minecraft:stone)
B(6,0,-4,minecraft:stone)
B(6,0,-3,minecraft:stone)
B(6,0,-2,minecraft:stone)
B(6,0,-1,minecraft:stone)
B(6,0,0,minecraft:stone)
B(6,0,1,minecraft:stone)
B(6,0,2,minecraft:stone)
B(6,0,3,minecraft:stone)
B(6,0,4,minecraft:stone)
B(6,0,5,minecraft:stone)
B(6,0,6,minecraft:stone)
B(6,0,7,minecraft:stone)
B(6,0,8,minecraft:stone)
B(6,0,9,minecraft:stone)
B(6,0,10,minecraft:stone)
B(6,0,11,minecraft:stone)
B(6,1,-11,minecraft:stone)
B(6,1,-10,minecraft:stone)
B(6,1,-9,minecraft:stone)
B(6,1,-8,minecraft:stone)
B(6,1,-7,minecraft:stone)
B(6,1,-6,minecraft:stone)
B(6,1,-5,minecraft:stone)
B(6,1,-4,minecraft:stone)
B(6,1,-3,minecraft:stone)
B(6,1,-2,minecraft:stone)
B(6,1,-1,minecraft:stone)
B(6,1,0,minecraft:stone)
B(6,1,1,minecraft:stone)
B(6,1,2,minecraft:stone)
B(6,1,3,minecraft:stone)
B(6,1,4,minecraft:stone)
B(6,1,5,minecraft:stone)
B(6,1,6,minecraft:stone)
B(6,1,7,minecraft:stone)
B(6,1,8,minecraft:stone)
B(6,1,9,minecraft:stone)
B(6,1,10,minecraft:stone)
B(6,2,-10,minecraft:stone)
B(6,2,-9,minecraft:stone)
B(6,2,-8,minecraft:stone)
B(6,2,-7,minecraft:stone)
B(6,2,-6,minecraft:stone)
B(6,2,-5,minecraft:stone)
B(6,2,-4,minecraft:stone)
B(6,2,-3,minecraft:stone)
B(6,2,-2,minecraft:stone)
B(6,2,-1,minecraft:stone)
B(6,2,1,minecraft:stone)
B(6,2,3,minecraft:stone)
B(6,2,4,minecraft:stone)
B(6,2,5,minecraft:stone)
B(6,2,6,minecraft:stone)
B(6,2,7,minecraft:stone)
B(6,2,8,minecraft:stone)
B(6,2,9,minecraft:stone)
B(6,3,-9,minecraft:stone)
B(6,3,-8,minecraft:stone)
B(6,3,-7,minecraft:stone)
B(6,3,-6,minecraft:stone)
B(6,3,-5,minecraft:stone)
B(6,3,-4,minecraft:stone)
B(6,3,-3,minecraft:stone)
B(6,3,-2,minecraft:stone)
B(6,3,6,minecraft:stone)
B(6,3,7,minecraft:stone)
B(6,3,8,minecraft:stone)
B(6,3,9,minecraft:stone)
B(6,4,-9,minecraft:stone)
B(6,4,-8,minecraft:stone)
B(6,4,-7,minecraft:stone)
B(6,4,-6,minecraft:stone)
B(6,4,-5,minecraft:stone)
B(6,4,-4,minecraft:stone)
B(6,4,-3,minecraft:stone)
B(6,4,-2,minecraft:stone)
B(6,4,7,minecraft:stone)
B(6,4,8,minecraft:stone)
B(6,4,9,minecraft:stone)
B(6,5,-9,minecraft:stone)
B(6,5,-8,minecraft:stone)
B(6,5,-7,minecraft:stone)
B(6,5,-6,minecraft:stone)
B(6,5,-5,minecraft:stone)
B(6,5,-3,minecraft:stone)
B(6,5,7,minecraft:stone)
B(6,5,8,minecraft:stone)
B(6,6,-8,minecraft:stone)
B(6,6,-7,minecraft:stone)
B(6,6,-6,minecraft:stone)
B(6,7,-8,minecraft:stone)
B(6,7,-7,minecraft:stone)
B(6,7,-6,minecraft:stone)
B(6,8,-7,minecraft:stone)
B(6,8,-6,minecraft:stone)
B(7,0,-13,minecraft:stone)
B(7,0,-12,minecraft:stone)
B(7,0,-11,minecraft:stone)
B(7,0,-10,minecraft:stone)
B(7,0,-9,minecraft:stone)
B(7,0,-8,minecraft:stone)
B(7,0,-7,minecraft:stone)
B(7,0,-6,minecraft:stone)
B(7,0,-5,minecraft:stone)
B(7,0,-4,minecraft:stone)
B(7,0,-3,minecraft:stone)
B(7,0,-2,minecraft:stone)
B(7,0,-1,minecraft:stone)
B(7,0,0,minecraft:stone)
B(7,0,1,minecraft:stone)
B(7,0,3,minecraft:stone)
B(7,0,4,minecraft:stone)
B(7,0,5,minecraft:stone)
B(7,0,6,minecraft:stone)
B(7,0,7,minecraft:stone)
B(7,0,8,minecraft:stone)
B(7,0,9,minecraft:stone)
B(7,0,10,minecraft:stone)
B(7,0,11,minecraft:stone)
B(7,0,12,minecraft:stone)
B(7,0,13,minecraft:stone)
B(7,0,14,minecraft:stone)
B(7,1,-11,minecraft:stone)
B(7,1,-10,minecraft:stone)
B(7,1,-9,minecraft:stone)
B(7,1,-8,minecraft:stone)
B(7,1,-7,minecraft:stone)
B(7,1,-6,minecraft:stone)
B(7,1,-5,minecraft:stone)
B(7,1,-4,minecraft:stone)
B(7,1,-3,minecraft:stone)
B(7,1,-2,minecraft:stone)
B(7,1,-1,minecraft:stone)
B(7,1,0,minecraft:stone)
B(7,1,3,minecraft:stone)
B(7,1,4,minecraft:stone)
B(7,1,5,minecraft:stone)
B(7,1,6,minecraft:stone)
B(7,1,7,minecraft:stone)
B(7,1,8,minecraft:stone)
B(7,1,9,minecraft:stone)
B(7,1,10,minecraft:stone)
B(7,1,11,minecraft:stone)
B(7,2,-11,minecraft:stone)
B(7,2,-10,minecraft:stone)
B(7,2,-9,minecraft:stone)
B(7,2,-8,minecraft:stone)
B(7,2,-7,minecraft:stone)
B(7,2,-6,minecraft:stone)
B(7,2,-5,minecraft:stone)
B(7,2,-4,minecraft:stone)
B(7,2,-3,minecraft:stone)
B(7,2,-2,minecraft:stone)
B(7,2,7,minecraft:stone)
B(7,2,8,minecraft:stone)
B(7,2,9,minecraft:stone)
B(7,2,10,minecraft:stone)
B(7,3,-10,minecraft:stone)
B(7,3,-9,minecraft:stone)
B(7,3,-8,minecraft:stone)
B(7,3,-7,minecraft:stone)
B(7,3,-6,minecraft:stone)
B(7,3,-5,minecraft:stone)
B(7,3,-4,minecraft:stone)
B(7,3,-3,minecraft:stone)
B(7,3,-2,minecraft:stone)
B(7,3,7,minecraft:stone)
B(7,3,8,minecraft:stone)
B(7,3,9,minecraft:stone)
B(7,4,-9,minecraft:stone)
B(7,4,-8,minecraft:stone)
B(7,4,-7,minecraft:stone)
B(7,4,-6,minecraft:stone)
B(7,4,-4,minecraft:stone)
B(7,4,-3,minecraft:stone)
B(7,4,-2,minecraft:stone)
B(7,4,7,minecraft:stone)
B(7,4,8,minecraft:stone)
B(7,4,9,minecraft:stone)
B(7,5,-9,minecraft:stone)
B(7,5,-8,minecraft:stone)
B(7,5,-7,minecraft:stone)
B(7,5,-6,minecraft:stone)
B(7,5,-3,minecraft:stone)
B(7,6,-8,minecraft:stone)
B(7,6,-7,minecraft:stone)
B(7,7,-8,minecraft:stone)
B(7,7,-7,minecraft:stone)
B(7,8,-8,minecraft:stone)
B(7,8,-7,minecraft:stone)
B(8,0,-14,minecraft:stone)
B(8,0,-13,minecraft:stone)
B(8,0,-12,minecraft:stone)
B(8,0,-11,minecraft:stone)
B(8,0,-10,minecraft:stone)
B(8,0,-9,minecraft:stone)
B(8,0,-8,minecraft:stone)
B(8,0,-7,minecraft:stone)
B(8,0,-6,minecraft:stone)
B(8,0,-5,minecraft:stone)
B(8,0,-4,minecraft:stone)
B(8,0,-3,minecraft:stone)
B(8,0,-2,minecraft:stone)
B(8,0,-1,minecraft:stone)
B(8,0,0,minecraft:stone)
B(8,0,1,minecraft:stone)
B(8,0,3,minecraft:stone)
B(8,0,4,minecraft:stone)
B(8,0,5,minecraft:stone)
B(8,0,6,minecraft:stone)
B(8,0,7,minecraft:stone)
B(8,0,8,minecraft:stone)
B(8,0,9,minecraft:stone)
B(8,0,10,minecraft:stone)
B(8,0,11,minecraft:stone)
B(8,0,12,minecraft:stone)
B(8,0,13,minecraft:stone)
B(8,0,14,minecraft:stone)
B(8,1,-12,minecraft:stone)
B(8,1,-11,minecraft:stone)
B(8,1,-10,minecraft:stone)
B(8,1,-9,minecraft:stone)
B(8,1,-8,minecraft:stone)
B(8,1,-7,minecraft:stone)
B(8,1,-6,minecraft:stone)
B(8,1,-5,minecraft:stone)
B(8,1,-4,minecraft:stone)
B(8,1,-3,minecraft:stone)
B(8,1,-2,minecraft:stone)
B(8,1,-1,minecraft:stone)
B(8,1,3,minecraft:stone)
B(8,1,4,minecraft:stone)
B(8,1,5,minecraft:stone)
B(8,1,6,minecraft:stone)
B(8,1,7,minecraft:stone)
B(8,1,8,minecraft:stone)
B(8,1,9,minecraft:stone)
B(8,1,10,minecraft:stone)
B(8,1,11,minecraft:stone)
B(8,1,12,minecraft:stone)
B(8,1,13,minecraft:stone)
B(8,2,-11,minecraft:stone)
B(8,2,-10,minecraft:stone)
B(8,2,-9,minecraft:stone)
B(8,2,-8,minecraft:stone)
B(8,2,-7,minecraft:stone)
B(8,2,-6,minecraft:stone)
B(8,2,-5,minecraft:stone)
B(8,2,-4,minecraft:stone)
B(8,2,-3,minecraft:stone)
B(8,2,-2,minecraft:stone)
B(8,2,7,minecraft:stone)
B(8,2,8,minecraft:stone)
B(8,2,9,minecraft:stone)
B(8,2,10,minecraft:stone)
B(8,3,-10,minecraft:stone)
B(8,3,-9,minecraft:stone)
B(8,3,-8,minecraft:stone)
B(8,3,-7,minecraft:stone)
B(8,3,-6,minecraft:stone)
B(8,3,-5,minecraft:stone)
B(8,3,-4,minecraft:stone)
B(8,3,-3,minecraft:stone)
B(8,3,-2,minecraft:stone)
B(8,3,7,minecraft:stone)
B(8,3,8,minecraft:stone)
B(8,3,9,minecraft:stone)
B(8,4,-10,minecraft:stone)
B(8,4,-9,minecraft:stone)
B(8,4,-8,minecraft:stone)
B(8,4,-7,minecraft:stone)
B(8,4,-6,minecraft:stone)
B(8,4,-3,minecraft:stone)
B(8,4,8,minecraft:stone)
B(8,4,9,minecraft:stone)
B(8,5,-9,minecraft:stone)
B(8,5,-8,minecraft:stone)
B(8,5,-7,minecraft:stone)
B(8,6,-8,minecraft:stone)
B(8,6,-7,minecraft:stone)
B(9,0,-14,minecraft:stone)
B(9,0,-13,minecraft:stone)
B(9,0,-12,minecraft:stone)
B(9,0,-11,minecraft:stone)
B(9,0,-10,minecraft:stone)
B(9,0,-9,minecraft:stone)
B(9,0,-8,minecraft:stone)
B(9,0,-7,minecraft:stone)
B(9,0,-6,minecraft:stone)
B(9,0,-5,minecraft:stone)
B(9,0,-4,minecraft:stone)
B(9,0,-3,minecraft:stone)
B(9,0,-2,minecraft:stone)
B(9,0,-1,minecraft:stone)
B(9,0,0,minecraft:stone)
B(9,0,3,minecraft:stone)
B(9,0,4,minecraft:stone)
B(9,0,5,minecraft:stone)
B(9,0,6,minecraft:stone)
B(9,0,7,minecraft:stone)
B(9,0,8,minecraft:stone)
B(9,0,9,minecraft:stone)
B(9,0,10,minecraft:stone)
B(9,0,11,minecraft:stone)
B(9,0,12,minecraft:stone)
B(9,0,13,minecraft:stone)
B(9,0,14,minecraft:stone)
B(9,1,-13,minecraft:stone)
B(9,1,-12,minecraft:stone)
B(9,1,-11,minecraft:stone)
B(9,1,-10,minecraft:stone)
B(9,1,-9,minecraft:stone)
B(9,1,-8,minecraft:stone)
B(9,1,-7,minecraft:stone)
B(9,1,-6,minecraft:stone)
B(9,1,-5,minecraft:stone)
B(9,1,-4,minecraft:stone)
B(9,1,-3,minecraft:stone)
B(9,1,-2,minecraft:stone)
B(9,1,-1,minecraft:stone)
B(9,1,3,minecraft:stone)
B(9,1,4,minecraft:stone)
B(9,1,5,minecraft:stone)
B(9,1,6,minecraft:stone)
B(9,1,7,minecraft:stone)
B(9,1,8,minecraft:stone)
B(9,1,9,minecraft:stone)
B(9,1,10,minecraft:stone)
B(9,1,11,minecraft:stone)
B(9,1,12,minecraft:stone)
B(9,1,13,minecraft:stone)
B(9,2,-12,minecraft:stone)
B(9,2,-11,minecraft:stone)
B(9,2,-10,minecraft:stone)
B(9,2,-9,minecraft:stone)
B(9,2,-8,minecraft:stone)
B(9,2,-7,minecraft:stone)
B(9,2,-6,minecraft:stone)
B(9,2,-5,minecraft:stone)
B(9,2,-4,minecraft:stone)
B(9,2,-3,minecraft:stone)
B(9,2,-2,minecraft:stone)
B(9,2,4,minecraft:stone)
B(9,2,5,minecraft:stone)
B(9,2,6,minecraft:stone)
B(9,2,7,minecraft:stone)
B(9,2,8,minecraft:stone)
B(9,2,9,minecraft:stone)
B(9,2,10,minecraft:stone)
B(9,2,11,minecraft:stone)
B(9,2,12,minecraft:stone)
B(9,3,-11,minecraft:stone)
B(9,3,-10,minecraft:stone)
B(9,3,-9,minecraft:stone)
B(9,3,-8,minecraft:stone)
B(9,3,-7,minecraft:stone)
B(9,3,-6,minecraft:stone)
B(9,3,-5,minecraft:stone)
B(9,3,-4,minecraft:stone)
B(9,3,-3,minecraft:stone)
B(9,3,6,minecraft:stone)
B(9,3,8,minecraft:stone)
B(9,3,9,minecraft:stone)
B(9,3,10,minecraft:stone)
B(9,3,11,minecraft:stone)
B(9,3,12,minecraft:stone)
B(9,4,-9,minecraft:stone)
B(9,4,-8,minecraft:stone)
B(9,4,-7,minecraft:stone)
B(9,4,8,minecraft:stone)
B(9,4,9,minecraft:stone)
B(9,4,11,minecraft:stone)
B(9,5,-8,minecraft:stone)
B(9,5,-7,minecraft:stone)
B(10,0,-15,minecraft:stone)
B(10,0,-14,minecraft:stone)
B(10,0,-13,minecraft:stone)
B(10,0,-12,minecraft:stone)
B(10,0,-11,minecraft:stone)
B(10,0,-10,minecraft:stone)
B(10,0,-9,minecraft:stone)
B(10,0,-8,minecraft:stone)
B(10,0,-7,minecraft:stone)
B(10,0,-6,minecraft:stone)
B(10,0,-5,minecraft:stone)
B(10,0,-4,minecraft:stone)
B(10,0,-3,minecraft:stone)
B(10,0,-2,minecraft:stone)
B(10,0,-1,minecraft:stone)
B(10,0,2,minecraft:stone)
B(10,0,3,minecraft:stone)
B(10,0,4,minecraft:stone)
B(10,0,5,minecraft:stone)
B(10,0,6,minecraft:stone)
B(10,0,7,minecraft:stone)
B(10,0,8,minecraft:stone)
B(10,0,9,minecraft:stone)
B(10,0,10,minecraft:stone)
B(10,0,11,minecraft:stone)
B(10,0,12,minecraft:stone)
B(10,0,13,minecraft:stone)
B(10,0,14,minecraft:stone)
B(10,1,-14,minecraft:stone)
B(10,1,-13,minecraft:stone)
B(10,1,-12,minecraft:stone)
B(10,1,-11,minecraft:stone)
B(10,1,-10,minecraft:stone)
B(10,1,-9,minecraft:stone)
B(10,1,-8,minecraft:stone)
B(10,1,-7,minecraft:stone)
B(10,1,-6,minecraft:stone)
B(10,1,-5,minecraft:stone)
B(10,1,-4,minecraft:stone)
B(10,1,-3,minecraft:stone)
B(10,1,-2,minecraft:stone)
B(10,1,-1,minecraft:stone)
B(10,1,3,minecraft:stone)
B(10,1,4,minecraft:stone)
B(10,1,5,minecraft:stone)
B(10,1,6,minecraft:stone)
B(10,1,7,minecraft:stone)
B(10,1,8,minecraft:stone)
B(10,1,9,minecraft:stone)
B(10,1,10,minecraft:stone)
B(10,1,11,minecraft:stone)
B(10,1,12,minecraft:stone)
B(10,1,13,minecraft:stone)
B(10,2,-13,minecraft:stone)
B(10,2,-12,minecraft:stone)
B(10,2,-11,minecraft:stone)
B(10,2,-10,minecraft:stone)
B(10,2,-9,minecraft:stone)
B(10,2,-8,minecraft:stone)
B(10,2,-7,minecraft:stone)
B(10,2,-6,minecraft:stone)
B(10,2,-5,minecraft:stone)
B(10,2,-4,minecraft:stone)
B(10,2,-2,minecraft:stone)
B(10,2,4,minecraft:stone)
B(10,2,5,minecraft:stone)
B(10,2,6,minecraft:stone)
B(10,2,7,minecraft:stone)
B(10,2,8,minecraft:stone)
B(10,2,9,minecraft:stone)
B(10,2,10,minecraft:stone)
B(10,2,11,minecraft:stone)
B(10,2,12,minecraft:stone)
B(10,2,13,minecraft:stone)
B(10,3,-13,minecraft:stone)
B(10,3,-12,minecraft:stone)
B(10,3,-11,minecraft:stone)
B(10,3,-10,minecraft:stone)
B(10,3,-9,minecraft:stone)
B(10,3,-8,minecraft:stone)
B(10,3,-7,minecraft:stone)
B(10,3,-6,minecraft:stone)
B(10,3,-5,minecraft:stone)
B(10,3,5,minecraft:stone)
B(10,3,6,minecraft:stone)
B(10,3,7,minecraft:stone)
B(10,3,8,minecraft:stone)
B(10,3,9,minecraft:stone)
B(10,3,10,minecraft:stone)
B(10,3,11,minecraft:stone)
B(10,3,12,minecraft:stone)
B(10,4,-12,minecraft:stone)
B(10,4,-11,minecraft:stone)
B(10,4,-10,minecraft:stone)
B(10,4,-9,minecraft:stone)
B(10,4,-8,minecraft:stone)
B(10,4,-7,minecraft:stone)
B(10,4,6,minecraft:stone)
B(10,4,7,minecraft:stone)
B(10,4,8,minecraft:stone)
B(10,4,10,minecraft:stone)
B(10,4,11,minecraft:stone)
B(10,4,12,minecraft:stone)
B(10,5,-8,minecraft:stone)
B(10,5,6,minecraft:stone)
B(11,0,-15,minecraft:stone)
B(11,0,-14,minecraft:stone)
B(11,0,-13,minecraft:stone)
B(11,0,-12,minecraft:stone)
B(11,0,-11,minecraft:stone)
B(11,0,-10,minecraft:stone)
B(11,0,-9,minecraft:stone)
B(11,0,-8,minecraft:stone)
B(11,0,-7,minecraft:stone)
B(11,0,-6,minecraft:stone)
B(11,0,-5,minecraft:stone)
B(11,0,-4,minecraft:stone)
B(11,0,-3,minecraft:stone)
B(11,0,-2,minecraft:stone)
B(11,0,-1,minecraft:stone)
B(11,0,2,minecraft:stone)
B(11,0,3,minecraft:stone)
B(11,0,4,minecraft:stone)
B(11,0,5,minecraft:stone)
B(11,0,6,minecraft:stone)
B(11,0,7,minecraft:stone)
B(11,0,8,minecraft:stone)
B(11,0,9,minecraft:stone)
B(11,0,10,minecraft:stone)
B(11,0,11,minecraft:stone)
B(11,0,12,minecraft:stone)
B(11,0,13,minecraft:stone)
B(11,0,14,minecraft:stone)
B(11,0,15,minecraft:stone)
B(11,1,-15,minecraft:stone)
B(11,1,-14,minecraft:stone)
B(11,1,-13,minecraft:stone)
B(11,1,-12,minecraft:stone)
B(11,1,-11,minecraft:stone)
B(11,1,-10,minecraft:stone)
B(11,1,-9,minecraft:stone)
B(11,1,-8,minecraft:stone)
B(11,1,-7,minecraft:stone)
B(11,1,-6,minecraft:stone)
B(11,1,-5,minecraft:stone)
B(11,1,-4,minecraft:stone)
B(11,1,3,minecraft:stone)
B(11,1,4,minecraft:stone)
B(11,1,5,minecraft:stone)
B(11,1,6,minecraft:stone)
B(11,1,7,minecraft:stone)
B(11,1,8,minecraft:stone)
B(11,1,9,minecraft:stone)
B(11,1,10,minecraft:stone)
B(11,1,11,minecraft:stone)
B(11,1,12,minecraft:stone)
B(11,1,13,minecraft:stone)
B(11,2,-14,minecraft:stone)
B(11,2,-13,minecraft:stone)
B(11,2,-12,minecraft:stone)
B(11,2,-11,minecraft:stone)
B(11,2,-10,minecraft:stone)
B(11,2,-9,minecraft:stone)
B(11,2,-8,minecraft:stone)
B(11,2,-7,minecraft:stone)
B(11,2,-6,minecraft:stone)
B(11,2,-5,minecraft:stone)
B(11,2,3,minecraft:stone)
B(11,2,4,minecraft:stone)
B(11,2,5,minecraft:stone)
B(11,2,6,minecraft:stone)
B(11,2,7,minecraft:stone)
B(11,2,8,minecraft:stone)
B(11,2,9,minecraft:stone)
B(11,2,10,minecraft:stone)
B(11,2,11,minecraft:stone)
B(11,2,12,minecraft:stone)
B(11,2,13,minecraft:stone)
B(11,3,-14,minecraft:stone)
B(11,3,-13,minecraft:stone)
B(11,3,-12,minecraft:stone)
B(11,3,-11,minecraft:stone)
B(11,3,-10,minecraft:stone)
B(11,3,-9,minecraft:stone)
B(11,3,-8,minecraft:stone)
B(11,3,-7,minecraft:stone)
B(11,3,5,minecraft:stone)
B(11,3,6,minecraft:stone)
B(11,3,7,minecraft:stone)
B(11,3,8,minecraft:stone)
B(11,3,9,minecraft:stone)
B(11,3,10,minecraft:stone)
B(11,3,11,minecraft:stone)
B(11,3,12,minecraft:stone)
B(11,4,-12,minecraft:stone)
B(11,4,-11,minecraft:stone)
B(11,4,-10,minecraft:stone)
B(11,4,-9,minecraft:stone)
B(11,4,-8,minecraft:stone)
B(11,4,6,minecraft:stone)
B(11,4,9,minecraft:stone)
B(11,4,10,minecraft:stone)
B(11,4,11,minecraft:stone)
B(11,4,12,minecraft:stone)
B(11,5,-11,minecraft:stone)
B(12,0,-15,minecraft:stone)
B(12,0,-14,minecraft:stone)
B(12,0,-13,minecraft:stone)
B(12,0,-12,minecraft:stone)
B(12,0,-11,minecraft:stone)
B(12,0,-10,minecraft:stone)
B(12,0,-9,minecraft:stone)
B(12,0,-8,minecraft:stone)
B(12,0,-7,minecraft:stone)
B(12,0,-6,minecraft:stone)
B(12,0,-5,minecraft:stone)
B(12,0,-4,minecraft:stone)
B(12,0,3,minecraft:stone)
B(12,0,4,minecraft:stone)
B(12,0,5,minecraft:stone)
B(12,0,6,minecraft:stone)
B(12,0,7,minecraft:stone)
B(12,0,8,minecraft:stone)
B(12,0,9,minecraft:stone)
B(12,0,10,minecraft:stone)
B(12,0,11,minecraft:stone)
B(12,0,12,minecraft:stone)
B(12,0,13,minecraft:stone)
B(12,0,14,minecraft:stone)
B(12,0,15,minecraft:stone)
B(12,1,-15,minecraft:stone)
B(12,1,-14,minecraft:stone)
B(12,1,-13,minecraft:stone)
B(12,1,-12,minecraft:stone)
B(12,1,-11,minecraft:stone)
B(12,1,-10,minecraft:stone)
B(12,1,-9,minecraft:stone)
B(12,1,-8,minecraft:stone)
B(12,1,-7,minecraft:stone)
B(12,1,-6,minecraft:stone)
B(12,1,-5,minecraft:stone)
B(12,1,5,minecraft:stone)
B(12,1,6,minecraft:stone)
B(12,1,7,minecraft:stone)
B(12,1,8,minecraft:stone)
B(12,1,9,minecraft:stone)
B(12,1,10,minecraft:stone)
B(12,1,11,minecraft:stone)
B(12,1,12,minecraft:stone)
B(12,1,13,minecraft:stone)
B(12,1,14,minecraft:stone)
B(12,2,-14,minecraft:stone)
B(12,2,-13,minecraft:stone)
B(12,2,-12,minecraft:stone)
B(12,2,-11,minecraft:stone)
B(12,2,-10,minecraft:stone)
B(12,2,-9,minecraft:stone)
B(12,2,-8,minecraft:stone)
B(12,2,-7,minecraft:stone)
B(12,2,-5,minecraft:stone)
B(12,2,7,minecraft:stone)
B(12,2,8,minecraft:stone)
B(12,2,9,minecraft:stone)
B(12,2,10,minecraft:stone)
B(12,2,11,minecraft:stone)
B(12,2,12,minecraft:stone)
B(12,2,13,minecraft:stone)
B(12,3,-14,minecraft:stone)
B(12,3,-13,minecraft:stone)
B(12,3,-12,minecraft:stone)
B(12,3,-11,minecraft:stone)
B(12,3,-10,minecraft:stone)
B(12,3,-9,minecraft:stone)
B(12,3,-8,minecraft:stone)
B(12,3,8,minecraft:stone)
B(12,3,9,minecraft:stone)
B(12,3,10,minecraft:stone)
B(12,3,11,minecraft:stone)
B(12,3,12,minecraft:stone)
B(12,3,13,minecraft:stone)
B(12,4,-12,minecraft:stone)
B(12,4,-9,minecraft:stone)
B(12,4,-8,minecraft:stone)
B(12,4,10,minecraft:stone)
B(12,4,11,minecraft:stone)
B(12,4,12,minecraft:stone)
B(12,4,13,minecraft:stone)
B(12,5,-9,minecraft:stone)
B(13,0,-15,minecraft:stone)
B(13,0,-14,minecraft:stone)
B(13,0,-13,minecraft:stone)
B(13,0,-12,minecraft:stone)
B(13,0,-11,minecraft:stone)
B(13,0,-10,minecraft:stone)
B(13,0,-9,minecraft:stone)
B(13,0,-8,minecraft:stone)
B(13,0,-7,minecraft:stone)
B(13,0,-6,minecraft:stone)
B(13,0,-5,minecraft:stone)
B(13,0,5,minecraft:stone)
B(13,0,6,minecraft:stone)
B(13,0,7,minecraft:stone)
B(13,0,8,minecraft:stone)
B(13,0,9,minecraft:stone)
B(13,0,10,minecraft:stone)
B(13,0,11,minecraft:stone)
B(13,0,12,minecraft:stone)
B(13,0,13,minecraft:stone)
B(13,0,14,minecraft:stone)
B(13,1,-15,minecraft:stone)
B(13,1,-14,minecraft:stone)
B(13,1,-13,minecraft:stone)
B(13,1,-12,minecraft:stone)
B(13,1,-11,minecraft:stone)
B(13,1,-10,minecraft:stone)
B(13,1,-9,minecraft:stone)
B(13,1,-8,minecraft:stone)
B(13,1,-7,minecraft:stone)
B(13,1,-6,minecraft:stone)
B(13,1,7,minecraft:stone)
B(13,1,8,minecraft:stone)
B(13,1,9,minecraft:stone)
B(13,1,10,minecraft:stone)
B(13,1,11,minecraft:stone)
B(13,1,12,minecraft:stone)
B(13,1,13,minecraft:stone)
B(13,1,14,minecraft:stone)
B(13,2,-14,minecraft:stone)
B(13,2,-13,minecraft:stone)
B(13,2,-11,minecraft:stone)
B(13,2,-10,minecraft:stone)
B(13,2,-9,minecraft:stone)
B(13,2,-8,minecraft:stone)
B(13,2,10,minecraft:stone)
B(13,2,11,minecraft:stone)
B(13,2,12,minecraft:stone)
B(13,2,13,minecraft:stone)
B(13,3,-10,minecraft:stone)
B(13,3,-9,minecraft:stone)
B(13,3,-8,minecraft:stone)
B(13,3,11,minecraft:stone)
B(13,3,12,minecraft:stone)
B(13,4,-10,minecraft:stone)
B(13,4,-9,minecraft:stone)
B(13,4,-8,minecraft:stone)
B(13,5,-9,minecraft:stone)
B(14,0,-15,minecraft:stone)
B(14,0,-14,minecraft:stone)
B(14,0,-13,minecraft:stone)
B(14,0,-12,minecraft:stone)
B(14,0,-11,minecraft:stone)
B(14,0,-10,minecraft:stone)
B(14,0,-9,minecraft:stone)
B(14,0,-8,minecraft:stone)
B(14,0,-7,minecraft:stone)
B(14,0,-6,minecraft:stone)
B(14,0,-5,minecraft:stone)
B(14,0,5,minecraft:stone)
B(14,0,6,minecraft:stone)
B(14,0,7,minecraft:stone)
B(14,0,8,minecraft:stone)
B(14,0,9,minecraft:stone)
B(14,0,10,minecraft:stone)
B(14,0,11,minecraft:stone)
B(14,0,12,minecraft:stone)
B(14,0,13,minecraft:stone)
B(14,0,14,minecraft:stone)
B(14,1,-11,minecraft:stone)
B(14,1,-10,minecraft:stone)
B(14,1,-9,minecraft:stone)
B(14,1,-8,minecraft:stone)
B(14,1,-7,minecraft:stone)
B(14,1,7,minecraft:stone)
B(14,1,8,minecraft:stone)
B(14,1,9,minecraft:stone)
B(14,1,12,minecraft:stone)
B(14,1,13,minecraft:stone)
B(14,2,-10,minecraft:stone)
B(14,2,-9,minecraft:stone)
B(14,2,-8,minecraft:stone)
B(14,2,-7,minecraft:stone)
B(14,3,-8,minecraft:stone)
B(15,0,-12,minecraft:stone)
B(15,0,-11,minecraft:stone)
B(15,0,-10,minecraft:stone)
B(15,0,-9,minecraft:stone)
B(15,0,-8,minecraft:stone)
B(15,0,-7,minecraft:stone)
B(15,0,-6,minecraft:stone)
B(15,0,8,minecraft:stone)
B(15,0,9,minecraft:stone)
B(15,1,-11,minecraft:stone)
B(15,1,-10,minecraft:stone)
B(15,1,-9,minecraft:stone)
B(15,1,-8,minecraft:stone)
B(15,1,-7,minecraft:stone)
B(16,0,-12,minecraft:stone)
B(16,0,-11,minecraft:stone)
B(16,0,-10,minecraft:stone)
B(16,0,-9,minecraft:stone)
B(16,0,-8,minecraft:stone)
B(16,0,-7,minecraft:stone)

#######################################################################
# +-----------------------------------------------------------------+ #
# |                            BO3 checks                           | #
# +-----------------------------------------------------------------+ #
#######################################################################

BlockCheck(0,-1,0,minecraft:sand,otg:dirt,minecraft:clay,minecraft:gravel)

#######################################################################
# +-----------------------------------------------------------------+ #
# |                             Branches                            | #
# +-----------------------------------------------------------------+ #
#######################################################################


#######################################################################
# +-----------------------------------------------------------------+ #
# |                             Entities                            | #
# +-----------------------------------------------------------------+ #
#######################################################################

