
#######################################################################
# +-----------------------------------------------------------------+ #
# |                            BO3 object                           | #
# +-----------------------------------------------------------------+ #
#######################################################################

Author: Unknown

Description: No description given

Version: 3

SettingsMode: WriteWithoutComments


#######################################################################
# +-----------------------------------------------------------------+ #
# |                          Main settings                          | #
# +-----------------------------------------------------------------+ #
#######################################################################

Tree: true

Frequency: 1

Rarity: 10.0

MaxSpawn: 0

RotateRandomly: true

SpawnHeight: highestSolidBlock

SpawnHeightOffset: -3

SpawnHeightVariance: 0

##############################
# Height Limits for the BO3. #
##############################

MinHeight: 52

MaxHeight: 62

######################
# Extrusion settings #
######################

ExtrudeMode: BottomDown

ExtrudeThroughBlocks: otg:air,minecraft:water

MaxBranchDepth: 10


#######################################################################
# +-----------------------------------------------------------------+ #
# |                      Source block settings                      | #
# +-----------------------------------------------------------------+ #
#######################################################################

SourceBlocks: otg:air

MaxPercentageOutsideSourceBlock: 100

OutsideSourceBlock: placeAnyway

DoReplaceBlocks: true

IsOTGPlus: false


#######################################################################
# +-----------------------------------------------------------------+ #
# |                              Blocks                             | #
# +-----------------------------------------------------------------+ #
#######################################################################

B(-11,0,-4,minecraft:stone)
B(-11,0,3,minecraft:stone)
B(-10,0,-6,minecraft:stone)
B(-10,0,-5,minecraft:stone)
B(-10,0,-4,minecraft:stone)
B(-10,0,-3,minecraft:stone)
B(-10,0,2,minecraft:stone)
B(-10,0,3,minecraft:stone)
B(-10,0,4,minecraft:stone)
B(-10,0,5,minecraft:stone)
B(-10,1,-4,minecraft:stone)
B(-10,1,-3,minecraft:stone)
B(-9,0,-6,minecraft:stone)
B(-9,0,-5,minecraft:stone)
B(-9,0,-4,minecraft:stone)
B(-9,0,-3,minecraft:stone)
B(-9,0,-2,minecraft:stone)
B(-9,0,-1,minecraft:stone)
B(-9,0,0,minecraft:stone)
B(-9,0,1,minecraft:stone)
B(-9,0,2,minecraft:stone)
B(-9,0,3,minecraft:stone)
B(-9,0,4,minecraft:stone)
B(-9,0,5,minecraft:stone)
B(-9,1,-5,minecraft:stone)
B(-9,1,-4,minecraft:stone)
B(-9,1,-3,minecraft:stone)
B(-9,1,-2,minecraft:stone)
B(-9,2,-2,minecraft:stone)
B(-8,0,-6,minecraft:stone)
B(-8,0,-5,minecraft:stone)
B(-8,0,-4,minecraft:stone)
B(-8,0,-3,minecraft:stone)
B(-8,0,-2,minecraft:stone)
B(-8,0,-1,minecraft:stone)
B(-8,0,0,minecraft:stone)
B(-8,0,1,minecraft:stone)
B(-8,0,2,minecraft:stone)
B(-8,0,3,minecraft:stone)
B(-8,0,4,minecraft:stone)
B(-8,0,5,minecraft:stone)
B(-8,0,6,minecraft:stone)
B(-8,1,-5,minecraft:stone)
B(-8,1,-4,minecraft:stone)
B(-8,1,-3,minecraft:stone)
B(-8,1,-2,minecraft:stone)
B(-8,1,-1,minecraft:stone)
B(-8,1,0,minecraft:stone)
B(-8,2,-4,minecraft:stone)
B(-8,2,-3,minecraft:stone)
B(-8,2,-2,minecraft:stone)
B(-8,2,-1,minecraft:stone)
B(-8,2,0,minecraft:stone)
B(-8,3,-3,minecraft:stone)
B(-7,0,-5,minecraft:stone)
B(-7,0,-4,minecraft:stone)
B(-7,0,-3,minecraft:stone)
B(-7,0,-2,minecraft:stone)
B(-7,0,-1,minecraft:stone)
B(-7,0,0,minecraft:stone)
B(-7,0,1,minecraft:stone)
B(-7,0,2,minecraft:stone)
B(-7,0,3,minecraft:stone)
B(-7,0,4,minecraft:stone)
B(-7,0,5,minecraft:stone)
B(-7,0,6,minecraft:stone)
B(-7,0,7,minecraft:stone)
B(-7,0,8,minecraft:stone)
B(-7,1,-5,minecraft:stone)
B(-7,1,-4,minecraft:stone)
B(-7,1,-3,minecraft:stone)
B(-7,1,-2,minecraft:stone)
B(-7,1,-1,minecraft:stone)
B(-7,1,0,minecraft:stone)
B(-7,1,1,minecraft:stone)
B(-7,1,2,minecraft:stone)
B(-7,1,3,minecraft:stone)
B(-7,1,4,minecraft:stone)
B(-7,2,-5,minecraft:stone)
B(-7,2,-4,minecraft:stone)
B(-7,2,-3,minecraft:stone)
B(-7,2,-2,minecraft:stone)
B(-7,2,-1,minecraft:stone)
B(-7,2,0,minecraft:stone)
B(-7,2,1,minecraft:stone)
B(-7,2,2,minecraft:stone)
B(-7,2,3,minecraft:stone)
B(-7,3,-4,minecraft:stone)
B(-7,3,-3,minecraft:stone)
B(-7,3,-2,minecraft:stone)
B(-7,3,-1,minecraft:stone)
B(-7,3,0,minecraft:stone)
B(-7,4,-2,minecraft:stone)
B(-7,4,-1,minecraft:stone)
B(-6,0,-6,minecraft:stone)
B(-6,0,-5,minecraft:stone)
B(-6,0,-4,minecraft:stone)
B(-6,0,-3,minecraft:stone)
B(-6,0,-2,minecraft:stone)
B(-6,0,-1,minecraft:stone)
B(-6,0,0,minecraft:stone)
B(-6,0,1,minecraft:stone)
B(-6,0,2,minecraft:stone)
B(-6,0,3,minecraft:stone)
B(-6,0,4,minecraft:stone)
B(-6,0,5,minecraft:stone)
B(-6,0,6,minecraft:stone)
B(-6,0,7,minecraft:stone)
B(-6,0,8,minecraft:stone)
B(-6,0,9,minecraft:stone)
B(-6,1,-5,minecraft:stone)
B(-6,1,-4,minecraft:stone)
B(-6,1,-3,minecraft:stone)
B(-6,1,-2,minecraft:stone)
B(-6,1,-1,minecraft:stone)
B(-6,1,0,minecraft:stone)
B(-6,1,1,minecraft:stone)
B(-6,1,2,minecraft:stone)
B(-6,1,3,minecraft:stone)
B(-6,1,4,minecraft:stone)
B(-6,1,6,minecraft:stone)
B(-6,1,7,minecraft:stone)
B(-6,2,-4,minecraft:stone)
B(-6,2,-3,minecraft:stone)
B(-6,2,-2,minecraft:stone)
B(-6,2,-1,minecraft:stone)
B(-6,2,0,minecraft:stone)
B(-6,2,1,minecraft:stone)
B(-6,2,2,minecraft:stone)
B(-6,2,3,minecraft:stone)
B(-6,3,-3,minecraft:stone)
B(-6,3,-2,minecraft:stone)
B(-6,3,-1,minecraft:stone)
B(-6,3,0,minecraft:stone)
B(-6,3,1,minecraft:stone)
B(-6,4,-2,minecraft:stone)
B(-6,4,-1,minecraft:stone)
B(-6,4,0,minecraft:stone)
B(-5,0,-7,minecraft:stone)
B(-5,0,-6,minecraft:stone)
B(-5,0,-5,minecraft:stone)
B(-5,0,-4,minecraft:stone)
B(-5,0,-3,minecraft:stone)
B(-5,0,-2,minecraft:stone)
B(-5,0,-1,minecraft:stone)
B(-5,0,0,minecraft:stone)
B(-5,0,1,minecraft:stone)
B(-5,0,2,minecraft:stone)
B(-5,0,3,minecraft:stone)
B(-5,0,4,minecraft:stone)
B(-5,0,5,minecraft:stone)
B(-5,0,6,minecraft:stone)
B(-5,0,7,minecraft:stone)
B(-5,0,8,minecraft:stone)
B(-5,0,9,minecraft:stone)
B(-5,0,10,minecraft:stone)
B(-5,1,-5,minecraft:stone)
B(-5,1,-4,minecraft:stone)
B(-5,1,-3,minecraft:stone)
B(-5,1,-2,minecraft:stone)
B(-5,1,-1,minecraft:stone)
B(-5,1,0,minecraft:stone)
B(-5,1,1,minecraft:stone)
B(-5,1,2,minecraft:stone)
B(-5,1,3,minecraft:stone)
B(-5,1,4,minecraft:stone)
B(-5,1,5,minecraft:stone)
B(-5,1,6,minecraft:stone)
B(-5,1,7,minecraft:stone)
B(-5,1,8,minecraft:stone)
B(-5,2,-4,minecraft:stone)
B(-5,2,-3,minecraft:stone)
B(-5,2,-2,minecraft:stone)
B(-5,2,-1,minecraft:stone)
B(-5,2,0,minecraft:stone)
B(-5,2,1,minecraft:stone)
B(-5,2,2,minecraft:stone)
B(-5,2,3,minecraft:stone)
B(-5,2,6,minecraft:stone)
B(-5,3,-3,minecraft:stone)
B(-5,3,-2,minecraft:stone)
B(-5,3,-1,minecraft:stone)
B(-5,3,0,minecraft:stone)
B(-5,3,1,minecraft:stone)
B(-5,3,2,minecraft:stone)
B(-5,4,-2,minecraft:stone)
B(-5,4,-1,minecraft:stone)
B(-5,4,0,minecraft:stone)
B(-5,4,1,minecraft:stone)
B(-5,5,0,minecraft:stone)
B(-4,0,-10,minecraft:stone)
B(-4,0,-9,minecraft:stone)
B(-4,0,-8,minecraft:stone)
B(-4,0,-7,minecraft:stone)
B(-4,0,-6,minecraft:stone)
B(-4,0,-5,minecraft:stone)
B(-4,0,-4,minecraft:stone)
B(-4,0,-3,minecraft:stone)
B(-4,0,-2,minecraft:stone)
B(-4,0,-1,minecraft:stone)
B(-4,0,0,minecraft:stone)
B(-4,0,1,minecraft:stone)
B(-4,0,2,minecraft:stone)
B(-4,0,3,minecraft:stone)
B(-4,0,4,minecraft:stone)
B(-4,0,5,minecraft:stone)
B(-4,0,6,minecraft:stone)
B(-4,0,7,minecraft:stone)
B(-4,0,8,minecraft:stone)
B(-4,0,9,minecraft:stone)
B(-4,0,10,minecraft:stone)
B(-4,0,11,minecraft:stone)
B(-4,1,-6,minecraft:stone)
B(-4,1,-5,minecraft:stone)
B(-4,1,-4,minecraft:stone)
B(-4,1,-3,minecraft:stone)
B(-4,1,-2,minecraft:stone)
B(-4,1,-1,minecraft:stone)
B(-4,1,0,minecraft:stone)
B(-4,1,1,minecraft:stone)
B(-4,1,2,minecraft:stone)
B(-4,1,3,minecraft:stone)
B(-4,1,4,minecraft:stone)
B(-4,1,5,minecraft:stone)
B(-4,1,6,minecraft:stone)
B(-4,1,7,minecraft:stone)
B(-4,1,8,minecraft:stone)
B(-4,1,9,minecraft:stone)
B(-4,2,-4,minecraft:stone)
B(-4,2,-3,minecraft:stone)
B(-4,2,-2,minecraft:stone)
B(-4,2,-1,minecraft:stone)
B(-4,2,0,minecraft:stone)
B(-4,2,1,minecraft:stone)
B(-4,2,2,minecraft:stone)
B(-4,2,3,minecraft:stone)
B(-4,2,4,minecraft:stone)
B(-4,2,5,minecraft:stone)
B(-4,2,6,minecraft:stone)
B(-4,2,7,minecraft:stone)
B(-4,2,8,minecraft:stone)
B(-4,3,-3,minecraft:stone)
B(-4,3,-2,minecraft:stone)
B(-4,3,-1,minecraft:stone)
B(-4,3,0,minecraft:stone)
B(-4,3,1,minecraft:stone)
B(-4,3,2,minecraft:stone)
B(-4,3,3,minecraft:stone)
B(-4,4,-2,minecraft:stone)
B(-4,4,-1,minecraft:stone)
B(-4,4,0,minecraft:stone)
B(-4,4,1,minecraft:stone)
B(-4,5,0,minecraft:stone)
B(-4,5,1,minecraft:stone)
B(-3,0,-10,minecraft:stone)
B(-3,0,-9,minecraft:stone)
B(-3,0,-8,minecraft:stone)
B(-3,0,-7,minecraft:stone)
B(-3,0,-6,minecraft:stone)
B(-3,0,-5,minecraft:stone)
B(-3,0,-4,minecraft:stone)
B(-3,0,-3,minecraft:stone)
B(-3,0,-2,minecraft:stone)
B(-3,0,-1,minecraft:stone)
B(-3,0,0,minecraft:stone)
B(-3,0,1,minecraft:stone)
B(-3,0,2,minecraft:stone)
B(-3,0,3,minecraft:stone)
B(-3,0,4,minecraft:stone)
B(-3,0,5,minecraft:stone)
B(-3,0,6,minecraft:stone)
B(-3,0,7,minecraft:stone)
B(-3,0,8,minecraft:stone)
B(-3,0,9,minecraft:stone)
B(-3,0,10,minecraft:stone)
B(-3,0,11,minecraft:stone)
B(-3,1,-7,minecraft:stone)
B(-3,1,-6,minecraft:stone)
B(-3,1,-5,minecraft:stone)
B(-3,1,-4,minecraft:stone)
B(-3,1,-3,minecraft:stone)
B(-3,1,-2,minecraft:stone)
B(-3,1,-1,minecraft:stone)
B(-3,1,0,minecraft:stone)
B(-3,1,1,minecraft:stone)
B(-3,1,2,minecraft:stone)
B(-3,1,3,minecraft:stone)
B(-3,1,4,minecraft:stone)
B(-3,1,5,minecraft:stone)
B(-3,1,6,minecraft:stone)
B(-3,1,7,minecraft:stone)
B(-3,1,8,minecraft:stone)
B(-3,1,9,minecraft:stone)
B(-3,2,-4,minecraft:stone)
B(-3,2,-3,minecraft:stone)
B(-3,2,-2,minecraft:stone)
B(-3,2,-1,minecraft:stone)
B(-3,2,0,minecraft:stone)
B(-3,2,1,minecraft:stone)
B(-3,2,2,minecraft:stone)
B(-3,2,3,minecraft:stone)
B(-3,2,4,minecraft:stone)
B(-3,2,5,minecraft:stone)
B(-3,2,6,minecraft:stone)
B(-3,2,7,minecraft:stone)
B(-3,2,8,minecraft:stone)
B(-3,3,-3,minecraft:stone)
B(-3,3,-2,minecraft:stone)
B(-3,3,-1,minecraft:stone)
B(-3,3,0,minecraft:stone)
B(-3,3,1,minecraft:stone)
B(-3,3,2,minecraft:stone)
B(-3,3,3,minecraft:stone)
B(-3,3,4,minecraft:stone)
B(-3,4,-1,minecraft:stone)
B(-3,4,0,minecraft:stone)
B(-3,4,1,minecraft:stone)
B(-3,4,2,minecraft:stone)
B(-3,4,3,minecraft:stone)
B(-3,5,0,minecraft:stone)
B(-3,5,1,minecraft:stone)
B(-3,5,2,minecraft:stone)
B(-2,0,-10,minecraft:stone)
B(-2,0,-9,minecraft:stone)
B(-2,0,-8,minecraft:stone)
B(-2,0,-7,minecraft:stone)
B(-2,0,-6,minecraft:stone)
B(-2,0,-5,minecraft:stone)
B(-2,0,-4,minecraft:stone)
B(-2,0,-3,minecraft:stone)
B(-2,0,-2,minecraft:stone)
B(-2,0,-1,minecraft:stone)
B(-2,0,0,minecraft:stone)
B(-2,0,1,minecraft:stone)
B(-2,0,2,minecraft:stone)
B(-2,0,3,minecraft:stone)
B(-2,0,4,minecraft:stone)
B(-2,0,5,minecraft:stone)
B(-2,0,6,minecraft:stone)
B(-2,0,7,minecraft:stone)
B(-2,0,8,minecraft:stone)
B(-2,0,9,minecraft:stone)
B(-2,0,10,minecraft:stone)
B(-2,1,-7,minecraft:stone)
B(-2,1,-6,minecraft:stone)
B(-2,1,-5,minecraft:stone)
B(-2,1,-4,minecraft:stone)
B(-2,1,-3,minecraft:stone)
B(-2,1,-2,minecraft:stone)
B(-2,1,-1,minecraft:stone)
B(-2,1,0,minecraft:stone)
B(-2,1,1,minecraft:stone)
B(-2,1,2,minecraft:stone)
B(-2,1,3,minecraft:stone)
B(-2,1,4,minecraft:stone)
B(-2,1,5,minecraft:stone)
B(-2,1,6,minecraft:stone)
B(-2,1,7,minecraft:stone)
B(-2,1,8,minecraft:stone)
B(-2,1,9,minecraft:stone)
B(-2,2,-4,minecraft:stone)
B(-2,2,-3,minecraft:stone)
B(-2,2,-2,minecraft:stone)
B(-2,2,-1,minecraft:stone)
B(-2,2,0,minecraft:stone)
B(-2,2,1,minecraft:stone)
B(-2,2,2,minecraft:stone)
B(-2,2,3,minecraft:stone)
B(-2,2,4,minecraft:stone)
B(-2,2,5,minecraft:stone)
B(-2,2,6,minecraft:stone)
B(-2,2,7,minecraft:stone)
B(-2,3,-4,minecraft:stone)
B(-2,3,-3,minecraft:stone)
B(-2,3,-2,minecraft:stone)
B(-2,3,-1,minecraft:stone)
B(-2,3,0,minecraft:stone)
B(-2,3,1,minecraft:stone)
B(-2,3,2,minecraft:stone)
B(-2,3,3,minecraft:stone)
B(-2,3,4,minecraft:stone)
B(-2,3,5,minecraft:stone)
B(-2,4,-2,minecraft:stone)
B(-2,4,-1,minecraft:stone)
B(-2,4,0,minecraft:stone)
B(-2,4,1,minecraft:stone)
B(-2,4,2,minecraft:stone)
B(-2,4,3,minecraft:stone)
B(-2,5,1,minecraft:stone)
B(-2,5,2,minecraft:stone)
B(-1,0,-9,minecraft:stone)
B(-1,0,-8,minecraft:stone)
B(-1,0,-7,minecraft:stone)
B(-1,0,-6,minecraft:stone)
B(-1,0,-5,minecraft:stone)
B(-1,0,-4,minecraft:stone)
B(-1,0,-3,minecraft:stone)
B(-1,0,-2,minecraft:stone)
B(-1,0,-1,minecraft:stone)
B(-1,0,0,minecraft:stone)
B(-1,0,1,minecraft:stone)
B(-1,0,2,minecraft:stone)
B(-1,0,3,minecraft:stone)
B(-1,0,4,minecraft:stone)
B(-1,0,5,minecraft:stone)
B(-1,0,6,minecraft:stone)
B(-1,0,7,minecraft:stone)
B(-1,0,8,minecraft:stone)
B(-1,0,9,minecraft:stone)
B(-1,0,10,minecraft:stone)
B(-1,0,11,minecraft:stone)
B(-1,1,-7,minecraft:stone)
B(-1,1,-6,minecraft:stone)
B(-1,1,-5,minecraft:stone)
B(-1,1,-4,minecraft:stone)
B(-1,1,-3,minecraft:stone)
B(-1,1,-2,minecraft:stone)
B(-1,1,-1,minecraft:stone)
B(-1,1,0,minecraft:stone)
B(-1,1,1,minecraft:stone)
B(-1,1,2,minecraft:stone)
B(-1,1,3,minecraft:stone)
B(-1,1,4,minecraft:stone)
B(-1,1,5,minecraft:stone)
B(-1,1,6,minecraft:stone)
B(-1,1,7,minecraft:stone)
B(-1,1,8,minecraft:stone)
B(-1,1,9,minecraft:stone)
B(-1,2,-4,minecraft:stone)
B(-1,2,-3,minecraft:stone)
B(-1,2,-2,minecraft:stone)
B(-1,2,-1,minecraft:stone)
B(-1,2,0,minecraft:stone)
B(-1,2,1,minecraft:stone)
B(-1,2,2,minecraft:stone)
B(-1,2,3,minecraft:stone)
B(-1,2,4,minecraft:stone)
B(-1,2,5,minecraft:stone)
B(-1,2,6,minecraft:stone)
B(-1,2,7,minecraft:stone)
B(-1,3,-2,minecraft:stone)
B(-1,3,-1,minecraft:stone)
B(-1,3,0,minecraft:stone)
B(-1,3,1,minecraft:stone)
B(-1,3,2,minecraft:stone)
B(-1,3,3,minecraft:stone)
B(-1,3,4,minecraft:stone)
B(-1,3,5,minecraft:stone)
B(-1,4,0,minecraft:stone)
B(-1,4,1,minecraft:stone)
B(-1,4,2,minecraft:stone)
B(-1,4,3,minecraft:stone)
B(-1,4,4,minecraft:stone)
B(-1,5,1,minecraft:stone)
B(-1,5,2,minecraft:stone)
B(-1,5,3,minecraft:stone)
B(-1,6,3,minecraft:stone)
B(0,0,-8,minecraft:stone)
B(0,0,-7,minecraft:stone)
B(0,0,-6,minecraft:stone)
B(0,0,-5,minecraft:stone)
B(0,0,-4,minecraft:stone)
B(0,0,-3,minecraft:stone)
B(0,0,-2,minecraft:stone)
B(0,0,-1,minecraft:stone)
B(0,0,0,minecraft:stone)
B(0,0,1,minecraft:stone)
B(0,0,2,minecraft:stone)
B(0,0,3,minecraft:stone)
B(0,0,4,minecraft:stone)
B(0,0,5,minecraft:stone)
B(0,0,6,minecraft:stone)
B(0,0,7,minecraft:stone)
B(0,0,8,minecraft:stone)
B(0,0,9,minecraft:stone)
B(0,1,-5,minecraft:stone)
B(0,1,-4,minecraft:stone)
B(0,1,-3,minecraft:stone)
B(0,1,-2,minecraft:stone)
B(0,1,-1,minecraft:stone)
B(0,1,0,minecraft:stone)
B(0,1,1,minecraft:stone)
B(0,1,2,minecraft:stone)
B(0,1,3,minecraft:stone)
B(0,1,4,minecraft:stone)
B(0,1,5,minecraft:stone)
B(0,1,6,minecraft:stone)
B(0,1,7,minecraft:stone)
B(0,1,8,minecraft:stone)
B(0,2,-5,minecraft:stone)
B(0,2,-4,minecraft:stone)
B(0,2,-2,minecraft:stone)
B(0,2,-1,minecraft:stone)
B(0,2,0,minecraft:stone)
B(0,2,1,minecraft:stone)
B(0,2,2,minecraft:stone)
B(0,2,3,minecraft:stone)
B(0,2,4,minecraft:stone)
B(0,2,5,minecraft:stone)
B(0,2,6,minecraft:stone)
B(0,2,7,minecraft:stone)
B(0,3,-1,minecraft:stone)
B(0,3,0,minecraft:stone)
B(0,3,1,minecraft:stone)
B(0,3,2,minecraft:stone)
B(0,3,3,minecraft:stone)
B(0,3,4,minecraft:stone)
B(0,3,5,minecraft:stone)
B(0,3,6,minecraft:stone)
B(0,3,7,minecraft:stone)
B(0,4,-1,minecraft:stone)
B(0,4,0,minecraft:stone)
B(0,4,1,minecraft:stone)
B(0,4,2,minecraft:stone)
B(0,4,3,minecraft:stone)
B(0,4,4,minecraft:stone)
B(0,4,5,minecraft:stone)
B(0,5,1,minecraft:stone)
B(0,5,2,minecraft:stone)
B(0,5,3,minecraft:stone)
B(1,0,-8,minecraft:stone)
B(1,0,-7,minecraft:stone)
B(1,0,-6,minecraft:stone)
B(1,0,-5,minecraft:stone)
B(1,0,-4,minecraft:stone)
B(1,0,-3,minecraft:stone)
B(1,0,-2,minecraft:stone)
B(1,0,-1,minecraft:stone)
B(1,0,0,minecraft:stone)
B(1,0,1,minecraft:stone)
B(1,0,2,minecraft:stone)
B(1,0,3,minecraft:stone)
B(1,0,4,minecraft:stone)
B(1,0,5,minecraft:stone)
B(1,0,6,minecraft:stone)
B(1,0,7,minecraft:stone)
B(1,0,8,minecraft:stone)
B(1,1,-5,minecraft:stone)
B(1,1,-4,minecraft:stone)
B(1,1,-3,minecraft:stone)
B(1,1,-2,minecraft:stone)
B(1,1,-1,minecraft:stone)
B(1,1,0,minecraft:stone)
B(1,1,1,minecraft:stone)
B(1,1,2,minecraft:stone)
B(1,1,3,minecraft:stone)
B(1,1,4,minecraft:stone)
B(1,1,5,minecraft:stone)
B(1,1,6,minecraft:stone)
B(1,1,7,minecraft:stone)
B(1,2,-2,minecraft:stone)
B(1,2,-1,minecraft:stone)
B(1,2,0,minecraft:stone)
B(1,2,1,minecraft:stone)
B(1,2,2,minecraft:stone)
B(1,2,3,minecraft:stone)
B(1,2,4,minecraft:stone)
B(1,2,5,minecraft:stone)
B(1,2,6,minecraft:stone)
B(1,2,7,minecraft:stone)
B(1,3,-2,minecraft:stone)
B(1,3,-1,minecraft:stone)
B(1,3,0,minecraft:stone)
B(1,3,1,minecraft:stone)
B(1,3,2,minecraft:stone)
B(1,3,3,minecraft:stone)
B(1,3,4,minecraft:stone)
B(1,3,5,minecraft:stone)
B(1,3,6,minecraft:stone)
B(1,4,-1,minecraft:stone)
B(1,4,0,minecraft:stone)
B(1,4,1,minecraft:stone)
B(1,4,2,minecraft:stone)
B(1,4,3,minecraft:stone)
B(1,4,4,minecraft:stone)
B(1,4,5,minecraft:stone)
B(1,5,2,minecraft:stone)
B(1,5,3,minecraft:stone)
B(2,0,-8,minecraft:stone)
B(2,0,-7,minecraft:stone)
B(2,0,-6,minecraft:stone)
B(2,0,-5,minecraft:stone)
B(2,0,-4,minecraft:stone)
B(2,0,-3,minecraft:stone)
B(2,0,-2,minecraft:stone)
B(2,0,-1,minecraft:stone)
B(2,0,0,minecraft:stone)
B(2,0,1,minecraft:stone)
B(2,0,2,minecraft:stone)
B(2,0,3,minecraft:stone)
B(2,0,4,minecraft:stone)
B(2,0,5,minecraft:stone)
B(2,0,6,minecraft:stone)
B(2,0,7,minecraft:stone)
B(2,0,8,minecraft:stone)
B(2,1,-7,minecraft:stone)
B(2,1,-6,minecraft:stone)
B(2,1,-5,minecraft:stone)
B(2,1,-4,minecraft:stone)
B(2,1,-3,minecraft:stone)
B(2,1,-2,minecraft:stone)
B(2,1,-1,minecraft:stone)
B(2,1,0,minecraft:stone)
B(2,1,1,minecraft:stone)
B(2,1,2,minecraft:stone)
B(2,1,3,minecraft:stone)
B(2,1,4,minecraft:stone)
B(2,1,5,minecraft:stone)
B(2,1,6,minecraft:stone)
B(2,1,7,minecraft:stone)
B(2,2,-2,minecraft:stone)
B(2,2,-1,minecraft:stone)
B(2,2,0,minecraft:stone)
B(2,2,1,minecraft:stone)
B(2,2,2,minecraft:stone)
B(2,2,3,minecraft:stone)
B(2,2,4,minecraft:stone)
B(2,2,5,minecraft:stone)
B(2,2,6,minecraft:stone)
B(2,3,0,minecraft:stone)
B(2,3,1,minecraft:stone)
B(2,3,2,minecraft:stone)
B(2,3,3,minecraft:stone)
B(2,3,4,minecraft:stone)
B(2,3,5,minecraft:stone)
B(2,4,0,minecraft:stone)
B(2,4,1,minecraft:stone)
B(2,4,2,minecraft:stone)
B(2,4,3,minecraft:stone)
B(2,4,4,minecraft:stone)
B(2,5,1,minecraft:stone)
B(2,5,2,minecraft:stone)
B(2,5,3,minecraft:stone)
B(2,6,2,minecraft:stone)
B(3,0,-8,minecraft:stone)
B(3,0,-7,minecraft:stone)
B(3,0,-6,minecraft:stone)
B(3,0,-5,minecraft:stone)
B(3,0,-4,minecraft:stone)
B(3,0,-3,minecraft:stone)
B(3,0,-2,minecraft:stone)
B(3,0,-1,minecraft:stone)
B(3,0,0,minecraft:stone)
B(3,0,1,minecraft:stone)
B(3,0,2,minecraft:stone)
B(3,0,3,minecraft:stone)
B(3,0,4,minecraft:stone)
B(3,0,5,minecraft:stone)
B(3,0,6,minecraft:stone)
B(3,0,7,minecraft:stone)
B(3,0,8,minecraft:stone)
B(3,0,9,minecraft:stone)
B(3,0,10,minecraft:stone)
B(3,1,-7,minecraft:stone)
B(3,1,-6,minecraft:stone)
B(3,1,-5,minecraft:stone)
B(3,1,-4,minecraft:stone)
B(3,1,-3,minecraft:stone)
B(3,1,-2,minecraft:stone)
B(3,1,-1,minecraft:stone)
B(3,1,0,minecraft:stone)
B(3,1,1,minecraft:stone)
B(3,1,2,minecraft:stone)
B(3,1,3,minecraft:stone)
B(3,1,4,minecraft:stone)
B(3,1,5,minecraft:stone)
B(3,1,6,minecraft:stone)
B(3,1,7,minecraft:stone)
B(3,2,-6,minecraft:stone)
B(3,2,-3,minecraft:stone)
B(3,2,-2,minecraft:stone)
B(3,2,-1,minecraft:stone)
B(3,2,0,minecraft:stone)
B(3,2,1,minecraft:stone)
B(3,2,2,minecraft:stone)
B(3,2,3,minecraft:stone)
B(3,2,4,minecraft:stone)
B(3,2,5,minecraft:stone)
B(3,2,6,minecraft:stone)
B(3,3,-1,minecraft:stone)
B(3,3,0,minecraft:stone)
B(3,3,1,minecraft:stone)
B(3,3,2,minecraft:stone)
B(3,3,3,minecraft:stone)
B(3,3,4,minecraft:stone)
B(3,3,5,minecraft:stone)
B(3,4,2,minecraft:stone)
B(3,4,3,minecraft:stone)
B(3,4,4,minecraft:stone)
B(3,4,5,minecraft:stone)
B(4,0,-8,minecraft:stone)
B(4,0,-7,minecraft:stone)
B(4,0,-6,minecraft:stone)
B(4,0,-5,minecraft:stone)
B(4,0,-4,minecraft:stone)
B(4,0,-3,minecraft:stone)
B(4,0,-2,minecraft:stone)
B(4,0,-1,minecraft:stone)
B(4,0,0,minecraft:stone)
B(4,0,1,minecraft:stone)
B(4,0,2,minecraft:stone)
B(4,0,3,minecraft:stone)
B(4,0,4,minecraft:stone)
B(4,0,5,minecraft:stone)
B(4,0,6,minecraft:stone)
B(4,0,7,minecraft:stone)
B(4,0,8,minecraft:stone)
B(4,0,9,minecraft:stone)
B(4,0,10,minecraft:stone)
B(4,0,11,minecraft:stone)
B(4,0,12,minecraft:stone)
B(4,0,13,minecraft:stone)
B(4,0,14,minecraft:stone)
B(4,1,-7,minecraft:stone)
B(4,1,-6,minecraft:stone)
B(4,1,-5,minecraft:stone)
B(4,1,-4,minecraft:stone)
B(4,1,-3,minecraft:stone)
B(4,1,-2,minecraft:stone)
B(4,1,-1,minecraft:stone)
B(4,1,0,minecraft:stone)
B(4,1,1,minecraft:stone)
B(4,1,2,minecraft:stone)
B(4,1,3,minecraft:stone)
B(4,1,4,minecraft:stone)
B(4,1,5,minecraft:stone)
B(4,1,6,minecraft:stone)
B(4,2,-6,minecraft:stone)
B(4,2,-3,minecraft:stone)
B(4,2,-2,minecraft:stone)
B(4,2,-1,minecraft:stone)
B(4,2,0,minecraft:stone)
B(4,2,1,minecraft:stone)
B(4,2,2,minecraft:stone)
B(4,2,3,minecraft:stone)
B(4,2,4,minecraft:stone)
B(4,2,5,minecraft:stone)
B(4,2,6,minecraft:stone)
B(4,3,-1,minecraft:stone)
B(4,3,0,minecraft:stone)
B(4,3,1,minecraft:stone)
B(4,3,2,minecraft:stone)
B(4,3,3,minecraft:stone)
B(4,3,4,minecraft:stone)
B(4,4,0,minecraft:stone)
B(4,4,1,minecraft:stone)
B(4,4,2,minecraft:stone)
B(4,4,3,minecraft:stone)
B(5,0,-11,minecraft:stone)
B(5,0,-9,minecraft:stone)
B(5,0,-8,minecraft:stone)
B(5,0,-7,minecraft:stone)
B(5,0,-6,minecraft:stone)
B(5,0,-5,minecraft:stone)
B(5,0,-4,minecraft:stone)
B(5,0,-3,minecraft:stone)
B(5,0,-2,minecraft:stone)
B(5,0,-1,minecraft:stone)
B(5,0,0,minecraft:stone)
B(5,0,1,minecraft:stone)
B(5,0,2,minecraft:stone)
B(5,0,3,minecraft:stone)
B(5,0,4,minecraft:stone)
B(5,0,5,minecraft:stone)
B(5,0,6,minecraft:stone)
B(5,0,7,minecraft:stone)
B(5,0,8,minecraft:stone)
B(5,0,9,minecraft:stone)
B(5,0,10,minecraft:stone)
B(5,0,11,minecraft:stone)
B(5,0,12,minecraft:stone)
B(5,0,13,minecraft:stone)
B(5,0,14,minecraft:stone)
B(5,1,-7,minecraft:stone)
B(5,1,-6,minecraft:stone)
B(5,1,-5,minecraft:stone)
B(5,1,-4,minecraft:stone)
B(5,1,-3,minecraft:stone)
B(5,1,-2,minecraft:stone)
B(5,1,-1,minecraft:stone)
B(5,1,0,minecraft:stone)
B(5,1,1,minecraft:stone)
B(5,1,2,minecraft:stone)
B(5,1,3,minecraft:stone)
B(5,1,4,minecraft:stone)
B(5,1,5,minecraft:stone)
B(5,1,6,minecraft:stone)
B(5,1,7,minecraft:stone)
B(5,1,8,minecraft:stone)
B(5,1,9,minecraft:stone)
B(5,1,10,minecraft:stone)
B(5,1,11,minecraft:stone)
B(5,2,-3,minecraft:stone)
B(5,2,-2,minecraft:stone)
B(5,2,-1,minecraft:stone)
B(5,2,0,minecraft:stone)
B(5,2,1,minecraft:stone)
B(5,2,2,minecraft:stone)
B(5,2,3,minecraft:stone)
B(5,2,4,minecraft:stone)
B(5,2,5,minecraft:stone)
B(5,2,6,minecraft:stone)
B(5,3,-2,minecraft:stone)
B(5,3,-1,minecraft:stone)
B(5,3,0,minecraft:stone)
B(5,3,1,minecraft:stone)
B(5,3,2,minecraft:stone)
B(5,4,0,minecraft:stone)
B(5,4,1,minecraft:stone)
B(5,4,2,minecraft:stone)
B(6,0,-12,minecraft:stone)
B(6,0,-11,minecraft:stone)
B(6,0,-10,minecraft:stone)
B(6,0,-9,minecraft:stone)
B(6,0,-8,minecraft:stone)
B(6,0,-7,minecraft:stone)
B(6,0,-6,minecraft:stone)
B(6,0,-5,minecraft:stone)
B(6,0,-4,minecraft:stone)
B(6,0,-3,minecraft:stone)
B(6,0,-2,minecraft:stone)
B(6,0,-1,minecraft:stone)
B(6,0,0,minecraft:stone)
B(6,0,1,minecraft:stone)
B(6,0,2,minecraft:stone)
B(6,0,3,minecraft:stone)
B(6,0,4,minecraft:stone)
B(6,0,5,minecraft:stone)
B(6,0,6,minecraft:stone)
B(6,0,7,minecraft:stone)
B(6,0,8,minecraft:stone)
B(6,0,9,minecraft:stone)
B(6,0,10,minecraft:stone)
B(6,0,11,minecraft:stone)
B(6,0,12,minecraft:stone)
B(6,0,13,minecraft:stone)
B(6,0,14,minecraft:stone)
B(6,1,-7,minecraft:stone)
B(6,1,-6,minecraft:stone)
B(6,1,-5,minecraft:stone)
B(6,1,-4,minecraft:stone)
B(6,1,-3,minecraft:stone)
B(6,1,-2,minecraft:stone)
B(6,1,-1,minecraft:stone)
B(6,1,0,minecraft:stone)
B(6,1,1,minecraft:stone)
B(6,1,2,minecraft:stone)
B(6,1,3,minecraft:stone)
B(6,1,4,minecraft:stone)
B(6,1,5,minecraft:stone)
B(6,1,6,minecraft:stone)
B(6,1,7,minecraft:stone)
B(6,1,8,minecraft:stone)
B(6,1,9,minecraft:stone)
B(6,1,10,minecraft:stone)
B(6,1,11,minecraft:stone)
B(6,2,-4,minecraft:stone)
B(6,2,-3,minecraft:stone)
B(6,2,-2,minecraft:stone)
B(6,2,-1,minecraft:stone)
B(6,2,0,minecraft:stone)
B(6,2,1,minecraft:stone)
B(6,2,2,minecraft:stone)
B(6,2,3,minecraft:stone)
B(6,2,4,minecraft:stone)
B(6,2,5,minecraft:stone)
B(6,2,9,minecraft:stone)
B(6,3,-2,minecraft:stone)
B(6,3,-1,minecraft:stone)
B(6,3,0,minecraft:stone)
B(6,3,1,minecraft:stone)
B(6,3,2,minecraft:stone)
B(6,4,-1,minecraft:stone)
B(6,4,0,minecraft:stone)
B(6,4,1,minecraft:stone)
B(7,0,-12,minecraft:stone)
B(7,0,-11,minecraft:stone)
B(7,0,-10,minecraft:stone)
B(7,0,-9,minecraft:stone)
B(7,0,-8,minecraft:stone)
B(7,0,-7,minecraft:stone)
B(7,0,-6,minecraft:stone)
B(7,0,-5,minecraft:stone)
B(7,0,-4,minecraft:stone)
B(7,0,-3,minecraft:stone)
B(7,0,-2,minecraft:stone)
B(7,0,-1,minecraft:stone)
B(7,0,0,minecraft:stone)
B(7,0,1,minecraft:stone)
B(7,0,2,minecraft:stone)
B(7,0,3,minecraft:stone)
B(7,0,4,minecraft:stone)
B(7,0,5,minecraft:stone)
B(7,0,6,minecraft:stone)
B(7,0,7,minecraft:stone)
B(7,0,8,minecraft:stone)
B(7,0,9,minecraft:stone)
B(7,0,10,minecraft:stone)
B(7,0,11,minecraft:stone)
B(7,0,12,minecraft:stone)
B(7,0,13,minecraft:stone)
B(7,1,-9,minecraft:stone)
B(7,1,-7,minecraft:stone)
B(7,1,-6,minecraft:stone)
B(7,1,-5,minecraft:stone)
B(7,1,-4,minecraft:stone)
B(7,1,-3,minecraft:stone)
B(7,1,-2,minecraft:stone)
B(7,1,-1,minecraft:stone)
B(7,1,0,minecraft:stone)
B(7,1,1,minecraft:stone)
B(7,1,2,minecraft:stone)
B(7,1,3,minecraft:stone)
B(7,1,4,minecraft:stone)
B(7,1,5,minecraft:stone)
B(7,1,6,minecraft:stone)
B(7,1,7,minecraft:stone)
B(7,1,8,minecraft:stone)
B(7,1,9,minecraft:stone)
B(7,1,10,minecraft:stone)
B(7,1,12,minecraft:stone)
B(7,2,-4,minecraft:stone)
B(7,2,-3,minecraft:stone)
B(7,2,-2,minecraft:stone)
B(7,2,-1,minecraft:stone)
B(7,2,0,minecraft:stone)
B(7,2,1,minecraft:stone)
B(7,2,2,minecraft:stone)
B(7,2,3,minecraft:stone)
B(7,3,-2,minecraft:stone)
B(7,3,-1,minecraft:stone)
B(7,3,0,minecraft:stone)
B(7,3,1,minecraft:stone)
B(8,0,-10,minecraft:stone)
B(8,0,-9,minecraft:stone)
B(8,0,-8,minecraft:stone)
B(8,0,-7,minecraft:stone)
B(8,0,-6,minecraft:stone)
B(8,0,-5,minecraft:stone)
B(8,0,-4,minecraft:stone)
B(8,0,-3,minecraft:stone)
B(8,0,-2,minecraft:stone)
B(8,0,-1,minecraft:stone)
B(8,0,0,minecraft:stone)
B(8,0,1,minecraft:stone)
B(8,0,2,minecraft:stone)
B(8,0,3,minecraft:stone)
B(8,0,4,minecraft:stone)
B(8,0,5,minecraft:stone)
B(8,0,6,minecraft:stone)
B(8,0,7,minecraft:stone)
B(8,0,8,minecraft:stone)
B(8,0,9,minecraft:stone)
B(8,0,10,minecraft:stone)
B(8,0,11,minecraft:stone)
B(8,0,12,minecraft:stone)
B(8,0,13,minecraft:stone)
B(8,1,-9,minecraft:stone)
B(8,1,-8,minecraft:stone)
B(8,1,-7,minecraft:stone)
B(8,1,-6,minecraft:stone)
B(8,1,-5,minecraft:stone)
B(8,1,-4,minecraft:stone)
B(8,1,-3,minecraft:stone)
B(8,1,-2,minecraft:stone)
B(8,1,-1,minecraft:stone)
B(8,1,0,minecraft:stone)
B(8,1,2,minecraft:stone)
B(8,1,5,minecraft:stone)
B(8,1,6,minecraft:stone)
B(8,1,7,minecraft:stone)
B(9,0,-10,minecraft:stone)
B(9,0,-9,minecraft:stone)
B(9,0,-8,minecraft:stone)
B(9,0,-7,minecraft:stone)
B(9,0,-6,minecraft:stone)
B(9,0,-5,minecraft:stone)
B(9,0,-4,minecraft:stone)
B(9,0,-3,minecraft:stone)
B(9,0,-2,minecraft:stone)
B(9,0,-1,minecraft:stone)
B(9,0,1,minecraft:stone)
B(9,0,2,minecraft:stone)
B(9,0,3,minecraft:stone)
B(9,0,4,minecraft:stone)
B(9,0,5,minecraft:stone)
B(9,0,6,minecraft:stone)
B(9,0,7,minecraft:stone)
B(9,0,8,minecraft:stone)
B(9,0,9,minecraft:stone)
B(9,0,12,minecraft:stone)
B(9,0,13,minecraft:stone)
B(9,1,-9,minecraft:stone)
B(9,1,-8,minecraft:stone)
B(9,1,-7,minecraft:stone)
B(9,1,-6,minecraft:stone)
B(9,1,4,minecraft:stone)
B(9,1,5,minecraft:stone)
B(9,1,6,minecraft:stone)
B(9,1,7,minecraft:stone)
B(9,2,-8,minecraft:stone)
B(9,2,-7,minecraft:stone)
B(10,0,-11,minecraft:stone)
B(10,0,-10,minecraft:stone)
B(10,0,-9,minecraft:stone)
B(10,0,-8,minecraft:stone)
B(10,0,-7,minecraft:stone)
B(10,0,-6,minecraft:stone)
B(10,0,-5,minecraft:stone)
B(10,0,-4,minecraft:stone)
B(10,0,-3,minecraft:stone)
B(10,0,-2,minecraft:stone)
B(10,0,3,minecraft:stone)
B(10,0,4,minecraft:stone)
B(10,0,5,minecraft:stone)
B(10,0,6,minecraft:stone)
B(10,0,7,minecraft:stone)
B(10,0,8,minecraft:stone)
B(10,0,9,minecraft:stone)
B(10,1,-9,minecraft:stone)
B(10,1,-8,minecraft:stone)
B(10,1,-7,minecraft:stone)
B(10,1,-6,minecraft:stone)
B(10,1,-5,minecraft:stone)
B(10,1,4,minecraft:stone)
B(10,1,5,minecraft:stone)
B(10,1,6,minecraft:stone)
B(10,1,7,minecraft:stone)
B(10,1,8,minecraft:stone)
B(10,2,-8,minecraft:stone)
B(10,2,-7,minecraft:stone)
B(11,0,-11,minecraft:stone)
B(11,0,-10,minecraft:stone)
B(11,0,-9,minecraft:stone)
B(11,0,-8,minecraft:stone)
B(11,0,-7,minecraft:stone)
B(11,0,-6,minecraft:stone)
B(11,0,-5,minecraft:stone)
B(11,0,-4,minecraft:stone)
B(11,0,3,minecraft:stone)
B(11,0,4,minecraft:stone)
B(11,0,5,minecraft:stone)
B(11,0,6,minecraft:stone)
B(11,0,7,minecraft:stone)
B(11,0,8,minecraft:stone)
B(11,0,9,minecraft:stone)
B(11,1,-9,minecraft:stone)
B(11,1,-8,minecraft:stone)
B(11,1,-7,minecraft:stone)
B(11,1,-6,minecraft:stone)
B(11,1,-5,minecraft:stone)
B(11,1,5,minecraft:stone)
B(11,1,6,minecraft:stone)
B(11,1,7,minecraft:stone)
B(11,2,-8,minecraft:stone)
B(11,2,-7,minecraft:stone)
B(12,0,-11,minecraft:stone)
B(12,0,-10,minecraft:stone)
B(12,0,-9,minecraft:stone)
B(12,0,-8,minecraft:stone)
B(12,0,-7,minecraft:stone)
B(12,0,-6,minecraft:stone)
B(12,0,-5,minecraft:stone)
B(12,0,-4,minecraft:stone)
B(12,0,4,minecraft:stone)
B(12,0,5,minecraft:stone)
B(12,0,6,minecraft:stone)
B(12,0,7,minecraft:stone)
B(12,0,8,minecraft:stone)
B(12,0,9,minecraft:stone)
B(12,0,10,minecraft:stone)
B(12,1,-10,minecraft:stone)
B(12,1,-9,minecraft:stone)
B(12,1,-8,minecraft:stone)
B(12,1,-7,minecraft:stone)
B(12,1,-6,minecraft:stone)
B(12,1,5,minecraft:stone)
B(12,1,6,minecraft:stone)
B(12,1,7,minecraft:stone)
B(12,1,8,minecraft:stone)
B(12,2,-8,minecraft:stone)
B(13,0,-11,minecraft:stone)
B(13,0,-10,minecraft:stone)
B(13,0,-9,minecraft:stone)
B(13,0,-8,minecraft:stone)
B(13,0,-7,minecraft:stone)
B(13,0,-6,minecraft:stone)
B(13,0,-5,minecraft:stone)
B(13,0,-4,minecraft:stone)
B(13,0,5,minecraft:stone)
B(13,0,6,minecraft:stone)
B(13,0,7,minecraft:stone)
B(13,0,8,minecraft:stone)
B(13,0,9,minecraft:stone)
B(13,0,10,minecraft:stone)
B(13,1,-9,minecraft:stone)
B(13,1,-8,minecraft:stone)
B(13,1,-7,minecraft:stone)
B(13,1,-6,minecraft:stone)
B(13,1,7,minecraft:stone)
B(14,0,-11,minecraft:stone)
B(14,0,-10,minecraft:stone)
B(14,0,-9,minecraft:stone)
B(14,0,-8,minecraft:stone)
B(14,0,-7,minecraft:stone)
B(14,0,-6,minecraft:stone)
B(14,0,6,minecraft:stone)
B(14,0,7,minecraft:stone)
B(14,0,8,minecraft:stone)
B(14,0,9,minecraft:stone)
B(14,1,-9,minecraft:stone)

#######################################################################
# +-----------------------------------------------------------------+ #
# |                            BO3 checks                           | #
# +-----------------------------------------------------------------+ #
#######################################################################

BlockCheck(0,-1,0,minecraft:sand,otg:dirt,minecraft:clay,minecraft:gravel)

#######################################################################
# +-----------------------------------------------------------------+ #
# |                             Branches                            | #
# +-----------------------------------------------------------------+ #
#######################################################################


#######################################################################
# +-----------------------------------------------------------------+ #
# |                             Entities                            | #
# +-----------------------------------------------------------------+ #
#######################################################################

