
#######################################################################
# +-----------------------------------------------------------------+ #
# |                            BO3 object                           | #
# +-----------------------------------------------------------------+ #
#######################################################################

Author: Unknown

Description: No description given

Version: 3

SettingsMode: WriteWithoutComments


#######################################################################
# +-----------------------------------------------------------------+ #
# |                          Main settings                          | #
# +-----------------------------------------------------------------+ #
#######################################################################

Tree: true

Frequency: 1

Rarity: 10.0

MaxSpawn: 0

RotateRandomly: true

SpawnHeight: highestSolidBlock

SpawnHeightOffset: -1

SpawnHeightVariance: 0

##############################
# Height Limits for the BO3. #
##############################

MinHeight: 52

MaxHeight: 62

######################
# Extrusion settings #
######################

ExtrudeMode: BottomDown

ExtrudeThroughBlocks: otg:air,minecraft:water

MaxBranchDepth: 10


#######################################################################
# +-----------------------------------------------------------------+ #
# |                      Source block settings                      | #
# +-----------------------------------------------------------------+ #
#######################################################################

SourceBlocks: otg:air

MaxPercentageOutsideSourceBlock: 100

OutsideSourceBlock: placeAnyway

DoReplaceBlocks: true

IsOTGPlus: false


#######################################################################
# +-----------------------------------------------------------------+ #
# |                              Blocks                             | #
# +-----------------------------------------------------------------+ #
#######################################################################

B(-7,0,-1,minecraft:stone)
B(-7,0,0,minecraft:stone)
B(-6,0,-2,minecraft:stone)
B(-6,0,-1,minecraft:stone)
B(-6,0,0,minecraft:stone)
B(-6,0,1,minecraft:stone)
B(-5,0,-2,minecraft:stone)
B(-5,0,-1,minecraft:stone)
B(-5,0,0,minecraft:stone)
B(-5,0,1,minecraft:stone)
B(-5,1,-1,minecraft:stone)
B(-5,1,0,minecraft:stone)
B(-4,0,-2,minecraft:stone)
B(-4,0,-1,minecraft:stone)
B(-4,0,0,minecraft:stone)
B(-4,0,1,minecraft:stone)
B(-4,0,2,minecraft:stone)
B(-4,0,3,minecraft:stone)
B(-4,1,-2,minecraft:stone)
B(-4,1,-1,minecraft:stone)
B(-4,1,0,minecraft:stone)
B(-4,1,1,minecraft:stone)
B(-4,2,-1,minecraft:stone)
B(-4,2,0,minecraft:stone)
B(-3,0,-5,minecraft:stone)
B(-3,0,-4,minecraft:stone)
B(-3,0,-3,minecraft:stone)
B(-3,0,-2,minecraft:stone)
B(-3,0,-1,minecraft:stone)
B(-3,0,0,minecraft:stone)
B(-3,0,1,minecraft:stone)
B(-3,0,2,minecraft:stone)
B(-3,0,3,minecraft:stone)
B(-3,0,4,minecraft:stone)
B(-3,1,-2,minecraft:stone)
B(-3,1,-1,minecraft:stone)
B(-3,1,0,minecraft:stone)
B(-3,1,1,minecraft:stone)
B(-3,2,-1,minecraft:stone)
B(-3,2,0,minecraft:stone)
B(-3,2,1,minecraft:stone)
B(-3,3,-1,minecraft:stone)
B(-3,3,0,minecraft:stone)
B(-2,0,-4,minecraft:stone)
B(-2,0,-3,minecraft:stone)
B(-2,0,-2,minecraft:stone)
B(-2,0,-1,minecraft:stone)
B(-2,0,0,minecraft:stone)
B(-2,0,1,minecraft:stone)
B(-2,0,2,minecraft:stone)
B(-2,0,3,minecraft:stone)
B(-2,0,4,minecraft:stone)
B(-2,0,5,minecraft:stone)
B(-2,1,-2,minecraft:stone)
B(-2,1,-1,minecraft:stone)
B(-2,1,0,minecraft:stone)
B(-2,1,1,minecraft:stone)
B(-2,1,2,minecraft:stone)
B(-2,1,3,minecraft:stone)
B(-2,1,4,minecraft:stone)
B(-2,2,-2,minecraft:stone)
B(-2,2,-1,minecraft:stone)
B(-2,2,0,minecraft:stone)
B(-2,2,1,minecraft:stone)
B(-2,2,2,minecraft:stone)
B(-2,3,0,minecraft:stone)
B(-2,3,1,minecraft:stone)
B(-1,0,-5,minecraft:stone)
B(-1,0,-4,minecraft:stone)
B(-1,0,-3,minecraft:stone)
B(-1,0,-2,minecraft:stone)
B(-1,0,-1,minecraft:stone)
B(-1,0,0,minecraft:stone)
B(-1,0,1,minecraft:stone)
B(-1,0,2,minecraft:stone)
B(-1,0,3,minecraft:stone)
B(-1,0,4,minecraft:stone)
B(-1,0,5,minecraft:stone)
B(-1,0,6,minecraft:stone)
B(-1,1,-3,minecraft:stone)
B(-1,1,-2,minecraft:stone)
B(-1,1,-1,minecraft:stone)
B(-1,1,0,minecraft:stone)
B(-1,1,1,minecraft:stone)
B(-1,1,2,minecraft:stone)
B(-1,1,3,minecraft:stone)
B(-1,1,4,minecraft:stone)
B(-1,2,-2,minecraft:stone)
B(-1,2,-1,minecraft:stone)
B(-1,2,0,minecraft:stone)
B(-1,2,1,minecraft:stone)
B(-1,2,2,minecraft:stone)
B(-1,2,3,minecraft:stone)
B(-1,3,-2,minecraft:stone)
B(-1,3,-1,minecraft:stone)
B(-1,3,0,minecraft:stone)
B(-1,3,1,minecraft:stone)
B(-1,4,-1,minecraft:stone)
B(-1,4,0,minecraft:stone)
B(0,0,-5,minecraft:stone)
B(0,0,-4,minecraft:stone)
B(0,0,-3,minecraft:stone)
B(0,0,-2,minecraft:stone)
B(0,0,-1,minecraft:stone)
B(0,0,0,minecraft:stone)
B(0,0,1,minecraft:stone)
B(0,0,2,minecraft:stone)
B(0,0,3,minecraft:stone)
B(0,0,4,minecraft:stone)
B(0,0,5,minecraft:stone)
B(0,1,-5,minecraft:stone)
B(0,1,-4,minecraft:stone)
B(0,1,-3,minecraft:stone)
B(0,1,-2,minecraft:stone)
B(0,1,-1,minecraft:stone)
B(0,1,0,minecraft:stone)
B(0,1,1,minecraft:stone)
B(0,1,2,minecraft:stone)
B(0,1,3,minecraft:stone)
B(0,1,4,minecraft:stone)
B(0,1,5,minecraft:stone)
B(0,2,-3,minecraft:stone)
B(0,2,-2,minecraft:stone)
B(0,2,-1,minecraft:stone)
B(0,2,0,minecraft:stone)
B(0,2,1,minecraft:stone)
B(0,2,2,minecraft:stone)
B(0,2,3,minecraft:stone)
B(0,2,4,minecraft:stone)
B(0,3,-1,minecraft:stone)
B(0,3,0,minecraft:stone)
B(0,3,1,minecraft:stone)
B(0,3,2,minecraft:stone)
B(0,4,0,minecraft:stone)
B(1,0,-5,minecraft:stone)
B(1,0,-4,minecraft:stone)
B(1,0,-3,minecraft:stone)
B(1,0,-2,minecraft:stone)
B(1,0,-1,minecraft:stone)
B(1,0,0,minecraft:stone)
B(1,0,1,minecraft:stone)
B(1,0,2,minecraft:stone)
B(1,0,3,minecraft:stone)
B(1,0,4,minecraft:stone)
B(1,0,5,minecraft:stone)
B(1,0,6,minecraft:stone)
B(1,1,-3,minecraft:stone)
B(1,1,-2,minecraft:stone)
B(1,1,-1,minecraft:stone)
B(1,1,0,minecraft:stone)
B(1,1,1,minecraft:stone)
B(1,1,2,minecraft:stone)
B(1,1,3,minecraft:stone)
B(1,1,4,minecraft:stone)
B(1,1,5,minecraft:stone)
B(1,2,-2,minecraft:stone)
B(1,2,-1,minecraft:stone)
B(1,2,0,minecraft:stone)
B(1,2,1,minecraft:stone)
B(1,2,2,minecraft:stone)
B(1,2,3,minecraft:stone)
B(1,2,4,minecraft:stone)
B(1,2,5,minecraft:stone)
B(1,3,0,minecraft:stone)
B(1,3,1,minecraft:stone)
B(1,3,2,minecraft:stone)
B(1,3,3,minecraft:stone)
B(1,3,4,minecraft:stone)
B(1,4,0,minecraft:stone)
B(2,0,-5,minecraft:stone)
B(2,0,-4,minecraft:stone)
B(2,0,-3,minecraft:stone)
B(2,0,-2,minecraft:stone)
B(2,0,-1,minecraft:stone)
B(2,0,0,minecraft:stone)
B(2,0,1,minecraft:stone)
B(2,0,2,minecraft:stone)
B(2,0,3,minecraft:stone)
B(2,0,4,minecraft:stone)
B(2,0,5,minecraft:stone)
B(2,1,-4,minecraft:stone)
B(2,1,-3,minecraft:stone)
B(2,1,-2,minecraft:stone)
B(2,1,-1,minecraft:stone)
B(2,1,0,minecraft:stone)
B(2,1,1,minecraft:stone)
B(2,1,2,minecraft:stone)
B(2,1,3,minecraft:stone)
B(2,1,4,minecraft:stone)
B(2,1,5,minecraft:stone)
B(2,2,-2,minecraft:stone)
B(2,2,-1,minecraft:stone)
B(2,2,0,minecraft:stone)
B(2,2,1,minecraft:stone)
B(2,2,2,minecraft:stone)
B(2,2,3,minecraft:stone)
B(2,2,4,minecraft:stone)
B(2,2,5,minecraft:stone)
B(2,3,-1,minecraft:stone)
B(2,3,3,minecraft:stone)
B(3,0,-6,minecraft:stone)
B(3,0,-5,minecraft:stone)
B(3,0,-4,minecraft:stone)
B(3,0,-3,minecraft:stone)
B(3,0,-2,minecraft:stone)
B(3,0,-1,minecraft:stone)
B(3,0,0,minecraft:stone)
B(3,0,1,minecraft:stone)
B(3,0,2,minecraft:stone)
B(3,0,3,minecraft:stone)
B(3,0,4,minecraft:stone)
B(3,0,5,minecraft:stone)
B(3,0,6,minecraft:stone)
B(3,1,-4,minecraft:stone)
B(3,1,-3,minecraft:stone)
B(3,1,-2,minecraft:stone)
B(3,1,-1,minecraft:stone)
B(3,1,0,minecraft:stone)
B(3,1,1,minecraft:stone)
B(3,1,2,minecraft:stone)
B(3,1,3,minecraft:stone)
B(3,1,4,minecraft:stone)
B(3,1,5,minecraft:stone)
B(3,2,-2,minecraft:stone)
B(3,2,-1,minecraft:stone)
B(3,2,0,minecraft:stone)
B(3,2,1,minecraft:stone)
B(3,2,2,minecraft:stone)
B(3,2,3,minecraft:stone)
B(3,2,4,minecraft:stone)
B(3,3,4,minecraft:stone)
B(4,0,-5,minecraft:stone)
B(4,0,-4,minecraft:stone)
B(4,0,-3,minecraft:stone)
B(4,0,-2,minecraft:stone)
B(4,0,-1,minecraft:stone)
B(4,0,0,minecraft:stone)
B(4,0,1,minecraft:stone)
B(4,0,2,minecraft:stone)
B(4,0,3,minecraft:stone)
B(4,0,4,minecraft:stone)
B(4,0,5,minecraft:stone)
B(4,0,6,minecraft:stone)
B(4,1,-1,minecraft:stone)
B(4,1,0,minecraft:stone)
B(4,1,1,minecraft:stone)
B(4,1,2,minecraft:stone)
B(4,1,3,minecraft:stone)
B(4,1,4,minecraft:stone)
B(4,1,5,minecraft:stone)
B(4,2,2,minecraft:stone)
B(4,2,3,minecraft:stone)
B(4,2,4,minecraft:stone)
B(5,0,-2,minecraft:stone)
B(5,0,-1,minecraft:stone)
B(5,0,0,minecraft:stone)
B(5,0,1,minecraft:stone)
B(5,0,2,minecraft:stone)
B(5,0,3,minecraft:stone)
B(5,0,4,minecraft:stone)
B(5,0,5,minecraft:stone)
B(5,0,6,minecraft:stone)
B(5,1,3,minecraft:stone)
B(5,1,4,minecraft:stone)
B(5,1,5,minecraft:stone)
B(6,0,-3,minecraft:stone)
B(6,0,-2,minecraft:stone)
B(6,0,-1,minecraft:stone)
B(6,0,0,minecraft:stone)
B(6,0,1,minecraft:stone)
B(6,0,3,minecraft:stone)
B(6,0,4,minecraft:stone)
B(6,0,5,minecraft:stone)
B(6,0,6,minecraft:stone)

#######################################################################
# +-----------------------------------------------------------------+ #
# |                            BO3 checks                           | #
# +-----------------------------------------------------------------+ #
#######################################################################

BlockCheck(0,-1,0,minecraft:sand,otg:dirt,minecraft:clay,minecraft:gravel)

#######################################################################
# +-----------------------------------------------------------------+ #
# |                             Branches                            | #
# +-----------------------------------------------------------------+ #
#######################################################################


#######################################################################
# +-----------------------------------------------------------------+ #
# |                             Entities                            | #
# +-----------------------------------------------------------------+ #
#######################################################################

