
#######################################################################
# +-----------------------------------------------------------------+ #
# |                            BO3 object                           | #
# +-----------------------------------------------------------------+ #
#######################################################################

Author: Unknown

Description: No description

Version: 3

SettingsMode: WriteWithoutComments


#######################################################################
# +-----------------------------------------------------------------+ #
# |                          Main settings                          | #
# +-----------------------------------------------------------------+ #
#######################################################################

Tree: false

Frequency: 1

Rarity: 100.0

MaxSpawn: 0

RotateRandomly: true

SpawnHeight: highestSolidBlock

SpawnHeightOffset: -3

SpawnHeightVariance: 0

##############################
# Height Limits for the BO3. #
##############################

MinHeight: 0

MaxHeight: 59

######################
# Extrusion settings #
######################

ExtrudeMode: None

ExtrudeThroughBlocks: otg:air

MaxBranchDepth: 10


#######################################################################
# +-----------------------------------------------------------------+ #
# |                      Source block settings                      | #
# +-----------------------------------------------------------------+ #
#######################################################################

SourceBlocks: minecraft:water

MaxPercentageOutsideSourceBlock: 100

OutsideSourceBlock: dontPlace

DoReplaceBlocks: true

IsOTGPlus: false


#######################################################################
# +-----------------------------------------------------------------+ #
# |                              Blocks                             | #
# +-----------------------------------------------------------------+ #
#######################################################################

B(-8,2,-4,minecraft:terracotta)
B(-8,2,-2,minecraft:terracotta)
B(-8,2,-1,minecraft:terracotta)
B(-8,2,0,minecraft:terracotta)
B(-7,1,-4,minecraft:terracotta)
B(-7,1,-3,minecraft:terracotta)
B(-7,1,-2,minecraft:terracotta)
B(-7,2,-5,minecraft:terracotta)
B(-7,2,-4,minecraft:terracotta)
B(-7,2,-3,minecraft:terracotta)
B(-7,2,-2,minecraft:terracotta)
B(-7,2,-1,minecraft:terracotta)
B(-7,2,0,minecraft:terracotta)
B(-7,2,1,minecraft:terracotta)
B(-7,3,-4,minecraft:terracotta)
B(-7,3,-3,minecraft:terracotta)
B(-7,3,-2,minecraft:terracotta)
B(-6,0,-3,minecraft:terracotta)
B(-6,1,-5,minecraft:terracotta)
B(-6,1,-4,minecraft:terracotta)
B(-6,1,-3,minecraft:terracotta)
B(-6,1,-2,minecraft:terracotta)
B(-6,2,-6,minecraft:terracotta)
B(-6,2,-5,minecraft:terracotta)
B(-6,2,-4,minecraft:terracotta)
B(-6,2,-3,minecraft:terracotta)
B(-6,2,-2,minecraft:terracotta)
B(-6,2,-1,minecraft:terracotta)
B(-6,2,2,minecraft:terracotta)
B(-6,2,3,minecraft:terracotta)
B(-6,3,-5,minecraft:terracotta)
B(-6,3,-4,minecraft:terracotta)
B(-6,3,-3,minecraft:terracotta)
B(-6,3,-2,minecraft:terracotta)
B(-5,0,-3,minecraft:terracotta)
B(-5,0,-2,minecraft:terracotta)
B(-5,1,-5,minecraft:terracotta)
B(-5,1,-4,minecraft:terracotta)
B(-5,1,-3,minecraft:terracotta)
B(-5,1,-2,minecraft:terracotta)
B(-5,1,-1,minecraft:terracotta)
B(-5,2,-7,minecraft:terracotta)
B(-5,2,-6,minecraft:terracotta)
B(-5,2,-5,minecraft:terracotta)
B(-5,2,-4,minecraft:terracotta)
B(-5,2,-3,minecraft:terracotta)
B(-5,2,-2,minecraft:terracotta)
B(-5,2,-1,minecraft:terracotta)
B(-5,2,0,minecraft:terracotta)
B(-5,2,1,minecraft:terracotta)
B(-5,2,2,minecraft:terracotta)
B(-5,2,3,minecraft:terracotta)
B(-5,2,4,minecraft:terracotta)
B(-5,3,-4,minecraft:terracotta)
B(-5,3,-3,minecraft:terracotta)
B(-5,3,-2,minecraft:terracotta)
B(-5,3,-1,minecraft:terracotta)
B(-4,0,-5,minecraft:terracotta)
B(-4,0,-4,minecraft:terracotta)
B(-4,0,-3,minecraft:terracotta)
B(-4,0,-2,minecraft:terracotta)
B(-4,1,-5,minecraft:terracotta)
B(-4,1,-4,minecraft:terracotta)
B(-4,1,-3,minecraft:terracotta)
B(-4,1,-2,minecraft:terracotta)
B(-4,1,-1,minecraft:terracotta)
B(-4,1,0,minecraft:terracotta)
B(-4,2,-5,minecraft:terracotta)
B(-4,2,-4,minecraft:terracotta)
B(-4,2,-3,minecraft:terracotta)
B(-4,2,-2,minecraft:terracotta)
B(-4,2,-1,minecraft:terracotta)
B(-4,2,0,minecraft:terracotta)
B(-4,2,1,minecraft:terracotta)
B(-4,2,2,minecraft:terracotta)
B(-4,3,-4,minecraft:terracotta)
B(-4,3,-3,minecraft:terracotta)
B(-4,3,-2,minecraft:terracotta)
B(-4,3,-1,minecraft:terracotta)
B(-4,3,0,minecraft:terracotta)
B(-3,0,-3,minecraft:terracotta)
B(-3,0,-2,minecraft:terracotta)
B(-3,0,-1,minecraft:terracotta)
B(-3,0,0,minecraft:terracotta)
B(-3,1,-5,minecraft:terracotta)
B(-3,1,-4,minecraft:terracotta)
B(-3,1,-3,minecraft:terracotta)
B(-3,1,-2,minecraft:terracotta)
B(-3,1,-1,minecraft:terracotta)
B(-3,1,0,minecraft:terracotta)
B(-3,1,1,minecraft:terracotta)
B(-3,1,2,minecraft:terracotta)
B(-3,2,-7,minecraft:terracotta)
B(-3,2,-6,minecraft:terracotta)
B(-3,2,-5,minecraft:terracotta)
B(-3,2,-4,minecraft:terracotta)
B(-3,2,-3,minecraft:terracotta)
B(-3,2,-2,minecraft:terracotta)
B(-3,2,-1,minecraft:terracotta)
B(-3,2,0,minecraft:terracotta)
B(-3,2,1,minecraft:terracotta)
B(-3,2,2,minecraft:terracotta)
B(-3,2,3,minecraft:terracotta)
B(-3,2,5,minecraft:terracotta)
B(-3,3,-5,minecraft:terracotta)
B(-3,3,-4,minecraft:terracotta)
B(-3,3,-3,minecraft:terracotta)
B(-3,3,-2,minecraft:terracotta)
B(-3,3,-1,minecraft:terracotta)
B(-3,3,0,minecraft:terracotta)
B(-3,3,1,minecraft:terracotta)
B(-2,0,-1,minecraft:terracotta)
B(-2,0,0,minecraft:terracotta)
B(-2,1,-4,minecraft:terracotta)
B(-2,1,-3,minecraft:terracotta)
B(-2,1,-2,minecraft:terracotta)
B(-2,1,-1,minecraft:terracotta)
B(-2,1,0,minecraft:terracotta)
B(-2,1,1,minecraft:terracotta)
B(-2,1,2,minecraft:terracotta)
B(-2,1,3,minecraft:terracotta)
B(-2,1,4,minecraft:terracotta)
B(-2,2,-6,minecraft:terracotta)
B(-2,2,-5,minecraft:terracotta)
B(-2,2,-4,minecraft:terracotta)
B(-2,2,-3,minecraft:terracotta)
B(-2,2,-2,minecraft:terracotta)
B(-2,2,-1,minecraft:terracotta)
B(-2,2,0,minecraft:terracotta)
B(-2,2,1,minecraft:terracotta)
B(-2,2,2,minecraft:terracotta)
B(-2,2,3,minecraft:terracotta)
B(-2,2,4,minecraft:terracotta)
B(-2,2,5,minecraft:terracotta)
B(-2,2,6,minecraft:terracotta)
B(-2,3,-4,minecraft:terracotta)
B(-2,3,-3,minecraft:terracotta)
B(-2,3,-2,minecraft:terracotta)
B(-2,3,-1,minecraft:terracotta)
B(-2,3,0,minecraft:terracotta)
B(-2,3,1,minecraft:terracotta)
B(-1,0,0,minecraft:terracotta)
B(-1,0,1,minecraft:terracotta)
B(-1,0,2,minecraft:terracotta)
B(-1,1,-2,minecraft:terracotta)
B(-1,1,-1,minecraft:terracotta)
B(-1,1,0,minecraft:terracotta)
B(-1,1,1,minecraft:terracotta)
B(-1,1,2,minecraft:terracotta)
B(-1,1,3,minecraft:terracotta)
B(-1,1,4,minecraft:terracotta)
B(-1,1,5,minecraft:terracotta)
B(-1,1,6,minecraft:terracotta)
B(-1,2,-6,minecraft:terracotta)
B(-1,2,-5,minecraft:terracotta)
B(-1,2,-4,minecraft:terracotta)
B(-1,2,-3,minecraft:terracotta)
B(-1,2,-2,minecraft:terracotta)
B(-1,2,-1,minecraft:terracotta)
B(-1,2,0,minecraft:terracotta)
B(-1,2,1,minecraft:terracotta)
B(-1,2,2,minecraft:terracotta)
B(-1,2,3,minecraft:terracotta)
B(-1,2,4,minecraft:terracotta)
B(-1,2,5,minecraft:terracotta)
B(-1,2,6,minecraft:terracotta)
B(-1,3,-1,minecraft:terracotta)
B(-1,3,0,minecraft:terracotta)
B(-1,3,1,minecraft:terracotta)
B(-1,3,4,minecraft:terracotta)
B(-1,3,5,minecraft:terracotta)
B(0,0,1,minecraft:terracotta)
B(0,0,2,minecraft:terracotta)
B(0,0,3,minecraft:terracotta)
B(0,0,4,minecraft:terracotta)
B(0,0,5,minecraft:terracotta)
B(0,0,6,minecraft:terracotta)
B(0,0,7,minecraft:terracotta)
B(0,1,0,minecraft:terracotta)
B(0,1,1,minecraft:terracotta)
B(0,1,2,minecraft:terracotta)
B(0,1,3,minecraft:terracotta)
B(0,1,4,minecraft:terracotta)
B(0,1,5,minecraft:terracotta)
B(0,1,6,minecraft:terracotta)
B(0,1,7,minecraft:terracotta)
B(0,2,-5,minecraft:terracotta)
B(0,2,-3,minecraft:terracotta)
B(0,2,-1,minecraft:terracotta)
B(0,2,0,minecraft:terracotta)
B(0,2,1,minecraft:terracotta)
B(0,2,2,minecraft:terracotta)
B(0,2,3,minecraft:terracotta)
B(0,2,5,minecraft:terracotta)
B(0,2,6,minecraft:terracotta)
B(0,3,0,minecraft:terracotta)
B(0,3,1,minecraft:terracotta)
B(0,3,3,minecraft:terracotta)
B(0,3,4,minecraft:terracotta)
B(0,3,5,minecraft:terracotta)
B(0,3,6,minecraft:terracotta)
B(0,4,5,minecraft:terracotta)
B(1,0,4,minecraft:terracotta)
B(1,0,5,minecraft:terracotta)
B(1,0,6,minecraft:terracotta)
B(1,0,7,minecraft:terracotta)
B(1,1,1,minecraft:terracotta)
B(1,1,3,minecraft:terracotta)
B(1,1,4,minecraft:terracotta)
B(1,1,5,minecraft:terracotta)
B(1,1,6,minecraft:terracotta)
B(1,1,7,minecraft:terracotta)
B(1,2,-5,minecraft:terracotta)
B(1,2,-4,minecraft:terracotta)
B(1,2,0,minecraft:terracotta)
B(1,2,1,minecraft:terracotta)
B(1,2,2,minecraft:terracotta)
B(1,2,3,minecraft:terracotta)
B(1,2,4,minecraft:terracotta)
B(1,2,5,minecraft:terracotta)
B(1,2,6,minecraft:terracotta)
B(1,2,7,minecraft:terracotta)
B(1,3,3,minecraft:terracotta)
B(1,3,4,minecraft:terracotta)
B(1,3,5,minecraft:terracotta)
B(1,3,6,minecraft:terracotta)
B(1,3,7,minecraft:terracotta)
B(1,4,4,minecraft:terracotta)
B(1,4,5,minecraft:terracotta)
B(1,4,6,minecraft:terracotta)
B(2,0,4,minecraft:terracotta)
B(2,0,5,minecraft:terracotta)
B(2,0,6,minecraft:terracotta)
B(2,1,3,minecraft:terracotta)
B(2,1,4,minecraft:terracotta)
B(2,1,5,minecraft:terracotta)
B(2,1,6,minecraft:terracotta)
B(2,1,7,minecraft:terracotta)
B(2,2,-4,minecraft:terracotta)
B(2,2,-2,minecraft:terracotta)
B(2,2,-1,minecraft:terracotta)
B(2,2,0,minecraft:terracotta)
B(2,2,1,minecraft:terracotta)
B(2,2,3,minecraft:terracotta)
B(2,2,4,minecraft:terracotta)
B(2,2,5,minecraft:terracotta)
B(2,2,6,minecraft:terracotta)
B(2,2,7,minecraft:terracotta)
B(2,3,3,minecraft:terracotta)
B(2,3,4,minecraft:terracotta)
B(2,3,5,minecraft:terracotta)
B(2,3,6,minecraft:terracotta)
B(2,4,4,minecraft:terracotta)
B(2,4,5,minecraft:terracotta)
B(3,1,5,minecraft:terracotta)
B(3,2,-1,minecraft:terracotta)
B(3,2,1,minecraft:terracotta)
B(3,2,5,minecraft:terracotta)
B(3,2,6,minecraft:terracotta)
B(3,2,7,minecraft:terracotta)
B(3,3,5,minecraft:terracotta)
B(3,3,6,minecraft:terracotta)

#######################################################################
# +-----------------------------------------------------------------+ #
# |                            BO3 checks                           | #
# +-----------------------------------------------------------------+ #
#######################################################################


#######################################################################
# +-----------------------------------------------------------------+ #
# |                             Branches                            | #
# +-----------------------------------------------------------------+ #
#######################################################################


#######################################################################
# +-----------------------------------------------------------------+ #
# |                             Entities                            | #
# +-----------------------------------------------------------------+ #
#######################################################################

