
#######################################################################
# +-----------------------------------------------------------------+ #
# |                            BO3 object                           | #
# +-----------------------------------------------------------------+ #
#######################################################################

Author: LordSmellyPants

Description: No description given

Version: 3

SettingsMode: WriteWithoutComments


#######################################################################
# +-----------------------------------------------------------------+ #
# |                          Main settings                          | #
# +-----------------------------------------------------------------+ #
#######################################################################

Tree: false

Frequency: 1

Rarity: 4.0

MaxSpawn: 0

RotateRandomly: true

SpawnHeight: randomY

SpawnHeightOffset: 0

SpawnHeightVariance: 0

##############################
# Height Limits for the BO3. #
##############################

MinHeight: 51

MaxHeight: 65

######################
# Extrusion settings #
######################

ExtrudeMode: None

ExtrudeThroughBlocks: minecraft:air

MaxBranchDepth: 10


#######################################################################
# +-----------------------------------------------------------------+ #
# |                      Source block settings                      | #
# +-----------------------------------------------------------------+ #
#######################################################################

SourceBlocks: minecraft:sand,minecraft:grass_block,minecraft:dirt,minecraft:gravel,minecraft:red_sand,minecraft:sandstone,minecraft:stone,minecraft:granite,minecraft:diorite,minecraft:andesite,minecraft:coarse_dirt,minecraft:clay,minecraft:terracotta,minecraft:white_terracotta,minecraft:poppy,minecraft:blue_orchid,minecraft:allium,minecraft:azure_bluet,minecraft:red_tulip,minecraft:orange_tulip,minecraft:white_tulip,minecraft:pink_tulip,minecraft:oxeye_daisy,minecraft:brown_mushroom,minecraft:red_mushroom,minecraft:sunflower,minecraft:lilac,minecraft:tall_grass,minecraft:large_fern,minecraft:rose_bush,minecraft:peony,minecraft:grass,minecraft:fern,minecraft:dead_bush,minecraft:coal_ore,minecraft:iron_ore,minecraft:gold_ore,minecraft:redstone_ore,minecraft:diamond_ore,minecraft:lapis_ore,minecraft:emerald_ore,minecraft:vine,minecraft:air,minecraft:water

MaxPercentageOutsideSourceBlock: 20

OutsideSourceBlock: placeAnyway

DoReplaceBlocks: true

IsOTGPlus: false


#######################################################################
# +-----------------------------------------------------------------+ #
# |                              Blocks                             | #
# +-----------------------------------------------------------------+ #
#######################################################################

B(-5,-2,0,minecraft:orange_terracotta)
B(-5,-1,0,minecraft:orange_terracotta)
B(-5,-1,1,minecraft:orange_terracotta)
B(-5,-1,2,minecraft:orange_terracotta)
B(-5,0,0,minecraft:orange_terracotta)
B(-5,0,1,minecraft:orange_terracotta)
B(-5,0,2,minecraft:orange_terracotta)
B(-5,0,3,minecraft:orange_terracotta)
B(-5,1,0,minecraft:orange_terracotta)
B(-5,1,1,minecraft:orange_terracotta)
B(-5,1,2,minecraft:orange_terracotta)
B(-5,1,3,minecraft:orange_terracotta)
B(-5,2,1,minecraft:orange_terracotta)
B(-5,2,2,minecraft:orange_terracotta)
B(-4,-3,-1,minecraft:orange_terracotta)
B(-4,-2,-2,minecraft:orange_terracotta)
B(-4,-2,-1,minecraft:orange_terracotta)
B(-4,-2,0,minecraft:orange_terracotta)
B(-4,-2,1,minecraft:orange_terracotta)
B(-4,-2,2,minecraft:orange_terracotta)
B(-4,-1,-2,minecraft:orange_terracotta)
B(-4,-1,-1,minecraft:orange_terracotta)
B(-4,-1,0,minecraft:orange_terracotta)
B(-4,-1,1,minecraft:orange_terracotta)
B(-4,-1,2,minecraft:orange_terracotta)
B(-4,-1,3,minecraft:orange_terracotta)
B(-4,-1,4,minecraft:orange_terracotta)
B(-4,0,-2,minecraft:orange_terracotta)
B(-4,0,-1,minecraft:orange_terracotta)
B(-4,0,0,minecraft:orange_terracotta)
B(-4,0,1,minecraft:orange_terracotta)
B(-4,0,2,minecraft:orange_terracotta)
B(-4,0,3,minecraft:orange_terracotta)
B(-4,0,4,minecraft:orange_terracotta)
B(-4,1,-2,minecraft:orange_terracotta)
B(-4,1,-1,minecraft:orange_terracotta)
B(-4,1,0,minecraft:orange_terracotta)
B(-4,1,1,minecraft:orange_terracotta)
B(-4,1,2,minecraft:orange_terracotta)
B(-4,1,3,minecraft:orange_terracotta)
B(-4,2,-1,minecraft:orange_terracotta)
B(-4,2,0,minecraft:orange_terracotta)
B(-4,2,1,minecraft:orange_terracotta)
B(-4,2,2,minecraft:orange_terracotta)
B(-4,2,3,minecraft:orange_terracotta)
B(-4,3,0,minecraft:terracotta)
B(-4,3,1,minecraft:yellow_terracotta)
B(-4,3,2,minecraft:yellow_terracotta)
B(-4,4,1,minecraft:terracotta)
B(-4,4,2,minecraft:yellow_terracotta)
B(-4,5,2,minecraft:terracotta)
B(-3,-4,-1,minecraft:orange_terracotta)
B(-3,-4,0,minecraft:orange_terracotta)
B(-3,-3,-2,minecraft:orange_terracotta)
B(-3,-3,-1,minecraft:orange_terracotta)
B(-3,-3,0,minecraft:orange_terracotta)
B(-3,-3,1,minecraft:orange_terracotta)
B(-3,-3,2,minecraft:orange_terracotta)
B(-3,-2,-2,minecraft:orange_terracotta)
B(-3,-2,-1,minecraft:orange_terracotta)
B(-3,-2,0,minecraft:orange_terracotta)
B(-3,-2,1,minecraft:orange_terracotta)
B(-3,-2,2,minecraft:orange_terracotta)
B(-3,-2,3,minecraft:orange_terracotta)
B(-3,-2,4,minecraft:orange_terracotta)
B(-3,-1,-2,minecraft:orange_terracotta)
B(-3,-1,-1,minecraft:orange_terracotta)
B(-3,-1,0,minecraft:orange_terracotta)
B(-3,-1,1,minecraft:orange_terracotta)
B(-3,-1,2,minecraft:orange_terracotta)
B(-3,-1,3,minecraft:orange_terracotta)
B(-3,-1,4,minecraft:orange_terracotta)
B(-3,-1,5,minecraft:orange_terracotta)
B(-3,0,-3,minecraft:orange_terracotta)
B(-3,0,-2,minecraft:orange_terracotta)
B(-3,0,-1,minecraft:orange_terracotta)
B(-3,0,0,minecraft:orange_terracotta)
B(-3,0,1,minecraft:orange_terracotta)
B(-3,0,2,minecraft:orange_terracotta)
B(-3,0,3,minecraft:orange_terracotta)
B(-3,0,4,minecraft:orange_terracotta)
B(-3,0,5,minecraft:orange_terracotta)
B(-3,1,-3,minecraft:orange_terracotta)
B(-3,1,-2,minecraft:orange_terracotta)
B(-3,1,-1,minecraft:orange_terracotta)
B(-3,1,0,minecraft:orange_terracotta)
B(-3,1,1,minecraft:orange_terracotta)
B(-3,1,2,minecraft:orange_terracotta)
B(-3,1,3,minecraft:orange_terracotta)
B(-3,1,4,minecraft:orange_terracotta)
B(-3,2,-2,minecraft:orange_terracotta)
B(-3,2,-1,minecraft:orange_terracotta)
B(-3,2,0,minecraft:orange_terracotta)
B(-3,2,1,minecraft:orange_terracotta)
B(-3,2,2,minecraft:orange_terracotta)
B(-3,2,3,minecraft:orange_terracotta)
B(-3,2,4,minecraft:orange_terracotta)
B(-3,3,-2,minecraft:yellow_terracotta)
B(-3,3,-1,minecraft:yellow_terracotta)
B(-3,3,0,minecraft:terracotta)
B(-3,3,1,minecraft:yellow_terracotta)
B(-3,3,2,minecraft:yellow_terracotta)
B(-3,3,3,minecraft:yellow_terracotta)
B(-3,3,4,minecraft:yellow_terracotta)
B(-3,4,-1,minecraft:yellow_terracotta)
B(-3,4,0,minecraft:yellow_terracotta)
B(-3,4,1,minecraft:terracotta)
B(-3,4,2,minecraft:terracotta)
B(-3,4,3,minecraft:terracotta)
B(-3,5,0,minecraft:terracotta)
B(-3,5,1,minecraft:terracotta)
B(-3,5,2,minecraft:terracotta)
B(-3,5,3,minecraft:terracotta)
B(-2,-4,0,minecraft:orange_terracotta)
B(-2,-4,1,minecraft:orange_terracotta)
B(-2,-4,2,minecraft:orange_terracotta)
B(-2,-3,-1,minecraft:orange_terracotta)
B(-2,-3,0,minecraft:orange_terracotta)
B(-2,-3,1,minecraft:orange_terracotta)
B(-2,-3,2,minecraft:orange_terracotta)
B(-2,-3,3,minecraft:orange_terracotta)
B(-2,-3,4,minecraft:orange_terracotta)
B(-2,-2,-2,minecraft:orange_terracotta)
B(-2,-2,-1,minecraft:orange_terracotta)
B(-2,-2,0,minecraft:orange_terracotta)
B(-2,-2,1,minecraft:orange_terracotta)
B(-2,-2,2,minecraft:orange_terracotta)
B(-2,-2,3,minecraft:orange_terracotta)
B(-2,-2,4,minecraft:orange_terracotta)
B(-2,-1,-3,minecraft:orange_terracotta)
B(-2,-1,-2,minecraft:orange_terracotta)
B(-2,-1,-1,minecraft:orange_terracotta)
B(-2,-1,0,minecraft:orange_terracotta)
B(-2,-1,1,minecraft:orange_terracotta)
B(-2,-1,2,minecraft:orange_terracotta)
B(-2,-1,3,minecraft:orange_terracotta)
B(-2,-1,4,minecraft:orange_terracotta)
B(-2,-1,5,minecraft:orange_terracotta)
B(-2,0,-3,minecraft:orange_terracotta)
B(-2,0,-2,minecraft:orange_terracotta)
B(-2,0,-1,minecraft:orange_terracotta)
B(-2,0,0,minecraft:orange_terracotta)
B(-2,0,1,minecraft:orange_terracotta)
B(-2,0,2,minecraft:orange_terracotta)
B(-2,0,3,minecraft:orange_terracotta)
B(-2,0,4,minecraft:orange_terracotta)
B(-2,0,5,minecraft:orange_terracotta)
B(-2,1,-3,minecraft:orange_terracotta)
B(-2,1,-2,minecraft:orange_terracotta)
B(-2,1,-1,minecraft:orange_terracotta)
B(-2,1,0,minecraft:orange_terracotta)
B(-2,1,1,minecraft:orange_terracotta)
B(-2,1,2,minecraft:orange_terracotta)
B(-2,1,3,minecraft:orange_terracotta)
B(-2,1,4,minecraft:orange_terracotta)
B(-2,2,-2,minecraft:orange_terracotta)
B(-2,2,-1,minecraft:orange_terracotta)
B(-2,2,0,minecraft:orange_terracotta)
B(-2,2,1,minecraft:orange_terracotta)
B(-2,2,2,minecraft:orange_terracotta)
B(-2,2,3,minecraft:orange_terracotta)
B(-2,2,4,minecraft:orange_terracotta)
B(-2,3,-2,minecraft:terracotta)
B(-2,3,-1,minecraft:terracotta)
B(-2,3,0,minecraft:terracotta)
B(-2,3,1,minecraft:yellow_terracotta)
B(-2,3,2,minecraft:yellow_terracotta)
B(-2,3,3,minecraft:terracotta)
B(-2,3,4,minecraft:yellow_terracotta)
B(-2,4,-2,minecraft:terracotta)
B(-2,4,-1,minecraft:terracotta)
B(-2,4,0,minecraft:terracotta)
B(-2,4,1,minecraft:terracotta)
B(-2,4,2,minecraft:terracotta)
B(-2,4,3,minecraft:terracotta)
B(-2,4,4,minecraft:yellow_terracotta)
B(-2,5,-1,minecraft:terracotta)
B(-2,5,0,minecraft:terracotta)
B(-2,5,1,minecraft:terracotta)
B(-2,5,2,minecraft:terracotta)
B(-2,5,3,minecraft:terracotta)
B(-2,5,4,minecraft:terracotta)
B(-2,6,1,minecraft:terracotta)
B(-2,6,2,minecraft:terracotta)
B(-2,6,3,minecraft:terracotta)
B(-2,7,1,minecraft:terracotta)
B(-2,7,2,minecraft:terracotta)
B(-2,8,1,minecraft:orange_terracotta)
B(-2,9,1,minecraft:terracotta)
B(-2,10,1,minecraft:terracotta)
B(-2,11,1,minecraft:orange_terracotta)
B(-2,12,1,minecraft:terracotta)
B(-1,-4,0,minecraft:orange_terracotta)
B(-1,-4,1,minecraft:orange_terracotta)
B(-1,-4,2,minecraft:orange_terracotta)
B(-1,-4,3,minecraft:orange_terracotta)
B(-1,-3,-1,minecraft:orange_terracotta)
B(-1,-3,0,minecraft:orange_terracotta)
B(-1,-3,1,minecraft:orange_terracotta)
B(-1,-3,2,minecraft:orange_terracotta)
B(-1,-3,3,minecraft:orange_terracotta)
B(-1,-3,4,minecraft:orange_terracotta)
B(-1,-2,-2,minecraft:orange_terracotta)
B(-1,-2,-1,minecraft:orange_terracotta)
B(-1,-2,0,minecraft:orange_terracotta)
B(-1,-2,1,minecraft:orange_terracotta)
B(-1,-2,2,minecraft:orange_terracotta)
B(-1,-2,3,minecraft:orange_terracotta)
B(-1,-2,4,minecraft:orange_terracotta)
B(-1,-2,5,minecraft:orange_terracotta)
B(-1,-1,-3,minecraft:orange_terracotta)
B(-1,-1,-2,minecraft:orange_terracotta)
B(-1,-1,-1,minecraft:orange_terracotta)
B(-1,-1,0,minecraft:orange_terracotta)
B(-1,-1,1,minecraft:orange_terracotta)
B(-1,-1,2,minecraft:orange_terracotta)
B(-1,-1,3,minecraft:orange_terracotta)
B(-1,-1,4,minecraft:orange_terracotta)
B(-1,-1,5,minecraft:orange_terracotta)
B(-1,0,-3,minecraft:orange_terracotta)
B(-1,0,-2,minecraft:orange_terracotta)
B(-1,0,-1,minecraft:orange_terracotta)
B(-1,0,0,minecraft:orange_terracotta)
B(-1,0,1,minecraft:orange_terracotta)
B(-1,0,2,minecraft:orange_terracotta)
B(-1,0,3,minecraft:orange_terracotta)
B(-1,0,4,minecraft:orange_terracotta)
B(-1,0,5,minecraft:orange_terracotta)
B(-1,0,6,minecraft:orange_terracotta)
B(-1,1,-3,minecraft:orange_terracotta)
B(-1,1,-2,minecraft:orange_terracotta)
B(-1,1,-1,minecraft:orange_terracotta)
B(-1,1,0,minecraft:orange_terracotta)
B(-1,1,1,minecraft:orange_terracotta)
B(-1,1,2,minecraft:orange_terracotta)
B(-1,1,3,minecraft:orange_terracotta)
B(-1,1,4,minecraft:orange_terracotta)
B(-1,1,5,minecraft:orange_terracotta)
B(-1,2,-2,minecraft:orange_terracotta)
B(-1,2,-1,minecraft:orange_terracotta)
B(-1,2,0,minecraft:orange_terracotta)
B(-1,2,1,minecraft:orange_terracotta)
B(-1,2,2,minecraft:orange_terracotta)
B(-1,2,3,minecraft:orange_terracotta)
B(-1,2,4,minecraft:orange_terracotta)
B(-1,2,5,minecraft:orange_terracotta)
B(-1,3,-2,minecraft:yellow_terracotta)
B(-1,3,-1,minecraft:terracotta)
B(-1,3,0,minecraft:terracotta)
B(-1,3,1,minecraft:terracotta)
B(-1,3,2,minecraft:terracotta)
B(-1,3,3,minecraft:terracotta)
B(-1,3,4,minecraft:yellow_terracotta)
B(-1,4,-2,minecraft:yellow_terracotta)
B(-1,4,-1,minecraft:terracotta)
B(-1,4,0,minecraft:terracotta)
B(-1,4,1,minecraft:terracotta)
B(-1,4,2,minecraft:terracotta)
B(-1,4,3,minecraft:terracotta)
B(-1,4,4,minecraft:yellow_terracotta)
B(-1,5,-2,minecraft:terracotta)
B(-1,5,-1,minecraft:terracotta)
B(-1,5,0,minecraft:terracotta)
B(-1,5,1,minecraft:terracotta)
B(-1,5,2,minecraft:terracotta)
B(-1,5,3,minecraft:terracotta)
B(-1,5,4,minecraft:terracotta)
B(-1,6,0,minecraft:terracotta)
B(-1,6,1,minecraft:terracotta)
B(-1,6,2,minecraft:terracotta)
B(-1,6,3,minecraft:terracotta)
B(-1,7,0,minecraft:terracotta)
B(-1,7,1,minecraft:terracotta)
B(-1,7,2,minecraft:terracotta)
B(-1,8,0,minecraft:terracotta)
B(-1,8,1,minecraft:orange_terracotta)
B(-1,8,2,minecraft:orange_terracotta)
B(-1,9,0,minecraft:terracotta)
B(-1,9,1,minecraft:terracotta)
B(-1,9,2,minecraft:terracotta)
B(-1,10,0,minecraft:terracotta)
B(-1,10,1,minecraft:terracotta)
B(-1,10,2,minecraft:terracotta)
B(-1,11,0,minecraft:terracotta)
B(-1,11,1,minecraft:terracotta)
B(-1,11,2,minecraft:orange_terracotta)
B(-1,12,0,minecraft:terracotta)
B(-1,12,1,minecraft:terracotta)
B(-1,12,2,minecraft:terracotta)
B(0,-4,0,minecraft:orange_terracotta)
B(0,-4,1,minecraft:orange_terracotta)
B(0,-4,2,minecraft:orange_terracotta)
B(0,-4,3,minecraft:orange_terracotta)
B(0,-4,4,minecraft:orange_terracotta)
B(0,-3,-1,minecraft:orange_terracotta)
B(0,-3,0,minecraft:orange_terracotta)
B(0,-3,1,minecraft:orange_terracotta)
B(0,-3,2,minecraft:orange_terracotta)
B(0,-3,3,minecraft:orange_terracotta)
B(0,-3,4,minecraft:orange_terracotta)
B(0,-3,5,minecraft:orange_terracotta)
B(0,-2,-2,minecraft:orange_terracotta)
B(0,-2,-1,minecraft:orange_terracotta)
B(0,-2,0,minecraft:orange_terracotta)
B(0,-2,1,minecraft:orange_terracotta)
B(0,-2,2,minecraft:orange_terracotta)
B(0,-2,3,minecraft:orange_terracotta)
B(0,-2,4,minecraft:orange_terracotta)
B(0,-2,5,minecraft:orange_terracotta)
B(0,-2,6,minecraft:orange_terracotta)
B(0,-1,-3,minecraft:orange_terracotta)
B(0,-1,-2,minecraft:orange_terracotta)
B(0,-1,-1,minecraft:orange_terracotta)
B(0,-1,0,minecraft:orange_terracotta)
B(0,-1,1,minecraft:orange_terracotta)
B(0,-1,2,minecraft:orange_terracotta)
B(0,-1,3,minecraft:orange_terracotta)
B(0,-1,4,minecraft:orange_terracotta)
B(0,-1,5,minecraft:orange_terracotta)
B(0,-1,6,minecraft:orange_terracotta)
B(0,0,-3,minecraft:orange_terracotta)
B(0,0,-2,minecraft:orange_terracotta)
B(0,0,-1,minecraft:orange_terracotta)
B(0,0,0,minecraft:orange_terracotta)
B(0,0,1,minecraft:orange_terracotta)
B(0,0,2,minecraft:orange_terracotta)
B(0,0,3,minecraft:orange_terracotta)
B(0,0,4,minecraft:orange_terracotta)
B(0,0,5,minecraft:orange_terracotta)
B(0,0,6,minecraft:orange_terracotta)
B(0,1,-3,minecraft:orange_terracotta)
B(0,1,-2,minecraft:orange_terracotta)
B(0,1,-1,minecraft:orange_terracotta)
B(0,1,0,minecraft:orange_terracotta)
B(0,1,1,minecraft:orange_terracotta)
B(0,1,2,minecraft:orange_terracotta)
B(0,1,3,minecraft:orange_terracotta)
B(0,1,4,minecraft:orange_terracotta)
B(0,1,5,minecraft:orange_terracotta)
B(0,1,6,minecraft:orange_terracotta)
B(0,2,-3,minecraft:orange_terracotta)
B(0,2,-2,minecraft:orange_terracotta)
B(0,2,-1,minecraft:orange_terracotta)
B(0,2,0,minecraft:orange_terracotta)
B(0,2,1,minecraft:orange_terracotta)
B(0,2,2,minecraft:orange_terracotta)
B(0,2,3,minecraft:orange_terracotta)
B(0,2,4,minecraft:orange_terracotta)
B(0,2,5,minecraft:orange_terracotta)
B(0,3,-2,minecraft:yellow_terracotta)
B(0,3,-1,minecraft:terracotta)
B(0,3,0,minecraft:terracotta)
B(0,3,1,minecraft:terracotta)
B(0,3,2,minecraft:terracotta)
B(0,3,3,minecraft:terracotta)
B(0,3,4,minecraft:yellow_terracotta)
B(0,4,-2,minecraft:yellow_terracotta)
B(0,4,-1,minecraft:terracotta)
B(0,4,0,minecraft:terracotta)
B(0,4,1,minecraft:terracotta)
B(0,4,2,minecraft:terracotta)
B(0,4,3,minecraft:terracotta)
B(0,4,4,minecraft:terracotta)
B(0,5,-2,minecraft:terracotta)
B(0,5,-1,minecraft:terracotta)
B(0,5,0,minecraft:terracotta)
B(0,5,1,minecraft:terracotta)
B(0,5,2,minecraft:terracotta)
B(0,5,3,minecraft:terracotta)
B(0,5,4,minecraft:terracotta)
B(0,6,-2,minecraft:terracotta)
B(0,6,-1,minecraft:terracotta)
B(0,6,0,minecraft:terracotta)
B(0,6,1,minecraft:terracotta)
B(0,6,2,minecraft:terracotta)
B(0,6,3,minecraft:terracotta)
B(0,6,4,minecraft:terracotta)
B(0,7,-1,minecraft:terracotta)
B(0,7,0,minecraft:terracotta)
B(0,7,1,minecraft:terracotta)
B(0,7,2,minecraft:terracotta)
B(0,7,3,minecraft:terracotta)
B(0,8,-1,minecraft:orange_terracotta)
B(0,8,0,minecraft:terracotta)
B(0,8,1,minecraft:orange_terracotta)
B(0,8,2,minecraft:orange_terracotta)
B(0,8,3,minecraft:orange_terracotta)
B(0,9,-1,minecraft:terracotta)
B(0,9,0,minecraft:terracotta)
B(0,9,1,minecraft:terracotta)
B(0,9,2,minecraft:terracotta)
B(0,10,-1,minecraft:terracotta)
B(0,10,0,minecraft:terracotta)
B(0,10,1,minecraft:terracotta)
B(0,10,2,minecraft:terracotta)
B(0,11,-1,minecraft:orange_terracotta)
B(0,11,0,minecraft:terracotta)
B(0,11,1,minecraft:terracotta)
B(0,11,2,minecraft:orange_terracotta)
B(0,12,-1,minecraft:terracotta)
B(0,12,0,minecraft:terracotta)
B(0,12,1,minecraft:terracotta)
B(0,12,2,minecraft:terracotta)
B(1,-4,-1,minecraft:orange_terracotta)
B(1,-4,0,minecraft:orange_terracotta)
B(1,-4,1,minecraft:orange_terracotta)
B(1,-4,2,minecraft:orange_terracotta)
B(1,-4,3,minecraft:orange_terracotta)
B(1,-3,-2,minecraft:orange_terracotta)
B(1,-3,-1,minecraft:orange_terracotta)
B(1,-3,0,minecraft:orange_terracotta)
B(1,-3,1,minecraft:orange_terracotta)
B(1,-3,2,minecraft:orange_terracotta)
B(1,-3,3,minecraft:orange_terracotta)
B(1,-3,4,minecraft:orange_terracotta)
B(1,-2,-2,minecraft:orange_terracotta)
B(1,-2,-1,minecraft:orange_terracotta)
B(1,-2,0,minecraft:orange_terracotta)
B(1,-2,1,minecraft:orange_terracotta)
B(1,-2,2,minecraft:orange_terracotta)
B(1,-2,3,minecraft:orange_terracotta)
B(1,-2,4,minecraft:orange_terracotta)
B(1,-2,5,minecraft:orange_terracotta)
B(1,-1,-3,minecraft:orange_terracotta)
B(1,-1,-2,minecraft:orange_terracotta)
B(1,-1,-1,minecraft:orange_terracotta)
B(1,-1,0,minecraft:orange_terracotta)
B(1,-1,1,minecraft:orange_terracotta)
B(1,-1,2,minecraft:orange_terracotta)
B(1,-1,3,minecraft:orange_terracotta)
B(1,-1,4,minecraft:orange_terracotta)
B(1,-1,5,minecraft:orange_terracotta)
B(1,-1,6,minecraft:orange_terracotta)
B(1,0,-3,minecraft:orange_terracotta)
B(1,0,-2,minecraft:orange_terracotta)
B(1,0,-1,minecraft:orange_terracotta)
B(1,0,0,minecraft:orange_terracotta)
B(1,0,1,minecraft:orange_terracotta)
B(1,0,2,minecraft:orange_terracotta)
B(1,0,3,minecraft:orange_terracotta)
B(1,0,4,minecraft:orange_terracotta)
B(1,0,5,minecraft:orange_terracotta)
B(1,0,6,minecraft:orange_terracotta)
B(1,1,-3,minecraft:orange_terracotta)
B(1,1,-2,minecraft:orange_terracotta)
B(1,1,-1,minecraft:orange_terracotta)
B(1,1,0,minecraft:orange_terracotta)
B(1,1,1,minecraft:orange_terracotta)
B(1,1,2,minecraft:orange_terracotta)
B(1,1,3,minecraft:orange_terracotta)
B(1,1,4,minecraft:orange_terracotta)
B(1,1,5,minecraft:yellow_terracotta)
B(1,1,6,minecraft:orange_terracotta)
B(1,2,-3,minecraft:orange_terracotta)
B(1,2,-2,minecraft:orange_terracotta)
B(1,2,-1,minecraft:orange_terracotta)
B(1,2,0,minecraft:orange_terracotta)
B(1,2,1,minecraft:orange_terracotta)
B(1,2,2,minecraft:orange_terracotta)
B(1,2,3,minecraft:orange_terracotta)
B(1,2,4,minecraft:orange_terracotta)
B(1,2,5,minecraft:orange_terracotta)
B(1,3,-3,minecraft:yellow_terracotta)
B(1,3,-2,minecraft:terracotta)
B(1,3,-1,minecraft:terracotta)
B(1,3,0,minecraft:terracotta)
B(1,3,1,minecraft:terracotta)
B(1,3,2,minecraft:terracotta)
B(1,3,3,minecraft:terracotta)
B(1,3,4,minecraft:yellow_terracotta)
B(1,3,5,minecraft:yellow_terracotta)
B(1,4,-3,minecraft:yellow_terracotta)
B(1,4,-2,minecraft:terracotta)
B(1,4,-1,minecraft:terracotta)
B(1,4,0,minecraft:terracotta)
B(1,4,1,minecraft:terracotta)
B(1,4,2,minecraft:terracotta)
B(1,4,3,minecraft:terracotta)
B(1,4,4,minecraft:yellow_terracotta)
B(1,5,-3,minecraft:terracotta)
B(1,5,-2,minecraft:terracotta)
B(1,5,-1,minecraft:terracotta)
B(1,5,0,minecraft:terracotta)
B(1,5,1,minecraft:terracotta)
B(1,5,2,minecraft:terracotta)
B(1,5,3,minecraft:terracotta)
B(1,5,4,minecraft:terracotta)
B(1,6,-2,minecraft:terracotta)
B(1,6,-1,minecraft:terracotta)
B(1,6,0,minecraft:terracotta)
B(1,6,1,minecraft:terracotta)
B(1,6,2,minecraft:terracotta)
B(1,6,3,minecraft:terracotta)
B(1,7,-2,minecraft:terracotta)
B(1,7,-1,minecraft:terracotta)
B(1,7,0,minecraft:terracotta)
B(1,7,1,minecraft:terracotta)
B(1,7,2,minecraft:terracotta)
B(1,8,-2,minecraft:terracotta)
B(1,8,-1,minecraft:terracotta)
B(1,8,0,minecraft:terracotta)
B(1,8,1,minecraft:orange_terracotta)
B(1,8,2,minecraft:orange_terracotta)
B(1,9,-2,minecraft:terracotta)
B(1,9,-1,minecraft:terracotta)
B(1,9,0,minecraft:terracotta)
B(1,9,1,minecraft:terracotta)
B(1,9,2,minecraft:terracotta)
B(1,10,-2,minecraft:terracotta)
B(1,10,-1,minecraft:terracotta)
B(1,10,0,minecraft:terracotta)
B(1,10,1,minecraft:terracotta)
B(1,10,2,minecraft:terracotta)
B(1,11,-1,minecraft:orange_terracotta)
B(1,11,0,minecraft:terracotta)
B(1,11,1,minecraft:orange_terracotta)
B(1,11,2,minecraft:orange_terracotta)
B(1,12,-1,minecraft:terracotta)
B(1,12,0,minecraft:terracotta)
B(1,12,1,minecraft:terracotta)
B(1,12,2,minecraft:terracotta)
B(2,-4,0,minecraft:orange_terracotta)
B(2,-4,1,minecraft:orange_terracotta)
B(2,-4,2,minecraft:orange_terracotta)
B(2,-4,3,minecraft:orange_terracotta)
B(2,-3,-2,minecraft:orange_terracotta)
B(2,-3,-1,minecraft:orange_terracotta)
B(2,-3,0,minecraft:orange_terracotta)
B(2,-3,1,minecraft:orange_terracotta)
B(2,-3,2,minecraft:orange_terracotta)
B(2,-3,3,minecraft:orange_terracotta)
B(2,-3,4,minecraft:orange_terracotta)
B(2,-2,-3,minecraft:orange_terracotta)
B(2,-2,-2,minecraft:orange_terracotta)
B(2,-2,-1,minecraft:orange_terracotta)
B(2,-2,0,minecraft:orange_terracotta)
B(2,-2,1,minecraft:orange_terracotta)
B(2,-2,2,minecraft:orange_terracotta)
B(2,-2,3,minecraft:orange_terracotta)
B(2,-2,4,minecraft:orange_terracotta)
B(2,-2,5,minecraft:orange_terracotta)
B(2,-1,-3,minecraft:orange_terracotta)
B(2,-1,-2,minecraft:orange_terracotta)
B(2,-1,-1,minecraft:orange_terracotta)
B(2,-1,0,minecraft:orange_terracotta)
B(2,-1,1,minecraft:orange_terracotta)
B(2,-1,2,minecraft:orange_terracotta)
B(2,-1,3,minecraft:orange_terracotta)
B(2,-1,4,minecraft:orange_terracotta)
B(2,-1,5,minecraft:orange_terracotta)
B(2,-1,6,minecraft:orange_terracotta)
B(2,0,-3,minecraft:orange_terracotta)
B(2,0,-2,minecraft:orange_terracotta)
B(2,0,-1,minecraft:orange_terracotta)
B(2,0,0,minecraft:orange_terracotta)
B(2,0,1,minecraft:orange_terracotta)
B(2,0,2,minecraft:orange_terracotta)
B(2,0,3,minecraft:orange_terracotta)
B(2,0,4,minecraft:orange_terracotta)
B(2,0,5,minecraft:orange_terracotta)
B(2,0,6,minecraft:orange_terracotta)
B(2,1,-3,minecraft:orange_terracotta)
B(2,1,-2,minecraft:orange_terracotta)
B(2,1,-1,minecraft:orange_terracotta)
B(2,1,0,minecraft:orange_terracotta)
B(2,1,1,minecraft:orange_terracotta)
B(2,1,2,minecraft:orange_terracotta)
B(2,1,3,minecraft:orange_terracotta)
B(2,1,4,minecraft:orange_terracotta)
B(2,1,5,minecraft:orange_terracotta)
B(2,1,6,minecraft:orange_terracotta)
B(2,2,-3,minecraft:orange_terracotta)
B(2,2,-2,minecraft:orange_terracotta)
B(2,2,-1,minecraft:orange_terracotta)
B(2,2,0,minecraft:orange_terracotta)
B(2,2,1,minecraft:orange_terracotta)
B(2,2,2,minecraft:orange_terracotta)
B(2,2,3,minecraft:orange_terracotta)
B(2,2,4,minecraft:orange_terracotta)
B(2,2,5,minecraft:orange_terracotta)
B(2,3,-3,minecraft:yellow_terracotta)
B(2,3,-2,minecraft:terracotta)
B(2,3,-1,minecraft:terracotta)
B(2,3,0,minecraft:terracotta)
B(2,3,1,minecraft:yellow_terracotta)
B(2,3,2,minecraft:yellow_terracotta)
B(2,3,3,minecraft:terracotta)
B(2,3,4,minecraft:terracotta)
B(2,4,-2,minecraft:yellow_terracotta)
B(2,4,-1,minecraft:terracotta)
B(2,4,0,minecraft:terracotta)
B(2,4,1,minecraft:terracotta)
B(2,4,2,minecraft:terracotta)
B(2,4,3,minecraft:terracotta)
B(2,4,4,minecraft:terracotta)
B(2,5,-2,minecraft:terracotta)
B(2,5,-1,minecraft:terracotta)
B(2,5,0,minecraft:terracotta)
B(2,5,1,minecraft:terracotta)
B(2,5,2,minecraft:terracotta)
B(2,5,3,minecraft:terracotta)
B(2,6,-1,minecraft:terracotta)
B(2,6,0,minecraft:terracotta)
B(2,6,1,minecraft:terracotta)
B(2,6,2,minecraft:terracotta)
B(2,6,3,minecraft:terracotta)
B(2,7,-1,minecraft:terracotta)
B(2,7,0,minecraft:terracotta)
B(2,7,1,minecraft:terracotta)
B(2,8,-1,minecraft:orange_terracotta)
B(2,8,0,minecraft:terracotta)
B(2,8,1,minecraft:orange_terracotta)
B(2,9,-1,minecraft:terracotta)
B(2,9,0,minecraft:terracotta)
B(2,9,1,minecraft:terracotta)
B(2,10,-1,minecraft:terracotta)
B(2,10,0,minecraft:terracotta)
B(2,11,-1,minecraft:orange_terracotta)
B(2,11,0,minecraft:orange_terracotta)
B(2,12,-1,minecraft:terracotta)
B(2,12,0,minecraft:terracotta)
B(3,-3,0,minecraft:orange_terracotta)
B(3,-3,1,minecraft:orange_terracotta)
B(3,-3,2,minecraft:orange_terracotta)
B(3,-3,3,minecraft:orange_terracotta)
B(3,-2,-2,minecraft:orange_terracotta)
B(3,-2,-1,minecraft:orange_terracotta)
B(3,-2,0,minecraft:orange_terracotta)
B(3,-2,1,minecraft:orange_terracotta)
B(3,-2,2,minecraft:orange_terracotta)
B(3,-2,3,minecraft:orange_terracotta)
B(3,-2,4,minecraft:orange_terracotta)
B(3,-1,-2,minecraft:orange_terracotta)
B(3,-1,-1,minecraft:orange_terracotta)
B(3,-1,0,minecraft:orange_terracotta)
B(3,-1,1,minecraft:orange_terracotta)
B(3,-1,2,minecraft:orange_terracotta)
B(3,-1,3,minecraft:orange_terracotta)
B(3,-1,4,minecraft:orange_terracotta)
B(3,-1,5,minecraft:orange_terracotta)
B(3,0,-3,minecraft:orange_terracotta)
B(3,0,-2,minecraft:orange_terracotta)
B(3,0,-1,minecraft:orange_terracotta)
B(3,0,0,minecraft:orange_terracotta)
B(3,0,1,minecraft:orange_terracotta)
B(3,0,2,minecraft:orange_terracotta)
B(3,0,3,minecraft:orange_terracotta)
B(3,0,4,minecraft:orange_terracotta)
B(3,0,5,minecraft:orange_terracotta)
B(3,1,-3,minecraft:orange_terracotta)
B(3,1,-2,minecraft:orange_terracotta)
B(3,1,-1,minecraft:orange_terracotta)
B(3,1,0,minecraft:orange_terracotta)
B(3,1,1,minecraft:orange_terracotta)
B(3,1,2,minecraft:orange_terracotta)
B(3,1,3,minecraft:orange_terracotta)
B(3,1,4,minecraft:yellow_terracotta)
B(3,1,5,minecraft:orange_terracotta)
B(3,2,-3,minecraft:orange_terracotta)
B(3,2,-2,minecraft:orange_terracotta)
B(3,2,-1,minecraft:orange_terracotta)
B(3,2,0,minecraft:orange_terracotta)
B(3,2,1,minecraft:orange_terracotta)
B(3,2,2,minecraft:orange_terracotta)
B(3,2,3,minecraft:orange_terracotta)
B(3,2,4,minecraft:orange_terracotta)
B(3,3,-2,minecraft:yellow_terracotta)
B(3,3,-1,minecraft:yellow_terracotta)
B(3,3,0,minecraft:terracotta)
B(3,3,1,minecraft:yellow_terracotta)
B(3,3,2,minecraft:yellow_terracotta)
B(3,3,3,minecraft:yellow_terracotta)
B(3,3,4,minecraft:yellow_terracotta)
B(3,4,-1,minecraft:yellow_terracotta)
B(3,4,0,minecraft:terracotta)
B(3,4,1,minecraft:terracotta)
B(3,4,2,minecraft:terracotta)
B(3,4,3,minecraft:yellow_terracotta)
B(3,5,0,minecraft:terracotta)
B(3,5,1,minecraft:terracotta)
B(3,5,2,minecraft:terracotta)
B(3,6,0,minecraft:terracotta)
B(3,6,1,minecraft:terracotta)
B(3,7,0,minecraft:terracotta)
B(3,8,0,minecraft:orange_terracotta)
B(4,-2,0,minecraft:orange_terracotta)
B(4,-2,2,minecraft:orange_terracotta)
B(4,-2,3,minecraft:orange_terracotta)
B(4,-1,-1,minecraft:orange_terracotta)
B(4,-1,0,minecraft:orange_terracotta)
B(4,-1,1,minecraft:orange_terracotta)
B(4,-1,2,minecraft:orange_terracotta)
B(4,-1,3,minecraft:orange_terracotta)
B(4,-1,4,minecraft:orange_terracotta)
B(4,0,-2,minecraft:orange_terracotta)
B(4,0,-1,minecraft:orange_terracotta)
B(4,0,0,minecraft:orange_terracotta)
B(4,0,1,minecraft:orange_terracotta)
B(4,0,2,minecraft:orange_terracotta)
B(4,0,3,minecraft:orange_terracotta)
B(4,0,4,minecraft:orange_terracotta)
B(4,1,-2,minecraft:orange_terracotta)
B(4,1,-1,minecraft:orange_terracotta)
B(4,1,0,minecraft:orange_terracotta)
B(4,1,1,minecraft:orange_terracotta)
B(4,1,2,minecraft:orange_terracotta)
B(4,1,3,minecraft:orange_terracotta)
B(4,1,4,minecraft:orange_terracotta)
B(4,2,-1,minecraft:orange_terracotta)
B(4,2,0,minecraft:orange_terracotta)
B(4,2,1,minecraft:orange_terracotta)
B(4,2,2,minecraft:orange_terracotta)
B(4,2,3,minecraft:orange_terracotta)
B(4,3,0,minecraft:yellow_terracotta)
B(4,3,1,minecraft:yellow_terracotta)
B(4,3,2,minecraft:yellow_terracotta)
B(4,4,0,minecraft:terracotta)
B(4,4,1,minecraft:yellow_terracotta)
B(4,5,0,minecraft:terracotta)
B(5,-1,0,minecraft:orange_terracotta)
B(5,-1,2,minecraft:orange_terracotta)
B(5,-1,3,minecraft:orange_terracotta)
B(5,0,-1,minecraft:orange_terracotta)
B(5,0,0,minecraft:orange_terracotta)
B(5,0,1,minecraft:orange_terracotta)
B(5,0,2,minecraft:orange_terracotta)
B(5,0,3,minecraft:orange_terracotta)
B(5,1,-1,minecraft:orange_terracotta)
B(5,1,0,minecraft:orange_terracotta)
B(5,1,1,minecraft:orange_terracotta)
B(5,1,2,minecraft:orange_terracotta)
B(5,1,3,minecraft:orange_terracotta)
B(5,2,0,minecraft:orange_terracotta)
B(5,2,1,minecraft:orange_terracotta)
B(5,2,2,minecraft:orange_terracotta)
B(5,3,1,minecraft:yellow_terracotta)

#######################################################################
# +-----------------------------------------------------------------+ #
# |                            BO3 checks                           | #
# +-----------------------------------------------------------------+ #
#######################################################################


#######################################################################
# +-----------------------------------------------------------------+ #
# |                             Branches                            | #
# +-----------------------------------------------------------------+ #
#######################################################################


#######################################################################
# +-----------------------------------------------------------------+ #
# |                             Entities                            | #
# +-----------------------------------------------------------------+ #
#######################################################################

