
#######################################################################
# +-----------------------------------------------------------------+ #
# |                            BO3 object                           | #
# +-----------------------------------------------------------------+ #
#######################################################################

Author: LordSmellyPants

Description: No description given

Version: 3

SettingsMode: WriteWithoutComments


#######################################################################
# +-----------------------------------------------------------------+ #
# |                          Main settings                          | #
# +-----------------------------------------------------------------+ #
#######################################################################

Tree: false

Frequency: 1

Rarity: 3.0

MaxSpawn: 0

RotateRandomly: true

SpawnHeight: randomY

SpawnHeightOffset: 0

SpawnHeightVariance: 0

##############################
# Height Limits for the BO3. #
##############################

MinHeight: 51

MaxHeight: 63

######################
# Extrusion settings #
######################

ExtrudeMode: None

ExtrudeThroughBlocks: minecraft:air

MaxBranchDepth: 10


#######################################################################
# +-----------------------------------------------------------------+ #
# |                      Source block settings                      | #
# +-----------------------------------------------------------------+ #
#######################################################################

SourceBlocks: minecraft:sand,minecraft:grass_block,minecraft:dirt,minecraft:gravel,minecraft:red_sand,minecraft:sandstone,minecraft:stone,minecraft:granite,minecraft:diorite,minecraft:andesite,minecraft:coarse_dirt,minecraft:clay,minecraft:terracotta,minecraft:white_terracotta,minecraft:poppy,minecraft:blue_orchid,minecraft:allium,minecraft:azure_bluet,minecraft:red_tulip,minecraft:orange_tulip,minecraft:white_tulip,minecraft:pink_tulip,minecraft:oxeye_daisy,minecraft:brown_mushroom,minecraft:red_mushroom,minecraft:sunflower,minecraft:lilac,minecraft:tall_grass,minecraft:large_fern,minecraft:rose_bush,minecraft:peony,minecraft:grass,minecraft:fern,minecraft:dead_bush,minecraft:coal_ore,minecraft:iron_ore,minecraft:gold_ore,minecraft:redstone_ore,minecraft:diamond_ore,minecraft:lapis_ore,minecraft:emerald_ore,minecraft:vine,minecraft:air,minecraft:water

MaxPercentageOutsideSourceBlock: 20

OutsideSourceBlock: placeAnyway

DoReplaceBlocks: true

IsOTGPlus: false


#######################################################################
# +-----------------------------------------------------------------+ #
# |                              Blocks                             | #
# +-----------------------------------------------------------------+ #
#######################################################################

B(-3,-2,-3,minecraft:orange_terracotta)
B(-3,-2,0,minecraft:orange_terracotta)
B(-3,-2,1,minecraft:orange_terracotta)
B(-3,-1,-4,minecraft:orange_terracotta)
B(-3,-1,-3,minecraft:orange_terracotta)
B(-3,-1,-2,minecraft:orange_terracotta)
B(-3,-1,-1,minecraft:orange_terracotta)
B(-3,-1,0,minecraft:orange_terracotta)
B(-3,-1,1,minecraft:orange_terracotta)
B(-3,-1,2,minecraft:orange_terracotta)
B(-3,0,-4,minecraft:orange_terracotta)
B(-3,0,-3,minecraft:orange_terracotta)
B(-3,0,-2,minecraft:orange_terracotta)
B(-3,0,-1,minecraft:orange_terracotta)
B(-3,0,0,minecraft:orange_terracotta)
B(-3,0,1,minecraft:orange_terracotta)
B(-3,0,2,minecraft:orange_terracotta)
B(-3,1,-2,minecraft:orange_terracotta)
B(-3,1,-1,minecraft:orange_terracotta)
B(-3,1,0,minecraft:orange_terracotta)
B(-3,1,1,minecraft:orange_terracotta)
B(-3,2,-1,minecraft:orange_terracotta)
B(-3,2,0,minecraft:orange_terracotta)
B(-2,-3,-4,minecraft:orange_terracotta)
B(-2,-3,-1,minecraft:orange_terracotta)
B(-2,-3,0,minecraft:orange_terracotta)
B(-2,-2,-4,minecraft:orange_terracotta)
B(-2,-2,-3,minecraft:orange_terracotta)
B(-2,-2,-2,minecraft:orange_terracotta)
B(-2,-2,-1,minecraft:orange_terracotta)
B(-2,-2,0,minecraft:orange_terracotta)
B(-2,-2,1,minecraft:orange_terracotta)
B(-2,-2,2,minecraft:orange_terracotta)
B(-2,-1,-6,minecraft:orange_terracotta)
B(-2,-1,-5,minecraft:orange_terracotta)
B(-2,-1,-4,minecraft:orange_terracotta)
B(-2,-1,-3,minecraft:orange_terracotta)
B(-2,-1,-2,minecraft:orange_terracotta)
B(-2,-1,-1,minecraft:orange_terracotta)
B(-2,-1,0,minecraft:orange_terracotta)
B(-2,-1,1,minecraft:orange_terracotta)
B(-2,-1,2,minecraft:orange_terracotta)
B(-2,-1,3,minecraft:orange_terracotta)
B(-2,-1,4,minecraft:orange_terracotta)
B(-2,-1,5,minecraft:orange_terracotta)
B(-2,0,-7,minecraft:orange_terracotta)
B(-2,0,-6,minecraft:orange_terracotta)
B(-2,0,-5,minecraft:orange_terracotta)
B(-2,0,-4,minecraft:orange_terracotta)
B(-2,0,-3,minecraft:orange_terracotta)
B(-2,0,-2,minecraft:orange_terracotta)
B(-2,0,-1,minecraft:orange_terracotta)
B(-2,0,0,minecraft:orange_terracotta)
B(-2,0,1,minecraft:orange_terracotta)
B(-2,0,2,minecraft:orange_terracotta)
B(-2,0,3,minecraft:orange_terracotta)
B(-2,0,4,minecraft:orange_terracotta)
B(-2,0,5,minecraft:orange_terracotta)
B(-2,1,-7,minecraft:orange_terracotta)
B(-2,1,-6,minecraft:orange_terracotta)
B(-2,1,-5,minecraft:orange_terracotta)
B(-2,1,-4,minecraft:orange_terracotta)
B(-2,1,-3,minecraft:orange_terracotta)
B(-2,1,-2,minecraft:orange_terracotta)
B(-2,1,-1,minecraft:orange_terracotta)
B(-2,1,0,minecraft:orange_terracotta)
B(-2,1,1,minecraft:orange_terracotta)
B(-2,1,2,minecraft:orange_terracotta)
B(-2,1,3,minecraft:orange_terracotta)
B(-2,2,-6,minecraft:yellow_terracotta)
B(-2,2,-5,minecraft:yellow_terracotta)
B(-2,2,-4,minecraft:yellow_terracotta)
B(-2,2,-3,minecraft:yellow_terracotta)
B(-2,2,-2,minecraft:yellow_terracotta)
B(-2,2,-1,minecraft:orange_terracotta)
B(-2,2,0,minecraft:orange_terracotta)
B(-2,2,1,minecraft:yellow_terracotta)
B(-2,2,2,minecraft:yellow_terracotta)
B(-2,3,-5,minecraft:yellow_terracotta)
B(-2,3,-4,minecraft:yellow_terracotta)
B(-2,3,-3,minecraft:yellow_terracotta)
B(-2,3,-2,minecraft:yellow_terracotta)
B(-2,3,-1,minecraft:yellow_terracotta)
B(-2,4,-3,minecraft:yellow_terracotta)
B(-2,4,-2,minecraft:yellow_terracotta)
B(-2,5,-3,minecraft:terracotta)
B(-2,6,-3,minecraft:terracotta)
B(-1,-4,-3,minecraft:orange_terracotta)
B(-1,-4,-1,minecraft:orange_terracotta)
B(-1,-3,-4,minecraft:orange_terracotta)
B(-1,-3,-3,minecraft:orange_terracotta)
B(-1,-3,-2,minecraft:orange_terracotta)
B(-1,-3,-1,minecraft:orange_terracotta)
B(-1,-3,0,minecraft:orange_terracotta)
B(-1,-3,1,minecraft:orange_terracotta)
B(-1,-2,-5,minecraft:orange_terracotta)
B(-1,-2,-4,minecraft:orange_terracotta)
B(-1,-2,-3,minecraft:orange_terracotta)
B(-1,-2,-2,minecraft:orange_terracotta)
B(-1,-2,-1,minecraft:orange_terracotta)
B(-1,-2,0,minecraft:orange_terracotta)
B(-1,-2,1,minecraft:orange_terracotta)
B(-1,-2,2,minecraft:orange_terracotta)
B(-1,-2,3,minecraft:orange_terracotta)
B(-1,-2,4,minecraft:orange_terracotta)
B(-1,-2,5,minecraft:orange_terracotta)
B(-1,-1,-8,minecraft:orange_terracotta)
B(-1,-1,-7,minecraft:orange_terracotta)
B(-1,-1,-6,minecraft:orange_terracotta)
B(-1,-1,-5,minecraft:orange_terracotta)
B(-1,-1,-4,minecraft:orange_terracotta)
B(-1,-1,-3,minecraft:orange_terracotta)
B(-1,-1,-2,minecraft:orange_terracotta)
B(-1,-1,-1,minecraft:orange_terracotta)
B(-1,-1,0,minecraft:orange_terracotta)
B(-1,-1,1,minecraft:orange_terracotta)
B(-1,-1,2,minecraft:orange_terracotta)
B(-1,-1,3,minecraft:orange_terracotta)
B(-1,-1,4,minecraft:orange_terracotta)
B(-1,-1,5,minecraft:orange_terracotta)
B(-1,-1,6,minecraft:orange_terracotta)
B(-1,0,-8,minecraft:orange_terracotta)
B(-1,0,-7,minecraft:yellow_terracotta)
B(-1,0,-6,minecraft:yellow_terracotta)
B(-1,0,-5,minecraft:orange_terracotta)
B(-1,0,-4,minecraft:orange_terracotta)
B(-1,0,-3,minecraft:orange_terracotta)
B(-1,0,-2,minecraft:orange_terracotta)
B(-1,0,-1,minecraft:orange_terracotta)
B(-1,0,0,minecraft:orange_terracotta)
B(-1,0,1,minecraft:orange_terracotta)
B(-1,0,2,minecraft:orange_terracotta)
B(-1,0,3,minecraft:orange_terracotta)
B(-1,0,4,minecraft:orange_terracotta)
B(-1,0,5,minecraft:orange_terracotta)
B(-1,0,6,minecraft:orange_terracotta)
B(-1,1,-7,minecraft:orange_terracotta)
B(-1,1,-6,minecraft:yellow_terracotta)
B(-1,1,-5,minecraft:orange_terracotta)
B(-1,1,-4,minecraft:orange_terracotta)
B(-1,1,-3,minecraft:orange_terracotta)
B(-1,1,-2,minecraft:orange_terracotta)
B(-1,1,-1,minecraft:orange_terracotta)
B(-1,1,0,minecraft:orange_terracotta)
B(-1,1,1,minecraft:orange_terracotta)
B(-1,1,2,minecraft:orange_terracotta)
B(-1,1,3,minecraft:orange_terracotta)
B(-1,1,4,minecraft:orange_terracotta)
B(-1,1,5,minecraft:orange_terracotta)
B(-1,2,-6,minecraft:yellow_terracotta)
B(-1,2,-5,minecraft:terracotta)
B(-1,2,-4,minecraft:terracotta)
B(-1,2,-3,minecraft:terracotta)
B(-1,2,-2,minecraft:terracotta)
B(-1,2,-1,minecraft:terracotta)
B(-1,2,0,minecraft:terracotta)
B(-1,2,1,minecraft:terracotta)
B(-1,2,2,minecraft:terracotta)
B(-1,2,3,minecraft:orange_terracotta)
B(-1,2,4,minecraft:yellow_terracotta)
B(-1,3,-6,minecraft:yellow_terracotta)
B(-1,3,-5,minecraft:yellow_terracotta)
B(-1,3,-4,minecraft:terracotta)
B(-1,3,-3,minecraft:terracotta)
B(-1,3,-2,minecraft:terracotta)
B(-1,3,-1,minecraft:terracotta)
B(-1,3,0,minecraft:yellow_terracotta)
B(-1,3,1,minecraft:yellow_terracotta)
B(-1,3,2,minecraft:yellow_terracotta)
B(-1,3,3,minecraft:orange_terracotta)
B(-1,4,-5,minecraft:yellow_terracotta)
B(-1,4,-4,minecraft:yellow_terracotta)
B(-1,4,-3,minecraft:terracotta)
B(-1,4,-2,minecraft:terracotta)
B(-1,4,-1,minecraft:terracotta)
B(-1,4,0,minecraft:terracotta)
B(-1,4,1,minecraft:terracotta)
B(-1,4,2,minecraft:terracotta)
B(-1,4,3,minecraft:terracotta)
B(-1,5,-4,minecraft:orange_terracotta)
B(-1,5,-3,minecraft:terracotta)
B(-1,5,-2,minecraft:terracotta)
B(-1,5,-1,minecraft:terracotta)
B(-1,5,0,minecraft:terracotta)
B(-1,5,1,minecraft:terracotta)
B(-1,5,2,minecraft:terracotta)
B(-1,5,3,minecraft:terracotta)
B(-1,6,-4,minecraft:orange_terracotta)
B(-1,6,-3,minecraft:orange_terracotta)
B(-1,6,-2,minecraft:terracotta)
B(-1,6,-1,minecraft:terracotta)
B(-1,6,0,minecraft:terracotta)
B(-1,6,1,minecraft:terracotta)
B(-1,6,2,minecraft:terracotta)
B(-1,6,3,minecraft:terracotta)
B(-1,7,-4,minecraft:orange_terracotta)
B(-1,7,-3,minecraft:orange_terracotta)
B(-1,7,-2,minecraft:orange_terracotta)
B(-1,7,-1,minecraft:orange_terracotta)
B(-1,7,0,minecraft:orange_terracotta)
B(-1,7,1,minecraft:orange_terracotta)
B(-1,7,2,minecraft:orange_terracotta)
B(-1,7,3,minecraft:orange_terracotta)
B(-1,8,-3,minecraft:orange_terracotta)
B(-1,8,-2,minecraft:terracotta)
B(-1,8,-1,minecraft:terracotta)
B(-1,8,0,minecraft:terracotta)
B(-1,8,1,minecraft:terracotta)
B(-1,8,2,minecraft:terracotta)
B(-1,8,3,minecraft:terracotta)
B(-1,9,-3,minecraft:terracotta)
B(-1,9,-2,minecraft:terracotta)
B(-1,9,-1,minecraft:terracotta)
B(-1,9,0,minecraft:terracotta)
B(-1,9,1,minecraft:terracotta)
B(-1,9,2,minecraft:terracotta)
B(-1,9,3,minecraft:terracotta)
B(-1,10,-3,minecraft:orange_terracotta)
B(-1,10,-2,minecraft:orange_terracotta)
B(-1,10,-1,minecraft:orange_terracotta)
B(-1,10,0,minecraft:orange_terracotta)
B(-1,10,1,minecraft:orange_terracotta)
B(-1,10,2,minecraft:orange_terracotta)
B(-1,10,3,minecraft:terracotta)
B(-1,11,-3,minecraft:terracotta)
B(-1,11,-2,minecraft:terracotta)
B(-1,11,-1,minecraft:terracotta)
B(-1,11,0,minecraft:terracotta)
B(-1,11,1,minecraft:terracotta)
B(-1,11,2,minecraft:terracotta)
B(-1,11,3,minecraft:terracotta)
B(-1,12,-3,minecraft:terracotta)
B(-1,12,-2,minecraft:terracotta)
B(-1,12,-1,minecraft:terracotta)
B(-1,12,0,minecraft:terracotta)
B(-1,12,1,minecraft:terracotta)
B(-1,12,2,minecraft:terracotta)
B(-1,13,-3,minecraft:red_terracotta)
B(-1,13,-2,minecraft:red_terracotta)
B(-1,13,-1,minecraft:red_terracotta)
B(-1,13,0,minecraft:red_terracotta)
B(-1,13,1,minecraft:red_terracotta)
B(-1,13,2,minecraft:red_terracotta)
B(-1,14,-1,minecraft:red_terracotta)
B(-1,14,0,minecraft:red_terracotta)
B(-1,14,1,minecraft:red_terracotta)
B(-1,14,2,minecraft:red_terracotta)
B(0,-5,-3,minecraft:orange_terracotta)
B(0,-5,-1,minecraft:orange_terracotta)
B(0,-4,-4,minecraft:orange_terracotta)
B(0,-4,-3,minecraft:orange_terracotta)
B(0,-4,-2,minecraft:orange_terracotta)
B(0,-4,-1,minecraft:orange_terracotta)
B(0,-4,0,minecraft:orange_terracotta)
B(0,-4,1,minecraft:orange_terracotta)
B(0,-4,2,minecraft:orange_terracotta)
B(0,-3,-5,minecraft:orange_terracotta)
B(0,-3,-4,minecraft:orange_terracotta)
B(0,-3,-3,minecraft:orange_terracotta)
B(0,-3,-2,minecraft:orange_terracotta)
B(0,-3,-1,minecraft:orange_terracotta)
B(0,-3,0,minecraft:orange_terracotta)
B(0,-3,1,minecraft:orange_terracotta)
B(0,-3,2,minecraft:orange_terracotta)
B(0,-3,3,minecraft:orange_terracotta)
B(0,-2,-8,minecraft:orange_terracotta)
B(0,-2,-7,minecraft:orange_terracotta)
B(0,-2,-6,minecraft:orange_terracotta)
B(0,-2,-5,minecraft:orange_terracotta)
B(0,-2,-4,minecraft:orange_terracotta)
B(0,-2,-3,minecraft:orange_terracotta)
B(0,-2,-2,minecraft:orange_terracotta)
B(0,-2,-1,minecraft:orange_terracotta)
B(0,-2,0,minecraft:orange_terracotta)
B(0,-2,1,minecraft:orange_terracotta)
B(0,-2,2,minecraft:orange_terracotta)
B(0,-2,3,minecraft:orange_terracotta)
B(0,-2,4,minecraft:orange_terracotta)
B(0,-2,5,minecraft:orange_terracotta)
B(0,-1,-9,minecraft:orange_terracotta)
B(0,-1,-8,minecraft:orange_terracotta)
B(0,-1,-7,minecraft:orange_terracotta)
B(0,-1,-6,minecraft:orange_terracotta)
B(0,-1,-5,minecraft:orange_terracotta)
B(0,-1,-4,minecraft:orange_terracotta)
B(0,-1,-3,minecraft:orange_terracotta)
B(0,-1,-2,minecraft:orange_terracotta)
B(0,-1,-1,minecraft:orange_terracotta)
B(0,-1,0,minecraft:orange_terracotta)
B(0,-1,1,minecraft:orange_terracotta)
B(0,-1,2,minecraft:orange_terracotta)
B(0,-1,3,minecraft:orange_terracotta)
B(0,-1,4,minecraft:orange_terracotta)
B(0,-1,5,minecraft:orange_terracotta)
B(0,-1,6,minecraft:orange_terracotta)
B(0,0,-9,minecraft:orange_terracotta)
B(0,0,-8,minecraft:orange_terracotta)
B(0,0,-7,minecraft:terracotta)
B(0,0,-6,minecraft:orange_terracotta)
B(0,0,-5,minecraft:orange_terracotta)
B(0,0,-4,minecraft:orange_terracotta)
B(0,0,-3,minecraft:orange_terracotta)
B(0,0,-2,minecraft:orange_terracotta)
B(0,0,-1,minecraft:orange_terracotta)
B(0,0,0,minecraft:orange_terracotta)
B(0,0,1,minecraft:orange_terracotta)
B(0,0,2,minecraft:orange_terracotta)
B(0,0,3,minecraft:orange_terracotta)
B(0,0,4,minecraft:orange_terracotta)
B(0,0,5,minecraft:orange_terracotta)
B(0,0,6,minecraft:orange_terracotta)
B(0,1,-8,minecraft:orange_terracotta)
B(0,1,-7,minecraft:terracotta)
B(0,1,-6,minecraft:orange_terracotta)
B(0,1,-5,minecraft:orange_terracotta)
B(0,1,-4,minecraft:orange_terracotta)
B(0,1,-3,minecraft:orange_terracotta)
B(0,1,-2,minecraft:orange_terracotta)
B(0,1,-1,minecraft:orange_terracotta)
B(0,1,0,minecraft:orange_terracotta)
B(0,1,1,minecraft:orange_terracotta)
B(0,1,2,minecraft:orange_terracotta)
B(0,1,3,minecraft:orange_terracotta)
B(0,1,4,minecraft:orange_terracotta)
B(0,1,5,minecraft:orange_terracotta)
B(0,1,6,minecraft:orange_terracotta)
B(0,2,-7,minecraft:orange_terracotta)
B(0,2,-6,minecraft:terracotta)
B(0,2,-5,minecraft:terracotta)
B(0,2,-4,minecraft:terracotta)
B(0,2,-3,minecraft:terracotta)
B(0,2,-2,minecraft:terracotta)
B(0,2,-1,minecraft:terracotta)
B(0,2,0,minecraft:terracotta)
B(0,2,1,minecraft:terracotta)
B(0,2,2,minecraft:terracotta)
B(0,2,3,minecraft:terracotta)
B(0,2,4,minecraft:orange_terracotta)
B(0,2,5,minecraft:yellow_terracotta)
B(0,3,-6,minecraft:yellow_terracotta)
B(0,3,-5,minecraft:terracotta)
B(0,3,-4,minecraft:terracotta)
B(0,3,-3,minecraft:terracotta)
B(0,3,-2,minecraft:terracotta)
B(0,3,-1,minecraft:terracotta)
B(0,3,0,minecraft:terracotta)
B(0,3,1,minecraft:terracotta)
B(0,3,2,minecraft:terracotta)
B(0,3,3,minecraft:terracotta)
B(0,3,4,minecraft:yellow_terracotta)
B(0,4,-6,minecraft:yellow_terracotta)
B(0,4,-5,minecraft:terracotta)
B(0,4,-4,minecraft:terracotta)
B(0,4,-3,minecraft:terracotta)
B(0,4,-2,minecraft:terracotta)
B(0,4,-1,minecraft:terracotta)
B(0,4,0,minecraft:terracotta)
B(0,4,1,minecraft:terracotta)
B(0,4,2,minecraft:terracotta)
B(0,4,3,minecraft:terracotta)
B(0,4,4,minecraft:terracotta)
B(0,5,-5,minecraft:terracotta)
B(0,5,-4,minecraft:terracotta)
B(0,5,-3,minecraft:terracotta)
B(0,5,-2,minecraft:terracotta)
B(0,5,-1,minecraft:terracotta)
B(0,5,0,minecraft:terracotta)
B(0,5,1,minecraft:terracotta)
B(0,5,2,minecraft:terracotta)
B(0,5,3,minecraft:terracotta)
B(0,5,4,minecraft:terracotta)
B(0,6,-5,minecraft:terracotta)
B(0,6,-4,minecraft:terracotta)
B(0,6,-3,minecraft:terracotta)
B(0,6,-2,minecraft:terracotta)
B(0,6,-1,minecraft:terracotta)
B(0,6,0,minecraft:terracotta)
B(0,6,1,minecraft:terracotta)
B(0,6,2,minecraft:terracotta)
B(0,6,3,minecraft:terracotta)
B(0,6,4,minecraft:terracotta)
B(0,7,-5,minecraft:terracotta)
B(0,7,-4,minecraft:terracotta)
B(0,7,-3,minecraft:terracotta)
B(0,7,-2,minecraft:terracotta)
B(0,7,-1,minecraft:terracotta)
B(0,7,0,minecraft:terracotta)
B(0,7,1,minecraft:terracotta)
B(0,7,2,minecraft:terracotta)
B(0,7,3,minecraft:terracotta)
B(0,7,4,minecraft:orange_terracotta)
B(0,8,-5,minecraft:terracotta)
B(0,8,-4,minecraft:terracotta)
B(0,8,-3,minecraft:terracotta)
B(0,8,-2,minecraft:terracotta)
B(0,8,-1,minecraft:terracotta)
B(0,8,0,minecraft:terracotta)
B(0,8,1,minecraft:terracotta)
B(0,8,2,minecraft:terracotta)
B(0,8,3,minecraft:terracotta)
B(0,8,4,minecraft:terracotta)
B(0,9,-4,minecraft:terracotta)
B(0,9,-3,minecraft:terracotta)
B(0,9,-2,minecraft:terracotta)
B(0,9,-1,minecraft:terracotta)
B(0,9,0,minecraft:terracotta)
B(0,9,1,minecraft:terracotta)
B(0,9,2,minecraft:terracotta)
B(0,9,3,minecraft:terracotta)
B(0,9,4,minecraft:terracotta)
B(0,10,-4,minecraft:orange_terracotta)
B(0,10,-3,minecraft:orange_terracotta)
B(0,10,-2,minecraft:orange_terracotta)
B(0,10,-1,minecraft:orange_terracotta)
B(0,10,0,minecraft:orange_terracotta)
B(0,10,1,minecraft:orange_terracotta)
B(0,10,2,minecraft:orange_terracotta)
B(0,10,3,minecraft:terracotta)
B(0,10,4,minecraft:orange_terracotta)
B(0,11,-4,minecraft:terracotta)
B(0,11,-3,minecraft:terracotta)
B(0,11,-2,minecraft:terracotta)
B(0,11,-1,minecraft:terracotta)
B(0,11,0,minecraft:terracotta)
B(0,11,1,minecraft:terracotta)
B(0,11,2,minecraft:terracotta)
B(0,11,3,minecraft:terracotta)
B(0,11,4,minecraft:terracotta)
B(0,12,-4,minecraft:terracotta)
B(0,12,-3,minecraft:terracotta)
B(0,12,-2,minecraft:terracotta)
B(0,12,-1,minecraft:terracotta)
B(0,12,0,minecraft:terracotta)
B(0,12,1,minecraft:terracotta)
B(0,12,2,minecraft:terracotta)
B(0,12,3,minecraft:terracotta)
B(0,12,4,minecraft:terracotta)
B(0,13,-4,minecraft:red_terracotta)
B(0,13,-3,minecraft:terracotta)
B(0,13,-2,minecraft:terracotta)
B(0,13,-1,minecraft:terracotta)
B(0,13,0,minecraft:terracotta)
B(0,13,1,minecraft:terracotta)
B(0,13,2,minecraft:terracotta)
B(0,13,3,minecraft:red_terracotta)
B(0,13,4,minecraft:red_terracotta)
B(0,14,-3,minecraft:red_terracotta)
B(0,14,-2,minecraft:terracotta)
B(0,14,-1,minecraft:red_terracotta)
B(0,14,0,minecraft:red_terracotta)
B(0,14,1,minecraft:red_terracotta)
B(0,14,2,minecraft:terracotta)
B(0,14,3,minecraft:red_terracotta)
B(0,14,4,minecraft:red_terracotta)
B(0,15,-2,minecraft:brown_terracotta)
B(0,15,-1,minecraft:brown_terracotta)
B(0,15,0,minecraft:brown_terracotta)
B(0,15,1,minecraft:brown_terracotta)
B(0,15,2,minecraft:brown_terracotta)
B(0,15,3,minecraft:brown_terracotta)
B(0,16,-2,minecraft:brown_terracotta)
B(0,16,-1,minecraft:brown_terracotta)
B(0,16,0,minecraft:brown_terracotta)
B(0,16,1,minecraft:brown_terracotta)
B(0,16,2,minecraft:brown_terracotta)
B(0,16,3,minecraft:brown_terracotta)
B(0,17,-2,minecraft:terracotta)
B(0,17,-1,minecraft:terracotta)
B(0,17,0,minecraft:terracotta)
B(0,17,1,minecraft:terracotta)
B(0,17,2,minecraft:terracotta)
B(0,17,3,minecraft:terracotta)
B(0,18,-2,minecraft:white_terracotta)
B(0,18,-1,minecraft:white_terracotta)
B(0,18,0,minecraft:white_terracotta)
B(0,18,1,minecraft:white_terracotta)
B(0,18,2,minecraft:white_terracotta)
B(0,18,3,minecraft:white_terracotta)
B(0,19,-2,minecraft:light_gray_terracotta)
B(0,19,-1,minecraft:light_gray_terracotta)
B(0,19,0,minecraft:light_gray_terracotta)
B(0,19,1,minecraft:light_gray_terracotta)
B(0,19,2,minecraft:light_gray_terracotta)
B(0,19,3,minecraft:light_gray_terracotta)
B(0,20,-2,minecraft:terracotta)
B(0,20,-1,minecraft:terracotta)
B(0,20,0,minecraft:terracotta)
B(0,20,1,minecraft:terracotta)
B(0,20,2,minecraft:terracotta)
B(0,20,3,minecraft:terracotta)
B(0,21,0,minecraft:terracotta)
B(0,21,1,minecraft:terracotta)
B(1,-5,-5,minecraft:orange_terracotta)
B(1,-5,-4,minecraft:orange_terracotta)
B(1,-5,-3,minecraft:orange_terracotta)
B(1,-5,-2,minecraft:orange_terracotta)
B(1,-5,-1,minecraft:orange_terracotta)
B(1,-5,0,minecraft:orange_terracotta)
B(1,-5,1,minecraft:orange_terracotta)
B(1,-5,2,minecraft:orange_terracotta)
B(1,-4,-6,minecraft:orange_terracotta)
B(1,-4,-5,minecraft:orange_terracotta)
B(1,-4,-4,minecraft:orange_terracotta)
B(1,-4,-3,minecraft:orange_terracotta)
B(1,-4,-2,minecraft:orange_terracotta)
B(1,-4,-1,minecraft:orange_terracotta)
B(1,-4,0,minecraft:orange_terracotta)
B(1,-4,1,minecraft:orange_terracotta)
B(1,-4,2,minecraft:orange_terracotta)
B(1,-3,-7,minecraft:orange_terracotta)
B(1,-3,-6,minecraft:orange_terracotta)
B(1,-3,-5,minecraft:orange_terracotta)
B(1,-3,-4,minecraft:orange_terracotta)
B(1,-3,-3,minecraft:orange_terracotta)
B(1,-3,-2,minecraft:orange_terracotta)
B(1,-3,-1,minecraft:orange_terracotta)
B(1,-3,0,minecraft:orange_terracotta)
B(1,-3,1,minecraft:orange_terracotta)
B(1,-3,2,minecraft:orange_terracotta)
B(1,-2,-8,minecraft:orange_terracotta)
B(1,-2,-7,minecraft:orange_terracotta)
B(1,-2,-6,minecraft:orange_terracotta)
B(1,-2,-5,minecraft:orange_terracotta)
B(1,-2,-4,minecraft:orange_terracotta)
B(1,-2,-3,minecraft:orange_terracotta)
B(1,-2,-2,minecraft:orange_terracotta)
B(1,-2,-1,minecraft:orange_terracotta)
B(1,-2,0,minecraft:orange_terracotta)
B(1,-2,1,minecraft:orange_terracotta)
B(1,-2,2,minecraft:orange_terracotta)
B(1,-2,3,minecraft:orange_terracotta)
B(1,-2,4,minecraft:orange_terracotta)
B(1,-2,5,minecraft:orange_terracotta)
B(1,-2,6,minecraft:orange_terracotta)
B(1,-1,-9,minecraft:orange_terracotta)
B(1,-1,-8,minecraft:orange_terracotta)
B(1,-1,-7,minecraft:orange_terracotta)
B(1,-1,-6,minecraft:orange_terracotta)
B(1,-1,-5,minecraft:orange_terracotta)
B(1,-1,-4,minecraft:orange_terracotta)
B(1,-1,-3,minecraft:orange_terracotta)
B(1,-1,-2,minecraft:orange_terracotta)
B(1,-1,-1,minecraft:orange_terracotta)
B(1,-1,0,minecraft:orange_terracotta)
B(1,-1,1,minecraft:orange_terracotta)
B(1,-1,2,minecraft:orange_terracotta)
B(1,-1,3,minecraft:orange_terracotta)
B(1,-1,4,minecraft:orange_terracotta)
B(1,-1,5,minecraft:orange_terracotta)
B(1,-1,6,minecraft:orange_terracotta)
B(1,0,-9,minecraft:orange_terracotta)
B(1,0,-8,minecraft:orange_terracotta)
B(1,0,-7,minecraft:orange_terracotta)
B(1,0,-6,minecraft:orange_terracotta)
B(1,0,-5,minecraft:orange_terracotta)
B(1,0,-4,minecraft:orange_terracotta)
B(1,0,-3,minecraft:orange_terracotta)
B(1,0,-2,minecraft:orange_terracotta)
B(1,0,-1,minecraft:orange_terracotta)
B(1,0,0,minecraft:orange_terracotta)
B(1,0,1,minecraft:orange_terracotta)
B(1,0,2,minecraft:orange_terracotta)
B(1,0,3,minecraft:orange_terracotta)
B(1,0,4,minecraft:orange_terracotta)
B(1,0,5,minecraft:orange_terracotta)
B(1,0,6,minecraft:orange_terracotta)
B(1,1,-8,minecraft:orange_terracotta)
B(1,1,-7,minecraft:orange_terracotta)
B(1,1,-6,minecraft:orange_terracotta)
B(1,1,-5,minecraft:orange_terracotta)
B(1,1,-4,minecraft:orange_terracotta)
B(1,1,-3,minecraft:orange_terracotta)
B(1,1,-2,minecraft:orange_terracotta)
B(1,1,-1,minecraft:orange_terracotta)
B(1,1,0,minecraft:orange_terracotta)
B(1,1,1,minecraft:orange_terracotta)
B(1,1,2,minecraft:orange_terracotta)
B(1,1,3,minecraft:orange_terracotta)
B(1,1,4,minecraft:orange_terracotta)
B(1,1,5,minecraft:orange_terracotta)
B(1,1,6,minecraft:orange_terracotta)
B(1,2,-8,minecraft:orange_terracotta)
B(1,2,-7,minecraft:terracotta)
B(1,2,-6,minecraft:terracotta)
B(1,2,-5,minecraft:terracotta)
B(1,2,-4,minecraft:terracotta)
B(1,2,-3,minecraft:terracotta)
B(1,2,-2,minecraft:terracotta)
B(1,2,-1,minecraft:terracotta)
B(1,2,0,minecraft:terracotta)
B(1,2,1,minecraft:terracotta)
B(1,2,2,minecraft:terracotta)
B(1,2,3,minecraft:terracotta)
B(1,2,4,minecraft:orange_terracotta)
B(1,2,5,minecraft:yellow_terracotta)
B(1,3,-7,minecraft:yellow_terracotta)
B(1,3,-6,minecraft:terracotta)
B(1,3,-5,minecraft:terracotta)
B(1,3,-4,minecraft:terracotta)
B(1,3,-3,minecraft:terracotta)
B(1,3,-2,minecraft:terracotta)
B(1,3,-1,minecraft:terracotta)
B(1,3,0,minecraft:terracotta)
B(1,3,1,minecraft:terracotta)
B(1,3,2,minecraft:terracotta)
B(1,3,3,minecraft:terracotta)
B(1,3,4,minecraft:yellow_terracotta)
B(1,4,-7,minecraft:yellow_terracotta)
B(1,4,-6,minecraft:terracotta)
B(1,4,-5,minecraft:terracotta)
B(1,4,-4,minecraft:terracotta)
B(1,4,-3,minecraft:terracotta)
B(1,4,-2,minecraft:terracotta)
B(1,4,-1,minecraft:terracotta)
B(1,4,0,minecraft:terracotta)
B(1,4,1,minecraft:terracotta)
B(1,4,2,minecraft:terracotta)
B(1,4,3,minecraft:terracotta)
B(1,4,4,minecraft:terracotta)
B(1,5,-7,minecraft:terracotta)
B(1,5,-6,minecraft:terracotta)
B(1,5,-5,minecraft:terracotta)
B(1,5,-4,minecraft:terracotta)
B(1,5,-3,minecraft:terracotta)
B(1,5,-2,minecraft:terracotta)
B(1,5,-1,minecraft:terracotta)
B(1,5,0,minecraft:terracotta)
B(1,5,1,minecraft:terracotta)
B(1,5,2,minecraft:terracotta)
B(1,5,3,minecraft:terracotta)
B(1,5,4,minecraft:terracotta)
B(1,6,-7,minecraft:terracotta)
B(1,6,-6,minecraft:terracotta)
B(1,6,-5,minecraft:terracotta)
B(1,6,-4,minecraft:terracotta)
B(1,6,-3,minecraft:terracotta)
B(1,6,-2,minecraft:terracotta)
B(1,6,-1,minecraft:terracotta)
B(1,6,0,minecraft:terracotta)
B(1,6,1,minecraft:terracotta)
B(1,6,2,minecraft:terracotta)
B(1,6,3,minecraft:terracotta)
B(1,6,4,minecraft:terracotta)
B(1,7,-6,minecraft:orange_terracotta)
B(1,7,-5,minecraft:terracotta)
B(1,7,-4,minecraft:terracotta)
B(1,7,-3,minecraft:terracotta)
B(1,7,-2,minecraft:terracotta)
B(1,7,-1,minecraft:terracotta)
B(1,7,0,minecraft:terracotta)
B(1,7,1,minecraft:terracotta)
B(1,7,2,minecraft:terracotta)
B(1,7,3,minecraft:terracotta)
B(1,7,4,minecraft:orange_terracotta)
B(1,8,-6,minecraft:terracotta)
B(1,8,-5,minecraft:terracotta)
B(1,8,-4,minecraft:terracotta)
B(1,8,-3,minecraft:terracotta)
B(1,8,-2,minecraft:terracotta)
B(1,8,-1,minecraft:terracotta)
B(1,8,0,minecraft:terracotta)
B(1,8,1,minecraft:terracotta)
B(1,8,2,minecraft:terracotta)
B(1,8,3,minecraft:terracotta)
B(1,8,4,minecraft:terracotta)
B(1,9,-5,minecraft:terracotta)
B(1,9,-4,minecraft:terracotta)
B(1,9,-3,minecraft:terracotta)
B(1,9,-2,minecraft:terracotta)
B(1,9,-1,minecraft:terracotta)
B(1,9,0,minecraft:terracotta)
B(1,9,1,minecraft:terracotta)
B(1,9,2,minecraft:terracotta)
B(1,9,3,minecraft:terracotta)
B(1,9,4,minecraft:terracotta)
B(1,10,-5,minecraft:terracotta)
B(1,10,-4,minecraft:terracotta)
B(1,10,-3,minecraft:orange_terracotta)
B(1,10,-2,minecraft:orange_terracotta)
B(1,10,-1,minecraft:orange_terracotta)
B(1,10,0,minecraft:orange_terracotta)
B(1,10,1,minecraft:orange_terracotta)
B(1,10,2,minecraft:orange_terracotta)
B(1,10,3,minecraft:terracotta)
B(1,10,4,minecraft:orange_terracotta)
B(1,11,-4,minecraft:terracotta)
B(1,11,-3,minecraft:terracotta)
B(1,11,-2,minecraft:terracotta)
B(1,11,-1,minecraft:terracotta)
B(1,11,0,minecraft:terracotta)
B(1,11,1,minecraft:terracotta)
B(1,11,2,minecraft:terracotta)
B(1,11,3,minecraft:terracotta)
B(1,11,4,minecraft:terracotta)
B(1,12,-4,minecraft:terracotta)
B(1,12,-3,minecraft:terracotta)
B(1,12,-2,minecraft:terracotta)
B(1,12,-1,minecraft:terracotta)
B(1,12,0,minecraft:terracotta)
B(1,12,1,minecraft:terracotta)
B(1,12,2,minecraft:terracotta)
B(1,12,3,minecraft:terracotta)
B(1,12,4,minecraft:terracotta)
B(1,13,-4,minecraft:red_terracotta)
B(1,13,-3,minecraft:terracotta)
B(1,13,-2,minecraft:terracotta)
B(1,13,-1,minecraft:terracotta)
B(1,13,0,minecraft:terracotta)
B(1,13,1,minecraft:terracotta)
B(1,13,2,minecraft:terracotta)
B(1,13,3,minecraft:terracotta)
B(1,13,4,minecraft:red_terracotta)
B(1,14,-4,minecraft:red_terracotta)
B(1,14,-3,minecraft:red_terracotta)
B(1,14,-2,minecraft:terracotta)
B(1,14,-1,minecraft:terracotta)
B(1,14,0,minecraft:terracotta)
B(1,14,1,minecraft:terracotta)
B(1,14,2,minecraft:terracotta)
B(1,14,3,minecraft:terracotta)
B(1,14,4,minecraft:red_terracotta)
B(1,15,-3,minecraft:brown_terracotta)
B(1,15,-2,minecraft:terracotta)
B(1,15,-1,minecraft:terracotta)
B(1,15,0,minecraft:terracotta)
B(1,15,1,minecraft:terracotta)
B(1,15,2,minecraft:terracotta)
B(1,15,3,minecraft:terracotta)
B(1,15,4,minecraft:brown_terracotta)
B(1,16,-3,minecraft:brown_terracotta)
B(1,16,-2,minecraft:terracotta)
B(1,16,-1,minecraft:terracotta)
B(1,16,0,minecraft:terracotta)
B(1,16,1,minecraft:terracotta)
B(1,16,2,minecraft:terracotta)
B(1,16,3,minecraft:brown_terracotta)
B(1,16,4,minecraft:brown_terracotta)
B(1,17,-3,minecraft:terracotta)
B(1,17,-2,minecraft:terracotta)
B(1,17,-1,minecraft:terracotta)
B(1,17,0,minecraft:terracotta)
B(1,17,1,minecraft:terracotta)
B(1,17,2,minecraft:terracotta)
B(1,17,3,minecraft:terracotta)
B(1,18,-3,minecraft:white_terracotta)
B(1,18,-2,minecraft:white_terracotta)
B(1,18,-1,minecraft:white_terracotta)
B(1,18,0,minecraft:white_terracotta)
B(1,18,1,minecraft:white_terracotta)
B(1,18,2,minecraft:white_terracotta)
B(1,18,3,minecraft:white_terracotta)
B(1,19,-3,minecraft:light_gray_terracotta)
B(1,19,-2,minecraft:light_gray_terracotta)
B(1,19,-1,minecraft:light_gray_terracotta)
B(1,19,0,minecraft:light_gray_terracotta)
B(1,19,1,minecraft:light_gray_terracotta)
B(1,19,2,minecraft:light_gray_terracotta)
B(1,19,3,minecraft:light_gray_terracotta)
B(1,20,-3,minecraft:terracotta)
B(1,20,-2,minecraft:terracotta)
B(1,20,-1,minecraft:terracotta)
B(1,20,0,minecraft:terracotta)
B(1,20,1,minecraft:terracotta)
B(1,20,2,minecraft:terracotta)
B(1,20,3,minecraft:terracotta)
B(1,21,-2,minecraft:terracotta)
B(1,21,-1,minecraft:terracotta)
B(1,21,0,minecraft:terracotta)
B(1,21,1,minecraft:terracotta)
B(1,21,2,minecraft:terracotta)
B(1,21,3,minecraft:terracotta)
B(2,-5,-5,minecraft:orange_terracotta)
B(2,-5,-4,minecraft:orange_terracotta)
B(2,-5,-3,minecraft:orange_terracotta)
B(2,-5,-2,minecraft:orange_terracotta)
B(2,-5,-1,minecraft:orange_terracotta)
B(2,-5,0,minecraft:orange_terracotta)
B(2,-5,1,minecraft:orange_terracotta)
B(2,-5,2,minecraft:orange_terracotta)
B(2,-4,-6,minecraft:orange_terracotta)
B(2,-4,-5,minecraft:orange_terracotta)
B(2,-4,-4,minecraft:orange_terracotta)
B(2,-4,-3,minecraft:orange_terracotta)
B(2,-4,-2,minecraft:orange_terracotta)
B(2,-4,-1,minecraft:orange_terracotta)
B(2,-4,0,minecraft:orange_terracotta)
B(2,-4,1,minecraft:orange_terracotta)
B(2,-4,2,minecraft:orange_terracotta)
B(2,-4,3,minecraft:orange_terracotta)
B(2,-3,-7,minecraft:orange_terracotta)
B(2,-3,-6,minecraft:orange_terracotta)
B(2,-3,-5,minecraft:orange_terracotta)
B(2,-3,-4,minecraft:orange_terracotta)
B(2,-3,-3,minecraft:orange_terracotta)
B(2,-3,-2,minecraft:orange_terracotta)
B(2,-3,-1,minecraft:orange_terracotta)
B(2,-3,0,minecraft:orange_terracotta)
B(2,-3,1,minecraft:orange_terracotta)
B(2,-3,2,minecraft:orange_terracotta)
B(2,-3,3,minecraft:orange_terracotta)
B(2,-3,4,minecraft:orange_terracotta)
B(2,-2,-9,minecraft:orange_terracotta)
B(2,-2,-8,minecraft:orange_terracotta)
B(2,-2,-7,minecraft:orange_terracotta)
B(2,-2,-6,minecraft:orange_terracotta)
B(2,-2,-5,minecraft:orange_terracotta)
B(2,-2,-4,minecraft:orange_terracotta)
B(2,-2,-3,minecraft:orange_terracotta)
B(2,-2,-2,minecraft:orange_terracotta)
B(2,-2,-1,minecraft:orange_terracotta)
B(2,-2,0,minecraft:orange_terracotta)
B(2,-2,1,minecraft:orange_terracotta)
B(2,-2,2,minecraft:orange_terracotta)
B(2,-2,3,minecraft:orange_terracotta)
B(2,-2,4,minecraft:orange_terracotta)
B(2,-2,5,minecraft:orange_terracotta)
B(2,-2,6,minecraft:orange_terracotta)
B(2,-1,-9,minecraft:orange_terracotta)
B(2,-1,-8,minecraft:orange_terracotta)
B(2,-1,-7,minecraft:orange_terracotta)
B(2,-1,-6,minecraft:orange_terracotta)
B(2,-1,-5,minecraft:orange_terracotta)
B(2,-1,-4,minecraft:orange_terracotta)
B(2,-1,-3,minecraft:orange_terracotta)
B(2,-1,-2,minecraft:orange_terracotta)
B(2,-1,-1,minecraft:orange_terracotta)
B(2,-1,0,minecraft:orange_terracotta)
B(2,-1,1,minecraft:orange_terracotta)
B(2,-1,2,minecraft:orange_terracotta)
B(2,-1,3,minecraft:orange_terracotta)
B(2,-1,4,minecraft:orange_terracotta)
B(2,-1,5,minecraft:orange_terracotta)
B(2,-1,6,minecraft:orange_terracotta)
B(2,-1,7,minecraft:orange_terracotta)
B(2,0,-9,minecraft:orange_terracotta)
B(2,0,-8,minecraft:orange_terracotta)
B(2,0,-7,minecraft:orange_terracotta)
B(2,0,-6,minecraft:orange_terracotta)
B(2,0,-5,minecraft:orange_terracotta)
B(2,0,-4,minecraft:orange_terracotta)
B(2,0,-3,minecraft:orange_terracotta)
B(2,0,-2,minecraft:orange_terracotta)
B(2,0,-1,minecraft:orange_terracotta)
B(2,0,0,minecraft:orange_terracotta)
B(2,0,1,minecraft:orange_terracotta)
B(2,0,2,minecraft:orange_terracotta)
B(2,0,3,minecraft:orange_terracotta)
B(2,0,4,minecraft:orange_terracotta)
B(2,0,5,minecraft:orange_terracotta)
B(2,0,6,minecraft:orange_terracotta)
B(2,0,7,minecraft:orange_terracotta)
B(2,1,-9,minecraft:orange_terracotta)
B(2,1,-8,minecraft:orange_terracotta)
B(2,1,-7,minecraft:orange_terracotta)
B(2,1,-6,minecraft:orange_terracotta)
B(2,1,-5,minecraft:orange_terracotta)
B(2,1,-4,minecraft:orange_terracotta)
B(2,1,-3,minecraft:orange_terracotta)
B(2,1,-2,minecraft:orange_terracotta)
B(2,1,-1,minecraft:orange_terracotta)
B(2,1,0,minecraft:orange_terracotta)
B(2,1,1,minecraft:orange_terracotta)
B(2,1,2,minecraft:orange_terracotta)
B(2,1,3,minecraft:orange_terracotta)
B(2,1,4,minecraft:orange_terracotta)
B(2,1,5,minecraft:orange_terracotta)
B(2,1,6,minecraft:orange_terracotta)
B(2,2,-8,minecraft:orange_terracotta)
B(2,2,-7,minecraft:terracotta)
B(2,2,-6,minecraft:terracotta)
B(2,2,-5,minecraft:terracotta)
B(2,2,-4,minecraft:terracotta)
B(2,2,-3,minecraft:terracotta)
B(2,2,-2,minecraft:terracotta)
B(2,2,-1,minecraft:terracotta)
B(2,2,0,minecraft:terracotta)
B(2,2,1,minecraft:terracotta)
B(2,2,2,minecraft:terracotta)
B(2,2,3,minecraft:terracotta)
B(2,2,4,minecraft:orange_terracotta)
B(2,2,5,minecraft:orange_terracotta)
B(2,3,-8,minecraft:yellow_terracotta)
B(2,3,-7,minecraft:terracotta)
B(2,3,-6,minecraft:terracotta)
B(2,3,-5,minecraft:terracotta)
B(2,3,-4,minecraft:terracotta)
B(2,3,-3,minecraft:terracotta)
B(2,3,-2,minecraft:terracotta)
B(2,3,-1,minecraft:terracotta)
B(2,3,0,minecraft:terracotta)
B(2,3,1,minecraft:terracotta)
B(2,3,2,minecraft:terracotta)
B(2,3,3,minecraft:terracotta)
B(2,3,4,minecraft:yellow_terracotta)
B(2,3,5,minecraft:yellow_terracotta)
B(2,4,-7,minecraft:terracotta)
B(2,4,-6,minecraft:terracotta)
B(2,4,-5,minecraft:terracotta)
B(2,4,-4,minecraft:terracotta)
B(2,4,-3,minecraft:terracotta)
B(2,4,-2,minecraft:terracotta)
B(2,4,-1,minecraft:terracotta)
B(2,4,0,minecraft:terracotta)
B(2,4,1,minecraft:terracotta)
B(2,4,2,minecraft:terracotta)
B(2,4,3,minecraft:terracotta)
B(2,4,4,minecraft:yellow_terracotta)
B(2,5,-7,minecraft:terracotta)
B(2,5,-6,minecraft:terracotta)
B(2,5,-5,minecraft:terracotta)
B(2,5,-4,minecraft:terracotta)
B(2,5,-3,minecraft:terracotta)
B(2,5,-2,minecraft:terracotta)
B(2,5,-1,minecraft:terracotta)
B(2,5,0,minecraft:terracotta)
B(2,5,1,minecraft:terracotta)
B(2,5,2,minecraft:terracotta)
B(2,5,3,minecraft:terracotta)
B(2,5,4,minecraft:terracotta)
B(2,6,-7,minecraft:terracotta)
B(2,6,-6,minecraft:terracotta)
B(2,6,-5,minecraft:terracotta)
B(2,6,-4,minecraft:terracotta)
B(2,6,-3,minecraft:terracotta)
B(2,6,-2,minecraft:terracotta)
B(2,6,-1,minecraft:terracotta)
B(2,6,0,minecraft:terracotta)
B(2,6,1,minecraft:terracotta)
B(2,6,2,minecraft:terracotta)
B(2,6,3,minecraft:terracotta)
B(2,6,4,minecraft:terracotta)
B(2,7,-6,minecraft:orange_terracotta)
B(2,7,-5,minecraft:terracotta)
B(2,7,-4,minecraft:terracotta)
B(2,7,-3,minecraft:terracotta)
B(2,7,-2,minecraft:terracotta)
B(2,7,-1,minecraft:terracotta)
B(2,7,0,minecraft:terracotta)
B(2,7,1,minecraft:terracotta)
B(2,7,2,minecraft:terracotta)
B(2,7,3,minecraft:orange_terracotta)
B(2,8,-5,minecraft:terracotta)
B(2,8,-4,minecraft:terracotta)
B(2,8,-3,minecraft:terracotta)
B(2,8,-2,minecraft:terracotta)
B(2,8,-1,minecraft:terracotta)
B(2,8,0,minecraft:terracotta)
B(2,8,1,minecraft:terracotta)
B(2,8,2,minecraft:terracotta)
B(2,8,3,minecraft:terracotta)
B(2,9,-4,minecraft:terracotta)
B(2,9,-3,minecraft:terracotta)
B(2,9,-2,minecraft:terracotta)
B(2,9,-1,minecraft:terracotta)
B(2,9,0,minecraft:terracotta)
B(2,9,1,minecraft:terracotta)
B(2,9,2,minecraft:terracotta)
B(2,9,3,minecraft:terracotta)
B(2,10,-4,minecraft:orange_terracotta)
B(2,10,-3,minecraft:orange_terracotta)
B(2,10,-2,minecraft:orange_terracotta)
B(2,10,-1,minecraft:orange_terracotta)
B(2,10,0,minecraft:orange_terracotta)
B(2,10,1,minecraft:orange_terracotta)
B(2,10,2,minecraft:orange_terracotta)
B(2,10,3,minecraft:orange_terracotta)
B(2,11,-4,minecraft:terracotta)
B(2,11,-3,minecraft:terracotta)
B(2,11,-2,minecraft:terracotta)
B(2,11,-1,minecraft:terracotta)
B(2,11,0,minecraft:terracotta)
B(2,11,1,minecraft:terracotta)
B(2,11,2,minecraft:terracotta)
B(2,11,3,minecraft:terracotta)
B(2,12,-4,minecraft:terracotta)
B(2,12,-3,minecraft:terracotta)
B(2,12,-2,minecraft:terracotta)
B(2,12,-1,minecraft:terracotta)
B(2,12,0,minecraft:terracotta)
B(2,12,1,minecraft:terracotta)
B(2,12,2,minecraft:terracotta)
B(2,12,3,minecraft:terracotta)
B(2,13,-4,minecraft:red_terracotta)
B(2,13,-3,minecraft:terracotta)
B(2,13,-2,minecraft:terracotta)
B(2,13,-1,minecraft:terracotta)
B(2,13,0,minecraft:terracotta)
B(2,13,1,minecraft:terracotta)
B(2,13,2,minecraft:terracotta)
B(2,13,3,minecraft:red_terracotta)
B(2,14,-4,minecraft:red_terracotta)
B(2,14,-3,minecraft:red_terracotta)
B(2,14,-2,minecraft:terracotta)
B(2,14,-1,minecraft:terracotta)
B(2,14,0,minecraft:terracotta)
B(2,14,1,minecraft:terracotta)
B(2,14,2,minecraft:terracotta)
B(2,14,3,minecraft:red_terracotta)
B(2,15,-3,minecraft:brown_terracotta)
B(2,15,-2,minecraft:terracotta)
B(2,15,-1,minecraft:terracotta)
B(2,15,0,minecraft:terracotta)
B(2,15,1,minecraft:terracotta)
B(2,15,2,minecraft:terracotta)
B(2,15,3,minecraft:brown_terracotta)
B(2,16,-3,minecraft:brown_terracotta)
B(2,16,-2,minecraft:terracotta)
B(2,16,-1,minecraft:terracotta)
B(2,16,0,minecraft:terracotta)
B(2,16,1,minecraft:terracotta)
B(2,16,2,minecraft:terracotta)
B(2,16,3,minecraft:brown_terracotta)
B(2,17,-3,minecraft:terracotta)
B(2,17,-2,minecraft:terracotta)
B(2,17,-1,minecraft:terracotta)
B(2,17,0,minecraft:terracotta)
B(2,17,1,minecraft:terracotta)
B(2,17,2,minecraft:terracotta)
B(2,17,3,minecraft:terracotta)
B(2,18,-3,minecraft:white_terracotta)
B(2,18,-2,minecraft:white_terracotta)
B(2,18,-1,minecraft:white_terracotta)
B(2,18,0,minecraft:white_terracotta)
B(2,18,1,minecraft:white_terracotta)
B(2,18,2,minecraft:white_terracotta)
B(2,18,3,minecraft:white_terracotta)
B(2,19,-3,minecraft:light_gray_terracotta)
B(2,19,-2,minecraft:light_gray_terracotta)
B(2,19,-1,minecraft:light_gray_terracotta)
B(2,19,0,minecraft:light_gray_terracotta)
B(2,19,1,minecraft:light_gray_terracotta)
B(2,19,2,minecraft:light_gray_terracotta)
B(2,19,3,minecraft:light_gray_terracotta)
B(2,20,-3,minecraft:terracotta)
B(2,20,-2,minecraft:terracotta)
B(2,20,-1,minecraft:terracotta)
B(2,20,0,minecraft:terracotta)
B(2,20,1,minecraft:terracotta)
B(2,20,2,minecraft:terracotta)
B(2,20,3,minecraft:terracotta)
B(2,21,-3,minecraft:terracotta)
B(2,21,-2,minecraft:terracotta)
B(2,21,-1,minecraft:terracotta)
B(2,21,0,minecraft:terracotta)
B(2,21,1,minecraft:terracotta)
B(2,21,2,minecraft:terracotta)
B(2,21,3,minecraft:terracotta)
B(3,-5,-4,minecraft:orange_terracotta)
B(3,-5,-3,minecraft:orange_terracotta)
B(3,-5,-2,minecraft:orange_terracotta)
B(3,-5,-1,minecraft:orange_terracotta)
B(3,-5,0,minecraft:orange_terracotta)
B(3,-5,1,minecraft:orange_terracotta)
B(3,-5,2,minecraft:orange_terracotta)
B(3,-4,-5,minecraft:orange_terracotta)
B(3,-4,-4,minecraft:orange_terracotta)
B(3,-4,-3,minecraft:orange_terracotta)
B(3,-4,-2,minecraft:orange_terracotta)
B(3,-4,-1,minecraft:orange_terracotta)
B(3,-4,0,minecraft:orange_terracotta)
B(3,-4,1,minecraft:orange_terracotta)
B(3,-4,2,minecraft:orange_terracotta)
B(3,-4,3,minecraft:orange_terracotta)
B(3,-4,4,minecraft:orange_terracotta)
B(3,-3,-6,minecraft:orange_terracotta)
B(3,-3,-5,minecraft:orange_terracotta)
B(3,-3,-4,minecraft:orange_terracotta)
B(3,-3,-3,minecraft:orange_terracotta)
B(3,-3,-2,minecraft:orange_terracotta)
B(3,-3,-1,minecraft:orange_terracotta)
B(3,-3,0,minecraft:orange_terracotta)
B(3,-3,1,minecraft:orange_terracotta)
B(3,-3,2,minecraft:orange_terracotta)
B(3,-3,3,minecraft:orange_terracotta)
B(3,-3,4,minecraft:orange_terracotta)
B(3,-2,-8,minecraft:orange_terracotta)
B(3,-2,-7,minecraft:orange_terracotta)
B(3,-2,-6,minecraft:orange_terracotta)
B(3,-2,-5,minecraft:orange_terracotta)
B(3,-2,-4,minecraft:orange_terracotta)
B(3,-2,-3,minecraft:orange_terracotta)
B(3,-2,-2,minecraft:orange_terracotta)
B(3,-2,-1,minecraft:orange_terracotta)
B(3,-2,0,minecraft:orange_terracotta)
B(3,-2,1,minecraft:orange_terracotta)
B(3,-2,2,minecraft:orange_terracotta)
B(3,-2,3,minecraft:orange_terracotta)
B(3,-2,4,minecraft:orange_terracotta)
B(3,-2,5,minecraft:orange_terracotta)
B(3,-2,6,minecraft:orange_terracotta)
B(3,-1,-9,minecraft:orange_terracotta)
B(3,-1,-8,minecraft:orange_terracotta)
B(3,-1,-7,minecraft:orange_terracotta)
B(3,-1,-6,minecraft:orange_terracotta)
B(3,-1,-5,minecraft:orange_terracotta)
B(3,-1,-4,minecraft:orange_terracotta)
B(3,-1,-3,minecraft:orange_terracotta)
B(3,-1,-2,minecraft:orange_terracotta)
B(3,-1,-1,minecraft:orange_terracotta)
B(3,-1,0,minecraft:orange_terracotta)
B(3,-1,1,minecraft:orange_terracotta)
B(3,-1,2,minecraft:orange_terracotta)
B(3,-1,3,minecraft:orange_terracotta)
B(3,-1,4,minecraft:orange_terracotta)
B(3,-1,5,minecraft:orange_terracotta)
B(3,-1,6,minecraft:orange_terracotta)
B(3,0,-8,minecraft:orange_terracotta)
B(3,0,-7,minecraft:orange_terracotta)
B(3,0,-6,minecraft:orange_terracotta)
B(3,0,-5,minecraft:orange_terracotta)
B(3,0,-4,minecraft:orange_terracotta)
B(3,0,-3,minecraft:orange_terracotta)
B(3,0,-2,minecraft:orange_terracotta)
B(3,0,-1,minecraft:orange_terracotta)
B(3,0,0,minecraft:orange_terracotta)
B(3,0,1,minecraft:orange_terracotta)
B(3,0,2,minecraft:orange_terracotta)
B(3,0,3,minecraft:orange_terracotta)
B(3,0,4,minecraft:orange_terracotta)
B(3,0,5,minecraft:orange_terracotta)
B(3,0,6,minecraft:orange_terracotta)
B(3,0,7,minecraft:orange_terracotta)
B(3,1,-8,minecraft:orange_terracotta)
B(3,1,-7,minecraft:orange_terracotta)
B(3,1,-6,minecraft:orange_terracotta)
B(3,1,-5,minecraft:orange_terracotta)
B(3,1,-4,minecraft:orange_terracotta)
B(3,1,-3,minecraft:orange_terracotta)
B(3,1,-2,minecraft:orange_terracotta)
B(3,1,-1,minecraft:orange_terracotta)
B(3,1,0,minecraft:orange_terracotta)
B(3,1,1,minecraft:orange_terracotta)
B(3,1,2,minecraft:orange_terracotta)
B(3,1,3,minecraft:orange_terracotta)
B(3,1,4,minecraft:orange_terracotta)
B(3,1,5,minecraft:orange_terracotta)
B(3,1,6,minecraft:orange_terracotta)
B(3,1,7,minecraft:orange_terracotta)
B(3,2,-8,minecraft:orange_terracotta)
B(3,2,-7,minecraft:terracotta)
B(3,2,-6,minecraft:terracotta)
B(3,2,-5,minecraft:terracotta)
B(3,2,-4,minecraft:terracotta)
B(3,2,-3,minecraft:terracotta)
B(3,2,-2,minecraft:terracotta)
B(3,2,-1,minecraft:terracotta)
B(3,2,0,minecraft:terracotta)
B(3,2,1,minecraft:terracotta)
B(3,2,2,minecraft:terracotta)
B(3,2,3,minecraft:terracotta)
B(3,2,4,minecraft:orange_terracotta)
B(3,2,5,minecraft:orange_terracotta)
B(3,2,6,minecraft:orange_terracotta)
B(3,2,7,minecraft:orange_terracotta)
B(3,3,-7,minecraft:yellow_terracotta)
B(3,3,-6,minecraft:terracotta)
B(3,3,-5,minecraft:terracotta)
B(3,3,-4,minecraft:terracotta)
B(3,3,-3,minecraft:terracotta)
B(3,3,-2,minecraft:terracotta)
B(3,3,-1,minecraft:terracotta)
B(3,3,0,minecraft:terracotta)
B(3,3,1,minecraft:terracotta)
B(3,3,2,minecraft:terracotta)
B(3,3,3,minecraft:terracotta)
B(3,3,4,minecraft:terracotta)
B(3,3,5,minecraft:orange_terracotta)
B(3,3,6,minecraft:yellow_terracotta)
B(3,4,-7,minecraft:terracotta)
B(3,4,-6,minecraft:terracotta)
B(3,4,-5,minecraft:terracotta)
B(3,4,-4,minecraft:terracotta)
B(3,4,-3,minecraft:terracotta)
B(3,4,-2,minecraft:terracotta)
B(3,4,-1,minecraft:terracotta)
B(3,4,0,minecraft:terracotta)
B(3,4,1,minecraft:terracotta)
B(3,4,2,minecraft:terracotta)
B(3,4,3,minecraft:terracotta)
B(3,4,4,minecraft:terracotta)
B(3,4,5,minecraft:yellow_terracotta)
B(3,5,-7,minecraft:terracotta)
B(3,5,-6,minecraft:terracotta)
B(3,5,-5,minecraft:terracotta)
B(3,5,-4,minecraft:terracotta)
B(3,5,-3,minecraft:terracotta)
B(3,5,-2,minecraft:terracotta)
B(3,5,-1,minecraft:terracotta)
B(3,5,0,minecraft:terracotta)
B(3,5,1,minecraft:terracotta)
B(3,5,2,minecraft:terracotta)
B(3,5,3,minecraft:terracotta)
B(3,5,4,minecraft:terracotta)
B(3,5,5,minecraft:terracotta)
B(3,6,-6,minecraft:terracotta)
B(3,6,-5,minecraft:terracotta)
B(3,6,-4,minecraft:terracotta)
B(3,6,-3,minecraft:terracotta)
B(3,6,-2,minecraft:terracotta)
B(3,6,-1,minecraft:terracotta)
B(3,6,0,minecraft:terracotta)
B(3,6,1,minecraft:terracotta)
B(3,6,2,minecraft:terracotta)
B(3,6,3,minecraft:terracotta)
B(3,6,4,minecraft:terracotta)
B(3,7,-5,minecraft:orange_terracotta)
B(3,7,-4,minecraft:orange_terracotta)
B(3,7,-3,minecraft:orange_terracotta)
B(3,7,-2,minecraft:orange_terracotta)
B(3,7,-1,minecraft:terracotta)
B(3,7,0,minecraft:terracotta)
B(3,7,1,minecraft:terracotta)
B(3,7,2,minecraft:terracotta)
B(3,7,3,minecraft:orange_terracotta)
B(3,8,-4,minecraft:terracotta)
B(3,8,-3,minecraft:terracotta)
B(3,8,-2,minecraft:terracotta)
B(3,8,-1,minecraft:terracotta)
B(3,8,0,minecraft:terracotta)
B(3,8,1,minecraft:terracotta)
B(3,8,2,minecraft:terracotta)
B(3,8,3,minecraft:terracotta)
B(3,9,-4,minecraft:terracotta)
B(3,9,-3,minecraft:terracotta)
B(3,9,-2,minecraft:terracotta)
B(3,9,-1,minecraft:terracotta)
B(3,9,0,minecraft:terracotta)
B(3,9,1,minecraft:terracotta)
B(3,9,2,minecraft:terracotta)
B(3,9,3,minecraft:terracotta)
B(3,10,-4,minecraft:orange_terracotta)
B(3,10,-3,minecraft:terracotta)
B(3,10,-2,minecraft:terracotta)
B(3,10,-1,minecraft:terracotta)
B(3,10,0,minecraft:orange_terracotta)
B(3,10,1,minecraft:terracotta)
B(3,10,2,minecraft:terracotta)
B(3,10,3,minecraft:orange_terracotta)
B(3,11,-4,minecraft:terracotta)
B(3,11,-3,minecraft:terracotta)
B(3,11,-2,minecraft:terracotta)
B(3,11,-1,minecraft:terracotta)
B(3,11,0,minecraft:terracotta)
B(3,11,1,minecraft:terracotta)
B(3,11,2,minecraft:terracotta)
B(3,11,3,minecraft:terracotta)
B(3,12,-4,minecraft:terracotta)
B(3,12,-3,minecraft:terracotta)
B(3,12,-2,minecraft:terracotta)
B(3,12,-1,minecraft:terracotta)
B(3,12,0,minecraft:terracotta)
B(3,12,1,minecraft:terracotta)
B(3,12,2,minecraft:terracotta)
B(3,12,3,minecraft:terracotta)
B(3,13,-4,minecraft:red_terracotta)
B(3,13,-3,minecraft:terracotta)
B(3,13,-2,minecraft:terracotta)
B(3,13,-1,minecraft:terracotta)
B(3,13,0,minecraft:terracotta)
B(3,13,1,minecraft:terracotta)
B(3,13,2,minecraft:terracotta)
B(3,13,3,minecraft:red_terracotta)
B(3,14,-4,minecraft:red_terracotta)
B(3,14,-3,minecraft:terracotta)
B(3,14,-2,minecraft:terracotta)
B(3,14,-1,minecraft:terracotta)
B(3,14,0,minecraft:terracotta)
B(3,14,1,minecraft:terracotta)
B(3,14,2,minecraft:terracotta)
B(3,14,3,minecraft:red_terracotta)
B(3,15,-4,minecraft:brown_terracotta)
B(3,15,-3,minecraft:terracotta)
B(3,15,-2,minecraft:terracotta)
B(3,15,-1,minecraft:terracotta)
B(3,15,0,minecraft:terracotta)
B(3,15,1,minecraft:terracotta)
B(3,15,2,minecraft:terracotta)
B(3,15,3,minecraft:brown_terracotta)
B(3,16,-4,minecraft:brown_terracotta)
B(3,16,-3,minecraft:terracotta)
B(3,16,-2,minecraft:terracotta)
B(3,16,-1,minecraft:terracotta)
B(3,16,0,minecraft:terracotta)
B(3,16,1,minecraft:terracotta)
B(3,16,2,minecraft:terracotta)
B(3,16,3,minecraft:brown_terracotta)
B(3,17,-4,minecraft:terracotta)
B(3,17,-3,minecraft:terracotta)
B(3,17,-2,minecraft:terracotta)
B(3,17,-1,minecraft:terracotta)
B(3,17,0,minecraft:terracotta)
B(3,17,1,minecraft:terracotta)
B(3,17,2,minecraft:terracotta)
B(3,17,3,minecraft:terracotta)
B(3,18,-4,minecraft:white_terracotta)
B(3,18,-3,minecraft:white_terracotta)
B(3,18,-2,minecraft:white_terracotta)
B(3,18,-1,minecraft:white_terracotta)
B(3,18,0,minecraft:white_terracotta)
B(3,18,1,minecraft:white_terracotta)
B(3,18,2,minecraft:white_terracotta)
B(3,18,3,minecraft:white_terracotta)
B(3,19,-4,minecraft:light_gray_terracotta)
B(3,19,-3,minecraft:light_gray_terracotta)
B(3,19,-2,minecraft:light_gray_terracotta)
B(3,19,-1,minecraft:light_gray_terracotta)
B(3,19,0,minecraft:light_gray_terracotta)
B(3,19,1,minecraft:light_gray_terracotta)
B(3,19,2,minecraft:light_gray_terracotta)
B(3,19,3,minecraft:light_gray_terracotta)
B(3,20,-4,minecraft:terracotta)
B(3,20,-3,minecraft:terracotta)
B(3,20,-2,minecraft:terracotta)
B(3,20,-1,minecraft:terracotta)
B(3,20,0,minecraft:terracotta)
B(3,20,1,minecraft:terracotta)
B(3,20,2,minecraft:terracotta)
B(3,20,3,minecraft:terracotta)
B(3,21,-3,minecraft:terracotta)
B(3,21,-2,minecraft:terracotta)
B(3,21,-1,minecraft:terracotta)
B(3,21,0,minecraft:terracotta)
B(3,21,1,minecraft:terracotta)
B(3,21,2,minecraft:terracotta)
B(3,21,3,minecraft:terracotta)
B(4,-5,-3,minecraft:orange_terracotta)
B(4,-5,-2,minecraft:orange_terracotta)
B(4,-5,-1,minecraft:orange_terracotta)
B(4,-5,0,minecraft:orange_terracotta)
B(4,-5,1,minecraft:orange_terracotta)
B(4,-5,2,minecraft:orange_terracotta)
B(4,-4,-4,minecraft:orange_terracotta)
B(4,-4,-3,minecraft:orange_terracotta)
B(4,-4,-2,minecraft:orange_terracotta)
B(4,-4,-1,minecraft:orange_terracotta)
B(4,-4,0,minecraft:orange_terracotta)
B(4,-4,1,minecraft:orange_terracotta)
B(4,-4,2,minecraft:orange_terracotta)
B(4,-4,3,minecraft:orange_terracotta)
B(4,-4,4,minecraft:orange_terracotta)
B(4,-3,-5,minecraft:orange_terracotta)
B(4,-3,-4,minecraft:orange_terracotta)
B(4,-3,-3,minecraft:orange_terracotta)
B(4,-3,-2,minecraft:orange_terracotta)
B(4,-3,-1,minecraft:orange_terracotta)
B(4,-3,0,minecraft:orange_terracotta)
B(4,-3,1,minecraft:orange_terracotta)
B(4,-3,2,minecraft:orange_terracotta)
B(4,-3,3,minecraft:orange_terracotta)
B(4,-3,4,minecraft:orange_terracotta)
B(4,-3,5,minecraft:orange_terracotta)
B(4,-2,-7,minecraft:orange_terracotta)
B(4,-2,-6,minecraft:orange_terracotta)
B(4,-2,-5,minecraft:orange_terracotta)
B(4,-2,-4,minecraft:orange_terracotta)
B(4,-2,-3,minecraft:orange_terracotta)
B(4,-2,-2,minecraft:orange_terracotta)
B(4,-2,-1,minecraft:orange_terracotta)
B(4,-2,0,minecraft:orange_terracotta)
B(4,-2,1,minecraft:orange_terracotta)
B(4,-2,2,minecraft:orange_terracotta)
B(4,-2,3,minecraft:orange_terracotta)
B(4,-2,4,minecraft:orange_terracotta)
B(4,-2,5,minecraft:orange_terracotta)
B(4,-1,-8,minecraft:orange_terracotta)
B(4,-1,-7,minecraft:orange_terracotta)
B(4,-1,-6,minecraft:orange_terracotta)
B(4,-1,-5,minecraft:orange_terracotta)
B(4,-1,-4,minecraft:orange_terracotta)
B(4,-1,-3,minecraft:orange_terracotta)
B(4,-1,-2,minecraft:orange_terracotta)
B(4,-1,-1,minecraft:orange_terracotta)
B(4,-1,0,minecraft:orange_terracotta)
B(4,-1,1,minecraft:orange_terracotta)
B(4,-1,2,minecraft:orange_terracotta)
B(4,-1,3,minecraft:orange_terracotta)
B(4,-1,4,minecraft:orange_terracotta)
B(4,-1,5,minecraft:orange_terracotta)
B(4,-1,6,minecraft:orange_terracotta)
B(4,0,-8,minecraft:orange_terracotta)
B(4,0,-7,minecraft:orange_terracotta)
B(4,0,-6,minecraft:orange_terracotta)
B(4,0,-5,minecraft:orange_terracotta)
B(4,0,-4,minecraft:orange_terracotta)
B(4,0,-3,minecraft:orange_terracotta)
B(4,0,-2,minecraft:orange_terracotta)
B(4,0,-1,minecraft:orange_terracotta)
B(4,0,0,minecraft:orange_terracotta)
B(4,0,1,minecraft:orange_terracotta)
B(4,0,2,minecraft:orange_terracotta)
B(4,0,3,minecraft:orange_terracotta)
B(4,0,4,minecraft:orange_terracotta)
B(4,0,5,minecraft:orange_terracotta)
B(4,0,6,minecraft:orange_terracotta)
B(4,0,7,minecraft:orange_terracotta)
B(4,1,-7,minecraft:orange_terracotta)
B(4,1,-6,minecraft:orange_terracotta)
B(4,1,-5,minecraft:orange_terracotta)
B(4,1,-4,minecraft:orange_terracotta)
B(4,1,-3,minecraft:orange_terracotta)
B(4,1,-2,minecraft:orange_terracotta)
B(4,1,-1,minecraft:orange_terracotta)
B(4,1,0,minecraft:orange_terracotta)
B(4,1,1,minecraft:orange_terracotta)
B(4,1,2,minecraft:orange_terracotta)
B(4,1,3,minecraft:orange_terracotta)
B(4,1,4,minecraft:orange_terracotta)
B(4,1,5,minecraft:orange_terracotta)
B(4,1,6,minecraft:orange_terracotta)
B(4,1,7,minecraft:orange_terracotta)
B(4,2,-7,minecraft:yellow_terracotta)
B(4,2,-6,minecraft:terracotta)
B(4,2,-5,minecraft:terracotta)
B(4,2,-4,minecraft:terracotta)
B(4,2,-3,minecraft:terracotta)
B(4,2,-2,minecraft:terracotta)
B(4,2,-1,minecraft:terracotta)
B(4,2,0,minecraft:terracotta)
B(4,2,1,minecraft:terracotta)
B(4,2,2,minecraft:terracotta)
B(4,2,3,minecraft:terracotta)
B(4,2,4,minecraft:terracotta)
B(4,2,5,minecraft:orange_terracotta)
B(4,2,6,minecraft:orange_terracotta)
B(4,2,7,minecraft:orange_terracotta)
B(4,3,-7,minecraft:yellow_terracotta)
B(4,3,-6,minecraft:terracotta)
B(4,3,-5,minecraft:terracotta)
B(4,3,-4,minecraft:terracotta)
B(4,3,-3,minecraft:terracotta)
B(4,3,-2,minecraft:terracotta)
B(4,3,-1,minecraft:terracotta)
B(4,3,0,minecraft:terracotta)
B(4,3,1,minecraft:terracotta)
B(4,3,2,minecraft:terracotta)
B(4,3,3,minecraft:terracotta)
B(4,3,4,minecraft:terracotta)
B(4,3,5,minecraft:orange_terracotta)
B(4,3,6,minecraft:orange_terracotta)
B(4,3,7,minecraft:orange_terracotta)
B(4,4,-6,minecraft:terracotta)
B(4,4,-5,minecraft:terracotta)
B(4,4,-4,minecraft:terracotta)
B(4,4,-3,minecraft:terracotta)
B(4,4,-2,minecraft:terracotta)
B(4,4,-1,minecraft:terracotta)
B(4,4,0,minecraft:terracotta)
B(4,4,1,minecraft:terracotta)
B(4,4,2,minecraft:terracotta)
B(4,4,3,minecraft:terracotta)
B(4,4,4,minecraft:terracotta)
B(4,4,5,minecraft:yellow_terracotta)
B(4,5,-6,minecraft:terracotta)
B(4,5,-5,minecraft:terracotta)
B(4,5,-4,minecraft:terracotta)
B(4,5,-3,minecraft:terracotta)
B(4,5,-2,minecraft:terracotta)
B(4,5,-1,minecraft:terracotta)
B(4,5,0,minecraft:terracotta)
B(4,5,1,minecraft:terracotta)
B(4,5,2,minecraft:terracotta)
B(4,5,3,minecraft:terracotta)
B(4,5,4,minecraft:terracotta)
B(4,6,-5,minecraft:terracotta)
B(4,6,-4,minecraft:terracotta)
B(4,6,-3,minecraft:terracotta)
B(4,6,-2,minecraft:terracotta)
B(4,6,-1,minecraft:terracotta)
B(4,6,0,minecraft:terracotta)
B(4,6,1,minecraft:terracotta)
B(4,6,2,minecraft:terracotta)
B(4,6,3,minecraft:terracotta)
B(4,7,-4,minecraft:orange_terracotta)
B(4,7,-3,minecraft:orange_terracotta)
B(4,7,-2,minecraft:terracotta)
B(4,7,-1,minecraft:terracotta)
B(4,7,0,minecraft:terracotta)
B(4,7,1,minecraft:orange_terracotta)
B(4,7,2,minecraft:terracotta)
B(4,7,3,minecraft:orange_terracotta)
B(4,8,-4,minecraft:terracotta)
B(4,8,-3,minecraft:terracotta)
B(4,8,-2,minecraft:terracotta)
B(4,8,-1,minecraft:terracotta)
B(4,8,0,minecraft:terracotta)
B(4,8,1,minecraft:terracotta)
B(4,8,2,minecraft:terracotta)
B(4,8,3,minecraft:terracotta)
B(4,9,-4,minecraft:terracotta)
B(4,9,-3,minecraft:terracotta)
B(4,9,-2,minecraft:terracotta)
B(4,9,-1,minecraft:terracotta)
B(4,9,0,minecraft:terracotta)
B(4,9,1,minecraft:terracotta)
B(4,9,2,minecraft:terracotta)
B(4,9,3,minecraft:terracotta)
B(4,10,-4,minecraft:orange_terracotta)
B(4,10,-3,minecraft:terracotta)
B(4,10,-2,minecraft:terracotta)
B(4,10,-1,minecraft:terracotta)
B(4,10,0,minecraft:orange_terracotta)
B(4,10,1,minecraft:terracotta)
B(4,10,2,minecraft:terracotta)
B(4,10,3,minecraft:orange_terracotta)
B(4,11,-4,minecraft:terracotta)
B(4,11,-3,minecraft:terracotta)
B(4,11,-2,minecraft:terracotta)
B(4,11,-1,minecraft:terracotta)
B(4,11,0,minecraft:terracotta)
B(4,11,1,minecraft:terracotta)
B(4,11,2,minecraft:terracotta)
B(4,11,3,minecraft:terracotta)
B(4,12,-4,minecraft:terracotta)
B(4,12,-3,minecraft:terracotta)
B(4,12,-2,minecraft:terracotta)
B(4,12,-1,minecraft:terracotta)
B(4,12,0,minecraft:terracotta)
B(4,12,1,minecraft:terracotta)
B(4,12,2,minecraft:terracotta)
B(4,12,3,minecraft:terracotta)
B(4,13,-4,minecraft:red_terracotta)
B(4,13,-3,minecraft:terracotta)
B(4,13,-2,minecraft:terracotta)
B(4,13,-1,minecraft:terracotta)
B(4,13,0,minecraft:terracotta)
B(4,13,1,minecraft:terracotta)
B(4,13,2,minecraft:terracotta)
B(4,13,3,minecraft:red_terracotta)
B(4,14,-4,minecraft:red_terracotta)
B(4,14,-3,minecraft:terracotta)
B(4,14,-2,minecraft:terracotta)
B(4,14,-1,minecraft:terracotta)
B(4,14,0,minecraft:terracotta)
B(4,14,1,minecraft:terracotta)
B(4,14,2,minecraft:terracotta)
B(4,14,3,minecraft:red_terracotta)
B(4,15,-4,minecraft:brown_terracotta)
B(4,15,-3,minecraft:terracotta)
B(4,15,-2,minecraft:terracotta)
B(4,15,-1,minecraft:terracotta)
B(4,15,0,minecraft:terracotta)
B(4,15,1,minecraft:terracotta)
B(4,15,2,minecraft:terracotta)
B(4,15,3,minecraft:brown_terracotta)
B(4,16,-4,minecraft:brown_terracotta)
B(4,16,-3,minecraft:terracotta)
B(4,16,-2,minecraft:terracotta)
B(4,16,-1,minecraft:terracotta)
B(4,16,0,minecraft:terracotta)
B(4,16,1,minecraft:terracotta)
B(4,16,2,minecraft:terracotta)
B(4,16,3,minecraft:brown_terracotta)
B(4,17,-4,minecraft:terracotta)
B(4,17,-3,minecraft:terracotta)
B(4,17,-2,minecraft:terracotta)
B(4,17,-1,minecraft:terracotta)
B(4,17,0,minecraft:terracotta)
B(4,17,1,minecraft:terracotta)
B(4,17,2,minecraft:terracotta)
B(4,17,3,minecraft:terracotta)
B(4,18,-4,minecraft:white_terracotta)
B(4,18,-3,minecraft:white_terracotta)
B(4,18,-2,minecraft:white_terracotta)
B(4,18,-1,minecraft:white_terracotta)
B(4,18,0,minecraft:white_terracotta)
B(4,18,1,minecraft:white_terracotta)
B(4,18,2,minecraft:white_terracotta)
B(4,18,3,minecraft:white_terracotta)
B(4,19,-4,minecraft:light_gray_terracotta)
B(4,19,-3,minecraft:light_gray_terracotta)
B(4,19,-2,minecraft:light_gray_terracotta)
B(4,19,-1,minecraft:light_gray_terracotta)
B(4,19,0,minecraft:light_gray_terracotta)
B(4,19,1,minecraft:light_gray_terracotta)
B(4,19,2,minecraft:light_gray_terracotta)
B(4,19,3,minecraft:light_gray_terracotta)
B(4,20,-4,minecraft:terracotta)
B(4,20,-3,minecraft:terracotta)
B(4,20,-2,minecraft:terracotta)
B(4,20,-1,minecraft:terracotta)
B(4,20,0,minecraft:terracotta)
B(4,20,1,minecraft:terracotta)
B(4,20,2,minecraft:terracotta)
B(4,20,3,minecraft:terracotta)
B(4,21,-3,minecraft:terracotta)
B(4,21,-2,minecraft:terracotta)
B(4,21,-1,minecraft:terracotta)
B(4,21,0,minecraft:terracotta)
B(4,21,1,minecraft:terracotta)
B(4,21,2,minecraft:terracotta)
B(4,21,3,minecraft:terracotta)
B(5,-5,-2,minecraft:orange_terracotta)
B(5,-5,-1,minecraft:orange_terracotta)
B(5,-5,0,minecraft:orange_terracotta)
B(5,-5,1,minecraft:orange_terracotta)
B(5,-5,2,minecraft:orange_terracotta)
B(5,-5,3,minecraft:orange_terracotta)
B(5,-4,-3,minecraft:orange_terracotta)
B(5,-4,-2,minecraft:orange_terracotta)
B(5,-4,-1,minecraft:orange_terracotta)
B(5,-4,0,minecraft:orange_terracotta)
B(5,-4,1,minecraft:orange_terracotta)
B(5,-4,2,minecraft:orange_terracotta)
B(5,-4,3,minecraft:orange_terracotta)
B(5,-4,4,minecraft:orange_terracotta)
B(5,-3,-4,minecraft:orange_terracotta)
B(5,-3,-3,minecraft:orange_terracotta)
B(5,-3,-2,minecraft:orange_terracotta)
B(5,-3,-1,minecraft:orange_terracotta)
B(5,-3,0,minecraft:orange_terracotta)
B(5,-3,1,minecraft:orange_terracotta)
B(5,-3,2,minecraft:orange_terracotta)
B(5,-3,3,minecraft:orange_terracotta)
B(5,-3,4,minecraft:orange_terracotta)
B(5,-2,-5,minecraft:orange_terracotta)
B(5,-2,-4,minecraft:orange_terracotta)
B(5,-2,-3,minecraft:orange_terracotta)
B(5,-2,-2,minecraft:orange_terracotta)
B(5,-2,-1,minecraft:orange_terracotta)
B(5,-2,0,minecraft:orange_terracotta)
B(5,-2,1,minecraft:orange_terracotta)
B(5,-2,2,minecraft:orange_terracotta)
B(5,-2,3,minecraft:orange_terracotta)
B(5,-2,4,minecraft:orange_terracotta)
B(5,-2,5,minecraft:orange_terracotta)
B(5,-2,6,minecraft:orange_terracotta)
B(5,-1,-7,minecraft:orange_terracotta)
B(5,-1,-6,minecraft:orange_terracotta)
B(5,-1,-5,minecraft:orange_terracotta)
B(5,-1,-4,minecraft:orange_terracotta)
B(5,-1,-3,minecraft:orange_terracotta)
B(5,-1,-2,minecraft:orange_terracotta)
B(5,-1,-1,minecraft:orange_terracotta)
B(5,-1,0,minecraft:orange_terracotta)
B(5,-1,1,minecraft:orange_terracotta)
B(5,-1,2,minecraft:orange_terracotta)
B(5,-1,3,minecraft:orange_terracotta)
B(5,-1,4,minecraft:orange_terracotta)
B(5,-1,5,minecraft:orange_terracotta)
B(5,-1,6,minecraft:orange_terracotta)
B(5,-1,7,minecraft:orange_terracotta)
B(5,0,-7,minecraft:orange_terracotta)
B(5,0,-6,minecraft:orange_terracotta)
B(5,0,-5,minecraft:orange_terracotta)
B(5,0,-4,minecraft:orange_terracotta)
B(5,0,-3,minecraft:orange_terracotta)
B(5,0,-2,minecraft:orange_terracotta)
B(5,0,-1,minecraft:orange_terracotta)
B(5,0,0,minecraft:orange_terracotta)
B(5,0,1,minecraft:orange_terracotta)
B(5,0,2,minecraft:orange_terracotta)
B(5,0,3,minecraft:orange_terracotta)
B(5,0,4,minecraft:orange_terracotta)
B(5,0,5,minecraft:orange_terracotta)
B(5,0,6,minecraft:orange_terracotta)
B(5,0,7,minecraft:orange_terracotta)
B(5,1,-6,minecraft:orange_terracotta)
B(5,1,-5,minecraft:orange_terracotta)
B(5,1,-4,minecraft:orange_terracotta)
B(5,1,-3,minecraft:orange_terracotta)
B(5,1,-2,minecraft:orange_terracotta)
B(5,1,-1,minecraft:orange_terracotta)
B(5,1,0,minecraft:orange_terracotta)
B(5,1,1,minecraft:orange_terracotta)
B(5,1,2,minecraft:orange_terracotta)
B(5,1,3,minecraft:orange_terracotta)
B(5,1,4,minecraft:orange_terracotta)
B(5,1,5,minecraft:orange_terracotta)
B(5,1,6,minecraft:orange_terracotta)
B(5,1,7,minecraft:orange_terracotta)
B(5,2,-6,minecraft:yellow_terracotta)
B(5,2,-5,minecraft:terracotta)
B(5,2,-4,minecraft:terracotta)
B(5,2,-3,minecraft:terracotta)
B(5,2,-2,minecraft:terracotta)
B(5,2,-1,minecraft:terracotta)
B(5,2,0,minecraft:terracotta)
B(5,2,1,minecraft:terracotta)
B(5,2,2,minecraft:terracotta)
B(5,2,3,minecraft:terracotta)
B(5,2,4,minecraft:terracotta)
B(5,2,5,minecraft:orange_terracotta)
B(5,2,6,minecraft:orange_terracotta)
B(5,3,-6,minecraft:yellow_terracotta)
B(5,3,-5,minecraft:terracotta)
B(5,3,-4,minecraft:terracotta)
B(5,3,-3,minecraft:terracotta)
B(5,3,-2,minecraft:terracotta)
B(5,3,-1,minecraft:terracotta)
B(5,3,0,minecraft:terracotta)
B(5,3,1,minecraft:terracotta)
B(5,3,2,minecraft:terracotta)
B(5,3,3,minecraft:terracotta)
B(5,3,4,minecraft:terracotta)
B(5,3,5,minecraft:orange_terracotta)
B(5,3,6,minecraft:orange_terracotta)
B(5,4,-6,minecraft:terracotta)
B(5,4,-5,minecraft:terracotta)
B(5,4,-4,minecraft:terracotta)
B(5,4,-3,minecraft:terracotta)
B(5,4,-2,minecraft:terracotta)
B(5,4,-1,minecraft:terracotta)
B(5,4,0,minecraft:terracotta)
B(5,4,1,minecraft:terracotta)
B(5,4,2,minecraft:terracotta)
B(5,4,3,minecraft:terracotta)
B(5,4,4,minecraft:terracotta)
B(5,5,-5,minecraft:terracotta)
B(5,5,-4,minecraft:terracotta)
B(5,5,-3,minecraft:terracotta)
B(5,5,-2,minecraft:terracotta)
B(5,5,-1,minecraft:terracotta)
B(5,5,0,minecraft:terracotta)
B(5,5,1,minecraft:terracotta)
B(5,5,2,minecraft:terracotta)
B(5,5,3,minecraft:terracotta)
B(5,5,4,minecraft:terracotta)
B(5,6,-4,minecraft:terracotta)
B(5,6,-3,minecraft:terracotta)
B(5,6,-2,minecraft:terracotta)
B(5,6,-1,minecraft:terracotta)
B(5,6,0,minecraft:terracotta)
B(5,6,1,minecraft:terracotta)
B(5,6,2,minecraft:terracotta)
B(5,6,3,minecraft:terracotta)
B(5,7,-4,minecraft:orange_terracotta)
B(5,7,-3,minecraft:orange_terracotta)
B(5,7,-2,minecraft:orange_terracotta)
B(5,7,-1,minecraft:terracotta)
B(5,7,0,minecraft:terracotta)
B(5,7,1,minecraft:orange_terracotta)
B(5,7,2,minecraft:terracotta)
B(5,7,3,minecraft:orange_terracotta)
B(5,8,-4,minecraft:terracotta)
B(5,8,-3,minecraft:terracotta)
B(5,8,-2,minecraft:terracotta)
B(5,8,-1,minecraft:terracotta)
B(5,8,0,minecraft:terracotta)
B(5,8,1,minecraft:terracotta)
B(5,8,2,minecraft:terracotta)
B(5,8,3,minecraft:terracotta)
B(5,9,-4,minecraft:terracotta)
B(5,9,-3,minecraft:terracotta)
B(5,9,-2,minecraft:terracotta)
B(5,9,-1,minecraft:terracotta)
B(5,9,0,minecraft:terracotta)
B(5,9,1,minecraft:terracotta)
B(5,9,2,minecraft:terracotta)
B(5,9,3,minecraft:terracotta)
B(5,10,-4,minecraft:orange_terracotta)
B(5,10,-3,minecraft:terracotta)
B(5,10,-2,minecraft:orange_terracotta)
B(5,10,-1,minecraft:orange_terracotta)
B(5,10,0,minecraft:orange_terracotta)
B(5,10,1,minecraft:terracotta)
B(5,10,2,minecraft:terracotta)
B(5,10,3,minecraft:orange_terracotta)
B(5,11,-4,minecraft:terracotta)
B(5,11,-3,minecraft:terracotta)
B(5,11,-2,minecraft:terracotta)
B(5,11,-1,minecraft:terracotta)
B(5,11,0,minecraft:terracotta)
B(5,11,1,minecraft:terracotta)
B(5,11,2,minecraft:terracotta)
B(5,11,3,minecraft:terracotta)
B(5,12,-4,minecraft:terracotta)
B(5,12,-3,minecraft:terracotta)
B(5,12,-2,minecraft:terracotta)
B(5,12,-1,minecraft:terracotta)
B(5,12,0,minecraft:terracotta)
B(5,12,1,minecraft:terracotta)
B(5,12,2,minecraft:terracotta)
B(5,12,3,minecraft:terracotta)
B(5,13,-4,minecraft:red_terracotta)
B(5,13,-3,minecraft:terracotta)
B(5,13,-2,minecraft:terracotta)
B(5,13,-1,minecraft:terracotta)
B(5,13,0,minecraft:terracotta)
B(5,13,1,minecraft:terracotta)
B(5,13,2,minecraft:terracotta)
B(5,13,3,minecraft:red_terracotta)
B(5,14,-4,minecraft:red_terracotta)
B(5,14,-3,minecraft:red_terracotta)
B(5,14,-2,minecraft:terracotta)
B(5,14,-1,minecraft:terracotta)
B(5,14,0,minecraft:terracotta)
B(5,14,1,minecraft:terracotta)
B(5,14,2,minecraft:terracotta)
B(5,14,3,minecraft:red_terracotta)
B(5,15,-3,minecraft:brown_terracotta)
B(5,15,-2,minecraft:brown_terracotta)
B(5,15,-1,minecraft:terracotta)
B(5,15,0,minecraft:terracotta)
B(5,15,1,minecraft:terracotta)
B(5,15,2,minecraft:terracotta)
B(5,15,3,minecraft:brown_terracotta)
B(5,16,-3,minecraft:brown_terracotta)
B(5,16,-2,minecraft:terracotta)
B(5,16,-1,minecraft:terracotta)
B(5,16,0,minecraft:terracotta)
B(5,16,1,minecraft:terracotta)
B(5,16,2,minecraft:terracotta)
B(5,16,3,minecraft:brown_terracotta)
B(5,17,-2,minecraft:terracotta)
B(5,17,-1,minecraft:terracotta)
B(5,17,0,minecraft:terracotta)
B(5,17,1,minecraft:terracotta)
B(5,17,2,minecraft:terracotta)
B(5,18,-2,minecraft:white_terracotta)
B(5,18,-1,minecraft:white_terracotta)
B(5,18,0,minecraft:white_terracotta)
B(5,18,1,minecraft:white_terracotta)
B(5,18,2,minecraft:white_terracotta)
B(5,19,-2,minecraft:light_gray_terracotta)
B(5,19,-1,minecraft:light_gray_terracotta)
B(5,19,0,minecraft:light_gray_terracotta)
B(5,19,1,minecraft:light_gray_terracotta)
B(5,19,2,minecraft:light_gray_terracotta)
B(5,20,-2,minecraft:terracotta)
B(5,20,-1,minecraft:terracotta)
B(5,20,0,minecraft:terracotta)
B(5,20,1,minecraft:terracotta)
B(5,20,2,minecraft:terracotta)
B(5,21,-2,minecraft:terracotta)
B(5,21,-1,minecraft:terracotta)
B(5,21,0,minecraft:terracotta)
B(5,21,1,minecraft:terracotta)
B(5,21,2,minecraft:terracotta)
B(6,-5,1,minecraft:orange_terracotta)
B(6,-5,2,minecraft:orange_terracotta)
B(6,-5,3,minecraft:orange_terracotta)
B(6,-4,-2,minecraft:orange_terracotta)
B(6,-4,-1,minecraft:orange_terracotta)
B(6,-4,0,minecraft:orange_terracotta)
B(6,-4,1,minecraft:orange_terracotta)
B(6,-4,2,minecraft:orange_terracotta)
B(6,-4,3,minecraft:orange_terracotta)
B(6,-4,4,minecraft:orange_terracotta)
B(6,-3,-2,minecraft:orange_terracotta)
B(6,-3,-1,minecraft:orange_terracotta)
B(6,-3,0,minecraft:orange_terracotta)
B(6,-3,1,minecraft:orange_terracotta)
B(6,-3,2,minecraft:orange_terracotta)
B(6,-3,3,minecraft:orange_terracotta)
B(6,-3,4,minecraft:orange_terracotta)
B(6,-3,5,minecraft:orange_terracotta)
B(6,-2,-6,minecraft:orange_terracotta)
B(6,-2,-5,minecraft:orange_terracotta)
B(6,-2,-4,minecraft:orange_terracotta)
B(6,-2,-3,minecraft:orange_terracotta)
B(6,-2,-2,minecraft:orange_terracotta)
B(6,-2,-1,minecraft:orange_terracotta)
B(6,-2,0,minecraft:orange_terracotta)
B(6,-2,1,minecraft:orange_terracotta)
B(6,-2,2,minecraft:orange_terracotta)
B(6,-2,3,minecraft:orange_terracotta)
B(6,-2,4,minecraft:orange_terracotta)
B(6,-2,5,minecraft:orange_terracotta)
B(6,-2,6,minecraft:orange_terracotta)
B(6,-1,-7,minecraft:orange_terracotta)
B(6,-1,-6,minecraft:orange_terracotta)
B(6,-1,-5,minecraft:orange_terracotta)
B(6,-1,-4,minecraft:orange_terracotta)
B(6,-1,-3,minecraft:orange_terracotta)
B(6,-1,-2,minecraft:orange_terracotta)
B(6,-1,-1,minecraft:orange_terracotta)
B(6,-1,0,minecraft:orange_terracotta)
B(6,-1,1,minecraft:orange_terracotta)
B(6,-1,2,minecraft:orange_terracotta)
B(6,-1,3,minecraft:orange_terracotta)
B(6,-1,4,minecraft:orange_terracotta)
B(6,-1,5,minecraft:orange_terracotta)
B(6,-1,6,minecraft:orange_terracotta)
B(6,-1,7,minecraft:orange_terracotta)
B(6,0,-7,minecraft:orange_terracotta)
B(6,0,-6,minecraft:orange_terracotta)
B(6,0,-5,minecraft:orange_terracotta)
B(6,0,-4,minecraft:orange_terracotta)
B(6,0,-3,minecraft:orange_terracotta)
B(6,0,-2,minecraft:orange_terracotta)
B(6,0,-1,minecraft:orange_terracotta)
B(6,0,0,minecraft:orange_terracotta)
B(6,0,1,minecraft:orange_terracotta)
B(6,0,2,minecraft:orange_terracotta)
B(6,0,3,minecraft:orange_terracotta)
B(6,0,4,minecraft:orange_terracotta)
B(6,0,5,minecraft:orange_terracotta)
B(6,0,6,minecraft:orange_terracotta)
B(6,0,7,minecraft:orange_terracotta)
B(6,1,-6,minecraft:orange_terracotta)
B(6,1,-5,minecraft:orange_terracotta)
B(6,1,-4,minecraft:orange_terracotta)
B(6,1,-3,minecraft:orange_terracotta)
B(6,1,-2,minecraft:orange_terracotta)
B(6,1,-1,minecraft:orange_terracotta)
B(6,1,0,minecraft:orange_terracotta)
B(6,1,1,minecraft:orange_terracotta)
B(6,1,2,minecraft:orange_terracotta)
B(6,1,3,minecraft:orange_terracotta)
B(6,1,4,minecraft:orange_terracotta)
B(6,1,5,minecraft:orange_terracotta)
B(6,1,6,minecraft:orange_terracotta)
B(6,2,-5,minecraft:yellow_terracotta)
B(6,2,-4,minecraft:terracotta)
B(6,2,-3,minecraft:terracotta)
B(6,2,-2,minecraft:terracotta)
B(6,2,-1,minecraft:terracotta)
B(6,2,0,minecraft:terracotta)
B(6,2,1,minecraft:terracotta)
B(6,2,2,minecraft:terracotta)
B(6,2,3,minecraft:terracotta)
B(6,2,4,minecraft:terracotta)
B(6,2,5,minecraft:orange_terracotta)
B(6,2,6,minecraft:orange_terracotta)
B(6,3,-5,minecraft:yellow_terracotta)
B(6,3,-4,minecraft:terracotta)
B(6,3,-3,minecraft:terracotta)
B(6,3,-2,minecraft:terracotta)
B(6,3,-1,minecraft:terracotta)
B(6,3,0,minecraft:terracotta)
B(6,3,1,minecraft:terracotta)
B(6,3,2,minecraft:terracotta)
B(6,3,3,minecraft:terracotta)
B(6,3,4,minecraft:terracotta)
B(6,3,5,minecraft:yellow_terracotta)
B(6,4,-5,minecraft:terracotta)
B(6,4,-4,minecraft:terracotta)
B(6,4,-3,minecraft:terracotta)
B(6,4,-2,minecraft:terracotta)
B(6,4,-1,minecraft:terracotta)
B(6,4,0,minecraft:terracotta)
B(6,4,1,minecraft:terracotta)
B(6,4,2,minecraft:terracotta)
B(6,4,3,minecraft:terracotta)
B(6,4,4,minecraft:terracotta)
B(6,5,-4,minecraft:terracotta)
B(6,5,-3,minecraft:terracotta)
B(6,5,-2,minecraft:terracotta)
B(6,5,-1,minecraft:terracotta)
B(6,5,0,minecraft:terracotta)
B(6,5,1,minecraft:terracotta)
B(6,5,2,minecraft:terracotta)
B(6,5,3,minecraft:terracotta)
B(6,5,4,minecraft:terracotta)
B(6,6,-4,minecraft:terracotta)
B(6,6,-3,minecraft:terracotta)
B(6,6,-2,minecraft:terracotta)
B(6,6,-1,minecraft:terracotta)
B(6,6,0,minecraft:terracotta)
B(6,6,1,minecraft:terracotta)
B(6,6,2,minecraft:terracotta)
B(6,6,3,minecraft:terracotta)
B(6,7,-4,minecraft:orange_terracotta)
B(6,7,-3,minecraft:orange_terracotta)
B(6,7,-2,minecraft:orange_terracotta)
B(6,7,-1,minecraft:orange_terracotta)
B(6,7,0,minecraft:terracotta)
B(6,7,1,minecraft:orange_terracotta)
B(6,7,2,minecraft:terracotta)
B(6,7,3,minecraft:orange_terracotta)
B(6,8,-4,minecraft:terracotta)
B(6,8,-3,minecraft:terracotta)
B(6,8,-2,minecraft:terracotta)
B(6,8,-1,minecraft:terracotta)
B(6,8,0,minecraft:terracotta)
B(6,8,1,minecraft:terracotta)
B(6,8,2,minecraft:terracotta)
B(6,8,3,minecraft:terracotta)
B(6,9,-4,minecraft:terracotta)
B(6,9,-3,minecraft:terracotta)
B(6,9,-2,minecraft:terracotta)
B(6,9,-1,minecraft:terracotta)
B(6,9,0,minecraft:terracotta)
B(6,9,1,minecraft:terracotta)
B(6,9,2,minecraft:terracotta)
B(6,9,3,minecraft:terracotta)
B(6,10,-4,minecraft:orange_terracotta)
B(6,10,-3,minecraft:orange_terracotta)
B(6,10,-2,minecraft:orange_terracotta)
B(6,10,-1,minecraft:orange_terracotta)
B(6,10,0,minecraft:orange_terracotta)
B(6,10,1,minecraft:terracotta)
B(6,10,2,minecraft:orange_terracotta)
B(6,10,3,minecraft:orange_terracotta)
B(6,11,-4,minecraft:terracotta)
B(6,11,-3,minecraft:terracotta)
B(6,11,-2,minecraft:terracotta)
B(6,11,-1,minecraft:terracotta)
B(6,11,0,minecraft:terracotta)
B(6,11,1,minecraft:terracotta)
B(6,11,2,minecraft:terracotta)
B(6,11,3,minecraft:terracotta)
B(6,12,-3,minecraft:terracotta)
B(6,12,-2,minecraft:terracotta)
B(6,12,-1,minecraft:terracotta)
B(6,12,0,minecraft:terracotta)
B(6,12,1,minecraft:terracotta)
B(6,12,2,minecraft:terracotta)
B(6,12,3,minecraft:terracotta)
B(6,13,-3,minecraft:red_terracotta)
B(6,13,-2,minecraft:terracotta)
B(6,13,-1,minecraft:red_terracotta)
B(6,13,0,minecraft:red_terracotta)
B(6,13,1,minecraft:red_terracotta)
B(6,13,2,minecraft:red_terracotta)
B(6,14,-2,minecraft:terracotta)
B(6,14,-1,minecraft:red_terracotta)
B(6,14,0,minecraft:red_terracotta)
B(6,14,1,minecraft:red_terracotta)
B(6,14,2,minecraft:red_terracotta)
B(6,15,-2,minecraft:terracotta)
B(6,15,-1,minecraft:brown_terracotta)
B(6,15,0,minecraft:brown_terracotta)
B(6,15,1,minecraft:brown_terracotta)
B(6,15,2,minecraft:brown_terracotta)
B(6,16,-2,minecraft:terracotta)
B(6,16,-1,minecraft:brown_terracotta)
B(6,16,0,minecraft:brown_terracotta)
B(6,16,1,minecraft:brown_terracotta)
B(6,16,2,minecraft:brown_terracotta)
B(6,17,-2,minecraft:terracotta)
B(6,17,-1,minecraft:terracotta)
B(6,17,0,minecraft:terracotta)
B(6,17,1,minecraft:terracotta)
B(6,17,2,minecraft:terracotta)
B(6,18,-2,minecraft:terracotta)
B(6,18,-1,minecraft:white_terracotta)
B(6,18,0,minecraft:white_terracotta)
B(6,18,1,minecraft:white_terracotta)
B(6,18,2,minecraft:white_terracotta)
B(6,19,-2,minecraft:terracotta)
B(6,19,-1,minecraft:light_gray_terracotta)
B(6,19,0,minecraft:light_gray_terracotta)
B(6,19,1,minecraft:light_gray_terracotta)
B(6,19,2,minecraft:light_gray_terracotta)
B(6,20,-2,minecraft:terracotta)
B(6,20,-1,minecraft:terracotta)
B(6,20,0,minecraft:terracotta)
B(6,20,1,minecraft:terracotta)
B(6,20,2,minecraft:terracotta)
B(6,21,-1,minecraft:terracotta)
B(6,21,0,minecraft:terracotta)
B(6,21,1,minecraft:terracotta)
B(6,21,2,minecraft:terracotta)
B(7,-4,0,minecraft:orange_terracotta)
B(7,-4,1,minecraft:orange_terracotta)
B(7,-4,2,minecraft:orange_terracotta)
B(7,-3,-2,minecraft:orange_terracotta)
B(7,-3,-1,minecraft:orange_terracotta)
B(7,-3,0,minecraft:orange_terracotta)
B(7,-3,1,minecraft:orange_terracotta)
B(7,-3,2,minecraft:orange_terracotta)
B(7,-3,3,minecraft:orange_terracotta)
B(7,-3,4,minecraft:orange_terracotta)
B(7,-3,5,minecraft:orange_terracotta)
B(7,-2,-4,minecraft:orange_terracotta)
B(7,-2,-3,minecraft:orange_terracotta)
B(7,-2,-2,minecraft:orange_terracotta)
B(7,-2,-1,minecraft:orange_terracotta)
B(7,-2,0,minecraft:orange_terracotta)
B(7,-2,1,minecraft:orange_terracotta)
B(7,-2,2,minecraft:orange_terracotta)
B(7,-2,3,minecraft:orange_terracotta)
B(7,-2,4,minecraft:orange_terracotta)
B(7,-2,5,minecraft:orange_terracotta)
B(7,-1,-5,minecraft:orange_terracotta)
B(7,-1,-4,minecraft:orange_terracotta)
B(7,-1,-3,minecraft:orange_terracotta)
B(7,-1,-2,minecraft:orange_terracotta)
B(7,-1,-1,minecraft:orange_terracotta)
B(7,-1,0,minecraft:orange_terracotta)
B(7,-1,1,minecraft:orange_terracotta)
B(7,-1,2,minecraft:orange_terracotta)
B(7,-1,3,minecraft:orange_terracotta)
B(7,-1,4,minecraft:orange_terracotta)
B(7,-1,5,minecraft:orange_terracotta)
B(7,-1,6,minecraft:orange_terracotta)
B(7,0,-5,minecraft:orange_terracotta)
B(7,0,-4,minecraft:orange_terracotta)
B(7,0,-3,minecraft:orange_terracotta)
B(7,0,-2,minecraft:orange_terracotta)
B(7,0,-1,minecraft:orange_terracotta)
B(7,0,0,minecraft:orange_terracotta)
B(7,0,1,minecraft:orange_terracotta)
B(7,0,2,minecraft:orange_terracotta)
B(7,0,3,minecraft:orange_terracotta)
B(7,0,4,minecraft:orange_terracotta)
B(7,0,5,minecraft:orange_terracotta)
B(7,0,6,minecraft:orange_terracotta)
B(7,0,7,minecraft:orange_terracotta)
B(7,1,-5,minecraft:orange_terracotta)
B(7,1,-4,minecraft:orange_terracotta)
B(7,1,-3,minecraft:orange_terracotta)
B(7,1,-2,minecraft:orange_terracotta)
B(7,1,-1,minecraft:orange_terracotta)
B(7,1,0,minecraft:orange_terracotta)
B(7,1,1,minecraft:orange_terracotta)
B(7,1,2,minecraft:orange_terracotta)
B(7,1,3,minecraft:orange_terracotta)
B(7,1,4,minecraft:orange_terracotta)
B(7,1,5,minecraft:orange_terracotta)
B(7,1,6,minecraft:orange_terracotta)
B(7,2,-5,minecraft:yellow_terracotta)
B(7,2,-4,minecraft:yellow_terracotta)
B(7,2,-3,minecraft:terracotta)
B(7,2,-2,minecraft:terracotta)
B(7,2,-1,minecraft:terracotta)
B(7,2,0,minecraft:terracotta)
B(7,2,1,minecraft:terracotta)
B(7,2,2,minecraft:terracotta)
B(7,2,3,minecraft:terracotta)
B(7,2,4,minecraft:terracotta)
B(7,2,5,minecraft:yellow_terracotta)
B(7,3,-4,minecraft:yellow_terracotta)
B(7,3,-3,minecraft:terracotta)
B(7,3,-2,minecraft:terracotta)
B(7,3,-1,minecraft:terracotta)
B(7,3,0,minecraft:terracotta)
B(7,3,1,minecraft:terracotta)
B(7,3,2,minecraft:terracotta)
B(7,3,3,minecraft:terracotta)
B(7,3,5,minecraft:yellow_terracotta)
B(7,4,-4,minecraft:terracotta)
B(7,4,-3,minecraft:terracotta)
B(7,4,-2,minecraft:terracotta)
B(7,4,-1,minecraft:terracotta)
B(7,4,0,minecraft:terracotta)
B(7,4,1,minecraft:terracotta)
B(7,4,2,minecraft:terracotta)
B(7,4,3,minecraft:terracotta)
B(7,4,4,minecraft:terracotta)
B(7,5,-4,minecraft:terracotta)
B(7,5,-3,minecraft:terracotta)
B(7,5,-2,minecraft:terracotta)
B(7,5,-1,minecraft:terracotta)
B(7,5,0,minecraft:terracotta)
B(7,5,1,minecraft:terracotta)
B(7,5,2,minecraft:terracotta)
B(7,5,3,minecraft:terracotta)
B(7,5,4,minecraft:terracotta)
B(7,6,-4,minecraft:terracotta)
B(7,6,-3,minecraft:terracotta)
B(7,6,-2,minecraft:terracotta)
B(7,6,-1,minecraft:terracotta)
B(7,6,0,minecraft:terracotta)
B(7,6,1,minecraft:terracotta)
B(7,6,2,minecraft:terracotta)
B(7,6,3,minecraft:terracotta)
B(7,7,-3,minecraft:orange_terracotta)
B(7,7,-2,minecraft:orange_terracotta)
B(7,7,-1,minecraft:orange_terracotta)
B(7,7,0,minecraft:orange_terracotta)
B(7,7,1,minecraft:orange_terracotta)
B(7,7,2,minecraft:orange_terracotta)
B(7,7,3,minecraft:orange_terracotta)
B(7,8,-2,minecraft:terracotta)
B(7,8,-1,minecraft:terracotta)
B(7,8,0,minecraft:terracotta)
B(7,8,1,minecraft:terracotta)
B(7,8,2,minecraft:terracotta)
B(7,9,-2,minecraft:terracotta)
B(7,9,-1,minecraft:terracotta)
B(7,9,0,minecraft:terracotta)
B(7,9,1,minecraft:terracotta)
B(7,9,2,minecraft:terracotta)
B(7,10,-2,minecraft:orange_terracotta)
B(7,10,-1,minecraft:orange_terracotta)
B(7,10,0,minecraft:orange_terracotta)
B(7,10,1,minecraft:orange_terracotta)
B(7,11,-2,minecraft:terracotta)
B(7,11,-1,minecraft:terracotta)
B(7,11,0,minecraft:terracotta)
B(7,12,-1,minecraft:terracotta)
B(8,-3,-1,minecraft:orange_terracotta)
B(8,-3,0,minecraft:orange_terracotta)
B(8,-3,1,minecraft:orange_terracotta)
B(8,-3,4,minecraft:orange_terracotta)
B(8,-2,-2,minecraft:orange_terracotta)
B(8,-2,-1,minecraft:orange_terracotta)
B(8,-2,0,minecraft:orange_terracotta)
B(8,-2,1,minecraft:orange_terracotta)
B(8,-2,2,minecraft:orange_terracotta)
B(8,-2,3,minecraft:orange_terracotta)
B(8,-2,4,minecraft:orange_terracotta)
B(8,-2,5,minecraft:orange_terracotta)
B(8,-2,6,minecraft:orange_terracotta)
B(8,-1,-4,minecraft:orange_terracotta)
B(8,-1,-3,minecraft:orange_terracotta)
B(8,-1,-2,minecraft:orange_terracotta)
B(8,-1,-1,minecraft:orange_terracotta)
B(8,-1,0,minecraft:orange_terracotta)
B(8,-1,1,minecraft:orange_terracotta)
B(8,-1,2,minecraft:orange_terracotta)
B(8,-1,3,minecraft:orange_terracotta)
B(8,-1,4,minecraft:orange_terracotta)
B(8,-1,5,minecraft:orange_terracotta)
B(8,-1,6,minecraft:orange_terracotta)
B(8,0,-4,minecraft:orange_terracotta)
B(8,0,-3,minecraft:orange_terracotta)
B(8,0,-2,minecraft:orange_terracotta)
B(8,0,-1,minecraft:orange_terracotta)
B(8,0,0,minecraft:orange_terracotta)
B(8,0,1,minecraft:orange_terracotta)
B(8,0,2,minecraft:orange_terracotta)
B(8,0,3,minecraft:orange_terracotta)
B(8,0,4,minecraft:orange_terracotta)
B(8,0,5,minecraft:orange_terracotta)
B(8,0,6,minecraft:orange_terracotta)
B(8,1,-4,minecraft:orange_terracotta)
B(8,1,-3,minecraft:orange_terracotta)
B(8,1,-2,minecraft:orange_terracotta)
B(8,1,-1,minecraft:orange_terracotta)
B(8,1,0,minecraft:orange_terracotta)
B(8,1,1,minecraft:orange_terracotta)
B(8,1,2,minecraft:orange_terracotta)
B(8,1,3,minecraft:orange_terracotta)
B(8,1,4,minecraft:orange_terracotta)
B(8,1,5,minecraft:orange_terracotta)
B(8,2,-3,minecraft:yellow_terracotta)
B(8,2,-2,minecraft:terracotta)
B(8,2,-1,minecraft:terracotta)
B(8,2,0,minecraft:terracotta)
B(8,2,1,minecraft:terracotta)
B(8,2,2,minecraft:terracotta)
B(8,2,3,minecraft:yellow_terracotta)
B(8,2,4,minecraft:yellow_terracotta)
B(8,3,-3,minecraft:yellow_terracotta)
B(8,3,-2,minecraft:terracotta)
B(8,3,-1,minecraft:terracotta)
B(8,3,0,minecraft:terracotta)
B(8,3,1,minecraft:terracotta)
B(8,3,2,minecraft:terracotta)
B(8,3,3,minecraft:yellow_terracotta)
B(8,3,4,minecraft:yellow_terracotta)
B(8,4,-2,minecraft:terracotta)
B(8,4,-1,minecraft:terracotta)
B(8,4,0,minecraft:terracotta)
B(8,4,1,minecraft:terracotta)
B(8,4,2,minecraft:terracotta)
B(8,5,-2,minecraft:terracotta)
B(8,5,-1,minecraft:terracotta)
B(8,5,0,minecraft:terracotta)
B(8,5,1,minecraft:terracotta)
B(8,5,2,minecraft:terracotta)
B(8,6,-1,minecraft:terracotta)
B(8,6,0,minecraft:terracotta)
B(8,7,-1,minecraft:orange_terracotta)
B(8,7,0,minecraft:orange_terracotta)
B(8,8,-1,minecraft:terracotta)
B(9,-2,-1,minecraft:orange_terracotta)
B(9,-2,0,minecraft:orange_terracotta)
B(9,-2,1,minecraft:orange_terracotta)
B(9,-2,2,minecraft:orange_terracotta)
B(9,-2,3,minecraft:orange_terracotta)
B(9,-1,-3,minecraft:orange_terracotta)
B(9,-1,-2,minecraft:orange_terracotta)
B(9,-1,-1,minecraft:orange_terracotta)
B(9,-1,0,minecraft:orange_terracotta)
B(9,-1,1,minecraft:orange_terracotta)
B(9,-1,2,minecraft:orange_terracotta)
B(9,-1,3,minecraft:orange_terracotta)
B(9,-1,4,minecraft:orange_terracotta)
B(9,-1,5,minecraft:orange_terracotta)
B(9,0,-4,minecraft:orange_terracotta)
B(9,0,-3,minecraft:orange_terracotta)
B(9,0,-2,minecraft:orange_terracotta)
B(9,0,-1,minecraft:orange_terracotta)
B(9,0,0,minecraft:orange_terracotta)
B(9,0,1,minecraft:orange_terracotta)
B(9,0,2,minecraft:orange_terracotta)
B(9,0,3,minecraft:orange_terracotta)
B(9,0,4,minecraft:orange_terracotta)
B(9,0,5,minecraft:orange_terracotta)
B(9,1,-3,minecraft:orange_terracotta)
B(9,1,-2,minecraft:yellow_terracotta)
B(9,1,-1,minecraft:orange_terracotta)
B(9,1,0,minecraft:orange_terracotta)
B(9,1,1,minecraft:orange_terracotta)
B(9,1,2,minecraft:orange_terracotta)
B(9,1,3,minecraft:orange_terracotta)
B(9,2,-3,minecraft:yellow_terracotta)
B(9,2,-2,minecraft:yellow_terracotta)
B(9,2,-1,minecraft:yellow_terracotta)
B(9,2,0,minecraft:yellow_terracotta)
B(9,2,1,minecraft:yellow_terracotta)
B(9,2,2,minecraft:yellow_terracotta)
B(9,3,-2,minecraft:yellow_terracotta)
B(9,3,-1,minecraft:terracotta)
B(9,3,0,minecraft:terracotta)
B(9,3,1,minecraft:yellow_terracotta)
B(9,3,2,minecraft:yellow_terracotta)
B(9,4,-1,minecraft:terracotta)
B(9,4,0,minecraft:terracotta)
B(9,5,0,minecraft:terracotta)
B(10,-2,-1,minecraft:orange_terracotta)
B(10,-1,-2,minecraft:orange_terracotta)
B(10,-1,-1,minecraft:orange_terracotta)
B(10,-1,0,minecraft:orange_terracotta)
B(10,-1,1,minecraft:orange_terracotta)
B(10,-1,3,minecraft:orange_terracotta)
B(10,0,-3,minecraft:orange_terracotta)
B(10,0,-2,minecraft:orange_terracotta)
B(10,0,-1,minecraft:orange_terracotta)
B(10,0,0,minecraft:orange_terracotta)
B(10,0,1,minecraft:orange_terracotta)
B(10,0,2,minecraft:orange_terracotta)
B(10,0,3,minecraft:orange_terracotta)
B(10,0,4,minecraft:orange_terracotta)
B(10,1,-2,minecraft:orange_terracotta)
B(10,1,-1,minecraft:orange_terracotta)
B(10,1,0,minecraft:orange_terracotta)
B(10,2,-1,minecraft:yellow_terracotta)

#######################################################################
# +-----------------------------------------------------------------+ #
# |                            BO3 checks                           | #
# +-----------------------------------------------------------------+ #
#######################################################################


#######################################################################
# +-----------------------------------------------------------------+ #
# |                             Branches                            | #
# +-----------------------------------------------------------------+ #
#######################################################################


#######################################################################
# +-----------------------------------------------------------------+ #
# |                             Entities                            | #
# +-----------------------------------------------------------------+ #
#######################################################################

