
#######################################################################
# +-----------------------------------------------------------------+ #
# |                            BO3 object                           | #
# +-----------------------------------------------------------------+ #
#######################################################################

# This is the config file of a custom object.
# If you add this object correctly to your BiomeConfigs, it will spawn in the world.

# This is the creator of this BO3 object
Author: Unknown

# A short description of this BO3 object
Description: This BO3 was converted from a schematic using OTGEdit. The author and description information of the schematic could not be found. If you know who the author of the schematic is then please add this information.

# The BO3 version, don't change this! It can be used by external applications to do a version check.
Version: 3

# The settings mode, WriteAll, WriteWithoutComments or WriteDisable. See WorldConfig.
SettingsMode: WriteAll


#######################################################################
# +-----------------------------------------------------------------+ #
# |                          Main settings                          | #
# +-----------------------------------------------------------------+ #
#######################################################################

# This needs to be set to true to spawn the object in the Tree and Sapling resources.
Tree: true

# The frequency of the BO3 from 1 to 200. Tries this many times to spawn this BO3 when using the CustomObject(...) resource.
# Ignored by Tree(..), Sapling(..) and CustomStructure(..)
Frequency: 40

# The rarity of the BO3 from 0 to 100. Each spawn attempt has rarity% chance to succeed when using the CustomObject(...) resource.
# Ignored by Tree(..), Sapling(..) and CustomStructure(..)
Rarity: 100.0

# If you set this to true, the BO3 will be placed with a random rotation.
RotateRandomly: true

# The spawn height of the BO3: randomY, highestBlock or highestSolidBlock.
SpawnHeight: randomY

# The offset from the spawn height to spawn this BO3
# Ex. SpawnHeight = highestSolidBlock, SpawnHeightOffset = 3; This object will spawn 3 blocks above the highest solid block
SpawnHeightOffset: 0

# A random amount to offset the spawn location from the spawn offset height
# Ex. SpawnHeightOffset = 3, SpawnHeightVariance = 3; This object will spawn 3 to 6 blocks above the original spot it would have spawned
SpawnHeightVariance: 0

##############################
# Height Limits for the BO3. #
##############################

# When in randomY mode used as the minimum Y or in atMinY mode as the actual Y to spawn this BO3 at.
MinHeight: 63

# When in randomY mode used as the maximum Y to spawn this BO3 at.
MaxHeight: 255

######################
# Extrusion settings #
######################

# The style of extrusion you wish to use - BottomDown, TopUp, None (Default)
ExtrudeMode: None

# The blocks to extrude your BO3 through
ExtrudeThroughBlocks: minecraft:air

# Objects can have other objects attacthed to it: branches. Branches can also
# have branches attached to it, which can also have branches, etc. This is the
# maximum branch depth for this objects.
MaxBranchDepth: 10

# When spawned with the UseWorld keyword, this BO3 should NOT spawn in the following biomes.
# If you write the BO3 name directly in the BiomeConfigs, this will be ignored.
ExcludedBiomes: All


#######################################################################
# +-----------------------------------------------------------------+ #
# |                      Source block settings                      | #
# +-----------------------------------------------------------------+ #
#######################################################################

# The block(s) the BO3 should spawn in.
SourceBlocks: minecraft:air,minecraft:grass_block,minecraft:dirt

# The maximum percentage of the BO3 that can be outside the SourceBlock.
# The BO3 won't be placed on a location with more blocks outside the SourceBlock than this percentage.
MaxPercentageOutsideSourceBlock: 5

# What to do when a block is about to be placed outside the SourceBlock? (dontPlace, placeAnyway)
OutsideSourceBlock: dontPlace

# Disable doReplaceBlocks to make this BO3 ignore any ReplacedBlocks settings in biome configs, improves performance.
DoReplaceBlocks: true

# OTG+ settings #
# Legacy setting, rename this file to .BO4 instead. Set this to true to enable the advanced customstructure features of OTG+.
IsOTGPlus: false


#######################################################################
# +-----------------------------------------------------------------+ #
# |                              Blocks                             | #
# +-----------------------------------------------------------------+ #
#######################################################################

# All the blocks used in the BO3 are listed here. Possible blocks:
# Block(x,y,z,id[.data][,nbtfile.nbt)
# RandomBlock(x,y,z,id[:data][,nbtfile.nbt],chance[,id[:data][,nbtfile.nbt],chance[,...]])
#  So RandomBlock(0,0,0,CHEST,chest.nbt,50,CHEST,anotherchest.nbt,100) will spawn a chest at
#  the BO3 origin, and give it a 50% chance to have the contents of chest.nbt, or, if that
#  fails, a 100% percent chance to have the contents of anotherchest.nbt.
# *Note: Unlike Entity() and Spawner(), for Block() .txt files don't work, only .nbt files work.
# MinecraftObject(x,y,z,name) (TODO: This may not work anymore and needs to be tested.
#  Spawns an object in the Mojang NBT structure format. For example, 
#  MinecraftObject(0,0,0,minecraft:igloo/igloo_bottom)
#  spawns the bottom part of an igloo.
B(-3,22,0,biomesoplenty:redwood_leaves[distance=1,persistent=false])
B(-3,22,2,biomesoplenty:redwood_leaves[distance=1,persistent=false])
B(-3,22,3,biomesoplenty:redwood_leaves[distance=1,persistent=false])
B(-3,22,4,biomesoplenty:redwood_leaves[distance=1,persistent=false])
B(-3,23,2,biomesoplenty:redwood_leaves[distance=1,persistent=false])
B(-3,23,3,biomesoplenty:redwood_leaves[distance=1,persistent=false])
B(-3,24,1,biomesoplenty:redwood_leaves[distance=1,persistent=false])
B(-3,24,2,biomesoplenty:redwood_leaves[distance=1,persistent=false])
B(-3,24,3,biomesoplenty:redwood_leaves[distance=1,persistent=false])
B(-3,24,4,biomesoplenty:redwood_leaves[distance=1,persistent=false])
B(-3,25,0,biomesoplenty:redwood_leaves[distance=1,persistent=false])
B(-3,25,2,biomesoplenty:redwood_leaves[distance=1,persistent=false])
B(-3,25,3,biomesoplenty:redwood_leaves[distance=1,persistent=false])
B(-3,25,4,biomesoplenty:redwood_leaves[distance=1,persistent=false])
B(-3,26,0,biomesoplenty:redwood_leaves[distance=1,persistent=false])
B(-3,26,2,biomesoplenty:redwood_leaves[distance=1,persistent=false])
B(-3,26,3,biomesoplenty:redwood_leaves[distance=1,persistent=false])
B(-3,26,4,biomesoplenty:redwood_leaves[distance=1,persistent=false])
B(-3,29,0,biomesoplenty:redwood_leaves[distance=1,persistent=false])
B(-3,29,3,biomesoplenty:redwood_leaves[distance=1,persistent=false])
B(-3,30,0,biomesoplenty:redwood_leaves[distance=1,persistent=false])
B(-3,30,1,biomesoplenty:redwood_leaves[distance=1,persistent=false])
B(-3,30,2,biomesoplenty:redwood_leaves[distance=1,persistent=false])
B(-3,30,4,biomesoplenty:redwood_leaves[distance=1,persistent=false])
B(-3,31,0,biomesoplenty:redwood_leaves[distance=1,persistent=false])
B(-3,31,1,biomesoplenty:redwood_leaves[distance=1,persistent=false])
B(-3,31,2,biomesoplenty:redwood_leaves[distance=1,persistent=false])
B(-3,31,3,biomesoplenty:redwood_leaves[distance=1,persistent=false])
B(-3,31,4,biomesoplenty:redwood_leaves[distance=1,persistent=false])
B(-3,32,1,biomesoplenty:redwood_leaves[distance=1,persistent=false])
B(-3,32,2,biomesoplenty:redwood_leaves[distance=1,persistent=false])
B(-3,32,3,biomesoplenty:redwood_leaves[distance=1,persistent=false])
B(-3,32,4,biomesoplenty:redwood_leaves[distance=1,persistent=false])
B(-3,33,1,biomesoplenty:redwood_leaves[distance=1,persistent=false])
B(-3,33,3,biomesoplenty:redwood_leaves[distance=1,persistent=false])
B(-3,36,2,biomesoplenty:redwood_leaves[distance=1,persistent=false])
B(-3,36,4,biomesoplenty:redwood_leaves[distance=1,persistent=false])
B(-3,37,0,biomesoplenty:redwood_leaves[distance=1,persistent=false])
B(-3,37,1,biomesoplenty:redwood_leaves[distance=1,persistent=false])
B(-3,37,3,biomesoplenty:redwood_leaves[distance=1,persistent=false])
B(-3,37,4,biomesoplenty:redwood_leaves[distance=1,persistent=false])
B(-3,38,0,biomesoplenty:redwood_leaves[distance=1,persistent=false])
B(-3,38,1,biomesoplenty:redwood_leaves[distance=1,persistent=false])
B(-3,38,2,biomesoplenty:redwood_leaves[distance=1,persistent=false])
B(-3,38,3,biomesoplenty:redwood_leaves[distance=1,persistent=false])
B(-3,39,1,biomesoplenty:redwood_leaves[distance=1,persistent=false])
B(-3,39,2,biomesoplenty:redwood_leaves[distance=1,persistent=false])
B(-3,39,4,biomesoplenty:redwood_leaves[distance=1,persistent=false])
B(-3,40,2,biomesoplenty:redwood_leaves[distance=1,persistent=false])
B(-3,40,3,biomesoplenty:redwood_leaves[distance=1,persistent=false])
B(-3,40,4,biomesoplenty:redwood_leaves[distance=1,persistent=false])
B(-2,0,0,biomesoplenty:redwood_log)
B(-2,0,2,biomesoplenty:redwood_log)
B(-2,22,-1,biomesoplenty:redwood_leaves[distance=1,persistent=false])
B(-2,22,0,biomesoplenty:redwood_leaves[distance=1,persistent=false])
B(-2,22,1,biomesoplenty:redwood_leaves[distance=1,persistent=false])
B(-2,22,2,biomesoplenty:redwood_leaves[distance=1,persistent=false])
B(-2,22,3,biomesoplenty:redwood_leaves[distance=1,persistent=false])
B(-2,22,4,biomesoplenty:redwood_leaves[distance=1,persistent=false])
B(-2,23,-1,biomesoplenty:redwood_leaves[distance=1,persistent=false])
B(-2,23,0,biomesoplenty:redwood_leaves[distance=1,persistent=false])
B(-2,23,1,biomesoplenty:redwood_leaves[distance=1,persistent=false])
B(-2,23,2,biomesoplenty:redwood_leaves[distance=1,persistent=false])
B(-2,23,3,biomesoplenty:redwood_leaves[distance=1,persistent=false])
B(-2,23,4,biomesoplenty:redwood_leaves[distance=1,persistent=false])
B(-2,23,5,biomesoplenty:redwood_leaves[distance=1,persistent=false])
B(-2,23,6,biomesoplenty:redwood_leaves[distance=1,persistent=false])
B(-2,24,0,biomesoplenty:redwood_leaves[distance=1,persistent=false])
B(-2,24,1,biomesoplenty:redwood_leaves[distance=1,persistent=false])
B(-2,24,2,biomesoplenty:redwood_leaves[distance=1,persistent=false])
B(-2,24,3,biomesoplenty:redwood_leaves[distance=1,persistent=false])
B(-2,24,4,biomesoplenty:redwood_leaves[distance=1,persistent=false])
B(-2,24,5,biomesoplenty:redwood_leaves[distance=1,persistent=false])
B(-2,25,0,biomesoplenty:redwood_leaves[distance=1,persistent=false])
B(-2,25,1,biomesoplenty:redwood_leaves[distance=1,persistent=false])
B(-2,25,2,biomesoplenty:redwood_leaves[distance=1,persistent=false])
B(-2,25,3,biomesoplenty:redwood_leaves[distance=1,persistent=false])
B(-2,25,4,biomesoplenty:redwood_leaves[distance=1,persistent=false])
B(-2,25,5,biomesoplenty:redwood_leaves[distance=1,persistent=false])
B(-2,26,-1,biomesoplenty:redwood_leaves[distance=1,persistent=false])
B(-2,26,0,biomesoplenty:redwood_leaves[distance=1,persistent=false])
B(-2,26,1,biomesoplenty:redwood_leaves[distance=1,persistent=false])
B(-2,26,2,biomesoplenty:redwood_leaves[distance=1,persistent=false])
B(-2,26,3,biomesoplenty:redwood_leaves[distance=1,persistent=false])
B(-2,26,4,biomesoplenty:redwood_leaves[distance=1,persistent=false])
B(-2,26,6,biomesoplenty:redwood_leaves[distance=1,persistent=false])
B(-2,29,-1,biomesoplenty:redwood_leaves[distance=1,persistent=false])
B(-2,29,0,biomesoplenty:redwood_leaves[distance=1,persistent=false])
B(-2,29,1,biomesoplenty:redwood_leaves[distance=1,persistent=false])
B(-2,29,2,biomesoplenty:redwood_leaves[distance=1,persistent=false])
B(-2,29,3,biomesoplenty:redwood_leaves[distance=1,persistent=false])
B(-2,29,4,biomesoplenty:redwood_leaves[distance=1,persistent=false])
B(-2,30,-1,biomesoplenty:redwood_leaves[distance=1,persistent=false])
B(-2,30,0,biomesoplenty:redwood_leaves[distance=1,persistent=false])
B(-2,30,1,biomesoplenty:redwood_leaves[distance=1,persistent=false])
B(-2,30,2,biomesoplenty:redwood_leaves[distance=1,persistent=false])
B(-2,30,3,biomesoplenty:redwood_leaves[distance=1,persistent=false])
B(-2,30,4,biomesoplenty:redwood_leaves[distance=1,persistent=false])
B(-2,30,5,biomesoplenty:redwood_leaves[distance=1,persistent=false])
B(-2,31,0,biomesoplenty:redwood_leaves[distance=1,persistent=false])
B(-2,31,1,biomesoplenty:redwood_leaves[distance=1,persistent=false])
B(-2,31,2,biomesoplenty:redwood_leaves[distance=1,persistent=false])
B(-2,31,3,biomesoplenty:redwood_leaves[distance=1,persistent=false])
B(-2,31,4,biomesoplenty:redwood_leaves[distance=1,persistent=false])
B(-2,32,-1,biomesoplenty:redwood_leaves[distance=1,persistent=false])
B(-2,32,0,biomesoplenty:redwood_leaves[distance=1,persistent=false])
B(-2,32,1,biomesoplenty:redwood_leaves[distance=1,persistent=false])
B(-2,32,2,biomesoplenty:redwood_leaves[distance=1,persistent=false])
B(-2,32,3,biomesoplenty:redwood_leaves[distance=1,persistent=false])
B(-2,32,4,biomesoplenty:redwood_leaves[distance=1,persistent=false])
B(-2,32,5,biomesoplenty:redwood_leaves[distance=1,persistent=false])
B(-2,33,0,biomesoplenty:redwood_leaves[distance=1,persistent=false])
B(-2,33,1,biomesoplenty:redwood_leaves[distance=1,persistent=false])
B(-2,33,2,biomesoplenty:redwood_leaves[distance=1,persistent=false])
B(-2,33,3,biomesoplenty:redwood_leaves[distance=1,persistent=false])
B(-2,33,4,biomesoplenty:redwood_leaves[distance=1,persistent=false])
B(-2,33,5,biomesoplenty:redwood_leaves[distance=1,persistent=false])
B(-2,36,-1,biomesoplenty:redwood_leaves[distance=1,persistent=false])
B(-2,36,0,biomesoplenty:redwood_leaves[distance=1,persistent=false])
B(-2,36,1,biomesoplenty:redwood_leaves[distance=1,persistent=false])
B(-2,36,2,biomesoplenty:redwood_leaves[distance=1,persistent=false])
B(-2,36,3,biomesoplenty:redwood_leaves[distance=1,persistent=false])
B(-2,36,4,biomesoplenty:redwood_leaves[distance=1,persistent=false])
B(-2,36,5,biomesoplenty:redwood_leaves[distance=1,persistent=false])
B(-2,37,0,biomesoplenty:redwood_leaves[distance=1,persistent=false])
B(-2,37,1,biomesoplenty:redwood_leaves[distance=1,persistent=false])
B(-2,37,2,biomesoplenty:redwood_leaves[distance=1,persistent=false])
B(-2,37,3,biomesoplenty:redwood_leaves[distance=1,persistent=false])
B(-2,37,4,biomesoplenty:redwood_leaves[distance=1,persistent=false])
B(-2,37,5,biomesoplenty:redwood_leaves[distance=1,persistent=false])
B(-2,38,0,biomesoplenty:redwood_leaves[distance=1,persistent=false])
B(-2,38,1,biomesoplenty:redwood_leaves[distance=1,persistent=false])
B(-2,38,2,biomesoplenty:redwood_leaves[distance=1,persistent=false])
B(-2,38,3,biomesoplenty:redwood_leaves[distance=1,persistent=false])
B(-2,38,4,biomesoplenty:redwood_leaves[distance=1,persistent=false])
B(-2,38,5,biomesoplenty:redwood_leaves[distance=1,persistent=false])
B(-2,39,-1,biomesoplenty:redwood_leaves[distance=1,persistent=false])
B(-2,39,0,biomesoplenty:redwood_leaves[distance=1,persistent=false])
B(-2,39,1,biomesoplenty:redwood_leaves[distance=1,persistent=false])
B(-2,39,2,biomesoplenty:redwood_leaves[distance=1,persistent=false])
B(-2,39,3,biomesoplenty:redwood_leaves[distance=1,persistent=false])
B(-2,39,4,biomesoplenty:redwood_leaves[distance=1,persistent=false])
B(-2,39,5,biomesoplenty:redwood_leaves[distance=1,persistent=false])
B(-2,39,6,biomesoplenty:redwood_leaves[distance=1,persistent=false])
B(-2,40,-1,biomesoplenty:redwood_leaves[distance=1,persistent=false])
B(-2,40,0,biomesoplenty:redwood_leaves[distance=1,persistent=false])
B(-2,40,1,biomesoplenty:redwood_leaves[distance=1,persistent=false])
B(-2,40,2,biomesoplenty:redwood_leaves[distance=1,persistent=false])
B(-2,40,3,biomesoplenty:redwood_leaves[distance=1,persistent=false])
B(-2,40,4,biomesoplenty:redwood_leaves[distance=1,persistent=false])
B(-2,40,5,biomesoplenty:redwood_leaves[distance=1,persistent=false])
B(-1,0,-1,biomesoplenty:redwood_log)
B(-1,0,0,biomesoplenty:redwood_log)
B(-1,0,1,biomesoplenty:redwood_log)
B(-1,0,2,biomesoplenty:redwood_log)
B(-1,0,3,biomesoplenty:redwood_log)
B(-1,0,4,biomesoplenty:redwood_log)
B(-1,0,5,biomesoplenty:redwood_log)
B(-1,1,0,biomesoplenty:redwood_log)
B(-1,1,1,biomesoplenty:redwood_log)
B(-1,1,2,biomesoplenty:redwood_log)
B(-1,1,3,biomesoplenty:redwood_log)
B(-1,1,4,biomesoplenty:redwood_log)
B(-1,2,2,biomesoplenty:redwood_log)
B(-1,2,3,biomesoplenty:redwood_log)
B(-1,21,0,biomesoplenty:redwood_leaves[distance=1,persistent=false])
B(-1,21,1,biomesoplenty:redwood_leaves[distance=1,persistent=false])
B(-1,21,2,biomesoplenty:redwood_leaves[distance=1,persistent=false])
B(-1,21,3,biomesoplenty:redwood_leaves[distance=1,persistent=false])
B(-1,21,4,biomesoplenty:redwood_leaves[distance=1,persistent=false])
B(-1,22,-2,biomesoplenty:redwood_leaves[distance=1,persistent=false])
B(-1,22,-1,biomesoplenty:redwood_leaves[distance=1,persistent=false])
B(-1,22,0,biomesoplenty:redwood_leaves[distance=1,persistent=false])
B(-1,22,1,biomesoplenty:redwood_leaves[distance=1,persistent=false])
B(-1,22,2,biomesoplenty:redwood_leaves[distance=1,persistent=false])
B(-1,22,3,biomesoplenty:redwood_leaves[distance=1,persistent=false])
B(-1,22,4,biomesoplenty:redwood_leaves[distance=1,persistent=false])
B(-1,22,5,biomesoplenty:redwood_leaves[distance=1,persistent=false])
B(-1,22,6,biomesoplenty:redwood_leaves[distance=1,persistent=false])
B(-1,23,-2,biomesoplenty:redwood_leaves[distance=1,persistent=false])
B(-1,23,-1,biomesoplenty:redwood_leaves[distance=1,persistent=false])
B(-1,23,0,biomesoplenty:redwood_leaves[distance=1,persistent=false])
B(-1,23,1,biomesoplenty:redwood_leaves[distance=1,persistent=false])
B(-1,23,2,biomesoplenty:redwood_leaves[distance=1,persistent=false])
B(-1,23,3,biomesoplenty:redwood_leaves[distance=1,persistent=false])
B(-1,23,4,biomesoplenty:redwood_leaves[distance=1,persistent=false])
B(-1,23,5,biomesoplenty:redwood_leaves[distance=1,persistent=false])
B(-1,24,-2,biomesoplenty:redwood_leaves[distance=1,persistent=false])
B(-1,24,-1,biomesoplenty:redwood_leaves[distance=1,persistent=false])
B(-1,24,0,biomesoplenty:redwood_leaves[distance=1,persistent=false])
B(-1,24,1,biomesoplenty:redwood_leaves[distance=1,persistent=false])
B(-1,24,2,biomesoplenty:redwood_leaves[distance=1,persistent=false])
B(-1,24,3,biomesoplenty:redwood_leaves[distance=1,persistent=false])
B(-1,24,4,biomesoplenty:redwood_leaves[distance=1,persistent=false])
B(-1,24,5,biomesoplenty:redwood_leaves[distance=1,persistent=false])
B(-1,24,6,biomesoplenty:redwood_leaves[distance=1,persistent=false])
B(-1,25,-2,biomesoplenty:redwood_leaves[distance=1,persistent=false])
B(-1,25,-1,biomesoplenty:redwood_leaves[distance=1,persistent=false])
B(-1,25,0,biomesoplenty:redwood_leaves[distance=1,persistent=false])
B(-1,25,1,biomesoplenty:redwood_leaves[distance=1,persistent=false])
B(-1,25,2,biomesoplenty:redwood_leaves[distance=1,persistent=false])
B(-1,25,3,biomesoplenty:redwood_leaves[distance=1,persistent=false])
B(-1,25,4,biomesoplenty:redwood_leaves[distance=1,persistent=false])
B(-1,25,5,biomesoplenty:redwood_leaves[distance=1,persistent=false])
B(-1,25,6,biomesoplenty:redwood_leaves[distance=1,persistent=false])
B(-1,26,-2,biomesoplenty:redwood_leaves[distance=1,persistent=false])
B(-1,26,-1,biomesoplenty:redwood_leaves[distance=1,persistent=false])
B(-1,26,0,biomesoplenty:redwood_leaves[distance=1,persistent=false])
B(-1,26,1,biomesoplenty:redwood_leaves[distance=1,persistent=false])
B(-1,26,2,biomesoplenty:redwood_leaves[distance=1,persistent=false])
B(-1,26,3,biomesoplenty:redwood_leaves[distance=1,persistent=false])
B(-1,26,4,biomesoplenty:redwood_leaves[distance=1,persistent=false])
B(-1,26,5,biomesoplenty:redwood_leaves[distance=1,persistent=false])
B(-1,26,6,biomesoplenty:redwood_leaves[distance=1,persistent=false])
B(-1,27,0,biomesoplenty:redwood_leaves[distance=1,persistent=false])
B(-1,27,1,biomesoplenty:redwood_leaves[distance=1,persistent=false])
B(-1,27,2,biomesoplenty:redwood_leaves[distance=1,persistent=false])
B(-1,27,3,biomesoplenty:redwood_leaves[distance=1,persistent=false])
B(-1,27,4,biomesoplenty:redwood_leaves[distance=1,persistent=false])
B(-1,28,0,biomesoplenty:redwood_leaves[distance=1,persistent=false])
B(-1,28,1,biomesoplenty:redwood_leaves[distance=1,persistent=false])
B(-1,28,2,biomesoplenty:redwood_leaves[distance=1,persistent=false])
B(-1,28,3,biomesoplenty:redwood_leaves[distance=1,persistent=false])
B(-1,28,4,biomesoplenty:redwood_leaves[distance=1,persistent=false])
B(-1,29,-2,biomesoplenty:redwood_leaves[distance=1,persistent=false])
B(-1,29,-1,biomesoplenty:redwood_leaves[distance=1,persistent=false])
B(-1,29,0,biomesoplenty:redwood_leaves[distance=1,persistent=false])
B(-1,29,1,biomesoplenty:redwood_leaves[distance=1,persistent=false])
B(-1,29,2,biomesoplenty:redwood_leaves[distance=1,persistent=false])
B(-1,29,3,biomesoplenty:redwood_leaves[distance=1,persistent=false])
B(-1,29,4,biomesoplenty:redwood_leaves[distance=1,persistent=false])
B(-1,29,5,biomesoplenty:redwood_leaves[distance=1,persistent=false])
B(-1,29,6,biomesoplenty:redwood_leaves[distance=1,persistent=false])
B(-1,30,-2,biomesoplenty:redwood_leaves[distance=1,persistent=false])
B(-1,30,-1,biomesoplenty:redwood_leaves[distance=1,persistent=false])
B(-1,30,0,biomesoplenty:redwood_leaves[distance=1,persistent=false])
B(-1,30,1,biomesoplenty:redwood_leaves[distance=1,persistent=false])
B(-1,30,2,biomesoplenty:redwood_leaves[distance=1,persistent=false])
B(-1,30,3,biomesoplenty:redwood_leaves[distance=1,persistent=false])
B(-1,30,4,biomesoplenty:redwood_leaves[distance=1,persistent=false])
B(-1,30,5,biomesoplenty:redwood_leaves[distance=1,persistent=false])
B(-1,30,6,biomesoplenty:redwood_leaves[distance=1,persistent=false])
B(-1,31,-2,biomesoplenty:redwood_leaves[distance=1,persistent=false])
B(-1,31,-1,biomesoplenty:redwood_leaves[distance=1,persistent=false])
B(-1,31,0,biomesoplenty:redwood_leaves[distance=1,persistent=false])
B(-1,31,1,biomesoplenty:redwood_leaves[distance=1,persistent=false])
B(-1,31,2,biomesoplenty:redwood_leaves[distance=1,persistent=false])
B(-1,31,3,biomesoplenty:redwood_leaves[distance=1,persistent=false])
B(-1,31,4,biomesoplenty:redwood_leaves[distance=1,persistent=false])
B(-1,31,5,biomesoplenty:redwood_leaves[distance=1,persistent=false])
B(-1,31,6,biomesoplenty:redwood_leaves[distance=1,persistent=false])
B(-1,32,-2,biomesoplenty:redwood_leaves[distance=1,persistent=false])
B(-1,32,-1,biomesoplenty:redwood_leaves[distance=1,persistent=false])
B(-1,32,0,biomesoplenty:redwood_leaves[distance=1,persistent=false])
B(-1,32,1,biomesoplenty:redwood_leaves[distance=1,persistent=false])
B(-1,32,2,biomesoplenty:redwood_leaves[distance=1,persistent=false])
B(-1,32,3,biomesoplenty:redwood_leaves[distance=1,persistent=false])
B(-1,32,4,biomesoplenty:redwood_leaves[distance=1,persistent=false])
B(-1,32,5,biomesoplenty:redwood_leaves[distance=1,persistent=false])
B(-1,33,-2,biomesoplenty:redwood_leaves[distance=1,persistent=false])
B(-1,33,-1,biomesoplenty:redwood_leaves[distance=1,persistent=false])
B(-1,33,0,biomesoplenty:redwood_leaves[distance=1,persistent=false])
B(-1,33,1,biomesoplenty:redwood_leaves[distance=1,persistent=false])
B(-1,33,2,biomesoplenty:redwood_leaves[distance=1,persistent=false])
B(-1,33,3,biomesoplenty:redwood_leaves[distance=1,persistent=false])
B(-1,33,4,biomesoplenty:redwood_leaves[distance=1,persistent=false])
B(-1,33,5,biomesoplenty:redwood_leaves[distance=1,persistent=false])
B(-1,33,6,biomesoplenty:redwood_leaves[distance=1,persistent=false])
B(-1,34,0,biomesoplenty:redwood_leaves[distance=1,persistent=false])
B(-1,34,1,biomesoplenty:redwood_leaves[distance=1,persistent=false])
B(-1,34,2,biomesoplenty:redwood_leaves[distance=1,persistent=false])
B(-1,34,3,biomesoplenty:redwood_leaves[distance=1,persistent=false])
B(-1,34,4,biomesoplenty:redwood_leaves[distance=1,persistent=false])
B(-1,35,0,biomesoplenty:redwood_leaves[distance=1,persistent=false])
B(-1,35,1,biomesoplenty:redwood_leaves[distance=1,persistent=false])
B(-1,35,2,biomesoplenty:redwood_leaves[distance=1,persistent=false])
B(-1,35,3,biomesoplenty:redwood_leaves[distance=1,persistent=false])
B(-1,35,4,biomesoplenty:redwood_leaves[distance=1,persistent=false])
B(-1,36,-1,biomesoplenty:redwood_leaves[distance=1,persistent=false])
B(-1,36,0,biomesoplenty:redwood_leaves[distance=1,persistent=false])
B(-1,36,1,biomesoplenty:redwood_leaves[distance=1,persistent=false])
B(-1,36,2,biomesoplenty:redwood_leaves[distance=1,persistent=false])
B(-1,36,3,biomesoplenty:redwood_leaves[distance=1,persistent=false])
B(-1,36,4,biomesoplenty:redwood_leaves[distance=1,persistent=false])
B(-1,36,5,biomesoplenty:redwood_leaves[distance=1,persistent=false])
B(-1,37,-2,biomesoplenty:redwood_leaves[distance=1,persistent=false])
B(-1,37,-1,biomesoplenty:redwood_leaves[distance=1,persistent=false])
B(-1,37,0,biomesoplenty:redwood_leaves[distance=1,persistent=false])
B(-1,37,1,biomesoplenty:redwood_leaves[distance=1,persistent=false])
B(-1,37,2,biomesoplenty:redwood_leaves[distance=1,persistent=false])
B(-1,37,3,biomesoplenty:redwood_leaves[distance=1,persistent=false])
B(-1,37,4,biomesoplenty:redwood_leaves[distance=1,persistent=false])
B(-1,37,5,biomesoplenty:redwood_leaves[distance=1,persistent=false])
B(-1,38,-2,biomesoplenty:redwood_leaves[distance=1,persistent=false])
B(-1,38,-1,biomesoplenty:redwood_leaves[distance=1,persistent=false])
B(-1,38,0,biomesoplenty:redwood_leaves[distance=1,persistent=false])
B(-1,38,1,biomesoplenty:redwood_leaves[distance=1,persistent=false])
B(-1,38,2,biomesoplenty:redwood_leaves[distance=1,persistent=false])
B(-1,38,3,biomesoplenty:redwood_leaves[distance=1,persistent=false])
B(-1,38,4,biomesoplenty:redwood_leaves[distance=1,persistent=false])
B(-1,38,5,biomesoplenty:redwood_leaves[distance=1,persistent=false])
B(-1,38,6,biomesoplenty:redwood_leaves[distance=1,persistent=false])
B(-1,39,-2,biomesoplenty:redwood_leaves[distance=1,persistent=false])
B(-1,39,-1,biomesoplenty:redwood_leaves[distance=1,persistent=false])
B(-1,39,0,biomesoplenty:redwood_leaves[distance=1,persistent=false])
B(-1,39,1,biomesoplenty:redwood_leaves[distance=1,persistent=false])
B(-1,39,2,biomesoplenty:redwood_leaves[distance=1,persistent=false])
B(-1,39,3,biomesoplenty:redwood_leaves[distance=1,persistent=false])
B(-1,39,4,biomesoplenty:redwood_leaves[distance=1,persistent=false])
B(-1,39,5,biomesoplenty:redwood_leaves[distance=1,persistent=false])
B(-1,39,6,biomesoplenty:redwood_leaves[distance=1,persistent=false])
B(-1,40,-2,biomesoplenty:redwood_leaves[distance=1,persistent=false])
B(-1,40,-1,biomesoplenty:redwood_leaves[distance=1,persistent=false])
B(-1,40,0,biomesoplenty:redwood_leaves[distance=1,persistent=false])
B(-1,40,1,biomesoplenty:redwood_leaves[distance=1,persistent=false])
B(-1,40,2,biomesoplenty:redwood_leaves[distance=1,persistent=false])
B(-1,40,3,biomesoplenty:redwood_leaves[distance=1,persistent=false])
B(-1,40,4,biomesoplenty:redwood_leaves[distance=1,persistent=false])
B(-1,40,5,biomesoplenty:redwood_leaves[distance=1,persistent=false])
B(-1,40,6,biomesoplenty:redwood_leaves[distance=1,persistent=false])
B(-1,41,0,biomesoplenty:redwood_leaves[distance=1,persistent=false])
B(-1,41,1,biomesoplenty:redwood_leaves[distance=1,persistent=false])
B(-1,41,2,biomesoplenty:redwood_leaves[distance=1,persistent=false])
B(-1,41,3,biomesoplenty:redwood_leaves[distance=1,persistent=false])
B(-1,41,4,biomesoplenty:redwood_leaves[distance=1,persistent=false])
B(-1,42,0,biomesoplenty:redwood_leaves[distance=1,persistent=false])
B(-1,42,1,biomesoplenty:redwood_leaves[distance=1,persistent=false])
B(-1,42,2,biomesoplenty:redwood_leaves[distance=1,persistent=false])
B(-1,42,3,biomesoplenty:redwood_leaves[distance=1,persistent=false])
B(-1,42,4,biomesoplenty:redwood_leaves[distance=1,persistent=false])
B(0,0,-1,biomesoplenty:redwood_log)
B(0,0,0,biomesoplenty:redwood_log)
B(0,0,1,biomesoplenty:redwood_log)
B(0,0,2,biomesoplenty:redwood_log)
B(0,0,3,biomesoplenty:redwood_log)
B(0,0,4,biomesoplenty:redwood_log)
B(0,0,5,biomesoplenty:redwood_log)
B(0,1,-1,biomesoplenty:redwood_log)
B(0,1,0,biomesoplenty:redwood_log)
B(0,1,1,biomesoplenty:redwood_log)
B(0,1,2,biomesoplenty:redwood_log)
B(0,1,3,biomesoplenty:redwood_log)
B(0,1,4,biomesoplenty:redwood_log)
B(0,1,5,biomesoplenty:redwood_log)
B(0,2,-1,biomesoplenty:redwood_log)
B(0,2,1,biomesoplenty:redwood_log)
B(0,2,2,biomesoplenty:redwood_log)
B(0,2,3,biomesoplenty:redwood_log)
B(0,2,5,biomesoplenty:redwood_log)
B(0,3,1,biomesoplenty:redwood_log)
B(0,3,2,biomesoplenty:redwood_log)
B(0,3,3,biomesoplenty:redwood_log)
B(0,4,1,biomesoplenty:redwood_log)
B(0,4,2,biomesoplenty:redwood_log)
B(0,4,3,biomesoplenty:redwood_log)
B(0,21,-1,biomesoplenty:redwood_leaves[distance=1,persistent=false])
B(0,21,0,biomesoplenty:redwood_leaves[distance=1,persistent=false])
B(0,21,1,biomesoplenty:redwood_leaves[distance=1,persistent=false])
B(0,21,2,biomesoplenty:redwood_leaves[distance=1,persistent=false])
B(0,21,3,biomesoplenty:redwood_leaves[distance=1,persistent=false])
B(0,21,4,biomesoplenty:redwood_leaves[distance=1,persistent=false])
B(0,21,5,biomesoplenty:redwood_leaves[distance=1,persistent=false])
B(0,22,-2,biomesoplenty:redwood_leaves[distance=1,persistent=false])
B(0,22,-1,biomesoplenty:redwood_leaves[distance=1,persistent=false])
B(0,22,0,biomesoplenty:redwood_leaves[distance=1,persistent=false])
B(0,22,1,biomesoplenty:redwood_leaves[distance=1,persistent=false])
B(0,22,2,biomesoplenty:redwood_leaves[distance=1,persistent=false])
B(0,22,3,biomesoplenty:redwood_leaves[distance=1,persistent=false])
B(0,22,4,biomesoplenty:redwood_leaves[distance=1,persistent=false])
B(0,22,5,biomesoplenty:redwood_leaves[distance=1,persistent=false])
B(0,22,6,biomesoplenty:redwood_leaves[distance=1,persistent=false])
B(0,23,-2,biomesoplenty:redwood_leaves[distance=1,persistent=false])
B(0,23,-1,biomesoplenty:redwood_leaves[distance=1,persistent=false])
B(0,23,0,biomesoplenty:redwood_leaves[distance=1,persistent=false])
B(0,23,1,biomesoplenty:redwood_leaves[distance=1,persistent=false])
B(0,23,2,biomesoplenty:redwood_leaves[distance=1,persistent=false])
B(0,23,3,biomesoplenty:redwood_leaves[distance=1,persistent=false])
B(0,23,4,biomesoplenty:redwood_leaves[distance=1,persistent=false])
B(0,23,5,biomesoplenty:redwood_leaves[distance=1,persistent=false])
B(0,23,6,biomesoplenty:redwood_leaves[distance=1,persistent=false])
B(0,24,-3,biomesoplenty:redwood_leaves[distance=1,persistent=false])
B(0,24,-2,biomesoplenty:redwood_leaves[distance=1,persistent=false])
B(0,24,-1,biomesoplenty:redwood_leaves[distance=1,persistent=false])
B(0,24,0,biomesoplenty:redwood_leaves[distance=1,persistent=false])
B(0,24,1,biomesoplenty:redwood_leaves[distance=1,persistent=false])
B(0,24,2,biomesoplenty:redwood_leaves[distance=1,persistent=false])
B(0,24,3,biomesoplenty:redwood_leaves[distance=1,persistent=false])
B(0,24,4,biomesoplenty:redwood_leaves[distance=1,persistent=false])
B(0,24,5,biomesoplenty:redwood_leaves[distance=1,persistent=false])
B(0,24,6,biomesoplenty:redwood_leaves[distance=1,persistent=false])
B(0,24,7,biomesoplenty:redwood_leaves[distance=1,persistent=false])
B(0,25,-3,biomesoplenty:redwood_leaves[distance=1,persistent=false])
B(0,25,-2,biomesoplenty:redwood_leaves[distance=1,persistent=false])
B(0,25,-1,biomesoplenty:redwood_leaves[distance=1,persistent=false])
B(0,25,0,biomesoplenty:redwood_leaves[distance=1,persistent=false])
B(0,25,1,biomesoplenty:redwood_leaves[distance=1,persistent=false])
B(0,25,2,biomesoplenty:redwood_leaves[distance=1,persistent=false])
B(0,25,3,biomesoplenty:redwood_leaves[distance=1,persistent=false])
B(0,25,4,biomesoplenty:redwood_leaves[distance=1,persistent=false])
B(0,25,5,biomesoplenty:redwood_leaves[distance=1,persistent=false])
B(0,25,6,biomesoplenty:redwood_leaves[distance=1,persistent=false])
B(0,25,7,biomesoplenty:redwood_leaves[distance=1,persistent=false])
B(0,26,-3,biomesoplenty:redwood_leaves[distance=1,persistent=false])
B(0,26,-2,biomesoplenty:redwood_leaves[distance=1,persistent=false])
B(0,26,-1,biomesoplenty:redwood_leaves[distance=1,persistent=false])
B(0,26,0,biomesoplenty:redwood_leaves[distance=1,persistent=false])
B(0,26,1,biomesoplenty:redwood_leaves[distance=1,persistent=false])
B(0,26,2,biomesoplenty:redwood_leaves[distance=1,persistent=false])
B(0,26,3,biomesoplenty:redwood_leaves[distance=1,persistent=false])
B(0,26,4,biomesoplenty:redwood_leaves[distance=1,persistent=false])
B(0,26,5,biomesoplenty:redwood_leaves[distance=1,persistent=false])
B(0,26,6,biomesoplenty:redwood_leaves[distance=1,persistent=false])
B(0,26,7,biomesoplenty:redwood_leaves[distance=1,persistent=false])
B(0,27,-1,biomesoplenty:redwood_leaves[distance=1,persistent=false])
B(0,27,0,biomesoplenty:redwood_leaves[distance=1,persistent=false])
B(0,27,1,biomesoplenty:redwood_leaves[distance=1,persistent=false])
B(0,27,2,biomesoplenty:redwood_leaves[distance=1,persistent=false])
B(0,27,3,biomesoplenty:redwood_leaves[distance=1,persistent=false])
B(0,27,4,biomesoplenty:redwood_leaves[distance=1,persistent=false])
B(0,27,5,biomesoplenty:redwood_leaves[distance=1,persistent=false])
B(0,28,-1,biomesoplenty:redwood_leaves[distance=1,persistent=false])
B(0,28,0,biomesoplenty:redwood_leaves[distance=1,persistent=false])
B(0,28,1,biomesoplenty:redwood_leaves[distance=1,persistent=false])
B(0,28,2,biomesoplenty:redwood_leaves[distance=1,persistent=false])
B(0,28,3,biomesoplenty:redwood_leaves[distance=1,persistent=false])
B(0,28,4,biomesoplenty:redwood_leaves[distance=1,persistent=false])
B(0,28,5,biomesoplenty:redwood_leaves[distance=1,persistent=false])
B(0,29,-2,biomesoplenty:redwood_leaves[distance=1,persistent=false])
B(0,29,-1,biomesoplenty:redwood_leaves[distance=1,persistent=false])
B(0,29,0,biomesoplenty:redwood_leaves[distance=1,persistent=false])
B(0,29,1,biomesoplenty:redwood_leaves[distance=1,persistent=false])
B(0,29,2,biomesoplenty:redwood_leaves[distance=1,persistent=false])
B(0,29,3,biomesoplenty:redwood_leaves[distance=1,persistent=false])
B(0,29,4,biomesoplenty:redwood_leaves[distance=1,persistent=false])
B(0,29,5,biomesoplenty:redwood_leaves[distance=1,persistent=false])
B(0,29,6,biomesoplenty:redwood_leaves[distance=1,persistent=false])
B(0,29,7,biomesoplenty:redwood_leaves[distance=1,persistent=false])
B(0,30,-3,biomesoplenty:redwood_leaves[distance=1,persistent=false])
B(0,30,-2,biomesoplenty:redwood_leaves[distance=1,persistent=false])
B(0,30,-1,biomesoplenty:redwood_leaves[distance=1,persistent=false])
B(0,30,0,biomesoplenty:redwood_leaves[distance=1,persistent=false])
B(0,30,1,biomesoplenty:redwood_leaves[distance=1,persistent=false])
B(0,30,2,biomesoplenty:redwood_leaves[distance=1,persistent=false])
B(0,30,3,biomesoplenty:redwood_leaves[distance=1,persistent=false])
B(0,30,4,biomesoplenty:redwood_leaves[distance=1,persistent=false])
B(0,30,5,biomesoplenty:redwood_leaves[distance=1,persistent=false])
B(0,30,6,biomesoplenty:redwood_leaves[distance=1,persistent=false])
B(0,30,7,biomesoplenty:redwood_leaves[distance=1,persistent=false])
B(0,31,-2,biomesoplenty:redwood_leaves[distance=1,persistent=false])
B(0,31,-1,biomesoplenty:redwood_leaves[distance=1,persistent=false])
B(0,31,0,biomesoplenty:redwood_leaves[distance=1,persistent=false])
B(0,31,1,biomesoplenty:redwood_leaves[distance=1,persistent=false])
B(0,31,2,biomesoplenty:redwood_leaves[distance=1,persistent=false])
B(0,31,3,biomesoplenty:redwood_leaves[distance=1,persistent=false])
B(0,31,4,biomesoplenty:redwood_leaves[distance=1,persistent=false])
B(0,31,5,biomesoplenty:redwood_leaves[distance=1,persistent=false])
B(0,31,6,biomesoplenty:redwood_leaves[distance=1,persistent=false])
B(0,32,-3,biomesoplenty:redwood_leaves[distance=1,persistent=false])
B(0,32,-2,biomesoplenty:redwood_leaves[distance=1,persistent=false])
B(0,32,-1,biomesoplenty:redwood_leaves[distance=1,persistent=false])
B(0,32,0,biomesoplenty:redwood_leaves[distance=1,persistent=false])
B(0,32,1,biomesoplenty:redwood_leaves[distance=1,persistent=false])
B(0,32,2,biomesoplenty:redwood_leaves[distance=1,persistent=false])
B(0,32,3,biomesoplenty:redwood_leaves[distance=1,persistent=false])
B(0,32,4,biomesoplenty:redwood_leaves[distance=1,persistent=false])
B(0,32,5,biomesoplenty:redwood_leaves[distance=1,persistent=false])
B(0,32,6,biomesoplenty:redwood_leaves[distance=1,persistent=false])
B(0,32,7,biomesoplenty:redwood_leaves[distance=1,persistent=false])
B(0,33,-2,biomesoplenty:redwood_leaves[distance=1,persistent=false])
B(0,33,-1,biomesoplenty:redwood_leaves[distance=1,persistent=false])
B(0,33,0,biomesoplenty:redwood_leaves[distance=1,persistent=false])
B(0,33,1,biomesoplenty:redwood_leaves[distance=1,persistent=false])
B(0,33,2,biomesoplenty:redwood_leaves[distance=1,persistent=false])
B(0,33,3,biomesoplenty:redwood_leaves[distance=1,persistent=false])
B(0,33,4,biomesoplenty:redwood_leaves[distance=1,persistent=false])
B(0,33,5,biomesoplenty:redwood_leaves[distance=1,persistent=false])
B(0,33,6,biomesoplenty:redwood_leaves[distance=1,persistent=false])
B(0,33,7,biomesoplenty:redwood_leaves[distance=1,persistent=false])
B(0,34,-1,biomesoplenty:redwood_leaves[distance=1,persistent=false])
B(0,34,0,biomesoplenty:redwood_leaves[distance=1,persistent=false])
B(0,34,1,biomesoplenty:redwood_leaves[distance=1,persistent=false])
B(0,34,2,biomesoplenty:redwood_leaves[distance=1,persistent=false])
B(0,34,3,biomesoplenty:redwood_leaves[distance=1,persistent=false])
B(0,34,4,biomesoplenty:redwood_leaves[distance=1,persistent=false])
B(0,34,5,biomesoplenty:redwood_leaves[distance=1,persistent=false])
B(0,35,-1,biomesoplenty:redwood_leaves[distance=1,persistent=false])
B(0,35,0,biomesoplenty:redwood_leaves[distance=1,persistent=false])
B(0,35,1,biomesoplenty:redwood_leaves[distance=1,persistent=false])
B(0,35,2,biomesoplenty:redwood_leaves[distance=1,persistent=false])
B(0,35,3,biomesoplenty:redwood_leaves[distance=1,persistent=false])
B(0,35,4,biomesoplenty:redwood_leaves[distance=1,persistent=false])
B(0,35,5,biomesoplenty:redwood_leaves[distance=1,persistent=false])
B(0,36,-2,biomesoplenty:redwood_leaves[distance=1,persistent=false])
B(0,36,-1,biomesoplenty:redwood_leaves[distance=1,persistent=false])
B(0,36,0,biomesoplenty:redwood_leaves[distance=1,persistent=false])
B(0,36,1,biomesoplenty:redwood_leaves[distance=1,persistent=false])
B(0,36,2,biomesoplenty:redwood_leaves[distance=1,persistent=false])
B(0,36,3,biomesoplenty:redwood_leaves[distance=1,persistent=false])
B(0,36,4,biomesoplenty:redwood_leaves[distance=1,persistent=false])
B(0,36,5,biomesoplenty:redwood_leaves[distance=1,persistent=false])
B(0,36,6,biomesoplenty:redwood_leaves[distance=1,persistent=false])
B(0,36,7,biomesoplenty:redwood_leaves[distance=1,persistent=false])
B(0,37,-3,biomesoplenty:redwood_leaves[distance=1,persistent=false])
B(0,37,-2,biomesoplenty:redwood_leaves[distance=1,persistent=false])
B(0,37,-1,biomesoplenty:redwood_leaves[distance=1,persistent=false])
B(0,37,0,biomesoplenty:redwood_leaves[distance=1,persistent=false])
B(0,37,1,biomesoplenty:redwood_leaves[distance=1,persistent=false])
B(0,37,2,biomesoplenty:redwood_leaves[distance=1,persistent=false])
B(0,37,3,biomesoplenty:redwood_leaves[distance=1,persistent=false])
B(0,37,4,biomesoplenty:redwood_leaves[distance=1,persistent=false])
B(0,37,5,biomesoplenty:redwood_leaves[distance=1,persistent=false])
B(0,37,6,biomesoplenty:redwood_leaves[distance=1,persistent=false])
B(0,38,-3,biomesoplenty:redwood_leaves[distance=1,persistent=false])
B(0,38,-2,biomesoplenty:redwood_leaves[distance=1,persistent=false])
B(0,38,-1,biomesoplenty:redwood_leaves[distance=1,persistent=false])
B(0,38,0,biomesoplenty:redwood_leaves[distance=1,persistent=false])
B(0,38,1,biomesoplenty:redwood_leaves[distance=1,persistent=false])
B(0,38,2,biomesoplenty:redwood_leaves[distance=1,persistent=false])
B(0,38,3,biomesoplenty:redwood_leaves[distance=1,persistent=false])
B(0,38,4,biomesoplenty:redwood_leaves[distance=1,persistent=false])
B(0,38,5,biomesoplenty:redwood_leaves[distance=1,persistent=false])
B(0,38,6,biomesoplenty:redwood_leaves[distance=1,persistent=false])
B(0,38,7,biomesoplenty:redwood_leaves[distance=1,persistent=false])
B(0,39,-2,biomesoplenty:redwood_leaves[distance=1,persistent=false])
B(0,39,-1,biomesoplenty:redwood_leaves[distance=1,persistent=false])
B(0,39,0,biomesoplenty:redwood_leaves[distance=1,persistent=false])
B(0,39,1,biomesoplenty:redwood_leaves[distance=1,persistent=false])
B(0,39,2,biomesoplenty:redwood_leaves[distance=1,persistent=false])
B(0,39,3,biomesoplenty:redwood_leaves[distance=1,persistent=false])
B(0,39,4,biomesoplenty:redwood_leaves[distance=1,persistent=false])
B(0,39,5,biomesoplenty:redwood_leaves[distance=1,persistent=false])
B(0,39,6,biomesoplenty:redwood_leaves[distance=1,persistent=false])
B(0,39,7,biomesoplenty:redwood_leaves[distance=1,persistent=false])
B(0,40,-2,biomesoplenty:redwood_leaves[distance=1,persistent=false])
B(0,40,-1,biomesoplenty:redwood_leaves[distance=1,persistent=false])
B(0,40,0,biomesoplenty:redwood_leaves[distance=1,persistent=false])
B(0,40,1,biomesoplenty:redwood_leaves[distance=1,persistent=false])
B(0,40,2,biomesoplenty:redwood_leaves[distance=1,persistent=false])
B(0,40,3,biomesoplenty:redwood_leaves[distance=1,persistent=false])
B(0,40,4,biomesoplenty:redwood_leaves[distance=1,persistent=false])
B(0,40,5,biomesoplenty:redwood_leaves[distance=1,persistent=false])
B(0,40,6,biomesoplenty:redwood_leaves[distance=1,persistent=false])
B(0,41,-1,biomesoplenty:redwood_leaves[distance=1,persistent=false])
B(0,41,0,biomesoplenty:redwood_leaves[distance=1,persistent=false])
B(0,41,1,biomesoplenty:redwood_leaves[distance=1,persistent=false])
B(0,41,2,biomesoplenty:redwood_leaves[distance=1,persistent=false])
B(0,41,3,biomesoplenty:redwood_leaves[distance=1,persistent=false])
B(0,41,4,biomesoplenty:redwood_leaves[distance=1,persistent=false])
B(0,41,5,biomesoplenty:redwood_leaves[distance=1,persistent=false])
B(0,42,-1,biomesoplenty:redwood_leaves[distance=1,persistent=false])
B(0,42,0,biomesoplenty:redwood_leaves[distance=1,persistent=false])
B(0,42,1,biomesoplenty:redwood_leaves[distance=1,persistent=false])
B(0,42,2,biomesoplenty:redwood_leaves[distance=1,persistent=false])
B(0,42,3,biomesoplenty:redwood_leaves[distance=1,persistent=false])
B(0,42,4,biomesoplenty:redwood_leaves[distance=1,persistent=false])
B(0,42,5,biomesoplenty:redwood_leaves[distance=1,persistent=false])
B(1,0,-2,biomesoplenty:redwood_log)
B(1,0,-1,biomesoplenty:redwood_log)
B(1,0,0,biomesoplenty:redwood_log)
B(1,0,1,biomesoplenty:redwood_log)
B(1,0,2,biomesoplenty:redwood_log)
B(1,0,3,biomesoplenty:redwood_log)
B(1,0,4,biomesoplenty:redwood_log)
B(1,0,5,biomesoplenty:redwood_log)
B(1,1,-1,biomesoplenty:redwood_log)
B(1,1,0,biomesoplenty:redwood_log)
B(1,1,1,biomesoplenty:redwood_log)
B(1,1,2,biomesoplenty:redwood_log)
B(1,1,3,biomesoplenty:redwood_log)
B(1,1,4,biomesoplenty:redwood_log)
B(1,1,5,biomesoplenty:redwood_log)
B(1,1,6,biomesoplenty:redwood_leaves[distance=1,persistent=false])
B(1,1,7,biomesoplenty:redwood_leaves[distance=1,persistent=false])
B(1,2,-1,biomesoplenty:redwood_log)
B(1,2,0,biomesoplenty:redwood_log)
B(1,2,1,biomesoplenty:redwood_log)
B(1,2,2,biomesoplenty:redwood_log)
B(1,2,3,biomesoplenty:redwood_log)
B(1,2,4,biomesoplenty:redwood_log)
B(1,2,5,biomesoplenty:redwood_log)
B(1,3,0,biomesoplenty:redwood_log)
B(1,3,1,biomesoplenty:redwood_log)
B(1,3,2,biomesoplenty:redwood_log)
B(1,3,3,biomesoplenty:redwood_log)
B(1,3,4,biomesoplenty:redwood_log)
B(1,4,0,biomesoplenty:redwood_log)
B(1,4,1,biomesoplenty:redwood_log)
B(1,4,2,biomesoplenty:redwood_log)
B(1,4,3,biomesoplenty:redwood_log)
B(1,4,4,biomesoplenty:redwood_log)
B(1,5,1,biomesoplenty:redwood_log)
B(1,5,2,biomesoplenty:redwood_log)
B(1,5,3,biomesoplenty:redwood_log)
B(1,5,4,biomesoplenty:redwood_log)
B(1,6,1,biomesoplenty:redwood_log)
B(1,6,2,biomesoplenty:redwood_log)
B(1,6,3,biomesoplenty:redwood_log)
B(1,7,1,biomesoplenty:redwood_log)
B(1,7,2,biomesoplenty:redwood_log)
B(1,7,3,biomesoplenty:redwood_log)
B(1,8,-1,biomesoplenty:redwood_leaves[distance=1,persistent=false])
B(1,8,0,biomesoplenty:redwood_leaves[distance=1,persistent=false])
B(1,8,1,biomesoplenty:redwood_leaves[distance=1,persistent=false])
B(1,8,2,biomesoplenty:redwood_log)
B(1,9,2,biomesoplenty:redwood_log)
B(1,10,2,biomesoplenty:redwood_log)
B(1,11,2,biomesoplenty:redwood_log)
B(1,12,2,biomesoplenty:redwood_log)
B(1,13,2,biomesoplenty:redwood_log)
B(1,14,2,biomesoplenty:redwood_log)
B(1,15,2,biomesoplenty:redwood_log)
B(1,16,2,biomesoplenty:redwood_log)
B(1,17,2,biomesoplenty:redwood_log)
B(1,18,2,biomesoplenty:redwood_log)
B(1,19,2,biomesoplenty:redwood_log)
B(1,20,2,biomesoplenty:redwood_log)
B(1,21,-1,biomesoplenty:redwood_leaves[distance=1,persistent=false])
B(1,21,0,biomesoplenty:redwood_leaves[distance=1,persistent=false])
B(1,21,1,biomesoplenty:redwood_leaves[distance=1,persistent=false])
B(1,21,2,biomesoplenty:redwood_log)
B(1,21,3,biomesoplenty:redwood_leaves[distance=1,persistent=false])
B(1,21,4,biomesoplenty:redwood_leaves[distance=1,persistent=false])
B(1,21,5,biomesoplenty:redwood_leaves[distance=1,persistent=false])
B(1,22,-3,biomesoplenty:redwood_leaves[distance=1,persistent=false])
B(1,22,-2,biomesoplenty:redwood_leaves[distance=1,persistent=false])
B(1,22,-1,biomesoplenty:redwood_leaves[distance=1,persistent=false])
B(1,22,0,biomesoplenty:redwood_leaves[distance=1,persistent=false])
B(1,22,1,biomesoplenty:redwood_leaves[distance=1,persistent=false])
B(1,22,2,biomesoplenty:redwood_log)
B(1,22,3,biomesoplenty:redwood_leaves[distance=1,persistent=false])
B(1,22,4,biomesoplenty:redwood_leaves[distance=1,persistent=false])
B(1,22,5,biomesoplenty:redwood_leaves[distance=1,persistent=false])
B(1,22,6,biomesoplenty:redwood_leaves[distance=1,persistent=false])
B(1,22,7,biomesoplenty:redwood_leaves[distance=1,persistent=false])
B(1,23,-2,biomesoplenty:redwood_leaves[distance=1,persistent=false])
B(1,23,-1,biomesoplenty:redwood_leaves[distance=1,persistent=false])
B(1,23,0,biomesoplenty:redwood_leaves[distance=1,persistent=false])
B(1,23,1,biomesoplenty:redwood_leaves[distance=1,persistent=false])
B(1,23,2,biomesoplenty:redwood_log)
B(1,23,3,biomesoplenty:redwood_leaves[distance=1,persistent=false])
B(1,23,4,biomesoplenty:redwood_leaves[distance=1,persistent=false])
B(1,23,5,biomesoplenty:redwood_leaves[distance=1,persistent=false])
B(1,23,6,biomesoplenty:redwood_leaves[distance=1,persistent=false])
B(1,23,7,biomesoplenty:redwood_leaves[distance=1,persistent=false])
B(1,24,-3,biomesoplenty:redwood_leaves[distance=1,persistent=false])
B(1,24,-2,biomesoplenty:redwood_leaves[distance=1,persistent=false])
B(1,24,-1,biomesoplenty:redwood_leaves[distance=1,persistent=false])
B(1,24,0,biomesoplenty:redwood_leaves[distance=1,persistent=false])
B(1,24,1,biomesoplenty:redwood_leaves[distance=1,persistent=false])
B(1,24,2,biomesoplenty:redwood_log)
B(1,24,3,biomesoplenty:redwood_leaves[distance=1,persistent=false])
B(1,24,4,biomesoplenty:redwood_leaves[distance=1,persistent=false])
B(1,24,5,biomesoplenty:redwood_leaves[distance=1,persistent=false])
B(1,24,6,biomesoplenty:redwood_leaves[distance=1,persistent=false])
B(1,24,7,biomesoplenty:redwood_leaves[distance=1,persistent=false])
B(1,25,-3,biomesoplenty:redwood_leaves[distance=1,persistent=false])
B(1,25,-2,biomesoplenty:redwood_leaves[distance=1,persistent=false])
B(1,25,-1,biomesoplenty:redwood_leaves[distance=1,persistent=false])
B(1,25,0,biomesoplenty:redwood_leaves[distance=1,persistent=false])
B(1,25,1,biomesoplenty:redwood_leaves[distance=1,persistent=false])
B(1,25,2,biomesoplenty:redwood_log)
B(1,25,3,biomesoplenty:redwood_leaves[distance=1,persistent=false])
B(1,25,4,biomesoplenty:redwood_leaves[distance=1,persistent=false])
B(1,25,5,biomesoplenty:redwood_leaves[distance=1,persistent=false])
B(1,25,6,biomesoplenty:redwood_leaves[distance=1,persistent=false])
B(1,26,-2,biomesoplenty:redwood_leaves[distance=1,persistent=false])
B(1,26,-1,biomesoplenty:redwood_leaves[distance=1,persistent=false])
B(1,26,0,biomesoplenty:redwood_leaves[distance=1,persistent=false])
B(1,26,1,biomesoplenty:redwood_leaves[distance=1,persistent=false])
B(1,26,2,biomesoplenty:redwood_log)
B(1,26,3,biomesoplenty:redwood_leaves[distance=1,persistent=false])
B(1,26,4,biomesoplenty:redwood_leaves[distance=1,persistent=false])
B(1,26,5,biomesoplenty:redwood_leaves[distance=1,persistent=false])
B(1,26,6,biomesoplenty:redwood_leaves[distance=1,persistent=false])
B(1,26,7,biomesoplenty:redwood_leaves[distance=1,persistent=false])
B(1,27,-1,biomesoplenty:redwood_leaves[distance=1,persistent=false])
B(1,27,0,biomesoplenty:redwood_leaves[distance=1,persistent=false])
B(1,27,1,biomesoplenty:redwood_leaves[distance=1,persistent=false])
B(1,27,2,biomesoplenty:redwood_log)
B(1,27,3,biomesoplenty:redwood_leaves[distance=1,persistent=false])
B(1,27,4,biomesoplenty:redwood_leaves[distance=1,persistent=false])
B(1,27,5,biomesoplenty:redwood_leaves[distance=1,persistent=false])
B(1,28,-1,biomesoplenty:redwood_leaves[distance=1,persistent=false])
B(1,28,0,biomesoplenty:redwood_leaves[distance=1,persistent=false])
B(1,28,1,biomesoplenty:redwood_leaves[distance=1,persistent=false])
B(1,28,2,biomesoplenty:redwood_log)
B(1,28,3,biomesoplenty:redwood_leaves[distance=1,persistent=false])
B(1,28,4,biomesoplenty:redwood_leaves[distance=1,persistent=false])
B(1,28,5,biomesoplenty:redwood_leaves[distance=1,persistent=false])
B(1,29,-2,biomesoplenty:redwood_leaves[distance=1,persistent=false])
B(1,29,-1,biomesoplenty:redwood_leaves[distance=1,persistent=false])
B(1,29,0,biomesoplenty:redwood_leaves[distance=1,persistent=false])
B(1,29,1,biomesoplenty:redwood_leaves[distance=1,persistent=false])
B(1,29,2,biomesoplenty:redwood_log)
B(1,29,3,biomesoplenty:redwood_leaves[distance=1,persistent=false])
B(1,29,4,biomesoplenty:redwood_leaves[distance=1,persistent=false])
B(1,29,5,biomesoplenty:redwood_leaves[distance=1,persistent=false])
B(1,29,6,biomesoplenty:redwood_leaves[distance=1,persistent=false])
B(1,30,-3,biomesoplenty:redwood_leaves[distance=1,persistent=false])
B(1,30,-2,biomesoplenty:redwood_leaves[distance=1,persistent=false])
B(1,30,-1,biomesoplenty:redwood_leaves[distance=1,persistent=false])
B(1,30,0,biomesoplenty:redwood_leaves[distance=1,persistent=false])
B(1,30,1,biomesoplenty:redwood_leaves[distance=1,persistent=false])
B(1,30,2,biomesoplenty:redwood_log)
B(1,30,3,biomesoplenty:redwood_leaves[distance=1,persistent=false])
B(1,30,4,biomesoplenty:redwood_leaves[distance=1,persistent=false])
B(1,30,5,biomesoplenty:redwood_leaves[distance=1,persistent=false])
B(1,30,6,biomesoplenty:redwood_leaves[distance=1,persistent=false])
B(1,30,7,biomesoplenty:redwood_leaves[distance=1,persistent=false])
B(1,31,-3,biomesoplenty:redwood_leaves[distance=1,persistent=false])
B(1,31,-2,biomesoplenty:redwood_leaves[distance=1,persistent=false])
B(1,31,-1,biomesoplenty:redwood_leaves[distance=1,persistent=false])
B(1,31,0,biomesoplenty:redwood_leaves[distance=1,persistent=false])
B(1,31,1,biomesoplenty:redwood_leaves[distance=1,persistent=false])
B(1,31,2,biomesoplenty:redwood_log)
B(1,31,3,biomesoplenty:redwood_leaves[distance=1,persistent=false])
B(1,31,4,biomesoplenty:redwood_leaves[distance=1,persistent=false])
B(1,31,5,biomesoplenty:redwood_leaves[distance=1,persistent=false])
B(1,31,6,biomesoplenty:redwood_leaves[distance=1,persistent=false])
B(1,31,7,biomesoplenty:redwood_leaves[distance=1,persistent=false])
B(1,32,-2,biomesoplenty:redwood_leaves[distance=1,persistent=false])
B(1,32,-1,biomesoplenty:redwood_leaves[distance=1,persistent=false])
B(1,32,0,biomesoplenty:redwood_leaves[distance=1,persistent=false])
B(1,32,1,biomesoplenty:redwood_leaves[distance=1,persistent=false])
B(1,32,2,biomesoplenty:redwood_log)
B(1,32,3,biomesoplenty:redwood_leaves[distance=1,persistent=false])
B(1,32,4,biomesoplenty:redwood_leaves[distance=1,persistent=false])
B(1,32,5,biomesoplenty:redwood_leaves[distance=1,persistent=false])
B(1,32,6,biomesoplenty:redwood_leaves[distance=1,persistent=false])
B(1,32,7,biomesoplenty:redwood_leaves[distance=1,persistent=false])
B(1,33,-2,biomesoplenty:redwood_leaves[distance=1,persistent=false])
B(1,33,-1,biomesoplenty:redwood_leaves[distance=1,persistent=false])
B(1,33,0,biomesoplenty:redwood_leaves[distance=1,persistent=false])
B(1,33,1,biomesoplenty:redwood_leaves[distance=1,persistent=false])
B(1,33,2,biomesoplenty:redwood_log)
B(1,33,3,biomesoplenty:redwood_leaves[distance=1,persistent=false])
B(1,33,4,biomesoplenty:redwood_leaves[distance=1,persistent=false])
B(1,33,5,biomesoplenty:redwood_leaves[distance=1,persistent=false])
B(1,33,6,biomesoplenty:redwood_leaves[distance=1,persistent=false])
B(1,33,7,biomesoplenty:redwood_leaves[distance=1,persistent=false])
B(1,34,-1,biomesoplenty:redwood_leaves[distance=1,persistent=false])
B(1,34,0,biomesoplenty:redwood_leaves[distance=1,persistent=false])
B(1,34,1,biomesoplenty:redwood_leaves[distance=1,persistent=false])
B(1,34,2,biomesoplenty:redwood_log)
B(1,34,3,biomesoplenty:redwood_leaves[distance=1,persistent=false])
B(1,34,4,biomesoplenty:redwood_leaves[distance=1,persistent=false])
B(1,34,5,biomesoplenty:redwood_leaves[distance=1,persistent=false])
B(1,35,-1,biomesoplenty:redwood_leaves[distance=1,persistent=false])
B(1,35,0,biomesoplenty:redwood_leaves[distance=1,persistent=false])
B(1,35,1,biomesoplenty:redwood_leaves[distance=1,persistent=false])
B(1,35,2,biomesoplenty:redwood_log)
B(1,35,3,biomesoplenty:redwood_leaves[distance=1,persistent=false])
B(1,35,4,biomesoplenty:redwood_leaves[distance=1,persistent=false])
B(1,35,5,biomesoplenty:redwood_leaves[distance=1,persistent=false])
B(1,36,-3,biomesoplenty:redwood_leaves[distance=1,persistent=false])
B(1,36,-2,biomesoplenty:redwood_leaves[distance=1,persistent=false])
B(1,36,-1,biomesoplenty:redwood_leaves[distance=1,persistent=false])
B(1,36,0,biomesoplenty:redwood_leaves[distance=1,persistent=false])
B(1,36,1,biomesoplenty:redwood_leaves[distance=1,persistent=false])
B(1,36,2,biomesoplenty:redwood_log)
B(1,36,3,biomesoplenty:redwood_leaves[distance=1,persistent=false])
B(1,36,4,biomesoplenty:redwood_leaves[distance=1,persistent=false])
B(1,36,5,biomesoplenty:redwood_leaves[distance=1,persistent=false])
B(1,36,6,biomesoplenty:redwood_leaves[distance=1,persistent=false])
B(1,36,7,biomesoplenty:redwood_leaves[distance=1,persistent=false])
B(1,37,-3,biomesoplenty:redwood_leaves[distance=1,persistent=false])
B(1,37,-2,biomesoplenty:redwood_leaves[distance=1,persistent=false])
B(1,37,-1,biomesoplenty:redwood_leaves[distance=1,persistent=false])
B(1,37,0,biomesoplenty:redwood_leaves[distance=1,persistent=false])
B(1,37,1,biomesoplenty:redwood_leaves[distance=1,persistent=false])
B(1,37,2,biomesoplenty:redwood_log)
B(1,37,3,biomesoplenty:redwood_leaves[distance=1,persistent=false])
B(1,37,4,biomesoplenty:redwood_leaves[distance=1,persistent=false])
B(1,37,5,biomesoplenty:redwood_leaves[distance=1,persistent=false])
B(1,37,6,biomesoplenty:redwood_leaves[distance=1,persistent=false])
B(1,38,-3,biomesoplenty:redwood_leaves[distance=1,persistent=false])
B(1,38,-2,biomesoplenty:redwood_leaves[distance=1,persistent=false])
B(1,38,-1,biomesoplenty:redwood_leaves[distance=1,persistent=false])
B(1,38,0,biomesoplenty:redwood_leaves[distance=1,persistent=false])
B(1,38,1,biomesoplenty:redwood_leaves[distance=1,persistent=false])
B(1,38,2,biomesoplenty:redwood_log)
B(1,38,3,biomesoplenty:redwood_leaves[distance=1,persistent=false])
B(1,38,4,biomesoplenty:redwood_leaves[distance=1,persistent=false])
B(1,38,5,biomesoplenty:redwood_leaves[distance=1,persistent=false])
B(1,38,6,biomesoplenty:redwood_leaves[distance=1,persistent=false])
B(1,39,-3,biomesoplenty:redwood_leaves[distance=1,persistent=false])
B(1,39,-2,biomesoplenty:redwood_leaves[distance=1,persistent=false])
B(1,39,-1,biomesoplenty:redwood_leaves[distance=1,persistent=false])
B(1,39,0,biomesoplenty:redwood_leaves[distance=1,persistent=false])
B(1,39,1,biomesoplenty:redwood_leaves[distance=1,persistent=false])
B(1,39,2,biomesoplenty:redwood_log)
B(1,39,3,biomesoplenty:redwood_leaves[distance=1,persistent=false])
B(1,39,4,biomesoplenty:redwood_leaves[distance=1,persistent=false])
B(1,39,5,biomesoplenty:redwood_leaves[distance=1,persistent=false])
B(1,39,6,biomesoplenty:redwood_leaves[distance=1,persistent=false])
B(1,40,-2,biomesoplenty:redwood_leaves[distance=1,persistent=false])
B(1,40,-1,biomesoplenty:redwood_leaves[distance=1,persistent=false])
B(1,40,0,biomesoplenty:redwood_leaves[distance=1,persistent=false])
B(1,40,1,biomesoplenty:redwood_leaves[distance=1,persistent=false])
B(1,40,2,biomesoplenty:redwood_log)
B(1,40,3,biomesoplenty:redwood_leaves[distance=1,persistent=false])
B(1,40,4,biomesoplenty:redwood_leaves[distance=1,persistent=false])
B(1,40,5,biomesoplenty:redwood_leaves[distance=1,persistent=false])
B(1,40,6,biomesoplenty:redwood_leaves[distance=1,persistent=false])
B(1,40,7,biomesoplenty:redwood_leaves[distance=1,persistent=false])
B(1,41,-1,biomesoplenty:redwood_leaves[distance=1,persistent=false])
B(1,41,0,biomesoplenty:redwood_leaves[distance=1,persistent=false])
B(1,41,1,biomesoplenty:redwood_leaves[distance=1,persistent=false])
B(1,41,2,biomesoplenty:redwood_leaves[distance=1,persistent=false])
B(1,41,3,biomesoplenty:redwood_leaves[distance=1,persistent=false])
B(1,41,4,biomesoplenty:redwood_leaves[distance=1,persistent=false])
B(1,41,5,biomesoplenty:redwood_leaves[distance=1,persistent=false])
B(1,42,-1,biomesoplenty:redwood_leaves[distance=1,persistent=false])
B(1,42,0,biomesoplenty:redwood_leaves[distance=1,persistent=false])
B(1,42,1,biomesoplenty:redwood_leaves[distance=1,persistent=false])
B(1,42,2,biomesoplenty:redwood_leaves[distance=1,persistent=false])
B(1,42,3,biomesoplenty:redwood_leaves[distance=1,persistent=false])
B(1,42,4,biomesoplenty:redwood_leaves[distance=1,persistent=false])
B(1,42,5,biomesoplenty:redwood_leaves[distance=1,persistent=false])
B(2,0,-2,biomesoplenty:redwood_log)
B(2,0,-1,biomesoplenty:redwood_log)
B(2,0,0,biomesoplenty:redwood_log)
B(2,0,1,biomesoplenty:redwood_log)
B(2,0,2,biomesoplenty:redwood_log)
B(2,0,3,biomesoplenty:redwood_log)
B(2,0,4,biomesoplenty:redwood_log)
B(2,0,5,biomesoplenty:redwood_log)
B(2,0,6,biomesoplenty:redwood_log)
B(2,1,-1,biomesoplenty:redwood_log)
B(2,1,0,biomesoplenty:redwood_log)
B(2,1,1,biomesoplenty:redwood_log)
B(2,1,2,biomesoplenty:redwood_log)
B(2,1,3,biomesoplenty:redwood_log)
B(2,1,4,biomesoplenty:redwood_log)
B(2,1,5,biomesoplenty:redwood_log)
B(2,1,6,biomesoplenty:redwood_leaves[distance=1,persistent=false])
B(2,1,7,biomesoplenty:redwood_leaves[distance=1,persistent=false])
B(2,1,8,biomesoplenty:redwood_leaves[distance=1,persistent=false])
B(2,2,0,biomesoplenty:redwood_log)
B(2,2,1,biomesoplenty:redwood_log)
B(2,2,2,biomesoplenty:redwood_log)
B(2,2,3,biomesoplenty:redwood_log)
B(2,2,4,biomesoplenty:redwood_log)
B(2,2,5,biomesoplenty:redwood_log)
B(2,2,6,biomesoplenty:redwood_leaves[distance=1,persistent=false])
B(2,3,-2,biomesoplenty:redwood_leaves[distance=1,persistent=false])
B(2,3,-1,biomesoplenty:redwood_leaves[distance=1,persistent=false])
B(2,3,0,biomesoplenty:redwood_log)
B(2,3,1,biomesoplenty:redwood_log)
B(2,3,2,biomesoplenty:redwood_log)
B(2,3,3,biomesoplenty:redwood_log)
B(2,3,4,biomesoplenty:redwood_log)
B(2,3,5,biomesoplenty:redwood_log)
B(2,4,0,biomesoplenty:redwood_log)
B(2,4,1,biomesoplenty:redwood_log)
B(2,4,2,biomesoplenty:redwood_log)
B(2,4,3,biomesoplenty:redwood_log)
B(2,4,4,biomesoplenty:redwood_log)
B(2,5,0,biomesoplenty:redwood_log)
B(2,5,1,biomesoplenty:redwood_log)
B(2,5,2,biomesoplenty:redwood_log)
B(2,5,3,biomesoplenty:redwood_log)
B(2,5,4,biomesoplenty:redwood_log)
B(2,5,5,biomesoplenty:redwood_leaves[distance=1,persistent=false])
B(2,6,0,biomesoplenty:redwood_log)
B(2,6,1,biomesoplenty:redwood_log)
B(2,6,2,biomesoplenty:redwood_log)
B(2,6,3,biomesoplenty:redwood_log)
B(2,6,4,biomesoplenty:redwood_log)
B(2,7,1,biomesoplenty:redwood_log)
B(2,7,2,biomesoplenty:redwood_log)
B(2,7,3,biomesoplenty:redwood_log)
B(2,8,-1,biomesoplenty:redwood_leaves[distance=1,persistent=false])
B(2,8,0,biomesoplenty:redwood_leaves[distance=1,persistent=false])
B(2,8,1,biomesoplenty:redwood_log)
B(2,8,2,biomesoplenty:redwood_log)
B(2,8,3,biomesoplenty:redwood_log)
B(2,9,0,biomesoplenty:redwood_leaves[distance=1,persistent=false])
B(2,9,1,biomesoplenty:redwood_log)
B(2,9,2,biomesoplenty:redwood_log)
B(2,9,3,biomesoplenty:redwood_log)
B(2,10,1,biomesoplenty:redwood_log)
B(2,10,2,biomesoplenty:redwood_log)
B(2,10,3,biomesoplenty:redwood_log)
B(2,11,1,biomesoplenty:redwood_log)
B(2,11,2,biomesoplenty:redwood_log)
B(2,11,3,biomesoplenty:redwood_log)
B(2,12,1,biomesoplenty:redwood_log)
B(2,12,2,biomesoplenty:redwood_log)
B(2,12,3,biomesoplenty:redwood_log)
B(2,13,1,biomesoplenty:redwood_log)
B(2,13,2,biomesoplenty:redwood_log)
B(2,13,3,biomesoplenty:redwood_log)
B(2,14,1,biomesoplenty:redwood_log)
B(2,14,2,biomesoplenty:redwood_log)
B(2,14,3,biomesoplenty:redwood_log)
B(2,15,1,biomesoplenty:redwood_log)
B(2,15,2,biomesoplenty:redwood_log)
B(2,15,3,biomesoplenty:redwood_log)
B(2,16,1,biomesoplenty:redwood_log)
B(2,16,2,biomesoplenty:redwood_log)
B(2,16,3,biomesoplenty:redwood_log)
B(2,17,1,biomesoplenty:redwood_log)
B(2,17,2,biomesoplenty:redwood_log)
B(2,17,3,biomesoplenty:redwood_log)
B(2,18,1,biomesoplenty:redwood_log)
B(2,18,2,biomesoplenty:redwood_log)
B(2,18,3,biomesoplenty:redwood_log)
B(2,19,1,biomesoplenty:redwood_log)
B(2,19,2,biomesoplenty:redwood_log)
B(2,19,3,biomesoplenty:redwood_log)
B(2,20,1,biomesoplenty:redwood_log)
B(2,20,2,biomesoplenty:redwood_log)
B(2,20,3,biomesoplenty:redwood_log)
B(2,21,-1,biomesoplenty:redwood_leaves[distance=1,persistent=false])
B(2,21,0,biomesoplenty:redwood_leaves[distance=1,persistent=false])
B(2,21,1,biomesoplenty:redwood_log)
B(2,21,2,biomesoplenty:redwood_log)
B(2,21,3,biomesoplenty:redwood_log)
B(2,21,4,biomesoplenty:redwood_leaves[distance=1,persistent=false])
B(2,21,5,biomesoplenty:redwood_leaves[distance=1,persistent=false])
B(2,22,-2,biomesoplenty:redwood_leaves[distance=1,persistent=false])
B(2,22,-1,biomesoplenty:redwood_leaves[distance=1,persistent=false])
B(2,22,0,biomesoplenty:redwood_leaves[distance=1,persistent=false])
B(2,22,1,biomesoplenty:redwood_log)
B(2,22,2,biomesoplenty:redwood_log)
B(2,22,3,biomesoplenty:redwood_log)
B(2,22,4,biomesoplenty:redwood_leaves[distance=1,persistent=false])
B(2,22,5,biomesoplenty:redwood_leaves[distance=1,persistent=false])
B(2,22,6,biomesoplenty:redwood_leaves[distance=1,persistent=false])
B(2,22,7,biomesoplenty:redwood_leaves[distance=1,persistent=false])
B(2,23,-2,biomesoplenty:redwood_leaves[distance=1,persistent=false])
B(2,23,-1,biomesoplenty:redwood_leaves[distance=1,persistent=false])
B(2,23,0,biomesoplenty:redwood_leaves[distance=1,persistent=false])
B(2,23,1,biomesoplenty:redwood_log)
B(2,23,2,biomesoplenty:redwood_log)
B(2,23,3,biomesoplenty:redwood_log)
B(2,23,4,biomesoplenty:redwood_leaves[distance=1,persistent=false])
B(2,23,5,biomesoplenty:redwood_leaves[distance=1,persistent=false])
B(2,23,6,biomesoplenty:redwood_leaves[distance=1,persistent=false])
B(2,23,7,biomesoplenty:redwood_leaves[distance=1,persistent=false])
B(2,24,-3,biomesoplenty:redwood_leaves[distance=1,persistent=false])
B(2,24,-2,biomesoplenty:redwood_leaves[distance=1,persistent=false])
B(2,24,-1,biomesoplenty:redwood_leaves[distance=1,persistent=false])
B(2,24,0,biomesoplenty:redwood_leaves[distance=1,persistent=false])
B(2,24,1,biomesoplenty:redwood_log)
B(2,24,2,biomesoplenty:redwood_log)
B(2,24,3,biomesoplenty:redwood_log)
B(2,24,4,biomesoplenty:redwood_leaves[distance=1,persistent=false])
B(2,24,5,biomesoplenty:redwood_leaves[distance=1,persistent=false])
B(2,24,6,biomesoplenty:redwood_leaves[distance=1,persistent=false])
B(2,24,7,biomesoplenty:redwood_leaves[distance=1,persistent=false])
B(2,25,-3,biomesoplenty:redwood_leaves[distance=1,persistent=false])
B(2,25,-2,biomesoplenty:redwood_leaves[distance=1,persistent=false])
B(2,25,-1,biomesoplenty:redwood_leaves[distance=1,persistent=false])
B(2,25,0,biomesoplenty:redwood_leaves[distance=1,persistent=false])
B(2,25,1,biomesoplenty:redwood_log)
B(2,25,2,biomesoplenty:redwood_log)
B(2,25,3,biomesoplenty:redwood_log)
B(2,25,4,biomesoplenty:redwood_leaves[distance=1,persistent=false])
B(2,25,5,biomesoplenty:redwood_leaves[distance=1,persistent=false])
B(2,25,6,biomesoplenty:redwood_leaves[distance=1,persistent=false])
B(2,26,-2,biomesoplenty:redwood_leaves[distance=1,persistent=false])
B(2,26,-1,biomesoplenty:redwood_leaves[distance=1,persistent=false])
B(2,26,0,biomesoplenty:redwood_leaves[distance=1,persistent=false])
B(2,26,1,biomesoplenty:redwood_log)
B(2,26,2,biomesoplenty:redwood_log)
B(2,26,3,biomesoplenty:redwood_log)
B(2,26,4,biomesoplenty:redwood_leaves[distance=1,persistent=false])
B(2,26,5,biomesoplenty:redwood_leaves[distance=1,persistent=false])
B(2,26,6,biomesoplenty:redwood_leaves[distance=1,persistent=false])
B(2,26,7,biomesoplenty:redwood_leaves[distance=1,persistent=false])
B(2,27,-1,biomesoplenty:redwood_leaves[distance=1,persistent=false])
B(2,27,0,biomesoplenty:redwood_leaves[distance=1,persistent=false])
B(2,27,1,biomesoplenty:redwood_log)
B(2,27,2,biomesoplenty:redwood_log)
B(2,27,3,biomesoplenty:redwood_log)
B(2,27,4,biomesoplenty:redwood_leaves[distance=1,persistent=false])
B(2,27,5,biomesoplenty:redwood_leaves[distance=1,persistent=false])
B(2,28,-1,biomesoplenty:redwood_leaves[distance=1,persistent=false])
B(2,28,0,biomesoplenty:redwood_leaves[distance=1,persistent=false])
B(2,28,1,biomesoplenty:redwood_log)
B(2,28,2,biomesoplenty:redwood_log)
B(2,28,3,biomesoplenty:redwood_log)
B(2,28,4,biomesoplenty:redwood_leaves[distance=1,persistent=false])
B(2,28,5,biomesoplenty:redwood_leaves[distance=1,persistent=false])
B(2,29,-3,biomesoplenty:redwood_leaves[distance=1,persistent=false])
B(2,29,-2,biomesoplenty:redwood_leaves[distance=1,persistent=false])
B(2,29,-1,biomesoplenty:redwood_leaves[distance=1,persistent=false])
B(2,29,0,biomesoplenty:redwood_leaves[distance=1,persistent=false])
B(2,29,1,biomesoplenty:redwood_log)
B(2,29,2,biomesoplenty:redwood_log)
B(2,29,3,biomesoplenty:redwood_log)
B(2,29,4,biomesoplenty:redwood_leaves[distance=1,persistent=false])
B(2,29,5,biomesoplenty:redwood_leaves[distance=1,persistent=false])
B(2,29,6,biomesoplenty:redwood_leaves[distance=1,persistent=false])
B(2,29,7,biomesoplenty:redwood_leaves[distance=1,persistent=false])
B(2,30,-3,biomesoplenty:redwood_leaves[distance=1,persistent=false])
B(2,30,-2,biomesoplenty:redwood_leaves[distance=1,persistent=false])
B(2,30,-1,biomesoplenty:redwood_leaves[distance=1,persistent=false])
B(2,30,0,biomesoplenty:redwood_leaves[distance=1,persistent=false])
B(2,30,1,biomesoplenty:redwood_log)
B(2,30,2,biomesoplenty:redwood_log)
B(2,30,3,biomesoplenty:redwood_log)
B(2,30,4,biomesoplenty:redwood_leaves[distance=1,persistent=false])
B(2,30,5,biomesoplenty:redwood_leaves[distance=1,persistent=false])
B(2,30,6,biomesoplenty:redwood_leaves[distance=1,persistent=false])
B(2,31,-3,biomesoplenty:redwood_leaves[distance=1,persistent=false])
B(2,31,-2,biomesoplenty:redwood_leaves[distance=1,persistent=false])
B(2,31,-1,biomesoplenty:redwood_leaves[distance=1,persistent=false])
B(2,31,0,biomesoplenty:redwood_leaves[distance=1,persistent=false])
B(2,31,1,biomesoplenty:redwood_log)
B(2,31,2,biomesoplenty:redwood_log)
B(2,31,3,biomesoplenty:redwood_log)
B(2,31,4,biomesoplenty:redwood_leaves[distance=1,persistent=false])
B(2,31,5,biomesoplenty:redwood_leaves[distance=1,persistent=false])
B(2,31,6,biomesoplenty:redwood_leaves[distance=1,persistent=false])
B(2,32,-2,biomesoplenty:redwood_leaves[distance=1,persistent=false])
B(2,32,-1,biomesoplenty:redwood_leaves[distance=1,persistent=false])
B(2,32,0,biomesoplenty:redwood_leaves[distance=1,persistent=false])
B(2,32,1,biomesoplenty:redwood_log)
B(2,32,2,biomesoplenty:redwood_log)
B(2,32,3,biomesoplenty:redwood_log)
B(2,32,4,biomesoplenty:redwood_leaves[distance=1,persistent=false])
B(2,32,5,biomesoplenty:redwood_leaves[distance=1,persistent=false])
B(2,32,6,biomesoplenty:redwood_leaves[distance=1,persistent=false])
B(2,32,7,biomesoplenty:redwood_leaves[distance=1,persistent=false])
B(2,33,-3,biomesoplenty:redwood_leaves[distance=1,persistent=false])
B(2,33,-2,biomesoplenty:redwood_leaves[distance=1,persistent=false])
B(2,33,-1,biomesoplenty:redwood_leaves[distance=1,persistent=false])
B(2,33,0,biomesoplenty:redwood_leaves[distance=1,persistent=false])
B(2,33,1,biomesoplenty:redwood_log)
B(2,33,2,biomesoplenty:redwood_log)
B(2,33,3,biomesoplenty:redwood_log)
B(2,33,4,biomesoplenty:redwood_leaves[distance=1,persistent=false])
B(2,33,5,biomesoplenty:redwood_leaves[distance=1,persistent=false])
B(2,33,6,biomesoplenty:redwood_leaves[distance=1,persistent=false])
B(2,34,-1,biomesoplenty:redwood_leaves[distance=1,persistent=false])
B(2,34,0,biomesoplenty:redwood_leaves[distance=1,persistent=false])
B(2,34,1,biomesoplenty:redwood_log)
B(2,34,2,biomesoplenty:redwood_log)
B(2,34,3,biomesoplenty:redwood_log)
B(2,34,4,biomesoplenty:redwood_leaves[distance=1,persistent=false])
B(2,34,5,biomesoplenty:redwood_leaves[distance=1,persistent=false])
B(2,35,-1,biomesoplenty:redwood_leaves[distance=1,persistent=false])
B(2,35,0,biomesoplenty:redwood_leaves[distance=1,persistent=false])
B(2,35,1,biomesoplenty:redwood_log)
B(2,35,2,biomesoplenty:redwood_log)
B(2,35,3,biomesoplenty:redwood_log)
B(2,35,4,biomesoplenty:redwood_leaves[distance=1,persistent=false])
B(2,35,5,biomesoplenty:redwood_leaves[distance=1,persistent=false])
B(2,36,-2,biomesoplenty:redwood_leaves[distance=1,persistent=false])
B(2,36,-1,biomesoplenty:redwood_leaves[distance=1,persistent=false])
B(2,36,0,biomesoplenty:redwood_leaves[distance=1,persistent=false])
B(2,36,1,biomesoplenty:redwood_log)
B(2,36,2,biomesoplenty:redwood_log)
B(2,36,3,biomesoplenty:redwood_log)
B(2,36,4,biomesoplenty:redwood_leaves[distance=1,persistent=false])
B(2,36,5,biomesoplenty:redwood_leaves[distance=1,persistent=false])
B(2,36,6,biomesoplenty:redwood_leaves[distance=1,persistent=false])
B(2,37,-3,biomesoplenty:redwood_leaves[distance=1,persistent=false])
B(2,37,-2,biomesoplenty:redwood_leaves[distance=1,persistent=false])
B(2,37,-1,biomesoplenty:redwood_leaves[distance=1,persistent=false])
B(2,37,0,biomesoplenty:redwood_leaves[distance=1,persistent=false])
B(2,37,1,biomesoplenty:redwood_log)
B(2,37,2,biomesoplenty:redwood_log)
B(2,37,3,biomesoplenty:redwood_log)
B(2,37,4,biomesoplenty:redwood_leaves[distance=1,persistent=false])
B(2,37,5,biomesoplenty:redwood_leaves[distance=1,persistent=false])
B(2,37,6,biomesoplenty:redwood_leaves[distance=1,persistent=false])
B(2,37,7,biomesoplenty:redwood_leaves[distance=1,persistent=false])
B(2,38,-2,biomesoplenty:redwood_leaves[distance=1,persistent=false])
B(2,38,-1,biomesoplenty:redwood_leaves[distance=1,persistent=false])
B(2,38,0,biomesoplenty:redwood_leaves[distance=1,persistent=false])
B(2,38,1,biomesoplenty:redwood_log)
B(2,38,2,biomesoplenty:redwood_log)
B(2,38,3,biomesoplenty:redwood_log)
B(2,38,4,biomesoplenty:redwood_leaves[distance=1,persistent=false])
B(2,38,5,biomesoplenty:redwood_leaves[distance=1,persistent=false])
B(2,38,6,biomesoplenty:redwood_leaves[distance=1,persistent=false])
B(2,38,7,biomesoplenty:redwood_leaves[distance=1,persistent=false])
B(2,39,-3,biomesoplenty:redwood_leaves[distance=1,persistent=false])
B(2,39,-2,biomesoplenty:redwood_leaves[distance=1,persistent=false])
B(2,39,-1,biomesoplenty:redwood_leaves[distance=1,persistent=false])
B(2,39,0,biomesoplenty:redwood_leaves[distance=1,persistent=false])
B(2,39,1,biomesoplenty:redwood_log)
B(2,39,2,biomesoplenty:redwood_log)
B(2,39,3,biomesoplenty:redwood_log)
B(2,39,4,biomesoplenty:redwood_leaves[distance=1,persistent=false])
B(2,39,5,biomesoplenty:redwood_leaves[distance=1,persistent=false])
B(2,39,6,biomesoplenty:redwood_leaves[distance=1,persistent=false])
B(2,39,7,biomesoplenty:redwood_leaves[distance=1,persistent=false])
B(2,40,-3,biomesoplenty:redwood_leaves[distance=1,persistent=false])
B(2,40,-2,biomesoplenty:redwood_leaves[distance=1,persistent=false])
B(2,40,-1,biomesoplenty:redwood_leaves[distance=1,persistent=false])
B(2,40,0,biomesoplenty:redwood_leaves[distance=1,persistent=false])
B(2,40,1,biomesoplenty:redwood_log)
B(2,40,2,biomesoplenty:redwood_log)
B(2,40,3,biomesoplenty:redwood_log)
B(2,40,4,biomesoplenty:redwood_leaves[distance=1,persistent=false])
B(2,40,5,biomesoplenty:redwood_leaves[distance=1,persistent=false])
B(2,40,6,biomesoplenty:redwood_leaves[distance=1,persistent=false])
B(2,40,7,biomesoplenty:redwood_leaves[distance=1,persistent=false])
B(2,41,-1,biomesoplenty:redwood_leaves[distance=1,persistent=false])
B(2,41,0,biomesoplenty:redwood_leaves[distance=1,persistent=false])
B(2,41,1,biomesoplenty:redwood_leaves[distance=1,persistent=false])
B(2,41,2,biomesoplenty:redwood_leaves[distance=1,persistent=false])
B(2,41,3,biomesoplenty:redwood_leaves[distance=1,persistent=false])
B(2,41,4,biomesoplenty:redwood_leaves[distance=1,persistent=false])
B(2,41,5,biomesoplenty:redwood_leaves[distance=1,persistent=false])
B(2,42,-1,biomesoplenty:redwood_leaves[distance=1,persistent=false])
B(2,42,0,biomesoplenty:redwood_leaves[distance=1,persistent=false])
B(2,42,1,biomesoplenty:redwood_leaves[distance=1,persistent=false])
B(2,42,2,biomesoplenty:redwood_leaves[distance=1,persistent=false])
B(2,42,3,biomesoplenty:redwood_leaves[distance=1,persistent=false])
B(2,42,4,biomesoplenty:redwood_leaves[distance=1,persistent=false])
B(2,42,5,biomesoplenty:redwood_leaves[distance=1,persistent=false])
B(3,0,-1,biomesoplenty:redwood_log)
B(3,0,0,biomesoplenty:redwood_log)
B(3,0,1,biomesoplenty:redwood_log)
B(3,0,2,biomesoplenty:redwood_log)
B(3,0,3,biomesoplenty:redwood_log)
B(3,0,4,biomesoplenty:redwood_log)
B(3,0,5,biomesoplenty:redwood_log)
B(3,0,6,biomesoplenty:redwood_log)
B(3,1,-1,biomesoplenty:redwood_log)
B(3,1,0,biomesoplenty:redwood_log)
B(3,1,1,biomesoplenty:redwood_log)
B(3,1,2,biomesoplenty:redwood_log)
B(3,1,3,biomesoplenty:redwood_log)
B(3,1,4,biomesoplenty:redwood_log)
B(3,1,5,biomesoplenty:redwood_log)
B(3,1,6,biomesoplenty:redwood_log)
B(3,1,7,biomesoplenty:redwood_leaves[distance=1,persistent=false])
B(3,1,8,biomesoplenty:redwood_leaves[distance=1,persistent=false])
B(3,2,-1,biomesoplenty:redwood_log)
B(3,2,0,biomesoplenty:redwood_log)
B(3,2,1,biomesoplenty:redwood_log)
B(3,2,2,biomesoplenty:redwood_log)
B(3,2,3,biomesoplenty:redwood_log)
B(3,2,4,biomesoplenty:redwood_log)
B(3,2,5,biomesoplenty:redwood_log)
B(3,2,6,biomesoplenty:redwood_leaves[distance=1,persistent=false])
B(3,2,7,biomesoplenty:redwood_leaves[distance=1,persistent=false])
B(3,3,-3,biomesoplenty:redwood_leaves[distance=1,persistent=false])
B(3,3,-2,biomesoplenty:redwood_leaves[distance=1,persistent=false])
B(3,3,-1,biomesoplenty:redwood_leaves[distance=1,persistent=false])
B(3,3,0,biomesoplenty:redwood_log)
B(3,3,1,biomesoplenty:redwood_log)
B(3,3,2,biomesoplenty:redwood_log)
B(3,3,3,biomesoplenty:redwood_log)
B(3,3,4,biomesoplenty:redwood_log)
B(3,4,-2,biomesoplenty:redwood_leaves[distance=1,persistent=false])
B(3,4,-1,biomesoplenty:redwood_leaves[distance=1,persistent=false])
B(3,4,0,biomesoplenty:redwood_log)
B(3,4,1,biomesoplenty:redwood_log)
B(3,4,2,biomesoplenty:redwood_log)
B(3,4,3,biomesoplenty:redwood_log)
B(3,4,4,biomesoplenty:redwood_log)
B(3,5,0,biomesoplenty:redwood_log)
B(3,5,1,biomesoplenty:redwood_log)
B(3,5,2,biomesoplenty:redwood_log)
B(3,5,3,biomesoplenty:redwood_log)
B(3,5,4,biomesoplenty:redwood_leaves[distance=1,persistent=false])
B(3,5,5,biomesoplenty:redwood_leaves[distance=1,persistent=false])
B(3,6,1,biomesoplenty:redwood_log)
B(3,6,2,biomesoplenty:redwood_log)
B(3,6,3,biomesoplenty:redwood_log)
B(3,6,4,biomesoplenty:redwood_leaves[distance=1,persistent=false])
B(3,7,1,biomesoplenty:redwood_log)
B(3,7,2,biomesoplenty:redwood_log)
B(3,7,3,biomesoplenty:redwood_log)
B(3,8,-1,biomesoplenty:redwood_leaves[distance=1,persistent=false])
B(3,8,0,biomesoplenty:redwood_leaves[distance=1,persistent=false])
B(3,8,1,biomesoplenty:redwood_log)
B(3,8,2,biomesoplenty:redwood_log)
B(3,8,3,biomesoplenty:redwood_leaves[distance=1,persistent=false])
B(3,9,0,biomesoplenty:redwood_leaves[distance=1,persistent=false])
B(3,9,1,biomesoplenty:redwood_leaves[distance=1,persistent=false])
B(3,9,2,biomesoplenty:redwood_log)
B(3,10,2,biomesoplenty:redwood_log)
B(3,11,2,biomesoplenty:redwood_log)
B(3,12,2,biomesoplenty:redwood_log)
B(3,13,2,biomesoplenty:redwood_log)
B(3,14,2,biomesoplenty:redwood_log)
B(3,15,2,biomesoplenty:redwood_log)
B(3,16,2,biomesoplenty:redwood_log)
B(3,17,2,biomesoplenty:redwood_log)
B(3,18,2,biomesoplenty:redwood_log)
B(3,19,2,biomesoplenty:redwood_log)
B(3,20,2,biomesoplenty:redwood_log)
B(3,21,-1,biomesoplenty:redwood_leaves[distance=1,persistent=false])
B(3,21,0,biomesoplenty:redwood_leaves[distance=1,persistent=false])
B(3,21,1,biomesoplenty:redwood_leaves[distance=1,persistent=false])
B(3,21,2,biomesoplenty:redwood_log)
B(3,21,3,biomesoplenty:redwood_leaves[distance=1,persistent=false])
B(3,21,4,biomesoplenty:redwood_leaves[distance=1,persistent=false])
B(3,21,5,biomesoplenty:redwood_leaves[distance=1,persistent=false])
B(3,22,-2,biomesoplenty:redwood_leaves[distance=1,persistent=false])
B(3,22,-1,biomesoplenty:redwood_leaves[distance=1,persistent=false])
B(3,22,0,biomesoplenty:redwood_leaves[distance=1,persistent=false])
B(3,22,1,biomesoplenty:redwood_leaves[distance=1,persistent=false])
B(3,22,2,biomesoplenty:redwood_log)
B(3,22,3,biomesoplenty:redwood_leaves[distance=1,persistent=false])
B(3,22,4,biomesoplenty:redwood_leaves[distance=1,persistent=false])
B(3,22,5,biomesoplenty:redwood_leaves[distance=1,persistent=false])
B(3,22,6,biomesoplenty:redwood_leaves[distance=1,persistent=false])
B(3,22,7,biomesoplenty:redwood_leaves[distance=1,persistent=false])
B(3,23,-3,biomesoplenty:redwood_leaves[distance=1,persistent=false])
B(3,23,-2,biomesoplenty:redwood_leaves[distance=1,persistent=false])
B(3,23,-1,biomesoplenty:redwood_leaves[distance=1,persistent=false])
B(3,23,0,biomesoplenty:redwood_leaves[distance=1,persistent=false])
B(3,23,1,biomesoplenty:redwood_leaves[distance=1,persistent=false])
B(3,23,2,biomesoplenty:redwood_log)
B(3,23,3,biomesoplenty:redwood_leaves[distance=1,persistent=false])
B(3,23,4,biomesoplenty:redwood_leaves[distance=1,persistent=false])
B(3,23,5,biomesoplenty:redwood_leaves[distance=1,persistent=false])
B(3,23,6,biomesoplenty:redwood_leaves[distance=1,persistent=false])
B(3,23,7,biomesoplenty:redwood_leaves[distance=1,persistent=false])
B(3,24,-2,biomesoplenty:redwood_leaves[distance=1,persistent=false])
B(3,24,-1,biomesoplenty:redwood_leaves[distance=1,persistent=false])
B(3,24,0,biomesoplenty:redwood_leaves[distance=1,persistent=false])
B(3,24,1,biomesoplenty:redwood_leaves[distance=1,persistent=false])
B(3,24,2,biomesoplenty:redwood_log)
B(3,24,3,biomesoplenty:redwood_leaves[distance=1,persistent=false])
B(3,24,4,biomesoplenty:redwood_leaves[distance=1,persistent=false])
B(3,24,5,biomesoplenty:redwood_leaves[distance=1,persistent=false])
B(3,24,6,biomesoplenty:redwood_leaves[distance=1,persistent=false])
B(3,24,7,biomesoplenty:redwood_leaves[distance=1,persistent=false])
B(3,25,-3,biomesoplenty:redwood_leaves[distance=1,persistent=false])
B(3,25,-2,biomesoplenty:redwood_leaves[distance=1,persistent=false])
B(3,25,-1,biomesoplenty:redwood_leaves[distance=1,persistent=false])
B(3,25,0,biomesoplenty:redwood_leaves[distance=1,persistent=false])
B(3,25,1,biomesoplenty:redwood_leaves[distance=1,persistent=false])
B(3,25,2,biomesoplenty:redwood_log)
B(3,25,3,biomesoplenty:redwood_leaves[distance=1,persistent=false])
B(3,25,4,biomesoplenty:redwood_leaves[distance=1,persistent=false])
B(3,25,5,biomesoplenty:redwood_leaves[distance=1,persistent=false])
B(3,25,6,biomesoplenty:redwood_leaves[distance=1,persistent=false])
B(3,25,7,biomesoplenty:redwood_leaves[distance=1,persistent=false])
B(3,26,-3,biomesoplenty:redwood_leaves[distance=1,persistent=false])
B(3,26,-2,biomesoplenty:redwood_leaves[distance=1,persistent=false])
B(3,26,-1,biomesoplenty:redwood_leaves[distance=1,persistent=false])
B(3,26,0,biomesoplenty:redwood_leaves[distance=1,persistent=false])
B(3,26,1,biomesoplenty:redwood_leaves[distance=1,persistent=false])
B(3,26,2,biomesoplenty:redwood_log)
B(3,26,3,biomesoplenty:redwood_leaves[distance=1,persistent=false])
B(3,26,4,biomesoplenty:redwood_leaves[distance=1,persistent=false])
B(3,26,5,biomesoplenty:redwood_leaves[distance=1,persistent=false])
B(3,26,6,biomesoplenty:redwood_leaves[distance=1,persistent=false])
B(3,26,7,biomesoplenty:redwood_leaves[distance=1,persistent=false])
B(3,27,-1,biomesoplenty:redwood_leaves[distance=1,persistent=false])
B(3,27,0,biomesoplenty:redwood_leaves[distance=1,persistent=false])
B(3,27,1,biomesoplenty:redwood_leaves[distance=1,persistent=false])
B(3,27,2,biomesoplenty:redwood_log)
B(3,27,3,biomesoplenty:redwood_leaves[distance=1,persistent=false])
B(3,27,4,biomesoplenty:redwood_leaves[distance=1,persistent=false])
B(3,27,5,biomesoplenty:redwood_leaves[distance=1,persistent=false])
B(3,28,-1,biomesoplenty:redwood_leaves[distance=1,persistent=false])
B(3,28,0,biomesoplenty:redwood_leaves[distance=1,persistent=false])
B(3,28,1,biomesoplenty:redwood_leaves[distance=1,persistent=false])
B(3,28,2,biomesoplenty:redwood_log)
B(3,28,3,biomesoplenty:redwood_leaves[distance=1,persistent=false])
B(3,28,4,biomesoplenty:redwood_leaves[distance=1,persistent=false])
B(3,28,5,biomesoplenty:redwood_leaves[distance=1,persistent=false])
B(3,29,-3,biomesoplenty:redwood_leaves[distance=1,persistent=false])
B(3,29,-2,biomesoplenty:redwood_leaves[distance=1,persistent=false])
B(3,29,-1,biomesoplenty:redwood_leaves[distance=1,persistent=false])
B(3,29,0,biomesoplenty:redwood_leaves[distance=1,persistent=false])
B(3,29,1,biomesoplenty:redwood_leaves[distance=1,persistent=false])
B(3,29,2,biomesoplenty:redwood_log)
B(3,29,3,biomesoplenty:redwood_leaves[distance=1,persistent=false])
B(3,29,4,biomesoplenty:redwood_leaves[distance=1,persistent=false])
B(3,29,5,biomesoplenty:redwood_leaves[distance=1,persistent=false])
B(3,29,6,biomesoplenty:redwood_leaves[distance=1,persistent=false])
B(3,29,7,biomesoplenty:redwood_leaves[distance=1,persistent=false])
B(3,30,-2,biomesoplenty:redwood_leaves[distance=1,persistent=false])
B(3,30,-1,biomesoplenty:redwood_leaves[distance=1,persistent=false])
B(3,30,0,biomesoplenty:redwood_leaves[distance=1,persistent=false])
B(3,30,1,biomesoplenty:redwood_leaves[distance=1,persistent=false])
B(3,30,2,biomesoplenty:redwood_log)
B(3,30,3,biomesoplenty:redwood_leaves[distance=1,persistent=false])
B(3,30,4,biomesoplenty:redwood_leaves[distance=1,persistent=false])
B(3,30,5,biomesoplenty:redwood_leaves[distance=1,persistent=false])
B(3,30,6,biomesoplenty:redwood_leaves[distance=1,persistent=false])
B(3,30,7,biomesoplenty:redwood_leaves[distance=1,persistent=false])
B(3,31,-3,biomesoplenty:redwood_leaves[distance=1,persistent=false])
B(3,31,-2,biomesoplenty:redwood_leaves[distance=1,persistent=false])
B(3,31,-1,biomesoplenty:redwood_leaves[distance=1,persistent=false])
B(3,31,0,biomesoplenty:redwood_leaves[distance=1,persistent=false])
B(3,31,1,biomesoplenty:redwood_leaves[distance=1,persistent=false])
B(3,31,2,biomesoplenty:redwood_log)
B(3,31,3,biomesoplenty:redwood_leaves[distance=1,persistent=false])
B(3,31,4,biomesoplenty:redwood_leaves[distance=1,persistent=false])
B(3,31,5,biomesoplenty:redwood_leaves[distance=1,persistent=false])
B(3,31,6,biomesoplenty:redwood_leaves[distance=1,persistent=false])
B(3,31,7,biomesoplenty:redwood_leaves[distance=1,persistent=false])
B(3,32,-3,biomesoplenty:redwood_leaves[distance=1,persistent=false])
B(3,32,-2,biomesoplenty:redwood_leaves[distance=1,persistent=false])
B(3,32,-1,biomesoplenty:redwood_leaves[distance=1,persistent=false])
B(3,32,0,biomesoplenty:redwood_leaves[distance=1,persistent=false])
B(3,32,1,biomesoplenty:redwood_leaves[distance=1,persistent=false])
B(3,32,2,biomesoplenty:redwood_log)
B(3,32,3,biomesoplenty:redwood_leaves[distance=1,persistent=false])
B(3,32,4,biomesoplenty:redwood_leaves[distance=1,persistent=false])
B(3,32,5,biomesoplenty:redwood_leaves[distance=1,persistent=false])
B(3,32,6,biomesoplenty:redwood_leaves[distance=1,persistent=false])
B(3,33,-3,biomesoplenty:redwood_leaves[distance=1,persistent=false])
B(3,33,-2,biomesoplenty:redwood_leaves[distance=1,persistent=false])
B(3,33,-1,biomesoplenty:redwood_leaves[distance=1,persistent=false])
B(3,33,0,biomesoplenty:redwood_leaves[distance=1,persistent=false])
B(3,33,1,biomesoplenty:redwood_leaves[distance=1,persistent=false])
B(3,33,2,biomesoplenty:redwood_log)
B(3,33,3,biomesoplenty:redwood_leaves[distance=1,persistent=false])
B(3,33,4,biomesoplenty:redwood_leaves[distance=1,persistent=false])
B(3,33,5,biomesoplenty:redwood_leaves[distance=1,persistent=false])
B(3,33,6,biomesoplenty:redwood_leaves[distance=1,persistent=false])
B(3,33,7,biomesoplenty:redwood_leaves[distance=1,persistent=false])
B(3,34,-1,biomesoplenty:redwood_leaves[distance=1,persistent=false])
B(3,34,0,biomesoplenty:redwood_leaves[distance=1,persistent=false])
B(3,34,1,biomesoplenty:redwood_leaves[distance=1,persistent=false])
B(3,34,2,biomesoplenty:redwood_log)
B(3,34,3,biomesoplenty:redwood_leaves[distance=1,persistent=false])
B(3,34,4,biomesoplenty:redwood_leaves[distance=1,persistent=false])
B(3,34,5,biomesoplenty:redwood_leaves[distance=1,persistent=false])
B(3,35,-1,biomesoplenty:redwood_leaves[distance=1,persistent=false])
B(3,35,0,biomesoplenty:redwood_leaves[distance=1,persistent=false])
B(3,35,1,biomesoplenty:redwood_leaves[distance=1,persistent=false])
B(3,35,2,biomesoplenty:redwood_log)
B(3,35,3,biomesoplenty:redwood_leaves[distance=1,persistent=false])
B(3,35,4,biomesoplenty:redwood_leaves[distance=1,persistent=false])
B(3,35,5,biomesoplenty:redwood_leaves[distance=1,persistent=false])
B(3,36,-3,biomesoplenty:redwood_leaves[distance=1,persistent=false])
B(3,36,-2,biomesoplenty:redwood_leaves[distance=1,persistent=false])
B(3,36,-1,biomesoplenty:redwood_leaves[distance=1,persistent=false])
B(3,36,0,biomesoplenty:redwood_leaves[distance=1,persistent=false])
B(3,36,1,biomesoplenty:redwood_leaves[distance=1,persistent=false])
B(3,36,2,biomesoplenty:redwood_log)
B(3,36,3,biomesoplenty:redwood_leaves[distance=1,persistent=false])
B(3,36,4,biomesoplenty:redwood_leaves[distance=1,persistent=false])
B(3,36,5,biomesoplenty:redwood_leaves[distance=1,persistent=false])
B(3,36,6,biomesoplenty:redwood_leaves[distance=1,persistent=false])
B(3,36,7,biomesoplenty:redwood_leaves[distance=1,persistent=false])
B(3,37,-3,biomesoplenty:redwood_leaves[distance=1,persistent=false])
B(3,37,-2,biomesoplenty:redwood_leaves[distance=1,persistent=false])
B(3,37,-1,biomesoplenty:redwood_leaves[distance=1,persistent=false])
B(3,37,0,biomesoplenty:redwood_leaves[distance=1,persistent=false])
B(3,37,1,biomesoplenty:redwood_leaves[distance=1,persistent=false])
B(3,37,2,biomesoplenty:redwood_log)
B(3,37,3,biomesoplenty:redwood_leaves[distance=1,persistent=false])
B(3,37,4,biomesoplenty:redwood_leaves[distance=1,persistent=false])
B(3,37,5,biomesoplenty:redwood_leaves[distance=1,persistent=false])
B(3,37,6,biomesoplenty:redwood_leaves[distance=1,persistent=false])
B(3,37,7,biomesoplenty:redwood_leaves[distance=1,persistent=false])
B(3,38,-3,biomesoplenty:redwood_leaves[distance=1,persistent=false])
B(3,38,-2,biomesoplenty:redwood_leaves[distance=1,persistent=false])
B(3,38,-1,biomesoplenty:redwood_leaves[distance=1,persistent=false])
B(3,38,0,biomesoplenty:redwood_leaves[distance=1,persistent=false])
B(3,38,1,biomesoplenty:redwood_leaves[distance=1,persistent=false])
B(3,38,2,biomesoplenty:redwood_log)
B(3,38,3,biomesoplenty:redwood_leaves[distance=1,persistent=false])
B(3,38,4,biomesoplenty:redwood_leaves[distance=1,persistent=false])
B(3,38,5,biomesoplenty:redwood_leaves[distance=1,persistent=false])
B(3,38,6,biomesoplenty:redwood_leaves[distance=1,persistent=false])
B(3,38,7,biomesoplenty:redwood_leaves[distance=1,persistent=false])
B(3,39,-3,biomesoplenty:redwood_leaves[distance=1,persistent=false])
B(3,39,-2,biomesoplenty:redwood_leaves[distance=1,persistent=false])
B(3,39,-1,biomesoplenty:redwood_leaves[distance=1,persistent=false])
B(3,39,0,biomesoplenty:redwood_leaves[distance=1,persistent=false])
B(3,39,1,biomesoplenty:redwood_leaves[distance=1,persistent=false])
B(3,39,2,biomesoplenty:redwood_log)
B(3,39,3,biomesoplenty:redwood_leaves[distance=1,persistent=false])
B(3,39,4,biomesoplenty:redwood_leaves[distance=1,persistent=false])
B(3,39,5,biomesoplenty:redwood_leaves[distance=1,persistent=false])
B(3,39,6,biomesoplenty:redwood_leaves[distance=1,persistent=false])
B(3,39,7,biomesoplenty:redwood_leaves[distance=1,persistent=false])
B(3,40,-2,biomesoplenty:redwood_leaves[distance=1,persistent=false])
B(3,40,-1,biomesoplenty:redwood_leaves[distance=1,persistent=false])
B(3,40,0,biomesoplenty:redwood_leaves[distance=1,persistent=false])
B(3,40,1,biomesoplenty:redwood_leaves[distance=1,persistent=false])
B(3,40,2,biomesoplenty:redwood_log)
B(3,40,3,biomesoplenty:redwood_leaves[distance=1,persistent=false])
B(3,40,4,biomesoplenty:redwood_leaves[distance=1,persistent=false])
B(3,40,5,biomesoplenty:redwood_leaves[distance=1,persistent=false])
B(3,40,6,biomesoplenty:redwood_leaves[distance=1,persistent=false])
B(3,41,-1,biomesoplenty:redwood_leaves[distance=1,persistent=false])
B(3,41,0,biomesoplenty:redwood_leaves[distance=1,persistent=false])
B(3,41,1,biomesoplenty:redwood_leaves[distance=1,persistent=false])
B(3,41,2,biomesoplenty:redwood_leaves[distance=1,persistent=false])
B(3,41,3,biomesoplenty:redwood_leaves[distance=1,persistent=false])
B(3,41,4,biomesoplenty:redwood_leaves[distance=1,persistent=false])
B(3,41,5,biomesoplenty:redwood_leaves[distance=1,persistent=false])
B(3,42,-1,biomesoplenty:redwood_leaves[distance=1,persistent=false])
B(3,42,0,biomesoplenty:redwood_leaves[distance=1,persistent=false])
B(3,42,1,biomesoplenty:redwood_leaves[distance=1,persistent=false])
B(3,42,2,biomesoplenty:redwood_leaves[distance=1,persistent=false])
B(3,42,3,biomesoplenty:redwood_leaves[distance=1,persistent=false])
B(3,42,4,biomesoplenty:redwood_leaves[distance=1,persistent=false])
B(3,42,5,biomesoplenty:redwood_leaves[distance=1,persistent=false])
B(4,0,-1,biomesoplenty:redwood_log)
B(4,0,0,biomesoplenty:redwood_log)
B(4,0,1,biomesoplenty:redwood_log)
B(4,0,2,biomesoplenty:redwood_log)
B(4,0,3,biomesoplenty:redwood_log)
B(4,0,4,biomesoplenty:redwood_log)
B(4,0,5,biomesoplenty:redwood_log)
B(4,1,-1,biomesoplenty:redwood_log)
B(4,1,0,biomesoplenty:redwood_log)
B(4,1,1,biomesoplenty:redwood_log)
B(4,1,2,biomesoplenty:redwood_log)
B(4,1,3,biomesoplenty:redwood_log)
B(4,1,4,biomesoplenty:redwood_log)
B(4,1,5,biomesoplenty:redwood_log)
B(4,1,6,biomesoplenty:redwood_leaves[distance=1,persistent=false])
B(4,1,7,biomesoplenty:redwood_leaves[distance=1,persistent=false])
B(4,1,8,biomesoplenty:redwood_leaves[distance=1,persistent=false])
B(4,2,-1,biomesoplenty:redwood_log)
B(4,2,1,biomesoplenty:redwood_log)
B(4,2,2,biomesoplenty:redwood_log)
B(4,2,3,biomesoplenty:redwood_log)
B(4,2,5,biomesoplenty:redwood_leaves[distance=1,persistent=false])
B(4,2,6,biomesoplenty:redwood_leaves[distance=1,persistent=false])
B(4,3,-3,biomesoplenty:redwood_leaves[distance=1,persistent=false])
B(4,3,-2,biomesoplenty:redwood_leaves[distance=1,persistent=false])
B(4,3,-1,biomesoplenty:redwood_leaves[distance=1,persistent=false])
B(4,3,0,biomesoplenty:redwood_leaves[distance=1,persistent=false])
B(4,3,1,biomesoplenty:redwood_log)
B(4,3,2,biomesoplenty:redwood_log)
B(4,3,3,biomesoplenty:redwood_log)
B(4,4,-2,biomesoplenty:redwood_leaves[distance=1,persistent=false])
B(4,4,-1,biomesoplenty:redwood_leaves[distance=1,persistent=false])
B(4,4,0,biomesoplenty:redwood_leaves[distance=1,persistent=false])
B(4,4,1,biomesoplenty:redwood_log)
B(4,4,2,biomesoplenty:redwood_log)
B(4,4,3,biomesoplenty:redwood_log)
B(4,5,1,biomesoplenty:redwood_log)
B(4,5,2,biomesoplenty:redwood_log)
B(4,5,3,biomesoplenty:redwood_log)
B(4,5,4,biomesoplenty:redwood_leaves[distance=1,persistent=false])
B(4,5,5,biomesoplenty:redwood_leaves[distance=1,persistent=false])
B(4,6,2,biomesoplenty:redwood_leaves[distance=1,persistent=false])
B(4,6,3,biomesoplenty:redwood_leaves[distance=1,persistent=false])
B(4,6,4,biomesoplenty:redwood_leaves[distance=1,persistent=false])
B(4,8,-1,biomesoplenty:redwood_leaves[distance=1,persistent=false])
B(4,8,0,biomesoplenty:redwood_leaves[distance=1,persistent=false])
B(4,8,1,biomesoplenty:redwood_leaves[distance=1,persistent=false])
B(4,8,2,biomesoplenty:redwood_leaves[distance=1,persistent=false])
B(4,8,3,biomesoplenty:redwood_leaves[distance=1,persistent=false])
B(4,9,0,biomesoplenty:redwood_leaves[distance=1,persistent=false])
B(4,9,1,biomesoplenty:redwood_leaves[distance=1,persistent=false])
B(4,21,-1,biomesoplenty:redwood_leaves[distance=1,persistent=false])
B(4,21,0,biomesoplenty:redwood_leaves[distance=1,persistent=false])
B(4,21,1,biomesoplenty:redwood_leaves[distance=1,persistent=false])
B(4,21,2,biomesoplenty:redwood_leaves[distance=1,persistent=false])
B(4,21,3,biomesoplenty:redwood_leaves[distance=1,persistent=false])
B(4,21,4,biomesoplenty:redwood_leaves[distance=1,persistent=false])
B(4,21,5,biomesoplenty:redwood_leaves[distance=1,persistent=false])
B(4,22,-2,biomesoplenty:redwood_leaves[distance=1,persistent=false])
B(4,22,-1,biomesoplenty:redwood_leaves[distance=1,persistent=false])
B(4,22,0,biomesoplenty:redwood_leaves[distance=1,persistent=false])
B(4,22,1,biomesoplenty:redwood_leaves[distance=1,persistent=false])
B(4,22,2,biomesoplenty:redwood_leaves[distance=1,persistent=false])
B(4,22,3,biomesoplenty:redwood_leaves[distance=1,persistent=false])
B(4,22,4,biomesoplenty:redwood_leaves[distance=1,persistent=false])
B(4,22,5,biomesoplenty:redwood_leaves[distance=1,persistent=false])
B(4,22,6,biomesoplenty:redwood_leaves[distance=1,persistent=false])
B(4,23,-2,biomesoplenty:redwood_leaves[distance=1,persistent=false])
B(4,23,-1,biomesoplenty:redwood_leaves[distance=1,persistent=false])
B(4,23,0,biomesoplenty:redwood_leaves[distance=1,persistent=false])
B(4,23,1,biomesoplenty:redwood_leaves[distance=1,persistent=false])
B(4,23,2,biomesoplenty:redwood_leaves[distance=1,persistent=false])
B(4,23,3,biomesoplenty:redwood_leaves[distance=1,persistent=false])
B(4,23,4,biomesoplenty:redwood_leaves[distance=1,persistent=false])
B(4,23,5,biomesoplenty:redwood_leaves[distance=1,persistent=false])
B(4,23,6,biomesoplenty:redwood_leaves[distance=1,persistent=false])
B(4,24,-3,biomesoplenty:redwood_leaves[distance=1,persistent=false])
B(4,24,-2,biomesoplenty:redwood_leaves[distance=1,persistent=false])
B(4,24,-1,biomesoplenty:redwood_leaves[distance=1,persistent=false])
B(4,24,0,biomesoplenty:redwood_leaves[distance=1,persistent=false])
B(4,24,1,biomesoplenty:redwood_leaves[distance=1,persistent=false])
B(4,24,2,biomesoplenty:redwood_leaves[distance=1,persistent=false])
B(4,24,3,biomesoplenty:redwood_leaves[distance=1,persistent=false])
B(4,24,4,biomesoplenty:redwood_leaves[distance=1,persistent=false])
B(4,24,5,biomesoplenty:redwood_leaves[distance=1,persistent=false])
B(4,24,6,biomesoplenty:redwood_leaves[distance=1,persistent=false])
B(4,24,7,biomesoplenty:redwood_leaves[distance=1,persistent=false])
B(4,25,-3,biomesoplenty:redwood_leaves[distance=1,persistent=false])
B(4,25,-2,biomesoplenty:redwood_leaves[distance=1,persistent=false])
B(4,25,-1,biomesoplenty:redwood_leaves[distance=1,persistent=false])
B(4,25,0,biomesoplenty:redwood_leaves[distance=1,persistent=false])
B(4,25,1,biomesoplenty:redwood_leaves[distance=1,persistent=false])
B(4,25,2,biomesoplenty:redwood_leaves[distance=1,persistent=false])
B(4,25,3,biomesoplenty:redwood_leaves[distance=1,persistent=false])
B(4,25,4,biomesoplenty:redwood_leaves[distance=1,persistent=false])
B(4,25,5,biomesoplenty:redwood_leaves[distance=1,persistent=false])
B(4,25,6,biomesoplenty:redwood_leaves[distance=1,persistent=false])
B(4,26,-3,biomesoplenty:redwood_leaves[distance=1,persistent=false])
B(4,26,-2,biomesoplenty:redwood_leaves[distance=1,persistent=false])
B(4,26,-1,biomesoplenty:redwood_leaves[distance=1,persistent=false])
B(4,26,0,biomesoplenty:redwood_leaves[distance=1,persistent=false])
B(4,26,1,biomesoplenty:redwood_leaves[distance=1,persistent=false])
B(4,26,2,biomesoplenty:redwood_leaves[distance=1,persistent=false])
B(4,26,3,biomesoplenty:redwood_leaves[distance=1,persistent=false])
B(4,26,4,biomesoplenty:redwood_leaves[distance=1,persistent=false])
B(4,26,5,biomesoplenty:redwood_leaves[distance=1,persistent=false])
B(4,26,6,biomesoplenty:redwood_leaves[distance=1,persistent=false])
B(4,26,7,biomesoplenty:redwood_leaves[distance=1,persistent=false])
B(4,27,-1,biomesoplenty:redwood_leaves[distance=1,persistent=false])
B(4,27,0,biomesoplenty:redwood_leaves[distance=1,persistent=false])
B(4,27,1,biomesoplenty:redwood_leaves[distance=1,persistent=false])
B(4,27,2,biomesoplenty:redwood_leaves[distance=1,persistent=false])
B(4,27,3,biomesoplenty:redwood_leaves[distance=1,persistent=false])
B(4,27,4,biomesoplenty:redwood_leaves[distance=1,persistent=false])
B(4,27,5,biomesoplenty:redwood_leaves[distance=1,persistent=false])
B(4,28,-1,biomesoplenty:redwood_leaves[distance=1,persistent=false])
B(4,28,0,biomesoplenty:redwood_leaves[distance=1,persistent=false])
B(4,28,1,biomesoplenty:redwood_leaves[distance=1,persistent=false])
B(4,28,2,biomesoplenty:redwood_leaves[distance=1,persistent=false])
B(4,28,3,biomesoplenty:redwood_leaves[distance=1,persistent=false])
B(4,28,4,biomesoplenty:redwood_leaves[distance=1,persistent=false])
B(4,28,5,biomesoplenty:redwood_leaves[distance=1,persistent=false])
B(4,29,-3,biomesoplenty:redwood_leaves[distance=1,persistent=false])
B(4,29,-2,biomesoplenty:redwood_leaves[distance=1,persistent=false])
B(4,29,-1,biomesoplenty:redwood_leaves[distance=1,persistent=false])
B(4,29,0,biomesoplenty:redwood_leaves[distance=1,persistent=false])
B(4,29,1,biomesoplenty:redwood_leaves[distance=1,persistent=false])
B(4,29,2,biomesoplenty:redwood_leaves[distance=1,persistent=false])
B(4,29,3,biomesoplenty:redwood_leaves[distance=1,persistent=false])
B(4,29,4,biomesoplenty:redwood_leaves[distance=1,persistent=false])
B(4,29,5,biomesoplenty:redwood_leaves[distance=1,persistent=false])
B(4,29,6,biomesoplenty:redwood_leaves[distance=1,persistent=false])
B(4,29,7,biomesoplenty:redwood_leaves[distance=1,persistent=false])
B(4,30,-2,biomesoplenty:redwood_leaves[distance=1,persistent=false])
B(4,30,-1,biomesoplenty:redwood_leaves[distance=1,persistent=false])
B(4,30,0,biomesoplenty:redwood_leaves[distance=1,persistent=false])
B(4,30,1,biomesoplenty:redwood_leaves[distance=1,persistent=false])
B(4,30,2,biomesoplenty:redwood_leaves[distance=1,persistent=false])
B(4,30,3,biomesoplenty:redwood_leaves[distance=1,persistent=false])
B(4,30,4,biomesoplenty:redwood_leaves[distance=1,persistent=false])
B(4,30,5,biomesoplenty:redwood_leaves[distance=1,persistent=false])
B(4,30,6,biomesoplenty:redwood_leaves[distance=1,persistent=false])
B(4,30,7,biomesoplenty:redwood_leaves[distance=1,persistent=false])
B(4,31,-2,biomesoplenty:redwood_leaves[distance=1,persistent=false])
B(4,31,-1,biomesoplenty:redwood_leaves[distance=1,persistent=false])
B(4,31,0,biomesoplenty:redwood_leaves[distance=1,persistent=false])
B(4,31,1,biomesoplenty:redwood_leaves[distance=1,persistent=false])
B(4,31,2,biomesoplenty:redwood_leaves[distance=1,persistent=false])
B(4,31,3,biomesoplenty:redwood_leaves[distance=1,persistent=false])
B(4,31,4,biomesoplenty:redwood_leaves[distance=1,persistent=false])
B(4,31,5,biomesoplenty:redwood_leaves[distance=1,persistent=false])
B(4,31,6,biomesoplenty:redwood_leaves[distance=1,persistent=false])
B(4,31,7,biomesoplenty:redwood_leaves[distance=1,persistent=false])
