
#######################################################################
# +-----------------------------------------------------------------+ #
# |                            BO4 object                           | #
# +-----------------------------------------------------------------+ #
#######################################################################

Author: Unknown

Description: No description given

SettingsMode: WriteWithoutComments


#######################################################################
# +-----------------------------------------------------------------+ #
# |                          Main settings                          | #
# +-----------------------------------------------------------------+ #
#######################################################################

FixedRotation: 

Frequency: 0

SpawnHeight: highestBlock

UseCenterForHighestBlock: true

##############################
# Height Limits for the BO4. #
##############################

MinHeight: 0

MaxHeight: 255

InheritBO3: 

InheritBO3Rotation: NORTH

OverrideChildSettings: true

OverrideParentHeight: false

CanOverride: false

BranchFrequency: 0

BranchFrequencyGroup: 

MustBeBelowOther: false

MustBeInside: 

CannotBeInside: 

ReplacesBO3: 

MustBeInsideWorldBorders: false

CanSpawnOnWater: true

SpawnOnWaterOnly: false

SpawnUnderWater: false

SpawnAtWaterLevel: false

HeightOffset: 0

RemoveAir: true

ReplaceAbove: 

ReplaceBelow: 

ReplaceWithBiomeBlocks: true

ReplaceWithSurfaceBlock: GRASS

ReplaceWithGroundBlock: DIRT

ReplaceWithStoneBlock: STONE

SmoothRadius: 0

SmoothHeightOffset: 0

SmoothStartTop: false

SmoothStartWood: false

SmoothingSurfaceBlock: 

SmoothingGroundBlock: 

BO3Group: 

IsSpawnPoint: false

DoReplaceBlocks: true


#######################################################################
# +-----------------------------------------------------------------+ #
# |                              Blocks                             | #
# +-----------------------------------------------------------------+ #
#######################################################################

B(-8,0,-1,minecraft:granite)
B(-8,1,-1,minecraft:granite)
B(-8,2,-1,minecraft:granite)
B(-8,3,-1,minecraft:granite)
B(-8,4,-1,minecraft:grass_block)
B(-8,0,0,minecraft:granite)
B(-8,1,0,minecraft:granite)
B(-8,2,0,minecraft:granite)
B(-8,3,0,minecraft:granite)
B(-8,4,0,minecraft:grass_block)
B(-8,0,1,minecraft:stone)
B(-8,1,1,minecraft:stone)
B(-8,2,1,minecraft:stone)
B(-8,3,1,minecraft:stone)
B(-8,4,1,minecraft:andesite)
B(-8,10,1,minecraft:andesite)
B(-8,11,1,minecraft:grass_block)
B(-8,27,1,minecraft:dirt)
B(-8,28,1,minecraft:dirt)
B(-8,0,2,minecraft:stone)
B(-8,1,2,minecraft:stone)
B(-8,2,2,minecraft:stone)
B(-8,3,2,minecraft:stone)
B(-8,4,2,minecraft:andesite)
B(-8,5,2,minecraft:andesite)
B(-8,6,2,minecraft:andesite)
B(-8,7,2,minecraft:andesite)
B(-8,8,2,minecraft:andesite)
B(-8,9,2,minecraft:andesite)
B(-8,10,2,minecraft:andesite)
B(-8,11,2,minecraft:andesite)
B(-8,15,2,minecraft:andesite)
B(-8,16,2,minecraft:andesite)
B(-8,17,2,minecraft:granite)
B(-8,24,2,minecraft:granite)
B(-8,25,2,minecraft:granite)
B(-8,26,2,minecraft:granite)
B(-8,27,2,minecraft:dirt)
B(-8,28,2,minecraft:granite)
B(-8,29,2,minecraft:granite)
B(-8,30,2,minecraft:granite)
B(-8,31,2,minecraft:granite)
B(-8,32,2,minecraft:granite)
B(-8,33,2,minecraft:grass_block)
B(-8,0,3,minecraft:stone)
B(-8,1,3,minecraft:stone)
B(-8,2,3,minecraft:stone)
B(-8,3,3,minecraft:stone)
B(-8,4,3,minecraft:andesite)
B(-8,5,3,minecraft:andesite)
B(-8,6,3,minecraft:andesite)
B(-8,7,3,minecraft:andesite)
B(-8,8,3,minecraft:andesite)
B(-8,9,3,minecraft:dirt)
B(-8,10,3,minecraft:dirt)
B(-8,11,3,minecraft:grass_block)
B(-8,17,3,minecraft:granite)
B(-8,18,3,minecraft:granite)
B(-8,23,3,minecraft:granite)
B(-8,24,3,minecraft:granite)
B(-8,25,3,minecraft:granite)
B(-8,26,3,minecraft:granite)
B(-8,27,3,minecraft:dirt)
B(-8,28,3,minecraft:granite)
B(-8,29,3,minecraft:granite)
B(-8,30,3,minecraft:granite)
B(-8,31,3,minecraft:granite)
B(-8,32,3,minecraft:dirt)
B(-8,33,3,minecraft:dirt)
B(-8,34,3,minecraft:grass_block)
B(-8,0,4,minecraft:stone)
B(-8,1,4,minecraft:stone)
B(-8,2,4,minecraft:stone)
B(-8,3,4,minecraft:stone)
B(-8,4,4,minecraft:stone)
B(-8,5,4,minecraft:andesite)
B(-8,6,4,minecraft:andesite)
B(-8,7,4,minecraft:andesite)
B(-8,8,4,minecraft:stone)
B(-8,9,4,minecraft:stone)
B(-8,10,4,minecraft:granite)
B(-8,11,4,minecraft:granite)
B(-8,12,4,minecraft:granite)
B(-8,13,4,minecraft:granite)
B(-8,15,4,minecraft:granite)
B(-8,16,4,minecraft:granite)
B(-8,17,4,minecraft:granite)
B(-8,18,4,minecraft:granite)
B(-8,19,4,minecraft:granite)
B(-8,20,4,minecraft:granite)
B(-8,21,4,minecraft:granite)
B(-8,22,4,minecraft:granite)
B(-8,23,4,minecraft:granite)
B(-8,24,4,minecraft:granite)
B(-8,25,4,minecraft:granite)
B(-8,26,4,minecraft:granite)
B(-8,27,4,minecraft:dirt)
B(-8,28,4,minecraft:granite)
B(-8,29,4,minecraft:granite)
B(-8,30,4,minecraft:granite)
B(-8,31,4,minecraft:granite)
B(-8,32,4,minecraft:granite)
B(-8,33,4,minecraft:dirt)
B(-8,34,4,minecraft:grass_block)
B(-8,39,4,minecraft:granite)
B(-8,40,4,minecraft:granite)
B(-8,41,4,minecraft:dirt)
B(-8,42,4,minecraft:dirt)
B(-8,43,4,minecraft:granite)
B(-8,0,5,minecraft:stone)
B(-8,1,5,minecraft:stone)
B(-8,2,5,minecraft:stone)
B(-8,3,5,minecraft:stone)
B(-8,4,5,minecraft:stone)
B(-8,5,5,minecraft:stone)
B(-8,6,5,minecraft:stone)
B(-8,7,5,minecraft:stone)
B(-8,8,5,minecraft:stone)
B(-8,9,5,minecraft:stone)
B(-8,10,5,minecraft:granite)
B(-8,11,5,minecraft:granite)
B(-8,12,5,minecraft:granite)
B(-8,13,5,minecraft:granite)
B(-8,14,5,minecraft:granite)
B(-8,15,5,minecraft:granite)
B(-8,16,5,minecraft:granite)
B(-8,17,5,minecraft:granite)
B(-8,18,5,minecraft:granite)
B(-8,19,5,minecraft:granite)
B(-8,20,5,minecraft:granite)
B(-8,21,5,minecraft:granite)
B(-8,22,5,minecraft:granite)
B(-8,23,5,minecraft:granite)
B(-8,24,5,minecraft:granite)
B(-8,25,5,minecraft:granite)
B(-8,26,5,minecraft:dirt)
B(-8,27,5,minecraft:dirt)
B(-8,28,5,minecraft:granite)
B(-8,29,5,minecraft:granite)
B(-8,30,5,minecraft:granite)
B(-8,31,5,minecraft:granite)
B(-8,32,5,minecraft:granite)
B(-8,33,5,minecraft:stone)
B(-8,34,5,minecraft:dirt)
B(-8,35,5,minecraft:dirt)
B(-8,36,5,minecraft:granite)
B(-8,37,5,minecraft:granite)
B(-8,38,5,minecraft:granite)
B(-8,39,5,minecraft:granite)
B(-8,40,5,minecraft:granite)
B(-8,41,5,minecraft:dirt)
B(-8,42,5,minecraft:dirt)
B(-8,43,5,minecraft:grass_block)
B(-8,0,6,minecraft:stone)
B(-8,1,6,minecraft:stone)
B(-8,2,6,minecraft:stone)
B(-8,3,6,minecraft:stone)
B(-8,4,6,minecraft:stone)
B(-8,5,6,minecraft:stone)
B(-8,6,6,minecraft:stone)
B(-8,7,6,minecraft:stone)
B(-8,8,6,minecraft:stone)
B(-8,9,6,minecraft:stone)
B(-8,10,6,minecraft:granite)
B(-8,11,6,minecraft:granite)
B(-8,12,6,minecraft:granite)
B(-8,13,6,minecraft:granite)
B(-8,14,6,minecraft:granite)
B(-8,15,6,minecraft:granite)
B(-8,16,6,minecraft:granite)
B(-8,17,6,minecraft:granite)
B(-8,18,6,minecraft:granite)
B(-8,19,6,minecraft:granite)
B(-8,20,6,minecraft:granite)
B(-8,21,6,minecraft:granite)
B(-8,22,6,minecraft:granite)
B(-8,23,6,minecraft:granite)
B(-8,24,6,minecraft:granite)
B(-8,25,6,minecraft:granite)
B(-8,26,6,minecraft:granite)
B(-8,27,6,minecraft:dirt)
B(-8,28,6,minecraft:granite)
B(-8,29,6,minecraft:granite)
B(-8,30,6,minecraft:granite)
B(-8,31,6,minecraft:granite)
B(-8,32,6,minecraft:granite)
B(-8,33,6,minecraft:granite)
B(-8,34,6,minecraft:dirt)
B(-8,35,6,minecraft:dirt)
B(-8,36,6,minecraft:dirt)
B(-8,37,6,minecraft:dirt)
B(-8,38,6,minecraft:dirt)
B(-8,39,6,minecraft:dirt)
B(-8,40,6,minecraft:granite)
B(-8,41,6,minecraft:granite)
B(-8,42,6,minecraft:dirt)
B(-8,43,6,minecraft:dirt)
B(-8,44,6,minecraft:dirt)
B(-8,45,6,minecraft:granite)
B(-8,46,6,minecraft:granite)
B(-8,47,6,minecraft:dirt)
B(-8,48,6,minecraft:dirt)
B(-8,49,6,minecraft:granite)
B(-8,0,7,minecraft:stone)
B(-8,1,7,minecraft:stone)
B(-8,2,7,minecraft:stone)
B(-8,3,7,minecraft:stone)
B(-8,4,7,minecraft:stone)
B(-8,5,7,minecraft:stone)
B(-8,6,7,minecraft:stone)
B(-8,7,7,minecraft:granite)
B(-8,8,7,minecraft:granite)
B(-8,9,7,minecraft:granite)
B(-8,10,7,minecraft:granite)
B(-8,11,7,minecraft:granite)
B(-8,12,7,minecraft:granite)
B(-8,13,7,minecraft:granite)
B(-8,14,7,minecraft:granite)
B(-8,15,7,minecraft:stone)
B(-8,16,7,minecraft:granite)
B(-8,17,7,minecraft:granite)
B(-8,18,7,minecraft:granite)
B(-8,19,7,minecraft:granite)
B(-8,20,7,minecraft:granite)
B(-8,21,7,minecraft:andesite)
B(-8,22,7,minecraft:andesite)
B(-8,23,7,minecraft:andesite)
B(-8,24,7,minecraft:granite)
B(-8,25,7,minecraft:granite)
B(-8,26,7,minecraft:granite)
B(-8,27,7,minecraft:granite)
B(-8,28,7,minecraft:granite)
B(-8,29,7,minecraft:stone)
B(-8,30,7,minecraft:granite)
B(-8,31,7,minecraft:granite)
B(-8,32,7,minecraft:granite)
B(-8,33,7,minecraft:granite)
B(-8,34,7,minecraft:granite)
B(-8,35,7,minecraft:granite)
B(-8,36,7,minecraft:granite)
B(-8,37,7,minecraft:granite)
B(-8,38,7,minecraft:granite)
B(-8,39,7,minecraft:granite)
B(-8,40,7,minecraft:granite)
B(-8,41,7,minecraft:granite)
B(-8,42,7,minecraft:granite)
B(-8,43,7,minecraft:dirt)
B(-8,44,7,minecraft:dirt)
B(-8,45,7,minecraft:granite)
B(-8,46,7,minecraft:granite)
B(-8,47,7,minecraft:granite)
B(-8,48,7,minecraft:grass_block)
B(-8,0,8,minecraft:stone)
B(-8,1,8,minecraft:stone)
B(-8,2,8,minecraft:stone)
B(-8,3,8,minecraft:stone)
B(-8,4,8,minecraft:stone)
B(-8,5,8,minecraft:stone)
B(-8,6,8,minecraft:stone)
B(-8,7,8,minecraft:granite)
B(-8,8,8,minecraft:granite)
B(-8,9,8,minecraft:granite)
B(-8,10,8,minecraft:granite)
B(-8,11,8,minecraft:granite)
B(-8,12,8,minecraft:granite)
B(-8,13,8,minecraft:granite)
B(-8,14,8,minecraft:granite)
B(-8,15,8,minecraft:stone)
B(-8,16,8,minecraft:stone)
B(-8,17,8,minecraft:granite)
B(-8,18,8,minecraft:granite)
B(-8,19,8,minecraft:granite)
B(-8,20,8,minecraft:stone)
B(-8,21,8,minecraft:andesite)
B(-8,22,8,minecraft:andesite)
B(-8,23,8,minecraft:andesite)
B(-8,24,8,minecraft:granite)
B(-8,25,8,minecraft:granite)
B(-8,26,8,minecraft:granite)
B(-8,27,8,minecraft:granite)
B(-8,29,8,minecraft:granite)
B(-8,30,8,minecraft:granite)
B(-8,31,8,minecraft:granite)
B(-8,32,8,minecraft:granite)
B(-8,33,8,minecraft:granite)
B(-8,34,8,minecraft:granite)
B(-8,35,8,minecraft:granite)
B(-8,36,8,minecraft:granite)
B(-8,37,8,minecraft:granite)
B(-8,38,8,minecraft:granite)
B(-8,39,8,minecraft:granite)
B(-8,40,8,minecraft:granite)
B(-8,41,8,minecraft:granite)
B(-8,42,8,minecraft:granite)
B(-8,43,8,minecraft:dirt)
B(-8,44,8,minecraft:grass_block)
B(-8,46,8,minecraft:granite)
B(-8,47,8,minecraft:granite)
B(-8,48,8,minecraft:granite)
B(-8,49,8,minecraft:andesite)
B(-7,3,-1,minecraft:grass_block)
B(-7,0,0,minecraft:stone)
B(-7,1,0,minecraft:dirt)
B(-7,2,0,minecraft:dirt)
B(-7,3,0,minecraft:dirt)
B(-7,4,0,minecraft:grass_block)
B(-7,0,1,minecraft:stone)
B(-7,1,1,minecraft:stone)
B(-7,2,1,minecraft:dirt)
B(-7,3,1,minecraft:dirt)
B(-7,4,1,minecraft:grass_block)
B(-7,0,2,minecraft:stone)
B(-7,1,2,minecraft:stone)
B(-7,2,2,minecraft:stone)
B(-7,3,2,minecraft:stone)
B(-7,4,2,minecraft:andesite)
B(-7,5,2,minecraft:andesite)
B(-7,6,2,minecraft:andesite)
B(-7,7,2,minecraft:andesite)
B(-7,11,2,minecraft:grass_block)
B(-7,0,3,minecraft:stone)
B(-7,1,3,minecraft:stone)
B(-7,2,3,minecraft:stone)
B(-7,3,3,minecraft:stone)
B(-7,4,3,minecraft:andesite)
B(-7,5,3,minecraft:andesite)
B(-7,6,3,minecraft:andesite)
B(-7,7,3,minecraft:andesite)
B(-7,8,3,minecraft:andesite)
B(-7,9,3,minecraft:dirt)
B(-7,10,3,minecraft:dirt)
B(-7,11,3,minecraft:grass_block)
B(-7,26,3,minecraft:granite)
B(-7,27,3,minecraft:dirt)
B(-7,28,3,minecraft:granite)
B(-7,29,3,minecraft:granite)
B(-7,30,3,minecraft:granite)
B(-7,31,3,minecraft:granite)
B(-7,32,3,minecraft:dirt)
B(-7,33,3,minecraft:grass_block)
B(-7,0,4,minecraft:stone)
B(-7,1,4,minecraft:stone)
B(-7,2,4,minecraft:stone)
B(-7,3,4,minecraft:stone)
B(-7,4,4,minecraft:stone)
B(-7,5,4,minecraft:andesite)
B(-7,6,4,minecraft:andesite)
B(-7,7,4,minecraft:andesite)
B(-7,8,4,minecraft:stone)
B(-7,9,4,minecraft:dirt)
B(-7,10,4,minecraft:granite)
B(-7,11,4,minecraft:dirt)
B(-7,12,4,minecraft:granite)
B(-7,13,4,minecraft:granite)
B(-7,17,4,minecraft:granite)
B(-7,18,4,minecraft:granite)
B(-7,23,4,minecraft:granite)
B(-7,24,4,minecraft:granite)
B(-7,25,4,minecraft:granite)
B(-7,26,4,minecraft:granite)
B(-7,27,4,minecraft:dirt)
B(-7,28,4,minecraft:granite)
B(-7,29,4,minecraft:granite)
B(-7,30,4,minecraft:granite)
B(-7,31,4,minecraft:granite)
B(-7,32,4,minecraft:dirt)
B(-7,33,4,minecraft:grass_block)
B(-7,38,4,minecraft:granite)
B(-7,39,4,minecraft:granite)
B(-7,40,4,minecraft:dirt)
B(-7,41,4,minecraft:grass_block)
B(-7,0,5,minecraft:stone)
B(-7,1,5,minecraft:stone)
B(-7,2,5,minecraft:stone)
B(-7,3,5,minecraft:stone)
B(-7,4,5,minecraft:stone)
B(-7,5,5,minecraft:stone)
B(-7,6,5,minecraft:stone)
B(-7,7,5,minecraft:dirt)
B(-7,8,5,minecraft:stone)
B(-7,9,5,minecraft:granite)
B(-7,10,5,minecraft:granite)
B(-7,11,5,minecraft:granite)
B(-7,12,5,minecraft:granite)
B(-7,13,5,minecraft:granite)
B(-7,14,5,minecraft:granite)
B(-7,15,5,minecraft:granite)
B(-7,16,5,minecraft:granite)
B(-7,17,5,minecraft:granite)
B(-7,18,5,minecraft:granite)
B(-7,20,5,minecraft:granite)
B(-7,21,5,minecraft:granite)
B(-7,22,5,minecraft:granite)
B(-7,23,5,minecraft:granite)
B(-7,24,5,minecraft:granite)
B(-7,25,5,minecraft:granite)
B(-7,26,5,minecraft:dirt)
B(-7,27,5,minecraft:dirt)
B(-7,28,5,minecraft:granite)
B(-7,29,5,minecraft:granite)
B(-7,30,5,minecraft:granite)
B(-7,31,5,minecraft:granite)
B(-7,32,5,minecraft:granite)
B(-7,33,5,minecraft:andesite)
B(-7,34,5,minecraft:dirt)
B(-7,35,5,minecraft:dirt)
B(-7,36,5,minecraft:dirt)
B(-7,37,5,minecraft:dirt)
B(-7,38,5,minecraft:dirt)
B(-7,39,5,minecraft:dirt)
B(-7,40,5,minecraft:dirt)
B(-7,41,5,minecraft:dirt)
B(-7,42,5,minecraft:dirt)
B(-7,43,5,minecraft:grass_block)
B(-7,0,6,minecraft:stone)
B(-7,1,6,minecraft:stone)
B(-7,2,6,minecraft:stone)
B(-7,3,6,minecraft:stone)
B(-7,4,6,minecraft:stone)
B(-7,6,6,minecraft:granite)
B(-7,7,6,minecraft:granite)
B(-7,8,6,minecraft:granite)
B(-7,9,6,minecraft:granite)
B(-7,10,6,minecraft:granite)
B(-7,11,6,minecraft:granite)
B(-7,12,6,minecraft:granite)
B(-7,13,6,minecraft:granite)
B(-7,14,6,minecraft:granite)
B(-7,15,6,minecraft:granite)
B(-7,16,6,minecraft:granite)
B(-7,17,6,minecraft:granite)
B(-7,18,6,minecraft:granite)
B(-7,19,6,minecraft:granite)
B(-7,20,6,minecraft:granite)
B(-7,21,6,minecraft:granite)
B(-7,22,6,minecraft:granite)
B(-7,23,6,minecraft:granite)
B(-7,24,6,minecraft:granite)
B(-7,25,6,minecraft:granite)
B(-7,26,6,minecraft:dirt)
B(-7,27,6,minecraft:dirt)
B(-7,28,6,minecraft:granite)
B(-7,29,6,minecraft:granite)
B(-7,30,6,minecraft:granite)
B(-7,31,6,minecraft:granite)
B(-7,32,6,minecraft:granite)
B(-7,33,6,minecraft:granite)
B(-7,34,6,minecraft:dirt)
B(-7,35,6,minecraft:dirt)
B(-7,36,6,minecraft:dirt)
B(-7,37,6,minecraft:dirt)
B(-7,38,6,minecraft:dirt)
B(-7,39,6,minecraft:dirt)
B(-7,40,6,minecraft:granite)
B(-7,41,6,minecraft:dirt)
B(-7,42,6,minecraft:dirt)
B(-7,43,6,minecraft:grass_block)
B(-7,0,7,minecraft:stone)
B(-7,1,7,minecraft:stone)
B(-7,2,7,minecraft:stone)
B(-7,3,7,minecraft:stone)
B(-7,4,7,minecraft:stone)
B(-7,5,7,minecraft:stone)
B(-7,6,7,minecraft:granite)
B(-7,7,7,minecraft:granite)
B(-7,9,7,minecraft:granite)
B(-7,10,7,minecraft:granite)
B(-7,11,7,minecraft:granite)
B(-7,12,7,minecraft:granite)
B(-7,13,7,minecraft:granite)
B(-7,14,7,minecraft:granite)
B(-7,15,7,minecraft:granite)
B(-7,16,7,minecraft:granite)
B(-7,17,7,minecraft:granite)
B(-7,21,7,minecraft:stone)
B(-7,22,7,minecraft:andesite)
B(-7,23,7,minecraft:granite)
B(-7,24,7,minecraft:granite)
B(-7,25,7,minecraft:granite)
B(-7,26,7,minecraft:dirt)
B(-7,27,7,minecraft:granite)
B(-7,30,7,minecraft:granite)
B(-7,31,7,minecraft:granite)
B(-7,32,7,minecraft:granite)
B(-7,33,7,minecraft:granite)
B(-7,34,7,minecraft:granite)
B(-7,35,7,minecraft:dirt)
B(-7,36,7,minecraft:dirt)
B(-7,37,7,minecraft:dirt)
B(-7,38,7,minecraft:granite)
B(-7,39,7,minecraft:granite)
B(-7,40,7,minecraft:granite)
B(-7,41,7,minecraft:dirt)
B(-7,42,7,minecraft:dirt)
B(-7,43,7,minecraft:grass_block)
B(-7,0,8,minecraft:granite)
B(-7,1,8,minecraft:granite)
B(-7,2,8,minecraft:granite)
B(-7,3,8,minecraft:granite)
B(-7,4,8,minecraft:granite)
B(-7,5,8,minecraft:granite)
B(-7,6,8,minecraft:granite)
B(-7,8,8,minecraft:granite)
B(-7,9,8,minecraft:granite)
B(-7,10,8,minecraft:granite)
B(-7,11,8,minecraft:granite)
B(-7,12,8,minecraft:granite)
B(-7,13,8,minecraft:granite)
B(-7,14,8,minecraft:granite)
B(-7,15,8,minecraft:dirt)
B(-7,16,8,minecraft:dirt)
B(-7,17,8,minecraft:granite)
B(-7,18,8,minecraft:granite)
B(-7,24,8,minecraft:granite)
B(-7,25,8,minecraft:granite)
B(-7,34,8,minecraft:granite)
B(-7,35,8,minecraft:granite)
B(-7,36,8,minecraft:granite)
B(-7,37,8,minecraft:granite)
B(-7,38,8,minecraft:granite)
B(-7,39,8,minecraft:granite)
B(-7,40,8,minecraft:granite)
B(-7,41,8,minecraft:dirt)
B(-7,42,8,minecraft:dirt)
B(-7,43,8,minecraft:dirt)
B(-7,44,8,minecraft:dirt)
B(-7,45,8,minecraft:granite)
B(-7,46,8,minecraft:granite)
B(-7,47,8,minecraft:granite)
B(-7,48,8,minecraft:grass_block)
B(-6,2,0,minecraft:dirt)
B(-6,3,0,minecraft:grass_block)
B(-6,0,1,minecraft:stone)
B(-6,1,1,minecraft:dirt)
B(-6,2,1,minecraft:dirt)
B(-6,3,1,minecraft:dirt)
B(-6,4,1,minecraft:grass_block)
B(-6,0,2,minecraft:dirt)
B(-6,1,2,minecraft:dirt)
B(-6,2,2,minecraft:dirt)
B(-6,3,2,minecraft:stone)
B(-6,4,2,minecraft:andesite)
B(-6,0,3,minecraft:stone)
B(-6,1,3,minecraft:dirt)
B(-6,2,3,minecraft:stone)
B(-6,3,3,minecraft:stone)
B(-6,4,3,minecraft:andesite)
B(-6,5,3,minecraft:andesite)
B(-6,6,3,minecraft:grass_block)
B(-6,0,4,minecraft:stone)
B(-6,1,4,minecraft:stone)
B(-6,2,4,minecraft:stone)
B(-6,3,4,minecraft:stone)
B(-6,4,4,minecraft:stone)
B(-6,5,4,minecraft:andesite)
B(-6,6,4,minecraft:dirt)
B(-6,7,4,minecraft:andesite)
B(-6,8,4,minecraft:stone)
B(-6,9,4,minecraft:stone)
B(-6,24,4,minecraft:granite)
B(-6,25,4,minecraft:granite)
B(-6,26,4,minecraft:granite)
B(-6,30,4,minecraft:granite)
B(-6,31,4,minecraft:granite)
B(-6,32,4,minecraft:grass_block)
B(-6,0,5,minecraft:stone)
B(-6,1,5,minecraft:stone)
B(-6,2,5,minecraft:stone)
B(-6,3,5,minecraft:stone)
B(-6,4,5,minecraft:stone)
B(-6,5,5,minecraft:stone)
B(-6,6,5,minecraft:dirt)
B(-6,7,5,minecraft:granite)
B(-6,8,5,minecraft:granite)
B(-6,9,5,minecraft:granite)
B(-6,10,5,minecraft:granite)
B(-6,11,5,minecraft:granite)
B(-6,12,5,minecraft:granite)
B(-6,13,5,minecraft:granite)
B(-6,23,5,minecraft:granite)
B(-6,24,5,minecraft:granite)
B(-6,25,5,minecraft:granite)
B(-6,26,5,minecraft:dirt)
B(-6,27,5,minecraft:grass_block)
B(-6,29,5,minecraft:granite)
B(-6,30,5,minecraft:granite)
B(-6,31,5,minecraft:granite)
B(-6,32,5,minecraft:granite)
B(-6,0,6,minecraft:stone)
B(-6,1,6,minecraft:stone)
B(-6,2,6,minecraft:stone)
B(-6,3,6,minecraft:stone)
B(-6,4,6,minecraft:stone)
B(-6,5,6,minecraft:stone)
B(-6,6,6,minecraft:dirt)
B(-6,7,6,minecraft:granite)
B(-6,8,6,minecraft:granite)
B(-6,9,6,minecraft:granite)
B(-6,10,6,minecraft:granite)
B(-6,11,6,minecraft:granite)
B(-6,12,6,minecraft:granite)
B(-6,13,6,minecraft:granite)
B(-6,24,6,minecraft:granite)
B(-6,25,6,minecraft:granite)
B(-6,26,6,minecraft:grass_block)
B(-6,31,6,minecraft:granite)
B(-6,39,6,minecraft:dirt)
B(-6,40,6,minecraft:granite)
B(-6,41,6,minecraft:grass_block)
B(-6,0,7,minecraft:stone)
B(-6,1,7,minecraft:granite)
B(-6,2,7,minecraft:granite)
B(-6,3,7,minecraft:granite)
B(-6,4,7,minecraft:granite)
B(-6,5,7,minecraft:granite)
B(-6,6,7,minecraft:dirt)
B(-6,7,7,minecraft:dirt)
B(-6,8,7,minecraft:granite)
B(-6,9,7,minecraft:granite)
B(-6,10,7,minecraft:granite)
B(-6,11,7,minecraft:granite)
B(-6,12,7,minecraft:granite)
B(-6,13,7,minecraft:granite)
B(-6,14,7,minecraft:granite)
B(-6,15,7,minecraft:granite)
B(-6,36,7,minecraft:dirt)
B(-6,37,7,minecraft:dirt)
B(-6,38,7,minecraft:dirt)
B(-6,39,7,minecraft:dirt)
B(-6,40,7,minecraft:granite)
B(-6,41,7,minecraft:dirt)
B(-6,42,7,minecraft:grass_block)
B(-6,0,8,minecraft:granite)
B(-6,1,8,minecraft:granite)
B(-6,2,8,minecraft:granite)
B(-6,3,8,minecraft:granite)
B(-6,4,8,minecraft:granite)
B(-6,5,8,minecraft:granite)
B(-6,6,8,minecraft:granite)
B(-6,7,8,minecraft:granite)
B(-6,8,8,minecraft:granite)
B(-6,9,8,minecraft:granite)
B(-6,10,8,minecraft:granite)
B(-6,11,8,minecraft:granite)
B(-6,12,8,minecraft:granite)
B(-6,13,8,minecraft:granite)
B(-6,14,8,minecraft:granite)
B(-6,15,8,minecraft:dirt)
B(-6,16,8,minecraft:grass_block)
B(-6,37,8,minecraft:granite)
B(-6,38,8,minecraft:granite)
B(-6,39,8,minecraft:granite)
B(-6,40,8,minecraft:granite)
B(-6,41,8,minecraft:grass_block)
B(-5,0,1,minecraft:grass_block)
B(-5,0,2,minecraft:dirt)
B(-5,1,2,minecraft:dirt)
B(-5,2,2,minecraft:grass_block)
B(-5,4,2,minecraft:stone)
B(-5,0,3,minecraft:dirt)
B(-5,1,3,minecraft:dirt)
B(-5,2,3,minecraft:dirt)
B(-5,3,3,minecraft:stone)
B(-5,4,3,minecraft:dirt)
B(-5,5,3,minecraft:dirt)
B(-5,6,3,minecraft:grass_block)
B(-5,0,4,minecraft:stone)
B(-5,1,4,minecraft:stone)
B(-5,2,4,minecraft:stone)
B(-5,3,4,minecraft:dirt)
B(-5,4,4,minecraft:dirt)
B(-5,5,4,minecraft:dirt)
B(-5,6,4,minecraft:grass_block)
B(-5,0,5,minecraft:stone)
B(-5,1,5,minecraft:stone)
B(-5,2,5,minecraft:stone)
B(-5,3,5,minecraft:dirt)
B(-5,4,5,minecraft:dirt)
B(-5,5,5,minecraft:dirt)
B(-5,6,5,minecraft:stone)
B(-5,0,6,minecraft:stone)
B(-5,1,6,minecraft:stone)
B(-5,2,6,minecraft:stone)
B(-5,3,6,minecraft:stone)
B(-5,4,6,minecraft:dirt)
B(-5,5,6,minecraft:granite)
B(-5,6,6,minecraft:grass_block)
B(-5,0,7,minecraft:stone)
B(-5,1,7,minecraft:granite)
B(-5,2,7,minecraft:granite)
B(-5,3,7,minecraft:granite)
B(-5,4,7,minecraft:granite)
B(-5,5,7,minecraft:granite)
B(-5,6,7,minecraft:granite)
B(-5,0,8,minecraft:granite)
B(-5,1,8,minecraft:granite)
B(-5,2,8,minecraft:granite)
B(-5,3,8,minecraft:granite)
B(-5,4,8,minecraft:granite)
B(-5,5,8,minecraft:granite)
B(-5,6,8,minecraft:dirt)
B(-5,7,8,minecraft:granite)
B(-5,8,8,minecraft:granite)
B(-5,9,8,minecraft:granite)
B(-4,0,3,minecraft:stone)
B(-4,3,3,minecraft:dirt)
B(-4,4,3,minecraft:grass_block)
B(-4,0,4,minecraft:stone)
B(-4,2,4,minecraft:stone)
B(-4,3,4,minecraft:dirt)
B(-4,4,4,minecraft:dirt)
B(-4,5,4,minecraft:grass_block)
B(-4,1,5,minecraft:stone)
B(-4,2,5,minecraft:stone)
B(-4,3,5,minecraft:dirt)
B(-4,4,5,minecraft:dirt)
B(-4,5,5,minecraft:grass_block)
B(-4,0,6,minecraft:stone)
B(-4,1,6,minecraft:stone)
B(-4,2,6,minecraft:stone)
B(-4,3,6,minecraft:dirt)
B(-4,4,6,minecraft:dirt)
B(-4,5,6,minecraft:granite)
B(-4,0,7,minecraft:stone)
B(-4,1,7,minecraft:granite)
B(-4,2,7,minecraft:granite)
B(-4,3,7,minecraft:granite)
B(-4,4,7,minecraft:granite)
B(-4,5,7,minecraft:granite)
B(-4,0,8,minecraft:granite)
B(-4,1,8,minecraft:granite)
B(-4,2,8,minecraft:granite)
B(-4,3,8,minecraft:granite)
B(-4,4,8,minecraft:granite)
B(-4,5,8,minecraft:granite)
B(-4,6,8,minecraft:grass_block)

#######################################################################
# +-----------------------------------------------------------------+ #
# |                             Branches                            | #
# +-----------------------------------------------------------------+ #
#######################################################################


#######################################################################
# +-----------------------------------------------------------------+ #
# |                             Entities                            | #
# +-----------------------------------------------------------------+ #
#######################################################################

