
#######################################################################
# +-----------------------------------------------------------------+ #
# |                            BO3 object                           | #
# +-----------------------------------------------------------------+ #
#######################################################################

Author: Unknown

Description: No description given

Version: 3

SettingsMode: WriteWithoutComments


#######################################################################
# +-----------------------------------------------------------------+ #
# |                          Main settings                          | #
# +-----------------------------------------------------------------+ #
#######################################################################

Tree: true

Frequency: 0

Rarity: 100.0

MaxSpawn: 0

RotateRandomly: true

SpawnHeight: randomY

SpawnHeightOffset: 0

SpawnHeightVariance: 0

##############################
# Height Limits for the BO3. #
##############################

MinHeight: 52

MaxHeight: 84

######################
# Extrusion settings #
######################

ExtrudeMode: None

ExtrudeThroughBlocks: minecraft:air

MaxBranchDepth: 10


#######################################################################
# +-----------------------------------------------------------------+ #
# |                      Source block settings                      | #
# +-----------------------------------------------------------------+ #
#######################################################################

SourceBlocks: minecraft:air,minecraft:grass_block,minecraft:dirt,minecraft:water,minecraft:snow_block

MaxPercentageOutsideSourceBlock: 5

OutsideSourceBlock: dontPlace

DoReplaceBlocks: true

IsOTGPlus: false


#######################################################################
# +-----------------------------------------------------------------+ #
# |                              Blocks                             | #
# +-----------------------------------------------------------------+ #
#######################################################################

B(-6,5,-1,minecraft:dirt)
B(-6,6,-1,minecraft:dirt)
B(-6,7,-1,minecraft:grass_block)
B(-6,6,0,minecraft:dirt)
B(-6,7,0,minecraft:grass_block)
B(-6,2,1,minecraft:stone)
B(-6,5,1,minecraft:dirt)
B(-6,6,1,minecraft:grass_block)
B(-6,2,2,minecraft:grass_block)
B(-6,4,2,minecraft:dirt)
B(-6,5,2,minecraft:dirt)
B(-6,6,2,minecraft:grass_block)
B(-6,2,3,minecraft:dirt)
B(-6,3,3,minecraft:grass_block)
B(-6,5,3,minecraft:dirt)
B(-6,6,3,minecraft:grass_block)
B(-5,5,-3,minecraft:dirt)
B(-5,6,-3,minecraft:dirt)
B(-5,7,-3,minecraft:grass_block)
B(-5,4,-2,minecraft:andesite)
B(-5,5,-2,minecraft:dirt)
B(-5,6,-2,minecraft:dirt)
B(-5,7,-2,minecraft:dirt)
B(-5,8,-2,minecraft:grass_block)
B(-5,4,-1,minecraft:stone)
B(-5,5,-1,minecraft:dirt)
B(-5,6,-1,minecraft:dirt)
B(-5,7,-1,minecraft:dirt)
B(-5,8,-1,minecraft:grass_block)
B(-5,3,0,minecraft:stone)
B(-5,4,0,minecraft:dirt)
B(-5,5,0,minecraft:dirt)
B(-5,6,0,minecraft:dirt)
B(-5,7,0,minecraft:dirt)
B(-5,8,0,minecraft:dirt)
B(-5,9,0,minecraft:coarse_dirt)
B(-5,1,1,minecraft:stone)
B(-5,2,1,minecraft:stone)
B(-5,3,1,minecraft:andesite)
B(-5,4,1,minecraft:andesite)
B(-5,5,1,minecraft:dirt)
B(-5,6,1,minecraft:andesite)
B(-5,7,1,minecraft:dirt)
B(-5,8,1,minecraft:dirt)
B(-5,9,1,minecraft:coarse_dirt)
B(-5,1,2,minecraft:stone)
B(-5,2,2,minecraft:dirt)
B(-5,3,2,minecraft:dirt)
B(-5,4,2,minecraft:dirt)
B(-5,5,2,minecraft:dirt)
B(-5,6,2,minecraft:dirt)
B(-5,7,2,minecraft:andesite)
B(-5,8,2,minecraft:dirt)
B(-5,9,2,minecraft:andesite)
B(-5,1,3,minecraft:dirt)
B(-5,2,3,minecraft:dirt)
B(-5,3,3,minecraft:dirt)
B(-5,4,3,minecraft:dirt)
B(-5,5,3,minecraft:dirt)
B(-5,6,3,minecraft:coarse_dirt)
B(-5,7,3,minecraft:andesite)
B(-5,8,3,minecraft:grass_block)
B(-5,1,4,minecraft:stone)
B(-5,2,4,minecraft:dirt)
B(-5,3,4,minecraft:dirt)
B(-5,4,4,minecraft:dirt)
B(-5,5,4,minecraft:dirt)
B(-5,6,4,minecraft:coarse_dirt)
B(-5,7,4,minecraft:coarse_dirt)
B(-5,4,5,minecraft:stone)
B(-5,5,5,minecraft:dirt)
B(-5,6,5,minecraft:coarse_dirt)
B(-4,5,-5,minecraft:andesite)
B(-4,6,-5,minecraft:andesite)
B(-4,4,-4,minecraft:andesite)
B(-4,5,-4,minecraft:andesite)
B(-4,6,-4,minecraft:dirt)
B(-4,7,-4,minecraft:grass_block)
B(-4,2,-3,minecraft:andesite)
B(-4,3,-3,minecraft:andesite)
B(-4,4,-3,minecraft:andesite)
B(-4,5,-3,minecraft:dirt)
B(-4,6,-3,minecraft:dirt)
B(-4,7,-3,minecraft:dirt)
B(-4,8,-3,minecraft:stone)
B(-4,2,-2,minecraft:stone)
B(-4,3,-2,minecraft:andesite)
B(-4,4,-2,minecraft:andesite)
B(-4,5,-2,minecraft:andesite)
B(-4,6,-2,minecraft:dirt)
B(-4,7,-2,minecraft:dirt)
B(-4,8,-2,minecraft:stone)
B(-4,9,-2,minecraft:andesite)
B(-4,1,-1,minecraft:stone)
B(-4,2,-1,minecraft:stone)
B(-4,3,-1,minecraft:stone)
B(-4,4,-1,minecraft:stone)
B(-4,5,-1,minecraft:stone)
B(-4,6,-1,minecraft:dirt)
B(-4,7,-1,minecraft:dirt)
B(-4,8,-1,minecraft:dirt)
B(-4,9,-1,minecraft:coarse_dirt)
B(-4,10,-1,minecraft:coarse_dirt)
B(-4,0,0,minecraft:stone)
B(-4,1,0,minecraft:stone)
B(-4,2,0,minecraft:stone)
B(-4,3,0,minecraft:stone)
B(-4,4,0,minecraft:stone)
B(-4,5,0,minecraft:stone)
B(-4,6,0,minecraft:stone)
B(-4,7,0,minecraft:dirt)
B(-4,8,0,minecraft:dirt)
B(-4,9,0,minecraft:coarse_dirt)
B(-4,10,0,minecraft:coarse_dirt)
B(-4,0,1,minecraft:stone)
B(-4,1,1,minecraft:stone)
B(-4,2,1,minecraft:stone)
B(-4,3,1,minecraft:stone)
B(-4,4,1,minecraft:andesite)
B(-4,5,1,minecraft:andesite)
B(-4,6,1,minecraft:andesite)
B(-4,7,1,minecraft:stone)
B(-4,8,1,minecraft:andesite)
B(-4,9,1,minecraft:coarse_dirt)
B(-4,10,1,minecraft:coarse_dirt)
B(-4,0,2,minecraft:stone)
B(-4,1,2,minecraft:stone)
B(-4,2,2,minecraft:stone)
B(-4,3,2,minecraft:stone)
B(-4,4,2,minecraft:andesite)
B(-4,5,2,minecraft:dirt)
B(-4,6,2,minecraft:andesite)
B(-4,7,2,minecraft:stone)
B(-4,8,2,minecraft:dirt)
B(-4,9,2,minecraft:andesite)
B(-4,0,3,minecraft:stone)
B(-4,1,3,minecraft:stone)
B(-4,2,3,minecraft:stone)
B(-4,3,3,minecraft:stone)
B(-4,4,3,minecraft:dirt)
B(-4,5,3,minecraft:dirt)
B(-4,6,3,minecraft:coarse_dirt)
B(-4,7,3,minecraft:stone)
B(-4,8,3,minecraft:grass_block)
B(-4,0,4,minecraft:stone)
B(-4,1,4,minecraft:stone)
B(-4,2,4,minecraft:stone)
B(-4,3,4,minecraft:stone)
B(-4,4,4,minecraft:stone)
B(-4,5,4,minecraft:dirt)
B(-4,6,4,minecraft:coarse_dirt)
B(-4,7,4,minecraft:coarse_dirt)
B(-4,2,5,minecraft:stone)
B(-4,3,5,minecraft:stone)
B(-4,4,5,minecraft:stone)
B(-4,5,5,minecraft:dirt)
B(-4,6,5,minecraft:coarse_dirt)
B(-4,3,6,minecraft:stone)
B(-4,4,6,minecraft:stone)
B(-4,5,6,minecraft:stone)
B(-3,5,-6,minecraft:andesite)
B(-3,4,-5,minecraft:andesite)
B(-3,5,-5,minecraft:andesite)
B(-3,6,-5,minecraft:andesite)
B(-3,7,-5,minecraft:dirt)
B(-3,8,-5,minecraft:grass_block)
B(-3,2,-4,minecraft:andesite)
B(-3,3,-4,minecraft:andesite)
B(-3,4,-4,minecraft:andesite)
B(-3,5,-4,minecraft:andesite)
B(-3,6,-4,minecraft:andesite)
B(-3,7,-4,minecraft:dirt)
B(-3,8,-4,minecraft:dirt)
B(-3,9,-4,minecraft:grass_block)
B(-3,2,-3,minecraft:andesite)
B(-3,3,-3,minecraft:andesite)
B(-3,4,-3,minecraft:andesite)
B(-3,5,-3,minecraft:andesite)
B(-3,6,-3,minecraft:andesite)
B(-3,7,-3,minecraft:dirt)
B(-3,8,-3,minecraft:andesite)
B(-3,9,-3,minecraft:andesite)
B(-3,1,-2,minecraft:stone)
B(-3,2,-2,minecraft:stone)
B(-3,3,-2,minecraft:andesite)
B(-3,4,-2,minecraft:andesite)
B(-3,5,-2,minecraft:andesite)
B(-3,6,-2,minecraft:stone)
B(-3,7,-2,minecraft:dirt)
B(-3,8,-2,minecraft:stone)
B(-3,9,-2,minecraft:dirt)
B(-3,0,-1,minecraft:stone)
B(-3,1,-1,minecraft:stone)
B(-3,2,-1,minecraft:stone)
B(-3,3,-1,minecraft:stone)
B(-3,4,-1,minecraft:stone)
B(-3,5,-1,minecraft:stone)
B(-3,6,-1,minecraft:stone)
B(-3,7,-1,minecraft:stone)
B(-3,8,-1,minecraft:andesite)
B(-3,9,-1,minecraft:coarse_dirt)
B(-3,10,-1,minecraft:coarse_dirt)
B(-3,0,0,minecraft:stone)
B(-3,1,0,minecraft:stone)
B(-3,2,0,minecraft:stone)
B(-3,3,0,minecraft:stone)
B(-3,4,0,minecraft:stone)
B(-3,5,0,minecraft:stone)
B(-3,6,0,minecraft:stone)
B(-3,7,0,minecraft:stone)
B(-3,8,0,minecraft:andesite)
B(-3,9,0,minecraft:coarse_dirt)
B(-3,10,0,minecraft:coarse_dirt)
B(-3,0,1,minecraft:stone)
B(-3,1,1,minecraft:stone)
B(-3,2,1,minecraft:stone)
B(-3,3,1,minecraft:stone)
B(-3,4,1,minecraft:stone)
B(-3,5,1,minecraft:stone)
B(-3,6,1,minecraft:stone)
B(-3,7,1,minecraft:stone)
B(-3,8,1,minecraft:andesite)
B(-3,9,1,minecraft:coarse_dirt)
B(-3,10,1,minecraft:coarse_dirt)
B(-3,0,2,minecraft:stone)
B(-3,1,2,minecraft:stone)
B(-3,2,2,minecraft:stone)
B(-3,3,2,minecraft:stone)
B(-3,4,2,minecraft:stone)
B(-3,5,2,minecraft:stone)
B(-3,6,2,minecraft:stone)
B(-3,7,2,minecraft:stone)
B(-3,8,2,minecraft:dirt)
B(-3,9,2,minecraft:dirt)
B(-3,10,2,minecraft:coarse_dirt)
B(-3,0,3,minecraft:stone)
B(-3,1,3,minecraft:stone)
B(-3,2,3,minecraft:stone)
B(-3,3,3,minecraft:stone)
B(-3,4,3,minecraft:stone)
B(-3,5,3,minecraft:stone)
B(-3,6,3,minecraft:stone)
B(-3,7,3,minecraft:stone)
B(-3,8,3,minecraft:dirt)
B(-3,9,3,minecraft:grass_block)
B(-3,0,4,minecraft:stone)
B(-3,1,4,minecraft:stone)
B(-3,2,4,minecraft:stone)
B(-3,3,4,minecraft:stone)
B(-3,4,4,minecraft:stone)
B(-3,5,4,minecraft:stone)
B(-3,6,4,minecraft:coarse_dirt)
B(-3,7,4,minecraft:coarse_dirt)
B(-3,8,4,minecraft:dirt)
B(-3,9,4,minecraft:grass_block)
B(-3,1,5,minecraft:stone)
B(-3,2,5,minecraft:stone)
B(-3,3,5,minecraft:stone)
B(-3,4,5,minecraft:stone)
B(-3,5,5,minecraft:stone)
B(-3,6,5,minecraft:coarse_dirt)
B(-3,7,5,minecraft:coarse_dirt)
B(-3,8,5,minecraft:grass_block)
B(-3,3,6,minecraft:stone)
B(-3,4,6,minecraft:stone)
B(-3,5,6,minecraft:stone)
B(-3,6,6,minecraft:coarse_dirt)
B(-3,7,6,minecraft:coarse_dirt)
B(-2,4,-6,minecraft:stone)
B(-2,5,-6,minecraft:stone)
B(-2,6,-6,minecraft:stone)
B(-2,7,-6,minecraft:stone)
B(-2,3,-5,minecraft:andesite)
B(-2,4,-5,minecraft:andesite)
B(-2,5,-5,minecraft:andesite)
B(-2,6,-5,minecraft:stone)
B(-2,7,-5,minecraft:dirt)
B(-2,8,-5,minecraft:dirt)
B(-2,9,-5,minecraft:dirt)
B(-2,10,-5,minecraft:grass_block)
B(-2,2,-4,minecraft:stone)
B(-2,3,-4,minecraft:andesite)
B(-2,4,-4,minecraft:andesite)
B(-2,5,-4,minecraft:andesite)
B(-2,6,-4,minecraft:stone)
B(-2,7,-4,minecraft:stone)
B(-2,8,-4,minecraft:dirt)
B(-2,9,-4,minecraft:dirt)
B(-2,10,-4,minecraft:grass_block)
B(-2,2,-3,minecraft:stone)
B(-2,3,-3,minecraft:andesite)
B(-2,4,-3,minecraft:andesite)
B(-2,5,-3,minecraft:andesite)
B(-2,6,-3,minecraft:stone)
B(-2,7,-3,minecraft:stone)
B(-2,8,-3,minecraft:andesite)
B(-2,9,-3,minecraft:andesite)
B(-2,10,-3,minecraft:andesite)
B(-2,0,-2,minecraft:stone)
B(-2,1,-2,minecraft:stone)
B(-2,2,-2,minecraft:stone)
B(-2,3,-2,minecraft:stone)
B(-2,4,-2,minecraft:stone)
B(-2,5,-2,minecraft:stone)
B(-2,6,-2,minecraft:stone)
B(-2,7,-2,minecraft:stone)
B(-2,8,-2,minecraft:stone)
B(-2,9,-2,minecraft:andesite)
B(-2,10,-2,minecraft:coarse_dirt)
B(-2,0,-1,minecraft:stone)
B(-2,1,-1,minecraft:stone)
B(-2,2,-1,minecraft:stone)
B(-2,3,-1,minecraft:stone)
B(-2,4,-1,minecraft:stone)
B(-2,5,-1,minecraft:stone)
B(-2,6,-1,minecraft:stone)
B(-2,7,-1,minecraft:stone)
B(-2,8,-1,minecraft:stone)
B(-2,9,-1,minecraft:dirt)
B(-2,10,-1,minecraft:coarse_dirt)
B(-2,0,0,minecraft:stone)
B(-2,1,0,minecraft:stone)
B(-2,2,0,minecraft:stone)
B(-2,3,0,minecraft:stone)
B(-2,4,0,minecraft:stone)
B(-2,5,0,minecraft:stone)
B(-2,6,0,minecraft:stone)
B(-2,7,0,minecraft:stone)
B(-2,8,0,minecraft:stone)
B(-2,9,0,minecraft:andesite)
B(-2,10,0,minecraft:coarse_dirt)
B(-2,0,1,minecraft:stone)
B(-2,1,1,minecraft:stone)
B(-2,2,1,minecraft:stone)
B(-2,3,1,minecraft:stone)
B(-2,4,1,minecraft:stone)
B(-2,5,1,minecraft:stone)
B(-2,6,1,minecraft:stone)
B(-2,7,1,minecraft:stone)
B(-2,8,1,minecraft:stone)
B(-2,9,1,minecraft:dirt)
B(-2,10,1,minecraft:coarse_dirt)
B(-2,0,2,minecraft:stone)
B(-2,1,2,minecraft:stone)
B(-2,2,2,minecraft:stone)
B(-2,3,2,minecraft:stone)
B(-2,4,2,minecraft:stone)
B(-2,5,2,minecraft:stone)
B(-2,6,2,minecraft:stone)
B(-2,7,2,minecraft:stone)
B(-2,8,2,minecraft:dirt)
B(-2,9,2,minecraft:stone)
B(-2,10,2,minecraft:grass_block)
B(-2,0,3,minecraft:stone)
B(-2,1,3,minecraft:stone)
B(-2,2,3,minecraft:stone)
B(-2,3,3,minecraft:stone)
B(-2,4,3,minecraft:stone)
B(-2,5,3,minecraft:stone)
B(-2,6,3,minecraft:stone)
B(-2,7,3,minecraft:stone)
B(-2,8,3,minecraft:dirt)
B(-2,9,3,minecraft:dirt)
B(-2,10,3,minecraft:grass_block)
B(-2,0,4,minecraft:stone)
B(-2,1,4,minecraft:stone)
B(-2,2,4,minecraft:stone)
B(-2,3,4,minecraft:stone)
B(-2,4,4,minecraft:stone)
B(-2,5,4,minecraft:stone)
B(-2,6,4,minecraft:stone)
B(-2,7,4,minecraft:coarse_dirt)
B(-2,8,4,minecraft:dirt)
B(-2,9,4,minecraft:coarse_dirt)
B(-2,1,5,minecraft:stone)
B(-2,2,5,minecraft:stone)
B(-2,3,5,minecraft:stone)
B(-2,4,5,minecraft:stone)
B(-2,5,5,minecraft:stone)
B(-2,6,5,minecraft:coarse_dirt)
B(-2,7,5,minecraft:coarse_dirt)
B(-2,8,5,minecraft:grass_block)
B(-2,4,6,minecraft:stone)
B(-2,5,6,minecraft:stone)
B(-2,6,6,minecraft:andesite)
B(-2,7,6,minecraft:coarse_dirt)
B(-2,8,6,minecraft:andesite)
B(-1,4,-6,minecraft:stone)
B(-1,5,-6,minecraft:stone)
B(-1,6,-6,minecraft:stone)
B(-1,7,-6,minecraft:stone)
B(-1,8,-6,minecraft:stone)
B(-1,9,-6,minecraft:grass_block)
B(-1,4,-5,minecraft:stone)
B(-1,5,-5,minecraft:stone)
B(-1,6,-5,minecraft:stone)
B(-1,7,-5,minecraft:stone)
B(-1,8,-5,minecraft:dirt)
B(-1,9,-5,minecraft:dirt)
B(-1,10,-5,minecraft:grass_block)
B(-1,3,-4,minecraft:stone)
B(-1,4,-4,minecraft:stone)
B(-1,5,-4,minecraft:stone)
B(-1,6,-4,minecraft:stone)
B(-1,7,-4,minecraft:stone)
B(-1,8,-4,minecraft:andesite)
B(-1,9,-4,minecraft:dirt)
B(-1,10,-4,minecraft:grass_block)
B(-1,1,-3,minecraft:stone)
B(-1,2,-3,minecraft:stone)
B(-1,3,-3,minecraft:stone)
B(-1,4,-3,minecraft:stone)
B(-1,5,-3,minecraft:stone)
B(-1,6,-3,minecraft:stone)
B(-1,7,-3,minecraft:stone)
B(-1,8,-3,minecraft:andesite)
B(-1,9,-3,minecraft:andesite)
B(-1,10,-3,minecraft:andesite)
B(-1,11,-3,minecraft:andesite)
B(-1,1,-2,minecraft:stone)
B(-1,2,-2,minecraft:stone)
B(-1,3,-2,minecraft:stone)
B(-1,4,-2,minecraft:stone)
B(-1,5,-2,minecraft:stone)
B(-1,6,-2,minecraft:stone)
B(-1,7,-2,minecraft:stone)
B(-1,8,-2,minecraft:stone)
B(-1,9,-2,minecraft:dirt)
B(-1,10,-2,minecraft:coarse_dirt)
B(-1,11,-2,minecraft:coarse_dirt)
B(-1,0,-1,minecraft:stone)
B(-1,1,-1,minecraft:stone)
B(-1,2,-1,minecraft:stone)
B(-1,3,-1,minecraft:stone)
B(-1,4,-1,minecraft:stone)
B(-1,5,-1,minecraft:stone)
B(-1,6,-1,minecraft:stone)
B(-1,7,-1,minecraft:stone)
B(-1,8,-1,minecraft:stone)
B(-1,9,-1,minecraft:dirt)
B(-1,10,-1,minecraft:coarse_dirt)
B(-1,0,0,minecraft:stone)
B(-1,1,0,minecraft:stone)
B(-1,2,0,minecraft:stone)
B(-1,3,0,minecraft:stone)
B(-1,4,0,minecraft:stone)
B(-1,5,0,minecraft:stone)
B(-1,6,0,minecraft:stone)
B(-1,7,0,minecraft:stone)
B(-1,8,0,minecraft:stone)
B(-1,9,0,minecraft:dirt)
B(-1,10,0,minecraft:coarse_dirt)
B(-1,0,1,minecraft:stone)
B(-1,1,1,minecraft:stone)
B(-1,2,1,minecraft:stone)
B(-1,3,1,minecraft:stone)
B(-1,4,1,minecraft:stone)
B(-1,5,1,minecraft:stone)
B(-1,6,1,minecraft:stone)
B(-1,7,1,minecraft:stone)
B(-1,8,1,minecraft:stone)
B(-1,9,1,minecraft:stone)
B(-1,10,1,minecraft:grass_block)
B(-1,0,2,minecraft:stone)
B(-1,1,2,minecraft:stone)
B(-1,2,2,minecraft:stone)
B(-1,3,2,minecraft:stone)
B(-1,4,2,minecraft:stone)
B(-1,5,2,minecraft:stone)
B(-1,6,2,minecraft:stone)
B(-1,7,2,minecraft:stone)
B(-1,8,2,minecraft:stone)
B(-1,9,2,minecraft:stone)
B(-1,10,2,minecraft:grass_block)
B(-1,0,3,minecraft:stone)
B(-1,1,3,minecraft:stone)
B(-1,2,3,minecraft:stone)
B(-1,3,3,minecraft:stone)
B(-1,4,3,minecraft:stone)
B(-1,5,3,minecraft:stone)
B(-1,6,3,minecraft:stone)
B(-1,7,3,minecraft:stone)
B(-1,8,3,minecraft:stone)
B(-1,9,3,minecraft:dirt)
B(-1,10,3,minecraft:grass_block)
B(-1,0,4,minecraft:stone)
B(-1,1,4,minecraft:stone)
B(-1,2,4,minecraft:stone)
B(-1,3,4,minecraft:stone)
B(-1,4,4,minecraft:stone)
B(-1,5,4,minecraft:stone)
B(-1,6,4,minecraft:andesite)
B(-1,7,4,minecraft:andesite)
B(-1,8,4,minecraft:dirt)
B(-1,9,4,minecraft:grass_block)
B(-1,2,5,minecraft:stone)
B(-1,3,5,minecraft:stone)
B(-1,4,5,minecraft:stone)
B(-1,5,5,minecraft:andesite)
B(-1,6,5,minecraft:andesite)
B(-1,7,5,minecraft:andesite)
B(-1,8,5,minecraft:andesite)
B(-1,4,6,minecraft:stone)
B(-1,5,6,minecraft:dirt)
B(-1,6,6,minecraft:coarse_dirt)
B(-1,7,6,minecraft:andesite)
B(-1,5,7,minecraft:dirt)
B(-1,6,7,minecraft:coarse_dirt)
B(0,4,-6,minecraft:dirt)
B(0,5,-6,minecraft:dirt)
B(0,6,-6,minecraft:dirt)
B(0,7,-6,minecraft:stone)
B(0,3,-5,minecraft:stone)
B(0,4,-5,minecraft:stone)
B(0,5,-5,minecraft:dirt)
B(0,6,-5,minecraft:stone)
B(0,7,-5,minecraft:dirt)
B(0,8,-5,minecraft:dirt)
B(0,9,-5,minecraft:dirt)
B(0,10,-5,minecraft:grass_block)
B(0,3,-4,minecraft:stone)
B(0,4,-4,minecraft:stone)
B(0,5,-4,minecraft:stone)
B(0,6,-4,minecraft:stone)
B(0,7,-4,minecraft:stone)
B(0,8,-4,minecraft:dirt)
B(0,9,-4,minecraft:andesite)
B(0,10,-4,minecraft:coarse_dirt)
B(0,2,-3,minecraft:stone)
B(0,3,-3,minecraft:stone)
B(0,4,-3,minecraft:stone)
B(0,5,-3,minecraft:stone)
B(0,6,-3,minecraft:stone)
B(0,7,-3,minecraft:stone)
B(0,8,-3,minecraft:stone)
B(0,9,-3,minecraft:andesite)
B(0,10,-3,minecraft:andesite)
B(0,1,-2,minecraft:stone)
B(0,2,-2,minecraft:stone)
B(0,3,-2,minecraft:stone)
B(0,4,-2,minecraft:stone)
B(0,5,-2,minecraft:stone)
B(0,6,-2,minecraft:stone)
B(0,7,-2,minecraft:stone)
B(0,8,-2,minecraft:stone)
B(0,9,-2,minecraft:andesite)
B(0,10,-2,minecraft:coarse_dirt)
B(0,11,-2,minecraft:coarse_dirt)
B(0,0,-1,minecraft:stone)
B(0,1,-1,minecraft:stone)
B(0,2,-1,minecraft:stone)
B(0,3,-1,minecraft:stone)
B(0,4,-1,minecraft:stone)
B(0,5,-1,minecraft:stone)
B(0,6,-1,minecraft:stone)
B(0,7,-1,minecraft:stone)
B(0,8,-1,minecraft:stone)
B(0,9,-1,minecraft:dirt)
B(0,10,-1,minecraft:coarse_dirt)
B(0,0,0,minecraft:stone)
B(0,1,0,minecraft:stone)
B(0,2,0,minecraft:stone)
B(0,3,0,minecraft:stone)
B(0,4,0,minecraft:stone)
B(0,5,0,minecraft:stone)
B(0,6,0,minecraft:stone)
B(0,7,0,minecraft:stone)
B(0,8,0,minecraft:stone)
B(0,9,0,minecraft:stone)
B(0,10,0,minecraft:coarse_dirt)
B(0,0,1,minecraft:stone)
B(0,1,1,minecraft:stone)
B(0,2,1,minecraft:stone)
B(0,3,1,minecraft:stone)
B(0,4,1,minecraft:stone)
B(0,5,1,minecraft:stone)
B(0,6,1,minecraft:stone)
B(0,7,1,minecraft:stone)
B(0,8,1,minecraft:stone)
B(0,9,1,minecraft:stone)
B(0,10,1,minecraft:grass_block)
B(0,0,2,minecraft:stone)
B(0,1,2,minecraft:stone)
B(0,2,2,minecraft:stone)
B(0,3,2,minecraft:stone)
B(0,4,2,minecraft:stone)
B(0,5,2,minecraft:stone)
B(0,6,2,minecraft:stone)
B(0,7,2,minecraft:stone)
B(0,8,2,minecraft:stone)
B(0,9,2,minecraft:dirt)
B(0,10,2,minecraft:grass_block)
B(0,0,3,minecraft:stone)
B(0,1,3,minecraft:stone)
B(0,2,3,minecraft:stone)
B(0,3,3,minecraft:stone)
B(0,4,3,minecraft:stone)
B(0,5,3,minecraft:stone)
B(0,6,3,minecraft:stone)
B(0,7,3,minecraft:stone)
B(0,8,3,minecraft:stone)
B(0,9,3,minecraft:dirt)
B(0,10,3,minecraft:grass_block)
B(0,0,4,minecraft:stone)
B(0,1,4,minecraft:stone)
B(0,2,4,minecraft:stone)
B(0,3,4,minecraft:stone)
B(0,4,4,minecraft:stone)
B(0,5,4,minecraft:stone)
B(0,6,4,minecraft:andesite)
B(0,7,4,minecraft:andesite)
B(0,8,4,minecraft:andesite)
B(0,9,4,minecraft:dirt)
B(0,10,4,minecraft:grass_block)
B(0,2,5,minecraft:stone)
B(0,3,5,minecraft:stone)
B(0,4,5,minecraft:stone)
B(0,5,5,minecraft:andesite)
B(0,6,5,minecraft:andesite)
B(0,7,5,minecraft:andesite)
B(0,8,5,minecraft:andesite)
B(0,9,5,minecraft:andesite)
B(0,4,6,minecraft:dirt)
B(0,5,6,minecraft:dirt)
B(0,6,6,minecraft:coarse_dirt)
B(0,7,6,minecraft:coarse_dirt)
B(0,4,7,minecraft:dirt)
B(0,5,7,minecraft:dirt)
B(0,6,7,minecraft:coarse_dirt)
B(1,5,-6,minecraft:dirt)
B(1,6,-6,minecraft:dirt)
B(1,4,-5,minecraft:dirt)
B(1,5,-5,minecraft:dirt)
B(1,6,-5,minecraft:dirt)
B(1,7,-5,minecraft:dirt)
B(1,8,-5,minecraft:dirt)
B(1,9,-5,minecraft:dirt)
B(1,10,-5,minecraft:stone)
B(1,3,-4,minecraft:stone)
B(1,4,-4,minecraft:stone)
B(1,5,-4,minecraft:stone)
B(1,6,-4,minecraft:stone)
B(1,7,-4,minecraft:dirt)
B(1,8,-4,minecraft:dirt)
B(1,9,-4,minecraft:dirt)
B(1,10,-4,minecraft:andesite)
B(1,2,-3,minecraft:stone)
B(1,3,-3,minecraft:stone)
B(1,4,-3,minecraft:stone)
B(1,5,-3,minecraft:stone)
B(1,6,-3,minecraft:stone)
B(1,7,-3,minecraft:stone)
B(1,8,-3,minecraft:stone)
B(1,9,-3,minecraft:andesite)
B(1,10,-3,minecraft:coarse_dirt)
B(1,1,-2,minecraft:stone)
B(1,2,-2,minecraft:stone)
B(1,3,-2,minecraft:stone)
B(1,4,-2,minecraft:stone)
B(1,5,-2,minecraft:stone)
B(1,6,-2,minecraft:stone)
B(1,7,-2,minecraft:stone)
B(1,8,-2,minecraft:stone)
B(1,9,-2,minecraft:andesite)
B(1,10,-2,minecraft:dirt)
B(1,11,-2,minecraft:coarse_dirt)
B(1,1,-1,minecraft:stone)
B(1,2,-1,minecraft:stone)
B(1,3,-1,minecraft:stone)
B(1,4,-1,minecraft:stone)
B(1,5,-1,minecraft:stone)
B(1,6,-1,minecraft:stone)
B(1,7,-1,minecraft:stone)
B(1,8,-1,minecraft:stone)
B(1,9,-1,minecraft:dirt)
B(1,10,-1,minecraft:grass_block)
B(1,0,0,minecraft:stone)
B(1,1,0,minecraft:stone)
B(1,2,0,minecraft:stone)
B(1,3,0,minecraft:stone)
B(1,4,0,minecraft:stone)
B(1,5,0,minecraft:stone)
B(1,6,0,minecraft:stone)
B(1,7,0,minecraft:stone)
B(1,8,0,minecraft:stone)
B(1,9,0,minecraft:stone)
B(1,0,1,minecraft:stone)
B(1,1,1,minecraft:stone)
B(1,2,1,minecraft:stone)
B(1,3,1,minecraft:stone)
B(1,4,1,minecraft:stone)
B(1,5,1,minecraft:stone)
B(1,6,1,minecraft:stone)
B(1,7,1,minecraft:stone)
B(1,8,1,minecraft:stone)
B(1,9,1,minecraft:stone)
B(1,10,1,minecraft:grass_block)
B(1,0,2,minecraft:stone)
B(1,1,2,minecraft:stone)
B(1,2,2,minecraft:stone)
B(1,3,2,minecraft:stone)
B(1,4,2,minecraft:stone)
B(1,5,2,minecraft:stone)
B(1,6,2,minecraft:stone)
B(1,7,2,minecraft:stone)
B(1,8,2,minecraft:stone)
B(1,9,2,minecraft:dirt)
B(1,10,2,minecraft:dirt)
B(1,11,2,minecraft:stone)
B(1,0,3,minecraft:stone)
B(1,1,3,minecraft:stone)
B(1,2,3,minecraft:stone)
B(1,3,3,minecraft:stone)
B(1,4,3,minecraft:stone)
B(1,5,3,minecraft:stone)
B(1,6,3,minecraft:stone)
B(1,7,3,minecraft:stone)
B(1,8,3,minecraft:stone)
B(1,9,3,minecraft:grass_block)
B(1,0,4,minecraft:stone)
B(1,1,4,minecraft:stone)
B(1,2,4,minecraft:stone)
B(1,3,4,minecraft:stone)
B(1,4,4,minecraft:stone)
B(1,5,4,minecraft:stone)
B(1,6,4,minecraft:andesite)
B(1,7,4,minecraft:andesite)
B(1,8,4,minecraft:andesite)
B(1,9,4,minecraft:grass_block)
B(1,2,5,minecraft:stone)
B(1,3,5,minecraft:stone)
B(1,4,5,minecraft:stone)
B(1,5,5,minecraft:andesite)
B(1,6,5,minecraft:andesite)
B(1,7,5,minecraft:andesite)
B(1,8,5,minecraft:coarse_dirt)
B(1,4,6,minecraft:stone)
B(1,5,6,minecraft:dirt)
B(1,6,6,minecraft:coarse_dirt)
B(1,7,6,minecraft:coarse_dirt)
B(1,8,6,minecraft:andesite)
B(1,4,7,minecraft:dirt)
B(1,5,7,minecraft:dirt)
B(1,6,7,minecraft:coarse_dirt)
B(2,5,-5,minecraft:dirt)
B(2,6,-5,minecraft:dirt)
B(2,7,-5,minecraft:dirt)
B(2,8,-5,minecraft:dirt)
B(2,9,-5,minecraft:grass_block)
B(2,3,-4,minecraft:stone)
B(2,4,-4,minecraft:stone)
B(2,5,-4,minecraft:stone)
B(2,6,-4,minecraft:dirt)
B(2,7,-4,minecraft:dirt)
B(2,8,-4,minecraft:dirt)
B(2,9,-4,minecraft:dirt)
B(2,10,-4,minecraft:grass_block)
B(2,3,-3,minecraft:stone)
B(2,4,-3,minecraft:stone)
B(2,5,-3,minecraft:stone)
B(2,6,-3,minecraft:stone)
B(2,7,-3,minecraft:stone)
B(2,8,-3,minecraft:stone)
B(2,9,-3,minecraft:andesite)
B(2,10,-3,minecraft:grass_block)
B(2,2,-2,minecraft:stone)
B(2,3,-2,minecraft:stone)
B(2,4,-2,minecraft:stone)
B(2,5,-2,minecraft:stone)
B(2,6,-2,minecraft:stone)
B(2,7,-2,minecraft:stone)
B(2,8,-2,minecraft:stone)
B(2,9,-2,minecraft:dirt)
B(2,10,-2,minecraft:grass_block)
B(2,1,-1,minecraft:stone)
B(2,2,-1,minecraft:stone)
B(2,3,-1,minecraft:stone)
B(2,4,-1,minecraft:stone)
B(2,5,-1,minecraft:stone)
B(2,6,-1,minecraft:stone)
B(2,7,-1,minecraft:stone)
B(2,8,-1,minecraft:stone)
B(2,9,-1,minecraft:dirt)
B(2,10,-1,minecraft:grass_block)
B(2,1,0,minecraft:stone)
B(2,2,0,minecraft:stone)
B(2,3,0,minecraft:stone)
B(2,4,0,minecraft:stone)
B(2,5,0,minecraft:stone)
B(2,6,0,minecraft:stone)
B(2,7,0,minecraft:stone)
B(2,8,0,minecraft:stone)
B(2,9,0,minecraft:grass_block)
B(2,0,1,minecraft:stone)
B(2,1,1,minecraft:stone)
B(2,2,1,minecraft:stone)
B(2,3,1,minecraft:stone)
B(2,4,1,minecraft:stone)
B(2,5,1,minecraft:stone)
B(2,6,1,minecraft:stone)
B(2,7,1,minecraft:stone)
B(2,8,1,minecraft:stone)
B(2,9,1,minecraft:stone)
B(2,10,1,minecraft:grass_block)
B(2,0,2,minecraft:stone)
B(2,1,2,minecraft:stone)
B(2,2,2,minecraft:stone)
B(2,3,2,minecraft:stone)
B(2,4,2,minecraft:stone)
B(2,5,2,minecraft:stone)
B(2,6,2,minecraft:stone)
B(2,7,2,minecraft:stone)
B(2,8,2,minecraft:stone)
B(2,9,2,minecraft:dirt)
B(2,10,2,minecraft:dirt)
B(2,11,2,minecraft:stone)
B(2,0,3,minecraft:stone)
B(2,1,3,minecraft:stone)
B(2,2,3,minecraft:stone)
B(2,3,3,minecraft:stone)
B(2,4,3,minecraft:stone)
B(2,5,3,minecraft:stone)
B(2,6,3,minecraft:stone)
B(2,7,3,minecraft:stone)
B(2,8,3,minecraft:stone)
B(2,9,3,minecraft:dirt)
B(2,10,3,minecraft:grass_block)
B(2,2,4,minecraft:stone)
B(2,3,4,minecraft:stone)
B(2,4,4,minecraft:stone)
B(2,5,4,minecraft:stone)
B(2,6,4,minecraft:stone)
B(2,7,4,minecraft:stone)
B(2,8,4,minecraft:coarse_dirt)
B(2,9,4,minecraft:dirt)
B(2,10,4,minecraft:grass_block)
B(2,3,5,minecraft:stone)
B(2,4,5,minecraft:stone)
B(2,5,5,minecraft:stone)
B(2,6,5,minecraft:andesite)
B(2,7,5,minecraft:andesite)
B(2,8,5,minecraft:coarse_dirt)
B(2,9,5,minecraft:grass_block)
B(2,3,6,minecraft:stone)
B(2,4,6,minecraft:stone)
B(2,5,6,minecraft:stone)
B(2,6,6,minecraft:coarse_dirt)
B(2,7,6,minecraft:andesite)
B(2,8,6,minecraft:coarse_dirt)
B(2,4,7,minecraft:stone)
B(2,5,7,minecraft:dirt)
B(2,6,7,minecraft:coarse_dirt)
B(3,6,-5,minecraft:dirt)
B(3,7,-5,minecraft:dirt)
B(3,8,-5,minecraft:grass_block)
B(3,4,-4,minecraft:stone)
B(3,5,-4,minecraft:stone)
B(3,6,-4,minecraft:stone)
B(3,7,-4,minecraft:dirt)
B(3,8,-4,minecraft:dirt)
B(3,9,-4,minecraft:dirt)
B(3,10,-4,minecraft:grass_block)
B(3,4,-3,minecraft:stone)
B(3,5,-3,minecraft:stone)
B(3,6,-3,minecraft:stone)
B(3,7,-3,minecraft:stone)
B(3,8,-3,minecraft:dirt)
B(3,9,-3,minecraft:coarse_dirt)
B(3,10,-3,minecraft:grass_block)
B(3,2,-2,minecraft:stone)
B(3,3,-2,minecraft:stone)
B(3,4,-2,minecraft:stone)
B(3,5,-2,minecraft:stone)
B(3,6,-2,minecraft:stone)
B(3,7,-2,minecraft:stone)
B(3,8,-2,minecraft:stone)
B(3,9,-2,minecraft:stone)
B(3,10,-2,minecraft:grass_block)
B(3,1,-1,minecraft:stone)
B(3,2,-1,minecraft:stone)
B(3,3,-1,minecraft:stone)
B(3,4,-1,minecraft:stone)
B(3,5,-1,minecraft:stone)
B(3,6,-1,minecraft:stone)
B(3,7,-1,minecraft:stone)
B(3,8,-1,minecraft:stone)
B(3,9,-1,minecraft:coarse_dirt)
B(3,1,0,minecraft:stone)
B(3,2,0,minecraft:stone)
B(3,3,0,minecraft:stone)
B(3,4,0,minecraft:stone)
B(3,5,0,minecraft:stone)
B(3,6,0,minecraft:stone)
B(3,7,0,minecraft:stone)
B(3,8,0,minecraft:stone)
B(3,9,0,minecraft:stone)
B(3,1,1,minecraft:stone)
B(3,2,1,minecraft:stone)
B(3,3,1,minecraft:stone)
B(3,4,1,minecraft:stone)
B(3,5,1,minecraft:stone)
B(3,6,1,minecraft:stone)
B(3,7,1,minecraft:stone)
B(3,8,1,minecraft:stone)
B(3,9,1,minecraft:stone)
B(3,10,1,minecraft:grass_block)
B(3,1,2,minecraft:stone)
B(3,2,2,minecraft:stone)
B(3,3,2,minecraft:stone)
B(3,4,2,minecraft:stone)
B(3,5,2,minecraft:stone)
B(3,6,2,minecraft:stone)
B(3,7,2,minecraft:stone)
B(3,8,2,minecraft:stone)
B(3,9,2,minecraft:coarse_dirt)
B(3,10,2,minecraft:dirt)
B(3,11,2,minecraft:coarse_dirt)
B(3,1,3,minecraft:stone)
B(3,2,3,minecraft:stone)
B(3,3,3,minecraft:stone)
B(3,4,3,minecraft:stone)
B(3,5,3,minecraft:stone)
B(3,6,3,minecraft:stone)
B(3,7,3,minecraft:stone)
B(3,8,3,minecraft:stone)
B(3,9,3,minecraft:dirt)
B(3,10,3,minecraft:grass_block)
B(3,2,4,minecraft:stone)
B(3,3,4,minecraft:stone)
B(3,4,4,minecraft:stone)
B(3,5,4,minecraft:stone)
B(3,6,4,minecraft:stone)
B(3,7,4,minecraft:stone)
B(3,8,4,minecraft:coarse_dirt)
B(3,9,4,minecraft:grass_block)
B(3,3,5,minecraft:stone)
B(3,4,5,minecraft:stone)
B(3,5,5,minecraft:stone)
B(3,6,5,minecraft:dirt)
B(3,7,5,minecraft:coarse_dirt)
B(3,8,5,minecraft:coarse_dirt)
B(3,4,6,minecraft:stone)
B(3,5,6,minecraft:dirt)
B(3,6,6,minecraft:dirt)
B(3,7,6,minecraft:coarse_dirt)
B(3,8,6,minecraft:coarse_dirt)
B(3,4,7,minecraft:stone)
B(3,5,7,minecraft:stone)
B(3,6,7,minecraft:dirt)
B(4,6,-4,minecraft:stone)
B(4,7,-4,minecraft:dirt)
B(4,8,-4,minecraft:grass_block)
B(4,4,-3,minecraft:stone)
B(4,5,-3,minecraft:stone)
B(4,6,-3,minecraft:stone)
B(4,7,-3,minecraft:dirt)
B(4,8,-3,minecraft:dirt)
B(4,9,-3,minecraft:coarse_dirt)
B(4,10,-3,minecraft:grass_block)
B(4,3,-2,minecraft:stone)
B(4,4,-2,minecraft:stone)
B(4,5,-2,minecraft:stone)
B(4,6,-2,minecraft:stone)
B(4,7,-2,minecraft:stone)
B(4,8,-2,minecraft:stone)
B(4,9,-2,minecraft:stone)
B(4,10,-2,minecraft:grass_block)
B(4,3,-1,minecraft:stone)
B(4,4,-1,minecraft:stone)
B(4,5,-1,minecraft:stone)
B(4,6,-1,minecraft:stone)
B(4,7,-1,minecraft:stone)
B(4,8,-1,minecraft:stone)
B(4,9,-1,minecraft:stone)
B(4,2,0,minecraft:stone)
B(4,3,0,minecraft:stone)
B(4,4,0,minecraft:stone)
B(4,5,0,minecraft:stone)
B(4,6,0,minecraft:stone)
B(4,7,0,minecraft:stone)
B(4,8,0,minecraft:stone)
B(4,9,0,minecraft:stone)
B(4,2,1,minecraft:stone)
B(4,3,1,minecraft:stone)
B(4,4,1,minecraft:stone)
B(4,5,1,minecraft:stone)
B(4,6,1,minecraft:stone)
B(4,7,1,minecraft:stone)
B(4,8,1,minecraft:stone)
B(4,9,1,minecraft:coarse_dirt)
B(4,10,1,minecraft:coarse_dirt)
B(4,2,2,minecraft:stone)
B(4,3,2,minecraft:stone)
B(4,4,2,minecraft:stone)
B(4,5,2,minecraft:stone)
B(4,6,2,minecraft:stone)
B(4,7,2,minecraft:stone)
B(4,8,2,minecraft:stone)
B(4,9,2,minecraft:coarse_dirt)
B(4,10,2,minecraft:grass_block)
B(4,2,3,minecraft:stone)
B(4,3,3,minecraft:stone)
B(4,4,3,minecraft:stone)
B(4,5,3,minecraft:stone)
B(4,6,3,minecraft:stone)
B(4,7,3,minecraft:stone)
B(4,8,3,minecraft:coarse_dirt)
B(4,9,3,minecraft:coarse_dirt)
B(4,10,3,minecraft:grass_block)
B(4,2,4,minecraft:stone)
B(4,3,4,minecraft:stone)
B(4,4,4,minecraft:stone)
B(4,5,4,minecraft:stone)
B(4,6,4,minecraft:stone)
B(4,7,4,minecraft:dirt)
B(4,8,4,minecraft:coarse_dirt)
B(4,9,4,minecraft:coarse_dirt)
B(4,3,5,minecraft:stone)
B(4,4,5,minecraft:stone)
B(4,5,5,minecraft:dirt)
B(4,6,5,minecraft:dirt)
B(4,7,5,minecraft:coarse_dirt)
B(4,8,5,minecraft:coarse_dirt)
B(4,4,6,minecraft:stone)
B(4,5,6,minecraft:dirt)
B(4,6,6,minecraft:dirt)
B(4,7,6,minecraft:coarse_dirt)
B(5,6,-3,minecraft:stone)
B(5,7,-3,minecraft:stone)
B(5,8,-3,minecraft:dirt)
B(5,9,-3,minecraft:stone)
B(5,5,-2,minecraft:stone)
B(5,6,-2,minecraft:stone)
B(5,7,-2,minecraft:stone)
B(5,8,-2,minecraft:stone)
B(5,9,-2,minecraft:stone)
B(5,4,-1,minecraft:stone)
B(5,5,-1,minecraft:stone)
B(5,6,-1,minecraft:stone)
B(5,7,-1,minecraft:stone)
B(5,8,-1,minecraft:stone)
B(5,9,-1,minecraft:coarse_dirt)
B(5,3,0,minecraft:stone)
B(5,4,0,minecraft:stone)
B(5,5,0,minecraft:stone)
B(5,6,0,minecraft:stone)
B(5,7,0,minecraft:stone)
B(5,8,0,minecraft:coarse_dirt)
B(5,9,0,minecraft:coarse_dirt)
B(5,3,1,minecraft:stone)
B(5,4,1,minecraft:stone)
B(5,5,1,minecraft:stone)
B(5,6,1,minecraft:stone)
B(5,7,1,minecraft:stone)
B(5,8,1,minecraft:stone)
B(5,9,1,minecraft:coarse_dirt)
B(5,3,2,minecraft:stone)
B(5,4,2,minecraft:stone)
B(5,5,2,minecraft:stone)
B(5,6,2,minecraft:stone)
B(5,7,2,minecraft:stone)
B(5,8,2,minecraft:stone)
B(5,9,2,minecraft:coarse_dirt)
B(5,3,3,minecraft:stone)
B(5,4,3,minecraft:stone)
B(5,5,3,minecraft:stone)
B(5,6,3,minecraft:stone)
B(5,7,3,minecraft:dirt)
B(5,8,3,minecraft:coarse_dirt)
B(5,9,3,minecraft:coarse_dirt)
B(5,3,4,minecraft:stone)
B(5,4,4,minecraft:stone)
B(5,5,4,minecraft:stone)
B(5,6,4,minecraft:dirt)
B(5,7,4,minecraft:dirt)
B(5,8,4,minecraft:coarse_dirt)
B(5,9,4,minecraft:coarse_dirt)
B(5,4,5,minecraft:stone)
B(5,5,5,minecraft:stone)
B(5,6,5,minecraft:dirt)
B(6,5,-2,minecraft:stone)
B(6,6,-2,minecraft:stone)
B(6,7,-2,minecraft:stone)
B(6,8,-2,minecraft:stone)
B(6,5,-1,minecraft:stone)
B(6,6,-1,minecraft:stone)
B(6,7,-1,minecraft:stone)
B(6,8,-1,minecraft:dirt)
B(6,5,0,minecraft:stone)
B(6,6,0,minecraft:stone)
B(6,7,0,minecraft:stone)
B(6,8,0,minecraft:coarse_dirt)
B(6,9,0,minecraft:coarse_dirt)
B(6,5,1,minecraft:stone)
B(6,6,1,minecraft:stone)
B(6,7,1,minecraft:stone)
B(6,8,1,minecraft:coarse_dirt)
B(6,9,1,minecraft:coarse_dirt)
B(6,6,2,minecraft:stone)
B(6,7,2,minecraft:stone)
B(6,8,2,minecraft:stone)
B(6,5,3,minecraft:stone)
B(6,6,3,minecraft:dirt)
B(6,7,3,minecraft:dirt)
B(6,5,4,minecraft:stone)
B(6,6,4,minecraft:dirt)
B(6,7,4,minecraft:dirt)
B(7,6,-1,minecraft:stone)
B(7,7,-1,minecraft:stone)
B(7,6,0,minecraft:stone)

#######################################################################
# +-----------------------------------------------------------------+ #
# |                            BO3 checks                           | #
# +-----------------------------------------------------------------+ #
#######################################################################

BlockCheck(0,5,0,minecraft:grass_block,minecraft:dirt,minecraft:water,minecraft:snow_block)
BlockCheck(1,-1,0,Solid)
BlockCheck(1,-1,-1,Solid)
BlockCheck(1,-1,1,Solid)
BlockCheck(0,-1,1,Solid)
BlockCheck(0,-1,-1,Solid)
BlockCheck(-1,-1,1,Solid)
BlockCheck(-1,-1,0,Solid)
BlockCheck(-1,-1,-1,Solid)
BlockCheck(2,-1,2,Solid)
BlockCheck(2,-1,1,Solid)
BlockCheck(2,-1,0,Solid)
BlockCheck(2,-1,-1,Solid)
BlockCheck(2,-1,-2,Solid)
BlockCheck(1,-1,2,Solid)
BlockCheck(1,-1,-2,Solid)
BlockCheck(0,-1,2,Solid)
BlockCheck(0,-1,-2,Solid)
BlockCheck(-1,-1,2,Solid)
BlockCheck(-1,-1,-2,Solid)
BlockCheck(-2,-1,2,Solid)
BlockCheck(-2,-1,1,Solid)
BlockCheck(-2,-1,0,Solid)
BlockCheck(-2,-1,-1,Solid)
BlockCheck(-2,-1,-2,Solid)
BlockCheck(4,-1,0,Solid)
BlockCheck(-4,-1,0,Solid)
BlockCheck(0,-1,4,Solid)
BlockCheck(0,-1,-4,Solid)
BlockCheck(4,-1,4,Solid)
BlockCheck(-4,-1,-4,Solid)
BlockCheck(-4,-1,4,Solid)
BlockCheck(4,-1,-4,Solid)

#######################################################################
# +-----------------------------------------------------------------+ #
# |                             Branches                            | #
# +-----------------------------------------------------------------+ #
#######################################################################


#######################################################################
# +-----------------------------------------------------------------+ #
# |                             Entities                            | #
# +-----------------------------------------------------------------+ #
#######################################################################

