
#######################################################################
# +-----------------------------------------------------------------+ #
# |                            BO3 object                           | #
# +-----------------------------------------------------------------+ #
#######################################################################

# This is the config file of a custom object.
# If you add this object correctly to your BiomeConfigs, it will spawn in the world.

# This is the creator of this BO3 object
Author: Unknown

# A short description of this BO3 object
Description: This BO3 was converted from a schematic using OTGEdit. The author and description information of the schematic could not be found. If you know who the author of the schematic is then please add this information.

# The BO3 version, don't change this! It can be used by external applications to do a version check.
Version: 3

# The settings mode, WriteAll, WriteWithoutComments or WriteDisable. See WorldConfig.
SettingsMode: WriteAll


#######################################################################
# +-----------------------------------------------------------------+ #
# |                          Main settings                          | #
# +-----------------------------------------------------------------+ #
#######################################################################

# This needs to be set to true to spawn the object in the Tree and Sapling resources.
Tree: true

# The frequency of the BO3 from 1 to 200. Tries this many times to spawn this BO3 when using the CustomObject(...) resource.
# Ignored by Tree(..), Sapling(..) and CustomStructure(..)
Frequency: 40

# The rarity of the BO3 from 0 to 100. Each spawn attempt has rarity% chance to succeed when using the CustomObject(...) resource.
# Ignored by Tree(..), Sapling(..) and CustomStructure(..)
Rarity: 100.0

# When using Frequency, after this many succesfull spawn attempts, abort spawning.
# For example, you can set 100 spawn attempts using Frequency, but stop spawning after 5 successfull spawns via MaxSpawn.
# 0 by default, which means ignore this setting.
# Ignored by Tree(..), Sapling(..) and CustomStructure(..)
MaxSpawn: 0

# If you set this to true, the BO3 will be placed with a random rotation.
RotateRandomly: true

# The spawn height of the BO3: randomY, highestBlock or highestSolidBlock.
SpawnHeight: randomY

# The offset from the spawn height to spawn this BO3
# Ex. SpawnHeight = highestSolidBlock, SpawnHeightOffset = 3; This object will spawn 3 blocks above the highest solid block
SpawnHeightOffset: 0

# A random amount to offset the spawn location from the spawn offset height
# Ex. SpawnHeightOffset = 3, SpawnHeightVariance = 3; This object will spawn 3 to 6 blocks above the original spot it would have spawned
SpawnHeightVariance: 0

##############################
# Height Limits for the BO3. #
##############################

# When in randomY mode used as the minimum Y or in atMinY mode as the actual Y to spawn this BO3 at.
MinHeight: 52

# When in randomY mode used as the maximum Y to spawn this BO3 at.
MaxHeight: 84

######################
# Extrusion settings #
######################

# The style of extrusion you wish to use - BottomDown, TopUp, None (Default)
ExtrudeMode: None

# The blocks to extrude your BO3 through
ExtrudeThroughBlocks: minecraft:air

# Objects can have other objects attacthed to it: branches. Branches can also
# have branches attached to it, which can also have branches, etc. This is the
# maximum branch depth for this objects.
MaxBranchDepth: 10


#######################################################################
# +-----------------------------------------------------------------+ #
# |                      Source block settings                      | #
# +-----------------------------------------------------------------+ #
#######################################################################

# The block(s) the BO3 should spawn in.
SourceBlocks: minecraft:air,minecraft:grass_block,minecraft:dirt,minecraft:water,minecraft:snow_block

# The maximum percentage of the BO3 that can be outside the SourceBlock.
# The BO3 won't be placed on a location with more blocks outside the SourceBlock than this percentage.
MaxPercentageOutsideSourceBlock: 5

# What to do when a block is about to be placed outside the SourceBlock? (dontPlace, placeAnyway)
OutsideSourceBlock: dontPlace

# Disable doReplaceBlocks to make this BO3 ignore any ReplacedBlocks settings in biome configs, improves performance.
DoReplaceBlocks: true

# OTG+ settings #
# Legacy setting, rename this file to .BO4 instead. Set this to true to enable the advanced customstructure features of OTG+.
IsOTGPlus: false


#######################################################################
# +-----------------------------------------------------------------+ #
# |                              Blocks                             | #
# +-----------------------------------------------------------------+ #
#######################################################################

# All the blocks used in the BO3 are listed here. Possible blocks:
# Block(x,y,z,id[.data][,nbtfile.nbt)
# RandomBlock(x,y,z,id[:data][,nbtfile.nbt],chance[,id[:data][,nbtfile.nbt],chance[,...]])
#  So RandomBlock(0,0,0,CHEST,chest.nbt,50,CHEST,anotherchest.nbt,100) will spawn a chest at
#  the BO3 origin, and give it a 50% chance to have the contents of chest.nbt, or, if that
#  fails, a 100% percent chance to have the contents of anotherchest.nbt.
# *Note: Unlike Entity() and Spawner(), for Block() .txt files don't work, only .nbt files work.
# MinecraftObject(x,y,z,name) (TODO: This may not work anymore and needs to be tested.
#  Spawns an object in the Mojang NBT structure format. For example, 
#  MinecraftObject(0,0,0,minecraft:igloo/igloo_bottom)
#  spawns the bottom part of an igloo.
B(-10,9,-3,minecraft:stone)
B(-10,11,-3,minecraft:stone)
B(-10,9,-2,minecraft:stone)
B(-10,10,-2,minecraft:stone)
B(-10,11,-2,minecraft:stone)
B(-10,4,-1,minecraft:stone)
B(-10,4,0,minecraft:stone)
B(-10,5,0,minecraft:stone)
B(-10,6,0,minecraft:stone)
B(-10,7,0,minecraft:stone)
B(-10,8,0,minecraft:stone)
B(-10,10,0,minecraft:stone)
B(-10,6,1,minecraft:stone)
B(-10,7,1,minecraft:stone)
B(-10,8,1,minecraft:stone)
B(-10,9,1,minecraft:stone)
B(-10,10,1,minecraft:stone)
B(-10,6,2,minecraft:stone)
B(-10,7,2,minecraft:stone)
B(-10,8,2,minecraft:stone)
B(-10,9,2,minecraft:stone)
B(-10,10,2,minecraft:stone)
B(-10,7,3,minecraft:stone)
B(-10,8,3,minecraft:stone)
B(-9,9,-5,minecraft:andesite)
B(-9,10,-5,minecraft:andesite)
B(-9,11,-5,minecraft:andesite)
B(-9,8,-4,minecraft:andesite)
B(-9,9,-4,minecraft:andesite)
B(-9,10,-4,minecraft:andesite)
B(-9,11,-4,minecraft:andesite)
B(-9,12,-4,minecraft:andesite)
B(-9,6,-3,minecraft:stone)
B(-9,7,-3,minecraft:stone)
B(-9,8,-3,minecraft:stone)
B(-9,9,-3,minecraft:andesite)
B(-9,10,-3,minecraft:andesite)
B(-9,11,-3,minecraft:andesite)
B(-9,12,-3,minecraft:stone)
B(-9,4,-2,minecraft:stone)
B(-9,5,-2,minecraft:stone)
B(-9,6,-2,minecraft:stone)
B(-9,7,-2,minecraft:stone)
B(-9,8,-2,minecraft:stone)
B(-9,9,-2,minecraft:stone)
B(-9,10,-2,minecraft:stone)
B(-9,11,-2,minecraft:stone)
B(-9,12,-2,minecraft:stone)
B(-9,4,-1,minecraft:stone)
B(-9,5,-1,minecraft:stone)
B(-9,6,-1,minecraft:stone)
B(-9,7,-1,minecraft:stone)
B(-9,8,-1,minecraft:stone)
B(-9,9,-1,minecraft:stone)
B(-9,10,-1,minecraft:stone)
B(-9,11,-1,minecraft:stone)
B(-9,12,-1,minecraft:stone)
B(-9,3,0,minecraft:stone)
B(-9,4,0,minecraft:stone)
B(-9,5,0,minecraft:stone)
B(-9,6,0,minecraft:stone)
B(-9,7,0,minecraft:stone)
B(-9,8,0,minecraft:stone)
B(-9,9,0,minecraft:stone)
B(-9,10,0,minecraft:stone)
B(-9,12,0,minecraft:stone)
B(-9,13,0,minecraft:stone)
B(-9,3,1,minecraft:stone)
B(-9,5,1,minecraft:stone)
B(-9,6,1,minecraft:stone)
B(-9,7,1,minecraft:stone)
B(-9,8,1,minecraft:stone)
B(-9,9,1,minecraft:stone)
B(-9,10,1,minecraft:stone)
B(-9,11,1,minecraft:stone)
B(-9,12,1,minecraft:stone)
B(-9,13,1,minecraft:stone)
B(-9,5,2,minecraft:stone)
B(-9,6,2,minecraft:stone)
B(-9,7,2,minecraft:stone)
B(-9,8,2,minecraft:stone)
B(-9,9,2,minecraft:stone)
B(-9,10,2,minecraft:stone)
B(-9,11,2,minecraft:stone)
B(-9,12,2,minecraft:stone)
B(-9,5,3,minecraft:stone)
B(-9,6,3,minecraft:stone)
B(-9,7,3,minecraft:stone)
B(-9,8,3,minecraft:stone)
B(-9,9,3,minecraft:stone)
B(-9,10,3,minecraft:stone)
B(-9,8,4,minecraft:stone)
B(-9,9,4,minecraft:stone)
B(-9,10,4,minecraft:stone)
B(-8,10,-6,minecraft:andesite)
B(-8,8,-5,minecraft:andesite)
B(-8,10,-5,minecraft:andesite)
B(-8,11,-5,minecraft:andesite)
B(-8,12,-5,minecraft:andesite)
B(-8,4,-4,minecraft:stone)
B(-8,5,-4,minecraft:stone)
B(-8,6,-4,minecraft:stone)
B(-8,7,-4,minecraft:stone)
B(-8,8,-4,minecraft:andesite)
B(-8,9,-4,minecraft:andesite)
B(-8,10,-4,minecraft:andesite)
B(-8,11,-4,minecraft:andesite)
B(-8,12,-4,minecraft:andesite)
B(-8,13,-4,minecraft:stone)
B(-8,3,-3,minecraft:stone)
B(-8,4,-3,minecraft:stone)
B(-8,5,-3,minecraft:stone)
B(-8,6,-3,minecraft:stone)
B(-8,7,-3,minecraft:stone)
B(-8,8,-3,minecraft:stone)
B(-8,9,-3,minecraft:andesite)
B(-8,10,-3,minecraft:andesite)
B(-8,11,-3,minecraft:andesite)
B(-8,12,-3,minecraft:stone)
B(-8,13,-3,minecraft:stone)
B(-8,4,-2,minecraft:stone)
B(-8,5,-2,minecraft:stone)
B(-8,6,-2,minecraft:stone)
B(-8,7,-2,minecraft:stone)
B(-8,8,-2,minecraft:stone)
B(-8,9,-2,minecraft:stone)
B(-8,10,-2,minecraft:stone)
B(-8,11,-2,minecraft:stone)
B(-8,12,-2,minecraft:stone)
B(-8,13,-2,minecraft:stone)
B(-8,2,-1,minecraft:stone)
B(-8,3,-1,minecraft:stone)
B(-8,4,-1,minecraft:stone)
B(-8,5,-1,minecraft:stone)
B(-8,6,-1,minecraft:stone)
B(-8,7,-1,minecraft:stone)
B(-8,8,-1,minecraft:stone)
B(-8,9,-1,minecraft:stone)
B(-8,10,-1,minecraft:stone)
B(-8,11,-1,minecraft:stone)
B(-8,12,-1,minecraft:stone)
B(-8,13,-1,minecraft:stone)
B(-8,14,-1,minecraft:stone)
B(-8,3,0,minecraft:stone)
B(-8,4,0,minecraft:stone)
B(-8,5,0,minecraft:stone)
B(-8,6,0,minecraft:stone)
B(-8,7,0,minecraft:stone)
B(-8,8,0,minecraft:stone)
B(-8,9,0,minecraft:stone)
B(-8,10,0,minecraft:stone)
B(-8,11,0,minecraft:stone)
B(-8,12,0,minecraft:stone)
B(-8,13,0,minecraft:stone)
B(-8,3,1,minecraft:stone)
B(-8,4,1,minecraft:stone)
B(-8,5,1,minecraft:stone)
B(-8,6,1,minecraft:stone)
B(-8,7,1,minecraft:stone)
B(-8,8,1,minecraft:stone)
B(-8,9,1,minecraft:stone)
B(-8,10,1,minecraft:stone)
B(-8,11,1,minecraft:stone)
B(-8,12,1,minecraft:stone)
B(-8,13,1,minecraft:stone)
B(-8,4,2,minecraft:stone)
B(-8,5,2,minecraft:stone)
B(-8,6,2,minecraft:stone)
B(-8,7,2,minecraft:stone)
B(-8,8,2,minecraft:stone)
B(-8,9,2,minecraft:stone)
B(-8,10,2,minecraft:stone)
B(-8,11,2,minecraft:stone)
B(-8,12,2,minecraft:stone)
B(-8,13,2,minecraft:stone)
B(-8,4,3,minecraft:stone)
B(-8,5,3,minecraft:stone)
B(-8,6,3,minecraft:stone)
B(-8,7,3,minecraft:stone)
B(-8,8,3,minecraft:stone)
B(-8,9,3,minecraft:stone)
B(-8,10,3,minecraft:stone)
B(-8,11,3,minecraft:stone)
B(-8,12,3,minecraft:stone)
B(-8,13,3,minecraft:stone)
B(-8,4,4,minecraft:stone)
B(-8,5,4,minecraft:stone)
B(-8,6,4,minecraft:stone)
B(-8,7,4,minecraft:stone)
B(-8,8,4,minecraft:stone)
B(-8,9,4,minecraft:stone)
B(-8,10,4,minecraft:stone)
B(-8,7,5,minecraft:andesite)
B(-8,8,5,minecraft:andesite)
B(-8,9,5,minecraft:andesite)
B(-7,5,-6,minecraft:stone)
B(-7,6,-6,minecraft:stone)
B(-7,7,-6,minecraft:stone)
B(-7,9,-6,minecraft:andesite)
B(-7,10,-6,minecraft:andesite)
B(-7,11,-6,minecraft:andesite)
B(-7,5,-5,minecraft:stone)
B(-7,6,-5,minecraft:stone)
B(-7,7,-5,minecraft:stone)
B(-7,8,-5,minecraft:andesite)
B(-7,9,-5,minecraft:andesite)
B(-7,10,-5,minecraft:andesite)
B(-7,11,-5,minecraft:andesite)
B(-7,12,-5,minecraft:andesite)
B(-7,4,-4,minecraft:stone)
B(-7,5,-4,minecraft:stone)
B(-7,6,-4,minecraft:stone)
B(-7,7,-4,minecraft:stone)
B(-7,8,-4,minecraft:andesite)
B(-7,9,-4,minecraft:andesite)
B(-7,10,-4,minecraft:andesite)
B(-7,11,-4,minecraft:andesite)
B(-7,12,-4,minecraft:andesite)
B(-7,13,-4,minecraft:stone)
B(-7,4,-3,minecraft:stone)
B(-7,5,-3,minecraft:stone)
B(-7,6,-3,minecraft:stone)
B(-7,7,-3,minecraft:stone)
B(-7,8,-3,minecraft:stone)
B(-7,9,-3,minecraft:andesite)
B(-7,10,-3,minecraft:andesite)
B(-7,11,-3,minecraft:andesite)
B(-7,12,-3,minecraft:stone)
B(-7,13,-3,minecraft:stone)
B(-7,14,-3,minecraft:stone)
B(-7,2,-2,minecraft:stone)
B(-7,3,-2,minecraft:stone)
B(-7,4,-2,minecraft:stone)
B(-7,5,-2,minecraft:stone)
B(-7,6,-2,minecraft:stone)
B(-7,7,-2,minecraft:stone)
B(-7,8,-2,minecraft:stone)
B(-7,9,-2,minecraft:stone)
B(-7,10,-2,minecraft:stone)
B(-7,11,-2,minecraft:stone)
B(-7,12,-2,minecraft:stone)
B(-7,13,-2,minecraft:stone)
B(-7,14,-2,minecraft:stone)
B(-7,3,-1,minecraft:stone)
B(-7,4,-1,minecraft:stone)
B(-7,5,-1,minecraft:stone)
B(-7,6,-1,minecraft:stone)
B(-7,7,-1,minecraft:stone)
B(-7,8,-1,minecraft:stone)
B(-7,9,-1,minecraft:stone)
B(-7,10,-1,minecraft:stone)
B(-7,11,-1,minecraft:stone)
B(-7,12,-1,minecraft:stone)
B(-7,13,-1,minecraft:stone)
B(-7,14,-1,minecraft:stone)
B(-7,2,0,minecraft:stone)
B(-7,3,0,minecraft:stone)
B(-7,4,0,minecraft:stone)
B(-7,5,0,minecraft:stone)
B(-7,6,0,minecraft:stone)
B(-7,7,0,minecraft:stone)
B(-7,8,0,minecraft:stone)
B(-7,9,0,minecraft:stone)
B(-7,10,0,minecraft:stone)
B(-7,11,0,minecraft:stone)
B(-7,12,0,minecraft:stone)
B(-7,13,0,minecraft:stone)
B(-7,3,1,minecraft:stone)
B(-7,4,1,minecraft:stone)
B(-7,5,1,minecraft:stone)
B(-7,6,1,minecraft:stone)
B(-7,7,1,minecraft:stone)
B(-7,8,1,minecraft:stone)
B(-7,9,1,minecraft:stone)
B(-7,10,1,minecraft:stone)
B(-7,11,1,minecraft:stone)
B(-7,12,1,minecraft:stone)
B(-7,13,1,minecraft:stone)
B(-7,14,1,minecraft:stone)
B(-7,3,2,minecraft:stone)
B(-7,4,2,minecraft:stone)
B(-7,5,2,minecraft:stone)
B(-7,6,2,minecraft:stone)
B(-7,7,2,minecraft:stone)
B(-7,8,2,minecraft:stone)
B(-7,9,2,minecraft:stone)
B(-7,10,2,minecraft:stone)
B(-7,11,2,minecraft:stone)
B(-7,12,2,minecraft:stone)
B(-7,13,2,minecraft:stone)
B(-7,14,2,minecraft:stone)
B(-7,3,3,minecraft:stone)
B(-7,4,3,minecraft:stone)
B(-7,5,3,minecraft:stone)
B(-7,6,3,minecraft:stone)
B(-7,7,3,minecraft:stone)
B(-7,8,3,minecraft:stone)
B(-7,9,3,minecraft:stone)
B(-7,10,3,minecraft:stone)
B(-7,11,3,minecraft:stone)
B(-7,12,3,minecraft:stone)
B(-7,13,3,minecraft:stone)
B(-7,4,4,minecraft:stone)
B(-7,5,4,minecraft:stone)
B(-7,6,4,minecraft:stone)
B(-7,7,4,minecraft:andesite)
B(-7,8,4,minecraft:andesite)
B(-7,9,4,minecraft:andesite)
B(-7,10,4,minecraft:stone)
B(-7,11,4,minecraft:stone)
B(-7,12,4,minecraft:stone)
B(-7,13,4,minecraft:stone)
B(-7,4,5,minecraft:stone)
B(-7,5,5,minecraft:andesite)
B(-7,6,5,minecraft:andesite)
B(-7,7,5,minecraft:andesite)
B(-7,8,5,minecraft:andesite)
B(-7,9,5,minecraft:andesite)
B(-7,10,5,minecraft:andesite)
B(-7,11,5,minecraft:andesite)
B(-7,5,6,minecraft:andesite)
B(-7,6,6,minecraft:andesite)
B(-7,7,6,minecraft:andesite)
B(-7,8,6,minecraft:andesite)
B(-6,6,-7,minecraft:andesite)
B(-6,7,-7,minecraft:andesite)
B(-6,8,-7,minecraft:andesite)
B(-6,5,-6,minecraft:andesite)
B(-6,6,-6,minecraft:andesite)
B(-6,7,-6,minecraft:andesite)
B(-6,8,-6,minecraft:andesite)
B(-6,9,-6,minecraft:andesite)
B(-6,10,-6,minecraft:andesite)
B(-6,11,-6,minecraft:andesite)
B(-6,4,-5,minecraft:stone)
B(-6,5,-5,minecraft:stone)
B(-6,6,-5,minecraft:stone)
B(-6,7,-5,minecraft:andesite)
B(-6,8,-5,minecraft:andesite)
B(-6,9,-5,minecraft:andesite)
B(-6,10,-5,minecraft:andesite)
B(-6,11,-5,minecraft:andesite)
B(-6,12,-5,minecraft:stone)
B(-6,13,-5,minecraft:stone)
B(-6,4,-4,minecraft:stone)
B(-6,5,-4,minecraft:stone)
B(-6,6,-4,minecraft:stone)
B(-6,7,-4,minecraft:stone)
B(-6,8,-4,minecraft:andesite)
B(-6,9,-4,minecraft:andesite)
B(-6,10,-4,minecraft:andesite)
B(-6,11,-4,minecraft:andesite)
B(-6,12,-4,minecraft:stone)
B(-6,13,-4,minecraft:stone)
B(-6,3,-3,minecraft:stone)
B(-6,4,-3,minecraft:stone)
B(-6,5,-3,minecraft:stone)
B(-6,6,-3,minecraft:stone)
B(-6,7,-3,minecraft:stone)
B(-6,8,-3,minecraft:stone)
B(-6,9,-3,minecraft:stone)
B(-6,10,-3,minecraft:stone)
B(-6,11,-3,minecraft:stone)
B(-6,12,-3,minecraft:stone)
B(-6,13,-3,minecraft:stone)
B(-6,14,-3,minecraft:stone)
B(-6,2,-2,minecraft:stone)
B(-6,3,-2,minecraft:stone)
B(-6,4,-2,minecraft:stone)
B(-6,5,-2,minecraft:stone)
B(-6,6,-2,minecraft:stone)
B(-6,7,-2,minecraft:stone)
B(-6,8,-2,minecraft:stone)
B(-6,9,-2,minecraft:stone)
B(-6,10,-2,minecraft:stone)
B(-6,11,-2,minecraft:stone)
B(-6,12,-2,minecraft:stone)
B(-6,13,-2,minecraft:stone)
B(-6,14,-2,minecraft:stone)
B(-6,2,-1,minecraft:stone)
B(-6,3,-1,minecraft:stone)
B(-6,4,-1,minecraft:stone)
B(-6,5,-1,minecraft:stone)
B(-6,6,-1,minecraft:stone)
B(-6,7,-1,minecraft:stone)
B(-6,8,-1,minecraft:stone)
B(-6,9,-1,minecraft:stone)
B(-6,10,-1,minecraft:stone)
B(-6,11,-1,minecraft:stone)
B(-6,12,-1,minecraft:stone)
B(-6,13,-1,minecraft:stone)
B(-6,14,-1,minecraft:stone)
B(-6,15,-1,minecraft:stone)
B(-6,1,0,minecraft:stone)
B(-6,2,0,minecraft:stone)
B(-6,3,0,minecraft:stone)
B(-6,4,0,minecraft:stone)
B(-6,5,0,minecraft:stone)
B(-6,6,0,minecraft:stone)
B(-6,7,0,minecraft:stone)
B(-6,8,0,minecraft:stone)
B(-6,9,0,minecraft:stone)
B(-6,10,0,minecraft:stone)
B(-6,11,0,minecraft:stone)
B(-6,12,0,minecraft:stone)
B(-6,13,0,minecraft:stone)
B(-6,14,0,minecraft:stone)
B(-6,2,1,minecraft:stone)
B(-6,3,1,minecraft:stone)
B(-6,4,1,minecraft:stone)
B(-6,5,1,minecraft:stone)
B(-6,6,1,minecraft:stone)
B(-6,7,1,minecraft:stone)
B(-6,8,1,minecraft:stone)
B(-6,9,1,minecraft:stone)
B(-6,10,1,minecraft:stone)
B(-6,11,1,minecraft:stone)
B(-6,12,1,minecraft:stone)
B(-6,13,1,minecraft:stone)
B(-6,14,1,minecraft:andesite)
B(-6,15,1,minecraft:andesite)
B(-6,2,2,minecraft:stone)
B(-6,3,2,minecraft:stone)
B(-6,4,2,minecraft:stone)
B(-6,5,2,minecraft:stone)
B(-6,6,2,minecraft:stone)
B(-6,7,2,minecraft:stone)
B(-6,8,2,minecraft:stone)
B(-6,9,2,minecraft:stone)
B(-6,10,2,minecraft:stone)
B(-6,11,2,minecraft:stone)
B(-6,12,2,minecraft:stone)
B(-6,13,2,minecraft:stone)
B(-6,14,2,minecraft:andesite)
B(-6,3,3,minecraft:stone)
B(-6,4,3,minecraft:stone)
B(-6,5,3,minecraft:stone)
B(-6,6,3,minecraft:stone)
B(-6,7,3,minecraft:stone)
B(-6,8,3,minecraft:stone)
B(-6,9,3,minecraft:stone)
B(-6,10,3,minecraft:stone)
B(-6,11,3,minecraft:stone)
B(-6,12,3,minecraft:andesite)
B(-6,13,3,minecraft:andesite)
B(-6,14,3,minecraft:andesite)
B(-6,3,4,minecraft:stone)
B(-6,4,4,minecraft:stone)
B(-6,5,4,minecraft:stone)
B(-6,6,4,minecraft:stone)
B(-6,7,4,minecraft:andesite)
B(-6,8,4,minecraft:andesite)
B(-6,9,4,minecraft:andesite)
B(-6,10,4,minecraft:stone)
B(-6,11,4,minecraft:andesite)
B(-6,12,4,minecraft:andesite)
B(-6,13,4,minecraft:andesite)
B(-6,14,4,minecraft:andesite)
B(-6,3,5,minecraft:andesite)
B(-6,4,5,minecraft:andesite)
B(-6,5,5,minecraft:andesite)
B(-6,6,5,minecraft:andesite)
B(-6,7,5,minecraft:andesite)
B(-6,8,5,minecraft:andesite)
B(-6,9,5,minecraft:andesite)
B(-6,10,5,minecraft:andesite)
B(-6,11,5,minecraft:andesite)
B(-6,12,5,minecraft:andesite)
B(-6,4,6,minecraft:andesite)
B(-6,5,6,minecraft:andesite)
B(-6,6,6,minecraft:andesite)
B(-6,7,6,minecraft:andesite)
B(-6,8,6,minecraft:andesite)
B(-6,9,6,minecraft:andesite)
B(-6,10,6,minecraft:andesite)
B(-6,11,6,minecraft:andesite)
B(-6,12,6,minecraft:andesite)
B(-6,6,7,minecraft:andesite)
B(-6,7,7,minecraft:andesite)
B(-6,7,8,minecraft:andesite)
B(-5,6,-8,minecraft:andesite)
B(-5,7,-8,minecraft:andesite)
B(-5,5,-7,minecraft:andesite)
B(-5,6,-7,minecraft:andesite)
B(-5,7,-7,minecraft:andesite)
B(-5,8,-7,minecraft:andesite)
B(-5,4,-6,minecraft:stone)
B(-5,5,-6,minecraft:andesite)
B(-5,6,-6,minecraft:andesite)
B(-5,7,-6,minecraft:andesite)
B(-5,8,-6,minecraft:andesite)
B(-5,9,-6,minecraft:andesite)
B(-5,10,-6,minecraft:andesite)
B(-5,11,-6,minecraft:andesite)
B(-5,12,-6,minecraft:stone)
B(-5,3,-5,minecraft:stone)
B(-5,4,-5,minecraft:stone)
B(-5,5,-5,minecraft:stone)
B(-5,6,-5,minecraft:stone)
B(-5,7,-5,minecraft:andesite)
B(-5,8,-5,minecraft:andesite)
B(-5,9,-5,minecraft:andesite)
B(-5,10,-5,minecraft:andesite)
B(-5,11,-5,minecraft:andesite)
B(-5,12,-5,minecraft:stone)
B(-5,13,-5,minecraft:stone)
B(-5,3,-4,minecraft:stone)
B(-5,4,-4,minecraft:stone)
B(-5,5,-4,minecraft:stone)
B(-5,6,-4,minecraft:stone)
B(-5,7,-4,minecraft:stone)
B(-5,8,-4,minecraft:andesite)
B(-5,9,-4,minecraft:andesite)
B(-5,10,-4,minecraft:andesite)
B(-5,11,-4,minecraft:stone)
B(-5,12,-4,minecraft:stone)
B(-5,13,-4,minecraft:stone)
B(-5,14,-4,minecraft:stone)
B(-5,2,-3,minecraft:stone)
B(-5,3,-3,minecraft:stone)
B(-5,4,-3,minecraft:stone)
B(-5,5,-3,minecraft:stone)
B(-5,6,-3,minecraft:stone)
B(-5,7,-3,minecraft:stone)
B(-5,8,-3,minecraft:stone)
B(-5,9,-3,minecraft:stone)
B(-5,10,-3,minecraft:stone)
B(-5,11,-3,minecraft:stone)
B(-5,12,-3,minecraft:stone)
B(-5,13,-3,minecraft:stone)
B(-5,14,-3,minecraft:stone)
B(-5,15,-3,minecraft:stone)
B(-5,1,-2,minecraft:stone)
B(-5,3,-2,minecraft:stone)
B(-5,4,-2,minecraft:stone)
B(-5,5,-2,minecraft:stone)
B(-5,6,-2,minecraft:stone)
B(-5,7,-2,minecraft:stone)
B(-5,8,-2,minecraft:stone)
B(-5,9,-2,minecraft:stone)
B(-5,10,-2,minecraft:stone)
B(-5,11,-2,minecraft:stone)
B(-5,12,-2,minecraft:stone)
B(-5,13,-2,minecraft:stone)
B(-5,14,-2,minecraft:stone)
B(-5,15,-2,minecraft:stone)
B(-5,1,-1,minecraft:stone)
B(-5,3,-1,minecraft:stone)
B(-5,4,-1,minecraft:stone)
B(-5,5,-1,minecraft:stone)
B(-5,6,-1,minecraft:stone)
B(-5,7,-1,minecraft:stone)
B(-5,8,-1,minecraft:stone)
B(-5,9,-1,minecraft:stone)
B(-5,10,-1,minecraft:stone)
B(-5,11,-1,minecraft:stone)
B(-5,12,-1,minecraft:stone)
B(-5,13,-1,minecraft:stone)
B(-5,14,-1,minecraft:stone)
B(-5,15,-1,minecraft:stone)
B(-5,16,-1,minecraft:stone)
B(-5,1,0,minecraft:stone)
B(-5,2,0,minecraft:stone)
B(-5,3,0,minecraft:stone)
B(-5,4,0,minecraft:stone)
B(-5,5,0,minecraft:stone)
B(-5,6,0,minecraft:stone)
B(-5,7,0,minecraft:stone)
B(-5,8,0,minecraft:stone)
B(-5,9,0,minecraft:stone)
B(-5,10,0,minecraft:stone)
B(-5,11,0,minecraft:stone)
B(-5,12,0,minecraft:stone)
B(-5,13,0,minecraft:stone)
B(-5,14,0,minecraft:andesite)
B(-5,15,0,minecraft:andesite)
B(-5,16,0,minecraft:andesite)
B(-5,1,1,minecraft:stone)
B(-5,2,1,minecraft:stone)
B(-5,3,1,minecraft:stone)
B(-5,4,1,minecraft:stone)
B(-5,5,1,minecraft:stone)
B(-5,6,1,minecraft:stone)
B(-5,7,1,minecraft:stone)
B(-5,8,1,minecraft:stone)
B(-5,9,1,minecraft:stone)
B(-5,10,1,minecraft:stone)
B(-5,11,1,minecraft:stone)
B(-5,12,1,minecraft:stone)
B(-5,13,1,minecraft:andesite)
B(-5,14,1,minecraft:andesite)
B(-5,15,1,minecraft:andesite)
B(-5,1,2,minecraft:stone)
B(-5,2,2,minecraft:stone)
B(-5,3,2,minecraft:stone)
B(-5,4,2,minecraft:stone)
B(-5,5,2,minecraft:stone)
B(-5,6,2,minecraft:stone)
B(-5,7,2,minecraft:stone)
B(-5,8,2,minecraft:stone)
B(-5,9,2,minecraft:stone)
B(-5,10,2,minecraft:stone)
B(-5,11,2,minecraft:stone)
B(-5,12,2,minecraft:andesite)
B(-5,13,2,minecraft:andesite)
B(-5,14,2,minecraft:andesite)
B(-5,15,2,minecraft:andesite)
B(-5,2,3,minecraft:stone)
B(-5,3,3,minecraft:stone)
B(-5,4,3,minecraft:stone)
B(-5,5,3,minecraft:stone)
B(-5,6,3,minecraft:stone)
B(-5,7,3,minecraft:stone)
B(-5,8,3,minecraft:stone)
B(-5,9,3,minecraft:stone)
B(-5,10,3,minecraft:stone)
B(-5,11,3,minecraft:andesite)
B(-5,12,3,minecraft:andesite)
B(-5,13,3,minecraft:andesite)
B(-5,14,3,minecraft:andesite)
B(-5,15,3,minecraft:andesite)
B(-5,2,4,minecraft:stone)
B(-5,3,4,minecraft:stone)
B(-5,4,4,minecraft:stone)
B(-5,5,4,minecraft:stone)
B(-5,6,4,minecraft:stone)
B(-5,7,4,minecraft:andesite)
B(-5,8,4,minecraft:andesite)
B(-5,9,4,minecraft:andesite)
B(-5,10,4,minecraft:stone)
B(-5,11,4,minecraft:andesite)
B(-5,12,4,minecraft:andesite)
B(-5,13,4,minecraft:andesite)
B(-5,14,4,minecraft:andesite)
B(-5,2,5,minecraft:stone)
B(-5,3,5,minecraft:andesite)
B(-5,4,5,minecraft:andesite)
B(-5,5,5,minecraft:andesite)
B(-5,6,5,minecraft:andesite)
B(-5,7,5,minecraft:andesite)
B(-5,8,5,minecraft:andesite)
B(-5,9,5,minecraft:andesite)
B(-5,10,5,minecraft:andesite)
B(-5,11,5,minecraft:andesite)
B(-5,12,5,minecraft:andesite)
B(-5,13,5,minecraft:andesite)
B(-5,2,6,minecraft:andesite)
B(-5,3,6,minecraft:andesite)
B(-5,4,6,minecraft:andesite)
B(-5,5,6,minecraft:andesite)
B(-5,6,6,minecraft:andesite)
B(-5,7,6,minecraft:andesite)
B(-5,8,6,minecraft:andesite)
B(-5,9,6,minecraft:andesite)
B(-5,10,6,minecraft:andesite)
B(-5,11,6,minecraft:andesite)
B(-5,12,6,minecraft:andesite)
B(-5,4,7,minecraft:andesite)
B(-5,5,7,minecraft:andesite)
B(-5,6,7,minecraft:andesite)
B(-5,7,7,minecraft:andesite)
B(-5,8,7,minecraft:andesite)
B(-5,9,7,minecraft:andesite)
B(-5,10,7,minecraft:andesite)
B(-5,11,7,minecraft:andesite)
B(-4,5,-8,minecraft:andesite)
B(-4,6,-8,minecraft:andesite)
B(-4,7,-8,minecraft:andesite)
B(-4,4,-7,minecraft:andesite)
B(-4,5,-7,minecraft:andesite)
B(-4,6,-7,minecraft:andesite)
B(-4,7,-7,minecraft:andesite)
B(-4,8,-7,minecraft:andesite)
B(-4,9,-7,minecraft:andesite)
B(-4,10,-7,minecraft:andesite)
B(-4,11,-7,minecraft:andesite)
B(-4,12,-7,minecraft:stone)
B(-4,13,-7,minecraft:stone)
B(-4,3,-6,minecraft:stone)
B(-4,4,-6,minecraft:andesite)
B(-4,5,-6,minecraft:andesite)
B(-4,6,-6,minecraft:andesite)
B(-4,7,-6,minecraft:andesite)
B(-4,8,-6,minecraft:andesite)
B(-4,9,-6,minecraft:andesite)
B(-4,10,-6,minecraft:andesite)
B(-4,11,-6,minecraft:andesite)
B(-4,12,-6,minecraft:stone)
B(-4,13,-6,minecraft:stone)
B(-4,3,-5,minecraft:stone)
B(-4,4,-5,minecraft:stone)
B(-4,5,-5,minecraft:stone)
B(-4,6,-5,minecraft:stone)
B(-4,7,-5,minecraft:andesite)
B(-4,8,-5,minecraft:andesite)
B(-4,9,-5,minecraft:andesite)
B(-4,10,-5,minecraft:andesite)
B(-4,11,-5,minecraft:andesite)
B(-4,12,-5,minecraft:stone)
B(-4,13,-5,minecraft:stone)
B(-4,2,-4,minecraft:stone)
B(-4,3,-4,minecraft:stone)
B(-4,4,-4,minecraft:stone)
B(-4,5,-4,minecraft:stone)
B(-4,6,-4,minecraft:stone)
B(-4,7,-4,minecraft:stone)
B(-4,8,-4,minecraft:andesite)
B(-4,9,-4,minecraft:andesite)
B(-4,10,-4,minecraft:andesite)
B(-4,11,-4,minecraft:stone)
B(-4,12,-4,minecraft:stone)
B(-4,13,-4,minecraft:stone)
B(-4,14,-4,minecraft:stone)
B(-4,1,-3,minecraft:stone)
B(-4,2,-3,minecraft:stone)
B(-4,3,-3,minecraft:stone)
B(-4,4,-3,minecraft:stone)
B(-4,5,-3,minecraft:stone)
B(-4,6,-3,minecraft:stone)
B(-4,7,-3,minecraft:stone)
B(-4,8,-3,minecraft:stone)
B(-4,9,-3,minecraft:stone)
B(-4,10,-3,minecraft:stone)
B(-4,11,-3,minecraft:stone)
B(-4,12,-3,minecraft:stone)
B(-4,13,-3,minecraft:stone)
B(-4,14,-3,minecraft:stone)
B(-4,15,-3,minecraft:stone)
B(-4,16,-3,minecraft:stone)
B(-4,1,-2,minecraft:stone)
B(-4,2,-2,minecraft:stone)
B(-4,3,-2,minecraft:stone)
B(-4,4,-2,minecraft:stone)
B(-4,5,-2,minecraft:stone)
B(-4,6,-2,minecraft:stone)
B(-4,7,-2,minecraft:stone)
B(-4,8,-2,minecraft:stone)
B(-4,9,-2,minecraft:stone)
B(-4,10,-2,minecraft:stone)
B(-4,11,-2,minecraft:stone)
B(-4,12,-2,minecraft:stone)
B(-4,13,-2,minecraft:stone)
B(-4,14,-2,minecraft:stone)
B(-4,15,-2,minecraft:stone)
B(-4,16,-2,minecraft:stone)
B(-4,1,-1,minecraft:stone)
B(-4,2,-1,minecraft:stone)
B(-4,3,-1,minecraft:stone)
B(-4,4,-1,minecraft:stone)
B(-4,5,-1,minecraft:stone)
B(-4,6,-1,minecraft:stone)
B(-4,7,-1,minecraft:stone)
B(-4,8,-1,minecraft:stone)
B(-4,9,-1,minecraft:stone)
B(-4,10,-1,minecraft:stone)
B(-4,11,-1,minecraft:stone)
B(-4,12,-1,minecraft:stone)
B(-4,13,-1,minecraft:stone)
B(-4,14,-1,minecraft:stone)
B(-4,15,-1,minecraft:stone)
B(-4,16,-1,minecraft:stone)
B(-4,1,0,minecraft:stone)
B(-4,2,0,minecraft:stone)
B(-4,3,0,minecraft:stone)
B(-4,4,0,minecraft:stone)
B(-4,5,0,minecraft:stone)
B(-4,6,0,minecraft:stone)
B(-4,7,0,minecraft:stone)
B(-4,8,0,minecraft:stone)
B(-4,9,0,minecraft:stone)
B(-4,10,0,minecraft:stone)
B(-4,11,0,minecraft:stone)
B(-4,12,0,minecraft:stone)
B(-4,13,0,minecraft:stone)
B(-4,14,0,minecraft:andesite)
B(-4,15,0,minecraft:andesite)
B(-4,16,0,minecraft:andesite)
B(-4,1,1,minecraft:stone)
B(-4,2,1,minecraft:stone)
B(-4,3,1,minecraft:stone)
B(-4,4,1,minecraft:stone)
B(-4,5,1,minecraft:stone)
B(-4,6,1,minecraft:stone)
B(-4,7,1,minecraft:stone)
B(-4,8,1,minecraft:stone)
B(-4,9,1,minecraft:stone)
B(-4,10,1,minecraft:stone)
B(-4,11,1,minecraft:stone)
B(-4,12,1,minecraft:stone)
B(-4,13,1,minecraft:andesite)
B(-4,14,1,minecraft:andesite)
B(-4,15,1,minecraft:andesite)
B(-4,16,1,minecraft:andesite)
B(-4,1,2,minecraft:stone)
B(-4,2,2,minecraft:stone)
B(-4,3,2,minecraft:stone)
B(-4,4,2,minecraft:stone)
B(-4,5,2,minecraft:stone)
B(-4,6,2,minecraft:stone)
B(-4,7,2,minecraft:stone)
B(-4,8,2,minecraft:stone)
B(-4,9,2,minecraft:stone)
B(-4,10,2,minecraft:stone)
B(-4,11,2,minecraft:stone)
B(-4,12,2,minecraft:andesite)
B(-4,13,2,minecraft:andesite)
B(-4,14,2,minecraft:andesite)
B(-4,15,2,minecraft:andesite)
B(-4,2,3,minecraft:stone)
B(-4,3,3,minecraft:stone)
B(-4,4,3,minecraft:stone)
B(-4,5,3,minecraft:stone)
B(-4,6,3,minecraft:stone)
B(-4,7,3,minecraft:stone)
B(-4,8,3,minecraft:stone)
B(-4,9,3,minecraft:stone)
B(-4,10,3,minecraft:stone)
B(-4,11,3,minecraft:andesite)
B(-4,12,3,minecraft:andesite)
B(-4,13,3,minecraft:andesite)
B(-4,14,3,minecraft:andesite)
B(-4,15,3,minecraft:andesite)
B(-4,1,4,minecraft:stone)
B(-4,2,4,minecraft:stone)
B(-4,3,4,minecraft:stone)
B(-4,4,4,minecraft:stone)
B(-4,5,4,minecraft:stone)
B(-4,6,4,minecraft:stone)
B(-4,7,4,minecraft:stone)
B(-4,8,4,minecraft:stone)
B(-4,9,4,minecraft:stone)
B(-4,10,4,minecraft:stone)
B(-4,11,4,minecraft:andesite)
B(-4,12,4,minecraft:andesite)
B(-4,13,4,minecraft:andesite)
B(-4,2,5,minecraft:stone)
B(-4,3,5,minecraft:andesite)
B(-4,4,5,minecraft:andesite)
B(-4,5,5,minecraft:andesite)
B(-4,6,5,minecraft:stone)
B(-4,7,5,minecraft:andesite)
B(-4,8,5,minecraft:andesite)
B(-4,9,5,minecraft:andesite)
B(-4,10,5,minecraft:andesite)
B(-4,11,5,minecraft:andesite)
B(-4,12,5,minecraft:andesite)
B(-4,13,5,minecraft:andesite)
B(-4,2,6,minecraft:andesite)
B(-4,3,6,minecraft:andesite)
B(-4,4,6,minecraft:andesite)
B(-4,5,6,minecraft:andesite)
B(-4,6,6,minecraft:andesite)
B(-4,7,6,minecraft:andesite)
B(-4,8,6,minecraft:andesite)
B(-4,9,6,minecraft:andesite)
B(-4,10,6,minecraft:andesite)
B(-4,11,6,minecraft:andesite)
B(-4,12,6,minecraft:andesite)
B(-4,3,7,minecraft:andesite)
B(-4,4,7,minecraft:andesite)
B(-4,5,7,minecraft:andesite)
B(-4,6,7,minecraft:andesite)
B(-4,7,7,minecraft:andesite)
B(-4,8,7,minecraft:andesite)
B(-4,9,7,minecraft:andesite)
B(-4,10,7,minecraft:andesite)
B(-4,11,7,minecraft:andesite)
B(-4,5,8,minecraft:andesite)
B(-4,6,8,minecraft:andesite)
B(-4,7,8,minecraft:andesite)
B(-4,8,8,minecraft:stone)
B(-3,5,-8,minecraft:andesite)
B(-3,6,-8,minecraft:andesite)
B(-3,7,-8,minecraft:andesite)
B(-3,10,-8,minecraft:stone)
B(-3,11,-8,minecraft:stone)
B(-3,12,-8,minecraft:stone)
B(-3,4,-7,minecraft:andesite)
B(-3,5,-7,minecraft:andesite)
B(-3,6,-7,minecraft:andesite)
B(-3,7,-7,minecraft:andesite)
B(-3,8,-7,minecraft:andesite)
B(-3,9,-7,minecraft:andesite)
B(-3,10,-7,minecraft:andesite)
B(-3,11,-7,minecraft:stone)
B(-3,12,-7,minecraft:stone)
B(-3,13,-7,minecraft:stone)
B(-3,4,-6,minecraft:andesite)
B(-3,5,-6,minecraft:andesite)
B(-3,6,-6,minecraft:andesite)
B(-3,7,-6,minecraft:stone)
B(-3,8,-6,minecraft:andesite)
B(-3,9,-6,minecraft:andesite)
B(-3,10,-6,minecraft:andesite)
B(-3,11,-6,minecraft:stone)
B(-3,12,-6,minecraft:stone)
B(-3,13,-6,minecraft:stone)
B(-3,14,-6,minecraft:stone)
B(-3,2,-5,minecraft:stone)
B(-3,3,-5,minecraft:stone)
B(-3,4,-5,minecraft:stone)
B(-3,5,-5,minecraft:stone)
B(-3,6,-5,minecraft:stone)
B(-3,7,-5,minecraft:stone)
B(-3,8,-5,minecraft:andesite)
B(-3,9,-5,minecraft:andesite)
B(-3,10,-5,minecraft:andesite)
B(-3,11,-5,minecraft:stone)
B(-3,12,-5,minecraft:stone)
B(-3,13,-5,minecraft:stone)
B(-3,14,-5,minecraft:stone)
B(-3,2,-4,minecraft:stone)
B(-3,3,-4,minecraft:stone)
B(-3,4,-4,minecraft:stone)
B(-3,5,-4,minecraft:stone)
B(-3,6,-4,minecraft:stone)
B(-3,7,-4,minecraft:stone)
B(-3,8,-4,minecraft:stone)
B(-3,9,-4,minecraft:stone)
B(-3,10,-4,minecraft:stone)
B(-3,11,-4,minecraft:stone)
B(-3,12,-4,minecraft:stone)
B(-3,13,-4,minecraft:stone)
B(-3,14,-4,minecraft:stone)
B(-3,15,-4,minecraft:stone)
B(-3,16,-4,minecraft:stone)
B(-3,1,-3,minecraft:stone)
B(-3,2,-3,minecraft:stone)
B(-3,3,-3,minecraft:stone)
B(-3,4,-3,minecraft:stone)
B(-3,5,-3,minecraft:stone)
B(-3,6,-3,minecraft:stone)
B(-3,7,-3,minecraft:stone)
B(-3,8,-3,minecraft:stone)
B(-3,9,-3,minecraft:stone)
B(-3,10,-3,minecraft:stone)
B(-3,11,-3,minecraft:stone)
B(-3,12,-3,minecraft:stone)
B(-3,13,-3,minecraft:stone)
B(-3,14,-3,minecraft:stone)
B(-3,15,-3,minecraft:stone)
B(-3,16,-3,minecraft:stone)
B(-3,1,-2,minecraft:stone)
B(-3,2,-2,minecraft:stone)
B(-3,3,-2,minecraft:stone)
B(-3,4,-2,minecraft:stone)
B(-3,5,-2,minecraft:stone)
B(-3,6,-2,minecraft:stone)
B(-3,7,-2,minecraft:stone)
B(-3,8,-2,minecraft:stone)
B(-3,9,-2,minecraft:stone)
B(-3,10,-2,minecraft:stone)
B(-3,11,-2,minecraft:stone)
B(-3,12,-2,minecraft:stone)
B(-3,13,-2,minecraft:stone)
B(-3,14,-2,minecraft:stone)
B(-3,15,-2,minecraft:stone)
B(-3,16,-2,minecraft:stone)
B(-3,17,-2,minecraft:stone)
B(-3,0,-1,minecraft:stone)
B(-3,1,-1,minecraft:stone)
B(-3,2,-1,minecraft:stone)
B(-3,3,-1,minecraft:stone)
B(-3,4,-1,minecraft:stone)
B(-3,5,-1,minecraft:stone)
B(-3,6,-1,minecraft:stone)
B(-3,7,-1,minecraft:stone)
B(-3,8,-1,minecraft:stone)
B(-3,9,-1,minecraft:stone)
B(-3,10,-1,minecraft:stone)
B(-3,11,-1,minecraft:stone)
B(-3,12,-1,minecraft:stone)
B(-3,13,-1,minecraft:stone)
B(-3,14,-1,minecraft:stone)
B(-3,15,-1,minecraft:stone)
B(-3,16,-1,minecraft:stone)
B(-3,17,-1,minecraft:stone)
B(-3,0,0,minecraft:stone)
B(-3,1,0,minecraft:stone)
B(-3,2,0,minecraft:stone)
B(-3,3,0,minecraft:stone)
B(-3,4,0,minecraft:stone)
B(-3,5,0,minecraft:stone)
B(-3,6,0,minecraft:stone)
B(-3,7,0,minecraft:stone)
B(-3,8,0,minecraft:stone)
B(-3,9,0,minecraft:stone)
B(-3,10,0,minecraft:stone)
B(-3,11,0,minecraft:stone)
B(-3,12,0,minecraft:stone)
B(-3,13,0,minecraft:stone)
B(-3,14,0,minecraft:andesite)
B(-3,15,0,minecraft:andesite)
B(-3,16,0,minecraft:andesite)
B(-3,17,0,minecraft:andesite)
B(-3,0,1,minecraft:stone)
B(-3,1,1,minecraft:stone)
B(-3,2,1,minecraft:stone)
B(-3,3,1,minecraft:stone)
B(-3,4,1,minecraft:stone)
B(-3,5,1,minecraft:stone)
B(-3,6,1,minecraft:stone)
B(-3,7,1,minecraft:stone)
B(-3,8,1,minecraft:stone)
B(-3,9,1,minecraft:stone)
B(-3,10,1,minecraft:stone)
B(-3,11,1,minecraft:stone)
B(-3,12,1,minecraft:stone)
B(-3,13,1,minecraft:andesite)
B(-3,14,1,minecraft:andesite)
B(-3,15,1,minecraft:andesite)
B(-3,16,1,minecraft:andesite)
B(-3,1,2,minecraft:stone)
B(-3,2,2,minecraft:stone)
B(-3,3,2,minecraft:stone)
B(-3,4,2,minecraft:stone)
B(-3,5,2,minecraft:stone)
B(-3,6,2,minecraft:stone)
B(-3,7,2,minecraft:stone)
B(-3,8,2,minecraft:stone)
B(-3,9,2,minecraft:stone)
B(-3,10,2,minecraft:stone)
B(-3,11,2,minecraft:stone)
B(-3,12,2,minecraft:andesite)
B(-3,13,2,minecraft:andesite)
B(-3,14,2,minecraft:andesite)
B(-3,15,2,minecraft:andesite)
B(-3,16,2,minecraft:andesite)
B(-3,1,3,minecraft:stone)
B(-3,2,3,minecraft:stone)
B(-3,3,3,minecraft:stone)
B(-3,4,3,minecraft:stone)
B(-3,5,3,minecraft:stone)
B(-3,6,3,minecraft:stone)
B(-3,7,3,minecraft:stone)
B(-3,8,3,minecraft:stone)
B(-3,9,3,minecraft:stone)
B(-3,10,3,minecraft:stone)
B(-3,11,3,minecraft:andesite)
B(-3,12,3,minecraft:andesite)
B(-3,13,3,minecraft:andesite)
B(-3,1,4,minecraft:stone)
B(-3,2,4,minecraft:stone)
B(-3,3,4,minecraft:stone)
B(-3,4,4,minecraft:stone)
B(-3,5,4,minecraft:stone)
B(-3,6,4,minecraft:stone)
B(-3,7,4,minecraft:stone)
B(-3,8,4,minecraft:stone)
B(-3,9,4,minecraft:stone)
B(-3,10,4,minecraft:stone)
B(-3,11,4,minecraft:andesite)
B(-3,12,4,minecraft:andesite)
B(-3,13,4,minecraft:andesite)
B(-3,1,5,minecraft:stone)
B(-3,2,5,minecraft:stone)
B(-3,3,5,minecraft:andesite)
B(-3,4,5,minecraft:andesite)
B(-3,5,5,minecraft:andesite)
B(-3,6,5,minecraft:stone)
B(-3,7,5,minecraft:stone)
B(-3,8,5,minecraft:stone)
B(-3,9,5,minecraft:stone)
B(-3,10,5,minecraft:stone)
B(-3,11,5,minecraft:andesite)
B(-3,12,5,minecraft:andesite)
B(-3,13,5,minecraft:andesite)
B(-3,2,6,minecraft:andesite)
B(-3,3,6,minecraft:andesite)
B(-3,4,6,minecraft:andesite)
B(-3,5,6,minecraft:andesite)
B(-3,6,6,minecraft:andesite)
B(-3,7,6,minecraft:stone)
B(-3,8,6,minecraft:stone)
B(-3,9,6,minecraft:stone)
B(-3,10,6,minecraft:stone)
B(-3,11,6,minecraft:andesite)
B(-3,12,6,minecraft:andesite)
B(-3,3,7,minecraft:andesite)
B(-3,4,7,minecraft:andesite)
B(-3,5,7,minecraft:andesite)
B(-3,6,7,minecraft:andesite)
B(-3,7,7,minecraft:stone)
B(-3,8,7,minecraft:stone)
B(-3,9,7,minecraft:stone)
B(-3,10,7,minecraft:stone)
B(-3,11,7,minecraft:andesite)
B(-3,5,8,minecraft:andesite)
B(-3,6,8,minecraft:andesite)
B(-3,7,8,minecraft:stone)
B(-3,8,8,minecraft:stone)
B(-3,8,9,minecraft:stone)
B(-2,6,-8,minecraft:andesite)
B(-2,7,-8,minecraft:andesite)
B(-2,8,-8,minecraft:andesite)
B(-2,9,-8,minecraft:stone)
B(-2,10,-8,minecraft:stone)
B(-2,11,-8,minecraft:stone)
B(-2,12,-8,minecraft:stone)
B(-2,4,-7,minecraft:andesite)
B(-2,5,-7,minecraft:andesite)
B(-2,6,-7,minecraft:andesite)
B(-2,7,-7,minecraft:andesite)
B(-2,8,-7,minecraft:stone)
B(-2,9,-7,minecraft:stone)
B(-2,10,-7,minecraft:stone)
B(-2,11,-7,minecraft:stone)
B(-2,12,-7,minecraft:stone)
B(-2,13,-7,minecraft:stone)
B(-2,4,-6,minecraft:andesite)
B(-2,5,-6,minecraft:andesite)
B(-2,6,-6,minecraft:andesite)
B(-2,7,-6,minecraft:stone)
B(-2,8,-6,minecraft:stone)
B(-2,9,-6,minecraft:stone)
B(-2,10,-6,minecraft:stone)
B(-2,11,-6,minecraft:stone)
B(-2,12,-6,minecraft:stone)
B(-2,13,-6,minecraft:stone)
B(-2,14,-6,minecraft:stone)
B(-2,2,-5,minecraft:stone)
B(-2,3,-5,minecraft:stone)
B(-2,4,-5,minecraft:stone)
B(-2,5,-5,minecraft:stone)
B(-2,6,-5,minecraft:stone)
B(-2,7,-5,minecraft:stone)
B(-2,8,-5,minecraft:stone)
B(-2,9,-5,minecraft:stone)
B(-2,10,-5,minecraft:stone)
B(-2,11,-5,minecraft:stone)
B(-2,12,-5,minecraft:stone)
B(-2,13,-5,minecraft:stone)
B(-2,14,-5,minecraft:stone)
B(-2,2,-4,minecraft:stone)
B(-2,3,-4,minecraft:stone)
B(-2,4,-4,minecraft:stone)
B(-2,5,-4,minecraft:stone)
B(-2,6,-4,minecraft:stone)
B(-2,7,-4,minecraft:stone)
B(-2,8,-4,minecraft:stone)
B(-2,9,-4,minecraft:stone)
B(-2,10,-4,minecraft:stone)
B(-2,11,-4,minecraft:stone)
B(-2,12,-4,minecraft:stone)
B(-2,13,-4,minecraft:stone)
B(-2,14,-4,minecraft:stone)
B(-2,15,-4,minecraft:stone)
B(-2,16,-4,minecraft:stone)
B(-2,0,-3,minecraft:stone)
B(-2,1,-3,minecraft:stone)
B(-2,2,-3,minecraft:stone)
B(-2,3,-3,minecraft:stone)
B(-2,4,-3,minecraft:stone)
B(-2,5,-3,minecraft:stone)
B(-2,6,-3,minecraft:stone)
B(-2,7,-3,minecraft:stone)
B(-2,8,-3,minecraft:stone)
B(-2,9,-3,minecraft:stone)
B(-2,10,-3,minecraft:stone)
B(-2,11,-3,minecraft:stone)
B(-2,12,-3,minecraft:stone)
B(-2,13,-3,minecraft:stone)
B(-2,14,-3,minecraft:stone)
B(-2,15,-3,minecraft:stone)
B(-2,16,-3,minecraft:stone)
B(-2,17,-3,minecraft:stone)
B(-2,0,-2,minecraft:stone)
B(-2,1,-2,minecraft:stone)
B(-2,2,-2,minecraft:stone)
B(-2,3,-2,minecraft:stone)
B(-2,4,-2,minecraft:stone)
B(-2,5,-2,minecraft:stone)
B(-2,6,-2,minecraft:stone)
B(-2,7,-2,minecraft:stone)
B(-2,8,-2,minecraft:stone)
B(-2,9,-2,minecraft:stone)
B(-2,10,-2,minecraft:stone)
B(-2,11,-2,minecraft:stone)
B(-2,12,-2,minecraft:stone)
B(-2,13,-2,minecraft:stone)
B(-2,14,-2,minecraft:stone)
B(-2,15,-2,minecraft:stone)
B(-2,16,-2,minecraft:stone)
B(-2,17,-2,minecraft:stone)
B(-2,0,-1,minecraft:stone)
B(-2,1,-1,minecraft:stone)
B(-2,2,-1,minecraft:stone)
B(-2,3,-1,minecraft:stone)
B(-2,4,-1,minecraft:stone)
B(-2,5,-1,minecraft:stone)
B(-2,6,-1,minecraft:stone)
B(-2,7,-1,minecraft:stone)
B(-2,8,-1,minecraft:stone)
B(-2,9,-1,minecraft:stone)
B(-2,10,-1,minecraft:stone)
B(-2,11,-1,minecraft:stone)
B(-2,12,-1,minecraft:stone)
B(-2,13,-1,minecraft:stone)
B(-2,14,-1,minecraft:stone)
B(-2,15,-1,minecraft:stone)
B(-2,16,-1,minecraft:stone)
B(-2,17,-1,minecraft:stone)
B(-2,0,0,minecraft:stone)
B(-2,1,0,minecraft:stone)
B(-2,2,0,minecraft:stone)
B(-2,3,0,minecraft:stone)
B(-2,4,0,minecraft:stone)
B(-2,5,0,minecraft:stone)
B(-2,6,0,minecraft:stone)
B(-2,7,0,minecraft:stone)
B(-2,8,0,minecraft:stone)
B(-2,9,0,minecraft:stone)
B(-2,10,0,minecraft:stone)
B(-2,11,0,minecraft:stone)
B(-2,12,0,minecraft:stone)
B(-2,13,0,minecraft:stone)
B(-2,14,0,minecraft:stone)
B(-2,15,0,minecraft:andesite)
B(-2,16,0,minecraft:andesite)
B(-2,0,1,minecraft:stone)
B(-2,1,1,minecraft:stone)
B(-2,2,1,minecraft:stone)
B(-2,3,1,minecraft:stone)
B(-2,4,1,minecraft:stone)
B(-2,5,1,minecraft:stone)
B(-2,6,1,minecraft:stone)
B(-2,7,1,minecraft:stone)
B(-2,8,1,minecraft:stone)
B(-2,9,1,minecraft:stone)
B(-2,10,1,minecraft:stone)
B(-2,11,1,minecraft:stone)
B(-2,12,1,minecraft:stone)
B(-2,13,1,minecraft:stone)
B(-2,14,1,minecraft:andesite)
B(-2,15,1,minecraft:andesite)
B(-2,16,1,minecraft:andesite)
B(-2,0,2,minecraft:stone)
B(-2,1,2,minecraft:stone)
B(-2,2,2,minecraft:stone)
B(-2,3,2,minecraft:stone)
B(-2,4,2,minecraft:stone)
B(-2,5,2,minecraft:stone)
B(-2,6,2,minecraft:stone)
B(-2,7,2,minecraft:stone)
B(-2,8,2,minecraft:stone)
B(-2,9,2,minecraft:stone)
B(-2,10,2,minecraft:stone)
B(-2,11,2,minecraft:stone)
B(-2,12,2,minecraft:stone)
B(-2,13,2,minecraft:stone)
B(-2,14,2,minecraft:andesite)
B(-2,15,2,minecraft:andesite)
B(-2,16,2,minecraft:andesite)
B(-2,0,3,minecraft:stone)
B(-2,1,3,minecraft:stone)
B(-2,2,3,minecraft:stone)
B(-2,3,3,minecraft:stone)
B(-2,4,3,minecraft:stone)
B(-2,5,3,minecraft:stone)
B(-2,6,3,minecraft:stone)
B(-2,7,3,minecraft:stone)
B(-2,8,3,minecraft:stone)
B(-2,9,3,minecraft:stone)
B(-2,10,3,minecraft:stone)
B(-2,11,3,minecraft:stone)
B(-2,12,3,minecraft:andesite)
B(-2,13,3,minecraft:andesite)
B(-2,14,3,minecraft:andesite)
B(-2,1,4,minecraft:stone)
B(-2,2,4,minecraft:stone)
B(-2,3,4,minecraft:stone)
B(-2,4,4,minecraft:stone)
B(-2,5,4,minecraft:stone)
B(-2,6,4,minecraft:stone)
B(-2,7,4,minecraft:stone)
B(-2,8,4,minecraft:stone)
B(-2,9,4,minecraft:stone)
B(-2,10,4,minecraft:stone)
B(-2,11,4,minecraft:stone)
B(-2,12,4,minecraft:andesite)
B(-2,13,4,minecraft:andesite)
B(-2,14,4,minecraft:andesite)
B(-2,1,5,minecraft:stone)
B(-2,2,5,minecraft:stone)
B(-2,3,5,minecraft:andesite)
B(-2,4,5,minecraft:andesite)
B(-2,5,5,minecraft:andesite)
B(-2,6,5,minecraft:stone)
B(-2,7,5,minecraft:stone)
B(-2,8,5,minecraft:stone)
B(-2,9,5,minecraft:stone)
B(-2,10,5,minecraft:stone)
B(-2,11,5,minecraft:stone)
B(-2,12,5,minecraft:andesite)
B(-2,13,5,minecraft:andesite)
B(-2,2,6,minecraft:andesite)
B(-2,3,6,minecraft:andesite)
B(-2,4,6,minecraft:andesite)
B(-2,5,6,minecraft:andesite)
B(-2,6,6,minecraft:andesite)
B(-2,7,6,minecraft:stone)
B(-2,8,6,minecraft:stone)
B(-2,9,6,minecraft:stone)
B(-2,10,6,minecraft:stone)
B(-2,11,6,minecraft:stone)
B(-2,12,6,minecraft:stone)
B(-2,3,7,minecraft:andesite)
B(-2,4,7,minecraft:andesite)
B(-2,5,7,minecraft:andesite)
B(-2,6,7,minecraft:andesite)
B(-2,7,7,minecraft:andesite)
B(-2,8,7,minecraft:stone)
B(-2,9,7,minecraft:stone)
B(-2,10,7,minecraft:stone)
B(-2,3,8,minecraft:andesite)
B(-2,4,8,minecraft:andesite)
B(-2,5,8,minecraft:andesite)
B(-2,6,8,minecraft:andesite)
B(-2,7,8,minecraft:andesite)
B(-2,8,8,minecraft:stone)
B(-1,6,-9,minecraft:andesite)
B(-1,7,-9,minecraft:andesite)
B(-1,8,-9,minecraft:andesite)
B(-1,5,-8,minecraft:andesite)
B(-1,6,-8,minecraft:andesite)
B(-1,7,-8,minecraft:andesite)
B(-1,8,-8,minecraft:andesite)
B(-1,9,-8,minecraft:andesite)
B(-1,10,-8,minecraft:stone)
B(-1,11,-8,minecraft:stone)
B(-1,12,-8,minecraft:stone)
B(-1,4,-7,minecraft:andesite)
B(-1,5,-7,minecraft:andesite)
B(-1,6,-7,minecraft:andesite)
B(-1,7,-7,minecraft:andesite)
B(-1,8,-7,minecraft:andesite)
B(-1,9,-7,minecraft:stone)
B(-1,10,-7,minecraft:stone)
B(-1,11,-7,minecraft:stone)
B(-1,12,-7,minecraft:stone)
B(-1,13,-7,minecraft:stone)
B(-1,3,-6,minecraft:stone)
B(-1,4,-6,minecraft:stone)
B(-1,5,-6,minecraft:stone)
B(-1,6,-6,minecraft:stone)
B(-1,7,-6,minecraft:stone)
B(-1,8,-6,minecraft:stone)
B(-1,9,-6,minecraft:stone)
B(-1,10,-6,minecraft:stone)
B(-1,11,-6,minecraft:stone)
B(-1,12,-6,minecraft:stone)
B(-1,13,-6,minecraft:stone)
B(-1,14,-6,minecraft:stone)
B(-1,2,-5,minecraft:stone)
B(-1,3,-5,minecraft:stone)
B(-1,4,-5,minecraft:stone)
B(-1,5,-5,minecraft:stone)
B(-1,6,-5,minecraft:stone)
B(-1,7,-5,minecraft:stone)
B(-1,8,-5,minecraft:stone)
B(-1,9,-5,minecraft:stone)
B(-1,10,-5,minecraft:stone)
B(-1,11,-5,minecraft:stone)
B(-1,12,-5,minecraft:stone)
B(-1,13,-5,minecraft:stone)
B(-1,14,-5,minecraft:stone)
B(-1,15,-5,minecraft:stone)
B(-1,16,-5,minecraft:stone)
B(-1,17,-5,minecraft:stone)
B(-1,1,-4,minecraft:stone)
B(-1,2,-4,minecraft:stone)
B(-1,3,-4,minecraft:stone)
B(-1,4,-4,minecraft:stone)
B(-1,5,-4,minecraft:stone)
B(-1,6,-4,minecraft:stone)
B(-1,7,-4,minecraft:stone)
B(-1,8,-4,minecraft:stone)
B(-1,9,-4,minecraft:stone)
B(-1,10,-4,minecraft:stone)
B(-1,11,-4,minecraft:stone)
B(-1,12,-4,minecraft:stone)
B(-1,13,-4,minecraft:stone)
B(-1,14,-4,minecraft:stone)
B(-1,15,-4,minecraft:stone)
B(-1,16,-4,minecraft:stone)
B(-1,17,-4,minecraft:stone)
B(-1,0,-3,minecraft:stone)
B(-1,1,-3,minecraft:stone)
B(-1,2,-3,minecraft:stone)
B(-1,3,-3,minecraft:stone)
B(-1,4,-3,minecraft:stone)
B(-1,5,-3,minecraft:stone)
B(-1,6,-3,minecraft:stone)
B(-1,7,-3,minecraft:stone)
B(-1,8,-3,minecraft:stone)
B(-1,9,-3,minecraft:stone)
B(-1,10,-3,minecraft:stone)
B(-1,11,-3,minecraft:stone)
B(-1,12,-3,minecraft:stone)
B(-1,13,-3,minecraft:stone)
B(-1,14,-3,minecraft:stone)
B(-1,15,-3,minecraft:stone)
B(-1,16,-3,minecraft:stone)
B(-1,17,-3,minecraft:stone)
B(-1,0,-2,minecraft:stone)
B(-1,1,-2,minecraft:stone)
B(-1,2,-2,minecraft:stone)
B(-1,3,-2,minecraft:stone)
B(-1,4,-2,minecraft:stone)
B(-1,5,-2,minecraft:stone)
B(-1,6,-2,minecraft:stone)
B(-1,7,-2,minecraft:stone)
B(-1,8,-2,minecraft:stone)
B(-1,9,-2,minecraft:stone)
B(-1,10,-2,minecraft:stone)
B(-1,11,-2,minecraft:stone)
B(-1,12,-2,minecraft:stone)
B(-1,13,-2,minecraft:stone)
B(-1,14,-2,minecraft:stone)
B(-1,15,-2,minecraft:stone)
B(-1,16,-2,minecraft:stone)
B(-1,17,-2,minecraft:stone)
B(-1,0,-1,minecraft:stone)
B(-1,1,-1,minecraft:stone)
B(-1,2,-1,minecraft:stone)
B(-1,3,-1,minecraft:stone)
B(-1,4,-1,minecraft:stone)
B(-1,5,-1,minecraft:stone)
B(-1,6,-1,minecraft:stone)
B(-1,7,-1,minecraft:stone)
B(-1,8,-1,minecraft:stone)
B(-1,9,-1,minecraft:stone)
B(-1,10,-1,minecraft:stone)
B(-1,11,-1,minecraft:stone)
B(-1,12,-1,minecraft:stone)
B(-1,13,-1,minecraft:stone)
B(-1,14,-1,minecraft:stone)
B(-1,15,-1,minecraft:stone)
B(-1,16,-1,minecraft:andesite)
B(-1,17,-1,minecraft:andesite)
B(-1,0,0,minecraft:stone)
B(-1,1,0,minecraft:stone)
B(-1,2,0,minecraft:stone)
B(-1,3,0,minecraft:stone)
B(-1,4,0,minecraft:stone)
B(-1,5,0,minecraft:stone)
B(-1,6,0,minecraft:stone)
B(-1,7,0,minecraft:stone)
B(-1,8,0,minecraft:stone)
B(-1,9,0,minecraft:stone)
B(-1,10,0,minecraft:stone)
B(-1,11,0,minecraft:stone)
B(-1,12,0,minecraft:stone)
B(-1,13,0,minecraft:stone)
B(-1,14,0,minecraft:stone)
B(-1,15,0,minecraft:andesite)
B(-1,16,0,minecraft:andesite)
B(-1,17,0,minecraft:andesite)
B(-1,0,1,minecraft:stone)
B(-1,1,1,minecraft:stone)
B(-1,2,1,minecraft:stone)
B(-1,3,1,minecraft:stone)
B(-1,4,1,minecraft:stone)
B(-1,5,1,minecraft:stone)
B(-1,6,1,minecraft:stone)
B(-1,7,1,minecraft:stone)
B(-1,8,1,minecraft:stone)
B(-1,9,1,minecraft:stone)
B(-1,10,1,minecraft:stone)
B(-1,11,1,minecraft:stone)
B(-1,12,1,minecraft:stone)
B(-1,13,1,minecraft:stone)
B(-1,14,1,minecraft:andesite)
B(-1,15,1,minecraft:andesite)
B(-1,16,1,minecraft:andesite)
B(-1,0,2,minecraft:stone)
B(-1,1,2,minecraft:stone)
B(-1,2,2,minecraft:stone)
B(-1,3,2,minecraft:stone)
B(-1,4,2,minecraft:stone)
B(-1,5,2,minecraft:stone)
B(-1,6,2,minecraft:stone)
B(-1,7,2,minecraft:stone)
B(-1,8,2,minecraft:stone)
B(-1,9,2,minecraft:stone)
B(-1,10,2,minecraft:stone)
B(-1,11,2,minecraft:stone)
B(-1,12,2,minecraft:stone)
B(-1,13,2,minecraft:stone)
B(-1,14,2,minecraft:andesite)
B(-1,15,2,minecraft:andesite)
B(-1,16,2,minecraft:andesite)
B(-1,0,3,minecraft:stone)
B(-1,1,3,minecraft:stone)
B(-1,2,3,minecraft:stone)
B(-1,3,3,minecraft:stone)
B(-1,4,3,minecraft:stone)
B(-1,5,3,minecraft:stone)
B(-1,6,3,minecraft:stone)
B(-1,7,3,minecraft:stone)
B(-1,8,3,minecraft:stone)
B(-1,9,3,minecraft:stone)
B(-1,10,3,minecraft:stone)
B(-1,11,3,minecraft:stone)
B(-1,12,3,minecraft:stone)
B(-1,13,3,minecraft:stone)
B(-1,14,3,minecraft:andesite)
B(-1,15,3,minecraft:andesite)
B(-1,1,4,minecraft:stone)
B(-1,2,4,minecraft:stone)
B(-1,3,4,minecraft:stone)
B(-1,4,4,minecraft:stone)
B(-1,5,4,minecraft:stone)
B(-1,6,4,minecraft:stone)
B(-1,7,4,minecraft:stone)
B(-1,8,4,minecraft:stone)
B(-1,9,4,minecraft:stone)
B(-1,10,4,minecraft:stone)
B(-1,11,4,minecraft:stone)
B(-1,12,4,minecraft:stone)
B(-1,13,4,minecraft:stone)
B(-1,14,4,minecraft:stone)
B(-1,15,4,minecraft:andesite)
B(-1,1,5,minecraft:stone)
B(-1,2,5,minecraft:stone)
B(-1,3,5,minecraft:stone)
B(-1,4,5,minecraft:stone)
B(-1,5,5,minecraft:stone)
B(-1,6,5,minecraft:stone)
B(-1,7,5,minecraft:stone)
B(-1,8,5,minecraft:stone)
B(-1,9,5,minecraft:stone)
B(-1,10,5,minecraft:stone)
B(-1,11,5,minecraft:stone)
B(-1,12,5,minecraft:stone)
B(-1,13,5,minecraft:stone)
B(-1,14,5,minecraft:stone)
B(-1,15,5,minecraft:stone)
B(-1,2,6,minecraft:stone)
B(-1,3,6,minecraft:andesite)
B(-1,4,6,minecraft:andesite)
B(-1,5,6,minecraft:andesite)
B(-1,6,6,minecraft:andesite)
B(-1,7,6,minecraft:stone)
B(-1,8,6,minecraft:stone)
B(-1,9,6,minecraft:stone)
B(-1,10,6,minecraft:stone)
B(-1,11,6,minecraft:stone)
B(-1,12,6,minecraft:stone)
B(-1,3,7,minecraft:andesite)
B(-1,4,7,minecraft:andesite)
B(-1,5,7,minecraft:andesite)
B(-1,6,7,minecraft:andesite)
B(-1,7,7,minecraft:andesite)
B(-1,8,7,minecraft:stone)
B(-1,9,7,minecraft:stone)
B(-1,10,7,minecraft:stone)
B(-1,5,8,minecraft:andesite)
B(-1,6,8,minecraft:andesite)
B(-1,7,8,minecraft:andesite)
B(-1,8,8,minecraft:stone)
B(-1,9,8,minecraft:stone)
B(0,7,-9,minecraft:andesite)
B(0,8,-9,minecraft:andesite)
B(0,9,-9,minecraft:andesite)
B(0,10,-9,minecraft:stone)
B(0,11,-9,minecraft:stone)
B(0,5,-8,minecraft:andesite)
B(0,6,-8,minecraft:andesite)
B(0,7,-8,minecraft:andesite)
B(0,8,-8,minecraft:andesite)
B(0,9,-8,minecraft:andesite)
B(0,10,-8,minecraft:stone)
B(0,11,-8,minecraft:stone)
B(0,12,-8,minecraft:stone)
B(0,4,-7,minecraft:stone)
B(0,5,-7,minecraft:stone)
B(0,6,-7,minecraft:andesite)
B(0,7,-7,minecraft:andesite)
B(0,8,-7,minecraft:andesite)
B(0,9,-7,minecraft:stone)
B(0,10,-7,minecraft:stone)
B(0,11,-7,minecraft:stone)
B(0,12,-7,minecraft:stone)
B(0,13,-7,minecraft:stone)
B(0,3,-6,minecraft:stone)
B(0,4,-6,minecraft:stone)
B(0,5,-6,minecraft:stone)
B(0,6,-6,minecraft:stone)
B(0,7,-6,minecraft:stone)
B(0,8,-6,minecraft:stone)
B(0,9,-6,minecraft:stone)
B(0,10,-6,minecraft:stone)
B(0,11,-6,minecraft:stone)
B(0,12,-6,minecraft:stone)
B(0,13,-6,minecraft:stone)
B(0,14,-6,minecraft:stone)
B(0,15,-6,minecraft:stone)
B(0,16,-6,minecraft:stone)
B(0,2,-5,minecraft:stone)
B(0,3,-5,minecraft:stone)
B(0,4,-5,minecraft:stone)
B(0,5,-5,minecraft:stone)
B(0,6,-5,minecraft:stone)
B(0,7,-5,minecraft:stone)
B(0,8,-5,minecraft:stone)
B(0,9,-5,minecraft:stone)
B(0,10,-5,minecraft:stone)
B(0,11,-5,minecraft:stone)
B(0,12,-5,minecraft:stone)
B(0,13,-5,minecraft:stone)
B(0,14,-5,minecraft:stone)
B(0,15,-5,minecraft:stone)
B(0,16,-5,minecraft:stone)
B(0,17,-5,minecraft:stone)
B(0,2,-4,minecraft:stone)
B(0,3,-4,minecraft:stone)
B(0,4,-4,minecraft:stone)
B(0,5,-4,minecraft:stone)
B(0,6,-4,minecraft:stone)
B(0,7,-4,minecraft:stone)
B(0,8,-4,minecraft:stone)
B(0,9,-4,minecraft:stone)
B(0,10,-4,minecraft:stone)
B(0,11,-4,minecraft:stone)
B(0,12,-4,minecraft:stone)
B(0,13,-4,minecraft:stone)
B(0,14,-4,minecraft:stone)
B(0,15,-4,minecraft:stone)
B(0,16,-4,minecraft:stone)
B(0,17,-4,minecraft:stone)
B(0,0,-3,minecraft:stone)
B(0,1,-3,minecraft:stone)
B(0,2,-3,minecraft:stone)
B(0,3,-3,minecraft:stone)
B(0,4,-3,minecraft:stone)
B(0,5,-3,minecraft:stone)
B(0,6,-3,minecraft:stone)
B(0,7,-3,minecraft:stone)
B(0,8,-3,minecraft:stone)
B(0,9,-3,minecraft:stone)
B(0,10,-3,minecraft:stone)
B(0,11,-3,minecraft:stone)
B(0,12,-3,minecraft:stone)
B(0,13,-3,minecraft:stone)
B(0,14,-3,minecraft:stone)
B(0,15,-3,minecraft:stone)
B(0,16,-3,minecraft:stone)
B(0,17,-3,minecraft:stone)
B(0,0,-2,minecraft:stone)
B(0,1,-2,minecraft:stone)
B(0,2,-2,minecraft:stone)
B(0,3,-2,minecraft:stone)
B(0,4,-2,minecraft:stone)
B(0,5,-2,minecraft:stone)
B(0,6,-2,minecraft:stone)
B(0,7,-2,minecraft:stone)
B(0,8,-2,minecraft:stone)
B(0,9,-2,minecraft:stone)
B(0,10,-2,minecraft:stone)
B(0,11,-2,minecraft:stone)
B(0,12,-2,minecraft:stone)
B(0,13,-2,minecraft:stone)
B(0,14,-2,minecraft:stone)
B(0,15,-2,minecraft:stone)
B(0,16,-2,minecraft:stone)
B(0,17,-2,minecraft:stone)
B(0,0,-1,minecraft:stone)
B(0,1,-1,minecraft:stone)
B(0,2,-1,minecraft:stone)
B(0,3,-1,minecraft:stone)
B(0,4,-1,minecraft:stone)
B(0,5,-1,minecraft:stone)
B(0,6,-1,minecraft:stone)
B(0,7,-1,minecraft:stone)
B(0,8,-1,minecraft:stone)
B(0,9,-1,minecraft:stone)
B(0,10,-1,minecraft:stone)
B(0,11,-1,minecraft:stone)
B(0,12,-1,minecraft:stone)
B(0,13,-1,minecraft:stone)
B(0,14,-1,minecraft:stone)
B(0,15,-1,minecraft:stone)
B(0,16,-1,minecraft:andesite)
B(0,17,-1,minecraft:andesite)
B(0,0,0,minecraft:stone)
B(0,1,0,minecraft:stone)
B(0,2,0,minecraft:stone)
B(0,3,0,minecraft:stone)
B(0,4,0,minecraft:stone)
B(0,5,0,minecraft:stone)
B(0,6,0,minecraft:stone)
B(0,7,0,minecraft:stone)
B(0,8,0,minecraft:stone)
B(0,9,0,minecraft:stone)
B(0,10,0,minecraft:stone)
B(0,11,0,minecraft:stone)
B(0,12,0,minecraft:stone)
B(0,13,0,minecraft:stone)
B(0,14,0,minecraft:stone)
B(0,15,0,minecraft:andesite)
B(0,16,0,minecraft:andesite)
B(0,17,0,minecraft:andesite)
B(0,0,1,minecraft:stone)
B(0,1,1,minecraft:stone)
B(0,2,1,minecraft:stone)
B(0,3,1,minecraft:stone)
B(0,4,1,minecraft:stone)
B(0,5,1,minecraft:stone)
B(0,6,1,minecraft:stone)
B(0,7,1,minecraft:stone)
B(0,8,1,minecraft:stone)
B(0,9,1,minecraft:stone)
B(0,10,1,minecraft:stone)
B(0,11,1,minecraft:stone)
B(0,12,1,minecraft:stone)
B(0,13,1,minecraft:stone)
B(0,14,1,minecraft:stone)
B(0,15,1,minecraft:andesite)
B(0,16,1,minecraft:andesite)
B(0,17,1,minecraft:andesite)
B(0,0,2,minecraft:stone)
B(0,1,2,minecraft:stone)
B(0,2,2,minecraft:stone)
B(0,3,2,minecraft:stone)
B(0,4,2,minecraft:stone)
B(0,5,2,minecraft:stone)
B(0,6,2,minecraft:stone)
B(0,7,2,minecraft:stone)
B(0,8,2,minecraft:stone)
B(0,9,2,minecraft:stone)
B(0,10,2,minecraft:stone)
B(0,11,2,minecraft:stone)
B(0,12,2,minecraft:stone)
B(0,13,2,minecraft:stone)
B(0,14,2,minecraft:stone)
B(0,15,2,minecraft:andesite)
B(0,16,2,minecraft:andesite)
B(0,0,3,minecraft:stone)
B(0,1,3,minecraft:stone)
B(0,2,3,minecraft:stone)
B(0,3,3,minecraft:stone)
B(0,4,3,minecraft:stone)
B(0,5,3,minecraft:stone)
B(0,6,3,minecraft:stone)
B(0,7,3,minecraft:stone)
B(0,8,3,minecraft:stone)
B(0,9,3,minecraft:stone)
B(0,10,3,minecraft:stone)
B(0,11,3,minecraft:stone)
B(0,12,3,minecraft:stone)
B(0,13,3,minecraft:stone)
B(0,14,3,minecraft:stone)
B(0,15,3,minecraft:andesite)
B(0,16,3,minecraft:andesite)
B(0,0,4,minecraft:stone)
B(0,1,4,minecraft:stone)
B(0,2,4,minecraft:stone)
B(0,3,4,minecraft:stone)
B(0,4,4,minecraft:stone)
B(0,5,4,minecraft:stone)
B(0,6,4,minecraft:stone)
B(0,7,4,minecraft:stone)
B(0,8,4,minecraft:stone)
B(0,9,4,minecraft:stone)
B(0,10,4,minecraft:stone)
B(0,11,4,minecraft:stone)
B(0,12,4,minecraft:stone)
B(0,13,4,minecraft:stone)
B(0,14,4,minecraft:stone)
B(0,15,4,minecraft:andesite)
B(0,16,4,minecraft:andesite)
B(0,1,5,minecraft:stone)
B(0,2,5,minecraft:stone)
B(0,3,5,minecraft:stone)
B(0,4,5,minecraft:stone)
B(0,5,5,minecraft:stone)
B(0,6,5,minecraft:stone)
B(0,7,5,minecraft:stone)
B(0,8,5,minecraft:stone)
B(0,9,5,minecraft:stone)
B(0,10,5,minecraft:stone)
B(0,11,5,minecraft:stone)
B(0,12,5,minecraft:stone)
B(0,13,5,minecraft:stone)
B(0,14,5,minecraft:stone)
B(0,15,5,minecraft:andesite)
B(0,1,6,minecraft:stone)
B(0,2,6,minecraft:stone)
B(0,3,6,minecraft:stone)
B(0,4,6,minecraft:andesite)
B(0,5,6,minecraft:andesite)
B(0,6,6,minecraft:andesite)
B(0,7,6,minecraft:stone)
B(0,8,6,minecraft:stone)
B(0,9,6,minecraft:stone)
B(0,10,6,minecraft:stone)
B(0,11,6,minecraft:stone)
B(0,12,6,minecraft:stone)
B(0,13,6,minecraft:stone)
B(0,14,6,minecraft:stone)
B(0,2,7,minecraft:stone)
B(0,3,7,minecraft:andesite)
B(0,4,7,minecraft:andesite)
B(0,5,7,minecraft:andesite)
B(0,6,7,minecraft:andesite)
B(0,7,7,minecraft:andesite)
B(0,8,7,minecraft:stone)
B(0,9,7,minecraft:stone)
B(0,5,8,minecraft:andesite)
B(0,6,8,minecraft:andesite)
B(0,7,8,minecraft:andesite)
B(0,8,8,minecraft:stone)
B(0,9,8,minecraft:stone)
B(1,6,-9,minecraft:andesite)
B(1,8,-9,minecraft:andesite)
B(1,9,-9,minecraft:andesite)
B(1,10,-9,minecraft:stone)
B(1,11,-9,minecraft:stone)
B(1,5,-8,minecraft:andesite)
B(1,6,-8,minecraft:andesite)
B(1,7,-8,minecraft:andesite)
B(1,8,-8,minecraft:andesite)
B(1,9,-8,minecraft:andesite)
B(1,10,-8,minecraft:stone)
B(1,11,-8,minecraft:stone)
B(1,12,-8,minecraft:stone)
B(1,4,-7,minecraft:stone)
B(1,5,-7,minecraft:stone)
B(1,6,-7,minecraft:andesite)
B(1,7,-7,minecraft:andesite)
B(1,8,-7,minecraft:andesite)
B(1,9,-7,minecraft:stone)
B(1,10,-7,minecraft:stone)
B(1,11,-7,minecraft:stone)
B(1,12,-7,minecraft:stone)
B(1,13,-7,minecraft:stone)
B(1,14,-7,minecraft:stone)
B(1,15,-7,minecraft:stone)
B(1,4,-6,minecraft:stone)
B(1,5,-6,minecraft:stone)
B(1,6,-6,minecraft:stone)
B(1,7,-6,minecraft:stone)
B(1,8,-6,minecraft:stone)
B(1,9,-6,minecraft:stone)
B(1,10,-6,minecraft:stone)
B(1,11,-6,minecraft:stone)
B(1,12,-6,minecraft:stone)
B(1,13,-6,minecraft:stone)
B(1,14,-6,minecraft:stone)
B(1,15,-6,minecraft:stone)
B(1,16,-6,minecraft:stone)
B(1,3,-5,minecraft:stone)
B(1,4,-5,minecraft:stone)
B(1,5,-5,minecraft:stone)
B(1,6,-5,minecraft:stone)
B(1,7,-5,minecraft:stone)
B(1,8,-5,minecraft:stone)
B(1,9,-5,minecraft:stone)
B(1,10,-5,minecraft:stone)
B(1,11,-5,minecraft:stone)
B(1,12,-5,minecraft:stone)
B(1,13,-5,minecraft:stone)
B(1,14,-5,minecraft:stone)
B(1,15,-5,minecraft:stone)
B(1,16,-5,minecraft:stone)
B(1,17,-5,minecraft:stone)
B(1,1,-4,minecraft:stone)
B(1,2,-4,minecraft:stone)
B(1,3,-4,minecraft:stone)
B(1,4,-4,minecraft:stone)
B(1,5,-4,minecraft:stone)
B(1,6,-4,minecraft:stone)
B(1,7,-4,minecraft:stone)
B(1,8,-4,minecraft:stone)
B(1,9,-4,minecraft:stone)
B(1,10,-4,minecraft:stone)
B(1,11,-4,minecraft:stone)
B(1,12,-4,minecraft:stone)
B(1,13,-4,minecraft:stone)
B(1,14,-4,minecraft:stone)
B(1,15,-4,minecraft:stone)
B(1,16,-4,minecraft:stone)
B(1,17,-4,minecraft:stone)
B(1,0,-3,minecraft:stone)
B(1,1,-3,minecraft:stone)
B(1,2,-3,minecraft:stone)
B(1,3,-3,minecraft:stone)
B(1,4,-3,minecraft:stone)
B(1,5,-3,minecraft:stone)
B(1,6,-3,minecraft:stone)
B(1,7,-3,minecraft:stone)
B(1,8,-3,minecraft:stone)
B(1,9,-3,minecraft:stone)
B(1,10,-3,minecraft:stone)
B(1,11,-3,minecraft:stone)
B(1,12,-3,minecraft:stone)
B(1,13,-3,minecraft:stone)
B(1,14,-3,minecraft:stone)
B(1,15,-3,minecraft:stone)
B(1,16,-3,minecraft:stone)
B(1,17,-3,minecraft:stone)
B(1,0,-2,minecraft:stone)
B(1,1,-2,minecraft:stone)
B(1,2,-2,minecraft:stone)
B(1,3,-2,minecraft:stone)
B(1,4,-2,minecraft:stone)
B(1,5,-2,minecraft:stone)
B(1,6,-2,minecraft:stone)
B(1,7,-2,minecraft:stone)
B(1,8,-2,minecraft:stone)
B(1,9,-2,minecraft:stone)
B(1,10,-2,minecraft:stone)
B(1,11,-2,minecraft:stone)
B(1,12,-2,minecraft:stone)
B(1,13,-2,minecraft:stone)
B(1,14,-2,minecraft:stone)
B(1,15,-2,minecraft:stone)
B(1,16,-2,minecraft:stone)
B(1,17,-2,minecraft:stone)
B(1,0,-1,minecraft:stone)
B(1,1,-1,minecraft:stone)
B(1,2,-1,minecraft:stone)
B(1,3,-1,minecraft:stone)
B(1,4,-1,minecraft:stone)
B(1,5,-1,minecraft:stone)
B(1,6,-1,minecraft:stone)
B(1,7,-1,minecraft:stone)
B(1,8,-1,minecraft:stone)
B(1,9,-1,minecraft:stone)
B(1,10,-1,minecraft:stone)
B(1,11,-1,minecraft:stone)
B(1,12,-1,minecraft:stone)
B(1,13,-1,minecraft:stone)
B(1,14,-1,minecraft:stone)
B(1,15,-1,minecraft:stone)
B(1,16,-1,minecraft:andesite)
B(1,17,-1,minecraft:andesite)
B(1,0,0,minecraft:stone)
B(1,1,0,minecraft:stone)
B(1,2,0,minecraft:stone)
B(1,3,0,minecraft:stone)
B(1,4,0,minecraft:stone)
B(1,5,0,minecraft:stone)
B(1,6,0,minecraft:stone)
B(1,7,0,minecraft:stone)
B(1,8,0,minecraft:stone)
B(1,9,0,minecraft:stone)
B(1,10,0,minecraft:stone)
B(1,11,0,minecraft:stone)
B(1,12,0,minecraft:stone)
B(1,13,0,minecraft:stone)
B(1,14,0,minecraft:stone)
B(1,15,0,minecraft:andesite)
B(1,16,0,minecraft:andesite)
B(1,17,0,minecraft:andesite)
B(1,0,1,minecraft:stone)
B(1,1,1,minecraft:stone)
B(1,2,1,minecraft:stone)
B(1,3,1,minecraft:stone)
B(1,4,1,minecraft:stone)
B(1,5,1,minecraft:stone)
B(1,6,1,minecraft:stone)
B(1,7,1,minecraft:stone)
B(1,8,1,minecraft:stone)
B(1,9,1,minecraft:stone)
B(1,10,1,minecraft:stone)
B(1,11,1,minecraft:stone)
B(1,12,1,minecraft:stone)
B(1,13,1,minecraft:stone)
B(1,14,1,minecraft:stone)
B(1,15,1,minecraft:andesite)
B(1,16,1,minecraft:andesite)
B(1,17,1,minecraft:andesite)
B(1,0,2,minecraft:stone)
B(1,1,2,minecraft:stone)
B(1,2,2,minecraft:stone)
B(1,3,2,minecraft:stone)
B(1,4,2,minecraft:stone)
B(1,5,2,minecraft:stone)
B(1,6,2,minecraft:stone)
B(1,7,2,minecraft:stone)
B(1,8,2,minecraft:stone)
B(1,9,2,minecraft:stone)
B(1,10,2,minecraft:stone)
B(1,11,2,minecraft:stone)
B(1,12,2,minecraft:stone)
B(1,13,2,minecraft:stone)
B(1,14,2,minecraft:stone)
B(1,15,2,minecraft:andesite)
B(1,16,2,minecraft:andesite)
B(1,0,3,minecraft:stone)
B(1,1,3,minecraft:stone)
B(1,2,3,minecraft:stone)
B(1,3,3,minecraft:stone)
B(1,4,3,minecraft:stone)
B(1,5,3,minecraft:stone)
B(1,6,3,minecraft:stone)
B(1,7,3,minecraft:stone)
B(1,8,3,minecraft:stone)
B(1,9,3,minecraft:stone)
B(1,10,3,minecraft:stone)
B(1,11,3,minecraft:stone)
B(1,12,3,minecraft:stone)
B(1,13,3,minecraft:stone)
B(1,14,3,minecraft:andesite)
B(1,15,3,minecraft:andesite)
B(1,16,3,minecraft:andesite)
B(1,0,4,minecraft:stone)
B(1,1,4,minecraft:stone)
B(1,2,4,minecraft:stone)
B(1,3,4,minecraft:stone)
B(1,4,4,minecraft:stone)
B(1,5,4,minecraft:stone)
B(1,6,4,minecraft:stone)
B(1,7,4,minecraft:stone)
B(1,8,4,minecraft:stone)
B(1,9,4,minecraft:stone)
B(1,10,4,minecraft:stone)
B(1,11,4,minecraft:stone)
B(1,12,4,minecraft:stone)
B(1,13,4,minecraft:stone)
B(1,14,4,minecraft:andesite)
B(1,15,4,minecraft:andesite)
B(1,16,4,minecraft:andesite)
B(1,0,5,minecraft:stone)
B(1,1,5,minecraft:stone)
B(1,2,5,minecraft:stone)
B(1,3,5,minecraft:stone)
B(1,4,5,minecraft:stone)
B(1,5,5,minecraft:stone)
B(1,6,5,minecraft:stone)
B(1,7,5,minecraft:stone)
B(1,8,5,minecraft:stone)
B(1,9,5,minecraft:stone)
B(1,10,5,minecraft:stone)
B(1,11,5,minecraft:stone)
B(1,12,5,minecraft:stone)
B(1,13,5,minecraft:stone)
B(1,14,5,minecraft:andesite)
B(1,15,5,minecraft:andesite)
B(1,2,6,minecraft:stone)
B(1,3,6,minecraft:stone)
B(1,4,6,minecraft:stone)
B(1,5,6,minecraft:stone)
B(1,6,6,minecraft:stone)
B(1,7,6,minecraft:stone)
B(1,8,6,minecraft:stone)
B(1,9,6,minecraft:stone)
B(1,10,6,minecraft:stone)
B(1,11,6,minecraft:stone)
B(1,12,6,minecraft:stone)
B(1,13,6,minecraft:stone)
B(1,14,6,minecraft:stone)
B(1,2,7,minecraft:stone)
B(1,3,7,minecraft:stone)
B(1,4,7,minecraft:andesite)
B(1,5,7,minecraft:andesite)
B(1,6,7,minecraft:andesite)
B(1,7,7,minecraft:stone)
B(1,8,7,minecraft:stone)
B(1,9,7,minecraft:stone)
B(1,10,7,minecraft:stone)
B(1,7,8,minecraft:stone)
B(1,8,8,minecraft:stone)
B(2,7,-9,minecraft:andesite)
B(2,8,-9,minecraft:andesite)
B(2,9,-9,minecraft:stone)
B(2,10,-9,minecraft:stone)
B(2,11,-9,minecraft:stone)
B(2,5,-8,minecraft:stone)
B(2,6,-8,minecraft:andesite)
B(2,7,-8,minecraft:andesite)
B(2,8,-8,minecraft:andesite)
B(2,9,-8,minecraft:stone)
B(2,10,-8,minecraft:stone)
B(2,11,-8,minecraft:stone)
B(2,12,-8,minecraft:stone)
B(2,13,-8,minecraft:andesite)
B(2,14,-8,minecraft:andesite)
B(2,5,-7,minecraft:stone)
B(2,6,-7,minecraft:stone)
B(2,7,-7,minecraft:stone)
B(2,8,-7,minecraft:stone)
B(2,9,-7,minecraft:stone)
B(2,10,-7,minecraft:stone)
B(2,11,-7,minecraft:stone)
B(2,12,-7,minecraft:stone)
B(2,13,-7,minecraft:andesite)
B(2,14,-7,minecraft:andesite)
B(2,15,-7,minecraft:andesite)
B(2,4,-6,minecraft:stone)
B(2,5,-6,minecraft:stone)
B(2,6,-6,minecraft:stone)
B(2,7,-6,minecraft:stone)
B(2,8,-6,minecraft:stone)
B(2,9,-6,minecraft:stone)
B(2,10,-6,minecraft:stone)
B(2,11,-6,minecraft:stone)
B(2,12,-6,minecraft:stone)
B(2,13,-6,minecraft:andesite)
B(2,14,-6,minecraft:andesite)
B(2,15,-6,minecraft:andesite)
B(2,16,-6,minecraft:stone)
B(2,3,-5,minecraft:stone)
B(2,4,-5,minecraft:stone)
B(2,5,-5,minecraft:stone)
B(2,6,-5,minecraft:stone)
B(2,7,-5,minecraft:stone)
B(2,8,-5,minecraft:stone)
B(2,9,-5,minecraft:stone)
B(2,10,-5,minecraft:stone)
B(2,11,-5,minecraft:stone)
B(2,12,-5,minecraft:stone)
B(2,13,-5,minecraft:stone)
B(2,14,-5,minecraft:stone)
B(2,15,-5,minecraft:stone)
B(2,16,-5,minecraft:stone)
B(2,17,-5,minecraft:stone)
B(2,2,-4,minecraft:stone)
B(2,3,-4,minecraft:stone)
B(2,4,-4,minecraft:stone)
B(2,5,-4,minecraft:stone)
B(2,6,-4,minecraft:stone)
B(2,7,-4,minecraft:stone)
B(2,8,-4,minecraft:stone)
B(2,9,-4,minecraft:stone)
B(2,10,-4,minecraft:stone)
B(2,11,-4,minecraft:stone)
B(2,12,-4,minecraft:stone)
B(2,13,-4,minecraft:stone)
B(2,14,-4,minecraft:stone)
B(2,15,-4,minecraft:stone)
B(2,16,-4,minecraft:stone)
B(2,17,-4,minecraft:stone)
B(2,2,-3,minecraft:stone)
B(2,3,-3,minecraft:stone)
B(2,4,-3,minecraft:stone)
B(2,5,-3,minecraft:stone)
B(2,6,-3,minecraft:stone)
B(2,7,-3,minecraft:stone)
B(2,8,-3,minecraft:stone)
B(2,9,-3,minecraft:stone)
B(2,10,-3,minecraft:stone)
B(2,11,-3,minecraft:stone)
B(2,12,-3,minecraft:stone)
B(2,13,-3,minecraft:stone)
B(2,14,-3,minecraft:stone)
B(2,15,-3,minecraft:stone)
B(2,16,-3,minecraft:stone)
B(2,17,-3,minecraft:stone)
B(2,0,-2,minecraft:stone)
B(2,1,-2,minecraft:stone)
B(2,2,-2,minecraft:stone)
B(2,3,-2,minecraft:stone)
B(2,4,-2,minecraft:stone)
B(2,5,-2,minecraft:stone)
B(2,6,-2,minecraft:stone)
B(2,7,-2,minecraft:stone)
B(2,8,-2,minecraft:stone)
B(2,9,-2,minecraft:stone)
B(2,10,-2,minecraft:stone)
B(2,11,-2,minecraft:stone)
B(2,12,-2,minecraft:stone)
B(2,13,-2,minecraft:stone)
B(2,14,-2,minecraft:stone)
B(2,15,-2,minecraft:stone)
B(2,16,-2,minecraft:stone)
B(2,17,-2,minecraft:stone)
B(2,0,-1,minecraft:stone)
B(2,1,-1,minecraft:stone)
B(2,2,-1,minecraft:stone)
B(2,3,-1,minecraft:stone)
B(2,4,-1,minecraft:stone)
B(2,5,-1,minecraft:stone)
B(2,6,-1,minecraft:stone)
B(2,7,-1,minecraft:stone)
B(2,8,-1,minecraft:stone)
B(2,9,-1,minecraft:stone)
B(2,10,-1,minecraft:stone)
B(2,11,-1,minecraft:stone)
B(2,12,-1,minecraft:stone)
B(2,13,-1,minecraft:stone)
B(2,14,-1,minecraft:stone)
B(2,15,-1,minecraft:stone)
B(2,16,-1,minecraft:stone)
B(2,17,-1,minecraft:stone)
B(2,0,0,minecraft:stone)
B(2,1,0,minecraft:stone)
B(2,2,0,minecraft:stone)
B(2,3,0,minecraft:stone)
B(2,4,0,minecraft:stone)
B(2,5,0,minecraft:stone)
B(2,6,0,minecraft:stone)
B(2,7,0,minecraft:stone)
B(2,8,0,minecraft:stone)
B(2,9,0,minecraft:stone)
B(2,10,0,minecraft:stone)
B(2,11,0,minecraft:stone)
B(2,12,0,minecraft:stone)
B(2,13,0,minecraft:stone)
B(2,14,0,minecraft:stone)
B(2,15,0,minecraft:stone)
B(2,16,0,minecraft:andesite)
B(2,17,0,minecraft:andesite)
B(2,0,1,minecraft:stone)
B(2,1,1,minecraft:stone)
B(2,2,1,minecraft:stone)
B(2,3,1,minecraft:stone)
B(2,4,1,minecraft:stone)
B(2,5,1,minecraft:stone)
B(2,6,1,minecraft:stone)
B(2,7,1,minecraft:stone)
B(2,8,1,minecraft:stone)
B(2,9,1,minecraft:stone)
B(2,10,1,minecraft:stone)
B(2,11,1,minecraft:stone)
B(2,12,1,minecraft:stone)
B(2,13,1,minecraft:stone)
B(2,14,1,minecraft:stone)
B(2,15,1,minecraft:stone)
B(2,16,1,minecraft:andesite)
B(2,17,1,minecraft:andesite)
B(2,0,2,minecraft:stone)
B(2,1,2,minecraft:stone)
B(2,2,2,minecraft:stone)
B(2,3,2,minecraft:stone)
B(2,4,2,minecraft:stone)
B(2,5,2,minecraft:stone)
B(2,6,2,minecraft:stone)
B(2,7,2,minecraft:stone)
B(2,8,2,minecraft:stone)
B(2,9,2,minecraft:stone)
B(2,10,2,minecraft:stone)
B(2,11,2,minecraft:stone)
B(2,12,2,minecraft:stone)
B(2,13,2,minecraft:stone)
B(2,14,2,minecraft:stone)
B(2,15,2,minecraft:andesite)
B(2,16,2,minecraft:andesite)
B(2,0,3,minecraft:stone)
B(2,1,3,minecraft:stone)
B(2,2,3,minecraft:stone)
B(2,3,3,minecraft:stone)
B(2,4,3,minecraft:stone)
B(2,5,3,minecraft:stone)
B(2,6,3,minecraft:stone)
B(2,7,3,minecraft:stone)
B(2,8,3,minecraft:stone)
B(2,9,3,minecraft:stone)
B(2,10,3,minecraft:stone)
B(2,11,3,minecraft:stone)
B(2,12,3,minecraft:stone)
B(2,13,3,minecraft:stone)
B(2,14,3,minecraft:andesite)
B(2,15,3,minecraft:andesite)
B(2,16,3,minecraft:andesite)
B(2,0,4,minecraft:stone)
B(2,1,4,minecraft:stone)
B(2,2,4,minecraft:stone)
B(2,3,4,minecraft:stone)
B(2,4,4,minecraft:stone)
B(2,5,4,minecraft:stone)
B(2,6,4,minecraft:stone)
B(2,7,4,minecraft:stone)
B(2,8,4,minecraft:stone)
B(2,9,4,minecraft:stone)
B(2,10,4,minecraft:stone)
B(2,11,4,minecraft:stone)
B(2,12,4,minecraft:stone)
B(2,13,4,minecraft:andesite)
B(2,14,4,minecraft:andesite)
B(2,15,4,minecraft:andesite)
B(2,16,4,minecraft:andesite)
B(2,1,5,minecraft:stone)
B(2,2,5,minecraft:stone)
B(2,3,5,minecraft:stone)
B(2,4,5,minecraft:stone)
B(2,5,5,minecraft:stone)
B(2,6,5,minecraft:stone)
B(2,7,5,minecraft:stone)
B(2,8,5,minecraft:stone)
B(2,9,5,minecraft:stone)
B(2,10,5,minecraft:andesite)
B(2,11,5,minecraft:andesite)
B(2,12,5,minecraft:andesite)
B(2,13,5,minecraft:andesite)
B(2,14,5,minecraft:andesite)
B(2,15,5,minecraft:andesite)
B(2,2,6,minecraft:stone)
B(2,3,6,minecraft:stone)
B(2,4,6,minecraft:stone)
B(2,5,6,minecraft:stone)
B(2,6,6,minecraft:stone)
B(2,7,6,minecraft:stone)
B(2,8,6,minecraft:stone)
B(2,9,6,minecraft:stone)
B(2,10,6,minecraft:andesite)
B(2,11,6,minecraft:andesite)
B(2,12,6,minecraft:andesite)
B(2,13,6,minecraft:andesite)
B(2,14,6,minecraft:andesite)
B(2,2,7,minecraft:stone)
B(2,3,7,minecraft:stone)
B(2,4,7,minecraft:stone)
B(2,5,7,minecraft:stone)
B(2,6,7,minecraft:stone)
B(2,7,7,minecraft:stone)
B(2,8,7,minecraft:stone)
B(2,9,7,minecraft:stone)
B(2,6,8,minecraft:stone)
B(2,7,8,minecraft:stone)
B(2,8,8,minecraft:stone)
B(3,8,-9,minecraft:stone)
B(3,9,-9,minecraft:stone)
B(3,10,-9,minecraft:stone)
B(3,11,-9,minecraft:stone)
B(3,6,-8,minecraft:stone)
B(3,7,-8,minecraft:stone)
B(3,8,-8,minecraft:stone)
B(3,9,-8,minecraft:stone)
B(3,10,-8,minecraft:stone)
B(3,11,-8,minecraft:stone)
B(3,12,-8,minecraft:andesite)
B(3,13,-8,minecraft:andesite)
B(3,6,-7,minecraft:stone)
B(3,7,-7,minecraft:stone)
B(3,8,-7,minecraft:stone)
B(3,9,-7,minecraft:stone)
B(3,10,-7,minecraft:stone)
B(3,11,-7,minecraft:stone)
B(3,12,-7,minecraft:andesite)
B(3,13,-7,minecraft:andesite)
B(3,14,-7,minecraft:andesite)
B(3,15,-7,minecraft:andesite)
B(3,4,-6,minecraft:stone)
B(3,5,-6,minecraft:stone)
B(3,6,-6,minecraft:stone)
B(3,7,-6,minecraft:stone)
B(3,8,-6,minecraft:stone)
B(3,9,-6,minecraft:stone)
B(3,10,-6,minecraft:stone)
B(3,11,-6,minecraft:stone)
B(3,12,-6,minecraft:andesite)
B(3,13,-6,minecraft:andesite)
B(3,14,-6,minecraft:andesite)
B(3,15,-6,minecraft:andesite)
B(3,3,-5,minecraft:stone)
B(3,4,-5,minecraft:stone)
B(3,5,-5,minecraft:stone)
B(3,6,-5,minecraft:stone)
B(3,7,-5,minecraft:stone)
B(3,8,-5,minecraft:stone)
B(3,9,-5,minecraft:stone)
B(3,10,-5,minecraft:stone)
B(3,11,-5,minecraft:stone)
B(3,12,-5,minecraft:stone)
B(3,13,-5,minecraft:andesite)
B(3,14,-5,minecraft:andesite)
B(3,15,-5,minecraft:andesite)
B(3,16,-5,minecraft:stone)
B(3,2,-4,minecraft:stone)
B(3,3,-4,minecraft:stone)
B(3,4,-4,minecraft:stone)
B(3,5,-4,minecraft:stone)
B(3,6,-4,minecraft:stone)
B(3,7,-4,minecraft:stone)
B(3,8,-4,minecraft:stone)
B(3,9,-4,minecraft:stone)
B(3,10,-4,minecraft:stone)
B(3,11,-4,minecraft:stone)
B(3,12,-4,minecraft:stone)
B(3,13,-4,minecraft:stone)
B(3,14,-4,minecraft:stone)
B(3,15,-4,minecraft:stone)
B(3,16,-4,minecraft:stone)
B(3,2,-3,minecraft:stone)
B(3,3,-3,minecraft:stone)
B(3,4,-3,minecraft:stone)
B(3,5,-3,minecraft:stone)
B(3,6,-3,minecraft:stone)
B(3,7,-3,minecraft:stone)
B(3,8,-3,minecraft:stone)
B(3,9,-3,minecraft:stone)
B(3,10,-3,minecraft:stone)
B(3,11,-3,minecraft:stone)
B(3,12,-3,minecraft:stone)
B(3,13,-3,minecraft:stone)
B(3,14,-3,minecraft:stone)
B(3,15,-3,minecraft:stone)
B(3,16,-3,minecraft:stone)
B(3,2,-2,minecraft:stone)
B(3,3,-2,minecraft:stone)
B(3,4,-2,minecraft:stone)
B(3,5,-2,minecraft:stone)
B(3,6,-2,minecraft:stone)
B(3,7,-2,minecraft:stone)
B(3,8,-2,minecraft:stone)
B(3,9,-2,minecraft:stone)
B(3,10,-2,minecraft:stone)
B(3,11,-2,minecraft:stone)
B(3,12,-2,minecraft:stone)
B(3,13,-2,minecraft:stone)
B(3,14,-2,minecraft:stone)
B(3,15,-2,minecraft:stone)
B(3,16,-2,minecraft:stone)
B(3,17,-2,minecraft:stone)
B(3,0,-1,minecraft:stone)
B(3,1,-1,minecraft:stone)
B(3,2,-1,minecraft:stone)
B(3,3,-1,minecraft:stone)
B(3,4,-1,minecraft:stone)
B(3,5,-1,minecraft:stone)
B(3,6,-1,minecraft:stone)
B(3,7,-1,minecraft:stone)
B(3,8,-1,minecraft:stone)
B(3,9,-1,minecraft:stone)
B(3,10,-1,minecraft:stone)
B(3,11,-1,minecraft:stone)
B(3,12,-1,minecraft:stone)
B(3,13,-1,minecraft:stone)
B(3,14,-1,minecraft:stone)
B(3,15,-1,minecraft:stone)
B(3,16,-1,minecraft:stone)
B(3,17,-1,minecraft:stone)
B(3,0,0,minecraft:stone)
B(3,1,0,minecraft:stone)
B(3,2,0,minecraft:stone)
B(3,3,0,minecraft:stone)
B(3,4,0,minecraft:stone)
B(3,5,0,minecraft:stone)
B(3,6,0,minecraft:stone)
B(3,7,0,minecraft:stone)
B(3,8,0,minecraft:stone)
B(3,9,0,minecraft:stone)
B(3,10,0,minecraft:stone)
B(3,11,0,minecraft:stone)
B(3,12,0,minecraft:stone)
B(3,13,0,minecraft:stone)
B(3,14,0,minecraft:stone)
B(3,15,0,minecraft:stone)
B(3,16,0,minecraft:stone)
B(3,0,1,minecraft:stone)
B(3,1,1,minecraft:stone)
B(3,2,1,minecraft:stone)
B(3,3,1,minecraft:stone)
B(3,4,1,minecraft:stone)
B(3,5,1,minecraft:stone)
B(3,6,1,minecraft:stone)
B(3,7,1,minecraft:stone)
B(3,8,1,minecraft:stone)
B(3,9,1,minecraft:stone)
B(3,10,1,minecraft:stone)
B(3,11,1,minecraft:stone)
B(3,12,1,minecraft:stone)
B(3,13,1,minecraft:stone)
B(3,14,1,minecraft:stone)
B(3,15,1,minecraft:stone)
B(3,16,1,minecraft:stone)
B(3,1,2,minecraft:stone)
B(3,2,2,minecraft:stone)
B(3,3,2,minecraft:stone)
B(3,4,2,minecraft:stone)
B(3,5,2,minecraft:stone)
B(3,6,2,minecraft:stone)
B(3,7,2,minecraft:stone)
B(3,8,2,minecraft:stone)
B(3,9,2,minecraft:stone)
B(3,10,2,minecraft:stone)
B(3,11,2,minecraft:stone)
B(3,12,2,minecraft:stone)
B(3,13,2,minecraft:stone)
B(3,14,2,minecraft:stone)
B(3,15,2,minecraft:andesite)
B(3,16,2,minecraft:andesite)
B(3,1,3,minecraft:stone)
B(3,2,3,minecraft:stone)
B(3,3,3,minecraft:stone)
B(3,4,3,minecraft:stone)
B(3,5,3,minecraft:stone)
B(3,6,3,minecraft:stone)
B(3,7,3,minecraft:stone)
B(3,8,3,minecraft:stone)
B(3,9,3,minecraft:stone)
B(3,10,3,minecraft:stone)
B(3,11,3,minecraft:stone)
B(3,12,3,minecraft:stone)
B(3,13,3,minecraft:andesite)
B(3,14,3,minecraft:andesite)
B(3,15,3,minecraft:andesite)
B(3,1,4,minecraft:stone)
B(3,2,4,minecraft:stone)
B(3,3,4,minecraft:stone)
B(3,4,4,minecraft:stone)
B(3,5,4,minecraft:stone)
B(3,6,4,minecraft:stone)
B(3,7,4,minecraft:stone)
B(3,8,4,minecraft:stone)
B(3,9,4,minecraft:stone)
B(3,10,4,minecraft:andesite)
B(3,11,4,minecraft:andesite)
B(3,12,4,minecraft:andesite)
B(3,13,4,minecraft:andesite)
B(3,14,4,minecraft:andesite)
B(3,15,4,minecraft:andesite)
B(3,1,5,minecraft:stone)
B(3,2,5,minecraft:stone)
B(3,3,5,minecraft:stone)
B(3,4,5,minecraft:stone)
B(3,5,5,minecraft:stone)
B(3,6,5,minecraft:stone)
B(3,7,5,minecraft:stone)
B(3,8,5,minecraft:stone)
B(3,9,5,minecraft:andesite)
B(3,10,5,minecraft:andesite)
B(3,11,5,minecraft:andesite)
B(3,12,5,minecraft:andesite)
B(3,13,5,minecraft:andesite)
B(3,14,5,minecraft:andesite)
B(3,2,6,minecraft:stone)
B(3,3,6,minecraft:stone)
B(3,4,6,minecraft:stone)
B(3,5,6,minecraft:stone)
B(3,6,6,minecraft:stone)
B(3,7,6,minecraft:stone)
B(3,8,6,minecraft:andesite)
B(3,9,6,minecraft:andesite)
B(3,10,6,minecraft:andesite)
B(3,11,6,minecraft:andesite)
B(3,12,6,minecraft:andesite)
B(3,13,6,minecraft:andesite)
B(3,5,7,minecraft:stone)
B(3,6,7,minecraft:stone)
B(3,7,7,minecraft:stone)
B(3,8,7,minecraft:andesite)
B(3,9,7,minecraft:andesite)
B(3,6,8,minecraft:stone)
B(3,8,8,minecraft:andesite)
B(4,7,-9,minecraft:stone)
B(4,8,-9,minecraft:stone)
B(4,9,-9,minecraft:stone)
B(4,10,-9,minecraft:stone)
B(4,11,-9,minecraft:stone)
B(4,7,-8,minecraft:stone)
B(4,8,-8,minecraft:stone)
B(4,9,-8,minecraft:stone)
B(4,10,-8,minecraft:stone)
B(4,11,-8,minecraft:stone)
B(4,12,-8,minecraft:andesite)
B(4,13,-8,minecraft:andesite)
B(4,7,-7,minecraft:stone)
B(4,8,-7,minecraft:stone)
B(4,9,-7,minecraft:stone)
B(4,10,-7,minecraft:stone)
B(4,11,-7,minecraft:stone)
B(4,12,-7,minecraft:andesite)
B(4,13,-7,minecraft:andesite)
B(4,14,-7,minecraft:andesite)
B(4,4,-6,minecraft:stone)
B(4,5,-6,minecraft:stone)
B(4,6,-6,minecraft:stone)
B(4,7,-6,minecraft:stone)
B(4,8,-6,minecraft:stone)
B(4,9,-6,minecraft:stone)
B(4,10,-6,minecraft:stone)
B(4,11,-6,minecraft:stone)
B(4,12,-6,minecraft:andesite)
B(4,13,-6,minecraft:andesite)
B(4,14,-6,minecraft:andesite)
B(4,15,-6,minecraft:andesite)
B(4,3,-5,minecraft:stone)
B(4,4,-5,minecraft:stone)
B(4,5,-5,minecraft:stone)
B(4,6,-5,minecraft:stone)
B(4,7,-5,minecraft:stone)
B(4,8,-5,minecraft:stone)
B(4,9,-5,minecraft:stone)
B(4,10,-5,minecraft:stone)
B(4,11,-5,minecraft:stone)
B(4,12,-5,minecraft:andesite)
B(4,13,-5,minecraft:andesite)
B(4,14,-5,minecraft:andesite)
B(4,15,-5,minecraft:andesite)
B(4,16,-5,minecraft:stone)
B(4,2,-4,minecraft:stone)
B(4,3,-4,minecraft:stone)
B(4,4,-4,minecraft:stone)
B(4,5,-4,minecraft:stone)
B(4,6,-4,minecraft:stone)
B(4,7,-4,minecraft:stone)
B(4,8,-4,minecraft:stone)
B(4,9,-4,minecraft:stone)
B(4,10,-4,minecraft:stone)
B(4,11,-4,minecraft:stone)
B(4,12,-4,minecraft:andesite)
B(4,13,-4,minecraft:andesite)
B(4,14,-4,minecraft:andesite)
B(4,15,-4,minecraft:stone)
B(4,16,-4,minecraft:stone)
B(4,2,-3,minecraft:stone)
B(4,3,-3,minecraft:stone)
B(4,4,-3,minecraft:stone)
B(4,5,-3,minecraft:stone)
B(4,6,-3,minecraft:stone)
B(4,7,-3,minecraft:stone)
B(4,8,-3,minecraft:stone)
B(4,9,-3,minecraft:stone)
B(4,10,-3,minecraft:stone)
B(4,11,-3,minecraft:stone)
B(4,12,-3,minecraft:andesite)
B(4,13,-3,minecraft:andesite)
B(4,14,-3,minecraft:andesite)
B(4,15,-3,minecraft:stone)
B(4,16,-3,minecraft:stone)
B(4,2,-2,minecraft:stone)
B(4,3,-2,minecraft:stone)
B(4,4,-2,minecraft:stone)
B(4,5,-2,minecraft:stone)
B(4,6,-2,minecraft:stone)
B(4,7,-2,minecraft:stone)
B(4,8,-2,minecraft:stone)
B(4,9,-2,minecraft:stone)
B(4,10,-2,minecraft:stone)
B(4,11,-2,minecraft:stone)
B(4,12,-2,minecraft:stone)
B(4,13,-2,minecraft:stone)
B(4,14,-2,minecraft:stone)
B(4,15,-2,minecraft:stone)
B(4,16,-2,minecraft:stone)
B(4,1,-1,minecraft:stone)
B(4,2,-1,minecraft:stone)
B(4,3,-1,minecraft:stone)
B(4,4,-1,minecraft:stone)
B(4,5,-1,minecraft:stone)
B(4,6,-1,minecraft:stone)
B(4,7,-1,minecraft:stone)
B(4,8,-1,minecraft:stone)
B(4,9,-1,minecraft:stone)
B(4,10,-1,minecraft:stone)
B(4,11,-1,minecraft:stone)
B(4,12,-1,minecraft:stone)
B(4,13,-1,minecraft:stone)
B(4,14,-1,minecraft:stone)
B(4,15,-1,minecraft:stone)
B(4,16,-1,minecraft:stone)
B(4,0,0,minecraft:stone)
B(4,1,0,minecraft:stone)
B(4,2,0,minecraft:stone)
B(4,3,0,minecraft:stone)
B(4,4,0,minecraft:stone)
B(4,5,0,minecraft:stone)
B(4,6,0,minecraft:stone)
B(4,7,0,minecraft:stone)
B(4,8,0,minecraft:stone)
B(4,9,0,minecraft:stone)
B(4,10,0,minecraft:stone)
B(4,11,0,minecraft:stone)
B(4,12,0,minecraft:stone)
B(4,13,0,minecraft:stone)
B(4,14,0,minecraft:stone)
B(4,15,0,minecraft:stone)
B(4,16,0,minecraft:stone)
B(4,0,1,minecraft:stone)
B(4,1,1,minecraft:stone)
B(4,2,1,minecraft:stone)
B(4,3,1,minecraft:stone)
B(4,4,1,minecraft:stone)
B(4,5,1,minecraft:stone)
B(4,6,1,minecraft:stone)
B(4,7,1,minecraft:stone)
B(4,8,1,minecraft:stone)
B(4,9,1,minecraft:stone)
B(4,10,1,minecraft:stone)
B(4,11,1,minecraft:stone)
B(4,12,1,minecraft:stone)
B(4,13,1,minecraft:stone)
B(4,14,1,minecraft:stone)
B(4,15,1,minecraft:stone)
B(4,16,1,minecraft:stone)
B(4,0,2,minecraft:stone)
B(4,1,2,minecraft:stone)
B(4,2,2,minecraft:stone)
B(4,3,2,minecraft:stone)
B(4,4,2,minecraft:stone)
B(4,5,2,minecraft:stone)
B(4,6,2,minecraft:stone)
B(4,7,2,minecraft:stone)
B(4,8,2,minecraft:stone)
B(4,9,2,minecraft:stone)
B(4,10,2,minecraft:stone)
B(4,11,2,minecraft:stone)
B(4,12,2,minecraft:stone)
B(4,13,2,minecraft:stone)
B(4,14,2,minecraft:stone)
B(4,15,2,minecraft:stone)
B(4,16,2,minecraft:stone)
B(4,1,3,minecraft:stone)
B(4,2,3,minecraft:stone)
B(4,3,3,minecraft:stone)
B(4,4,3,minecraft:stone)
B(4,5,3,minecraft:stone)
B(4,6,3,minecraft:stone)
B(4,7,3,minecraft:stone)
B(4,8,3,minecraft:stone)
B(4,9,3,minecraft:stone)
B(4,10,3,minecraft:stone)
B(4,11,3,minecraft:stone)
B(4,12,3,minecraft:stone)
B(4,13,3,minecraft:andesite)
B(4,14,3,minecraft:andesite)
B(4,15,3,minecraft:andesite)
B(4,16,3,minecraft:andesite)
B(4,2,4,minecraft:stone)
B(4,3,4,minecraft:stone)
B(4,4,4,minecraft:stone)
B(4,5,4,minecraft:stone)
B(4,6,4,minecraft:stone)
B(4,7,4,minecraft:stone)
B(4,8,4,minecraft:stone)
B(4,9,4,minecraft:stone)
B(4,10,4,minecraft:andesite)
B(4,11,4,minecraft:andesite)
B(4,12,4,minecraft:andesite)
B(4,13,4,minecraft:andesite)
B(4,14,4,minecraft:andesite)
B(4,15,4,minecraft:andesite)
B(4,2,5,minecraft:stone)
B(4,3,5,minecraft:stone)
B(4,4,5,minecraft:stone)
B(4,5,5,minecraft:stone)
B(4,6,5,minecraft:stone)
B(4,7,5,minecraft:stone)
B(4,8,5,minecraft:andesite)
B(4,9,5,minecraft:andesite)
B(4,10,5,minecraft:andesite)
B(4,11,5,minecraft:andesite)
B(4,12,5,minecraft:andesite)
B(4,13,5,minecraft:andesite)
B(4,14,5,minecraft:andesite)
B(4,4,6,minecraft:stone)
B(4,5,6,minecraft:stone)
B(4,6,6,minecraft:stone)
B(4,7,6,minecraft:andesite)
B(4,8,6,minecraft:andesite)
B(4,9,6,minecraft:andesite)
B(4,10,6,minecraft:andesite)
B(4,11,6,minecraft:andesite)
B(4,12,6,minecraft:andesite)
B(4,13,6,minecraft:andesite)
B(4,5,7,minecraft:stone)
B(4,6,7,minecraft:stone)
B(4,7,7,minecraft:andesite)
B(4,8,7,minecraft:andesite)
B(4,9,7,minecraft:andesite)
B(4,6,8,minecraft:stone)
B(4,8,8,minecraft:andesite)
B(5,8,-8,minecraft:stone)
B(5,9,-8,minecraft:stone)
B(5,10,-8,minecraft:stone)
B(5,7,-7,minecraft:stone)
B(5,8,-7,minecraft:stone)
B(5,9,-7,minecraft:stone)
B(5,10,-7,minecraft:stone)
B(5,11,-7,minecraft:stone)
B(5,12,-7,minecraft:andesite)
B(5,13,-7,minecraft:andesite)
B(5,6,-6,minecraft:stone)
B(5,7,-6,minecraft:stone)
B(5,8,-6,minecraft:stone)
B(5,9,-6,minecraft:stone)
B(5,10,-6,minecraft:stone)
B(5,11,-6,minecraft:stone)
B(5,12,-6,minecraft:andesite)
B(5,13,-6,minecraft:andesite)
B(5,3,-5,minecraft:stone)
B(5,4,-5,minecraft:stone)
B(5,5,-5,minecraft:stone)
B(5,6,-5,minecraft:stone)
B(5,7,-5,minecraft:stone)
B(5,8,-5,minecraft:stone)
B(5,9,-5,minecraft:stone)
B(5,10,-5,minecraft:stone)
B(5,11,-5,minecraft:andesite)
B(5,12,-5,minecraft:andesite)
B(5,13,-5,minecraft:andesite)
B(5,14,-5,minecraft:andesite)
B(5,15,-5,minecraft:andesite)
B(5,3,-4,minecraft:stone)
B(5,4,-4,minecraft:stone)
B(5,5,-4,minecraft:stone)
B(5,6,-4,minecraft:stone)
B(5,7,-4,minecraft:stone)
B(5,8,-4,minecraft:stone)
B(5,9,-4,minecraft:stone)
B(5,10,-4,minecraft:stone)
B(5,11,-4,minecraft:andesite)
B(5,12,-4,minecraft:andesite)
B(5,13,-4,minecraft:andesite)
B(5,14,-4,minecraft:andesite)
B(5,15,-4,minecraft:andesite)
B(5,3,-3,minecraft:stone)
B(5,4,-3,minecraft:stone)
B(5,5,-3,minecraft:stone)
B(5,6,-3,minecraft:stone)
B(5,7,-3,minecraft:stone)
B(5,8,-3,minecraft:stone)
B(5,9,-3,minecraft:stone)
B(5,10,-3,minecraft:stone)
B(5,11,-3,minecraft:andesite)
B(5,12,-3,minecraft:andesite)
B(5,13,-3,minecraft:andesite)
B(5,14,-3,minecraft:andesite)
B(5,15,-3,minecraft:andesite)
B(5,16,-3,minecraft:stone)
B(5,2,-2,minecraft:stone)
B(5,3,-2,minecraft:stone)
B(5,4,-2,minecraft:stone)
B(5,5,-2,minecraft:stone)
B(5,6,-2,minecraft:stone)
B(5,7,-2,minecraft:stone)
B(5,8,-2,minecraft:stone)
B(5,9,-2,minecraft:stone)
B(5,10,-2,minecraft:stone)
B(5,11,-2,minecraft:stone)
B(5,12,-2,minecraft:andesite)
B(5,13,-2,minecraft:andesite)
B(5,14,-2,minecraft:andesite)
B(5,15,-2,minecraft:stone)
B(5,16,-2,minecraft:stone)
B(5,1,-1,minecraft:stone)
B(5,2,-1,minecraft:stone)
B(5,3,-1,minecraft:stone)
B(5,4,-1,minecraft:stone)
B(5,5,-1,minecraft:stone)
B(5,6,-1,minecraft:stone)
B(5,7,-1,minecraft:stone)
B(5,8,-1,minecraft:stone)
B(5,9,-1,minecraft:stone)
B(5,10,-1,minecraft:stone)
B(5,11,-1,minecraft:stone)
B(5,12,-1,minecraft:stone)
B(5,13,-1,minecraft:stone)
B(5,14,-1,minecraft:stone)
B(5,15,-1,minecraft:stone)
B(5,16,-1,minecraft:stone)
B(5,0,0,minecraft:stone)
B(5,1,0,minecraft:stone)
B(5,2,0,minecraft:stone)
B(5,3,0,minecraft:stone)
B(5,4,0,minecraft:stone)
B(5,5,0,minecraft:stone)
B(5,6,0,minecraft:stone)
B(5,7,0,minecraft:stone)
B(5,8,0,minecraft:stone)
B(5,9,0,minecraft:stone)
B(5,10,0,minecraft:stone)
B(5,11,0,minecraft:stone)
B(5,12,0,minecraft:stone)
B(5,13,0,minecraft:stone)
B(5,14,0,minecraft:stone)
B(5,15,0,minecraft:stone)
B(5,16,0,minecraft:stone)
B(5,17,0,minecraft:stone)
B(5,0,1,minecraft:stone)
B(5,1,1,minecraft:stone)
B(5,2,1,minecraft:stone)
B(5,3,1,minecraft:stone)
B(5,4,1,minecraft:stone)
B(5,5,1,minecraft:stone)
B(5,6,1,minecraft:stone)
B(5,7,1,minecraft:stone)
B(5,8,1,minecraft:stone)
B(5,9,1,minecraft:stone)
B(5,10,1,minecraft:stone)
B(5,11,1,minecraft:stone)
B(5,12,1,minecraft:stone)
B(5,13,1,minecraft:stone)
B(5,14,1,minecraft:stone)
B(5,15,1,minecraft:stone)
B(5,16,1,minecraft:stone)
B(5,0,2,minecraft:stone)
B(5,1,2,minecraft:stone)
B(5,2,2,minecraft:stone)
B(5,3,2,minecraft:stone)
B(5,4,2,minecraft:stone)
B(5,5,2,minecraft:stone)
B(5,6,2,minecraft:stone)
B(5,7,2,minecraft:stone)
B(5,8,2,minecraft:stone)
B(5,9,2,minecraft:stone)
B(5,10,2,minecraft:stone)
B(5,11,2,minecraft:stone)
B(5,12,2,minecraft:stone)
B(5,13,2,minecraft:stone)
B(5,14,2,minecraft:stone)
B(5,15,2,minecraft:stone)
B(5,1,3,minecraft:stone)
B(5,2,3,minecraft:stone)
B(5,3,3,minecraft:stone)
B(5,4,3,minecraft:stone)
B(5,5,3,minecraft:stone)
B(5,6,3,minecraft:stone)
B(5,7,3,minecraft:stone)
B(5,8,3,minecraft:stone)
B(5,9,3,minecraft:stone)
B(5,10,3,minecraft:stone)
B(5,11,3,minecraft:stone)
B(5,12,3,minecraft:stone)
B(5,13,3,minecraft:andesite)
B(5,14,3,minecraft:andesite)
B(5,15,3,minecraft:andesite)
B(5,2,4,minecraft:stone)
B(5,3,4,minecraft:stone)
B(5,4,4,minecraft:stone)
B(5,5,4,minecraft:stone)
B(5,6,4,minecraft:stone)
B(5,7,4,minecraft:stone)
B(5,8,4,minecraft:stone)
B(5,9,4,minecraft:stone)
B(5,10,4,minecraft:andesite)
B(5,11,4,minecraft:andesite)
B(5,12,4,minecraft:andesite)
B(5,13,4,minecraft:andesite)
B(5,14,4,minecraft:andesite)
B(5,3,5,minecraft:stone)
B(5,4,5,minecraft:stone)
B(5,5,5,minecraft:stone)
B(5,6,5,minecraft:stone)
B(5,7,5,minecraft:stone)
B(5,8,5,minecraft:andesite)
B(5,9,5,minecraft:andesite)
B(5,10,5,minecraft:andesite)
B(5,11,5,minecraft:andesite)
B(5,12,5,minecraft:andesite)
B(5,13,5,minecraft:andesite)
B(5,14,5,minecraft:andesite)
B(5,4,6,minecraft:stone)
B(5,5,6,minecraft:stone)
B(5,6,6,minecraft:stone)
B(5,7,6,minecraft:andesite)
B(5,8,6,minecraft:andesite)
B(5,9,6,minecraft:andesite)
B(5,11,6,minecraft:andesite)
B(5,12,6,minecraft:andesite)
B(5,13,6,minecraft:andesite)
B(5,7,7,minecraft:andesite)
B(5,8,7,minecraft:andesite)
B(5,9,7,minecraft:andesite)
B(6,7,-7,minecraft:stone)
B(6,8,-7,minecraft:stone)
B(6,9,-7,minecraft:andesite)
B(6,10,-7,minecraft:andesite)
B(6,6,-6,minecraft:stone)
B(6,7,-6,minecraft:andesite)
B(6,8,-6,minecraft:andesite)
B(6,9,-6,minecraft:andesite)
B(6,10,-6,minecraft:andesite)
B(6,11,-6,minecraft:andesite)
B(6,12,-6,minecraft:andesite)
B(6,13,-6,minecraft:andesite)
B(6,5,-5,minecraft:stone)
B(6,6,-5,minecraft:stone)
B(6,7,-5,minecraft:andesite)
B(6,8,-5,minecraft:andesite)
B(6,9,-5,minecraft:andesite)
B(6,10,-5,minecraft:andesite)
B(6,11,-5,minecraft:andesite)
B(6,12,-5,minecraft:andesite)
B(6,13,-5,minecraft:andesite)
B(6,14,-5,minecraft:andesite)
B(6,4,-4,minecraft:stone)
B(6,5,-4,minecraft:stone)
B(6,6,-4,minecraft:stone)
B(6,7,-4,minecraft:andesite)
B(6,8,-4,minecraft:andesite)
B(6,9,-4,minecraft:andesite)
B(6,10,-4,minecraft:stone)
B(6,11,-4,minecraft:andesite)
B(6,12,-4,minecraft:andesite)
B(6,13,-4,minecraft:andesite)
B(6,14,-4,minecraft:andesite)
B(6,15,-4,minecraft:andesite)
B(6,4,-3,minecraft:stone)
B(6,5,-3,minecraft:stone)
B(6,6,-3,minecraft:stone)
B(6,7,-3,minecraft:stone)
B(6,8,-3,minecraft:stone)
B(6,9,-3,minecraft:stone)
B(6,10,-3,minecraft:stone)
B(6,11,-3,minecraft:andesite)
B(6,12,-3,minecraft:andesite)
B(6,13,-3,minecraft:andesite)
B(6,14,-3,minecraft:andesite)
B(6,15,-3,minecraft:andesite)
B(6,16,-3,minecraft:stone)
B(6,2,-2,minecraft:stone)
B(6,3,-2,minecraft:stone)
B(6,4,-2,minecraft:stone)
B(6,5,-2,minecraft:stone)
B(6,6,-2,minecraft:stone)
B(6,7,-2,minecraft:stone)
B(6,8,-2,minecraft:stone)
B(6,9,-2,minecraft:stone)
B(6,10,-2,minecraft:stone)
B(6,11,-2,minecraft:stone)
B(6,12,-2,minecraft:andesite)
B(6,13,-2,minecraft:andesite)
B(6,14,-2,minecraft:andesite)
B(6,15,-2,minecraft:stone)
B(6,16,-2,minecraft:stone)
B(6,1,-1,minecraft:stone)
B(6,2,-1,minecraft:stone)
B(6,3,-1,minecraft:stone)
B(6,4,-1,minecraft:stone)
B(6,5,-1,minecraft:stone)
B(6,6,-1,minecraft:stone)
B(6,7,-1,minecraft:stone)
B(6,8,-1,minecraft:stone)
B(6,9,-1,minecraft:stone)
B(6,10,-1,minecraft:stone)
B(6,11,-1,minecraft:stone)
B(6,12,-1,minecraft:stone)
B(6,13,-1,minecraft:stone)
B(6,14,-1,minecraft:stone)
B(6,15,-1,minecraft:stone)
B(6,16,-1,minecraft:stone)
B(6,1,0,minecraft:stone)
B(6,2,0,minecraft:stone)
B(6,3,0,minecraft:stone)
B(6,4,0,minecraft:stone)
B(6,5,0,minecraft:stone)
B(6,6,0,minecraft:stone)
B(6,7,0,minecraft:stone)
B(6,8,0,minecraft:stone)
B(6,9,0,minecraft:stone)
B(6,10,0,minecraft:stone)
B(6,11,0,minecraft:stone)
B(6,12,0,minecraft:stone)
B(6,13,0,minecraft:stone)
B(6,14,0,minecraft:stone)
B(6,15,0,minecraft:stone)
B(6,1,1,minecraft:stone)
B(6,2,1,minecraft:stone)
B(6,3,1,minecraft:stone)
B(6,4,1,minecraft:stone)
B(6,5,1,minecraft:stone)
B(6,6,1,minecraft:stone)
B(6,7,1,minecraft:stone)
B(6,8,1,minecraft:stone)
B(6,9,1,minecraft:stone)
B(6,10,1,minecraft:stone)
B(6,11,1,minecraft:stone)
B(6,12,1,minecraft:stone)
B(6,13,1,minecraft:stone)
B(6,14,1,minecraft:stone)
B(6,15,1,minecraft:stone)
B(6,2,2,minecraft:stone)
B(6,3,2,minecraft:stone)
B(6,4,2,minecraft:stone)
B(6,5,2,minecraft:stone)
B(6,6,2,minecraft:stone)
B(6,7,2,minecraft:stone)
B(6,8,2,minecraft:stone)
B(6,9,2,minecraft:stone)
B(6,10,2,minecraft:stone)
B(6,11,2,minecraft:stone)
B(6,12,2,minecraft:stone)
B(6,13,2,minecraft:stone)
B(6,14,2,minecraft:stone)
B(6,15,2,minecraft:stone)
B(6,1,3,minecraft:stone)
B(6,2,3,minecraft:stone)
B(6,3,3,minecraft:stone)
B(6,4,3,minecraft:stone)
B(6,5,3,minecraft:stone)
B(6,6,3,minecraft:stone)
B(6,7,3,minecraft:stone)
B(6,8,3,minecraft:stone)
B(6,9,3,minecraft:stone)
B(6,10,3,minecraft:stone)
B(6,11,3,minecraft:stone)
B(6,12,3,minecraft:stone)
B(6,13,3,minecraft:stone)
B(6,14,3,minecraft:stone)
B(6,15,3,minecraft:stone)
B(6,3,4,minecraft:stone)
B(6,4,4,minecraft:stone)
B(6,5,4,minecraft:stone)
B(6,6,4,minecraft:stone)
B(6,7,4,minecraft:stone)
B(6,8,4,minecraft:stone)
B(6,9,4,minecraft:stone)
B(6,10,4,minecraft:stone)
B(6,11,4,minecraft:stone)
B(6,12,4,minecraft:stone)
B(6,13,4,minecraft:andesite)
B(6,14,4,minecraft:andesite)
B(6,15,4,minecraft:andesite)
B(6,3,5,minecraft:stone)
B(6,4,5,minecraft:stone)
B(6,5,5,minecraft:stone)
B(6,6,5,minecraft:stone)
B(6,7,5,minecraft:stone)
B(6,8,5,minecraft:andesite)
B(6,9,5,minecraft:andesite)
B(6,10,5,minecraft:andesite)
B(6,11,5,minecraft:andesite)
B(6,12,5,minecraft:andesite)
B(6,13,5,minecraft:andesite)
B(6,5,6,minecraft:stone)
B(6,6,6,minecraft:stone)
B(6,7,6,minecraft:andesite)
B(6,8,6,minecraft:andesite)
B(6,9,6,minecraft:andesite)
B(7,9,-7,minecraft:andesite)
B(7,6,-6,minecraft:andesite)
B(7,7,-6,minecraft:andesite)
B(7,8,-6,minecraft:andesite)
B(7,9,-6,minecraft:andesite)
B(7,10,-6,minecraft:andesite)
B(7,5,-5,minecraft:stone)
B(7,6,-5,minecraft:andesite)
B(7,7,-5,minecraft:andesite)
B(7,8,-5,minecraft:andesite)
B(7,9,-5,minecraft:andesite)
B(7,10,-5,minecraft:andesite)
B(7,11,-5,minecraft:andesite)
B(7,12,-5,minecraft:andesite)
B(7,5,-4,minecraft:stone)
B(7,6,-4,minecraft:andesite)
B(7,7,-4,minecraft:andesite)
B(7,8,-4,minecraft:andesite)
B(7,9,-4,minecraft:andesite)
B(7,10,-4,minecraft:andesite)
B(7,11,-4,minecraft:andesite)
B(7,12,-4,minecraft:andesite)
B(7,14,-4,minecraft:andesite)
B(7,4,-3,minecraft:stone)
B(7,5,-3,minecraft:stone)
B(7,6,-3,minecraft:stone)
B(7,7,-3,minecraft:andesite)
B(7,8,-3,minecraft:andesite)
B(7,9,-3,minecraft:andesite)
B(7,10,-3,minecraft:stone)
B(7,11,-3,minecraft:andesite)
B(7,12,-3,minecraft:andesite)
B(7,13,-3,minecraft:andesite)
B(7,3,-2,minecraft:stone)
B(7,4,-2,minecraft:stone)
B(7,5,-2,minecraft:stone)
B(7,6,-2,minecraft:andesite)
B(7,7,-2,minecraft:andesite)
B(7,8,-2,minecraft:andesite)
B(7,9,-2,minecraft:stone)
B(7,10,-2,minecraft:stone)
B(7,11,-2,minecraft:stone)
B(7,12,-2,minecraft:andesite)
B(7,13,-2,minecraft:andesite)
B(7,14,-2,minecraft:andesite)
B(7,15,-2,minecraft:stone)
B(7,3,-1,minecraft:stone)
B(7,4,-1,minecraft:stone)
B(7,5,-1,minecraft:stone)
B(7,6,-1,minecraft:andesite)
B(7,7,-1,minecraft:andesite)
B(7,8,-1,minecraft:andesite)
B(7,9,-1,minecraft:stone)
B(7,10,-1,minecraft:stone)
B(7,11,-1,minecraft:stone)
B(7,12,-1,minecraft:stone)
B(7,13,-1,minecraft:stone)
B(7,14,-1,minecraft:stone)
B(7,15,-1,minecraft:stone)
B(7,2,0,minecraft:stone)
B(7,3,0,minecraft:stone)
B(7,4,0,minecraft:stone)
B(7,5,0,minecraft:andesite)
B(7,6,0,minecraft:andesite)
B(7,7,0,minecraft:andesite)
B(7,8,0,minecraft:andesite)
B(7,9,0,minecraft:stone)
B(7,10,0,minecraft:stone)
B(7,11,0,minecraft:stone)
B(7,12,0,minecraft:stone)
B(7,13,0,minecraft:stone)
B(7,14,0,minecraft:stone)
B(7,15,0,minecraft:stone)
B(7,1,1,minecraft:stone)
B(7,2,1,minecraft:stone)
B(7,3,1,minecraft:stone)
B(7,4,1,minecraft:stone)
B(7,5,1,minecraft:andesite)
B(7,6,1,minecraft:andesite)
B(7,7,1,minecraft:andesite)
B(7,8,1,minecraft:stone)
B(7,9,1,minecraft:stone)
B(7,10,1,minecraft:stone)
B(7,11,1,minecraft:stone)
B(7,12,1,minecraft:stone)
B(7,13,1,minecraft:stone)
B(7,14,1,minecraft:stone)
B(7,15,1,minecraft:stone)
B(7,2,2,minecraft:stone)
B(7,3,2,minecraft:stone)
B(7,4,2,minecraft:stone)
B(7,5,2,minecraft:andesite)
B(7,6,2,minecraft:andesite)
B(7,7,2,minecraft:andesite)
B(7,8,2,minecraft:stone)
B(7,9,2,minecraft:stone)
B(7,10,2,minecraft:stone)
B(7,11,2,minecraft:stone)
B(7,12,2,minecraft:stone)
B(7,13,2,minecraft:stone)
B(7,14,2,minecraft:stone)
B(7,15,2,minecraft:stone)
B(7,2,3,minecraft:stone)
B(7,3,3,minecraft:stone)
B(7,4,3,minecraft:stone)
B(7,5,3,minecraft:stone)
B(7,6,3,minecraft:stone)
B(7,7,3,minecraft:stone)
B(7,8,3,minecraft:stone)
B(7,9,3,minecraft:stone)
B(7,10,3,minecraft:stone)
B(7,11,3,minecraft:stone)
B(7,12,3,minecraft:stone)
B(7,13,3,minecraft:stone)
B(7,14,3,minecraft:stone)
B(7,3,4,minecraft:stone)
B(7,4,4,minecraft:stone)
B(7,5,4,minecraft:stone)
B(7,6,4,minecraft:stone)
B(7,7,4,minecraft:stone)
B(7,8,4,minecraft:stone)
B(7,9,4,minecraft:stone)
B(7,10,4,minecraft:stone)
B(7,11,4,minecraft:stone)
B(7,12,4,minecraft:stone)
B(7,13,4,minecraft:stone)
B(7,14,4,minecraft:stone)
B(7,3,5,minecraft:stone)
B(7,4,5,minecraft:stone)
B(7,5,5,minecraft:stone)
B(7,6,5,minecraft:stone)
B(7,7,5,minecraft:stone)
B(7,8,5,minecraft:stone)
B(7,9,5,minecraft:stone)
B(7,10,5,minecraft:stone)
B(7,7,6,minecraft:stone)
B(7,8,6,minecraft:andesite)
B(7,9,6,minecraft:andesite)
B(8,10,-6,minecraft:andesite)
B(8,6,-5,minecraft:andesite)
B(8,7,-5,minecraft:andesite)
B(8,8,-5,minecraft:andesite)
B(8,9,-5,minecraft:andesite)
B(8,10,-5,minecraft:andesite)
B(8,6,-4,minecraft:andesite)
B(8,7,-4,minecraft:andesite)
B(8,8,-4,minecraft:andesite)
B(8,9,-4,minecraft:andesite)
B(8,10,-4,minecraft:andesite)
B(8,11,-4,minecraft:andesite)
B(8,4,-3,minecraft:stone)
B(8,5,-3,minecraft:stone)
B(8,6,-3,minecraft:andesite)
B(8,7,-3,minecraft:andesite)
B(8,8,-3,minecraft:andesite)
B(8,9,-3,minecraft:andesite)
B(8,10,-3,minecraft:andesite)
B(8,11,-3,minecraft:stone)
B(8,12,-3,minecraft:andesite)
B(8,3,-2,minecraft:stone)
B(8,4,-2,minecraft:stone)
B(8,5,-2,minecraft:andesite)
B(8,6,-2,minecraft:andesite)
B(8,7,-2,minecraft:andesite)
B(8,8,-2,minecraft:andesite)
B(8,9,-2,minecraft:andesite)
B(8,10,-2,minecraft:stone)
B(8,11,-2,minecraft:stone)
B(8,12,-2,minecraft:stone)
B(8,13,-2,minecraft:stone)
B(8,14,-2,minecraft:stone)
B(8,3,-1,minecraft:stone)
B(8,4,-1,minecraft:stone)
B(8,5,-1,minecraft:andesite)
B(8,6,-1,minecraft:andesite)
B(8,7,-1,minecraft:andesite)
B(8,8,-1,minecraft:andesite)
B(8,9,-1,minecraft:andesite)
B(8,10,-1,minecraft:stone)
B(8,11,-1,minecraft:stone)
B(8,12,-1,minecraft:stone)
B(8,13,-1,minecraft:stone)
B(8,2,0,minecraft:stone)
B(8,3,0,minecraft:stone)
B(8,4,0,minecraft:andesite)
B(8,5,0,minecraft:andesite)
B(8,6,0,minecraft:andesite)
B(8,7,0,minecraft:andesite)
B(8,8,0,minecraft:andesite)
B(8,9,0,minecraft:andesite)
B(8,10,0,minecraft:stone)
B(8,11,0,minecraft:stone)
B(8,12,0,minecraft:stone)
B(8,13,0,minecraft:stone)
B(8,14,0,minecraft:stone)
B(8,2,1,minecraft:stone)
B(8,3,1,minecraft:stone)
B(8,4,1,minecraft:andesite)
B(8,5,1,minecraft:andesite)
B(8,6,1,minecraft:andesite)
B(8,7,1,minecraft:andesite)
B(8,8,1,minecraft:andesite)
B(8,9,1,minecraft:stone)
B(8,10,1,minecraft:stone)
B(8,11,1,minecraft:stone)
B(8,12,1,minecraft:stone)
B(8,13,1,minecraft:stone)
B(8,14,1,minecraft:stone)
B(8,3,2,minecraft:stone)
B(8,4,2,minecraft:andesite)
B(8,5,2,minecraft:andesite)
B(8,6,2,minecraft:andesite)
B(8,7,2,minecraft:andesite)
B(8,8,2,minecraft:andesite)
B(8,9,2,minecraft:stone)
B(8,10,2,minecraft:stone)
B(8,11,2,minecraft:stone)
B(8,12,2,minecraft:stone)
B(8,13,2,minecraft:stone)
B(8,4,3,minecraft:stone)
B(8,5,3,minecraft:andesite)
B(8,6,3,minecraft:andesite)
B(8,7,3,minecraft:andesite)
B(8,8,3,minecraft:stone)
B(8,9,3,minecraft:stone)
B(8,10,3,minecraft:stone)
B(8,11,3,minecraft:stone)
B(8,12,3,minecraft:stone)
B(8,13,3,minecraft:stone)
B(8,4,4,minecraft:stone)
B(8,5,4,minecraft:stone)
B(8,6,4,minecraft:stone)
B(8,7,4,minecraft:stone)
B(8,8,4,minecraft:stone)
B(8,9,4,minecraft:stone)
B(8,10,4,minecraft:stone)
B(8,6,5,minecraft:stone)
B(8,7,5,minecraft:stone)
B(8,8,5,minecraft:stone)
B(8,9,5,minecraft:stone)
B(8,10,5,minecraft:stone)
B(9,7,-4,minecraft:andesite)
B(9,8,-4,minecraft:andesite)
B(9,9,-4,minecraft:andesite)
B(9,7,-3,minecraft:andesite)
B(9,8,-3,minecraft:andesite)
B(9,9,-3,minecraft:andesite)
B(9,4,-2,minecraft:stone)
B(9,6,-2,minecraft:andesite)
B(9,7,-2,minecraft:andesite)
B(9,8,-2,minecraft:andesite)
B(9,9,-2,minecraft:andesite)
B(9,10,-2,minecraft:stone)
B(9,11,-2,minecraft:stone)
B(9,3,-1,minecraft:stone)
B(9,4,-1,minecraft:stone)
B(9,5,-1,minecraft:andesite)
B(9,6,-1,minecraft:andesite)
B(9,7,-1,minecraft:andesite)
B(9,8,-1,minecraft:andesite)
B(9,9,-1,minecraft:andesite)
B(9,10,-1,minecraft:stone)
B(9,11,-1,minecraft:stone)
B(9,4,0,minecraft:andesite)
B(9,5,0,minecraft:andesite)
B(9,6,0,minecraft:andesite)
B(9,7,0,minecraft:andesite)
B(9,8,0,minecraft:andesite)
B(9,9,0,minecraft:andesite)
B(9,10,0,minecraft:stone)
B(9,11,0,minecraft:stone)
B(9,3,1,minecraft:stone)
B(9,4,1,minecraft:andesite)
B(9,5,1,minecraft:andesite)
B(9,6,1,minecraft:andesite)
B(9,7,1,minecraft:andesite)
B(9,8,1,minecraft:andesite)
B(9,3,2,minecraft:stone)
B(9,4,2,minecraft:andesite)
B(9,5,2,minecraft:andesite)
B(9,6,2,minecraft:andesite)
B(9,7,2,minecraft:andesite)
B(9,8,2,minecraft:andesite)
B(9,9,2,minecraft:stone)
B(9,7,3,minecraft:andesite)
B(9,8,3,minecraft:stone)
B(9,9,3,minecraft:stone)
B(9,7,4,minecraft:stone)
B(9,8,4,minecraft:stone)
B(9,9,4,minecraft:stone)
B(10,7,-1,minecraft:andesite)
B(10,6,0,minecraft:andesite)
B(10,5,1,minecraft:andesite)

#######################################################################
# +-----------------------------------------------------------------+ #
# |                            BO3 checks                           | #
# +-----------------------------------------------------------------+ #
#######################################################################

# Require a condition at a certain location in order for the BO3 to be spawned.
# BlockCheck(x,y,z,BlockName[,BlockName[,...]]) - one of the blocks must be at the location
# BlockCheckNot(x,y,z,BlockName[,BlockName[,...]]) - all the blocks must not be at the location
# LightCheck(x,y,z,minLightLevel,maxLightLevel) - light must be between min and max (inclusive)
# ModCheck(ModName[,ModName[,...]]) - all the mods listed must be loaded
# ModCheckNot(ModName[,ModName[,...]]) - all the mods listed must not be loaded

# You can use "Solid" as a BlockName for matching all solid blocks or "All" to match all blocks that aren't air.

# Examples:
#   BlockCheck(0,-1,0,GRASS,DIRT)  Require grass or dirt just below the object
#   BlockCheck(0,-1,0,Solid)		Require any solid block just below the object
#   BlockCheck(0,-1,0,WOOL)		Require any type of wool just below the object
#   BlockCheck(0,-1,0,WOOL:0)	  Require white wool just below the object
#   BlockCheckNot(0,-1,0,WOOL:0)	Require that there is no white wool below the object
#   LightCheck(0,0,0,0,1)		  Require almost complete darkness just below the object
BlockCheck(0,5,0,minecraft:grass_block,minecraft:dirt,minecraft:water,minecraft:snow_block)
BlockCheck(1,-1,0,Solid)
BlockCheck(1,-1,-1,Solid)
BlockCheck(1,-1,1,Solid)
BlockCheck(0,-1,1,Solid)
BlockCheck(0,-1,-1,Solid)
BlockCheck(-1,-1,1,Solid)
BlockCheck(-1,-1,0,Solid)
BlockCheck(-1,-1,-1,Solid)
BlockCheck(2,-1,2,Solid)
BlockCheck(2,-1,1,Solid)
BlockCheck(2,-1,0,Solid)
BlockCheck(2,-1,-1,Solid)
