
#######################################################################
# +-----------------------------------------------------------------+ #
# |                            BO3 object                           | #
# +-----------------------------------------------------------------+ #
#######################################################################

# This is the config file of a custom object.
# If you add this object correctly to your BiomeConfigs, it will spawn in the world.

# This is the creator of this BO3 object
Author: Unknown

# A short description of this BO3 object
Description: This BO3 was converted from a schematic using OTGEdit. The author and description information of the schematic could not be found. If you know who the author of the schematic is then please add this information.

# The BO3 version, don't change this! It can be used by external applications to do a version check.
Version: 3

# The settings mode, WriteAll, WriteWithoutComments or WriteDisable. See WorldConfig.
SettingsMode: WriteAll


#######################################################################
# +-----------------------------------------------------------------+ #
# |                          Main settings                          | #
# +-----------------------------------------------------------------+ #
#######################################################################

# This needs to be set to true to spawn the object in the Tree and Sapling resources.
Tree: true

# The frequency of the BO3 from 1 to 200. Tries this many times to spawn this BO3 when using the CustomObject(...) resource.
# Ignored by Tree(..), Sapling(..) and CustomStructure(..)
Frequency: 40

# The rarity of the BO3 from 0 to 100. Each spawn attempt has rarity% chance to succeed when using the CustomObject(...) resource.
# Ignored by Tree(..), Sapling(..) and CustomStructure(..)
Rarity: 100.0

# When using Frequency, after this many succesfull spawn attempts, abort spawning.
# For example, you can set 100 spawn attempts using Frequency, but stop spawning after 5 successfull spawns via MaxSpawn.
# 0 by default, which means ignore this setting.
# Ignored by Tree(..), Sapling(..) and CustomStructure(..)
MaxSpawn: 0

# If you set this to true, the BO3 will be placed with a random rotation.
RotateRandomly: true

# The spawn height of the BO3: randomY, highestBlock or highestSolidBlock.
SpawnHeight: randomY

# The offset from the spawn height to spawn this BO3
# Ex. SpawnHeight = highestSolidBlock, SpawnHeightOffset = 3; This object will spawn 3 blocks above the highest solid block
SpawnHeightOffset: 0

# A random amount to offset the spawn location from the spawn offset height
# Ex. SpawnHeightOffset = 3, SpawnHeightVariance = 3; This object will spawn 3 to 6 blocks above the original spot it would have spawned
SpawnHeightVariance: 0

##############################
# Height Limits for the BO3. #
##############################

# When in randomY mode used as the minimum Y or in atMinY mode as the actual Y to spawn this BO3 at.
MinHeight: 62

# When in randomY mode used as the maximum Y to spawn this BO3 at.
MaxHeight: 255

######################
# Extrusion settings #
######################

# The style of extrusion you wish to use - BottomDown, TopUp, None (Default)
ExtrudeMode: None

# The blocks to extrude your BO3 through
ExtrudeThroughBlocks: minecraft:air

# Objects can have other objects attacthed to it: branches. Branches can also
# have branches attached to it, which can also have branches, etc. This is the
# maximum branch depth for this objects.
MaxBranchDepth: 10


#######################################################################
# +-----------------------------------------------------------------+ #
# |                      Source block settings                      | #
# +-----------------------------------------------------------------+ #
#######################################################################

# The block(s) the BO3 should spawn in.
SourceBlocks: minecraft:air,minecraft:grass_block,minecraft:dirt

# The maximum percentage of the BO3 that can be outside the SourceBlock.
# The BO3 won't be placed on a location with more blocks outside the SourceBlock than this percentage.
MaxPercentageOutsideSourceBlock: 5

# What to do when a block is about to be placed outside the SourceBlock? (dontPlace, placeAnyway)
OutsideSourceBlock: dontPlace

# Disable doReplaceBlocks to make this BO3 ignore any ReplacedBlocks settings in biome configs, improves performance.
DoReplaceBlocks: true

# OTG+ settings #
# Legacy setting, rename this file to .BO4 instead. Set this to true to enable the advanced customstructure features of OTG+.
IsOTGPlus: false


#######################################################################
# +-----------------------------------------------------------------+ #
# |                              Blocks                             | #
# +-----------------------------------------------------------------+ #
#######################################################################

# All the blocks used in the BO3 are listed here. Possible blocks:
# Block(x,y,z,id[.data][,nbtfile.nbt)
# RandomBlock(x,y,z,id[:data][,nbtfile.nbt],chance[,id[:data][,nbtfile.nbt],chance[,...]])
#  So RandomBlock(0,0,0,CHEST,chest.nbt,50,CHEST,anotherchest.nbt,100) will spawn a chest at
#  the BO3 origin, and give it a 50% chance to have the contents of chest.nbt, or, if that
#  fails, a 100% percent chance to have the contents of anotherchest.nbt.
# *Note: Unlike Entity() and Spawner(), for Block() .txt files don't work, only .nbt files work.
# MinecraftObject(x,y,z,name) (TODO: This may not work anymore and needs to be tested.
#  Spawns an object in the Mojang NBT structure format. For example, 
#  MinecraftObject(0,0,0,minecraft:igloo/igloo_bottom)
#  spawns the bottom part of an igloo.
B(-6,18,-1,minecraft:oak_leaves)
B(-5,25,-3,minecraft:oak_leaves)
B(-5,18,-2,minecraft:oak_leaves)
B(-5,18,-1,minecraft:oak_leaves)
B(-5,18,0,minecraft:oak_leaves)
B(-5,25,0,minecraft:oak_leaves)
B(-5,18,2,minecraft:oak_leaves)
B(-5,27,2,minecraft:oak_leaves)
B(-5,28,2,minecraft:oak_leaves)
B(-5,18,3,minecraft:oak_leaves)
B(-4,25,-4,minecraft:oak_leaves)
B(-4,25,-3,minecraft:oak_leaves)
B(-4,26,-3,minecraft:oak_leaves)
B(-4,18,-2,minecraft:oak_leaves)
B(-4,25,-2,minecraft:oak_leaves)
B(-4,26,-2,minecraft:oak_leaves)
B(-4,17,-1,minecraft:oak_leaves)
B(-4,18,-1,minecraft:oak_log)
B(-4,19,-1,minecraft:oak_leaves)
B(-4,25,-1,minecraft:oak_leaves)
B(-4,29,-1,minecraft:oak_leaves)
B(-4,18,0,minecraft:oak_leaves)
B(-4,25,0,minecraft:oak_leaves)
B(-4,26,0,minecraft:oak_leaves)
B(-4,18,1,minecraft:oak_leaves)
B(-4,22,1,minecraft:oak_leaves)
B(-4,23,1,minecraft:oak_leaves)
B(-4,25,1,minecraft:oak_leaves)
B(-4,27,1,minecraft:oak_leaves)
B(-4,18,2,minecraft:oak_log)
B(-4,19,2,minecraft:oak_leaves)
B(-4,22,2,minecraft:oak_leaves)
B(-4,27,2,minecraft:oak_log)
B(-4,28,2,minecraft:oak_leaves)
B(-4,18,3,minecraft:oak_leaves)
B(-4,22,3,minecraft:oak_leaves)
B(-4,27,3,minecraft:oak_leaves)
B(-4,18,4,minecraft:oak_leaves)
B(-4,28,4,minecraft:oak_leaves)
B(-4,16,6,minecraft:oak_leaves)
B(-3,25,-3,minecraft:oak_leaves)
B(-3,25,-2,minecraft:oak_log)
B(-3,26,-2,minecraft:oak_leaves)
B(-3,29,-2,minecraft:oak_leaves)
B(-3,17,-1,minecraft:oak_leaves)
B(-3,25,-1,minecraft:oak_leaves)
B(-3,29,-1,minecraft:oak_leaves)
B(-3,17,0,minecraft:oak_log)
B(-3,18,0,minecraft:oak_leaves)
B(-3,22,0,minecraft:oak_leaves)
B(-3,23,0,minecraft:oak_leaves)
B(-3,25,0,minecraft:oak_log)
B(-3,26,0,minecraft:oak_leaves)
B(-3,29,0,minecraft:oak_leaves)
B(-3,21,1,minecraft:oak_leaves)
B(-3,22,1,minecraft:oak_log)
B(-3,23,1,minecraft:oak_leaves)
B(-3,25,1,minecraft:oak_leaves)
B(-3,27,1,minecraft:oak_leaves)
B(-3,17,2,minecraft:oak_log)
B(-3,18,2,minecraft:oak_leaves)
B(-3,21,2,minecraft:oak_leaves)
B(-3,22,2,minecraft:oak_leaves)
B(-3,27,2,minecraft:oak_log)
B(-3,21,3,minecraft:oak_leaves)
B(-3,22,3,minecraft:oak_log)
B(-3,23,3,minecraft:oak_leaves)
B(-3,27,3,minecraft:oak_log)
B(-3,28,3,minecraft:oak_leaves)
B(-3,15,4,minecraft:oak_leaves)
B(-3,16,4,minecraft:oak_leaves)
B(-3,22,4,minecraft:oak_leaves)
B(-3,27,4,minecraft:oak_leaves)
B(-3,28,4,minecraft:oak_log)
B(-3,29,4,minecraft:oak_leaves)
B(-3,16,5,minecraft:oak_leaves)
B(-3,28,5,minecraft:oak_leaves)
B(-3,16,6,minecraft:oak_leaves)
B(-3,16,7,minecraft:oak_leaves)
B(-2,24,-4,minecraft:oak_leaves)
B(-2,24,-3,minecraft:oak_leaves)
B(-2,24,-2,minecraft:oak_log)
B(-2,25,-2,minecraft:oak_leaves)
B(-2,29,-2,minecraft:oak_leaves)
B(-2,24,-1,minecraft:oak_log)
B(-2,29,-1,minecraft:oak_log)
B(-2,30,-1,minecraft:oak_leaves)
B(-2,22,0,minecraft:oak_leaves)
B(-2,25,0,minecraft:oak_leaves)
B(-2,29,0,minecraft:oak_leaves)
B(-2,31,0,minecraft:oak_leaves)
B(-2,32,0,minecraft:oak_leaves)
B(-2,33,0,minecraft:oak_leaves)
B(-2,17,1,minecraft:oak_log)
B(-2,33,1,minecraft:oak_leaves)
B(-2,20,2,minecraft:oak_log)
B(-2,21,2,minecraft:oak_log)
B(-2,26,2,minecraft:oak_log)
B(-2,29,2,minecraft:oak_leaves)
B(-2,15,3,minecraft:oak_leaves)
B(-2,22,3,minecraft:oak_leaves)
B(-2,27,3,minecraft:oak_leaves)
B(-2,29,3,minecraft:oak_leaves)
B(-2,15,4,minecraft:oak_log)
B(-2,16,4,minecraft:oak_leaves)
B(-2,28,4,minecraft:oak_leaves)
B(-2,15,5,minecraft:oak_leaves)
B(-2,16,5,minecraft:oak_leaves)
B(-2,27,5,minecraft:oak_leaves)
B(-2,28,5,minecraft:oak_leaves)
B(-2,16,6,minecraft:oak_leaves)
B(-1,24,-5,minecraft:oak_leaves)
B(-1,21,-4,minecraft:oak_leaves)
B(-1,24,-4,minecraft:oak_leaves)
B(-1,21,-3,minecraft:oak_leaves)
B(-1,24,-3,minecraft:oak_log)
B(-1,25,-3,minecraft:oak_leaves)
B(-1,28,-3,minecraft:oak_leaves)
B(-1,20,-2,minecraft:oak_leaves)
B(-1,21,-2,minecraft:oak_leaves)
B(-1,24,-2,minecraft:oak_leaves)
B(-1,28,-2,minecraft:oak_leaves)
B(-1,23,-1,minecraft:oak_log)
B(-1,29,-1,minecraft:oak_leaves)
B(-1,33,-1,minecraft:oak_leaves)
B(-1,0,0,minecraft:oak_log)
B(-1,1,0,minecraft:oak_log)
B(-1,2,0,minecraft:oak_log)
B(-1,3,0,minecraft:oak_log)
B(-1,29,0,minecraft:oak_log)
B(-1,31,0,minecraft:oak_log)
B(-1,33,0,minecraft:oak_leaves)
B(-1,34,0,minecraft:oak_leaves)
B(-1,17,1,minecraft:oak_log)
B(-1,19,1,minecraft:oak_log)
B(-1,31,1,minecraft:oak_leaves)
B(-1,32,1,minecraft:oak_leaves)
B(-1,33,1,minecraft:oak_leaves)
B(-1,22,2,minecraft:oak_leaves)
B(-1,26,2,minecraft:oak_log)
B(-1,29,2,minecraft:oak_log)
B(-1,30,2,minecraft:oak_leaves)
B(-1,33,2,minecraft:oak_leaves)
B(-1,15,3,minecraft:oak_leaves)
B(-1,21,3,minecraft:oak_leaves)
B(-1,22,3,minecraft:oak_log)
B(-1,23,3,minecraft:oak_leaves)
B(-1,27,3,minecraft:oak_log)
B(-1,28,3,minecraft:oak_leaves)
B(-1,29,3,minecraft:oak_leaves)
B(-1,30,3,minecraft:oak_leaves)
B(-1,15,4,minecraft:oak_log)
B(-1,16,4,minecraft:oak_leaves)
B(-1,22,4,minecraft:oak_leaves)
B(-1,27,4,minecraft:oak_leaves)
B(-1,28,4,minecraft:oak_leaves)
B(-1,15,5,minecraft:oak_leaves)
B(-1,28,5,minecraft:oak_leaves)
B(-1,16,6,minecraft:oak_leaves)
B(0,21,-4,minecraft:oak_leaves)
B(0,24,-4,minecraft:oak_leaves)
B(0,15,-3,minecraft:oak_leaves)
B(0,20,-3,minecraft:oak_leaves)
B(0,21,-3,minecraft:oak_leaves)
B(0,24,-3,minecraft:oak_leaves)
B(0,20,-2,minecraft:oak_log)
B(0,21,-2,minecraft:oak_leaves)
B(0,28,-2,minecraft:oak_leaves)
B(0,30,-2,minecraft:oak_leaves)
B(0,31,-2,minecraft:oak_leaves)
B(0,33,-2,minecraft:oak_leaves)
B(0,0,-1,minecraft:oak_log)
B(0,1,-1,minecraft:oak_log)
B(0,20,-1,minecraft:oak_leaves)
B(0,28,-1,minecraft:oak_log)
B(0,29,-1,minecraft:oak_leaves)
B(0,30,-1,minecraft:oak_log)
B(0,31,-1,minecraft:oak_leaves)
B(0,32,-1,minecraft:oak_leaves)
B(0,33,-1,minecraft:oak_leaves)
B(0,34,-1,minecraft:oak_leaves)
B(0,0,0,minecraft:oak_log)
B(0,1,0,minecraft:oak_log)
B(0,2,0,minecraft:oak_log)
B(0,3,0,minecraft:oak_log)
B(0,4,0,minecraft:oak_log)
B(0,5,0,minecraft:oak_log)
B(0,6,0,minecraft:oak_log)
B(0,7,0,minecraft:oak_log)
B(0,8,0,minecraft:oak_log)
B(0,9,0,minecraft:oak_log)
B(0,10,0,minecraft:oak_log)
B(0,11,0,minecraft:oak_log)
B(0,12,0,minecraft:oak_log)
B(0,13,0,minecraft:oak_log)
B(0,14,0,minecraft:oak_log)
B(0,15,0,minecraft:oak_log)
B(0,16,0,minecraft:oak_log)
B(0,17,0,minecraft:oak_log)
B(0,18,0,minecraft:oak_log)
B(0,19,0,minecraft:oak_log)
B(0,20,0,minecraft:oak_log)
B(0,21,0,minecraft:oak_log)
B(0,22,0,minecraft:oak_log)
B(0,23,0,minecraft:oak_log)
B(0,24,0,minecraft:oak_log)
B(0,25,0,minecraft:oak_log)
B(0,26,0,minecraft:oak_log)
B(0,27,0,minecraft:oak_log)
B(0,28,0,minecraft:oak_log)
B(0,29,0,minecraft:oak_log)
B(0,30,0,minecraft:oak_log)
B(0,31,0,minecraft:oak_log)
B(0,32,0,minecraft:oak_log)
B(0,33,0,minecraft:oak_log)
B(0,34,0,minecraft:oak_leaves)
B(0,0,1,minecraft:oak_log)
B(0,1,1,minecraft:oak_log)
B(0,2,1,minecraft:oak_log)
B(0,13,1,minecraft:oak_log)
B(0,14,1,minecraft:oak_log)
B(0,26,1,minecraft:oak_log)
B(0,29,1,minecraft:oak_log)
B(0,31,1,minecraft:oak_log)
B(0,32,1,minecraft:oak_leaves)
B(0,33,1,minecraft:oak_log)
B(0,34,1,minecraft:oak_leaves)
B(0,0,2,minecraft:oak_log)
B(0,14,2,minecraft:oak_log)
B(0,29,2,minecraft:oak_leaves)
B(0,32,2,minecraft:oak_leaves)
B(0,33,2,minecraft:oak_leaves)
B(0,15,3,minecraft:oak_log)
B(0,22,3,minecraft:oak_leaves)
B(0,27,3,minecraft:oak_leaves)
B(0,22,4,minecraft:oak_leaves)
B(0,28,4,minecraft:oak_leaves)
B(0,15,6,minecraft:oak_leaves)
B(1,15,-4,minecraft:oak_leaves)
B(1,15,-3,minecraft:oak_leaves)
B(1,21,-3,minecraft:oak_leaves)
B(1,15,-2,minecraft:oak_leaves)
B(1,28,-2,minecraft:oak_leaves)
B(1,19,-1,minecraft:oak_log)
B(1,20,-1,minecraft:oak_log)
B(1,28,-1,minecraft:oak_leaves)
B(1,32,-1,minecraft:oak_leaves)
B(1,0,0,minecraft:oak_log)
B(1,1,0,minecraft:oak_log)
B(1,24,0,minecraft:oak_log)
B(1,28,0,minecraft:oak_log)
B(1,31,0,minecraft:oak_leaves)
B(1,32,0,minecraft:oak_leaves)
B(1,33,0,minecraft:oak_leaves)
B(1,0,1,minecraft:oak_log)
B(1,14,1,minecraft:oak_log)
B(1,21,1,minecraft:oak_log)
B(1,26,1,minecraft:oak_leaves)
B(1,31,1,minecraft:oak_leaves)
B(1,26,2,minecraft:oak_leaves)
B(1,29,2,minecraft:oak_log)
B(1,30,2,minecraft:oak_leaves)
B(1,15,3,minecraft:oak_log)
B(1,26,3,minecraft:oak_leaves)
B(1,29,3,minecraft:oak_leaves)
B(1,29,4,minecraft:oak_leaves)
B(1,15,5,minecraft:oak_log)
B(1,15,6,minecraft:oak_log)
B(1,16,6,minecraft:oak_leaves)
B(1,16,7,minecraft:oak_leaves)
B(2,15,-4,minecraft:oak_leaves)
B(2,15,-3,minecraft:oak_leaves)
B(2,16,-3,minecraft:oak_leaves)
B(2,20,-3,minecraft:oak_leaves)
B(2,15,-2,minecraft:oak_log)
B(2,16,-2,minecraft:oak_leaves)
B(2,20,-2,minecraft:oak_log)
B(2,21,-2,minecraft:oak_leaves)
B(2,25,-2,minecraft:oak_leaves)
B(2,15,-1,minecraft:oak_log)
B(2,25,-1,minecraft:oak_leaves)
B(2,29,-1,minecraft:oak_leaves)
B(2,14,0,minecraft:oak_log)
B(2,25,0,minecraft:oak_log)
B(2,28,0,minecraft:oak_leaves)
B(2,29,0,minecraft:oak_log)
B(2,32,0,minecraft:oak_leaves)
B(2,25,1,minecraft:oak_log)
B(2,26,1,minecraft:oak_leaves)
B(2,29,1,minecraft:oak_leaves)
B(2,21,2,minecraft:oak_log)
B(2,25,2,minecraft:oak_leaves)
B(2,26,2,minecraft:oak_log)
B(2,27,2,minecraft:oak_leaves)
B(2,29,2,minecraft:oak_leaves)
B(2,26,3,minecraft:oak_leaves)
B(2,29,3,minecraft:oak_leaves)
B(2,15,4,minecraft:oak_log)
B(2,26,4,minecraft:oak_leaves)
B(2,16,5,minecraft:oak_leaves)
B(2,22,5,minecraft:oak_leaves)
B(2,15,6,minecraft:oak_leaves)
B(2,15,7,minecraft:oak_leaves)
B(3,20,-4,minecraft:oak_leaves)
B(3,15,-3,minecraft:oak_leaves)
B(3,20,-3,minecraft:oak_leaves)
B(3,21,-3,minecraft:oak_leaves)
B(3,25,-3,minecraft:oak_leaves)
B(3,15,-2,minecraft:oak_leaves)
B(3,20,-2,minecraft:oak_log)
B(3,21,-2,minecraft:oak_leaves)
B(3,25,-2,minecraft:oak_leaves)
B(3,26,-2,minecraft:oak_leaves)
B(3,29,-2,minecraft:oak_leaves)
B(3,20,-1,minecraft:oak_leaves)
B(3,25,-1,minecraft:oak_log)
B(3,26,-1,minecraft:oak_leaves)
B(3,29,-1,minecraft:oak_log)
B(3,30,-1,minecraft:oak_leaves)
B(3,14,0,minecraft:oak_log)
B(3,26,0,minecraft:oak_leaves)
B(3,29,0,minecraft:oak_leaves)
B(3,30,0,minecraft:oak_leaves)
B(3,14,1,minecraft:oak_leaves)
B(3,21,1,minecraft:oak_leaves)
B(3,25,1,minecraft:oak_log)
B(3,26,1,minecraft:oak_leaves)
B(3,29,1,minecraft:oak_log)
B(3,30,1,minecraft:oak_leaves)
B(3,14,2,minecraft:oak_leaves)
B(3,21,2,minecraft:oak_log)
B(3,25,2,minecraft:oak_leaves)
B(3,26,2,minecraft:oak_leaves)
B(3,27,2,minecraft:oak_leaves)
B(3,29,2,minecraft:oak_leaves)
B(3,21,3,minecraft:oak_log)
B(3,26,3,minecraft:oak_leaves)
B(3,16,4,minecraft:oak_leaves)
B(3,21,4,minecraft:oak_leaves)
B(3,22,4,minecraft:oak_leaves)
B(3,16,5,minecraft:oak_log)
B(3,17,5,minecraft:oak_leaves)
B(3,22,5,minecraft:oak_log)
B(3,23,5,minecraft:oak_leaves)
B(3,16,6,minecraft:oak_leaves)
B(3,22,6,minecraft:oak_leaves)
B(4,15,-3,minecraft:oak_leaves)
B(4,20,-3,minecraft:oak_leaves)
B(4,25,-3,minecraft:oak_leaves)
B(4,20,-2,minecraft:oak_leaves)
B(4,25,-2,minecraft:oak_leaves)
B(4,14,-1,minecraft:oak_leaves)
B(4,20,-1,minecraft:oak_leaves)
B(4,25,-1,minecraft:oak_leaves)
B(4,26,-1,minecraft:oak_leaves)
B(4,29,-1,minecraft:oak_leaves)
B(4,14,0,minecraft:oak_log)
B(4,21,0,minecraft:oak_leaves)
B(4,22,0,minecraft:oak_leaves)
B(4,26,0,minecraft:oak_leaves)
B(4,27,0,minecraft:oak_leaves)
B(4,30,0,minecraft:oak_leaves)
B(4,14,1,minecraft:oak_log)
B(4,15,1,minecraft:oak_leaves)
B(4,21,1,minecraft:oak_log)
B(4,22,1,minecraft:oak_leaves)
B(4,25,1,minecraft:oak_leaves)
B(4,26,1,minecraft:oak_log)
B(4,27,1,minecraft:oak_leaves)
B(4,29,1,minecraft:oak_leaves)
B(4,30,1,minecraft:oak_leaves)
B(4,14,2,minecraft:oak_leaves)
B(4,15,2,minecraft:oak_leaves)
B(4,21,2,minecraft:oak_leaves)
B(4,26,2,minecraft:oak_leaves)
B(4,27,2,minecraft:oak_leaves)
B(4,26,3,minecraft:oak_leaves)
B(4,21,4,minecraft:oak_log)
B(4,16,5,minecraft:oak_leaves)
B(4,17,5,minecraft:oak_leaves)
B(4,21,5,minecraft:oak_leaves)
B(4,22,5,minecraft:oak_leaves)
B(4,16,6,minecraft:oak_leaves)
B(4,22,6,minecraft:oak_leaves)
B(4,22,7,minecraft:oak_leaves)
B(5,25,-3,minecraft:oak_leaves)
B(5,13,-2,minecraft:oak_leaves)
B(5,20,-2,minecraft:oak_leaves)
B(5,25,-2,minecraft:oak_leaves)
B(5,13,-1,minecraft:oak_leaves)
B(5,22,-1,minecraft:oak_leaves)
B(5,13,0,minecraft:oak_log)
B(5,14,0,minecraft:oak_leaves)
B(5,21,0,minecraft:oak_leaves)
B(5,22,0,minecraft:oak_leaves)
B(5,13,1,minecraft:oak_leaves)
B(5,14,1,minecraft:oak_leaves)
B(5,21,1,minecraft:oak_log)
B(5,22,1,minecraft:oak_leaves)
B(5,23,1,minecraft:oak_leaves)
B(5,26,1,minecraft:oak_leaves)
B(5,27,1,minecraft:oak_leaves)
B(5,14,2,minecraft:oak_leaves)
B(5,21,2,minecraft:oak_leaves)
B(5,22,2,minecraft:oak_leaves)
B(5,26,2,minecraft:oak_leaves)
B(5,27,2,minecraft:oak_leaves)
B(5,22,3,minecraft:oak_leaves)
B(5,27,3,minecraft:oak_leaves)
B(5,21,4,minecraft:oak_leaves)
B(5,22,4,minecraft:oak_log)
B(5,23,4,minecraft:oak_leaves)
B(5,22,5,minecraft:oak_leaves)
B(5,22,6,minecraft:oak_leaves)
B(6,13,-1,minecraft:oak_leaves)
B(6,22,-1,minecraft:oak_leaves)
B(6,13,0,minecraft:oak_leaves)
B(6,22,0,minecraft:oak_log)
B(6,23,0,minecraft:oak_leaves)
B(6,13,1,minecraft:oak_leaves)
B(6,21,1,minecraft:oak_leaves)
B(6,22,1,minecraft:oak_leaves)
B(6,23,1,minecraft:oak_leaves)
B(6,26,1,minecraft:oak_leaves)
B(6,22,2,minecraft:oak_log)
B(6,23,2,minecraft:oak_leaves)
B(6,27,2,minecraft:oak_leaves)
B(6,22,3,minecraft:oak_leaves)
B(6,22,4,minecraft:oak_leaves)
B(6,23,4,minecraft:oak_leaves)
B(6,22,5,minecraft:oak_leaves)
B(7,13,-1,minecraft:oak_leaves)
B(7,22,0,minecraft:oak_leaves)
B(7,22,1,minecraft:oak_leaves)
B(7,22,2,minecraft:oak_leaves)
B(7,22,5,minecraft:oak_leaves)
B(8,22,1,minecraft:oak_leaves)

#######################################################################
# +-----------------------------------------------------------------+ #
# |                            BO3 checks                           | #
# +-----------------------------------------------------------------+ #
#######################################################################

# Require a condition at a certain location in order for the BO3 to be spawned.
# BlockCheck(x,y,z,BlockName[,BlockName[,...]]) - one of the blocks must be at the location
# BlockCheckNot(x,y,z,BlockName[,BlockName[,...]]) - all the blocks must not be at the location
# LightCheck(x,y,z,minLightLevel,maxLightLevel) - light must be between min and max (inclusive)
# ModCheck(ModName[,ModName[,...]]) - all the mods listed must be loaded
# ModCheckNot(ModName[,ModName[,...]]) - all the mods listed must not be loaded

# You can use "Solid" as a BlockName for matching all solid blocks or "All" to match all blocks that aren't air.

# Examples:
#   BlockCheck(0,-1,0,GRASS,DIRT)  Require grass or dirt just below the object
#   BlockCheck(0,-1,0,Solid)		Require any solid block just below the object
#   BlockCheck(0,-1,0,WOOL)		Require any type of wool just below the object
#   BlockCheck(0,-1,0,WOOL:0)	  Require white wool just below the object
#   BlockCheckNot(0,-1,0,WOOL:0)	Require that there is no white wool below the object
#   LightCheck(0,0,0,0,1)		  Require almost complete darkness just below the object
BlockCheck(0,-1,0,minecraft:grass_block,minecraft:dirt)
BlockCheck(1,-1,0,Solid)
BlockCheck(1,-1,-1,Solid)
BlockCheck(1,-1,1,Solid)
BlockCheck(0,-1,1,Solid)
BlockCheck(0,-1,-1,Solid)
BlockCheck(-1,-1,1,Solid)
BlockCheck(-1,-1,0,Solid)
BlockCheck(-1,-1,-1,Solid)
BlockCheck(2,-1,2,Solid)
BlockCheck(2,-1,1,Solid)
BlockCheck(2,-1,0,Solid)
BlockCheck(2,-1,-1,Solid)
BlockCheck(2,-1,-2,Solid)
BlockCheck(1,-1,2,Solid)
BlockCheck(1,-1,-2,Solid)
BlockCheck(0,-1,2,Solid)
BlockCheck(0,-1,-2,Solid)
BlockCheck(-1,-1,2,Solid)
BlockCheck(-1,-1,-2,Solid)
BlockCheck(-2,-1,2,Solid)
BlockCheck(-2,-1,1,Solid)
BlockCheck(-2,-1,0,Solid)
BlockCheck(-2,-1,-1,Solid)
BlockCheck(-2,-1,-2,Solid)

#######################################################################
# +-----------------------------------------------------------------+ #
# |                             Branches                            | #
# +-----------------------------------------------------------------+ #
#######################################################################

# Branches are child-BO3's that spawn if this BO3 is configured to spawn as a
# CustomStructure resource in a biome config. Branches can have branches,
# making complex structures possible. See the wiki for more details.

# Regular Branches spawn each branch with an independent chance of spawning.
# Branch(x,y,z,branchName,rotation,chance[,anotherBranchName,rotation,chance[,...]][IndividualChance])
# branchName - name of the object to spawn.
# rotation - NORTH, SOUTH, EAST or WEST.
# IndividualChance - The chance each branch has to spawn, assumed to be 100 when left blank
# isRequiredBranch - If this is set to true then at least one of the branches in this BO3 must spawn at these x,y,z coordinates. If no branch can spawn there then this BO3 fails to spawn and its branch is rolled back.
# isRequiredBranch:true branches must spawn or the current branch is rolled back entirely. This is useful for grouping BO3's that must spawn together, for instance a single room made of multiple BO3's/branches.
# If all parts of the room are connected together via isRequiredBranch:true branches then either the entire room will spawns or no part of it will spawn.
# *Note: When isRequiredBranch:true only one BO3 can be added per Branch() and it will automatically have a rarity of 100.0.
# isRequiredBranch:false branches are used to make optional parts of structures, for instance the middle section of a tunnel that has a beginning, middle and end BO3/branch and can have a variable length by repeating the middle BO3/branch.
# By making the start and end branches isRequiredBranch:true and the middle branch isRequiredbranch:false you can make it so that either:
# A. A tunnel spawns with at least a beginning and end branch
# B. A tunnel spawns with a beginning and end branch and as many middle branches as will fit in the available space.
# C. No tunnel spawns at all because there wasn't enough space to spawn at least a beginning and end branch.
# branchDepth - When creating a chain of branches that contains optional (isRequiredBranch:false) branches branch depth is configured for the first BO3 in the chain to determine the maximum length of the chain.
# branchDepth - 1 is inherited by each isRequiredBranch:false branch in the chain. When branchDepth is zero isRequiredBranch:false branches cannot spawn and the chain ends. In the case of the tunnel this means the last middle branch would be
# rolled back and an IsRequiredBranch:true end branch could be spawned in its place to make sure the tunnel has a proper ending.
# Instead of inheriting branchDepth - 1 from the parent branchDepth can be overridden by child branches if it is set higher than 0 (the default value).
# isRequiredBranch:true branches do inherit branchDepth and pass it on to their own branches, however they cannot be prevented from spawning by it and also don't subtract 1 from branchDepth when inheriting it.

# Weighted Branches spawn branches with a dependent chance of spawning.
# WeightedBranch(x,y,z,branchName,rotation,chance[,anotherBranchName,rotation,chance[,...]][MaxChanceOutOf])
# *Note: isRequiredBranch must be set to false. It is not possible to use isRequiredBranch:true with WeightedBranch() since isRequired:true branches must spawn and automatically have a rarity of 100.0.
# MaxChanceOutOf - The chance all branches have to spawn out of, assumed to be 100 when left blank

#######################################################################
# +-----------------------------------------------------------------+ #
# |                             Entities                            | #
# +-----------------------------------------------------------------+ #
#######################################################################

# Forge only (this may have changed, check for updates).
# An EntityFunction spawns an entity instead of a block. The entity is spawned only once when the BO3 is spawned.
# Entities are persistent by default so they don't de-spawn when no player is near, they are only unloaded.
# Usage: Entity(x,y,z,entityName,groupSize,NameTagOrNBTFileName) or Entity(x,y,z,mobName,groupSize)
# Use /otg entities to get a list of entities that can be used as entityName, this includes entities added by other mods and non-living entities.
# NameTagOrNBTFileName can be either a nametag for the mob or an .txt file with nbt data (such as myentityinfo.txt).
# In the text file you can use the same mob spawning parameters used with the /summon command to equip the
# entity and give it custom attributes etc. You can copy the DATA part of a summon command including surrounding 
# curly braces to a .txt file, for instance for: "/summon Skeleton x y z {DATA}"
# *Note: Unlike Block(), for Entity() .nbt files don't work, only .txt files work.
