
#######################################################################
# +-----------------------------------------------------------------+ #
# |                            BO4 object                           | #
# +-----------------------------------------------------------------+ #
#######################################################################

Author: Unknown

Description: No description given

SettingsMode: WriteWithoutComments


#######################################################################
# +-----------------------------------------------------------------+ #
# |                          Main settings                          | #
# +-----------------------------------------------------------------+ #
#######################################################################

FixedRotation: 

Frequency: 0

SpawnHeight: highestBlock

UseCenterForHighestBlock: true

##############################
# Height Limits for the BO4. #
##############################

MinHeight: 0

MaxHeight: 255

InheritBO3: 

InheritBO3Rotation: NORTH

OverrideChildSettings: true

OverrideParentHeight: false

CanOverride: false

BranchFrequency: 0

BranchFrequencyGroup: 

MustBeBelowOther: false

MustBeInside: 

CannotBeInside: 

ReplacesBO3: 

MustBeInsideWorldBorders: false

CanSpawnOnWater: true

SpawnOnWaterOnly: false

SpawnUnderWater: false

SpawnAtWaterLevel: false

HeightOffset: 0

RemoveAir: true

ReplaceAbove: 

ReplaceBelow: 

ReplaceWithBiomeBlocks: true

ReplaceWithSurfaceBlock: GRASS

ReplaceWithGroundBlock: DIRT

ReplaceWithStoneBlock: STONE

SmoothRadius: 0

SmoothHeightOffset: 0

SmoothStartTop: false

SmoothStartWood: false

SmoothingSurfaceBlock: 

SmoothingGroundBlock: 

BO3Group: 

IsSpawnPoint: false

DoReplaceBlocks: true


#######################################################################
# +-----------------------------------------------------------------+ #
# |                              Blocks                             | #
# +-----------------------------------------------------------------+ #
#######################################################################

B(-8,2,-7,minecraft:stone)
B(-8,3,-7,minecraft:cobblestone)
B(-8,4,-7,minecraft:stone)
B(-8,5,-7,minecraft:granite)
B(-8,6,-7,minecraft:granite)
B(-8,7,-7,minecraft:stone)
B(-8,8,-7,minecraft:stone)
B(-8,9,-7,minecraft:stone)
B(-8,10,-7,minecraft:stone)
B(-8,11,-7,minecraft:stone)
B(-8,12,-7,minecraft:stone)
B(-8,13,-7,minecraft:stone)
B(-8,14,-7,minecraft:stone)
B(-8,15,-7,minecraft:stone)
B(-8,16,-7,minecraft:dirt)
B(-8,17,-7,minecraft:dirt)
B(-8,18,-7,minecraft:dirt)
B(-8,19,-7,minecraft:water)
B(-8,20,-7,minecraft:water[level=4])
B(-8,4,-6,minecraft:cobblestone)
B(-8,5,-6,minecraft:cobblestone)
B(-8,6,-6,minecraft:cobblestone)
B(-8,7,-6,minecraft:cobblestone)
B(-8,8,-6,minecraft:stone)
B(-8,9,-6,minecraft:stone)
B(-8,10,-6,minecraft:stone)
B(-8,11,-6,minecraft:stone)
B(-8,12,-6,minecraft:stone)
B(-8,13,-6,minecraft:stone)
B(-8,14,-6,minecraft:stone)
B(-8,15,-6,minecraft:stone)
B(-8,16,-6,minecraft:dirt)
B(-8,17,-6,minecraft:dirt)
B(-8,18,-6,minecraft:dirt)
B(-8,19,-6,minecraft:water)
B(-8,20,-6,minecraft:water[level=5])
B(-8,9,-5,minecraft:cobblestone)
B(-8,10,-5,minecraft:cobblestone)
B(-8,11,-5,minecraft:cobblestone)
B(-8,12,-5,minecraft:cobblestone)
B(-8,13,-5,minecraft:cobblestone)
B(-8,14,-5,minecraft:stone)
B(-8,15,-5,minecraft:stone)
B(-8,16,-5,minecraft:dirt)
B(-8,17,-5,minecraft:dirt)
B(-8,18,-5,minecraft:dirt)
B(-8,19,-5,minecraft:water)
B(-8,13,-4,minecraft:stone)
B(-8,14,-4,minecraft:stone)
B(-8,15,-4,minecraft:cobblestone)
B(-8,16,-4,minecraft:cobblestone)
B(-8,17,-4,minecraft:dirt)
B(-8,18,-4,minecraft:dirt)
B(-8,19,-4,minecraft:grass_block)
B(-8,15,-3,minecraft:stone)
B(-8,16,-3,minecraft:stone)
B(-8,17,-3,minecraft:dirt)
B(-8,18,-3,minecraft:coarse_dirt)
B(-8,19,-3,minecraft:water)
B(-8,16,-2,minecraft:stone)
B(-8,17,-2,minecraft:dirt)
B(-8,18,-2,minecraft:dirt)
B(-8,19,-2,minecraft:grass_block)
B(-8,18,-1,minecraft:dirt)
B(-8,19,-1,minecraft:grass_block)
B(-8,18,0,minecraft:dirt)
B(-8,19,0,minecraft:grass_block)
B(-8,19,1,minecraft:grass_block)
B(-7,1,-7,minecraft:stone)
B(-7,2,-7,minecraft:stone)
B(-7,3,-7,minecraft:cobblestone)
B(-7,4,-7,minecraft:cobblestone)
B(-7,5,-7,minecraft:cobblestone)
B(-7,6,-7,minecraft:granite)
B(-7,7,-7,minecraft:granite)
B(-7,8,-7,minecraft:stone)
B(-7,9,-7,minecraft:stone)
B(-7,10,-7,minecraft:stone)
B(-7,11,-7,minecraft:stone)
B(-7,12,-7,minecraft:stone)
B(-7,13,-7,minecraft:stone)
B(-7,14,-7,minecraft:stone)
B(-7,15,-7,minecraft:stone)
B(-7,16,-7,minecraft:stone)
B(-7,17,-7,minecraft:dirt)
B(-7,18,-7,minecraft:dirt)
B(-7,19,-7,minecraft:water)
B(-7,20,-7,minecraft:water[level=3])
B(-7,4,-6,minecraft:cobblestone)
B(-7,5,-6,minecraft:cobblestone)
B(-7,6,-6,minecraft:cobblestone)
B(-7,7,-6,minecraft:cobblestone)
B(-7,8,-6,minecraft:cobblestone)
B(-7,9,-6,minecraft:stone)
B(-7,10,-6,minecraft:stone)
B(-7,11,-6,minecraft:stone)
B(-7,12,-6,minecraft:stone)
B(-7,13,-6,minecraft:stone)
B(-7,14,-6,minecraft:stone)
B(-7,15,-6,minecraft:stone)
B(-7,16,-6,minecraft:stone)
B(-7,17,-6,minecraft:dirt)
B(-7,18,-6,minecraft:dirt)
B(-7,19,-6,minecraft:water)
B(-7,20,-6,minecraft:water[level=4])
B(-7,9,-5,minecraft:cobblestone)
B(-7,10,-5,minecraft:cobblestone)
B(-7,11,-5,minecraft:cobblestone)
B(-7,12,-5,minecraft:cobblestone)
B(-7,13,-5,minecraft:stone)
B(-7,14,-5,minecraft:stone)
B(-7,15,-5,minecraft:stone)
B(-7,16,-5,minecraft:stone)
B(-7,17,-5,minecraft:dirt)
B(-7,18,-5,minecraft:dirt)
B(-7,19,-5,minecraft:water)
B(-7,11,-4,minecraft:cobblestone)
B(-7,12,-4,minecraft:stone)
B(-7,13,-4,minecraft:stone)
B(-7,14,-4,minecraft:stone)
B(-7,15,-4,minecraft:stone)
B(-7,16,-4,minecraft:stone)
B(-7,17,-4,minecraft:dirt)
B(-7,18,-4,minecraft:dirt)
B(-7,19,-4,minecraft:grass_block)
B(-7,13,-3,minecraft:stone)
B(-7,14,-3,minecraft:stone)
B(-7,15,-3,minecraft:stone)
B(-7,16,-3,minecraft:stone)
B(-7,17,-3,minecraft:dirt)
B(-7,18,-3,minecraft:dirt)
B(-7,19,-3,minecraft:grass_block)
B(-7,15,-2,minecraft:stone)
B(-7,16,-2,minecraft:stone)
B(-7,17,-2,minecraft:dirt)
B(-7,18,-2,minecraft:dirt)
B(-7,19,-2,minecraft:dirt)
B(-7,20,-2,minecraft:grass_block)
B(-7,17,-1,minecraft:stone)
B(-7,18,-1,minecraft:dirt)
B(-7,19,-1,minecraft:dirt)
B(-7,20,-1,minecraft:dirt)
B(-7,21,-1,minecraft:grass_block)
B(-7,18,0,minecraft:dirt)
B(-7,19,0,minecraft:dirt)
B(-7,20,0,minecraft:grass_block)
B(-7,19,1,minecraft:grass_block)
B(-6,4,-7,minecraft:cobblestone)
B(-6,5,-7,minecraft:cobblestone)
B(-6,6,-7,minecraft:stone)
B(-6,7,-7,minecraft:stone)
B(-6,8,-7,minecraft:cobblestone)
B(-6,9,-7,minecraft:stone)
B(-6,10,-7,minecraft:stone)
B(-6,11,-7,minecraft:stone)
B(-6,12,-7,minecraft:stone)
B(-6,13,-7,minecraft:stone)
B(-6,14,-7,minecraft:stone)
B(-6,15,-7,minecraft:stone)
B(-6,16,-7,minecraft:stone)
B(-6,17,-7,minecraft:stone)
B(-6,18,-7,minecraft:dirt)
B(-6,19,-7,minecraft:water)
B(-6,20,-7,minecraft:water[level=2])
B(-6,6,-6,minecraft:cobblestone)
B(-6,7,-6,minecraft:stone)
B(-6,8,-6,minecraft:stone)
B(-6,9,-6,minecraft:cobblestone)
B(-6,10,-6,minecraft:cobblestone)
B(-6,11,-6,minecraft:stone)
B(-6,12,-6,minecraft:stone)
B(-6,13,-6,minecraft:stone)
B(-6,14,-6,minecraft:stone)
B(-6,15,-6,minecraft:stone)
B(-6,16,-6,minecraft:stone)
B(-6,17,-6,minecraft:stone)
B(-6,18,-6,minecraft:dirt)
B(-6,19,-6,minecraft:water)
B(-6,7,-5,minecraft:cobblestone)
B(-6,8,-5,minecraft:cobblestone)
B(-6,9,-5,minecraft:cobblestone)
B(-6,10,-5,minecraft:cobblestone)
B(-6,11,-5,minecraft:cobblestone)
B(-6,12,-5,minecraft:stone)
B(-6,13,-5,minecraft:stone)
B(-6,14,-5,minecraft:stone)
B(-6,15,-5,minecraft:stone)
B(-6,16,-5,minecraft:stone)
B(-6,17,-5,minecraft:stone)
B(-6,18,-5,minecraft:dirt)
B(-6,19,-5,minecraft:coarse_dirt)
B(-6,9,-4,minecraft:cobblestone)
B(-6,10,-4,minecraft:cobblestone)
B(-6,11,-4,minecraft:cobblestone)
B(-6,12,-4,minecraft:stone)
B(-6,13,-4,minecraft:stone)
B(-6,14,-4,minecraft:stone)
B(-6,15,-4,minecraft:stone)
B(-6,16,-4,minecraft:stone)
B(-6,17,-4,minecraft:dirt)
B(-6,18,-4,minecraft:dirt)
B(-6,19,-4,minecraft:grass_block)
B(-6,12,-3,minecraft:stone)
B(-6,13,-3,minecraft:stone)
B(-6,14,-3,minecraft:stone)
B(-6,15,-3,minecraft:stone)
B(-6,16,-3,minecraft:stone)
B(-6,17,-3,minecraft:dirt)
B(-6,18,-3,minecraft:dirt)
B(-6,19,-3,minecraft:dirt)
B(-6,20,-3,minecraft:grass_block)
B(-6,15,-2,minecraft:stone)
B(-6,16,-2,minecraft:stone)
B(-6,17,-2,minecraft:dirt)
B(-6,18,-2,minecraft:dirt)
B(-6,19,-2,minecraft:dirt)
B(-6,20,-2,minecraft:grass_block)
B(-6,17,-1,minecraft:dirt)
B(-6,18,-1,minecraft:dirt)
B(-6,19,-1,minecraft:dirt)
B(-6,20,-1,minecraft:dirt)
B(-6,21,-1,minecraft:coarse_dirt)
B(-6,18,0,minecraft:dirt)
B(-6,19,0,minecraft:dirt)
B(-6,20,0,minecraft:grass_block)
B(-6,19,1,minecraft:dirt)
B(-6,20,1,minecraft:coarse_dirt)
B(-5,9,-7,minecraft:stone)
B(-5,10,-7,minecraft:stone)
B(-5,11,-7,minecraft:stone)
B(-5,12,-7,minecraft:cobblestone)
B(-5,13,-7,minecraft:cobblestone)
B(-5,14,-7,minecraft:stone)
B(-5,15,-7,minecraft:stone)
B(-5,16,-7,minecraft:stone)
B(-5,17,-7,minecraft:stone)
B(-5,18,-7,minecraft:dirt)
B(-5,19,-7,minecraft:water)
B(-5,20,-7,minecraft:water[level=1])
B(-5,10,-6,minecraft:cobblestone)
B(-5,11,-6,minecraft:cobblestone)
B(-5,12,-6,minecraft:cobblestone)
B(-5,13,-6,minecraft:cobblestone)
B(-5,14,-6,minecraft:cobblestone)
B(-5,15,-6,minecraft:stone)
B(-5,16,-6,minecraft:stone)
B(-5,17,-6,minecraft:stone)
B(-5,18,-6,minecraft:dirt)
B(-5,19,-6,minecraft:water)
B(-5,20,-6,minecraft:water[level=2])
B(-5,9,-5,minecraft:cobblestone)
B(-5,10,-5,minecraft:cobblestone)
B(-5,11,-5,minecraft:cobblestone)
B(-5,12,-5,minecraft:cobblestone)
B(-5,13,-5,minecraft:cobblestone)
B(-5,14,-5,minecraft:stone)
B(-5,15,-5,minecraft:stone)
B(-5,16,-5,minecraft:stone)
B(-5,17,-5,minecraft:stone)
B(-5,18,-5,minecraft:dirt)
B(-5,19,-5,minecraft:coarse_dirt)
B(-5,10,-4,minecraft:cobblestone)
B(-5,11,-4,minecraft:cobblestone)
B(-5,12,-4,minecraft:cobblestone)
B(-5,13,-4,minecraft:stone)
B(-5,14,-4,minecraft:stone)
B(-5,15,-4,minecraft:stone)
B(-5,16,-4,minecraft:stone)
B(-5,17,-4,minecraft:stone)
B(-5,18,-4,minecraft:dirt)
B(-5,19,-4,minecraft:dirt)
B(-5,20,-4,minecraft:grass_block)
B(-5,11,-3,minecraft:stone)
B(-5,12,-3,minecraft:stone)
B(-5,13,-3,minecraft:stone)
B(-5,14,-3,minecraft:stone)
B(-5,15,-3,minecraft:stone)
B(-5,16,-3,minecraft:stone)
B(-5,17,-3,minecraft:stone)
B(-5,18,-3,minecraft:dirt)
B(-5,19,-3,minecraft:dirt)
B(-5,20,-3,minecraft:grass_block)
B(-5,15,-2,minecraft:stone)
B(-5,16,-2,minecraft:stone)
B(-5,17,-2,minecraft:stone)
B(-5,18,-2,minecraft:dirt)
B(-5,19,-2,minecraft:dirt)
B(-5,20,-2,minecraft:grass_block)
B(-5,17,-1,minecraft:dirt)
B(-5,18,-1,minecraft:dirt)
B(-5,19,-1,minecraft:dirt)
B(-5,20,-1,minecraft:dirt)
B(-5,21,-1,minecraft:stone)
B(-5,18,0,minecraft:dirt)
B(-5,19,0,minecraft:dirt)
B(-5,20,0,minecraft:coarse_dirt)
B(-5,21,0,minecraft:coarse_dirt)
B(-4,13,-7,minecraft:cobblestone)
B(-4,14,-7,minecraft:cobblestone)
B(-4,15,-7,minecraft:cobblestone)
B(-4,16,-7,minecraft:stone)
B(-4,17,-7,minecraft:stone)
B(-4,18,-7,minecraft:dirt)
B(-4,19,-7,minecraft:dirt)
B(-4,20,-7,minecraft:water)
B(-4,13,-6,minecraft:cobblestone)
B(-4,14,-6,minecraft:cobblestone)
B(-4,15,-6,minecraft:cobblestone)
B(-4,16,-6,minecraft:stone)
B(-4,17,-6,minecraft:stone)
B(-4,18,-6,minecraft:dirt)
B(-4,19,-6,minecraft:grass_block)
B(-4,20,-6,minecraft:water[level=1])
B(-4,11,-5,minecraft:cobblestone)
B(-4,12,-5,minecraft:cobblestone)
B(-4,13,-5,minecraft:cobblestone)
B(-4,14,-5,minecraft:cobblestone)
B(-4,15,-5,minecraft:cobblestone)
B(-4,16,-5,minecraft:stone)
B(-4,17,-5,minecraft:stone)
B(-4,18,-5,minecraft:dirt)
B(-4,19,-5,minecraft:dirt)
B(-4,20,-5,minecraft:grass_block)
B(-4,11,-4,minecraft:cobblestone)
B(-4,12,-4,minecraft:cobblestone)
B(-4,13,-4,minecraft:cobblestone)
B(-4,14,-4,minecraft:cobblestone)
B(-4,15,-4,minecraft:stone)
B(-4,16,-4,minecraft:stone)
B(-4,17,-4,minecraft:stone)
B(-4,18,-4,minecraft:dirt)
B(-4,19,-4,minecraft:dirt)
B(-4,20,-4,minecraft:grass_block)
B(-4,13,-3,minecraft:cobblestone)
B(-4,14,-3,minecraft:stone)
B(-4,15,-3,minecraft:stone)
B(-4,16,-3,minecraft:stone)
B(-4,17,-3,minecraft:stone)
B(-4,18,-3,minecraft:stone)
B(-4,19,-3,minecraft:dirt)
B(-4,20,-3,minecraft:grass_block)
B(-4,16,-2,minecraft:stone)
B(-4,17,-2,minecraft:dirt)
B(-4,18,-2,minecraft:dirt)
B(-4,19,-2,minecraft:dirt)
B(-4,20,-2,minecraft:dirt)
B(-4,21,-2,minecraft:dirt)
B(-4,22,-2,minecraft:grass_block)
B(-4,17,-1,minecraft:dirt)
B(-4,18,-1,minecraft:dirt)
B(-4,19,-1,minecraft:dirt)
B(-4,20,-1,minecraft:dirt)
B(-4,21,-1,minecraft:dirt)
B(-4,22,-1,minecraft:coarse_dirt)
B(-4,19,0,minecraft:dirt)
B(-4,20,0,minecraft:grass_block)
B(-4,19,1,minecraft:grass_block)
B(-3,15,-7,minecraft:cobblestone)
B(-3,16,-7,minecraft:stone)
B(-3,17,-7,minecraft:stone)
B(-3,18,-7,minecraft:dirt)
B(-3,19,-7,minecraft:grass_block)
B(-3,20,-7,minecraft:water[level=1])
B(-3,16,-6,minecraft:stone)
B(-3,17,-6,minecraft:stone)
B(-3,18,-6,minecraft:dirt)
B(-3,19,-6,minecraft:dirt)
B(-3,20,-6,minecraft:grass_block)
B(-3,15,-5,minecraft:stone)
B(-3,16,-5,minecraft:stone)
B(-3,17,-5,minecraft:stone)
B(-3,18,-5,minecraft:stone)
B(-3,19,-5,minecraft:dirt)
B(-3,20,-5,minecraft:grass_block)
B(-3,14,-4,minecraft:cobblestone)
B(-3,15,-4,minecraft:stone)
B(-3,16,-4,minecraft:stone)
B(-3,17,-4,minecraft:stone)
B(-3,18,-4,minecraft:stone)
B(-3,19,-4,minecraft:dirt)
B(-3,20,-4,minecraft:grass_block)
B(-3,15,-3,minecraft:stone)
B(-3,16,-3,minecraft:cobblestone)
B(-3,17,-3,minecraft:dirt)
B(-3,18,-3,minecraft:dirt)
B(-3,19,-3,minecraft:dirt)
B(-3,20,-3,minecraft:grass_block)
B(-3,17,-2,minecraft:dirt)
B(-3,18,-2,minecraft:dirt)
B(-3,19,-2,minecraft:dirt)
B(-3,20,-2,minecraft:dirt)
B(-3,21,-2,minecraft:grass_block)
B(-3,18,-1,minecraft:dirt)
B(-3,19,-1,minecraft:dirt)
B(-3,20,-1,minecraft:grass_block)
B(-3,19,0,minecraft:dirt)
B(-3,20,0,minecraft:grass_block)
B(-2,17,-7,minecraft:stone)
B(-2,18,-7,minecraft:dirt)
B(-2,19,-7,minecraft:dirt)
B(-2,20,-7,minecraft:grass_block)
B(-2,17,-6,minecraft:stone)
B(-2,18,-6,minecraft:dirt)
B(-2,19,-6,minecraft:dirt)
B(-2,20,-6,minecraft:grass_block)
B(-2,17,-5,minecraft:stone)
B(-2,18,-5,minecraft:dirt)
B(-2,19,-5,minecraft:dirt)
B(-2,20,-5,minecraft:grass_block)
B(-2,17,-4,minecraft:stone)
B(-2,18,-4,minecraft:stone)
B(-2,19,-4,minecraft:stone)
B(-2,20,-4,minecraft:grass_block)
B(-2,18,-3,minecraft:dirt)
B(-2,19,-3,minecraft:dirt)
B(-2,20,-3,minecraft:grass_block)
B(-2,17,-2,minecraft:dirt)
B(-2,18,-2,minecraft:dirt)
B(-2,19,-2,minecraft:dirt)
B(-2,20,-2,minecraft:grass_block)
B(-2,19,-1,minecraft:grass_block)
B(-1,17,-7,minecraft:dirt)
B(-1,18,-7,minecraft:dirt)
B(-1,19,-7,minecraft:dirt)
B(-1,20,-7,minecraft:dirt)
B(-1,21,-7,minecraft:grass_block)
B(-1,17,-6,minecraft:dirt)
B(-1,18,-6,minecraft:dirt)
B(-1,19,-6,minecraft:dirt)
B(-1,20,-6,minecraft:grass_block)
B(-1,18,-5,minecraft:dirt)
B(-1,19,-5,minecraft:dirt)
B(-1,20,-5,minecraft:grass_block)
B(-1,18,-4,minecraft:dirt)
B(-1,19,-4,minecraft:dirt)
B(-1,20,-4,minecraft:grass_block)
B(-1,18,-3,minecraft:dirt)
B(-1,19,-3,minecraft:dirt)
B(-1,20,-3,minecraft:grass_block)
B(-1,18,-2,minecraft:grass_block)
B(0,18,-7,minecraft:dirt)
B(0,19,-7,minecraft:dirt)
B(0,20,-7,minecraft:dirt)
B(0,21,-7,minecraft:grass_block)
B(0,18,-6,minecraft:dirt)
B(0,19,-6,minecraft:dirt)
B(0,20,-6,minecraft:grass_block)
B(0,19,-5,minecraft:dirt)
B(0,20,-5,minecraft:grass_block)
B(0,19,-4,minecraft:dirt)
B(0,20,-4,minecraft:grass_block)
B(0,19,-3,minecraft:grass_block)
B(1,20,-7,minecraft:grass_block)
B(1,20,-6,minecraft:grass_block)
B(1,20,-5,minecraft:grass_block)

#######################################################################
# +-----------------------------------------------------------------+ #
# |                             Branches                            | #
# +-----------------------------------------------------------------+ #
#######################################################################


#######################################################################
# +-----------------------------------------------------------------+ #
# |                             Entities                            | #
# +-----------------------------------------------------------------+ #
#######################################################################

