
#######################################################################
# +-----------------------------------------------------------------+ #
# |                            BO4 object                           | #
# +-----------------------------------------------------------------+ #
#######################################################################

Author: Unknown

Description: No description given

SettingsMode: WriteWithoutComments


#######################################################################
# +-----------------------------------------------------------------+ #
# |                          Main settings                          | #
# +-----------------------------------------------------------------+ #
#######################################################################

FixedRotation: 

Frequency: 0

SpawnHeight: highestBlock

UseCenterForHighestBlock: true

##############################
# Height Limits for the BO4. #
##############################

MinHeight: 0

MaxHeight: 255

InheritBO3: 

InheritBO3Rotation: NORTH

OverrideChildSettings: true

OverrideParentHeight: false

CanOverride: false

BranchFrequency: 0

BranchFrequencyGroup: 

MustBeBelowOther: false

MustBeInside: 

CannotBeInside: 

ReplacesBO3: 

MustBeInsideWorldBorders: false

CanSpawnOnWater: true

SpawnOnWaterOnly: false

SpawnUnderWater: false

SpawnAtWaterLevel: false

HeightOffset: 0

RemoveAir: true

ReplaceAbove: 

ReplaceBelow: 

ReplaceWithBiomeBlocks: true

ReplaceWithSurfaceBlock: GRASS

ReplaceWithGroundBlock: DIRT

ReplaceWithStoneBlock: STONE

SmoothRadius: 0

SmoothHeightOffset: 0

SmoothStartTop: false

SmoothStartWood: false

SmoothingSurfaceBlock: 

SmoothingGroundBlock: 

BO3Group: 

IsSpawnPoint: false

DoReplaceBlocks: true


#######################################################################
# +-----------------------------------------------------------------+ #
# |                              Blocks                             | #
# +-----------------------------------------------------------------+ #
#######################################################################

B(-8,19,-1,minecraft:dirt)
B(-8,20,-1,minecraft:grass_block)
B(-8,18,0,minecraft:dirt)
B(-8,19,0,minecraft:dirt)
B(-8,20,0,minecraft:dirt)
B(-8,21,0,minecraft:dirt)
B(-8,22,0,minecraft:dirt)
B(-8,23,0,minecraft:stone)
B(-8,18,1,minecraft:dirt)
B(-8,19,1,minecraft:dirt)
B(-8,20,1,minecraft:dirt)
B(-8,21,1,minecraft:dirt)
B(-8,22,1,minecraft:coarse_dirt)
B(-8,17,2,minecraft:stone)
B(-8,18,2,minecraft:dirt)
B(-8,19,2,minecraft:dirt)
B(-8,20,2,minecraft:dirt)
B(-8,21,2,minecraft:dirt)
B(-8,22,2,minecraft:grass_block)
B(-8,16,3,minecraft:cobblestone)
B(-8,17,3,minecraft:cobblestone)
B(-8,18,3,minecraft:dirt)
B(-8,19,3,minecraft:dirt)
B(-8,20,3,minecraft:dirt)
B(-8,21,3,minecraft:dirt)
B(-8,22,3,minecraft:coarse_dirt)
B(-8,12,4,minecraft:stone)
B(-8,13,4,minecraft:stone)
B(-8,14,4,minecraft:stone)
B(-8,15,4,minecraft:stone)
B(-8,16,4,minecraft:cobblestone)
B(-8,17,4,minecraft:stone)
B(-8,18,4,minecraft:dirt)
B(-8,19,4,minecraft:dirt)
B(-8,20,4,minecraft:dirt)
B(-8,21,4,minecraft:grass_block)
B(-8,10,5,minecraft:cobblestone)
B(-8,11,5,minecraft:cobblestone)
B(-8,12,5,minecraft:cobblestone)
B(-8,13,5,minecraft:cobblestone)
B(-8,14,5,minecraft:stone)
B(-8,15,5,minecraft:stone)
B(-8,16,5,minecraft:stone)
B(-8,17,5,minecraft:stone)
B(-8,18,5,minecraft:dirt)
B(-8,19,5,minecraft:dirt)
B(-8,20,5,minecraft:dirt)
B(-8,21,5,minecraft:grass_block)
B(-8,8,6,minecraft:cobblestone)
B(-8,9,6,minecraft:cobblestone)
B(-8,10,6,minecraft:cobblestone)
B(-8,11,6,minecraft:cobblestone)
B(-8,12,6,minecraft:cobblestone)
B(-8,13,6,minecraft:stone)
B(-8,14,6,minecraft:stone)
B(-8,15,6,minecraft:stone)
B(-8,16,6,minecraft:stone)
B(-8,17,6,minecraft:stone)
B(-8,18,6,minecraft:dirt)
B(-8,19,6,minecraft:dirt)
B(-8,20,6,minecraft:grass_block)
B(-8,5,7,minecraft:stone)
B(-8,6,7,minecraft:stone)
B(-8,7,7,minecraft:cobblestone)
B(-8,8,7,minecraft:cobblestone)
B(-8,9,7,minecraft:cobblestone)
B(-8,10,7,minecraft:stone)
B(-8,11,7,minecraft:stone)
B(-8,12,7,minecraft:stone)
B(-8,13,7,minecraft:stone)
B(-8,14,7,minecraft:stone)
B(-8,15,7,minecraft:stone)
B(-8,16,7,minecraft:stone)
B(-8,17,7,minecraft:stone)
B(-8,18,7,minecraft:stone)
B(-8,19,7,minecraft:grass_block)
B(-8,3,8,minecraft:cobblestone)
B(-8,4,8,minecraft:cobblestone)
B(-8,5,8,minecraft:stone)
B(-8,6,8,minecraft:stone)
B(-8,7,8,minecraft:cobblestone)
B(-8,8,8,minecraft:stone)
B(-8,9,8,minecraft:stone)
B(-8,10,8,minecraft:stone)
B(-8,11,8,minecraft:stone)
B(-8,12,8,minecraft:stone)
B(-8,13,8,minecraft:stone)
B(-8,14,8,minecraft:stone)
B(-8,15,8,minecraft:stone)
B(-8,16,8,minecraft:stone)
B(-8,17,8,minecraft:dirt)
B(-8,18,8,minecraft:dirt)
B(-8,19,8,minecraft:grass_block)
B(-7,20,-2,minecraft:grass_block)
B(-7,19,-1,minecraft:dirt)
B(-7,20,-1,minecraft:dirt)
B(-7,21,-1,minecraft:dirt)
B(-7,22,-1,minecraft:grass_block)
B(-7,18,0,minecraft:stone)
B(-7,19,0,minecraft:dirt)
B(-7,20,0,minecraft:dirt)
B(-7,21,0,minecraft:dirt)
B(-7,22,0,minecraft:dirt)
B(-7,23,0,minecraft:dirt)
B(-7,24,0,minecraft:stone)
B(-7,25,0,minecraft:stone)
B(-7,18,1,minecraft:dirt)
B(-7,19,1,minecraft:dirt)
B(-7,20,1,minecraft:dirt)
B(-7,21,1,minecraft:dirt)
B(-7,22,1,minecraft:dirt)
B(-7,23,1,minecraft:grass_block)
B(-7,17,2,minecraft:cobblestone)
B(-7,18,2,minecraft:dirt)
B(-7,19,2,minecraft:dirt)
B(-7,20,2,minecraft:dirt)
B(-7,21,2,minecraft:dirt)
B(-7,22,2,minecraft:dirt)
B(-7,23,2,minecraft:dirt)
B(-7,24,2,minecraft:stone)
B(-7,15,3,minecraft:stone)
B(-7,16,3,minecraft:cobblestone)
B(-7,17,3,minecraft:stone)
B(-7,18,3,minecraft:dirt)
B(-7,19,3,minecraft:dirt)
B(-7,20,3,minecraft:dirt)
B(-7,21,3,minecraft:dirt)
B(-7,22,3,minecraft:dirt)
B(-7,23,3,minecraft:coarse_dirt)
B(-7,11,4,minecraft:stone)
B(-7,12,4,minecraft:stone)
B(-7,13,4,minecraft:stone)
B(-7,14,4,minecraft:stone)
B(-7,15,4,minecraft:stone)
B(-7,16,4,minecraft:stone)
B(-7,17,4,minecraft:stone)
B(-7,18,4,minecraft:stone)
B(-7,19,4,minecraft:dirt)
B(-7,20,4,minecraft:dirt)
B(-7,21,4,minecraft:dirt)
B(-7,22,4,minecraft:coarse_dirt)
B(-7,10,5,minecraft:stone)
B(-7,11,5,minecraft:stone)
B(-7,12,5,minecraft:stone)
B(-7,13,5,minecraft:stone)
B(-7,14,5,minecraft:stone)
B(-7,15,5,minecraft:stone)
B(-7,16,5,minecraft:stone)
B(-7,17,5,minecraft:stone)
B(-7,18,5,minecraft:stone)
B(-7,19,5,minecraft:dirt)
B(-7,20,5,minecraft:dirt)
B(-7,21,5,minecraft:grass_block)
B(-7,7,6,minecraft:cobblestone)
B(-7,8,6,minecraft:cobblestone)
B(-7,9,6,minecraft:cobblestone)
B(-7,10,6,minecraft:cobblestone)
B(-7,11,6,minecraft:stone)
B(-7,12,6,minecraft:stone)
B(-7,13,6,minecraft:stone)
B(-7,14,6,minecraft:stone)
B(-7,15,6,minecraft:stone)
B(-7,16,6,minecraft:stone)
B(-7,17,6,minecraft:stone)
B(-7,18,6,minecraft:stone)
B(-7,19,6,minecraft:dirt)
B(-7,20,6,minecraft:dirt)
B(-7,21,6,minecraft:grass_block)
B(-7,4,7,minecraft:stone)
B(-7,5,7,minecraft:stone)
B(-7,6,7,minecraft:stone)
B(-7,7,7,minecraft:cobblestone)
B(-7,8,7,minecraft:cobblestone)
B(-7,9,7,minecraft:stone)
B(-7,10,7,minecraft:stone)
B(-7,11,7,minecraft:stone)
B(-7,12,7,minecraft:stone)
B(-7,13,7,minecraft:stone)
B(-7,14,7,minecraft:stone)
B(-7,15,7,minecraft:stone)
B(-7,16,7,minecraft:stone)
B(-7,17,7,minecraft:stone)
B(-7,18,7,minecraft:stone)
B(-7,19,7,minecraft:dirt)
B(-7,20,7,minecraft:dirt)
B(-7,21,7,minecraft:grass_block)
B(-7,1,8,minecraft:stone)
B(-7,2,8,minecraft:stone)
B(-7,3,8,minecraft:cobblestone)
B(-7,4,8,minecraft:cobblestone)
B(-7,5,8,minecraft:stone)
B(-7,6,8,minecraft:granite)
B(-7,7,8,minecraft:stone)
B(-7,8,8,minecraft:stone)
B(-7,9,8,minecraft:stone)
B(-7,10,8,minecraft:stone)
B(-7,11,8,minecraft:stone)
B(-7,12,8,minecraft:stone)
B(-7,13,8,minecraft:stone)
B(-7,14,8,minecraft:stone)
B(-7,15,8,minecraft:stone)
B(-7,16,8,minecraft:stone)
B(-7,17,8,minecraft:stone)
B(-7,18,8,minecraft:stone)
B(-7,19,8,minecraft:dirt)
B(-7,20,8,minecraft:grass_block)
B(-6,20,-2,minecraft:dirt)
B(-6,21,-2,minecraft:grass_block)
B(-6,19,-1,minecraft:dirt)
B(-6,20,-1,minecraft:dirt)
B(-6,21,-1,minecraft:dirt)
B(-6,22,-1,minecraft:dirt)
B(-6,23,-1,minecraft:grass_block)
B(-6,18,0,minecraft:dirt)
B(-6,19,0,minecraft:dirt)
B(-6,20,0,minecraft:dirt)
B(-6,21,0,minecraft:dirt)
B(-6,22,0,minecraft:dirt)
B(-6,23,0,minecraft:grass_block)
B(-6,17,1,minecraft:stone)
B(-6,18,1,minecraft:dirt)
B(-6,19,1,minecraft:dirt)
B(-6,20,1,minecraft:dirt)
B(-6,21,1,minecraft:dirt)
B(-6,22,1,minecraft:dirt)
B(-6,23,1,minecraft:dirt)
B(-6,24,1,minecraft:stone)
B(-6,16,2,minecraft:stone)
B(-6,17,2,minecraft:stone)
B(-6,18,2,minecraft:dirt)
B(-6,19,2,minecraft:dirt)
B(-6,20,2,minecraft:dirt)
B(-6,21,2,minecraft:dirt)
B(-6,22,2,minecraft:dirt)
B(-6,23,2,minecraft:dirt)
B(-6,24,2,minecraft:stone)
B(-6,25,2,minecraft:stone)
B(-6,26,2,minecraft:stone)
B(-6,14,3,minecraft:stone)
B(-6,15,3,minecraft:stone)
B(-6,16,3,minecraft:stone)
B(-6,17,3,minecraft:stone)
B(-6,18,3,minecraft:dirt)
B(-6,19,3,minecraft:dirt)
B(-6,20,3,minecraft:dirt)
B(-6,21,3,minecraft:dirt)
B(-6,22,3,minecraft:stone)
B(-6,23,3,minecraft:stone)
B(-6,24,3,minecraft:stone)
B(-6,25,3,minecraft:stone)
B(-6,11,4,minecraft:stone)
B(-6,12,4,minecraft:stone)
B(-6,13,4,minecraft:stone)
B(-6,14,4,minecraft:stone)
B(-6,15,4,minecraft:stone)
B(-6,16,4,minecraft:stone)
B(-6,17,4,minecraft:stone)
B(-6,18,4,minecraft:stone)
B(-6,19,4,minecraft:dirt)
B(-6,20,4,minecraft:dirt)
B(-6,21,4,minecraft:dirt)
B(-6,22,4,minecraft:dirt)
B(-6,23,4,minecraft:coarse_dirt)
B(-6,10,5,minecraft:stone)
B(-6,11,5,minecraft:stone)
B(-6,12,5,minecraft:stone)
B(-6,13,5,minecraft:stone)
B(-6,14,5,minecraft:stone)
B(-6,15,5,minecraft:stone)
B(-6,16,5,minecraft:stone)
B(-6,17,5,minecraft:stone)
B(-6,18,5,minecraft:dirt)
B(-6,19,5,minecraft:dirt)
B(-6,20,5,minecraft:dirt)
B(-6,21,5,minecraft:dirt)
B(-6,22,5,minecraft:coarse_dirt)
B(-6,8,6,minecraft:cobblestone)
B(-6,9,6,minecraft:cobblestone)
B(-6,10,6,minecraft:cobblestone)
B(-6,11,6,minecraft:stone)
B(-6,12,6,minecraft:stone)
B(-6,13,6,minecraft:stone)
B(-6,14,6,minecraft:stone)
B(-6,15,6,minecraft:stone)
B(-6,16,6,minecraft:stone)
B(-6,17,6,minecraft:stone)
B(-6,18,6,minecraft:dirt)
B(-6,19,6,minecraft:dirt)
B(-6,20,6,minecraft:dirt)
B(-6,21,6,minecraft:grass_block)
B(-6,4,7,minecraft:stone)
B(-6,5,7,minecraft:stone)
B(-6,6,7,minecraft:stone)
B(-6,7,7,minecraft:cobblestone)
B(-6,8,7,minecraft:cobblestone)
B(-6,9,7,minecraft:stone)
B(-6,10,7,minecraft:stone)
B(-6,11,7,minecraft:stone)
B(-6,12,7,minecraft:stone)
B(-6,13,7,minecraft:stone)
B(-6,14,7,minecraft:stone)
B(-6,15,7,minecraft:stone)
B(-6,16,7,minecraft:stone)
B(-6,17,7,minecraft:stone)
B(-6,18,7,minecraft:coal_ore)
B(-6,19,7,minecraft:dirt)
B(-6,20,7,minecraft:grass_block)
B(-6,3,8,minecraft:cobblestone)
B(-6,4,8,minecraft:cobblestone)
B(-6,5,8,minecraft:stone)
B(-6,6,8,minecraft:stone)
B(-6,7,8,minecraft:cobblestone)
B(-6,8,8,minecraft:stone)
B(-6,9,8,minecraft:stone)
B(-6,10,8,minecraft:stone)
B(-6,11,8,minecraft:stone)
B(-6,12,8,minecraft:stone)
B(-6,13,8,minecraft:stone)
B(-6,14,8,minecraft:stone)
B(-6,15,8,minecraft:stone)
B(-6,16,8,minecraft:stone)
B(-6,17,8,minecraft:stone)
B(-6,18,8,minecraft:stone)
B(-6,19,8,minecraft:dirt)
B(-6,20,8,minecraft:grass_block)
B(-5,20,-2,minecraft:dirt)
B(-5,21,-2,minecraft:grass_block)
B(-5,19,-1,minecraft:dirt)
B(-5,20,-1,minecraft:dirt)
B(-5,21,-1,minecraft:dirt)
B(-5,22,-1,minecraft:grass_block)
B(-5,18,0,minecraft:dirt)
B(-5,19,0,minecraft:dirt)
B(-5,20,0,minecraft:dirt)
B(-5,21,0,minecraft:dirt)
B(-5,22,0,minecraft:dirt)
B(-5,23,0,minecraft:dirt)
B(-5,24,0,minecraft:stone)
B(-5,25,0,minecraft:stone)
B(-5,17,1,minecraft:stone)
B(-5,18,1,minecraft:dirt)
B(-5,19,1,minecraft:dirt)
B(-5,20,1,minecraft:dirt)
B(-5,21,1,minecraft:dirt)
B(-5,22,1,minecraft:dirt)
B(-5,23,1,minecraft:dirt)
B(-5,24,1,minecraft:stone)
B(-5,25,1,minecraft:stone)
B(-5,26,1,minecraft:stone)
B(-5,16,2,minecraft:stone)
B(-5,17,2,minecraft:stone)
B(-5,18,2,minecraft:stone)
B(-5,19,2,minecraft:dirt)
B(-5,20,2,minecraft:dirt)
B(-5,21,2,minecraft:dirt)
B(-5,22,2,minecraft:dirt)
B(-5,23,2,minecraft:dirt)
B(-5,24,2,minecraft:water)
B(-5,15,3,minecraft:stone)
B(-5,16,3,minecraft:stone)
B(-5,17,3,minecraft:stone)
B(-5,18,3,minecraft:dirt)
B(-5,19,3,minecraft:dirt)
B(-5,20,3,minecraft:dirt)
B(-5,21,3,minecraft:dirt)
B(-5,22,3,minecraft:dirt)
B(-5,23,3,minecraft:dirt)
B(-5,24,3,minecraft:water)
B(-5,11,4,minecraft:stone)
B(-5,12,4,minecraft:stone)
B(-5,13,4,minecraft:stone)
B(-5,14,4,minecraft:stone)
B(-5,15,4,minecraft:stone)
B(-5,16,4,minecraft:stone)
B(-5,17,4,minecraft:stone)
B(-5,18,4,minecraft:dirt)
B(-5,19,4,minecraft:dirt)
B(-5,20,4,minecraft:dirt)
B(-5,21,4,minecraft:dirt)
B(-5,22,4,minecraft:dirt)
B(-5,23,4,minecraft:dirt)
B(-5,24,4,minecraft:coarse_dirt)
B(-5,10,5,minecraft:stone)
B(-5,11,5,minecraft:stone)
B(-5,12,5,minecraft:cobblestone)
B(-5,13,5,minecraft:cobblestone)
B(-5,14,5,minecraft:cobblestone)
B(-5,15,5,minecraft:stone)
B(-5,16,5,minecraft:stone)
B(-5,17,5,minecraft:stone)
B(-5,18,5,minecraft:dirt)
B(-5,19,5,minecraft:dirt)
B(-5,20,5,minecraft:dirt)
B(-5,21,5,minecraft:dirt)
B(-5,22,5,minecraft:dirt)
B(-5,23,5,minecraft:coarse_dirt)
B(-5,7,6,minecraft:cobblestone)
B(-5,8,6,minecraft:cobblestone)
B(-5,9,6,minecraft:cobblestone)
B(-5,10,6,minecraft:stone)
B(-5,11,6,minecraft:stone)
B(-5,12,6,minecraft:stone)
B(-5,13,6,minecraft:stone)
B(-5,14,6,minecraft:stone)
B(-5,15,6,minecraft:stone)
B(-5,16,6,minecraft:stone)
B(-5,17,6,minecraft:stone)
B(-5,18,6,minecraft:dirt)
B(-5,19,6,minecraft:dirt)
B(-5,20,6,minecraft:dirt)
B(-5,21,6,minecraft:dirt)
B(-5,22,6,minecraft:coarse_dirt)
B(-5,6,7,minecraft:stone)
B(-5,7,7,minecraft:cobblestone)
B(-5,8,7,minecraft:cobblestone)
B(-5,9,7,minecraft:cobblestone)
B(-5,10,7,minecraft:stone)
B(-5,11,7,minecraft:stone)
B(-5,12,7,minecraft:stone)
B(-5,13,7,minecraft:stone)
B(-5,14,7,minecraft:stone)
B(-5,15,7,minecraft:stone)
B(-5,16,7,minecraft:stone)
B(-5,17,7,minecraft:stone)
B(-5,18,7,minecraft:dirt)
B(-5,19,7,minecraft:dirt)
B(-5,20,7,minecraft:dirt)
B(-5,21,7,minecraft:dirt)
B(-5,22,7,minecraft:grass_block)
B(-5,7,8,minecraft:stone)
B(-5,8,8,minecraft:cobblestone)
B(-5,9,8,minecraft:stone)
B(-5,10,8,minecraft:stone)
B(-5,11,8,minecraft:stone)
B(-5,12,8,minecraft:stone)
B(-5,13,8,minecraft:stone)
B(-5,14,8,minecraft:stone)
B(-5,15,8,minecraft:stone)
B(-5,16,8,minecraft:stone)
B(-5,17,8,minecraft:stone)
B(-5,18,8,minecraft:dirt)
B(-5,19,8,minecraft:grass_block)
B(-5,20,8,minecraft:water[level=1])
B(-4,20,-2,minecraft:dirt)
B(-4,21,-2,minecraft:grass_block)
B(-4,19,-1,minecraft:dirt)
B(-4,20,-1,minecraft:dirt)
B(-4,21,-1,minecraft:grass_block)
B(-4,18,0,minecraft:dirt)
B(-4,19,0,minecraft:dirt)
B(-4,20,0,minecraft:dirt)
B(-4,21,0,minecraft:dirt)
B(-4,22,0,minecraft:stone)
B(-4,23,0,minecraft:stone)
B(-4,17,1,minecraft:stone)
B(-4,18,1,minecraft:dirt)
B(-4,19,1,minecraft:dirt)
B(-4,20,1,minecraft:dirt)
B(-4,21,1,minecraft:dirt)
B(-4,22,1,minecraft:dirt)
B(-4,23,1,minecraft:dirt)
B(-4,24,1,minecraft:stone)
B(-4,17,2,minecraft:stone)
B(-4,18,2,minecraft:stone)
B(-4,19,2,minecraft:dirt)
B(-4,20,2,minecraft:dirt)
B(-4,21,2,minecraft:dirt)
B(-4,22,2,minecraft:dirt)
B(-4,23,2,minecraft:dirt)
B(-4,24,2,minecraft:water)
B(-4,16,3,minecraft:stone)
B(-4,17,3,minecraft:stone)
B(-4,18,3,minecraft:dirt)
B(-4,19,3,minecraft:dirt)
B(-4,20,3,minecraft:dirt)
B(-4,21,3,minecraft:dirt)
B(-4,22,3,minecraft:dirt)
B(-4,23,3,minecraft:dirt)
B(-4,24,3,minecraft:water)
B(-4,13,4,minecraft:cobblestone)
B(-4,14,4,minecraft:cobblestone)
B(-4,15,4,minecraft:stone)
B(-4,16,4,minecraft:stone)
B(-4,17,4,minecraft:cobblestone)
B(-4,18,4,minecraft:dirt)
B(-4,19,4,minecraft:dirt)
B(-4,20,4,minecraft:dirt)
B(-4,21,4,minecraft:dirt)
B(-4,22,4,minecraft:dirt)
B(-4,23,4,minecraft:dirt)
B(-4,24,4,minecraft:stone)
B(-4,25,4,minecraft:stone)
B(-4,10,5,minecraft:stone)
B(-4,11,5,minecraft:cobblestone)
B(-4,12,5,minecraft:cobblestone)
B(-4,13,5,minecraft:cobblestone)
B(-4,14,5,minecraft:cobblestone)
B(-4,15,5,minecraft:cobblestone)
B(-4,16,5,minecraft:stone)
B(-4,17,5,minecraft:stone)
B(-4,18,5,minecraft:dirt)
B(-4,19,5,minecraft:dirt)
B(-4,20,5,minecraft:dirt)
B(-4,21,5,minecraft:dirt)
B(-4,22,5,minecraft:dirt)
B(-4,23,5,minecraft:dirt)
B(-4,24,5,minecraft:coarse_dirt)
B(-4,9,6,minecraft:cobblestone)
B(-4,10,6,minecraft:stone)
B(-4,11,6,minecraft:stone)
B(-4,12,6,minecraft:cobblestone)
B(-4,13,6,minecraft:cobblestone)
B(-4,14,6,minecraft:stone)
B(-4,15,6,minecraft:stone)
B(-4,16,6,minecraft:stone)
B(-4,17,6,minecraft:stone)
B(-4,18,6,minecraft:dirt)
B(-4,19,6,minecraft:dirt)
B(-4,20,6,minecraft:dirt)
B(-4,21,6,minecraft:dirt)
B(-4,22,6,minecraft:dirt)
B(-4,8,7,minecraft:cobblestone)
B(-4,9,7,minecraft:cobblestone)
B(-4,10,7,minecraft:stone)
B(-4,11,7,minecraft:stone)
B(-4,12,7,minecraft:stone)
B(-4,13,7,minecraft:stone)
B(-4,14,7,minecraft:stone)
B(-4,15,7,minecraft:stone)
B(-4,16,7,minecraft:stone)
B(-4,17,7,minecraft:stone)
B(-4,18,7,minecraft:dirt)
B(-4,19,7,minecraft:dirt)
B(-4,20,7,minecraft:dirt)
B(-4,21,7,minecraft:coarse_dirt)
B(-4,22,7,minecraft:coarse_dirt)
B(-4,10,8,minecraft:stone)
B(-4,11,8,minecraft:stone)
B(-4,12,8,minecraft:stone)
B(-4,13,8,minecraft:cobblestone)
B(-4,14,8,minecraft:cobblestone)
B(-4,15,8,minecraft:stone)
B(-4,16,8,minecraft:stone)
B(-4,17,8,minecraft:stone)
B(-4,18,8,minecraft:dirt)
B(-4,19,8,minecraft:dirt)
B(-4,20,8,minecraft:water[level=8])
B(-4,21,8,minecraft:water[level=8])
B(-4,22,8,minecraft:water[level=3])
B(-3,19,-1,minecraft:dirt)
B(-3,20,-1,minecraft:dirt)
B(-3,21,-1,minecraft:grass_block)
B(-3,19,0,minecraft:dirt)
B(-3,20,0,minecraft:dirt)
B(-3,21,0,minecraft:dirt)
B(-3,22,0,minecraft:grass_block)
B(-3,18,1,minecraft:dirt)
B(-3,19,1,minecraft:dirt)
B(-3,20,1,minecraft:dirt)
B(-3,21,1,minecraft:dirt)
B(-3,22,1,minecraft:dirt)
B(-3,23,1,minecraft:grass_block)
B(-3,17,2,minecraft:stone)
B(-3,18,2,minecraft:stone)
B(-3,19,2,minecraft:dirt)
B(-3,20,2,minecraft:dirt)
B(-3,21,2,minecraft:dirt)
B(-3,22,2,minecraft:dirt)
B(-3,23,2,minecraft:dirt)
B(-3,24,2,minecraft:stone)
B(-3,25,2,minecraft:stone)
B(-3,16,3,minecraft:stone)
B(-3,17,3,minecraft:stone)
B(-3,18,3,minecraft:dirt)
B(-3,19,3,minecraft:dirt)
B(-3,20,3,minecraft:dirt)
B(-3,21,3,minecraft:dirt)
B(-3,22,3,minecraft:dirt)
B(-3,23,3,minecraft:dirt)
B(-3,24,3,minecraft:water)
B(-3,15,4,minecraft:stone)
B(-3,16,4,minecraft:stone)
B(-3,17,4,minecraft:stone)
B(-3,18,4,minecraft:dirt)
B(-3,19,4,minecraft:dirt)
B(-3,20,4,minecraft:dirt)
B(-3,21,4,minecraft:dirt)
B(-3,22,4,minecraft:dirt)
B(-3,23,4,minecraft:dirt)
B(-3,24,4,minecraft:water)
B(-3,13,5,minecraft:cobblestone)
B(-3,14,5,minecraft:cobblestone)
B(-3,15,5,minecraft:cobblestone)
B(-3,16,5,minecraft:stone)
B(-3,17,5,minecraft:stone)
B(-3,18,5,minecraft:dirt)
B(-3,19,5,minecraft:dirt)
B(-3,20,5,minecraft:dirt)
B(-3,21,5,minecraft:dirt)
B(-3,22,5,minecraft:dirt)
B(-3,23,5,minecraft:dirt)
B(-3,24,5,minecraft:stone)
B(-3,25,5,minecraft:stone)
B(-3,11,6,minecraft:cobblestone)
B(-3,12,6,minecraft:cobblestone)
B(-3,13,6,minecraft:cobblestone)
B(-3,14,6,minecraft:cobblestone)
B(-3,15,6,minecraft:stone)
B(-3,16,6,minecraft:stone)
B(-3,17,6,minecraft:stone)
B(-3,18,6,minecraft:dirt)
B(-3,19,6,minecraft:dirt)
B(-3,20,6,minecraft:dirt)
B(-3,21,6,minecraft:dirt)
B(-3,22,6,minecraft:dirt)
B(-3,23,6,minecraft:dirt)
B(-3,24,6,minecraft:stone)
B(-3,10,7,minecraft:cobblestone)
B(-3,11,7,minecraft:cobblestone)
B(-3,12,7,minecraft:cobblestone)
B(-3,13,7,minecraft:cobblestone)
B(-3,14,7,minecraft:cobblestone)
B(-3,15,7,minecraft:stone)
B(-3,16,7,minecraft:stone)
B(-3,17,7,minecraft:stone)
B(-3,18,7,minecraft:stone)
B(-3,19,7,minecraft:dirt)
B(-3,20,7,minecraft:dirt)
B(-3,21,7,minecraft:dirt)
B(-3,22,7,minecraft:water[level=1])
B(-3,12,8,minecraft:cobblestone)
B(-3,13,8,minecraft:cobblestone)
B(-3,14,8,minecraft:cobblestone)
B(-3,15,8,minecraft:stone)
B(-3,16,8,minecraft:stone)
B(-3,17,8,minecraft:stone)
B(-3,18,8,minecraft:dirt)
B(-3,19,8,minecraft:dirt)
B(-3,20,8,minecraft:water[level=8])
B(-3,21,8,minecraft:water[level=8])
B(-3,22,8,minecraft:water[level=2])
B(-2,20,-1,minecraft:dirt)
B(-2,21,-1,minecraft:grass_block)
B(-2,19,0,minecraft:dirt)
B(-2,20,0,minecraft:dirt)
B(-2,21,0,minecraft:grass_block)
B(-2,19,1,minecraft:dirt)
B(-2,20,1,minecraft:dirt)
B(-2,21,1,minecraft:dirt)
B(-2,22,1,minecraft:stone)
B(-2,18,2,minecraft:dirt)
B(-2,19,2,minecraft:dirt)
B(-2,20,2,minecraft:dirt)
B(-2,21,2,minecraft:dirt)
B(-2,22,2,minecraft:dirt)
B(-2,23,2,minecraft:grass_block)
B(-2,17,3,minecraft:stone)
B(-2,18,3,minecraft:stone)
B(-2,19,3,minecraft:dirt)
B(-2,20,3,minecraft:dirt)
B(-2,21,3,minecraft:dirt)
B(-2,22,3,minecraft:dirt)
B(-2,23,3,minecraft:dirt)
B(-2,24,3,minecraft:stone)
B(-2,25,3,minecraft:stone)
B(-2,26,3,minecraft:stone)
B(-2,27,3,minecraft:stone)
B(-2,16,4,minecraft:stone)
B(-2,17,4,minecraft:stone)
B(-2,18,4,minecraft:dirt)
B(-2,19,4,minecraft:dirt)
B(-2,20,4,minecraft:dirt)
B(-2,21,4,minecraft:dirt)
B(-2,22,4,minecraft:dirt)
B(-2,23,4,minecraft:dirt)
B(-2,24,4,minecraft:water)
B(-2,14,5,minecraft:cobblestone)
B(-2,15,5,minecraft:cobblestone)
B(-2,16,5,minecraft:stone)
B(-2,17,5,minecraft:stone)
B(-2,18,5,minecraft:dirt)
B(-2,19,5,minecraft:dirt)
B(-2,20,5,minecraft:dirt)
B(-2,21,5,minecraft:dirt)
B(-2,22,5,minecraft:dirt)
B(-2,23,5,minecraft:dirt)
B(-2,24,5,minecraft:water)
B(-2,13,6,minecraft:cobblestone)
B(-2,14,6,minecraft:cobblestone)
B(-2,15,6,minecraft:stone)
B(-2,16,6,minecraft:stone)
B(-2,17,6,minecraft:stone)
B(-2,18,6,minecraft:dirt)
B(-2,19,6,minecraft:dirt)
B(-2,20,6,minecraft:dirt)
B(-2,21,6,minecraft:dirt)
B(-2,22,6,minecraft:dirt)
B(-2,23,6,minecraft:water)
B(-2,24,6,minecraft:water[level=1])
B(-2,14,7,minecraft:stone)
B(-2,15,7,minecraft:stone)
B(-2,16,7,minecraft:stone)
B(-2,17,7,minecraft:stone)
B(-2,18,7,minecraft:stone)
B(-2,19,7,minecraft:dirt)
B(-2,20,7,minecraft:dirt)
B(-2,21,7,minecraft:dirt)
B(-2,22,7,minecraft:water[level=8])
B(-2,23,7,minecraft:water[level=1])
B(-2,15,8,minecraft:stone)
B(-2,16,8,minecraft:stone)
B(-2,17,8,minecraft:stone)
B(-2,18,8,minecraft:stone)
B(-2,19,8,minecraft:dirt)
B(-2,20,8,minecraft:dirt)
B(-2,21,8,minecraft:dirt)
B(-2,22,8,minecraft:coarse_dirt)
B(-1,20,-1,minecraft:grass_block)
B(-1,19,0,minecraft:dirt)
B(-1,20,0,minecraft:dirt)
B(-1,21,0,minecraft:grass_block)
B(-1,19,1,minecraft:dirt)
B(-1,20,1,minecraft:dirt)
B(-1,21,1,minecraft:grass_block)
B(-1,18,2,minecraft:dirt)
B(-1,19,2,minecraft:dirt)
B(-1,20,2,minecraft:dirt)
B(-1,21,2,minecraft:dirt)
B(-1,22,2,minecraft:coarse_dirt)
B(-1,23,2,minecraft:dirt)
B(-1,17,3,minecraft:stone)
B(-1,18,3,minecraft:stone)
B(-1,19,3,minecraft:dirt)
B(-1,20,3,minecraft:dirt)
B(-1,21,3,minecraft:dirt)
B(-1,22,3,minecraft:dirt)
B(-1,23,3,minecraft:dirt)
B(-1,24,3,minecraft:stone)
B(-1,17,4,minecraft:stone)
B(-1,18,4,minecraft:dirt)
B(-1,19,4,minecraft:dirt)
B(-1,20,4,minecraft:dirt)
B(-1,21,4,minecraft:dirt)
B(-1,22,4,minecraft:dirt)
B(-1,23,4,minecraft:dirt)
B(-1,24,4,minecraft:stone)
B(-1,25,4,minecraft:stone)
B(-1,16,5,minecraft:stone)
B(-1,17,5,minecraft:stone)
B(-1,18,5,minecraft:dirt)
B(-1,19,5,minecraft:dirt)
B(-1,20,5,minecraft:grass_block)
B(-1,22,5,minecraft:dirt)
B(-1,23,5,minecraft:dirt)
B(-1,24,5,minecraft:stone)
B(-1,16,6,minecraft:stone)
B(-1,17,6,minecraft:stone)
B(-1,18,6,minecraft:dirt)
B(-1,19,6,minecraft:dirt)
B(-1,20,6,minecraft:dirt)
B(-1,21,6,minecraft:dirt)
B(-1,22,6,minecraft:dirt)
B(-1,23,6,minecraft:dirt)
B(-1,24,6,minecraft:stone)
B(-1,16,7,minecraft:stone)
B(-1,17,7,minecraft:stone)
B(-1,18,7,minecraft:stone)
B(-1,19,7,minecraft:dirt)
B(-1,20,7,minecraft:dirt)
B(-1,21,7,minecraft:dirt)
B(-1,22,7,minecraft:water)
B(-1,17,8,minecraft:stone)
B(-1,18,8,minecraft:dirt)
B(-1,19,8,minecraft:dirt)
B(-1,20,8,minecraft:dirt)
B(-1,21,8,minecraft:dirt)
B(-1,22,8,minecraft:dirt)
B(-1,23,8,minecraft:dirt)
B(0,19,0,minecraft:dirt)
B(0,20,0,minecraft:dirt)
B(0,21,0,minecraft:coarse_dirt)
B(0,19,1,minecraft:dirt)
B(0,20,1,minecraft:dirt)
B(0,21,1,minecraft:grass_block)
B(0,18,2,minecraft:dirt)
B(0,19,2,minecraft:dirt)
B(0,20,2,minecraft:dirt)
B(0,21,2,minecraft:coarse_dirt)
B(0,17,3,minecraft:stone)
B(0,18,3,minecraft:dirt)
B(0,19,3,minecraft:dirt)
B(0,20,3,minecraft:dirt)
B(0,21,3,minecraft:dirt)
B(0,22,3,minecraft:coarse_dirt)
B(0,23,3,minecraft:coarse_dirt)
B(0,17,4,minecraft:stone)
B(0,18,4,minecraft:dirt)
B(0,19,4,minecraft:dirt)
B(0,20,4,minecraft:dirt)
B(0,21,4,minecraft:dirt)
B(0,22,4,minecraft:dirt)
B(0,23,4,minecraft:dirt)
B(0,24,4,minecraft:stone)
B(0,17,5,minecraft:stone)
B(0,18,5,minecraft:dirt)
B(0,19,5,minecraft:dirt)
B(0,20,5,minecraft:dirt)
B(0,21,5,minecraft:dirt)
B(0,22,5,minecraft:dirt)
B(0,23,5,minecraft:dirt)
B(0,24,5,minecraft:stone)
B(0,25,5,minecraft:stone)
B(0,17,6,minecraft:stone)
B(0,18,6,minecraft:dirt)
B(0,19,6,minecraft:dirt)
B(0,20,6,minecraft:dirt)
B(0,21,6,minecraft:dirt)
B(0,22,6,minecraft:dirt)
B(0,23,6,minecraft:dirt)
B(0,24,6,minecraft:stone)
B(0,25,6,minecraft:stone)
B(0,18,7,minecraft:dirt)
B(0,19,7,minecraft:dirt)
B(0,20,7,minecraft:dirt)
B(0,21,7,minecraft:dirt)
B(0,22,7,minecraft:coarse_dirt)
B(0,23,7,minecraft:coarse_dirt)
B(0,18,8,minecraft:dirt)
B(0,19,8,minecraft:dirt)
B(0,20,8,minecraft:dirt)
B(0,21,8,minecraft:coarse_dirt)
B(1,20,0,minecraft:grass_block)
B(1,20,1,minecraft:dirt)
B(1,21,1,minecraft:coarse_dirt)
B(1,19,2,minecraft:dirt)
B(1,20,2,minecraft:grass_block)
B(1,18,3,minecraft:dirt)
B(1,19,3,minecraft:dirt)
B(1,20,3,minecraft:dirt)
B(1,21,3,minecraft:coarse_dirt)
B(1,22,3,minecraft:stone)
B(1,18,4,minecraft:stone)
B(1,19,4,minecraft:dirt)
B(1,20,4,minecraft:dirt)
B(1,21,4,minecraft:dirt)
B(1,22,4,minecraft:coarse_dirt)
B(1,23,4,minecraft:stone)
B(1,18,5,minecraft:stone)
B(1,19,5,minecraft:dirt)
B(1,20,5,minecraft:dirt)
B(1,21,5,minecraft:dirt)
B(1,22,5,minecraft:dirt)
B(1,23,5,minecraft:dirt)
B(1,18,6,minecraft:stone)
B(1,19,6,minecraft:dirt)
B(1,20,6,minecraft:dirt)
B(1,21,6,minecraft:dirt)
B(1,22,6,minecraft:dirt)
B(1,23,6,minecraft:stone)
B(1,24,6,minecraft:stone)
B(1,18,7,minecraft:dirt)
B(1,19,7,minecraft:dirt)
B(1,20,7,minecraft:dirt)
B(1,21,7,minecraft:dirt)
B(1,22,7,minecraft:grass_block)
B(1,19,8,minecraft:dirt)
B(1,20,8,minecraft:dirt)
B(1,21,8,minecraft:grass_block)
B(2,20,3,minecraft:dirt)
B(2,21,3,minecraft:grass_block)
B(2,19,4,minecraft:dirt)
B(2,20,4,minecraft:dirt)
B(2,21,4,minecraft:coarse_dirt)
B(2,22,4,minecraft:coarse_dirt)
B(2,19,5,minecraft:dirt)
B(2,20,5,minecraft:dirt)
B(2,21,5,minecraft:coarse_dirt)
B(2,19,6,minecraft:dirt)
B(2,20,6,minecraft:dirt)
B(2,21,6,minecraft:dirt)
B(2,22,6,minecraft:dirt)
B(2,23,6,minecraft:dirt)
B(2,19,7,minecraft:dirt)
B(2,20,7,minecraft:dirt)
B(2,21,7,minecraft:grass_block)
B(2,19,8,minecraft:dirt)
B(2,20,8,minecraft:grass_block)

#######################################################################
# +-----------------------------------------------------------------+ #
# |                             Branches                            | #
# +-----------------------------------------------------------------+ #
#######################################################################


#######################################################################
# +-----------------------------------------------------------------+ #
# |                             Entities                            | #
# +-----------------------------------------------------------------+ #
#######################################################################

