
#######################################################################
# +-----------------------------------------------------------------+ #
# |                            BO4 object                           | #
# +-----------------------------------------------------------------+ #
#######################################################################

Author: Unknown

Description: No description given

SettingsMode: WriteWithoutComments


#######################################################################
# +-----------------------------------------------------------------+ #
# |                          Main settings                          | #
# +-----------------------------------------------------------------+ #
#######################################################################

FixedRotation: 

Frequency: 0

SpawnHeight: highestBlock

UseCenterForHighestBlock: true

##############################
# Height Limits for the BO4. #
##############################

MinHeight: 0

MaxHeight: 255

InheritBO3: 

InheritBO3Rotation: NORTH

OverrideChildSettings: true

OverrideParentHeight: false

CanOverride: false

BranchFrequency: 0

BranchFrequencyGroup: 

MustBeBelowOther: false

MustBeInside: 

CannotBeInside: 

ReplacesBO3: 

MustBeInsideWorldBorders: false

CanSpawnOnWater: true

SpawnOnWaterOnly: false

SpawnUnderWater: false

SpawnAtWaterLevel: false

HeightOffset: 0

RemoveAir: true

ReplaceAbove: 

ReplaceBelow: 

ReplaceWithBiomeBlocks: true

ReplaceWithSurfaceBlock: GRASS

ReplaceWithGroundBlock: DIRT

ReplaceWithStoneBlock: STONE

SmoothRadius: 0

SmoothHeightOffset: 0

SmoothStartTop: false

SmoothStartWood: false

SmoothingSurfaceBlock: 

SmoothingGroundBlock: 

BO3Group: 

IsSpawnPoint: false

DoReplaceBlocks: true


#######################################################################
# +-----------------------------------------------------------------+ #
# |                              Blocks                             | #
# +-----------------------------------------------------------------+ #
#######################################################################

B(-1,19,3,minecraft:grass_block)
B(-1,19,4,minecraft:grass_block)
B(-1,18,5,minecraft:dirt)
B(-1,19,5,minecraft:grass_block)
B(-1,19,6,minecraft:grass_block)
B(0,19,2,minecraft:grass_block)
B(0,19,3,minecraft:grass_block)
B(0,18,4,minecraft:dirt)
B(0,19,4,minecraft:grass_block)
B(0,18,5,minecraft:dirt)
B(0,19,5,minecraft:grass_block)
B(0,18,6,minecraft:dirt)
B(0,19,6,minecraft:grass_block)
B(0,18,7,minecraft:dirt)
B(0,19,7,minecraft:grass_block)
B(0,18,8,minecraft:dirt)
B(0,19,8,minecraft:grass_block)
B(1,20,1,minecraft:grass_block)
B(1,18,2,minecraft:dirt)
B(1,19,2,minecraft:grass_block)
B(1,17,3,minecraft:dirt)
B(1,18,3,minecraft:dirt)
B(1,19,3,minecraft:grass_block)
B(1,18,4,minecraft:dirt)
B(1,19,4,minecraft:grass_block)
B(1,18,5,minecraft:dirt)
B(1,19,5,minecraft:grass_block)
B(1,17,6,minecraft:dirt)
B(1,18,6,minecraft:dirt)
B(1,19,6,minecraft:grass_block)
B(1,16,7,minecraft:dirt)
B(1,17,7,minecraft:dirt)
B(1,18,7,minecraft:dirt)
B(1,19,7,minecraft:grass_block)
B(1,17,8,minecraft:dirt)
B(1,18,8,minecraft:dirt)
B(1,19,8,minecraft:grass_block)
B(2,20,1,minecraft:grass_block)
B(2,18,2,minecraft:dirt)
B(2,19,2,minecraft:dirt)
B(2,20,2,minecraft:grass_block)
B(2,17,3,minecraft:dirt)
B(2,18,3,minecraft:dirt)
B(2,19,3,minecraft:grass_block)
B(2,17,4,minecraft:dirt)
B(2,18,4,minecraft:dirt)
B(2,19,4,minecraft:grass_block)
B(2,16,5,minecraft:dirt)
B(2,17,5,minecraft:dirt)
B(2,18,5,minecraft:dirt)
B(2,19,5,minecraft:grass_block)
B(2,15,6,minecraft:dirt)
B(2,16,6,minecraft:dirt)
B(2,17,6,minecraft:dirt)
B(2,18,6,minecraft:dirt)
B(2,19,6,minecraft:grass_block)
B(2,15,7,minecraft:dirt)
B(2,16,7,minecraft:dirt)
B(2,17,7,minecraft:dirt)
B(2,18,7,minecraft:dirt)
B(2,19,7,minecraft:coarse_dirt)
B(2,16,8,minecraft:dirt)
B(2,17,8,minecraft:dirt)
B(2,18,8,minecraft:dirt)
B(2,19,8,minecraft:coarse_dirt)
B(3,20,0,minecraft:grass_block)
B(3,19,1,minecraft:dirt)
B(3,20,1,minecraft:grass_block)
B(3,18,2,minecraft:dirt)
B(3,19,2,minecraft:dirt)
B(3,20,2,minecraft:grass_block)
B(3,17,3,minecraft:stone)
B(3,18,3,minecraft:dirt)
B(3,19,3,minecraft:dirt)
B(3,20,3,minecraft:grass_block)
B(3,17,4,minecraft:stone)
B(3,18,4,minecraft:dirt)
B(3,19,4,minecraft:grass_block)
B(3,18,5,minecraft:dirt)
B(3,19,5,minecraft:grass_block)
B(3,16,6,minecraft:dirt)
B(3,17,6,minecraft:dirt)
B(3,18,6,minecraft:dirt)
B(3,19,6,minecraft:grass_block)
B(3,14,7,minecraft:stone)
B(3,15,7,minecraft:stone)
B(3,16,7,minecraft:dirt)
B(3,17,7,minecraft:dirt)
B(3,18,7,minecraft:dirt)
B(3,19,7,minecraft:grass_block)
B(3,13,8,minecraft:stone)
B(3,14,8,minecraft:stone)
B(3,15,8,minecraft:cobblestone)
B(3,16,8,minecraft:dirt)
B(3,17,8,minecraft:dirt)
B(3,18,8,minecraft:coarse_dirt)
B(3,19,8,minecraft:water)
B(4,20,0,minecraft:grass_block)
B(4,18,1,minecraft:dirt)
B(4,19,1,minecraft:dirt)
B(4,20,1,minecraft:grass_block)
B(4,18,2,minecraft:dirt)
B(4,19,2,minecraft:dirt)
B(4,20,2,minecraft:grass_block)
B(4,18,3,minecraft:stone)
B(4,19,3,minecraft:dirt)
B(4,20,3,minecraft:grass_block)
B(4,18,4,minecraft:dirt)
B(4,19,4,minecraft:dirt)
B(4,20,4,minecraft:grass_block)
B(4,17,5,minecraft:stone)
B(4,18,5,minecraft:dirt)
B(4,19,5,minecraft:dirt)
B(4,20,5,minecraft:grass_block)
B(4,15,6,minecraft:stone)
B(4,16,6,minecraft:stone)
B(4,17,6,minecraft:stone)
B(4,18,6,minecraft:dirt)
B(4,19,6,minecraft:dirt)
B(4,20,6,minecraft:grass_block)
B(4,15,7,minecraft:stone)
B(4,16,7,minecraft:stone)
B(4,17,7,minecraft:stone)
B(4,18,7,minecraft:coarse_dirt)
B(4,19,7,minecraft:water)
B(4,12,8,minecraft:cobblestone)
B(4,13,8,minecraft:stone)
B(4,14,8,minecraft:stone)
B(4,15,8,minecraft:cobblestone)
B(4,16,8,minecraft:stone)
B(4,17,8,minecraft:dirt)
B(4,18,8,minecraft:water[level=8])
B(4,19,8,minecraft:water)
B(5,19,0,minecraft:dirt)
B(5,20,0,minecraft:grass_block)
B(5,18,1,minecraft:dirt)
B(5,19,1,minecraft:dirt)
B(5,20,1,minecraft:grass_block)
B(5,18,2,minecraft:dirt)
B(5,19,2,minecraft:dirt)
B(5,20,2,minecraft:grass_block)
B(5,18,3,minecraft:stone)
B(5,19,3,minecraft:dirt)
B(5,20,3,minecraft:grass_block)
B(5,18,4,minecraft:dirt)
B(5,19,4,minecraft:dirt)
B(5,20,4,minecraft:grass_block)
B(5,17,5,minecraft:stone)
B(5,18,5,minecraft:dirt)
B(5,19,5,minecraft:dirt)
B(5,20,5,minecraft:grass_block)
B(5,15,6,minecraft:stone)
B(5,16,6,minecraft:stone)
B(5,17,6,minecraft:stone)
B(5,18,6,minecraft:dirt)
B(5,19,6,minecraft:dirt)
B(5,20,6,minecraft:grass_block)
B(5,14,7,minecraft:cobblestone)
B(5,15,7,minecraft:cobblestone)
B(5,16,7,minecraft:cobblestone)
B(5,17,7,minecraft:stone)
B(5,18,7,minecraft:dirt)
B(5,19,7,minecraft:dirt)
B(5,20,7,minecraft:grass_block)
B(5,12,8,minecraft:stone)
B(5,13,8,minecraft:cobblestone)
B(5,14,8,minecraft:cobblestone)
B(5,15,8,minecraft:cobblestone)
B(5,16,8,minecraft:stone)
B(5,17,8,minecraft:dirt)
B(5,18,8,minecraft:dirt)
B(5,19,8,minecraft:water)
B(6,19,0,minecraft:dirt)
B(6,20,0,minecraft:grass_block)
B(6,19,1,minecraft:dirt)
B(6,20,1,minecraft:dirt)
B(6,21,1,minecraft:grass_block)
B(6,18,2,minecraft:dirt)
B(6,19,2,minecraft:dirt)
B(6,20,2,minecraft:dirt)
B(6,21,2,minecraft:grass_block)
B(6,18,3,minecraft:cobblestone)
B(6,19,3,minecraft:dirt)
B(6,20,3,minecraft:grass_block)
B(6,17,4,minecraft:stone)
B(6,18,4,minecraft:dirt)
B(6,19,4,minecraft:dirt)
B(6,20,4,minecraft:dirt)
B(6,21,4,minecraft:grass_block)
B(6,16,5,minecraft:stone)
B(6,17,5,minecraft:stone)
B(6,18,5,minecraft:dirt)
B(6,19,5,minecraft:dirt)
B(6,20,5,minecraft:grass_block)
B(6,14,6,minecraft:cobblestone)
B(6,15,6,minecraft:cobblestone)
B(6,16,6,minecraft:cobblestone)
B(6,17,6,minecraft:cobblestone)
B(6,18,6,minecraft:dirt)
B(6,19,6,minecraft:dirt)
B(6,20,6,minecraft:grass_block)
B(6,12,7,minecraft:cobblestone)
B(6,13,7,minecraft:cobblestone)
B(6,14,7,minecraft:cobblestone)
B(6,15,7,minecraft:cobblestone)
B(6,16,7,minecraft:cobblestone)
B(6,17,7,minecraft:stone)
B(6,18,7,minecraft:stone)
B(6,19,7,minecraft:grass_block)
B(6,9,8,minecraft:stone)
B(6,10,8,minecraft:stone)
B(6,11,8,minecraft:stone)
B(6,12,8,minecraft:stone)
B(6,13,8,minecraft:cobblestone)
B(6,14,8,minecraft:stone)
B(6,15,8,minecraft:stone)
B(6,16,8,minecraft:stone)
B(6,17,8,minecraft:water[level=8])
B(6,18,8,minecraft:water[level=8])
B(6,19,8,minecraft:water)
B(7,20,-1,minecraft:grass_block)
B(7,19,0,minecraft:dirt)
B(7,20,0,minecraft:dirt)
B(7,21,0,minecraft:grass_block)
B(7,18,1,minecraft:dirt)
B(7,19,1,minecraft:dirt)
B(7,20,1,minecraft:dirt)
B(7,21,1,minecraft:grass_block)
B(7,17,2,minecraft:stone)
B(7,18,2,minecraft:dirt)
B(7,19,2,minecraft:dirt)
B(7,20,2,minecraft:dirt)
B(7,21,2,minecraft:dirt)
B(7,22,2,minecraft:grass_block)
B(7,17,3,minecraft:cobblestone)
B(7,18,3,minecraft:stone)
B(7,19,3,minecraft:dirt)
B(7,20,3,minecraft:dirt)
B(7,21,3,minecraft:grass_block)
B(7,15,4,minecraft:stone)
B(7,16,4,minecraft:stone)
B(7,17,4,minecraft:cobblestone)
B(7,18,4,minecraft:dirt)
B(7,19,4,minecraft:dirt)
B(7,20,4,minecraft:dirt)
B(7,21,4,minecraft:grass_block)
B(7,13,5,minecraft:cobblestone)
B(7,14,5,minecraft:cobblestone)
B(7,15,5,minecraft:stone)
B(7,16,5,minecraft:stone)
B(7,17,5,minecraft:cobblestone)
B(7,18,5,minecraft:dirt)
B(7,19,5,minecraft:dirt)
B(7,20,5,minecraft:grass_block)
B(7,12,6,minecraft:cobblestone)
B(7,13,6,minecraft:cobblestone)
B(7,14,6,minecraft:cobblestone)
B(7,15,6,minecraft:cobblestone)
B(7,16,6,minecraft:cobblestone)
B(7,17,6,minecraft:stone)
B(7,18,6,minecraft:dirt)
B(7,19,6,minecraft:grass_block)
B(7,9,7,minecraft:cobblestone)
B(7,10,7,minecraft:stone)
B(7,11,7,minecraft:stone)
B(7,12,7,minecraft:cobblestone)
B(7,13,7,minecraft:cobblestone)
B(7,14,7,minecraft:stone)
B(7,15,7,minecraft:stone)
B(7,16,7,minecraft:stone)
B(7,17,7,minecraft:stone)
B(7,18,7,minecraft:stone)
B(7,19,7,minecraft:grass_block)
B(7,6,8,minecraft:stone)
B(7,7,8,minecraft:cobblestone)
B(7,8,8,minecraft:cobblestone)
B(7,9,8,minecraft:stone)
B(7,10,8,minecraft:stone)
B(7,11,8,minecraft:stone)
B(7,12,8,minecraft:stone)
B(7,13,8,minecraft:stone)
B(7,14,8,minecraft:stone)
B(7,15,8,minecraft:stone)
B(7,16,8,minecraft:stone)
B(7,17,8,minecraft:dirt)
B(7,18,8,minecraft:water[level=8])
B(7,19,8,minecraft:water)

#######################################################################
# +-----------------------------------------------------------------+ #
# |                             Branches                            | #
# +-----------------------------------------------------------------+ #
#######################################################################

Branch(16,0,0,true,afloatingisland2_C1_R0,NORTH,100.0,0)
Branch(0,0,16,true,afloatingisland2_C0_R1,NORTH,100.0,0)

#######################################################################
# +-----------------------------------------------------------------+ #
# |                             Entities                            | #
# +-----------------------------------------------------------------+ #
#######################################################################

