
#######################################################################
# +-----------------------------------------------------------------+ #
# |                            BO3 object                           | #
# +-----------------------------------------------------------------+ #
#######################################################################

# This is the config file of a custom object.
# If you add this object correctly to your BiomeConfigs, it will spawn in the world.

# This is the creator of this BO3 object
Author: Unknown

# A short description of this BO3 object
Description: This BO3 was converted from a schematic using OTGEdit. The author and description information of the schematic could not be found. If you know who the author of the schematic is then please add this information.

# The BO3 version, don't change this! It can be used by external applications to do a version check.
Version: 3

# The settings mode, WriteAll, WriteWithoutComments or WriteDisable. See WorldConfig.
SettingsMode: WriteAll


#######################################################################
# +-----------------------------------------------------------------+ #
# |                          Main settings                          | #
# +-----------------------------------------------------------------+ #
#######################################################################

# This needs to be set to true to spawn the object in the Tree and Sapling resources.
Tree: true

# The frequency of the BO3 from 1 to 200. Tries this many times to spawn this BO3 when using the CustomObject(...) resource.
# Ignored by Tree(..), Sapling(..) and CustomStructure(..)
Frequency: 40

# The rarity of the BO3 from 0 to 100. Each spawn attempt has rarity% chance to succeed when using the CustomObject(...) resource.
# Ignored by Tree(..), Sapling(..) and CustomStructure(..)
Rarity: 100.0

# When using Frequency, after this many succesfull spawn attempts, abort spawning.
# For example, you can set 100 spawn attempts using Frequency, but stop spawning after 5 successfull spawns via MaxSpawn.
# 0 by default, which means ignore this setting.
# Ignored by Tree(..), Sapling(..) and CustomStructure(..)
MaxSpawn: 0

# If you set this to true, the BO3 will be placed with a random rotation.
RotateRandomly: true

# The spawn height of the BO3: randomY, highestBlock or highestSolidBlock.
SpawnHeight: randomY

# The offset from the spawn height to spawn this BO3
# Ex. SpawnHeight = highestSolidBlock, SpawnHeightOffset = 3; This object will spawn 3 blocks above the highest solid block
SpawnHeightOffset: 0

# A random amount to offset the spawn location from the spawn offset height
# Ex. SpawnHeightOffset = 3, SpawnHeightVariance = 3; This object will spawn 3 to 6 blocks above the original spot it would have spawned
SpawnHeightVariance: 0

##############################
# Height Limits for the BO3. #
##############################

# When in randomY mode used as the minimum Y or in atMinY mode as the actual Y to spawn this BO3 at.
MinHeight: 62

# When in randomY mode used as the maximum Y to spawn this BO3 at.
MaxHeight: 255

######################
# Extrusion settings #
######################

# The style of extrusion you wish to use - BottomDown, TopUp, None (Default)
ExtrudeMode: None

# The blocks to extrude your BO3 through
ExtrudeThroughBlocks: minecraft:air

# Objects can have other objects attacthed to it: branches. Branches can also
# have branches attached to it, which can also have branches, etc. This is the
# maximum branch depth for this objects.
MaxBranchDepth: 10


#######################################################################
# +-----------------------------------------------------------------+ #
# |                      Source block settings                      | #
# +-----------------------------------------------------------------+ #
#######################################################################

# The block(s) the BO3 should spawn in.
SourceBlocks: minecraft:air,minecraft:grass_block,minecraft:dirt

# The maximum percentage of the BO3 that can be outside the SourceBlock.
# The BO3 won't be placed on a location with more blocks outside the SourceBlock than this percentage.
MaxPercentageOutsideSourceBlock: 5

# What to do when a block is about to be placed outside the SourceBlock? (dontPlace, placeAnyway)
OutsideSourceBlock: dontPlace

# Disable doReplaceBlocks to make this BO3 ignore any ReplacedBlocks settings in biome configs, improves performance.
DoReplaceBlocks: true

# OTG+ settings #
# Legacy setting, rename this file to .BO4 instead. Set this to true to enable the advanced customstructure features of OTG+.
IsOTGPlus: false


#######################################################################
# +-----------------------------------------------------------------+ #
# |                              Blocks                             | #
# +-----------------------------------------------------------------+ #
#######################################################################

# All the blocks used in the BO3 are listed here. Possible blocks:
# Block(x,y,z,id[.data][,nbtfile.nbt)
# RandomBlock(x,y,z,id[:data][,nbtfile.nbt],chance[,id[:data][,nbtfile.nbt],chance[,...]])
#  So RandomBlock(0,0,0,CHEST,chest.nbt,50,CHEST,anotherchest.nbt,100) will spawn a chest at
#  the BO3 origin, and give it a 50% chance to have the contents of chest.nbt, or, if that
#  fails, a 100% percent chance to have the contents of anotherchest.nbt.
# *Note: Unlike Entity() and Spawner(), for Block() .txt files don't work, only .nbt files work.
# MinecraftObject(x,y,z,name) (TODO: This may not work anymore and needs to be tested.
#  Spawns an object in the Mojang NBT structure format. For example, 
#  MinecraftObject(0,0,0,minecraft:igloo/igloo_bottom)
#  spawns the bottom part of an igloo.
B(-7,12,-3,byg:pink_cherry_leaves)
B(-7,8,-2,byg:pink_cherry_leaves)
B(-7,8,-1,byg:pink_cherry_leaves)
B(-7,9,-1,byg:pink_cherry_leaves)
B(-7,12,-1,byg:pink_cherry_leaves)
B(-7,12,0,byg:pink_cherry_leaves)
B(-7,10,1,byg:pink_cherry_leaves)
B(-6,10,-4,byg:pink_cherry_leaves)
B(-6,10,-3,byg:pink_cherry_leaves)
B(-6,11,-3,byg:pink_cherry_leaves)
B(-6,12,-3,byg:pink_cherry_leaves)
B(-6,12,-2,byg:pink_cherry_leaves)
B(-6,8,-1,byg:pink_cherry_leaves)
B(-6,9,-1,byg:pink_cherry_leaves)
B(-6,12,-1,byg:pink_cherry_leaves)
B(-6,9,0,byg:pink_cherry_leaves)
B(-6,10,0,byg:pink_cherry_leaves)
B(-6,11,0,byg:pink_cherry_leaves)
B(-6,10,1,byg:pink_cherry_leaves)
B(-5,10,-5,byg:pink_cherry_leaves)
B(-5,10,-4,byg:pink_cherry_leaves)
B(-5,8,-3,byg:pink_cherry_leaves)
B(-5,11,-3,byg:pink_cherry_leaves)
B(-5,8,-2,byg:pink_cherry_leaves)
B(-5,11,-2,byg:pink_cherry_leaves)
B(-5,12,-2,byg:pink_cherry_leaves)
B(-5,13,-2,byg:pink_cherry_leaves)
B(-5,7,-1,byg:pink_cherry_leaves)
B(-5,8,-1,byg:pink_cherry_leaves)
B(-5,9,-1,byg:pink_cherry_leaves)
B(-5,10,-1,byg:cherry_log)
B(-5,11,-1,byg:pink_cherry_leaves)
B(-5,12,-1,byg:pink_cherry_leaves)
B(-5,14,-1,byg:pink_cherry_leaves)
B(-5,15,-1,byg:pink_cherry_leaves)
B(-5,8,0,byg:pink_cherry_leaves)
B(-5,9,0,byg:pink_cherry_leaves)
B(-5,12,0,byg:pink_cherry_leaves)
B(-5,15,0,byg:pink_cherry_leaves)
B(-5,16,0,byg:pink_cherry_leaves)
B(-5,8,1,byg:pink_cherry_leaves)
B(-5,11,1,byg:pink_cherry_leaves)
B(-5,12,1,byg:pink_cherry_leaves)
B(-5,15,1,byg:pink_cherry_leaves)
B(-5,10,2,byg:pink_cherry_leaves)
B(-5,11,2,byg:pink_cherry_leaves)
B(-5,10,3,byg:pink_cherry_leaves)
B(-5,10,4,byg:pink_cherry_leaves)
B(-4,10,-6,byg:pink_cherry_leaves)
B(-4,8,-5,byg:pink_cherry_leaves)
B(-4,10,-5,byg:pink_cherry_leaves)
B(-4,11,-5,byg:pink_cherry_leaves)
B(-4,8,-4,byg:pink_cherry_leaves)
B(-4,9,-4,byg:pink_cherry_leaves)
B(-4,10,-4,byg:pink_cherry_leaves)
B(-4,11,-4,byg:pink_cherry_leaves)
B(-4,8,-3,byg:pink_cherry_leaves)
B(-4,9,-3,byg:pink_cherry_leaves)
B(-4,10,-3,byg:pink_cherry_leaves)
B(-4,11,-3,byg:pink_cherry_leaves)
B(-4,10,-2,byg:pink_cherry_leaves)
B(-4,11,-2,byg:pink_cherry_leaves)
B(-4,12,-2,byg:pink_cherry_leaves)
B(-4,13,-2,byg:pink_cherry_leaves)
B(-4,7,-1,byg:pink_cherry_leaves)
B(-4,8,-1,byg:pink_cherry_leaves)
B(-4,9,-1,byg:pink_cherry_leaves)
B(-4,10,-1,byg:cherry_log)
B(-4,12,-1,byg:pink_cherry_leaves)
B(-4,15,-1,byg:pink_cherry_leaves)
B(-4,16,-1,byg:pink_cherry_leaves)
B(-4,7,0,byg:pink_cherry_leaves)
B(-4,10,0,byg:pink_cherry_leaves)
B(-4,15,0,byg:pink_cherry_leaves)
B(-4,16,0,byg:pink_cherry_leaves)
B(-4,17,0,byg:pink_cherry_leaves)
B(-4,9,1,byg:pink_cherry_leaves)
B(-4,10,1,byg:pink_cherry_leaves)
B(-4,11,1,byg:pink_cherry_leaves)
B(-4,12,1,byg:pink_cherry_leaves)
B(-4,13,1,byg:pink_cherry_leaves)
B(-4,14,1,byg:pink_cherry_leaves)
B(-4,15,1,byg:pink_cherry_leaves)
B(-4,9,2,byg:pink_cherry_leaves)
B(-4,10,2,byg:pink_cherry_leaves)
B(-4,11,2,byg:pink_cherry_leaves)
B(-4,15,2,byg:pink_cherry_leaves)
B(-4,8,3,byg:pink_cherry_leaves)
B(-4,9,3,byg:pink_cherry_leaves)
B(-4,10,3,byg:pink_cherry_leaves)
B(-4,11,3,byg:pink_cherry_leaves)
B(-4,12,3,byg:pink_cherry_leaves)
B(-4,9,4,byg:pink_cherry_leaves)
B(-4,10,4,byg:pink_cherry_leaves)
B(-4,11,4,byg:pink_cherry_leaves)
B(-4,12,4,byg:pink_cherry_leaves)
B(-4,8,5,byg:pink_cherry_leaves)
B(-4,11,5,byg:pink_cherry_leaves)
B(-4,8,6,byg:pink_cherry_leaves)
B(-4,9,6,byg:pink_cherry_leaves)
B(-3,10,-7,byg:pink_cherry_leaves)
B(-3,10,-6,byg:pink_cherry_leaves)
B(-3,11,-6,byg:pink_cherry_leaves)
B(-3,9,-5,byg:pink_cherry_leaves)
B(-3,8,-4,byg:pink_cherry_leaves)
B(-3,9,-4,byg:pink_cherry_leaves)
B(-3,10,-4,byg:pink_cherry_leaves)
B(-3,12,-4,byg:pink_cherry_leaves)
B(-3,13,-4,byg:pink_cherry_leaves)
B(-3,9,-3,byg:pink_cherry_leaves)
B(-3,10,-3,byg:pink_cherry_leaves)
B(-3,11,-3,byg:pink_cherry_leaves)
B(-3,15,-3,byg:pink_cherry_leaves)
B(-3,10,-2,byg:pink_cherry_leaves)
B(-3,11,-2,byg:pink_cherry_leaves)
B(-3,14,-2,byg:pink_cherry_leaves)
B(-3,15,-2,byg:pink_cherry_leaves)
B(-3,17,-2,byg:pink_cherry_leaves)
B(-3,8,-1,byg:pink_cherry_leaves)
B(-3,10,-1,byg:cherry_log)
B(-3,11,-1,byg:pink_cherry_leaves)
B(-3,15,-1,byg:pink_cherry_leaves)
B(-3,9,0,byg:pink_cherry_leaves)
B(-3,10,0,byg:pink_cherry_leaves)
B(-3,13,0,byg:pink_cherry_leaves)
B(-3,14,0,byg:pink_cherry_leaves)
B(-3,15,0,byg:pink_cherry_leaves)
B(-3,16,0,byg:pink_cherry_leaves)
B(-3,17,0,byg:pink_cherry_leaves)
B(-3,18,0,byg:pink_cherry_leaves)
B(-3,8,1,byg:pink_cherry_leaves)
B(-3,9,1,byg:pink_cherry_leaves)
B(-3,11,1,byg:pink_cherry_leaves)
B(-3,13,1,byg:pink_cherry_leaves)
B(-3,14,1,byg:pink_cherry_leaves)
B(-3,9,2,byg:pink_cherry_leaves)
B(-3,13,2,byg:pink_cherry_leaves)
B(-3,14,2,byg:pink_cherry_leaves)
B(-3,15,2,byg:pink_cherry_leaves)
B(-3,16,2,byg:pink_cherry_leaves)
B(-3,11,3,byg:pink_cherry_leaves)
B(-3,12,3,byg:pink_cherry_leaves)
B(-3,13,3,byg:pink_cherry_leaves)
B(-3,7,4,byg:pink_cherry_leaves)
B(-3,10,4,byg:pink_cherry_leaves)
B(-3,11,4,byg:pink_cherry_leaves)
B(-3,12,4,byg:pink_cherry_leaves)
B(-3,7,5,byg:pink_cherry_leaves)
B(-3,8,5,byg:pink_cherry_leaves)
B(-3,9,5,byg:pink_cherry_leaves)
B(-3,10,5,byg:pink_cherry_leaves)
B(-3,11,5,byg:pink_cherry_leaves)
B(-3,8,6,byg:pink_cherry_leaves)
B(-3,10,6,byg:pink_cherry_leaves)
B(-3,11,6,byg:pink_cherry_leaves)
B(-3,11,7,byg:pink_cherry_leaves)
B(-2,9,-7,byg:pink_cherry_leaves)
B(-2,10,-7,byg:pink_cherry_leaves)
B(-2,11,-7,byg:pink_cherry_leaves)
B(-2,8,-6,byg:pink_cherry_leaves)
B(-2,9,-6,byg:pink_cherry_leaves)
B(-2,10,-6,byg:pink_cherry_leaves)
B(-2,11,-6,byg:pink_cherry_leaves)
B(-2,12,-6,byg:pink_cherry_leaves)
B(-2,7,-5,byg:pink_cherry_leaves)
B(-2,8,-5,byg:pink_cherry_leaves)
B(-2,9,-5,byg:pink_cherry_leaves)
B(-2,11,-5,byg:pink_cherry_leaves)
B(-2,12,-5,byg:pink_cherry_leaves)
B(-2,13,-5,byg:pink_cherry_leaves)
B(-2,15,-5,byg:pink_cherry_leaves)
B(-2,16,-5,byg:pink_cherry_leaves)
B(-2,7,-4,byg:pink_cherry_leaves)
B(-2,8,-4,byg:pink_cherry_leaves)
B(-2,10,-4,byg:cherry_log)
B(-2,11,-4,byg:pink_cherry_leaves)
B(-2,12,-4,byg:pink_cherry_leaves)
B(-2,13,-4,byg:pink_cherry_leaves)
B(-2,14,-4,byg:pink_cherry_leaves)
B(-2,15,-4,byg:pink_cherry_leaves)
B(-2,7,-3,byg:pink_cherry_leaves)
B(-2,10,-3,byg:cherry_log)
B(-2,11,-3,byg:pink_cherry_leaves)
B(-2,12,-3,byg:pink_cherry_leaves)
B(-2,13,-3,byg:pink_cherry_leaves)
B(-2,14,-3,byg:pink_cherry_leaves)
B(-2,15,-3,byg:pink_cherry_leaves)
B(-2,16,-3,byg:pink_cherry_leaves)
B(-2,10,-2,byg:cherry_log)
B(-2,11,-2,byg:pink_cherry_leaves)
B(-2,12,-2,byg:pink_cherry_leaves)
B(-2,13,-2,byg:pink_cherry_leaves)
B(-2,14,-2,byg:pink_cherry_leaves)
B(-2,15,-2,byg:pink_cherry_leaves)
B(-2,17,-2,byg:pink_cherry_leaves)
B(-2,9,-1,byg:pink_cherry_leaves)
B(-2,10,-1,byg:cherry_log)
B(-2,11,-1,byg:pink_cherry_leaves)
B(-2,12,-1,byg:pink_cherry_leaves)
B(-2,13,-1,byg:pink_cherry_leaves)
B(-2,14,-1,byg:pink_cherry_leaves)
B(-2,15,-1,byg:pink_cherry_leaves)
B(-2,16,-1,byg:pink_cherry_leaves)
B(-2,17,-1,byg:pink_cherry_leaves)
B(-2,18,-1,byg:pink_cherry_leaves)
B(-2,10,0,byg:pink_cherry_leaves)
B(-2,11,0,byg:pink_cherry_leaves)
B(-2,12,0,byg:pink_cherry_leaves)
B(-2,13,0,byg:pink_cherry_leaves)
B(-2,14,0,byg:pink_cherry_leaves)
B(-2,15,0,byg:cherry_log)
B(-2,16,0,byg:pink_cherry_leaves)
B(-2,17,0,byg:pink_cherry_leaves)
B(-2,18,0,byg:pink_cherry_leaves)
B(-2,9,1,byg:pink_cherry_leaves)
B(-2,10,1,byg:pink_cherry_leaves)
B(-2,11,1,byg:pink_cherry_leaves)
B(-2,12,1,byg:pink_cherry_leaves)
B(-2,14,1,byg:pink_cherry_leaves)
B(-2,17,1,byg:pink_cherry_leaves)
B(-2,18,1,byg:pink_cherry_leaves)
B(-2,19,1,byg:pink_cherry_leaves)
B(-2,8,2,byg:pink_cherry_leaves)
B(-2,10,2,byg:pink_cherry_leaves)
B(-2,11,2,byg:pink_cherry_leaves)
B(-2,13,2,byg:pink_cherry_leaves)
B(-2,14,2,byg:pink_cherry_leaves)
B(-2,15,2,byg:pink_cherry_leaves)
B(-2,16,2,byg:pink_cherry_leaves)
B(-2,17,2,byg:pink_cherry_leaves)
B(-2,8,3,byg:pink_cherry_leaves)
B(-2,9,3,byg:pink_cherry_leaves)
B(-2,10,3,byg:cherry_log)
B(-2,11,3,byg:pink_cherry_leaves)
B(-2,13,3,byg:pink_cherry_leaves)
B(-2,14,3,byg:pink_cherry_leaves)
B(-2,15,3,byg:pink_cherry_leaves)
B(-2,17,3,byg:pink_cherry_leaves)
B(-2,7,4,byg:pink_cherry_leaves)
B(-2,8,4,byg:pink_cherry_leaves)
B(-2,9,4,byg:pink_cherry_leaves)
B(-2,10,4,byg:cherry_log)
B(-2,12,4,byg:pink_cherry_leaves)
B(-2,13,4,byg:pink_cherry_leaves)
B(-2,15,4,byg:pink_cherry_leaves)
B(-2,16,4,byg:pink_cherry_leaves)
B(-2,17,4,byg:pink_cherry_leaves)
B(-2,7,5,byg:pink_cherry_leaves)
B(-2,8,5,byg:pink_cherry_leaves)
B(-2,9,5,byg:pink_cherry_leaves)
B(-2,10,5,byg:cherry_log)
B(-2,11,5,byg:pink_cherry_leaves)
B(-2,13,5,byg:pink_cherry_leaves)
B(-2,9,6,byg:pink_cherry_leaves)
B(-2,10,6,byg:pink_cherry_leaves)
B(-2,11,6,byg:pink_cherry_leaves)
B(-2,12,6,byg:pink_cherry_leaves)
B(-2,9,7,byg:pink_cherry_leaves)
B(-2,10,7,byg:pink_cherry_leaves)
B(-2,11,7,byg:pink_cherry_leaves)
B(-1,10,-7,byg:pink_cherry_leaves)
B(-1,11,-7,byg:pink_cherry_leaves)
B(-1,9,-6,byg:pink_cherry_leaves)
B(-1,11,-6,byg:pink_cherry_leaves)
B(-1,16,-6,byg:pink_cherry_leaves)
B(-1,13,-5,byg:pink_cherry_leaves)
B(-1,14,-5,byg:pink_cherry_leaves)
B(-1,15,-5,byg:pink_cherry_leaves)
B(-1,16,-5,byg:pink_cherry_leaves)
B(-1,7,-4,byg:pink_cherry_leaves)
B(-1,9,-4,byg:pink_cherry_leaves)
B(-1,10,-4,byg:pink_cherry_leaves)
B(-1,11,-4,byg:pink_cherry_leaves)
B(-1,12,-4,byg:pink_cherry_leaves)
B(-1,14,-4,byg:pink_cherry_leaves)
B(-1,15,-4,byg:pink_cherry_leaves)
B(-1,11,-3,byg:pink_cherry_leaves)
B(-1,12,-3,byg:pink_cherry_leaves)
B(-1,13,-3,byg:pink_cherry_leaves)
B(-1,14,-3,byg:pink_cherry_leaves)
B(-1,15,-3,byg:pink_cherry_leaves)
B(-1,16,-3,byg:pink_cherry_leaves)
B(-1,9,-2,byg:pink_cherry_leaves)
B(-1,12,-2,byg:pink_cherry_leaves)
B(-1,14,-2,byg:pink_cherry_leaves)
B(-1,15,-2,byg:pink_cherry_leaves)
B(-1,16,-2,byg:pink_cherry_leaves)
B(-1,10,-1,byg:cherry_log)
B(-1,13,-1,byg:pink_cherry_leaves)
B(-1,14,-1,byg:pink_cherry_leaves)
B(-1,15,-1,byg:pink_cherry_leaves)
B(-1,16,-1,byg:pink_cherry_leaves)
B(-1,17,-1,byg:pink_cherry_leaves)
B(-1,18,-1,byg:pink_cherry_leaves)
B(-1,19,-1,byg:pink_cherry_leaves)
B(-1,20,-1,byg:pink_cherry_leaves)
B(-1,14,0,byg:pink_cherry_leaves)
B(-1,15,0,byg:cherry_log)
B(-1,16,0,byg:pink_cherry_leaves)
B(-1,17,0,byg:pink_cherry_leaves)
B(-1,18,0,byg:pink_cherry_leaves)
B(-1,19,0,byg:pink_cherry_leaves)
B(-1,20,0,byg:pink_cherry_leaves)
B(-1,9,1,byg:pink_cherry_leaves)
B(-1,10,1,byg:pink_cherry_leaves)
B(-1,12,1,byg:pink_cherry_leaves)
B(-1,13,1,byg:pink_cherry_leaves)
B(-1,14,1,byg:pink_cherry_leaves)
B(-1,15,1,byg:pink_cherry_leaves)
B(-1,16,1,byg:pink_cherry_leaves)
B(-1,17,1,byg:pink_cherry_leaves)
B(-1,18,1,byg:pink_cherry_leaves)
B(-1,9,2,byg:pink_cherry_leaves)
B(-1,10,2,byg:pink_cherry_leaves)
B(-1,12,2,byg:pink_cherry_leaves)
B(-1,13,2,byg:pink_cherry_leaves)
B(-1,14,2,byg:pink_cherry_leaves)
B(-1,15,2,byg:pink_cherry_leaves)
B(-1,16,2,byg:pink_cherry_leaves)
B(-1,17,2,byg:pink_cherry_leaves)
B(-1,18,2,byg:pink_cherry_leaves)
B(-1,9,3,byg:pink_cherry_leaves)
B(-1,10,3,byg:cherry_log)
B(-1,11,3,byg:pink_cherry_leaves)
B(-1,12,3,byg:pink_cherry_leaves)
B(-1,13,3,byg:pink_cherry_leaves)
B(-1,14,3,byg:pink_cherry_leaves)
B(-1,8,4,byg:pink_cherry_leaves)
B(-1,11,4,byg:pink_cherry_leaves)
B(-1,12,4,byg:pink_cherry_leaves)
B(-1,13,4,byg:pink_cherry_leaves)
B(-1,15,4,byg:pink_cherry_leaves)
B(-1,16,4,byg:pink_cherry_leaves)
B(-1,17,4,byg:pink_cherry_leaves)
B(-1,10,5,byg:pink_cherry_leaves)
B(-1,16,5,byg:pink_cherry_leaves)
B(-1,9,6,byg:pink_cherry_leaves)
B(-1,10,6,byg:pink_cherry_leaves)
B(-1,12,6,byg:pink_cherry_leaves)
B(-1,10,7,byg:pink_cherry_leaves)
B(-1,11,7,byg:pink_cherry_leaves)
B(0,8,-6,byg:pink_cherry_leaves)
B(0,9,-6,byg:pink_cherry_leaves)
B(0,15,-6,byg:pink_cherry_leaves)
B(0,16,-6,byg:pink_cherry_leaves)
B(0,9,-5,byg:pink_cherry_leaves)
B(0,10,-5,byg:pink_cherry_leaves)
B(0,12,-5,byg:pink_cherry_leaves)
B(0,15,-5,byg:pink_cherry_leaves)
B(0,16,-5,byg:pink_cherry_leaves)
B(0,9,-4,byg:pink_cherry_leaves)
B(0,10,-4,byg:pink_cherry_leaves)
B(0,11,-4,byg:pink_cherry_leaves)
B(0,12,-4,byg:pink_cherry_leaves)
B(0,13,-4,byg:pink_cherry_leaves)
B(0,15,-4,byg:pink_cherry_leaves)
B(0,16,-4,byg:pink_cherry_leaves)
B(0,18,-4,byg:pink_cherry_leaves)
B(0,8,-3,byg:pink_cherry_leaves)
B(0,10,-3,byg:pink_cherry_leaves)
B(0,12,-3,byg:pink_cherry_leaves)
B(0,13,-3,byg:pink_cherry_leaves)
B(0,14,-3,byg:pink_cherry_leaves)
B(0,15,-3,byg:cherry_log)
B(0,16,-3,byg:pink_cherry_leaves)
B(0,17,-3,byg:pink_cherry_leaves)
B(0,19,-3,byg:pink_cherry_leaves)
B(0,8,-2,byg:pink_cherry_leaves)
B(0,9,-2,byg:pink_cherry_leaves)
B(0,10,-2,byg:pink_cherry_leaves)
B(0,13,-2,byg:pink_cherry_leaves)
B(0,14,-2,byg:pink_cherry_leaves)
B(0,15,-2,byg:cherry_log)
B(0,16,-2,byg:pink_cherry_leaves)
B(0,18,-2,byg:pink_cherry_leaves)
B(0,0,-1,byg:cherry_log)
B(0,1,-1,byg:cherry_log)
B(0,2,-1,byg:cherry_log)
B(0,3,-1,byg:cherry_log)
B(0,4,-1,byg:cherry_log)
B(0,5,-1,byg:cherry_log)
B(0,6,-1,byg:cherry_log)
B(0,7,-1,byg:cherry_log)
B(0,8,-1,byg:cherry_log)
B(0,9,-1,byg:cherry_log)
B(0,10,-1,byg:cherry_log)
B(0,11,-1,byg:cherry_log)
B(0,12,-1,byg:cherry_log)
B(0,13,-1,byg:cherry_log)
B(0,14,-1,byg:cherry_log)
B(0,15,-1,byg:cherry_log)
B(0,16,-1,byg:cherry_log)
B(0,17,-1,byg:cherry_log)
B(0,18,-1,byg:cherry_log)
B(0,19,-1,byg:pink_cherry_leaves)
B(0,0,0,byg:cherry_log)
B(0,1,0,byg:cherry_log)
B(0,2,0,byg:cherry_log)
B(0,3,0,byg:cherry_log)
B(0,4,0,byg:cherry_log)
B(0,5,0,byg:cherry_log)
B(0,6,0,byg:cherry_log)
B(0,7,0,byg:cherry_log)
B(0,8,0,byg:cherry_log)
B(0,9,0,byg:cherry_log)
B(0,10,0,byg:cherry_log)
B(0,11,0,byg:cherry_log)
B(0,12,0,byg:cherry_log)
B(0,13,0,byg:cherry_log)
B(0,14,0,byg:cherry_log)
B(0,15,0,byg:cherry_log)
B(0,16,0,byg:cherry_log)
B(0,17,0,byg:cherry_log)
B(0,18,0,byg:cherry_log)
B(0,19,0,byg:pink_cherry_leaves)
B(0,20,0,byg:pink_cherry_leaves)
B(0,21,0,byg:pink_cherry_leaves)
B(0,12,1,byg:pink_cherry_leaves)
B(0,13,1,byg:pink_cherry_leaves)
B(0,14,1,byg:pink_cherry_leaves)
B(0,15,1,byg:cherry_log)
B(0,16,1,byg:pink_cherry_leaves)
B(0,17,1,byg:pink_cherry_leaves)
B(0,18,1,byg:pink_cherry_leaves)
B(0,9,2,byg:pink_cherry_leaves)
B(0,10,2,byg:pink_cherry_leaves)
B(0,12,2,byg:pink_cherry_leaves)
B(0,13,2,byg:pink_cherry_leaves)
B(0,14,2,byg:pink_cherry_leaves)
B(0,15,2,byg:cherry_log)
B(0,16,2,byg:pink_cherry_leaves)
B(0,17,2,byg:pink_cherry_leaves)
B(0,18,2,byg:pink_cherry_leaves)
B(0,10,3,byg:cherry_log)
B(0,14,3,byg:pink_cherry_leaves)
B(0,15,3,byg:pink_cherry_leaves)
B(0,16,3,byg:pink_cherry_leaves)
B(0,17,3,byg:pink_cherry_leaves)
B(0,18,3,byg:pink_cherry_leaves)
B(0,11,4,byg:pink_cherry_leaves)
B(0,12,4,byg:pink_cherry_leaves)
B(0,14,4,byg:pink_cherry_leaves)
B(0,16,4,byg:pink_cherry_leaves)
B(0,10,5,byg:pink_cherry_leaves)
B(0,12,5,byg:pink_cherry_leaves)
B(0,15,5,byg:pink_cherry_leaves)
B(0,16,5,byg:pink_cherry_leaves)
B(0,10,6,byg:pink_cherry_leaves)
B(1,15,-6,byg:pink_cherry_leaves)
B(1,9,-5,byg:pink_cherry_leaves)
B(1,15,-5,byg:pink_cherry_leaves)
B(1,9,-4,byg:pink_cherry_leaves)
B(1,10,-4,byg:pink_cherry_leaves)
B(1,11,-4,byg:pink_cherry_leaves)
B(1,13,-4,byg:pink_cherry_leaves)
B(1,17,-4,byg:pink_cherry_leaves)
B(1,18,-4,byg:pink_cherry_leaves)
B(1,9,-3,byg:pink_cherry_leaves)
B(1,10,-3,byg:pink_cherry_leaves)
B(1,11,-3,byg:pink_cherry_leaves)
B(1,13,-3,byg:pink_cherry_leaves)
B(1,14,-3,byg:pink_cherry_leaves)
B(1,16,-3,byg:pink_cherry_leaves)
B(1,17,-3,byg:pink_cherry_leaves)
B(1,18,-3,byg:pink_cherry_leaves)
B(1,19,-3,byg:pink_cherry_leaves)
B(1,14,-2,byg:pink_cherry_leaves)
B(1,15,-2,byg:pink_cherry_leaves)
B(1,16,-2,byg:pink_cherry_leaves)
B(1,17,-2,byg:pink_cherry_leaves)
B(1,18,-2,byg:pink_cherry_leaves)
B(1,19,-2,byg:pink_cherry_leaves)
B(1,0,-1,byg:cherry_log)
B(1,1,-1,byg:cherry_log)
B(1,2,-1,byg:cherry_log)
B(1,3,-1,byg:cherry_log)
B(1,4,-1,byg:cherry_log)
B(1,5,-1,byg:cherry_log)
B(1,6,-1,byg:cherry_log)
B(1,7,-1,byg:cherry_log)
B(1,8,-1,byg:cherry_log)
B(1,9,-1,byg:cherry_log)
B(1,10,-1,byg:cherry_log)
B(1,11,-1,byg:cherry_log)
B(1,12,-1,byg:cherry_log)
B(1,13,-1,byg:cherry_log)
B(1,14,-1,byg:cherry_log)
B(1,15,-1,byg:cherry_log)
B(1,16,-1,byg:cherry_log)
B(1,17,-1,byg:cherry_log)
B(1,18,-1,byg:cherry_log)
B(1,19,-1,byg:pink_cherry_leaves)
B(1,0,0,byg:cherry_log)
B(1,1,0,byg:cherry_log)
B(1,2,0,byg:cherry_log)
B(1,3,0,byg:cherry_log)
B(1,4,0,byg:cherry_log)
B(1,5,0,byg:cherry_log)
B(1,6,0,byg:cherry_log)
B(1,7,0,byg:cherry_log)
B(1,8,0,byg:cherry_log)
B(1,9,0,byg:cherry_log)
B(1,10,0,byg:cherry_log)
B(1,11,0,byg:cherry_log)
B(1,12,0,byg:cherry_log)
B(1,13,0,byg:cherry_log)
B(1,14,0,byg:cherry_log)
B(1,15,0,byg:cherry_log)
B(1,16,0,byg:cherry_log)
B(1,17,0,byg:cherry_log)
B(1,18,0,byg:cherry_log)
B(1,19,0,byg:pink_cherry_leaves)
B(1,20,0,byg:pink_cherry_leaves)
B(1,21,0,byg:pink_cherry_leaves)
B(1,10,1,byg:cherry_log)
B(1,13,1,byg:pink_cherry_leaves)
B(1,14,1,byg:pink_cherry_leaves)
B(1,15,1,byg:pink_cherry_leaves)
B(1,16,1,byg:pink_cherry_leaves)
B(1,18,1,byg:pink_cherry_leaves)
B(1,19,1,byg:pink_cherry_leaves)
B(1,21,1,byg:pink_cherry_leaves)
B(1,9,2,byg:pink_cherry_leaves)
B(1,10,2,byg:cherry_log)
B(1,11,2,byg:pink_cherry_leaves)
B(1,13,2,byg:pink_cherry_leaves)
B(1,15,2,byg:pink_cherry_leaves)
B(1,16,2,byg:pink_cherry_leaves)
B(1,17,2,byg:pink_cherry_leaves)
B(1,18,2,byg:pink_cherry_leaves)
B(1,19,2,byg:pink_cherry_leaves)
B(1,20,2,byg:pink_cherry_leaves)
B(1,10,3,byg:cherry_log)
B(1,11,3,byg:pink_cherry_leaves)
B(1,13,3,byg:pink_cherry_leaves)
B(1,17,3,byg:pink_cherry_leaves)
B(1,18,3,byg:pink_cherry_leaves)
B(1,19,3,byg:pink_cherry_leaves)
B(1,9,4,byg:pink_cherry_leaves)
B(1,10,4,byg:pink_cherry_leaves)
B(1,13,4,byg:pink_cherry_leaves)
B(1,15,4,byg:pink_cherry_leaves)
B(1,16,4,byg:pink_cherry_leaves)
B(1,10,5,byg:pink_cherry_leaves)
B(1,11,5,byg:pink_cherry_leaves)
B(1,15,5,byg:pink_cherry_leaves)
B(2,9,-6,byg:pink_cherry_leaves)
B(2,10,-6,byg:pink_cherry_leaves)
B(2,10,-5,byg:pink_cherry_leaves)
B(2,11,-5,byg:pink_cherry_leaves)
B(2,12,-5,byg:pink_cherry_leaves)
B(2,13,-5,byg:pink_cherry_leaves)
B(2,15,-5,byg:pink_cherry_leaves)
B(2,9,-4,byg:pink_cherry_leaves)
B(2,10,-4,byg:pink_cherry_leaves)
B(2,12,-4,byg:pink_cherry_leaves)
B(2,15,-4,byg:pink_cherry_leaves)
B(2,16,-4,byg:pink_cherry_leaves)
B(2,10,-3,byg:pink_cherry_leaves)
B(2,11,-3,byg:pink_cherry_leaves)
B(2,12,-3,byg:pink_cherry_leaves)
B(2,14,-3,byg:pink_cherry_leaves)
B(2,15,-3,byg:pink_cherry_leaves)
B(2,17,-3,byg:pink_cherry_leaves)
B(2,10,-2,byg:pink_cherry_leaves)
B(2,12,-2,byg:pink_cherry_leaves)
B(2,15,-2,byg:pink_cherry_leaves)
B(2,16,-2,byg:pink_cherry_leaves)
B(2,17,-2,byg:pink_cherry_leaves)
B(2,18,-2,byg:pink_cherry_leaves)
B(2,10,-1,byg:cherry_log)
B(2,13,-1,byg:pink_cherry_leaves)
B(2,15,-1,byg:cherry_log)
B(2,16,-1,byg:pink_cherry_leaves)
B(2,17,-1,byg:pink_cherry_leaves)
B(2,8,0,byg:pink_cherry_leaves)
B(2,10,0,byg:pink_cherry_leaves)
B(2,12,0,byg:pink_cherry_leaves)
B(2,13,0,byg:pink_cherry_leaves)
B(2,14,0,byg:pink_cherry_leaves)
B(2,15,0,byg:cherry_log)
B(2,16,0,byg:pink_cherry_leaves)
B(2,18,0,byg:pink_cherry_leaves)
B(2,21,0,byg:pink_cherry_leaves)
B(2,8,1,byg:pink_cherry_leaves)
B(2,12,1,byg:pink_cherry_leaves)
B(2,13,1,byg:pink_cherry_leaves)
B(2,16,1,byg:pink_cherry_leaves)
B(2,18,1,byg:pink_cherry_leaves)
B(2,19,1,byg:pink_cherry_leaves)
B(2,20,1,byg:pink_cherry_leaves)
B(2,21,1,byg:pink_cherry_leaves)
B(2,10,2,byg:cherry_log)
B(2,11,2,byg:pink_cherry_leaves)
B(2,12,2,byg:pink_cherry_leaves)
B(2,13,2,byg:pink_cherry_leaves)
B(2,15,2,byg:pink_cherry_leaves)
B(2,17,2,byg:pink_cherry_leaves)
B(2,18,2,byg:pink_cherry_leaves)
B(2,10,3,byg:pink_cherry_leaves)
B(2,11,3,byg:pink_cherry_leaves)
B(2,9,4,byg:pink_cherry_leaves)
B(2,10,4,byg:pink_cherry_leaves)
B(3,10,-7,byg:pink_cherry_leaves)
B(3,8,-6,byg:pink_cherry_leaves)
B(3,10,-6,byg:pink_cherry_leaves)
B(3,11,-5,byg:pink_cherry_leaves)
B(3,13,-5,byg:pink_cherry_leaves)
B(3,9,-4,byg:pink_cherry_leaves)
B(3,10,-4,byg:cherry_log)
B(3,11,-4,byg:pink_cherry_leaves)
B(3,14,-4,byg:pink_cherry_leaves)
B(3,15,-4,byg:pink_cherry_leaves)
B(3,10,-3,byg:cherry_log)
B(3,12,-3,byg:pink_cherry_leaves)
B(3,13,-3,byg:pink_cherry_leaves)
B(3,15,-3,byg:pink_cherry_leaves)
B(3,16,-3,byg:pink_cherry_leaves)
B(3,9,-2,byg:pink_cherry_leaves)
B(3,10,-2,byg:cherry_log)
B(3,13,-2,byg:pink_cherry_leaves)
B(3,14,-2,byg:pink_cherry_leaves)
B(3,15,-2,byg:pink_cherry_leaves)
B(3,16,-2,byg:pink_cherry_leaves)
B(3,17,-2,byg:pink_cherry_leaves)
B(3,19,-2,byg:pink_cherry_leaves)
B(3,20,-2,byg:pink_cherry_leaves)
B(3,10,-1,byg:cherry_log)
B(3,11,-1,byg:pink_cherry_leaves)
B(3,13,-1,byg:pink_cherry_leaves)
B(3,15,-1,byg:cherry_log)
B(3,16,-1,byg:pink_cherry_leaves)
B(3,17,-1,byg:pink_cherry_leaves)
B(3,18,-1,byg:pink_cherry_leaves)
B(3,19,-1,byg:pink_cherry_leaves)
B(3,20,-1,byg:pink_cherry_leaves)
B(3,8,0,byg:pink_cherry_leaves)
B(3,9,0,byg:pink_cherry_leaves)
B(3,10,0,byg:pink_cherry_leaves)
B(3,12,0,byg:pink_cherry_leaves)
B(3,14,0,byg:pink_cherry_leaves)
B(3,16,0,byg:pink_cherry_leaves)
B(3,17,0,byg:pink_cherry_leaves)
B(3,18,0,byg:pink_cherry_leaves)
B(3,19,0,byg:pink_cherry_leaves)
B(3,7,1,byg:pink_cherry_leaves)
B(3,8,1,byg:pink_cherry_leaves)
B(3,9,1,byg:pink_cherry_leaves)
B(3,10,1,byg:pink_cherry_leaves)
B(3,11,1,byg:pink_cherry_leaves)
B(3,13,1,byg:pink_cherry_leaves)
B(3,14,1,byg:pink_cherry_leaves)
B(3,15,1,byg:pink_cherry_leaves)
B(3,16,1,byg:pink_cherry_leaves)
B(3,17,1,byg:pink_cherry_leaves)
B(3,18,1,byg:pink_cherry_leaves)
B(3,19,1,byg:pink_cherry_leaves)
B(3,7,2,byg:pink_cherry_leaves)
B(3,8,2,byg:pink_cherry_leaves)
B(3,9,2,byg:pink_cherry_leaves)
B(3,10,2,byg:cherry_log)
B(3,11,2,byg:pink_cherry_leaves)
B(3,12,2,byg:pink_cherry_leaves)
B(3,13,2,byg:pink_cherry_leaves)
B(3,14,2,byg:pink_cherry_leaves)
B(3,15,2,byg:pink_cherry_leaves)
B(3,16,2,byg:pink_cherry_leaves)
B(3,17,2,byg:pink_cherry_leaves)
B(3,8,3,byg:pink_cherry_leaves)
B(3,9,3,byg:pink_cherry_leaves)
B(3,12,3,byg:pink_cherry_leaves)
B(3,13,3,byg:pink_cherry_leaves)
B(3,15,3,byg:pink_cherry_leaves)
B(3,8,4,byg:pink_cherry_leaves)
B(3,9,4,byg:pink_cherry_leaves)
B(3,11,4,byg:pink_cherry_leaves)
B(4,9,-7,byg:pink_cherry_leaves)
B(4,10,-7,byg:pink_cherry_leaves)
B(4,11,-7,byg:pink_cherry_leaves)
B(4,8,-6,byg:pink_cherry_leaves)
B(4,9,-6,byg:pink_cherry_leaves)
B(4,10,-6,byg:pink_cherry_leaves)
B(4,9,-5,byg:pink_cherry_leaves)
B(4,11,-5,byg:pink_cherry_leaves)
B(4,13,-5,byg:pink_cherry_leaves)
B(4,7,-4,byg:pink_cherry_leaves)
B(4,9,-4,byg:pink_cherry_leaves)
B(4,10,-4,byg:cherry_log)
B(4,11,-4,byg:pink_cherry_leaves)
B(4,12,-4,byg:pink_cherry_leaves)
B(4,13,-4,byg:pink_cherry_leaves)
B(4,15,-4,byg:pink_cherry_leaves)
B(4,10,-3,byg:pink_cherry_leaves)
B(4,12,-3,byg:pink_cherry_leaves)
B(4,13,-3,byg:pink_cherry_leaves)
B(4,15,-3,byg:pink_cherry_leaves)
B(4,10,-2,byg:pink_cherry_leaves)
B(4,11,-2,byg:pink_cherry_leaves)
B(4,12,-2,byg:pink_cherry_leaves)
B(4,13,-2,byg:pink_cherry_leaves)
B(4,15,-2,byg:pink_cherry_leaves)
B(4,16,-2,byg:pink_cherry_leaves)
B(4,10,-1,byg:pink_cherry_leaves)
B(4,11,-1,byg:pink_cherry_leaves)
B(4,13,-1,byg:pink_cherry_leaves)
B(4,14,-1,byg:pink_cherry_leaves)
B(4,15,-1,byg:pink_cherry_leaves)
B(4,16,-1,byg:pink_cherry_leaves)
B(4,17,-1,byg:pink_cherry_leaves)
B(4,18,-1,byg:pink_cherry_leaves)
B(4,19,-1,byg:pink_cherry_leaves)
B(4,8,0,byg:pink_cherry_leaves)
B(4,9,0,byg:pink_cherry_leaves)
B(4,12,0,byg:pink_cherry_leaves)
B(4,15,0,byg:pink_cherry_leaves)
B(4,16,0,byg:pink_cherry_leaves)
B(4,17,0,byg:pink_cherry_leaves)
B(4,18,0,byg:pink_cherry_leaves)
B(4,19,0,byg:pink_cherry_leaves)
B(4,7,1,byg:pink_cherry_leaves)
B(4,9,1,byg:pink_cherry_leaves)
B(4,11,1,byg:pink_cherry_leaves)
B(4,12,1,byg:pink_cherry_leaves)
B(4,13,1,byg:pink_cherry_leaves)
B(4,14,1,byg:pink_cherry_leaves)
B(4,15,1,byg:pink_cherry_leaves)
B(4,17,1,byg:pink_cherry_leaves)
B(4,19,1,byg:pink_cherry_leaves)
B(4,7,2,byg:pink_cherry_leaves)
B(4,9,2,byg:pink_cherry_leaves)
B(4,10,2,byg:cherry_log)
B(4,12,2,byg:pink_cherry_leaves)
B(4,13,2,byg:pink_cherry_leaves)
B(4,15,2,byg:pink_cherry_leaves)
B(4,7,3,byg:pink_cherry_leaves)
B(4,9,3,byg:pink_cherry_leaves)
B(4,10,3,byg:cherry_log)
B(4,12,3,byg:pink_cherry_leaves)
B(4,8,4,byg:pink_cherry_leaves)
B(4,9,4,byg:pink_cherry_leaves)
B(4,10,4,byg:pink_cherry_leaves)
B(4,11,4,byg:pink_cherry_leaves)
B(4,12,4,byg:pink_cherry_leaves)
B(4,10,5,byg:pink_cherry_leaves)
B(4,11,5,byg:pink_cherry_leaves)
B(5,9,-7,byg:pink_cherry_leaves)
B(5,9,-6,byg:pink_cherry_leaves)
B(5,11,-6,byg:pink_cherry_leaves)
B(5,7,-5,byg:pink_cherry_leaves)
B(5,7,-4,byg:pink_cherry_leaves)
B(5,8,-4,byg:pink_cherry_leaves)
B(5,9,-4,byg:pink_cherry_leaves)
B(5,10,-4,byg:pink_cherry_leaves)
B(5,11,-4,byg:pink_cherry_leaves)
B(5,12,-4,byg:pink_cherry_leaves)
B(5,11,-3,byg:pink_cherry_leaves)
B(5,13,-3,byg:pink_cherry_leaves)
B(5,13,-2,byg:pink_cherry_leaves)
B(5,14,-2,byg:pink_cherry_leaves)
B(5,9,-1,byg:pink_cherry_leaves)
B(5,10,-1,byg:pink_cherry_leaves)
B(5,11,-1,byg:pink_cherry_leaves)
B(5,13,-1,byg:pink_cherry_leaves)
B(5,14,-1,byg:pink_cherry_leaves)
B(5,15,-1,byg:pink_cherry_leaves)
B(5,16,-1,byg:pink_cherry_leaves)
B(5,17,-1,byg:pink_cherry_leaves)
B(5,12,0,byg:pink_cherry_leaves)
B(5,13,0,byg:pink_cherry_leaves)
B(5,14,0,byg:pink_cherry_leaves)
B(5,17,0,byg:pink_cherry_leaves)
B(5,10,1,byg:pink_cherry_leaves)
B(5,11,1,byg:pink_cherry_leaves)
B(5,13,1,byg:pink_cherry_leaves)
B(5,7,2,byg:pink_cherry_leaves)
B(5,9,2,byg:pink_cherry_leaves)
B(5,10,2,byg:pink_cherry_leaves)
B(5,12,2,byg:pink_cherry_leaves)
B(5,8,3,byg:pink_cherry_leaves)
B(5,9,3,byg:pink_cherry_leaves)
B(5,10,3,byg:pink_cherry_leaves)
B(5,12,3,byg:pink_cherry_leaves)
B(5,8,4,byg:pink_cherry_leaves)
B(5,9,4,byg:pink_cherry_leaves)
B(5,10,4,byg:pink_cherry_leaves)
B(5,11,4,byg:pink_cherry_leaves)
B(5,10,5,byg:pink_cherry_leaves)
B(6,10,-6,byg:pink_cherry_leaves)
B(6,11,-6,byg:pink_cherry_leaves)
B(6,12,-6,byg:pink_cherry_leaves)
B(6,11,-5,byg:pink_cherry_leaves)
B(6,8,-4,byg:pink_cherry_leaves)
B(6,10,-4,byg:pink_cherry_leaves)
B(6,11,-4,byg:pink_cherry_leaves)
B(6,8,-3,byg:pink_cherry_leaves)
B(6,15,-2,byg:pink_cherry_leaves)
B(6,14,-1,byg:pink_cherry_leaves)
B(6,15,-1,byg:pink_cherry_leaves)
B(6,16,-1,byg:pink_cherry_leaves)
B(6,16,0,byg:pink_cherry_leaves)
B(6,10,1,byg:pink_cherry_leaves)
B(6,11,1,byg:pink_cherry_leaves)
B(6,8,2,byg:pink_cherry_leaves)
B(6,9,2,byg:pink_cherry_leaves)
B(6,10,2,byg:pink_cherry_leaves)
B(6,11,2,byg:pink_cherry_leaves)
B(6,12,2,byg:pink_cherry_leaves)
B(6,10,3,byg:pink_cherry_leaves)
B(6,8,4,byg:pink_cherry_leaves)
B(6,10,4,byg:pink_cherry_leaves)
B(7,10,-5,byg:pink_cherry_leaves)
B(7,9,-4,byg:pink_cherry_leaves)
B(7,10,-4,byg:pink_cherry_leaves)
B(7,11,-4,byg:pink_cherry_leaves)
B(7,9,-3,byg:pink_cherry_leaves)
B(7,10,1,byg:pink_cherry_leaves)
B(7,11,1,byg:pink_cherry_leaves)
B(7,10,2,byg:pink_cherry_leaves)
B(7,9,3,byg:pink_cherry_leaves)
B(7,10,3,byg:pink_cherry_leaves)

#######################################################################
# +-----------------------------------------------------------------+ #
# |                            BO3 checks                           | #
# +-----------------------------------------------------------------+ #
#######################################################################

# Require a condition at a certain location in order for the BO3 to be spawned.
# BlockCheck(x,y,z,BlockName[,BlockName[,...]]) - one of the blocks must be at the location
# BlockCheckNot(x,y,z,BlockName[,BlockName[,...]]) - all the blocks must not be at the location
# LightCheck(x,y,z,minLightLevel,maxLightLevel) - light must be between min and max (inclusive)
# ModCheck(ModName[,ModName[,...]]) - all the mods listed must be loaded
# ModCheckNot(ModName[,ModName[,...]]) - all the mods listed must not be loaded

# You can use "Solid" as a BlockName for matching all solid blocks or "All" to match all blocks that aren't air.

# Examples:
#   BlockCheck(0,-1,0,GRASS,DIRT)  Require grass or dirt just below the object
#   BlockCheck(0,-1,0,Solid)		Require any solid block just below the object
#   BlockCheck(0,-1,0,WOOL)		Require any type of wool just below the object
#   BlockCheck(0,-1,0,WOOL:0)	  Require white wool just below the object
#   BlockCheckNot(0,-1,0,WOOL:0)	Require that there is no white wool below the object
#   LightCheck(0,0,0,0,1)		  Require almost complete darkness just below the object
BlockCheck(0,-1,0,minecraft:grass_block,minecraft:dirt)
BlockCheck(1,-1,0,Solid)
BlockCheck(1,-1,-1,Solid)
BlockCheck(1,-1,1,Solid)
BlockCheck(0,-1,1,Solid)
BlockCheck(0,-1,-1,Solid)
BlockCheck(-1,-1,1,Solid)
BlockCheck(-1,-1,0,Solid)
BlockCheck(-1,-1,-1,Solid)
BlockCheck(2,-1,2,Solid)
BlockCheck(2,-1,1,Solid)
BlockCheck(2,-1,0,Solid)
BlockCheck(2,-1,-1,Solid)
BlockCheck(2,-1,-2,Solid)
BlockCheck(1,-1,2,Solid)
BlockCheck(1,-1,-2,Solid)
BlockCheck(0,-1,2,Solid)
BlockCheck(0,-1,-2,Solid)
BlockCheck(-1,-1,2,Solid)
BlockCheck(-1,-1,-2,Solid)
BlockCheck(-2,-1,2,Solid)
BlockCheck(-2,-1,1,Solid)
BlockCheck(-2,-1,0,Solid)
BlockCheck(-2,-1,-1,Solid)
BlockCheck(-2,-1,-2,Solid)

#######################################################################
# +-----------------------------------------------------------------+ #
# |                             Branches                            | #
# +-----------------------------------------------------------------+ #
#######################################################################

# Branches are child-BO3's that spawn if this BO3 is configured to spawn as a
# CustomStructure resource in a biome config. Branches can have branches,
# making complex structures possible. See the wiki for more details.

# Regular Branches spawn each branch with an independent chance of spawning.
# Branch(x,y,z,branchName,rotation,chance[,anotherBranchName,rotation,chance[,...]][IndividualChance])
# branchName - name of the object to spawn.
# rotation - NORTH, SOUTH, EAST or WEST.
# IndividualChance - The chance each branch has to spawn, assumed to be 100 when left blank
# isRequiredBranch - If this is set to true then at least one of the branches in this BO3 must spawn at these x,y,z coordinates. If no branch can spawn there then this BO3 fails to spawn and its branch is rolled back.
# isRequiredBranch:true branches must spawn or the current branch is rolled back entirely. This is useful for grouping BO3's that must spawn together, for instance a single room made of multiple BO3's/branches.
# If all parts of the room are connected together via isRequiredBranch:true branches then either the entire room will spawns or no part of it will spawn.
# *Note: When isRequiredBranch:true only one BO3 can be added per Branch() and it will automatically have a rarity of 100.0.
# isRequiredBranch:false branches are used to make optional parts of structures, for instance the middle section of a tunnel that has a beginning, middle and end BO3/branch and can have a variable length by repeating the middle BO3/branch.
# By making the start and end branches isRequiredBranch:true and the middle branch isRequiredbranch:false you can make it so that either:
# A. A tunnel spawns with at least a beginning and end branch
# B. A tunnel spawns with a beginning and end branch and as many middle branches as will fit in the available space.
# C. No tunnel spawns at all because there wasn't enough space to spawn at least a beginning and end branch.
# branchDepth - When creating a chain of branches that contains optional (isRequiredBranch:false) branches branch depth is configured for the first BO3 in the chain to determine the maximum length of the chain.
# branchDepth - 1 is inherited by each isRequiredBranch:false branch in the chain. When branchDepth is zero isRequiredBranch:false branches cannot spawn and the chain ends. In the case of the tunnel this means the last middle branch would be
# rolled back and an IsRequiredBranch:true end branch could be spawned in its place to make sure the tunnel has a proper ending.
# Instead of inheriting branchDepth - 1 from the parent branchDepth can be overridden by child branches if it is set higher than 0 (the default value).
# isRequiredBranch:true branches do inherit branchDepth and pass it on to their own branches, however they cannot be prevented from spawning by it and also don't subtract 1 from branchDepth when inheriting it.

# Weighted Branches spawn branches with a dependent chance of spawning.
# WeightedBranch(x,y,z,branchName,rotation,chance[,anotherBranchName,rotation,chance[,...]][MaxChanceOutOf])
# *Note: isRequiredBranch must be set to false. It is not possible to use isRequiredBranch:true with WeightedBranch() since isRequired:true branches must spawn and automatically have a rarity of 100.0.
# MaxChanceOutOf - The chance all branches have to spawn out of, assumed to be 100 when left blank

#######################################################################
# +-----------------------------------------------------------------+ #
# |                             Entities                            | #
# +-----------------------------------------------------------------+ #
#######################################################################

# Forge only (this may have changed, check for updates).
# An EntityFunction spawns an entity instead of a block. The entity is spawned only once when the BO3 is spawned.
# Entities are persistent by default so they don't de-spawn when no player is near, they are only unloaded.
# Usage: Entity(x,y,z,entityName,groupSize,NameTagOrNBTFileName) or Entity(x,y,z,mobName,groupSize)
# Use /otg entities to get a list of entities that can be used as entityName, this includes entities added by other mods and non-living entities.
# NameTagOrNBTFileName can be either a nametag for the mob or an .txt file with nbt data (such as myentityinfo.txt).
# In the text file you can use the same mob spawning parameters used with the /summon command to equip the
# entity and give it custom attributes etc. You can copy the DATA part of a summon command including surrounding 
# curly braces to a .txt file, for instance for: "/summon Skeleton x y z {DATA}"
# *Note: Unlike Block(), for Entity() .nbt files don't work, only .txt files work.
