
#######################################################################
# +-----------------------------------------------------------------+ #
# |                            BO4 object                           | #
# +-----------------------------------------------------------------+ #
#######################################################################

Author: Unknown

Description: No description given

SettingsMode: WriteWithoutComments


#######################################################################
# +-----------------------------------------------------------------+ #
# |                          Main settings                          | #
# +-----------------------------------------------------------------+ #
#######################################################################

FixedRotation: 

Frequency: 0

SpawnHeight: highestBlock

UseCenterForHighestBlock: true

##############################
# Height Limits for the BO4. #
##############################

MinHeight: 0

MaxHeight: 255

InheritBO3: 

InheritBO3Rotation: NORTH

OverrideChildSettings: true

OverrideParentHeight: false

CanOverride: false

BranchFrequency: 0

BranchFrequencyGroup: 

MustBeBelowOther: false

MustBeInside: 

CannotBeInside: 

ReplacesBO3: 

MustBeInsideWorldBorders: false

CanSpawnOnWater: true

SpawnOnWaterOnly: false

SpawnUnderWater: false

SpawnAtWaterLevel: false

HeightOffset: 0

RemoveAir: true

ReplaceAbove: 

ReplaceBelow: 

ReplaceWithBiomeBlocks: true

ReplaceWithSurfaceBlock: GRASS

ReplaceWithGroundBlock: DIRT

ReplaceWithStoneBlock: STONE

SmoothRadius: 0

SmoothHeightOffset: 0

SmoothStartTop: false

SmoothStartWood: false

SmoothingSurfaceBlock: 

SmoothingGroundBlock: 

BO3Group: 

IsSpawnPoint: false

DoReplaceBlocks: true


#######################################################################
# +-----------------------------------------------------------------+ #
# |                              Blocks                             | #
# +-----------------------------------------------------------------+ #
#######################################################################

B(-8,0,-7,minecraft:stone)
B(-8,1,-7,minecraft:stone)
B(-8,2,-7,minecraft:stone)
B(-8,3,-7,minecraft:stone)
B(-8,4,-7,minecraft:stone)
B(-8,5,-7,minecraft:stone)
B(-8,6,-7,minecraft:stone)
B(-8,7,-7,minecraft:stone)
B(-8,8,-7,minecraft:stone)
B(-8,9,-7,minecraft:stone)
B(-8,10,-7,minecraft:granite)
B(-8,11,-7,minecraft:granite)
B(-8,12,-7,minecraft:granite)
B(-8,13,-7,minecraft:stone)
B(-8,14,-7,minecraft:stone)
B(-8,15,-7,minecraft:stone)
B(-8,16,-7,minecraft:stone)
B(-8,17,-7,minecraft:stone)
B(-8,18,-7,minecraft:stone)
B(-8,19,-7,minecraft:granite)
B(-8,20,-7,minecraft:granite)
B(-8,21,-7,minecraft:granite)
B(-8,22,-7,minecraft:granite)
B(-8,23,-7,minecraft:granite)
B(-8,24,-7,minecraft:granite)
B(-8,25,-7,minecraft:granite)
B(-8,26,-7,minecraft:stone)
B(-8,27,-7,minecraft:stone)
B(-8,28,-7,minecraft:stone)
B(-8,29,-7,minecraft:stone)
B(-8,30,-7,minecraft:stone)
B(-8,31,-7,minecraft:granite)
B(-8,32,-7,minecraft:granite)
B(-8,33,-7,minecraft:granite)
B(-8,34,-7,minecraft:granite)
B(-8,35,-7,minecraft:granite)
B(-8,36,-7,minecraft:granite)
B(-8,37,-7,minecraft:granite)
B(-8,38,-7,minecraft:andesite)
B(-8,39,-7,minecraft:granite)
B(-8,40,-7,minecraft:granite)
B(-8,41,-7,minecraft:granite)
B(-8,42,-7,minecraft:granite)
B(-8,0,-6,minecraft:stone)
B(-8,1,-6,minecraft:stone)
B(-8,2,-6,minecraft:stone)
B(-8,3,-6,minecraft:granite)
B(-8,4,-6,minecraft:granite)
B(-8,5,-6,minecraft:granite)
B(-8,6,-6,minecraft:stone)
B(-8,7,-6,minecraft:granite)
B(-8,8,-6,minecraft:granite)
B(-8,9,-6,minecraft:granite)
B(-8,10,-6,minecraft:granite)
B(-8,11,-6,minecraft:granite)
B(-8,12,-6,minecraft:granite)
B(-8,13,-6,minecraft:granite)
B(-8,14,-6,minecraft:stone)
B(-8,15,-6,minecraft:dirt)
B(-8,16,-6,minecraft:stone)
B(-8,17,-6,minecraft:stone)
B(-8,18,-6,minecraft:stone)
B(-8,19,-6,minecraft:stone)
B(-8,20,-6,minecraft:stone)
B(-8,21,-6,minecraft:stone)
B(-8,22,-6,minecraft:granite)
B(-8,23,-6,minecraft:granite)
B(-8,24,-6,minecraft:granite)
B(-8,28,-6,minecraft:stone)
B(-8,29,-6,minecraft:dirt)
B(-8,30,-6,minecraft:stone)
B(-8,31,-6,minecraft:granite)
B(-8,32,-6,minecraft:granite)
B(-8,0,-5,minecraft:granite)
B(-8,1,-5,minecraft:granite)
B(-8,2,-5,minecraft:granite)
B(-8,3,-5,minecraft:granite)
B(-8,4,-5,minecraft:granite)
B(-8,5,-5,minecraft:granite)
B(-8,6,-5,minecraft:granite)
B(-8,7,-5,minecraft:granite)
B(-8,8,-5,minecraft:granite)
B(-8,9,-5,minecraft:granite)
B(-8,10,-5,minecraft:granite)
B(-8,11,-5,minecraft:granite)
B(-8,12,-5,minecraft:granite)
B(-8,13,-5,minecraft:granite)
B(-8,14,-5,minecraft:granite)
B(-8,15,-5,minecraft:dirt)
B(-8,16,-5,minecraft:dirt)
B(-8,17,-5,minecraft:stone)
B(-8,18,-5,minecraft:stone)
B(-8,19,-5,minecraft:stone)
B(-8,20,-5,minecraft:stone)
B(-8,21,-5,minecraft:stone)
B(-8,22,-5,minecraft:andesite)
B(-8,23,-5,minecraft:andesite)
B(-8,28,-5,minecraft:granite)
B(-8,29,-5,minecraft:granite)
B(-8,30,-5,minecraft:grass_block)
B(-8,0,-4,minecraft:granite)
B(-8,1,-4,minecraft:granite)
B(-8,2,-4,minecraft:granite)
B(-8,3,-4,minecraft:granite)
B(-8,4,-4,minecraft:granite)
B(-8,5,-4,minecraft:granite)
B(-8,6,-4,minecraft:granite)
B(-8,7,-4,minecraft:granite)
B(-8,8,-4,minecraft:granite)
B(-8,9,-4,minecraft:granite)
B(-8,10,-4,minecraft:granite)
B(-8,11,-4,minecraft:granite)
B(-8,12,-4,minecraft:granite)
B(-8,13,-4,minecraft:granite)
B(-8,14,-4,minecraft:granite)
B(-8,15,-4,minecraft:dirt)
B(-8,16,-4,minecraft:stone)
B(-8,17,-4,minecraft:stone)
B(-8,18,-4,minecraft:stone)
B(-8,0,-3,minecraft:granite)
B(-8,1,-3,minecraft:granite)
B(-8,2,-3,minecraft:granite)
B(-8,3,-3,minecraft:granite)
B(-8,4,-3,minecraft:granite)
B(-8,5,-3,minecraft:granite)
B(-8,6,-3,minecraft:granite)
B(-8,0,-2,minecraft:granite)
B(-7,0,-7,minecraft:stone)
B(-7,1,-7,minecraft:stone)
B(-7,2,-7,minecraft:stone)
B(-7,3,-7,minecraft:stone)
B(-7,4,-7,minecraft:stone)
B(-7,5,-7,minecraft:stone)
B(-7,6,-7,minecraft:stone)
B(-7,7,-7,minecraft:stone)
B(-7,8,-7,minecraft:stone)
B(-7,9,-7,minecraft:stone)
B(-7,10,-7,minecraft:stone)
B(-7,11,-7,minecraft:stone)
B(-7,12,-7,minecraft:stone)
B(-7,13,-7,minecraft:stone)
B(-7,14,-7,minecraft:stone)
B(-7,15,-7,minecraft:stone)
B(-7,16,-7,minecraft:stone)
B(-7,17,-7,minecraft:stone)
B(-7,18,-7,minecraft:stone)
B(-7,19,-7,minecraft:granite)
B(-7,20,-7,minecraft:granite)
B(-7,21,-7,minecraft:granite)
B(-7,22,-7,minecraft:granite)
B(-7,23,-7,minecraft:granite)
B(-7,28,-7,minecraft:dirt)
B(-7,29,-7,minecraft:stone)
B(-7,30,-7,minecraft:stone)
B(-7,31,-7,minecraft:andesite)
B(-7,32,-7,minecraft:granite)
B(-7,33,-7,minecraft:granite)
B(-7,34,-7,minecraft:grass_block)
B(-7,0,-6,minecraft:stone)
B(-7,1,-6,minecraft:stone)
B(-7,2,-6,minecraft:stone)
B(-7,3,-6,minecraft:granite)
B(-7,4,-6,minecraft:granite)
B(-7,5,-6,minecraft:granite)
B(-7,6,-6,minecraft:stone)
B(-7,7,-6,minecraft:granite)
B(-7,8,-6,minecraft:granite)
B(-7,9,-6,minecraft:granite)
B(-7,10,-6,minecraft:granite)
B(-7,11,-6,minecraft:granite)
B(-7,12,-6,minecraft:granite)
B(-7,13,-6,minecraft:granite)
B(-7,14,-6,minecraft:dirt)
B(-7,15,-6,minecraft:dirt)
B(-7,16,-6,minecraft:dirt)
B(-7,17,-6,minecraft:stone)
B(-7,18,-6,minecraft:stone)
B(-7,19,-6,minecraft:stone)
B(-7,20,-6,minecraft:granite)
B(-7,21,-6,minecraft:granite)
B(-7,22,-6,minecraft:granite)
B(-7,23,-6,minecraft:granite)
B(-7,29,-6,minecraft:dirt)
B(-7,30,-6,minecraft:grass_block)
B(-7,0,-5,minecraft:stone)
B(-7,1,-5,minecraft:stone)
B(-7,2,-5,minecraft:granite)
B(-7,3,-5,minecraft:granite)
B(-7,4,-5,minecraft:granite)
B(-7,5,-5,minecraft:granite)
B(-7,6,-5,minecraft:granite)
B(-7,7,-5,minecraft:granite)
B(-7,8,-5,minecraft:granite)
B(-7,9,-5,minecraft:granite)
B(-7,10,-5,minecraft:granite)
B(-7,11,-5,minecraft:granite)
B(-7,12,-5,minecraft:granite)
B(-7,13,-5,minecraft:granite)
B(-7,14,-5,minecraft:dirt)
B(-7,15,-5,minecraft:dirt)
B(-7,16,-5,minecraft:dirt)
B(-7,17,-5,minecraft:stone)
B(-7,18,-5,minecraft:andesite)
B(-7,19,-5,minecraft:stone)
B(-7,0,-4,minecraft:stone)
B(-7,1,-4,minecraft:granite)
B(-7,2,-4,minecraft:granite)
B(-7,3,-4,minecraft:granite)
B(-7,4,-4,minecraft:granite)
B(-7,5,-4,minecraft:granite)
B(-7,6,-4,minecraft:granite)
B(-7,7,-4,minecraft:granite)
B(-7,8,-4,minecraft:granite)
B(-7,9,-4,minecraft:granite)
B(-7,10,-4,minecraft:granite)
B(-7,11,-4,minecraft:granite)
B(-7,0,-3,minecraft:stone)
B(-7,1,-3,minecraft:granite)
B(-7,2,-3,minecraft:granite)
B(-7,3,-3,minecraft:granite)
B(-7,4,-3,minecraft:granite)
B(-7,5,-3,minecraft:granite)
B(-7,6,-3,minecraft:granite)
B(-7,7,-3,minecraft:granite)
B(-7,8,-3,minecraft:granite)
B(-7,9,-3,minecraft:granite)
B(-7,10,-3,minecraft:granite)
B(-7,0,-2,minecraft:stone)
B(-7,1,-2,minecraft:granite)
B(-6,0,-7,minecraft:stone)
B(-6,1,-7,minecraft:stone)
B(-6,2,-7,minecraft:stone)
B(-6,3,-7,minecraft:stone)
B(-6,4,-7,minecraft:stone)
B(-6,5,-7,minecraft:stone)
B(-6,6,-7,minecraft:stone)
B(-6,7,-7,minecraft:stone)
B(-6,8,-7,minecraft:stone)
B(-6,9,-7,minecraft:stone)
B(-6,10,-7,minecraft:stone)
B(-6,11,-7,minecraft:stone)
B(-6,12,-7,minecraft:dirt)
B(-6,13,-7,minecraft:stone)
B(-6,14,-7,minecraft:stone)
B(-6,15,-7,minecraft:stone)
B(-6,16,-7,minecraft:andesite)
B(-6,17,-7,minecraft:stone)
B(-6,18,-7,minecraft:stone)
B(-6,19,-7,minecraft:granite)
B(-6,20,-7,minecraft:granite)
B(-6,21,-7,minecraft:granite)
B(-6,22,-7,minecraft:granite)
B(-6,23,-7,minecraft:granite)
B(-6,24,-7,minecraft:granite)
B(-6,25,-7,minecraft:granite)
B(-6,26,-7,minecraft:dirt)
B(-6,27,-7,minecraft:dirt)
B(-6,28,-7,minecraft:grass_block)
B(-6,0,-6,minecraft:stone)
B(-6,1,-6,minecraft:stone)
B(-6,2,-6,minecraft:stone)
B(-6,3,-6,minecraft:stone)
B(-6,4,-6,minecraft:stone)
B(-6,5,-6,minecraft:stone)
B(-6,6,-6,minecraft:stone)
B(-6,7,-6,minecraft:granite)
B(-6,8,-6,minecraft:granite)
B(-6,9,-6,minecraft:granite)
B(-6,10,-6,minecraft:stone)
B(-6,11,-6,minecraft:dirt)
B(-6,12,-6,minecraft:dirt)
B(-6,13,-6,minecraft:dirt)
B(-6,14,-6,minecraft:dirt)
B(-6,15,-6,minecraft:dirt)
B(-6,16,-6,minecraft:dirt)
B(-6,17,-6,minecraft:stone)
B(-6,18,-6,minecraft:stone)
B(-6,19,-6,minecraft:stone)
B(-6,20,-6,minecraft:granite)
B(-6,21,-6,minecraft:granite)
B(-6,0,-5,minecraft:stone)
B(-6,1,-5,minecraft:stone)
B(-6,2,-5,minecraft:granite)
B(-6,3,-5,minecraft:granite)
B(-6,4,-5,minecraft:granite)
B(-6,5,-5,minecraft:granite)
B(-6,6,-5,minecraft:granite)
B(-6,7,-5,minecraft:granite)
B(-6,8,-5,minecraft:granite)
B(-6,9,-5,minecraft:granite)
B(-6,10,-5,minecraft:granite)
B(-6,11,-5,minecraft:granite)
B(-6,12,-5,minecraft:granite)
B(-6,13,-5,minecraft:stone)
B(-6,14,-5,minecraft:dirt)
B(-6,15,-5,minecraft:dirt)
B(-6,16,-5,minecraft:dirt)
B(-6,17,-5,minecraft:stone)
B(-6,0,-4,minecraft:stone)
B(-6,1,-4,minecraft:stone)
B(-6,2,-4,minecraft:granite)
B(-6,3,-4,minecraft:granite)
B(-6,4,-4,minecraft:granite)
B(-6,5,-4,minecraft:granite)
B(-6,6,-4,minecraft:granite)
B(-6,7,-4,minecraft:granite)
B(-6,8,-4,minecraft:granite)
B(-6,9,-4,minecraft:granite)
B(-6,10,-4,minecraft:granite)
B(-6,0,-3,minecraft:stone)
B(-5,0,-7,minecraft:stone)
B(-5,1,-7,minecraft:stone)
B(-5,2,-7,minecraft:stone)
B(-5,3,-7,minecraft:andesite)
B(-5,4,-7,minecraft:stone)
B(-5,5,-7,minecraft:stone)
B(-5,6,-7,minecraft:stone)
B(-5,7,-7,minecraft:stone)
B(-5,8,-7,minecraft:andesite)
B(-5,9,-7,minecraft:stone)
B(-5,10,-7,minecraft:stone)
B(-5,11,-7,minecraft:dirt)
B(-5,12,-7,minecraft:dirt)
B(-5,13,-7,minecraft:grass_block)
B(-5,0,-6,minecraft:stone)
B(-5,1,-6,minecraft:stone)
B(-5,2,-6,minecraft:stone)
B(-5,3,-6,minecraft:andesite)
B(-5,4,-6,minecraft:andesite)
B(-5,5,-6,minecraft:andesite)
B(-5,6,-6,minecraft:stone)
B(-5,7,-6,minecraft:stone)
B(-5,8,-6,minecraft:stone)
B(-5,9,-6,minecraft:stone)
B(-5,10,-6,minecraft:stone)
B(-5,11,-6,minecraft:dirt)
B(-5,12,-6,minecraft:dirt)
B(-5,13,-6,minecraft:grass_block)
B(-5,0,-5,minecraft:stone)
B(-5,1,-5,minecraft:stone)
B(-5,2,-5,minecraft:stone)
B(-5,3,-5,minecraft:stone)
B(-5,4,-5,minecraft:stone)
B(-5,5,-5,minecraft:stone)
B(-5,6,-5,minecraft:granite)
B(-5,7,-5,minecraft:granite)
B(-5,8,-5,minecraft:granite)
B(-5,9,-5,minecraft:granite)
B(-5,10,-5,minecraft:granite)
B(-5,0,-4,minecraft:stone)
B(-5,1,-4,minecraft:stone)
B(-5,2,-4,minecraft:stone)
B(-5,3,-4,minecraft:granite)
B(-5,4,-4,minecraft:granite)
B(-5,5,-4,minecraft:granite)
B(-5,6,-4,minecraft:granite)
B(-4,0,-7,minecraft:andesite)
B(-4,1,-7,minecraft:andesite)
B(-4,2,-7,minecraft:andesite)
B(-4,3,-7,minecraft:andesite)
B(-4,4,-7,minecraft:andesite)
B(-4,5,-7,minecraft:andesite)
B(-4,6,-7,minecraft:stone)
B(-4,7,-7,minecraft:stone)
B(-4,0,-6,minecraft:stone)
B(-4,1,-6,minecraft:stone)
B(-4,2,-6,minecraft:andesite)
B(-4,3,-6,minecraft:andesite)
B(-4,5,-6,minecraft:andesite)
B(-4,6,-6,minecraft:andesite)

#######################################################################
# +-----------------------------------------------------------------+ #
# |                             Branches                            | #
# +-----------------------------------------------------------------+ #
#######################################################################


#######################################################################
# +-----------------------------------------------------------------+ #
# |                             Entities                            | #
# +-----------------------------------------------------------------+ #
#######################################################################

