
#######################################################################
# +-----------------------------------------------------------------+ #
# |                            BO3 object                           | #
# +-----------------------------------------------------------------+ #
#######################################################################

Author: Unknown

Description: Converted version of the BO2 JunglePalm7

Version: 3

SettingsMode: WriteWithoutComments


#######################################################################
# +-----------------------------------------------------------------+ #
# |                          Main settings                          | #
# +-----------------------------------------------------------------+ #
#######################################################################

Tree: true

Frequency: 1

Rarity: 4.0

MaxSpawn: 0

RotateRandomly: true

SpawnHeight: highestSolidBlock

SpawnHeightOffset: 0

SpawnHeightVariance: 0

##############################
# Height Limits for the BO3. #
##############################

MinHeight: 62

MaxHeight: 65

######################
# Extrusion settings #
######################

ExtrudeMode: None

ExtrudeThroughBlocks: otg:air

MaxBranchDepth: 10


#######################################################################
# +-----------------------------------------------------------------+ #
# |                      Source block settings                      | #
# +-----------------------------------------------------------------+ #
#######################################################################

SourceBlocks: otg:dirt,minecraft:sand,otg:stained_clay,otg:sandstone,otg:air,otg:stone,otg:long_grass,minecraft:granite,minecraft:diorite,minecraft:andesite,minecraft:coarse_dirt,minecraft:grass_block,minecraft:podzol,minecraft:water,minecraft:terracotta,minecraft:clay,minecraft:red_sand,minecraft:gravel,minecraft:grass,minecraft:fern,minecraft:dead_bush,minecraft:dandelion,minecraft:poppy,minecraft:brown_mushroom,minecraft:red_mushroom

MaxPercentageOutsideSourceBlock: 0

OutsideSourceBlock: placeAnyway

DoReplaceBlocks: true

IsOTGPlus: false


#######################################################################
# +-----------------------------------------------------------------+ #
# |                              Blocks                             | #
# +-----------------------------------------------------------------+ #
#######################################################################

B(-4,11,-4,minecraft:jungle_leaves)
B(-4,11,2,minecraft:jungle_leaves)
B(-4,10,2,minecraft:jungle_leaves)
B(-2,10,7,minecraft:jungle_leaves)
B(-8,1,5,minecraft:jungle_log)
B(-8,2,5,minecraft:jungle_log)
B(-8,-3,7,minecraft:jungle_log)
B(-8,11,3,minecraft:jungle_leaves)
B(-3,9,8,minecraft:jungle_leaves)
B(-8,10,3,minecraft:jungle_leaves)
B(-2,13,-3,minecraft:jungle_leaves)
B(-7,10,-1,minecraft:jungle_leaves)
B(-8,-2,7,minecraft:jungle_log)
B(-3,10,10,minecraft:jungle_leaves)
B(-8,-1,7,minecraft:jungle_log)
B(-7,11,-1,minecraft:jungle_leaves)
B(-3,13,-2,minecraft:jungle_leaves)
B(-3,12,-2,minecraft:jungle_leaves)
B(-4,12,-1,minecraft:jungle_leaves)
B(-4,11,-1,minecraft:jungle_log)
B(-7,3,3,minecraft:jungle_log)
B(-4,10,-1,minecraft:jungle_log)
B(-7,1,7,minecraft:jungle_log)
B(-6,4,1,minecraft:jungle_log)
B(-4,10,7,minecraft:jungle_leaves)
B(-1,11,7,minecraft:jungle_leaves)
B(-5,4,7,minecraft:jungle_log)
B(-5,3,7,minecraft:jungle_log)
B(-3,11,5,minecraft:jungle_leaves)
B(-7,12,2,minecraft:jungle_leaves)
B(-8,0,6,minecraft:jungle_log)
B(-8,1,6,minecraft:jungle_log)
B(-3,8,7,minecraft:jungle_log)
B(-2,12,-1,minecraft:jungle_leaves)
B(-3,7,7,minecraft:jungle_log)
B(-3,9,7,minecraft:jungle_log)
B(-1,10,-1,minecraft:jungle_leaves)
B(-3,8,3,minecraft:jungle_leaves)
B(-3,9,3,minecraft:jungle_leaves)
B(-5,11,7,minecraft:jungle_leaves)
B(0,10,3,minecraft:jungle_leaves)
B(0,11,3,minecraft:jungle_leaves)
B(-3,10,8,minecraft:jungle_leaves)
B(-6,4,2,minecraft:jungle_log)
B(-5,13,-2,minecraft:jungle_leaves)
B(-5,12,-2,minecraft:jungle_leaves)
B(-3,12,0,minecraft:jungle_leaves)
B(-3,13,0,minecraft:jungle_leaves)
B(-2,13,1,minecraft:jungle_leaves)
B(-1,11,-1,minecraft:jungle_leaves)
B(-8,-5,8,minecraft:jungle_log)
B(-8,-4,8,minecraft:jungle_log)
B(-1,12,-4,minecraft:jungle_leaves)
B(-8,-3,8,minecraft:jungle_log)
B(-7,12,-4,minecraft:jungle_leaves)
B(-1,12,2,minecraft:jungle_leaves)
B(-6,13,1,minecraft:jungle_leaves)
B(-8,2,3,minecraft:jungle_log)
B(-4,8,0,minecraft:jungle_log)
B(-4,7,0,minecraft:jungle_log)
B(-8,0,7,minecraft:jungle_log)
B(-4,6,0,minecraft:jungle_log)
B(-3,9,6,minecraft:jungle_leaves)
B(-3,10,6,minecraft:jungle_leaves)
B(-4,8,-1,minecraft:jungle_log)
B(-4,12,-3,minecraft:jungle_leaves)
B(-4,9,-1,minecraft:jungle_log)
B(-6,2,7,minecraft:jungle_log)
B(-6,12,-1,minecraft:jungle_leaves)
B(-2,10,6,minecraft:jungle_leaves)
B(-4,11,0,minecraft:jungle_leaves)
B(-3,11,-1,minecraft:jungle_leaves)
B(-4,11,-2,minecraft:jungle_leaves)
B(-5,6,1,minecraft:jungle_log)
B(-5,5,1,minecraft:jungle_log)
B(-3,11,9,minecraft:jungle_leaves)
B(-4,5,7,minecraft:jungle_log)
B(-5,11,-1,minecraft:jungle_leaves)
B(-4,9,7,minecraft:jungle_leaves)
B(-4,6,7,minecraft:jungle_log)
B(-5,13,0,minecraft:jungle_leaves)
B(-5,12,0,minecraft:jungle_leaves)
B(-8,2,4,minecraft:jungle_log)
B(1,9,7,minecraft:jungle_leaves)
B(1,8,7,minecraft:jungle_leaves)
B(-7,3,2,minecraft:jungle_log)
B(-4,12,1,minecraft:jungle_leaves)
B(-3,10,4,minecraft:jungle_leaves)
B(0,10,7,minecraft:jungle_leaves)
B(-2,9,7,minecraft:jungle_leaves)
B(-7,8,7,minecraft:jungle_leaves)
B(-7,9,7,minecraft:jungle_leaves)
B(-6,13,-3,minecraft:jungle_leaves)
B(-3,8,11,minecraft:jungle_leaves)
B(-3,9,11,minecraft:jungle_leaves)
B(0,10,-5,minecraft:jungle_leaves)
B(-6,10,7,minecraft:jungle_leaves)
B(-8,11,-5,minecraft:jungle_leaves)
B(-8,10,-5,minecraft:jungle_leaves)
B(0,11,-5,minecraft:jungle_leaves)
B(-4,10,-4,minecraft:jungle_leaves)
B(-3,10,7,minecraft:jungle_leaves)

#######################################################################
# +-----------------------------------------------------------------+ #
# |                            BO3 checks                           | #
# +-----------------------------------------------------------------+ #
#######################################################################

BlockCheck(0,-1,0,otg:dirt,otg:stained_clay,otg:sandstone,minecraft:sand,minecraft:grass_block,minecraft:podzol,minecraft:terracotta,minecraft:clay,minecraft:red_sand)
BlockCheckNot(0,0,0,minecraft:water)

#######################################################################
# +-----------------------------------------------------------------+ #
# |                             Branches                            | #
# +-----------------------------------------------------------------+ #
#######################################################################


#######################################################################
# +-----------------------------------------------------------------+ #
# |                             Entities                            | #
# +-----------------------------------------------------------------+ #
#######################################################################

