
#######################################################################
# +-----------------------------------------------------------------+ #
# |                            BO3 object                           | #
# +-----------------------------------------------------------------+ #
#######################################################################

Author: Unknown

Description: Converted version of the BO2 JunglePalm11

Version: 3

SettingsMode: WriteWithoutComments


#######################################################################
# +-----------------------------------------------------------------+ #
# |                          Main settings                          | #
# +-----------------------------------------------------------------+ #
#######################################################################

Tree: true

Frequency: 1

Rarity: 4.0

MaxSpawn: 0

RotateRandomly: true

SpawnHeight: highestSolidBlock

SpawnHeightOffset: 0

SpawnHeightVariance: 0

##############################
# Height Limits for the BO3. #
##############################

MinHeight: 62

MaxHeight: 65

######################
# Extrusion settings #
######################

ExtrudeMode: None

ExtrudeThroughBlocks: otg:air

MaxBranchDepth: 10


#######################################################################
# +-----------------------------------------------------------------+ #
# |                      Source block settings                      | #
# +-----------------------------------------------------------------+ #
#######################################################################

SourceBlocks: otg:dirt,minecraft:sand,otg:stained_clay,otg:sandstone,otg:air,otg:stone,otg:long_grass,minecraft:granite,minecraft:diorite,minecraft:andesite,minecraft:coarse_dirt,minecraft:grass_block,minecraft:podzol,minecraft:water,minecraft:terracotta,minecraft:clay,minecraft:red_sand,minecraft:gravel,minecraft:grass,minecraft:fern,minecraft:dead_bush,minecraft:dandelion,minecraft:poppy,minecraft:brown_mushroom,minecraft:red_mushroom

MaxPercentageOutsideSourceBlock: 0

OutsideSourceBlock: placeAnyway

DoReplaceBlocks: true

IsOTGPlus: false


#######################################################################
# +-----------------------------------------------------------------+ #
# |                              Blocks                             | #
# +-----------------------------------------------------------------+ #
#######################################################################

B(0,1,2,minecraft:jungle_log)
B(-5,11,-3,minecraft:jungle_leaves)
B(-3,7,4,minecraft:jungle_log)
B(-7,8,3,minecraft:jungle_leaves)
B(-3,6,0,minecraft:jungle_log)
B(0,-1,5,minecraft:jungle_log)
B(-3,9,0,minecraft:jungle_leaves)
B(0,10,-4,minecraft:jungle_leaves)
B(-7,9,3,minecraft:jungle_leaves)
B(-1,11,1,minecraft:jungle_leaves)
B(-3,5,0,minecraft:jungle_log)
B(-3,4,0,minecraft:jungle_log)
B(-7,8,-5,minecraft:jungle_leaves)
B(-7,9,-5,minecraft:jungle_leaves)
B(-2,8,2,minecraft:jungle_leaves)
B(-2,7,2,minecraft:jungle_leaves)
B(-2,6,2,minecraft:jungle_log)
B(-2,5,2,minecraft:jungle_log)
B(1,-1,5,minecraft:jungle_log)
B(-3,8,-2,minecraft:air)
B(-3,9,-2,minecraft:jungle_leaves)
B(-3,10,5,minecraft:jungle_leaves)
B(1,0,3,minecraft:jungle_log)
B(1,8,5,minecraft:jungle_leaves)
B(1,7,5,minecraft:jungle_leaves)
B(0,9,-1,minecraft:jungle_leaves)
B(0,8,-1,minecraft:jungle_leaves)
B(-4,9,5,minecraft:jungle_leaves)
B(-3,10,-3,minecraft:jungle_leaves)
B(-6,9,-1,minecraft:jungle_leaves)
B(-6,8,-1,minecraft:jungle_leaves)
B(-6,10,-4,minecraft:jungle_leaves)
B(-1,10,-1,minecraft:jungle_leaves)
B(1,-1,6,minecraft:jungle_log)
B(-3,6,3,minecraft:jungle_log)
B(-4,9,-2,minecraft:air)
B(-2,9,5,minecraft:jungle_leaves)
B(-1,10,5,minecraft:jungle_leaves)
B(-2,8,5,minecraft:jungle_log)
B(-2,5,1,minecraft:jungle_log)
B(-2,4,1,minecraft:jungle_log)
B(-2,3,1,minecraft:jungle_log)
B(-2,10,4,minecraft:jungle_leaves)
B(-3,6,-1,minecraft:jungle_log)
B(-3,7,-1,minecraft:jungle_log)
B(-3,8,-1,minecraft:jungle_log)
B(-3,9,-1,minecraft:jungle_log)
B(1,0,4,minecraft:jungle_log)
B(-2,10,-2,minecraft:jungle_leaves)
B(-2,11,0,minecraft:jungle_leaves)
B(-2,10,0,minecraft:jungle_leaves)
B(-2,9,-1,minecraft:jungle_leaves)
B(-1,11,-3,minecraft:jungle_leaves)
B(-5,11,1,minecraft:jungle_leaves)
B(-3,9,2,minecraft:jungle_leaves)
B(-3,8,2,minecraft:jungle_leaves)
B(-1,2,2,minecraft:jungle_log)
B(-2,8,8,minecraft:jungle_leaves)
B(-2,7,8,minecraft:jungle_leaves)
B(-4,9,-1,minecraft:jungle_leaves)
B(-2,9,4,minecraft:air)
B(2,-3,7,minecraft:jungle_log)
B(-2,10,6,minecraft:jungle_leaves)
B(-5,8,5,minecraft:jungle_leaves)
B(-5,7,5,minecraft:jungle_leaves)
B(-4,10,0,minecraft:jungle_leaves)
B(-4,11,0,minecraft:jungle_leaves)
B(1,0,5,minecraft:jungle_log)
B(-3,8,-4,minecraft:jungle_leaves)
B(-3,10,-1,minecraft:jungle_leaves)
B(0,10,2,minecraft:jungle_leaves)
B(-3,9,-4,minecraft:jungle_leaves)
B(-4,11,-2,minecraft:jungle_leaves)
B(-4,10,-2,minecraft:jungle_leaves)
B(0,9,5,minecraft:jungle_leaves)
B(2,-3,6,minecraft:jungle_log)
B(2,-2,6,minecraft:jungle_log)
B(1,9,3,minecraft:jungle_leaves)
B(-3,10,1,minecraft:jungle_leaves)
B(1,8,3,minecraft:jungle_leaves)
B(0,1,3,minecraft:jungle_log)
B(-5,10,-1,minecraft:jungle_leaves)
B(1,9,-5,minecraft:jungle_leaves)
B(1,8,-5,minecraft:jungle_leaves)
B(-2,11,5,minecraft:jungle_leaves)
B(-2,10,5,minecraft:jungle_leaves)
B(-6,10,2,minecraft:jungle_leaves)
B(-2,9,7,minecraft:jungle_leaves)
B(-2,9,3,minecraft:jungle_leaves)
B(-1,8,5,minecraft:air)
B(-2,11,-2,minecraft:jungle_leaves)
B(-1,2,1,minecraft:jungle_log)

#######################################################################
# +-----------------------------------------------------------------+ #
# |                            BO3 checks                           | #
# +-----------------------------------------------------------------+ #
#######################################################################

BlockCheck(0,-1,0,otg:dirt,otg:stained_clay,otg:sandstone,minecraft:sand,minecraft:grass_block,minecraft:podzol,minecraft:terracotta,minecraft:clay,minecraft:red_sand)
BlockCheckNot(0,0,0,minecraft:water)

#######################################################################
# +-----------------------------------------------------------------+ #
# |                             Branches                            | #
# +-----------------------------------------------------------------+ #
#######################################################################


#######################################################################
# +-----------------------------------------------------------------+ #
# |                             Entities                            | #
# +-----------------------------------------------------------------+ #
#######################################################################

