
#######################################################################
# +-----------------------------------------------------------------+ #
# |                            BO4 object                           | #
# +-----------------------------------------------------------------+ #
#######################################################################

Author: Unknown

Description: No description given

SettingsMode: WriteWithoutComments


#######################################################################
# +-----------------------------------------------------------------+ #
# |                          Main settings                          | #
# +-----------------------------------------------------------------+ #
#######################################################################

FixedRotation: 

Frequency: 0

SpawnHeight: highestBlock

UseCenterForHighestBlock: true

##############################
# Height Limits for the BO4. #
##############################

MinHeight: 0

MaxHeight: 255

InheritBO3: 

InheritBO3Rotation: NORTH

OverrideChildSettings: true

OverrideParentHeight: false

CanOverride: false

BranchFrequency: 0

BranchFrequencyGroup: 

MustBeBelowOther: false

MustBeInside: 

CannotBeInside: 

ReplacesBO3: 

MustBeInsideWorldBorders: false

CanSpawnOnWater: true

SpawnOnWaterOnly: false

SpawnUnderWater: false

SpawnAtWaterLevel: false

HeightOffset: 0

RemoveAir: true

ReplaceAbove: 

ReplaceBelow: 

ReplaceWithBiomeBlocks: true

ReplaceWithSurfaceBlock: GRASS

ReplaceWithGroundBlock: DIRT

ReplaceWithStoneBlock: STONE

SmoothRadius: 0

SmoothHeightOffset: 0

SmoothStartTop: false

SmoothStartWood: false

SmoothingSurfaceBlock: 

SmoothingGroundBlock: 

BO3Group: 

IsSpawnPoint: false

DoReplaceBlocks: true


#######################################################################
# +-----------------------------------------------------------------+ #
# |                              Blocks                             | #
# +-----------------------------------------------------------------+ #
#######################################################################

B(-6,12,-7,minecraft:grass_block)
B(-5,12,-7,minecraft:grass_block)
B(-5,12,-6,minecraft:grass_block)
B(-5,12,-5,minecraft:grass_block)
B(-4,11,-7,minecraft:dirt)
B(-4,12,-7,minecraft:grass_block)
B(-4,11,-6,minecraft:dirt)
B(-4,12,-6,minecraft:grass_block)
B(-4,12,-5,minecraft:grass_block)
B(-3,10,-7,minecraft:dirt)
B(-3,11,-7,minecraft:dirt)
B(-3,12,-7,minecraft:grass_block)
B(-3,11,-6,minecraft:dirt)
B(-3,12,-6,minecraft:grass_block)
B(-3,12,-5,minecraft:grass_block)
B(-2,10,-7,minecraft:dirt)
B(-2,11,-7,minecraft:dirt)
B(-2,12,-7,minecraft:grass_block)
B(-2,11,-6,minecraft:dirt)
B(-2,12,-6,minecraft:grass_block)
B(-2,12,-5,minecraft:grass_block)
B(-1,10,-7,minecraft:dirt)
B(-1,11,-7,minecraft:dirt)
B(-1,12,-7,minecraft:dirt)
B(-1,13,-7,minecraft:grass_block)
B(-1,12,-6,minecraft:grass_block)
B(0,10,-7,minecraft:stone)
B(0,11,-7,minecraft:dirt)
B(0,12,-7,minecraft:dirt)
B(0,13,-7,minecraft:grass_block)
B(0,12,-6,minecraft:grass_block)
B(1,9,-7,minecraft:stone)
B(1,10,-7,minecraft:stone)
B(1,11,-7,minecraft:dirt)
B(1,12,-7,minecraft:dirt)
B(1,13,-7,minecraft:grass_block)
B(1,11,-6,minecraft:dirt)
B(1,12,-6,minecraft:grass_block)
B(1,12,-5,minecraft:grass_block)
B(2,9,-7,minecraft:stone)
B(2,10,-7,minecraft:stone)
B(2,11,-7,minecraft:dirt)
B(2,12,-7,minecraft:dirt)
B(2,13,-7,minecraft:grass_block)
B(2,10,-6,minecraft:stone)
B(2,11,-6,minecraft:dirt)
B(2,12,-6,minecraft:dirt)
B(2,13,-6,minecraft:grass_block)
B(2,11,-5,minecraft:dirt)
B(2,12,-5,minecraft:grass_block)
B(2,12,-4,minecraft:grass_block)
B(2,12,-3,minecraft:grass_block)
B(3,9,-7,minecraft:stone)
B(3,10,-7,minecraft:stone)
B(3,11,-7,minecraft:dirt)
B(3,12,-7,minecraft:dirt)
B(3,13,-7,minecraft:grass_block)
B(3,10,-6,minecraft:stone)
B(3,11,-6,minecraft:stone)
B(3,12,-6,minecraft:stone)
B(3,13,-6,minecraft:grass_block)
B(3,10,-5,minecraft:stone)
B(3,11,-5,minecraft:dirt)
B(3,12,-5,minecraft:dirt)
B(3,13,-5,minecraft:grass_block)
B(3,11,-4,minecraft:dirt)
B(3,12,-4,minecraft:dirt)
B(3,13,-4,minecraft:grass_block)
B(3,12,-3,minecraft:grass_block)
B(3,12,-2,minecraft:grass_block)
B(4,11,-7,minecraft:dirt)
B(4,12,-7,minecraft:dirt)
B(4,13,-7,minecraft:dirt)
B(4,14,-7,minecraft:grass_block)
B(4,10,-6,minecraft:stone)
B(4,11,-6,minecraft:dirt)
B(4,12,-6,minecraft:dirt)
B(4,13,-6,minecraft:dirt)
B(4,14,-6,minecraft:grass_block)
B(4,10,-5,minecraft:dirt)
B(4,11,-5,minecraft:dirt)
B(4,12,-5,minecraft:dirt)
B(4,13,-5,minecraft:grass_block)
B(4,11,-4,minecraft:dirt)
B(4,12,-4,minecraft:dirt)
B(4,13,-4,minecraft:grass_block)
B(4,12,-3,minecraft:dirt)
B(4,13,-3,minecraft:grass_block)
B(4,12,-2,minecraft:dirt)
B(4,13,-2,minecraft:grass_block)
B(4,12,-1,minecraft:grass_block)
B(5,10,-7,minecraft:dirt)
B(5,11,-7,minecraft:dirt)
B(5,12,-7,minecraft:dirt)
B(5,13,-7,minecraft:dirt)
B(5,14,-7,minecraft:dirt)
B(5,15,-7,minecraft:grass_block)
B(5,11,-6,minecraft:dirt)
B(5,12,-6,minecraft:dirt)
B(5,13,-6,minecraft:dirt)
B(5,14,-6,minecraft:grass_block)
B(5,11,-5,minecraft:dirt)
B(5,12,-5,minecraft:dirt)
B(5,13,-5,minecraft:grass_block)
B(5,11,-4,minecraft:dirt)
B(5,12,-4,minecraft:dirt)
B(5,13,-4,minecraft:dirt)
B(5,14,-4,minecraft:grass_block)
B(5,11,-3,minecraft:dirt)
B(5,12,-3,minecraft:dirt)
B(5,13,-3,minecraft:grass_block)
B(5,12,-2,minecraft:dirt)
B(5,13,-2,minecraft:grass_block)
B(5,12,-1,minecraft:dirt)
B(5,13,-1,minecraft:grass_block)
B(5,12,0,minecraft:dirt)
B(5,13,0,minecraft:grass_block)
B(5,12,1,minecraft:grass_block)
B(6,10,-7,minecraft:dirt)
B(6,11,-7,minecraft:dirt)
B(6,12,-7,minecraft:dirt)
B(6,13,-7,minecraft:dirt)
B(6,14,-7,minecraft:dirt)
B(6,15,-7,minecraft:grass_block)
B(6,11,-6,minecraft:dirt)
B(6,12,-6,minecraft:dirt)
B(6,13,-6,minecraft:dirt)
B(6,14,-6,minecraft:dirt)
B(6,15,-6,minecraft:grass_block)
B(6,11,-5,minecraft:dirt)
B(6,12,-5,minecraft:dirt)
B(6,13,-5,minecraft:dirt)
B(6,14,-5,minecraft:dirt)
B(6,15,-5,minecraft:grass_block)
B(6,11,-4,minecraft:dirt)
B(6,12,-4,minecraft:dirt)
B(6,13,-4,minecraft:dirt)
B(6,14,-4,minecraft:grass_block)
B(6,11,-3,minecraft:dirt)
B(6,12,-3,minecraft:dirt)
B(6,13,-3,minecraft:dirt)
B(6,14,-3,minecraft:grass_block)
B(6,11,-2,minecraft:dirt)
B(6,12,-2,minecraft:dirt)
B(6,13,-2,minecraft:grass_block)
B(6,12,-1,minecraft:dirt)
B(6,13,-1,minecraft:grass_block)
B(6,12,0,minecraft:dirt)
B(6,13,0,minecraft:grass_block)
B(6,12,1,minecraft:dirt)
B(6,13,1,minecraft:grass_block)
B(6,12,2,minecraft:grass_block)
B(7,10,-7,minecraft:dirt)
B(7,11,-7,minecraft:dirt)
B(7,12,-7,minecraft:dirt)
B(7,13,-7,minecraft:dirt)
B(7,14,-7,minecraft:dirt)
B(7,15,-7,minecraft:grass_block)
B(7,10,-6,minecraft:dirt)
B(7,11,-6,minecraft:dirt)
B(7,12,-6,minecraft:dirt)
B(7,13,-6,minecraft:dirt)
B(7,14,-6,minecraft:dirt)
B(7,15,-6,minecraft:grass_block)
B(7,11,-5,minecraft:dirt)
B(7,12,-5,minecraft:dirt)
B(7,13,-5,minecraft:dirt)
B(7,14,-5,minecraft:dirt)
B(7,15,-5,minecraft:grass_block)
B(7,11,-4,minecraft:dirt)
B(7,12,-4,minecraft:dirt)
B(7,13,-4,minecraft:dirt)
B(7,14,-4,minecraft:dirt)
B(7,15,-4,minecraft:grass_block)
B(7,11,-3,minecraft:dirt)
B(7,12,-3,minecraft:dirt)
B(7,13,-3,minecraft:dirt)
B(7,14,-3,minecraft:grass_block)
B(7,11,-2,minecraft:dirt)
B(7,12,-2,minecraft:dirt)
B(7,13,-2,minecraft:dirt)
B(7,14,-2,minecraft:grass_block)
B(7,11,-1,minecraft:dirt)
B(7,12,-1,minecraft:dirt)
B(7,13,-1,minecraft:grass_block)
B(7,11,0,minecraft:dirt)
B(7,12,0,minecraft:dirt)
B(7,13,0,minecraft:grass_block)
B(7,11,1,minecraft:dirt)
B(7,12,1,minecraft:dirt)
B(7,13,1,minecraft:grass_block)
B(7,12,2,minecraft:dirt)
B(7,13,2,minecraft:grass_block)

#######################################################################
# +-----------------------------------------------------------------+ #
# |                             Branches                            | #
# +-----------------------------------------------------------------+ #
#######################################################################

Branch(16,0,0,true,afloatingisland1_C1_R1,NORTH,100.0,0)

#######################################################################
# +-----------------------------------------------------------------+ #
# |                             Entities                            | #
# +-----------------------------------------------------------------+ #
#######################################################################

