
#######################################################################
# +-----------------------------------------------------------------+ #
# |                            BO4 object                           | #
# +-----------------------------------------------------------------+ #
#######################################################################

Author: Unknown

Description: No description given

SettingsMode: WriteWithoutComments


#######################################################################
# +-----------------------------------------------------------------+ #
# |                          Main settings                          | #
# +-----------------------------------------------------------------+ #
#######################################################################

FixedRotation: 

Frequency: 0

SpawnHeight: highestBlock

UseCenterForHighestBlock: true

##############################
# Height Limits for the BO4. #
##############################

MinHeight: 0

MaxHeight: 255

InheritBO3: 

InheritBO3Rotation: NORTH

OverrideChildSettings: true

OverrideParentHeight: false

CanOverride: false

BranchFrequency: 0

BranchFrequencyGroup: 

MustBeBelowOther: false

MustBeInside: 

CannotBeInside: 

ReplacesBO3: 

MustBeInsideWorldBorders: false

CanSpawnOnWater: true

SpawnOnWaterOnly: false

SpawnUnderWater: false

SpawnAtWaterLevel: false

HeightOffset: 0

RemoveAir: true

ReplaceAbove: 

ReplaceBelow: 

ReplaceWithBiomeBlocks: true

ReplaceWithSurfaceBlock: GRASS

ReplaceWithGroundBlock: DIRT

ReplaceWithStoneBlock: STONE

SmoothRadius: 0

SmoothHeightOffset: 0

SmoothStartTop: false

SmoothStartWood: false

SmoothingSurfaceBlock: 

SmoothingGroundBlock: 

BO3Group: 

IsSpawnPoint: false

DoReplaceBlocks: true


#######################################################################
# +-----------------------------------------------------------------+ #
# |                              Blocks                             | #
# +-----------------------------------------------------------------+ #
#######################################################################

B(-8,11,-7,minecraft:dirt)
B(-8,12,-7,minecraft:dirt)
B(-8,13,-7,minecraft:dirt)
B(-8,14,-7,minecraft:dirt)
B(-8,15,-7,minecraft:grass_block)
B(-8,9,-6,minecraft:stone)
B(-8,10,-6,minecraft:dirt)
B(-8,11,-6,minecraft:dirt)
B(-8,12,-6,minecraft:dirt)
B(-8,13,-6,minecraft:dirt)
B(-8,14,-6,minecraft:dirt)
B(-8,15,-6,minecraft:grass_block)
B(-8,10,-5,minecraft:dirt)
B(-8,11,-5,minecraft:dirt)
B(-8,12,-5,minecraft:dirt)
B(-8,13,-5,minecraft:dirt)
B(-8,14,-5,minecraft:dirt)
B(-8,15,-5,minecraft:grass_block)
B(-8,11,-4,minecraft:dirt)
B(-8,12,-4,minecraft:dirt)
B(-8,13,-4,minecraft:dirt)
B(-8,14,-4,minecraft:dirt)
B(-8,15,-4,minecraft:grass_block)
B(-8,11,-3,minecraft:dirt)
B(-8,12,-3,minecraft:dirt)
B(-8,13,-3,minecraft:dirt)
B(-8,14,-3,minecraft:grass_block)
B(-8,10,-2,minecraft:dirt)
B(-8,11,-2,minecraft:dirt)
B(-8,12,-2,minecraft:dirt)
B(-8,13,-2,minecraft:dirt)
B(-8,14,-2,minecraft:grass_block)
B(-8,10,-1,minecraft:dirt)
B(-8,11,-1,minecraft:dirt)
B(-8,12,-1,minecraft:dirt)
B(-8,13,-1,minecraft:dirt)
B(-8,14,-1,minecraft:grass_block)
B(-8,10,0,minecraft:stone)
B(-8,11,0,minecraft:dirt)
B(-8,12,0,minecraft:dirt)
B(-8,13,0,minecraft:grass_block)
B(-8,11,1,minecraft:dirt)
B(-8,12,1,minecraft:dirt)
B(-8,13,1,minecraft:grass_block)
B(-8,12,2,minecraft:dirt)
B(-8,13,2,minecraft:grass_block)
B(-8,12,3,minecraft:grass_block)
B(-8,12,4,minecraft:grass_block)
B(-7,8,-7,minecraft:stone)
B(-7,9,-7,minecraft:cobblestone)
B(-7,10,-7,minecraft:dirt)
B(-7,11,-7,minecraft:dirt)
B(-7,12,-7,minecraft:dirt)
B(-7,13,-7,minecraft:dirt)
B(-7,14,-7,minecraft:dirt)
B(-7,15,-7,minecraft:grass_block)
B(-7,7,-6,minecraft:stone)
B(-7,8,-6,minecraft:stone)
B(-7,9,-6,minecraft:cobblestone)
B(-7,10,-6,minecraft:dirt)
B(-7,11,-6,minecraft:dirt)
B(-7,12,-6,minecraft:dirt)
B(-7,13,-6,minecraft:dirt)
B(-7,14,-6,minecraft:dirt)
B(-7,15,-6,minecraft:grass_block)
B(-7,9,-5,minecraft:cobblestone)
B(-7,10,-5,minecraft:dirt)
B(-7,11,-5,minecraft:dirt)
B(-7,12,-5,minecraft:dirt)
B(-7,13,-5,minecraft:dirt)
B(-7,14,-5,minecraft:dirt)
B(-7,15,-5,minecraft:grass_block)
B(-7,10,-4,minecraft:dirt)
B(-7,11,-4,minecraft:dirt)
B(-7,12,-4,minecraft:dirt)
B(-7,13,-4,minecraft:dirt)
B(-7,14,-4,minecraft:dirt)
B(-7,15,-4,minecraft:grass_block)
B(-7,10,-3,minecraft:dirt)
B(-7,11,-3,minecraft:dirt)
B(-7,12,-3,minecraft:dirt)
B(-7,13,-3,minecraft:dirt)
B(-7,14,-3,minecraft:dirt)
B(-7,15,-3,minecraft:grass_block)
B(-7,10,-2,minecraft:dirt)
B(-7,11,-2,minecraft:dirt)
B(-7,12,-2,minecraft:dirt)
B(-7,13,-2,minecraft:dirt)
B(-7,14,-2,minecraft:grass_block)
B(-7,10,-1,minecraft:dirt)
B(-7,11,-1,minecraft:dirt)
B(-7,12,-1,minecraft:dirt)
B(-7,13,-1,minecraft:dirt)
B(-7,14,-1,minecraft:grass_block)
B(-7,10,0,minecraft:stone)
B(-7,11,0,minecraft:dirt)
B(-7,12,0,minecraft:dirt)
B(-7,13,0,minecraft:grass_block)
B(-7,11,1,minecraft:dirt)
B(-7,12,1,minecraft:dirt)
B(-7,13,1,minecraft:grass_block)
B(-7,12,2,minecraft:grass_block)
B(-7,12,3,minecraft:grass_block)
B(-7,12,4,minecraft:grass_block)
B(-6,4,-7,minecraft:cobblestone)
B(-6,5,-7,minecraft:stone)
B(-6,6,-7,minecraft:stone)
B(-6,7,-7,minecraft:stone)
B(-6,8,-7,minecraft:stone)
B(-6,9,-7,minecraft:stone)
B(-6,10,-7,minecraft:stone)
B(-6,11,-7,minecraft:dirt)
B(-6,12,-7,minecraft:dirt)
B(-6,13,-7,minecraft:dirt)
B(-6,14,-7,minecraft:dirt)
B(-6,15,-7,minecraft:grass_block)
B(-6,1,-6,minecraft:cobblestone)
B(-6,2,-6,minecraft:cobblestone)
B(-6,3,-6,minecraft:cobblestone)
B(-6,4,-6,minecraft:cobblestone)
B(-6,5,-6,minecraft:cobblestone)
B(-6,6,-6,minecraft:stone)
B(-6,7,-6,minecraft:stone)
B(-6,8,-6,minecraft:stone)
B(-6,9,-6,minecraft:stone)
B(-6,10,-6,minecraft:stone)
B(-6,11,-6,minecraft:dirt)
B(-6,12,-6,minecraft:dirt)
B(-6,13,-6,minecraft:dirt)
B(-6,14,-6,minecraft:dirt)
B(-6,15,-6,minecraft:grass_block)
B(-6,5,-5,minecraft:cobblestone)
B(-6,6,-5,minecraft:stone)
B(-6,7,-5,minecraft:stone)
B(-6,8,-5,minecraft:stone)
B(-6,9,-5,minecraft:stone)
B(-6,10,-5,minecraft:stone)
B(-6,11,-5,minecraft:dirt)
B(-6,12,-5,minecraft:dirt)
B(-6,13,-5,minecraft:dirt)
B(-6,14,-5,minecraft:dirt)
B(-6,15,-5,minecraft:grass_block)
B(-6,9,-4,minecraft:stone)
B(-6,10,-4,minecraft:dirt)
B(-6,11,-4,minecraft:dirt)
B(-6,12,-4,minecraft:dirt)
B(-6,13,-4,minecraft:dirt)
B(-6,14,-4,minecraft:dirt)
B(-6,15,-4,minecraft:grass_block)
B(-6,9,-3,minecraft:stone)
B(-6,10,-3,minecraft:dirt)
B(-6,11,-3,minecraft:dirt)
B(-6,12,-3,minecraft:dirt)
B(-6,13,-3,minecraft:dirt)
B(-6,14,-3,minecraft:dirt)
B(-6,15,-3,minecraft:grass_block)
B(-6,9,-2,minecraft:stone)
B(-6,10,-2,minecraft:dirt)
B(-6,11,-2,minecraft:dirt)
B(-6,12,-2,minecraft:dirt)
B(-6,13,-2,minecraft:dirt)
B(-6,14,-2,minecraft:grass_block)
B(-6,10,-1,minecraft:dirt)
B(-6,11,-1,minecraft:dirt)
B(-6,12,-1,minecraft:dirt)
B(-6,13,-1,minecraft:grass_block)
B(-6,11,0,minecraft:dirt)
B(-6,12,0,minecraft:dirt)
B(-6,13,0,minecraft:grass_block)
B(-6,12,1,minecraft:dirt)
B(-6,13,1,minecraft:grass_block)
B(-6,12,2,minecraft:dirt)
B(-6,13,2,minecraft:grass_block)
B(-6,12,3,minecraft:grass_block)
B(-5,5,-7,minecraft:stone)
B(-5,6,-7,minecraft:stone)
B(-5,7,-7,minecraft:stone)
B(-5,8,-7,minecraft:stone)
B(-5,9,-7,minecraft:cobblestone)
B(-5,10,-7,minecraft:stone)
B(-5,11,-7,minecraft:dirt)
B(-5,12,-7,minecraft:dirt)
B(-5,13,-7,minecraft:dirt)
B(-5,14,-7,minecraft:dirt)
B(-5,15,-7,minecraft:grass_block)
B(-5,5,-6,minecraft:cobblestone)
B(-5,6,-6,minecraft:stone)
B(-5,7,-6,minecraft:stone)
B(-5,8,-6,minecraft:stone)
B(-5,9,-6,minecraft:stone)
B(-5,10,-6,minecraft:dirt)
B(-5,11,-6,minecraft:dirt)
B(-5,12,-6,minecraft:dirt)
B(-5,13,-6,minecraft:dirt)
B(-5,14,-6,minecraft:dirt)
B(-5,15,-6,minecraft:grass_block)
B(-5,5,-5,minecraft:cobblestone)
B(-5,6,-5,minecraft:cobblestone)
B(-5,7,-5,minecraft:stone)
B(-5,8,-5,minecraft:stone)
B(-5,9,-5,minecraft:stone)
B(-5,10,-5,minecraft:dirt)
B(-5,11,-5,minecraft:dirt)
B(-5,12,-5,minecraft:dirt)
B(-5,13,-5,minecraft:dirt)
B(-5,14,-5,minecraft:dirt)
B(-5,15,-5,minecraft:grass_block)
B(-5,9,-4,minecraft:stone)
B(-5,10,-4,minecraft:dirt)
B(-5,11,-4,minecraft:dirt)
B(-5,12,-4,minecraft:dirt)
B(-5,13,-4,minecraft:dirt)
B(-5,14,-4,minecraft:dirt)
B(-5,15,-4,minecraft:grass_block)
B(-5,8,-3,minecraft:stone)
B(-5,9,-3,minecraft:stone)
B(-5,10,-3,minecraft:dirt)
B(-5,11,-3,minecraft:dirt)
B(-5,12,-3,minecraft:dirt)
B(-5,13,-3,minecraft:dirt)
B(-5,14,-3,minecraft:grass_block)
B(-5,8,-2,minecraft:cobblestone)
B(-5,9,-2,minecraft:cobblestone)
B(-5,10,-2,minecraft:dirt)
B(-5,11,-2,minecraft:dirt)
B(-5,12,-2,minecraft:dirt)
B(-5,13,-2,minecraft:dirt)
B(-5,14,-2,minecraft:grass_block)
B(-5,9,-1,minecraft:cobblestone)
B(-5,10,-1,minecraft:cobblestone)
B(-5,11,-1,minecraft:dirt)
B(-5,12,-1,minecraft:dirt)
B(-5,13,-1,minecraft:grass_block)
B(-5,11,0,minecraft:dirt)
B(-5,12,0,minecraft:dirt)
B(-5,13,0,minecraft:grass_block)
B(-5,12,1,minecraft:dirt)
B(-5,13,1,minecraft:grass_block)
B(-5,12,2,minecraft:dirt)
B(-5,13,2,minecraft:grass_block)
B(-5,12,3,minecraft:grass_block)
B(-4,7,-7,minecraft:stone)
B(-4,8,-7,minecraft:stone)
B(-4,9,-7,minecraft:stone)
B(-4,10,-7,minecraft:dirt)
B(-4,11,-7,minecraft:dirt)
B(-4,12,-7,minecraft:dirt)
B(-4,13,-7,minecraft:dirt)
B(-4,14,-7,minecraft:dirt)
B(-4,15,-7,minecraft:grass_block)
B(-4,9,-6,minecraft:stone)
B(-4,10,-6,minecraft:dirt)
B(-4,11,-6,minecraft:dirt)
B(-4,12,-6,minecraft:dirt)
B(-4,13,-6,minecraft:dirt)
B(-4,14,-6,minecraft:dirt)
B(-4,15,-6,minecraft:grass_block)
B(-4,8,-5,minecraft:stone)
B(-4,9,-5,minecraft:stone)
B(-4,10,-5,minecraft:dirt)
B(-4,11,-5,minecraft:dirt)
B(-4,12,-5,minecraft:dirt)
B(-4,13,-5,minecraft:dirt)
B(-4,14,-5,minecraft:dirt)
B(-4,15,-5,minecraft:grass_block)
B(-4,6,-4,minecraft:stone)
B(-4,7,-4,minecraft:stone)
B(-4,8,-4,minecraft:stone)
B(-4,9,-4,minecraft:stone)
B(-4,10,-4,minecraft:dirt)
B(-4,11,-4,minecraft:dirt)
B(-4,12,-4,minecraft:dirt)
B(-4,13,-4,minecraft:dirt)
B(-4,14,-4,minecraft:dirt)
B(-4,15,-4,minecraft:grass_block)
B(-4,6,-3,minecraft:stone)
B(-4,7,-3,minecraft:stone)
B(-4,8,-3,minecraft:stone)
B(-4,9,-3,minecraft:stone)
B(-4,10,-3,minecraft:dirt)
B(-4,11,-3,minecraft:dirt)
B(-4,12,-3,minecraft:dirt)
B(-4,13,-3,minecraft:dirt)
B(-4,14,-3,minecraft:dirt)
B(-4,15,-3,minecraft:grass_block)
B(-4,6,-2,minecraft:cobblestone)
B(-4,7,-2,minecraft:cobblestone)
B(-4,8,-2,minecraft:cobblestone)
B(-4,9,-2,minecraft:stone)
B(-4,10,-2,minecraft:dirt)
B(-4,11,-2,minecraft:dirt)
B(-4,12,-2,minecraft:dirt)
B(-4,13,-2,minecraft:grass_block)
B(-4,8,-1,minecraft:cobblestone)
B(-4,9,-1,minecraft:cobblestone)
B(-4,10,-1,minecraft:stone)
B(-4,11,-1,minecraft:dirt)
B(-4,12,-1,minecraft:dirt)
B(-4,13,-1,minecraft:grass_block)
B(-4,10,0,minecraft:stone)
B(-4,11,0,minecraft:dirt)
B(-4,12,0,minecraft:dirt)
B(-4,13,0,minecraft:grass_block)
B(-4,11,1,minecraft:dirt)
B(-4,12,1,minecraft:dirt)
B(-4,13,1,minecraft:grass_block)
B(-4,11,2,minecraft:dirt)
B(-4,12,2,minecraft:dirt)
B(-4,13,2,minecraft:grass_block)
B(-4,11,3,minecraft:dirt)
B(-4,12,3,minecraft:grass_block)
B(-4,12,4,minecraft:grass_block)
B(-4,12,5,minecraft:grass_block)
B(-3,7,-7,minecraft:stone)
B(-3,8,-7,minecraft:stone)
B(-3,9,-7,minecraft:stone)
B(-3,10,-7,minecraft:dirt)
B(-3,11,-7,minecraft:dirt)
B(-3,12,-7,minecraft:dirt)
B(-3,13,-7,minecraft:dirt)
B(-3,14,-7,minecraft:dirt)
B(-3,15,-7,minecraft:grass_block)
B(-3,10,-6,minecraft:dirt)
B(-3,11,-6,minecraft:dirt)
B(-3,12,-6,minecraft:dirt)
B(-3,13,-6,minecraft:dirt)
B(-3,14,-6,minecraft:dirt)
B(-3,15,-6,minecraft:grass_block)
B(-3,9,-5,minecraft:stone)
B(-3,10,-5,minecraft:dirt)
B(-3,11,-5,minecraft:dirt)
B(-3,12,-5,minecraft:dirt)
B(-3,13,-5,minecraft:dirt)
B(-3,14,-5,minecraft:dirt)
B(-3,15,-5,minecraft:grass_block)
B(-3,5,-4,minecraft:stone)
B(-3,6,-4,minecraft:stone)
B(-3,7,-4,minecraft:stone)
B(-3,8,-4,minecraft:stone)
B(-3,9,-4,minecraft:stone)
B(-3,10,-4,minecraft:dirt)
B(-3,11,-4,minecraft:dirt)
B(-3,12,-4,minecraft:dirt)
B(-3,13,-4,minecraft:dirt)
B(-3,14,-4,minecraft:dirt)
B(-3,15,-4,minecraft:grass_block)
B(-3,3,-3,minecraft:cobblestone)
B(-3,4,-3,minecraft:stone)
B(-3,5,-3,minecraft:stone)
B(-3,6,-3,minecraft:stone)
B(-3,7,-3,minecraft:stone)
B(-3,8,-3,minecraft:stone)
B(-3,9,-3,minecraft:stone)
B(-3,10,-3,minecraft:dirt)
B(-3,11,-3,minecraft:dirt)
B(-3,12,-3,minecraft:dirt)
B(-3,13,-3,minecraft:dirt)
B(-3,14,-3,minecraft:grass_block)
B(-3,5,-2,minecraft:stone)
B(-3,6,-2,minecraft:stone)
B(-3,7,-2,minecraft:stone)
B(-3,8,-2,minecraft:stone)
B(-3,9,-2,minecraft:stone)
B(-3,10,-2,minecraft:dirt)
B(-3,11,-2,minecraft:dirt)
B(-3,12,-2,minecraft:dirt)
B(-3,13,-2,minecraft:dirt)
B(-3,14,-2,minecraft:grass_block)
B(-3,8,-1,minecraft:cobblestone)
B(-3,9,-1,minecraft:stone)
B(-3,10,-1,minecraft:stone)
B(-3,11,-1,minecraft:dirt)
B(-3,12,-1,minecraft:dirt)
B(-3,13,-1,minecraft:dirt)
B(-3,14,-1,minecraft:grass_block)
B(-3,9,0,minecraft:stone)
B(-3,10,0,minecraft:stone)
B(-3,11,0,minecraft:dirt)
B(-3,12,0,minecraft:dirt)
B(-3,13,0,minecraft:grass_block)
B(-3,10,1,minecraft:dirt)
B(-3,11,1,minecraft:dirt)
B(-3,12,1,minecraft:grass_block)
B(-3,10,2,minecraft:dirt)
B(-3,11,2,minecraft:dirt)
B(-3,12,2,minecraft:grass_block)
B(-3,11,3,minecraft:dirt)
B(-3,12,3,minecraft:grass_block)
B(-3,12,4,minecraft:grass_block)
B(-3,12,5,minecraft:grass_block)
B(-2,8,-7,minecraft:stone)
B(-2,9,-7,minecraft:stone)
B(-2,10,-7,minecraft:dirt)
B(-2,11,-7,minecraft:dirt)
B(-2,12,-7,minecraft:dirt)
B(-2,13,-7,minecraft:dirt)
B(-2,14,-7,minecraft:dirt)
B(-2,15,-7,minecraft:grass_block)
B(-2,9,-6,minecraft:stone)
B(-2,10,-6,minecraft:stone)
B(-2,11,-6,minecraft:dirt)
B(-2,12,-6,minecraft:dirt)
B(-2,13,-6,minecraft:dirt)
B(-2,14,-6,minecraft:dirt)
B(-2,15,-6,minecraft:grass_block)
B(-2,7,-5,minecraft:stone)
B(-2,8,-5,minecraft:stone)
B(-2,9,-5,minecraft:stone)
B(-2,10,-5,minecraft:stone)
B(-2,11,-5,minecraft:dirt)
B(-2,12,-5,minecraft:dirt)
B(-2,13,-5,minecraft:dirt)
B(-2,14,-5,minecraft:dirt)
B(-2,15,-5,minecraft:grass_block)
B(-2,4,-4,minecraft:stone)
B(-2,5,-4,minecraft:stone)
B(-2,6,-4,minecraft:stone)
B(-2,7,-4,minecraft:stone)
B(-2,8,-4,minecraft:stone)
B(-2,9,-4,minecraft:stone)
B(-2,10,-4,minecraft:dirt)
B(-2,11,-4,minecraft:dirt)
B(-2,12,-4,minecraft:dirt)
B(-2,13,-4,minecraft:dirt)
B(-2,14,-4,minecraft:grass_block)
B(-2,2,-3,minecraft:stone)
B(-2,3,-3,minecraft:stone)
B(-2,4,-3,minecraft:stone)
B(-2,5,-3,minecraft:stone)
B(-2,6,-3,minecraft:stone)
B(-2,7,-3,minecraft:stone)
B(-2,8,-3,minecraft:stone)
B(-2,9,-3,minecraft:stone)
B(-2,10,-3,minecraft:dirt)
B(-2,11,-3,minecraft:dirt)
B(-2,12,-3,minecraft:dirt)
B(-2,13,-3,minecraft:dirt)
B(-2,14,-3,minecraft:grass_block)
B(-2,4,-2,minecraft:cobblestone)
B(-2,5,-2,minecraft:stone)
B(-2,6,-2,minecraft:stone)
B(-2,7,-2,minecraft:stone)
B(-2,8,-2,minecraft:stone)
B(-2,9,-2,minecraft:stone)
B(-2,10,-2,minecraft:dirt)
B(-2,11,-2,minecraft:dirt)
B(-2,12,-2,minecraft:dirt)
B(-2,13,-2,minecraft:grass_block)
B(-2,7,-1,minecraft:stone)
B(-2,8,-1,minecraft:cobblestone)
B(-2,9,-1,minecraft:cobblestone)
B(-2,10,-1,minecraft:stone)
B(-2,11,-1,minecraft:dirt)
B(-2,12,-1,minecraft:dirt)
B(-2,13,-1,minecraft:grass_block)
B(-2,9,0,minecraft:stone)
B(-2,10,0,minecraft:stone)
B(-2,11,0,minecraft:dirt)
B(-2,12,0,minecraft:dirt)
B(-2,13,0,minecraft:grass_block)
B(-2,11,1,minecraft:dirt)
B(-2,12,1,minecraft:dirt)
B(-2,13,1,minecraft:grass_block)
B(-2,12,2,minecraft:grass_block)
B(-2,12,3,minecraft:grass_block)
B(-2,12,4,minecraft:grass_block)
B(-1,7,-7,minecraft:stone)
B(-1,8,-7,minecraft:stone)
B(-1,9,-7,minecraft:stone)
B(-1,10,-7,minecraft:dirt)
B(-1,11,-7,minecraft:dirt)
B(-1,12,-7,minecraft:dirt)
B(-1,13,-7,minecraft:dirt)
B(-1,14,-7,minecraft:dirt)
B(-1,15,-7,minecraft:grass_block)
B(-1,8,-6,minecraft:stone)
B(-1,9,-6,minecraft:stone)
B(-1,10,-6,minecraft:dirt)
B(-1,11,-6,minecraft:dirt)
B(-1,12,-6,minecraft:dirt)
B(-1,13,-6,minecraft:dirt)
B(-1,14,-6,minecraft:dirt)
B(-1,15,-6,minecraft:grass_block)
B(-1,7,-5,minecraft:stone)
B(-1,8,-5,minecraft:stone)
B(-1,9,-5,minecraft:stone)
B(-1,10,-5,minecraft:dirt)
B(-1,11,-5,minecraft:dirt)
B(-1,12,-5,minecraft:dirt)
B(-1,13,-5,minecraft:dirt)
B(-1,14,-5,minecraft:dirt)
B(-1,15,-5,minecraft:grass_block)
B(-1,5,-4,minecraft:stone)
B(-1,6,-4,minecraft:stone)
B(-1,7,-4,minecraft:stone)
B(-1,8,-4,minecraft:stone)
B(-1,9,-4,minecraft:stone)
B(-1,10,-4,minecraft:dirt)
B(-1,11,-4,minecraft:iron_ore)
B(-1,12,-4,minecraft:iron_ore)
B(-1,13,-4,minecraft:dirt)
B(-1,14,-4,minecraft:dirt)
B(-1,15,-4,minecraft:grass_block)
B(-1,4,-3,minecraft:cobblestone)
B(-1,5,-3,minecraft:stone)
B(-1,6,-3,minecraft:stone)
B(-1,7,-3,minecraft:stone)
B(-1,8,-3,minecraft:stone)
B(-1,9,-3,minecraft:stone)
B(-1,10,-3,minecraft:dirt)
B(-1,11,-3,minecraft:iron_ore)
B(-1,12,-3,minecraft:iron_ore)
B(-1,13,-3,minecraft:dirt)
B(-1,14,-3,minecraft:grass_block)
B(-1,5,-2,minecraft:cobblestone)
B(-1,6,-2,minecraft:stone)
B(-1,7,-2,minecraft:stone)
B(-1,8,-2,minecraft:cobblestone)
B(-1,9,-2,minecraft:stone)
B(-1,10,-2,minecraft:dirt)
B(-1,11,-2,minecraft:dirt)
B(-1,12,-2,minecraft:dirt)
B(-1,13,-2,minecraft:grass_block)
B(-1,7,-1,minecraft:stone)
B(-1,8,-1,minecraft:cobblestone)
B(-1,9,-1,minecraft:cobblestone)
B(-1,10,-1,minecraft:cobblestone)
B(-1,11,-1,minecraft:dirt)
B(-1,12,-1,minecraft:dirt)
B(-1,13,-1,minecraft:grass_block)
B(-1,10,0,minecraft:stone)
B(-1,11,0,minecraft:dirt)
B(-1,12,0,minecraft:grass_block)
B(-1,12,1,minecraft:grass_block)
B(-1,12,2,minecraft:grass_block)
B(0,8,-7,minecraft:stone)
B(0,9,-7,minecraft:stone)
B(0,10,-7,minecraft:dirt)
B(0,11,-7,minecraft:dirt)
B(0,12,-7,minecraft:dirt)
B(0,13,-7,minecraft:dirt)
B(0,14,-7,minecraft:dirt)
B(0,15,-7,minecraft:grass_block)
B(0,9,-6,minecraft:stone)
B(0,10,-6,minecraft:dirt)
B(0,11,-6,minecraft:dirt)
B(0,12,-6,minecraft:dirt)
B(0,13,-6,minecraft:dirt)
B(0,14,-6,minecraft:grass_block)
B(0,9,-5,minecraft:stone)
B(0,10,-5,minecraft:dirt)
B(0,11,-5,minecraft:dirt)
B(0,12,-5,minecraft:dirt)
B(0,13,-5,minecraft:dirt)
B(0,14,-5,minecraft:grass_block)
B(0,9,-4,minecraft:stone)
B(0,10,-4,minecraft:dirt)
B(0,11,-4,minecraft:dirt)
B(0,12,-4,minecraft:dirt)
B(0,13,-4,minecraft:dirt)
B(0,14,-4,minecraft:grass_block)
B(0,8,-3,minecraft:stone)
B(0,9,-3,minecraft:stone)
B(0,10,-3,minecraft:dirt)
B(0,11,-3,minecraft:dirt)
B(0,12,-3,minecraft:dirt)
B(0,13,-3,minecraft:dirt)
B(0,14,-3,minecraft:grass_block)
B(0,8,-2,minecraft:cobblestone)
B(0,9,-2,minecraft:cobblestone)
B(0,10,-2,minecraft:dirt)
B(0,11,-2,minecraft:dirt)
B(0,12,-2,minecraft:dirt)
B(0,13,-2,minecraft:grass_block)
B(0,9,-1,minecraft:cobblestone)
B(0,10,-1,minecraft:dirt)
B(0,11,-1,minecraft:dirt)
B(0,12,-1,minecraft:dirt)
B(0,13,-1,minecraft:grass_block)
B(0,10,0,minecraft:dirt)
B(0,11,0,minecraft:dirt)
B(0,12,0,minecraft:dirt)
B(0,13,0,minecraft:grass_block)
B(0,12,1,minecraft:grass_block)
B(1,9,-7,minecraft:stone)
B(1,10,-7,minecraft:dirt)
B(1,11,-7,minecraft:dirt)
B(1,12,-7,minecraft:dirt)
B(1,13,-7,minecraft:dirt)
B(1,14,-7,minecraft:grass_block)
B(1,10,-6,minecraft:dirt)
B(1,11,-6,minecraft:dirt)
B(1,12,-6,minecraft:dirt)
B(1,13,-6,minecraft:dirt)
B(1,14,-6,minecraft:grass_block)
B(1,10,-5,minecraft:dirt)
B(1,11,-5,minecraft:dirt)
B(1,12,-5,minecraft:dirt)
B(1,13,-5,minecraft:dirt)
B(1,14,-5,minecraft:grass_block)
B(1,10,-4,minecraft:dirt)
B(1,11,-4,minecraft:dirt)
B(1,12,-4,minecraft:dirt)
B(1,13,-4,minecraft:dirt)
B(1,14,-4,minecraft:grass_block)
B(1,9,-3,minecraft:stone)
B(1,10,-3,minecraft:dirt)
B(1,11,-3,minecraft:dirt)
B(1,12,-3,minecraft:dirt)
B(1,13,-3,minecraft:grass_block)
B(1,11,-2,minecraft:dirt)
B(1,12,-2,minecraft:dirt)
B(1,13,-2,minecraft:grass_block)
B(1,11,-1,minecraft:dirt)
B(1,12,-1,minecraft:dirt)
B(1,13,-1,minecraft:grass_block)
B(1,11,0,minecraft:dirt)
B(1,12,0,minecraft:grass_block)
B(1,11,1,minecraft:dirt)
B(1,12,1,minecraft:grass_block)
B(1,12,2,minecraft:grass_block)
B(2,9,-7,minecraft:stone)
B(2,10,-7,minecraft:dirt)
B(2,11,-7,minecraft:dirt)
B(2,12,-7,minecraft:dirt)
B(2,13,-7,minecraft:grass_block)
B(2,9,-6,minecraft:stone)
B(2,10,-6,minecraft:dirt)
B(2,11,-6,minecraft:dirt)
B(2,12,-6,minecraft:dirt)
B(2,13,-6,minecraft:dirt)
B(2,14,-6,minecraft:grass_block)
B(2,10,-5,minecraft:stone)
B(2,11,-5,minecraft:dirt)
B(2,12,-5,minecraft:dirt)
B(2,13,-5,minecraft:grass_block)
B(2,10,-4,minecraft:dirt)
B(2,11,-4,minecraft:dirt)
B(2,12,-4,minecraft:dirt)
B(2,13,-4,minecraft:grass_block)
B(2,10,-3,minecraft:dirt)
B(2,11,-3,minecraft:dirt)
B(2,12,-3,minecraft:dirt)
B(2,13,-3,minecraft:grass_block)
B(2,11,-2,minecraft:dirt)
B(2,12,-2,minecraft:dirt)
B(2,13,-2,minecraft:grass_block)
B(2,12,-1,minecraft:grass_block)
B(2,12,0,minecraft:grass_block)
B(2,12,1,minecraft:grass_block)
B(3,8,-7,minecraft:stone)
B(3,9,-7,minecraft:stone)
B(3,10,-7,minecraft:stone)
B(3,11,-7,minecraft:dirt)
B(3,12,-7,minecraft:dirt)
B(3,13,-7,minecraft:grass_block)
B(3,8,-6,minecraft:stone)
B(3,9,-6,minecraft:stone)
B(3,10,-6,minecraft:stone)
B(3,11,-6,minecraft:dirt)
B(3,12,-6,minecraft:dirt)
B(3,13,-6,minecraft:grass_block)
B(3,9,-5,minecraft:stone)
B(3,10,-5,minecraft:stone)
B(3,11,-5,minecraft:dirt)
B(3,12,-5,minecraft:dirt)
B(3,13,-5,minecraft:grass_block)
B(3,10,-4,minecraft:dirt)
B(3,11,-4,minecraft:dirt)
B(3,12,-4,minecraft:grass_block)
B(3,11,-3,minecraft:dirt)
B(3,12,-3,minecraft:dirt)
B(3,13,-3,minecraft:grass_block)
B(3,12,-2,minecraft:grass_block)
B(3,12,-1,minecraft:grass_block)
B(3,12,0,minecraft:grass_block)
B(4,8,-7,minecraft:stone)
B(4,9,-7,minecraft:stone)
B(4,10,-7,minecraft:stone)
B(4,11,-7,minecraft:dirt)
B(4,12,-7,minecraft:dirt)
B(4,13,-7,minecraft:grass_block)
B(4,8,-6,minecraft:stone)
B(4,9,-6,minecraft:stone)
B(4,10,-6,minecraft:stone)
B(4,11,-6,minecraft:dirt)
B(4,12,-6,minecraft:dirt)
B(4,13,-6,minecraft:grass_block)
B(4,9,-5,minecraft:stone)
B(4,10,-5,minecraft:stone)
B(4,11,-5,minecraft:dirt)
B(4,12,-5,minecraft:grass_block)
B(4,11,-4,minecraft:dirt)
B(4,12,-4,minecraft:grass_block)
B(4,12,-3,minecraft:grass_block)
B(4,12,-2,minecraft:grass_block)
B(5,9,-7,minecraft:cobblestone)
B(5,10,-7,minecraft:dirt)
B(5,11,-7,minecraft:dirt)
B(5,12,-7,minecraft:dirt)
B(5,13,-7,minecraft:grass_block)
B(5,9,-6,minecraft:cobblestone)
B(5,10,-6,minecraft:dirt)
B(5,11,-6,minecraft:dirt)
B(5,12,-6,minecraft:grass_block)
B(5,10,-5,minecraft:dirt)
B(5,11,-5,minecraft:dirt)
B(5,12,-5,minecraft:grass_block)
B(5,11,-4,minecraft:dirt)
B(5,12,-4,minecraft:grass_block)
B(5,12,-3,minecraft:grass_block)
B(6,11,-7,minecraft:dirt)
B(6,12,-7,minecraft:dirt)
B(6,13,-7,minecraft:grass_block)
B(6,11,-6,minecraft:dirt)
B(6,12,-6,minecraft:grass_block)
B(6,11,-5,minecraft:dirt)
B(6,12,-5,minecraft:grass_block)
B(6,11,-4,minecraft:dirt)
B(6,12,-4,minecraft:grass_block)
B(6,12,-3,minecraft:grass_block)
B(7,12,-7,minecraft:grass_block)
B(7,12,-4,minecraft:grass_block)

#######################################################################
# +-----------------------------------------------------------------+ #
# |                             Branches                            | #
# +-----------------------------------------------------------------+ #
#######################################################################

Branch(16,0,0,true,afloatingisland1_C2_R1,NORTH,100.0,0)

#######################################################################
# +-----------------------------------------------------------------+ #
# |                             Entities                            | #
# +-----------------------------------------------------------------+ #
#######################################################################

